File: Sample Data Files/2014-07-16 EB on isolated PMN-PT no Ti spontaneous in situ/Ni-NiO_298K_SiO2_PMN-PT_5.0Tprebias_050V_Au_back.rso.raw
[Header]
TITLE,MPMS RSO Measurement
BYAPP,MPMS Measurement,2.1,Raw with ABS
FILEOPENTIME, 1405592468.125000 7/17/2014, 3:21:08 AM

INFO, APPNAME, MPMS MultiVu Application, Revision 1.58,  Build 076

INFO, NAME, EB in situ
INFO, WEIGHT, 0.000
INFO, AREA, 0.000
INFO, LENGTH, 0.000
INFO, SHAPE, 0
INFO, COMMENT,
INFO, SEQUENCE FILE: MHcurveUpTo100.seq


INFO, BACKGROUND DATA FILE:, None


STARTUPAXIS,X,8,LINEAR,AUTO,0.000000,0.000000
STARTUPAXIS,Y1,9,LINEAR,AUTO,0.000000,0.000000


STARTUPGROUP,Longitudinal
FIELDGROUP,Longitudinal,1,2,3,4,5,6,7,8,9,10,11,12,13,14,15,16,17,18,19,20,21,22
FIELDGROUP,Transverse,1,2,3,4,5,6,7,8,23,24,25,26,27,28,29,30,31,32,33,34,35,36

PLOT_APPEARANCE,ALL,HORZ_GRID_ON,VERT_GRID_ON,MARKERS_ONLY

[Data]
Time,Comment,Field (Oe),Start Temperature (K),End Temperature (K),Scan,Rejected,Position (cm),Long Voltage,Long Average Voltage,Long Detrended Voltage,Long Demeaned Voltage,Long Reg Fit,Long Detrended Fit,Long Demeaned Fit,Long Scaled Response,Long Avg. Scaled Response,Long Background Response,Long Response [w/ABS],Long Detrended Resp. [w/ABS],Long Fit [w/ABS],Long Detrended Fit [w/ABS],Trans Voltage,Trans Average Voltage,Trans Detrended Voltage,Trans Demeaned Voltage,Trans Reg Fit,Trans Detrended Fit,Trans Demeaned Fit,Trans Scaled Response,Trans Avg. Scaled Response,Trans Background Response,Trans Response [w/ABS],Trans Detrended Resp. [w/ABS],Trans Adjusted Fit,Trans Detrended Fit [w/ABS],
1405592468.125,,1.000000e+002,2.980050e+002,2.980050e+002,1,0,2.079471e+000,-2.029481e-002,-2.029481e-002,1.362018e+000,1.362018e+000,3.446417e-002,1.416776e+000,1.416776e+000,-8.845485e-007,-8.845485e-007,,,,,,,,,,,,,,,,,,,,
1405592468.125,,1.000000e+002,2.980050e+002,2.980050e+002,1,0,3.705970e+000,-1.936857e+000,-1.936857e+000,-6.329672e-001,-5.545449e-001,-1.923979e+000,-6.200894e-001,-5.416671e-001,-8.441785e-005,-8.441785e-005,,,,,,,,,,,,,,,,,,,,
1405592486.375,,1.000000e+002,2.980050e+002,2.979968e+002,1,0,4.361161e-001,-1.930601e+000,-1.930601e+000,-6.044556e-001,-5.644199e-001,-1.947709e+000,-6.215641e-001,-5.815283e-001,-8.414517e-005,-8.414517e-005,,,,,,,,,,,,,,,,,,,,
1405592503.640,,1.000000e+002,2.980050e+002,2.979968e+002,1,0,1.899756e+000,-4.638813e-002,-4.638813e-002,1.332573e+000,1.334420e+000,2.511535e-002,1.404077e+000,1.405924e+000,-2.021825e-006,-2.021825e-006,,,,,,,,,,,,,,,,,,,,
1405592503.640,,1.000000e+002,2.980050e+002,2.979968e+002,1,0,3.810189e+000,-1.942351e+000,-1.942351e+000,-6.428114e-001,-5.615422e-001,-1.886571e+000,-5.870322e-001,-5.057629e-001,-8.465727e-005,-8.465727e-005,,,,,,,,,,,,,,,,,,,,
1405592627.968,,7.500000e+001,2.980050e+002,2.980050e+002,1,0,5.564476e-001,-1.870327e+000,-1.870327e+000,-5.187398e-001,-4.809128e-001,-1.916917e+000,-5.653304e-001,-5.275034e-001,-8.151831e-005,-8.151831e-005,,,,,,,,,,,,,,,,,,,,
1405592645.218,,7.500000e+001,2.979968e+002,2.979968e+002,1,0,1.718932e+000,-1.944029e-001,-1.944029e-001,1.161953e+000,1.165308e+000,-1.615400e-001,1.194816e+000,1.198171e+000,-8.473063e-006,-8.473063e-006,,,,,,,,,,,,,,,,,,,,
1405592645.218,,7.500000e+001,2.979968e+002,2.979968e+002,1,0,3.893738e+000,-1.909085e+000,-1.909085e+000,-6.248512e-001,-5.493748e-001,-1.823277e+000,-5.390431e-001,-4.635667e-001,-8.320760e-005,-8.320760e-005,,,,,,,,,,,,,,,,,,,,
1405592662.953,,7.500000e+001,2.979968e+002,2.979968e+002,1,0,6.834221e-001,-1.722922e+000,-1.722922e+000,-3.998719e-001,-3.594267e-001,-1.789310e+000,-4.662590e-001,-4.258138e-001,-7.509368e-005,-7.509368e-005,,,,,,,,,,,,,,,,,,,,
1405592793.984,,5.000000e+001,2.979968e+002,2.979968e+002,1,0,1.538827e+000,-4.480117e-001,-4.480117e-001,8.918791e-001,8.963606e-001,-4.678829e-001,8.720079e-001,8.764895e-001,-1.952666e-005,-1.952666e-005,,,,,,,,,,,,,,,,,,,,
1405592793.984,,5.000000e+001,2.979968e+002,2.979968e+002,1,0,3.953603e+000,-1.868496e+000,-1.868496e+000,-5.928413e-001,-5.241233e-001,-1.768030e+000,-4.923754e-001,-4.236574e-001,-8.143869e-005,-8.143869e-005,,,,,,,,,,,,,,,,,,,,
1405592812.718,,5.000000e+001,2.979968e+002,2.980050e+002,1,0,8.160468e-001,-1.533708e+000,-1.533708e+000,-2.375168e-001,-1.987312e-001,-1.604120e+000,-3.079294e-001,-2.691438e-001,-6.684689e-005,-6.684689e-005,,,,,,,,,,,,,,,,,,,,
1405592830.953,,5.000000e+001,2.980050e+002,2.979968e+002,1,0,1.360908e+000,-7.165746e-001,-7.165746e-001,6.170614e-001,6.233137e-001,-7.790840e-001,5.545521e-001,5.608044e-001,-3.123202e-005,-3.123202e-005,,,,,,,,,,,,,,,,,,,,
1405592830.953,,5.000000e+001,2.980050e+002,2.979968e+002,1,0,3.987450e+000,-1.854762e+000,-1.854762e+000,-5.883383e-001,-5.148741e-001,-1.739765e+000,-4.733411e-001,-3.998768e-001,-8.084012e-005,-8.084012e-005,,,,,,,,,,,,,,,,,,,,
1405592949.218,,4.500000e+001,2.979968e+002,2.980050e+002,1,0,9.542971e-001,-1.338542e+000,-1.338542e+000,-4.414587e-002,-5.682826e-003,-1.413119e+000,-1.187232e-001,-8.026016e-002,-5.834059e-005,-5.834059e-005,,,,,,,,,,,,,,,,,,,,
1405592967.453,,4.500000e+001,2.979968e+002,2.980050e+002,1,0,1.187106e+000,-9.822383e-001,-9.822382e-001,3.317918e-001,3.393057e-001,-1.065971e+000,2.480591e-001,2.555730e-001,-4.281103e-005,-4.281103e-005,,,,,,,,,,,,,,,,,,,,
1405592967.453,,4.500000e+001,2.979968e+002,2.980050e+002,1,0,3.994404e+000,-1.831111e+000,-1.831111e+000,-5.817003e-001,-5.095667e-001,-1.715046e+000,-4.656359e-001,-3.935022e-001,-7.980929e-005,-7.980929e-005,,,,,,,,,,,,,,,,,,,,
1405592984.953,,4.500000e+001,2.979968e+002,2.979968e+002,1,0,1.098629e+000,-1.100192e+000,-1.100192e+000,1.832599e-001,2.243835e-001,-1.180988e+000,1.024646e-001,1.435882e-001,-4.795208e-005,-4.795208e-005,,,,,,,,,,,,,,,,,,,,
1405593103.781,,4.000000e+001,2.979968e+002,2.979968e+002,1,0,1.017706e+000,-1.244087e+000,-1.244087e+000,6.582182e-002,7.437420e-002,-1.335063e+000,-2.515394e-002,-1.660156e-002,-5.422378e-005,-5.422378e-005,,,,,,,,,,,,,,,,,,,,
1405593103.781,,4.000000e+001,2.979968e+002,2.979968e+002,1,0,3.974561e+000,-1.826685e+000,-1.826685e+000,-5.780687e-001,-5.082242e-001,-1.720654e+000,-4.720370e-001,-4.021926e-001,-7.961645e-005,-7.961645e-005,,,,,,,,,,,,,,,,,,,,
1405593121.546,,4.000000e+001,2.979968e+002,2.980050e+002,1,0,1.249804e+000,-8.600116e-001,-8.600116e-001,4.225361e-001,4.633026e-001,-9.328798e-001,3.496678e-001,3.904344e-001,-3.748378e-005,-3.748378e-005,,,,,,,,,,,,,,,,,,,,
1405593139.343,,4.000000e+001,2.980050e+002,2.979885e+002,1,0,8.549359e-001,-1.453902e+000,-1.453902e+000,-1.547381e-001,-1.442987e-001,-1.553182e+000,-2.540187e-001,-2.435793e-001,-6.336860e-005,-6.336860e-005,,,,,,,,,,,,,,,,,,,,
1405593139.343,,4.000000e+001,2.980050e+002,2.979885e+002,1,0,3.929838e+000,-1.825159e+000,-1.825159e+000,-5.901234e-001,-5.155563e-001,-1.730878e+000,-4.958415e-001,-4.212744e-001,-7.954994e-005,-7.954994e-005,,,,,,,,,,,,,,,,,,,,
1405593257.984,,3.500000e+001,2.979968e+002,2.979968e+002,1,0,1.408114e+000,-5.938902e-001,-5.938902e-001,6.678059e-001,7.084892e-001,-6.451318e-001,6.165643e-001,6.572475e-001,-2.588484e-005,-2.588484e-005,,,,,,,,,,,,,,,,,,,,
1405593275.968,,3.500000e+001,2.979968e+002,2.979968e+002,1,0,6.992437e-001,-1.628163e+000,-1.628163e+000,-3.476736e-001,-3.361697e-001,-1.706631e+000,-4.261422e-001,-4.146384e-001,-7.096383e-005,-7.096383e-005,,,,,,,,,,,,,,,,,,,,
1405593275.968,,3.500000e+001,2.979968e+002,2.979968e+002,1,0,3.862884e+000,-1.815241e+000,-1.815241e+000,-5.965851e-001,-5.232482e-001,-1.741252e+000,-5.225959e-001,-4.492590e-001,-7.911768e-005,-7.911768e-005,,,,,,,,,,,,,,,,,,,,
1405593294.203,,3.500000e+001,2.979968e+002,2.979968e+002,1,0,1.573362e+000,-3.389080e-001,-3.389080e-001,9.120974e-001,9.560111e-001,-3.513797e-001,8.996257e-001,9.435394e-001,-1.477138e-005,-1.477138e-005,,,,,,,,,,,,,,,,,,,,
1405593413.437,,3.000000e+001,2.979968e+002,2.980050e+002,1,0,5.522003e-001,-1.742607e+000,-1.742607e+000,-4.697731e-001,-4.574294e-001,-1.801411e+000,-5.285771e-001,-5.162334e-001,-7.595195e-005,-7.595195e-005,,,,,,,,,,,,,,,,,,,,
1405593413.437,,3.000000e+001,2.979968e+002,2.980050e+002,1,0,3.777186e+000,-1.807611e+000,-1.807611e+000,-5.937528e-001,-5.224339e-001,-1.762947e+000,-5.490883e-001,-4.777694e-001,-7.878517e-005,-7.878517e-005,,,,,,,,,,,,,,,,,,,,
1405593430.828,,3.000000e+001,2.979968e+002,2.980050e+002,1,0,1.744994e+000,-1.542711e-001,-1.542711e-001,1.091359e+000,1.134695e+000,-1.098395e-001,1.135790e+000,1.179127e+000,-6.723942e-006,-6.723942e-006,,,,,,,,,,,,,,,,,,,,
1405593449.484,,3.000000e+001,2.979968e+002,2.980050e+002,1,0,4.166850e-001,-1.803186e+000,-1.803186e+000,-5.396137e-001,-5.253578e-001,-1.834436e+000,-5.708637e-001,-5.566078e-001,-7.859230e-005,-7.859230e-005,,,,,,,,,,,,,,,,,,,,
1405593449.484,,3.000000e+001,2.979968e+002,2.980050e+002,1,0,3.676729e+000,-1.787164e+000,-1.787164e+000,-5.848918e-001,-5.093356e-001,-1.773165e+000,-5.708930e-001,-4.953369e-001,-7.789397e-005,-7.789397e-005,,,,,,,,,,,,,,,,,,,,
1405593568.546,,2.500000e+001,2.979968e+002,2.979885e+002,1,0,1.921586e+000,-4.425184e-002,-4.425184e-002,1.181966e+000,1.224372e+000,4.057345e-002,1.266791e+000,1.309197e+000,-1.928728e-006,-1.928728e-006,,,,,,,,,,,,,,,,,,,,
1405593587.437,,2.500000e+001,2.979968e+002,2.979968e+002,1,0,2.949705e-001,-1.801965e+000,-1.801965e+000,-5.567609e-001,-5.415764e-001,-1.799483e+000,-5.542786e-001,-5.390941e-001,-7.853914e-005,-7.853914e-005,,,,,,,,,,,,,,,,,,,,
1405593587.437,,2.500000e+001,2.979968e+002,2.979968e+002,1,0,3.564821e+000,-1.731773e+000,-1.731773e+000,-5.459259e-001,-4.713838e-001,-1.741518e+000,-5.556715e-001,-4.811294e-001,-7.547977e-005,-7.547977e-005,,,,,,,,,,,,,,,,,,,,
1405593605.171,,2.500000e+001,2.979968e+002,2.979968e+002,1,0,2.101268e+000,-4.730369e-002,-4.730369e-002,1.173329e+000,1.218659e+000,4.128316e-002,1.261916e+000,1.307246e+000,-2.061744e-006,-2.061744e-006,,,,,,,,,,,,,,,,,,,,
1405593723.281,,2.000000e+001,2.979968e+002,2.979968e+002,1,0,1.907769e-001,-1.765954e+000,-1.765954e+000,-5.442281e-001,-5.286635e-001,-1.732418e+000,-5.106925e-001,-4.951279e-001,-7.696958e-005,-7.696958e-005,,,,,,,,,,,,,,,,,,,,
1405593723.281,,2.000000e+001,2.979968e+002,2.979968e+002,1,0,3.444484e+000,-1.632282e+000,-1.632282e+000,-4.663303e-001,-3.949925e-001,-1.663854e+000,-4.979020e-001,-4.265642e-001,-7.114349e-005,-7.114349e-005,,,,,,,,,,,,,,,,,,,,
1405593741.015,,2.000000e+001,2.979968e+002,2.979885e+002,1,0,2.282178e+000,-1.524400e-001,-1.524400e-001,1.028964e+000,1.074478e+000,-1.081778e-001,1.073226e+000,1.118740e+000,-6.644138e-006,-6.644138e-006,,,,,,,,,,,,,,,,,,,,
1405593758.796,,2.000000e+001,2.979968e+002,2.980050e+002,1,0,1.073401e-001,-1.743370e+000,-1.743370e+000,-5.326318e-001,-5.153402e-001,-1.685498e+000,-4.747602e-001,-4.574686e-001,-7.598527e-005,-7.598527e-005,,,,,,,,,,,,,,,,,,,,
1405593758.796,,2.000000e+001,2.979968e+002,2.980050e+002,1,0,3.317658e+000,-1.513565e+000,-1.513565e+000,-3.600227e-001,-2.855358e-001,-1.559923e+000,-4.063805e-001,-3.318936e-001,-6.596918e-005,-6.596918e-005,,,,,,,,,,,,,,,,,,,,
1405593877.546,,1.500000e+001,2.979968e+002,2.979885e+002,1,0,2.462526e+000,-3.599658e-001,-3.599658e-001,8.050960e-001,8.475043e-001,-3.726233e-001,7.924385e-001,8.348468e-001,-1.568922e-005,-1.568922e-005,,,,,,,,,,,,,,,,,,,,
1405593895.781,,1.500000e+001,2.979885e+002,2.979968e+002,1,0,4.747586e-002,-1.685995e+000,-1.685995e+000,-5.021355e-001,-4.843780e-001,-1.614647e+000,-4.307870e-001,-4.130296e-001,-7.348460e-005,-7.348460e-005,,,,,,,,,,,,,,,,,,,,
1405593895.781,,1.500000e+001,2.979885e+002,2.979968e+002,1,0,3.185052e+000,-1.331828e+000,-1.331828e+000,-2.025090e-001,-1.302106e-001,-1.388982e+000,-2.596635e-001,-1.873652e-001,-5.804812e-005,-5.804812e-005,,,,,,,,,,,,,,,,,,,,
1405593914.015,,1.500000e+001,2.979968e+002,2.979968e+002,1,0,2.640011e+000,-5.757317e-001,-5.757317e-001,5.691370e-001,6.157131e-001,-6.334431e-001,5.114257e-001,5.580017e-001,-2.509344e-005,-2.509344e-005,,,,,,,,,,,,,,,,,,,,
1405594033.250,,1.000000e+001,2.980050e+002,2.979968e+002,1,0,1.359100e-002,-1.611530e+000,-1.611530e+000,-4.766072e-001,-4.590373e-001,-1.529947e+000,-3.950241e-001,-3.774542e-001,-7.023905e-005,-7.023905e-005,,,,,,,,,,,,,,,,,,,,
1405594033.250,,1.000000e+001,2.980050e+002,2.979968e+002,1,0,3.046769e+000,-1.101718e+000,-1.101718e+000,-1.716251e-002,5.077446e-002,-1.166914e+000,-8.235855e-002,-1.442158e-002,-4.801874e-005,-4.801874e-005,,,,,,,,,,,,,,,,,,,,
1405594050.500,,1.000000e+001,2.979968e+002,2.979968e+002,1,0,2.814188e+000,-7.849361e-001,-7.849361e-001,3.125362e-001,3.579732e-001,-8.627084e-001,2.347639e-001,2.802008e-001,-3.421169e-005,-3.421169e-005,,,,,,,,,,,,,,,,,,,,
1405594068.734,,1.000000e+001,2.979968e+002,2.979968e+002,1,0,6.623552e-003,-1.598407e+000,-1.598407e+000,-4.740617e-001,-4.544957e-001,-1.514965e+000,-3.906202e-001,-3.710542e-001,-6.966708e-005,-6.966708e-005,,,,,,,,,,,,,,,,,,,,
1405594068.734,,1.000000e+001,2.979968e+002,2.979968e+002,1,0,2.902343e+000,-8.902249e-001,-8.902249e-001,1.815366e-001,2.536863e-001,-9.616481e-001,1.101134e-001,1.822631e-001,-3.880074e-005,-3.880074e-005,,,,,,,,,,,,,,,,,,,,
1405594187.484,,5.000000e+000,2.979968e+002,2.979968e+002,1,0,2.983141e+000,-9.401227e-001,-9.401227e-001,8.440290e-002,1.258947e-001,-1.016574e+000,7.951891e-003,4.944372e-002,-4.097557e-005,-4.097557e-005,,,,,,,,,,,,,,,,,,,,
1405594204.750,,5.000000e+000,2.979968e+002,2.979968e+002,1,0,2.641282e-002,-1.482894e+000,-1.482894e+000,-4.447756e-001,-4.253054e-001,-1.405646e+000,-3.675276e-001,-3.480574e-001,-6.463246e-005,-6.463246e-005,,,,,,,,,,,,,,,,,,,,
1405594204.750,,5.000000e+000,2.979968e+002,2.979968e+002,1,0,2.751234e+000,-6.160161e-001,-6.160161e-001,3.728544e-001,4.415730e-001,-6.778643e-001,3.110062e-001,3.797247e-001,-2.684927e-005,-2.684927e-005,,,,,,,,,,,,,,,,,,,,
1405594222.484,,5.000000e+000,2.979968e+002,2.979968e+002,1,0,3.146075e+000,-1.108432e+000,-1.108432e+000,-1.102359e-001,-6.494951e-002,-1.176841e+000,-1.786447e-001,-1.333582e-001,-4.831140e-005,-4.831140e-005,,,,,,,,,,,,,,,,,,,,
1405594343.968,,0.000000e+000,2.979968e+002,2.979968e+002,1,0,7.114470e-002,-1.140324e+000,-1.140324e+000,-3.441533e-001,-3.272555e-001,-1.076390e+000,-2.802191e-001,-2.633213e-001,-4.970144e-005,-4.970144e-005,,,,,,,,,,,,,,,,,,,,
1405594343.968,,0.000000e+000,2.979968e+002,2.979968e+002,1,0,2.592942e+000,-2.932829e-001,-2.932829e-001,4.625210e-001,5.197858e-001,-3.192469e-001,4.365570e-001,4.938218e-001,-1.278284e-005,-1.278284e-005,,,,,,,,,,,,,,,,,,,,
1405594362.453,,0.000000e+000,2.979968e+002,2.980050e+002,1,0,3.301879e+000,-8.928190e-001,-8.928190e-001,-1.634886e-001,-1.256143e-001,-9.446033e-001,-2.152729e-001,-1.773986e-001,-3.891384e-005,-3.891384e-005,,,,,,,,,,,,,,,,,,,,
1405594380.703,,0.000000e+000,2.980132e+002,2.980050e+002,1,0,1.381993e-001,-1.053957e+000,-1.053957e+000,-3.341097e-001,-3.158153e-001,-1.003553e+000,-2.837062e-001,-2.654119e-001,-4.593709e-005,-4.593709e-005,,,,,,,,,,,,,,,,,,,,
1405594380.703,,0.000000e+000,2.980132e+002,2.980050e+002,1,0,2.427682e+000,-1.133763e-001,-1.133763e-001,5.650677e-001,6.247652e-001,-9.801506e-002,5.804290e-001,6.401263e-001,-4.941545e-006,-4.941545e-006,,,,,,,,,,,,,,,,,,,,
1405594516.234,,-5.000000e+000,2.979968e+002,2.979968e+002,1,0,3.448846e+000,5.026398e-001,5.026398e-001,2.051756e-001,2.761065e-001,4.103442e-001,1.128800e-001,1.838110e-001,1.095387e-005,1.095387e-005,,,,,,,,,,,,,,,,,,,,
1405594534.468,,-5.000000e+000,2.979968e+002,2.979968e+002,1,0,2.238382e-001,4.126102e-001,4.126103e-001,9.407248e-002,1.297179e-001,4.573094e-001,1.387717e-001,1.744170e-001,8.991879e-006,8.991879e-006,,,,,,,,,,,,,,,,,,,,
1405594534.468,,-5.000000e+000,2.979968e+002,2.979968e+002,1,0,2.256058e+000,1.121555e-001,1.121555e-001,-2.830198e-001,-1.707369e-001,2.311480e-001,-1.640273e-001,-5.174440e-002,2.444169e-006,2.444169e-006,,,,,,,,,,,,,,,,,,,,
1405594552.203,,-5.000000e+000,2.979968e+002,2.979968e+002,1,0,3.584419e+000,6.190680e-001,6.190680e-001,1.916199e-001,2.675158e-001,5.814942e-001,1.540461e-001,2.299420e-001,1.349115e-005,1.349115e-005,,,,,,,,,,,,,,,,,,,,
1405594676.703,,-1.000000e+001,2.979885e+002,2.980050e+002,1,0,3.242920e-001,1.857967e+000,1.857967e+000,5.696236e-001,5.918685e-001,1.877256e+000,5.889128e-001,6.111577e-001,4.049004e-005,4.049004e-005,,,,,,,,,,,,,,,,,,,,
1405594694.937,,-1.000000e+001,2.979968e+002,2.979968e+002,1,0,2.079494e+000,-2.105777e-002,-2.105777e-002,-1.382001e+000,-1.382001e+000,1.729383e-002,-1.343650e+000,-1.343650e+000,-4.589049e-007,-4.589049e-007,,,,,,,,,,,,,,,,,,,,
1405594694.937,,-1.000000e+001,2.979968e+002,2.979968e+002,1,0,3.706010e+000,1.990112e+000,1.990112e+000,5.814183e-001,6.291685e-001,1.997046e+000,5.883528e-001,6.361030e-001,4.336984e-005,4.336984e-005,,,,,,,,,,,,,,,,,,,,
1405594713.171,,-1.000000e+001,2.980050e+002,2.980050e+002,1,0,4.361247e-001,2.059237e+000,2.059237e+000,6.164799e-001,6.412802e-001,2.048429e+000,6.056729e-001,6.304731e-001,4.487624e-005,4.487624e-005,,,,,,,,,,,,,,,,,,,,
1405594827.343,,-1.500000e+001,2.979968e+002,2.979968e+002,1,0,1.899668e+000,-2.533036e-002,-2.533036e-002,-1.774221e+000,-1.773559e+000,-1.891999e-002,-1.767810e+000,-1.767149e+000,-5.520158e-007,-5.520158e-007,,,,,,,,,,,,,,,,,,,,
1405594827.343,,-1.500000e+001,2.979968e+002,2.979968e+002,1,0,3.810226e+000,2.460097e+000,2.460097e+000,6.827732e-001,7.118679e-001,2.493139e+000,7.158149e-001,7.449096e-001,5.361204e-005,5.361204e-005,,,,,,,,,,,,,,,,,,,,
1405594845.093,,-1.500000e+001,2.979968e+002,2.980050e+002,1,0,5.564663e-001,2.533494e+000,2.533494e+000,7.347093e-001,7.514496e-001,2.498304e+000,6.995189e-001,7.162592e-001,5.521155e-005,5.521155e-005,,,,,,,,,,,,,,,,,,,,
1405594863.359,,-1.500000e+001,2.979968e+002,2.980050e+002,1,0,1.718924e+000,2.258370e-001,2.258370e-001,-1.567796e+000,-1.566232e+000,2.138073e-001,-1.579826e+000,-1.578261e+000,4.921586e-006,4.921586e-006,,,,,,,,,,,,,,,,,,,,
1405594863.359,,-1.500000e+001,2.979968e+002,2.980050e+002,1,0,3.893783e+000,2.450179e+000,2.450179e+000,6.229157e-001,6.581098e-001,2.501493e+000,6.742301e-001,7.094241e-001,5.339589e-005,5.339589e-005,,,,,,,,,,,,,,,,,,,,
1405594980.109,,-2.000000e+001,2.979968e+002,2.979885e+002,1,0,6.834266e-001,2.596820e+000,2.596820e+000,6.804098e-001,6.886622e-001,2.545379e+000,6.289691e-001,6.372215e-001,5.659157e-005,5.659157e-005,,,,,,,,,,,,,,,,,,,,
1405594997.843,,-2.000000e+001,2.979885e+002,2.979968e+002,1,0,1.538376e+000,7.089450e-001,7.089450e-001,-1.258810e+000,-1.257483e+000,6.898263e-001,-1.277928e+000,-1.276601e+000,1.544978e-005,1.544978e-005,,,,,,,,,,,,,,,,,,,,
1405594997.843,,-2.000000e+001,2.979885e+002,2.979968e+002,1,0,3.953542e+000,2.627949e+000,2.627949e+000,6.411724e-001,6.615211e-001,2.683183e+000,6.964066e-001,7.167553e-001,5.726995e-005,5.726995e-005,,,,,,,,,,,,,,,,,,,,
1405595015.578,,-2.000000e+001,2.980050e+002,2.979968e+002,1,0,8.160677e-001,2.463301e+000,2.463301e+000,4.851796e-001,4.975020e-001,2.401254e+000,4.231326e-001,4.354550e-001,5.368185e-005,5.368185e-005,,,,,,,,,,,,,,,,,,,,
1405595134.328,,-2.500000e+001,2.979968e+002,2.979968e+002,1,0,1.361105e+000,1.277200e+000,1.277200e+000,-8.185822e-001,-8.177472e-001,1.241560e+000,-8.542221e-001,-8.533871e-001,2.783354e-005,2.783354e-005,,,,,,,,,,,,,,,,,,,,
1405595134.328,,-2.500000e+001,2.979968e+002,2.979968e+002,1,0,3.987543e+000,2.791528e+000,2.791528e+000,6.867695e-001,6.965811e-001,2.839487e+000,7.347289e-001,7.445405e-001,6.083474e-005,6.083474e-005,,,,,,,,,,,,,,,,,,,,
1405595153.062,,-2.500000e+001,2.980050e+002,2.979968e+002,1,0,9.543273e-001,2.391583e+000,2.391583e+000,2.491288e-001,2.556870e-001,2.334943e+000,1.924886e-001,1.990469e-001,5.211888e-005,5.211888e-005,,,,,,,,,,,,,,,,,,,,
1405595171.296,,-2.500000e+001,2.980050e+002,2.980050e+002,1,0,1.186705e+000,1.816004e+000,1.816004e+000,-3.264507e-001,-3.250314e-001,1.761137e+000,-3.813179e-001,-3.798985e-001,3.957551e-005,3.957551e-005,,,,,,,,,,,,,,,,,,,,
1405595171.296,,-2.500000e+001,2.980050e+002,2.980050e+002,1,0,3.994369e+000,2.845393e+000,2.845393e+000,6.907324e-001,7.043579e-001,2.894801e+000,7.401404e-001,7.537658e-001,6.200861e-005,6.200861e-005,,,,,,,,,,,,,,,,,,,,
1405595290.031,,-3.000000e+001,2.979968e+002,2.979968e+002,1,0,1.098699e+000,2.115085e+000,2.115085e+000,-1.052226e-001,-1.047008e-001,2.081179e+000,-1.391285e-001,-1.386068e-001,4.609325e-005,4.609325e-005,,,,,,,,,,,,,,,,,,,,
1405595307.765,,-3.000000e+001,2.980050e+002,2.979968e+002,1,0,1.017703e+000,2.338176e+000,2.338176e+000,1.243446e-001,1.249218e-001,2.282430e+000,6.859943e-002,6.917667e-002,5.095498e-005,5.095498e-005,,,,,,,,,,,,,,,,,,,,
1405595307.765,,-3.000000e+001,2.980050e+002,2.979968e+002,1,0,3.974620e+000,2.969298e+000,2.969298e+000,7.513304e-001,7.560446e-001,3.012231e+000,7.942627e-001,7.989769e-001,6.470879e-005,6.470879e-005,,,,,,,,,,,,,,,,,,,,
1405595325.515,,-3.000000e+001,2.979968e+002,2.979968e+002,1,0,1.249769e+000,1.674093e+000,1.674093e+000,-5.516376e-001,-5.472630e-001,1.674377e+000,-5.513532e-001,-5.469786e-001,3.648287e-005,3.648287e-005,,,,,,,,,,,,,,,,,,,,
1405595443.781,,-3.500000e+001,2.980050e+002,2.980050e+002,1,0,8.550434e-001,2.742241e+000,2.742241e+000,4.901523e-001,4.894063e-001,2.705609e+000,4.535204e-001,4.527745e-001,5.976058e-005,5.976058e-005,,,,,,,,,,,,,,,,,,,,
1405595443.781,,-3.500000e+001,2.980050e+002,2.980050e+002,1,0,3.929883e+000,3.060244e+000,3.060244e+000,8.127374e-001,8.074093e-001,3.092083e+000,8.445773e-001,8.392491e-001,6.669070e-005,6.669070e-005,,,,,,,,,,,,,,,,,,,,
1405595461.078,,-3.500000e+001,2.980050e+002,2.980050e+002,1,0,1.408042e+000,1.203192e+000,1.203192e+000,-1.053933e+000,-1.053104e+000,1.240971e+000,-1.016154e+000,-1.015325e+000,2.622070e-005,2.622070e-005,,,,,,,,,,,,,,,,,,,,
1405595478.328,,-3.500000e+001,2.979968e+002,2.979968e+002,1,0,6.990856e-001,3.063143e+000,3.063143e+000,7.794234e-001,7.797675e-001,3.027974e+000,7.442549e-001,7.445991e-001,6.675388e-005,6.675388e-005,,,,,,,,,,,,,,,,,,,,
1405595478.328,,-3.500000e+001,2.979968e+002,2.979968e+002,1,0,3.862833e+000,3.161412e+000,3.161412e+000,8.758433e-001,8.780372e-001,3.184548e+000,8.989788e-001,9.011726e-001,6.889543e-005,6.889543e-005,,,,,,,,,,,,,,,,,,,,
1405595596.578,,-4.000000e+001,2.979968e+002,2.979968e+002,1,0,1.573426e+000,7.013153e-001,7.013153e-001,-1.564346e+000,-1.568910e+000,7.553960e-001,-1.510265e+000,-1.514829e+000,1.528349e-005,1.528349e-005,,,,,,,,,,,,,,,,,,,,
1405595614.812,,-4.000000e+001,2.979968e+002,2.979968e+002,1,0,5.523550e-001,3.216956e+000,3.216956e+000,9.491328e-001,9.485672e-001,3.201645e+000,9.338216e-001,9.332559e-001,7.010584e-005,7.010584e-005,,,,,,,,,,,,,,,,,,,,
1405595614.812,,-4.000000e+001,2.979968e+002,2.979968e+002,1,0,3.777255e+000,3.226722e+000,3.226722e+000,9.616011e-001,9.583330e-001,3.230776e+000,9.656549e-001,9.623868e-001,7.031867e-005,7.031867e-005,,,,,,,,,,,,,,,,,,,,
1405595633.046,,-4.000000e+001,2.979968e+002,2.979968e+002,1,0,1.745007e+000,2.963347e-001,2.963347e-001,-1.991995e+000,-1.993040e+000,3.310764e-001,-1.957254e+000,-1.958298e+000,6.457904e-006,6.457904e-006,,,,,,,,,,,,,,,,,,,,
1405595745.296,,-4.500000e+001,2.980050e+002,2.980132e+002,1,0,4.166740e-001,3.310343e+000,3.310343e+000,1.009155e+000,1.007106e+000,3.310661e+000,1.009474e+000,1.007424e+000,7.214095e-005,7.214095e-005,,,,,,,,,,,,,,,,,,,,
1405595745.296,,-4.500000e+001,2.980050e+002,2.980132e+002,1,0,3.676726e+000,3.307444e+000,3.307443e+000,1.015069e+000,1.004206e+000,3.301805e+000,1.009430e+000,9.985681e-001,7.207776e-005,7.207776e-005,,,,,,,,,,,,,,,,,,,,
1405595763.781,,-4.500000e+001,2.980050e+002,2.980050e+002,1,0,1.921638e+000,6.286813e-002,6.286813e-002,-2.250385e+000,-2.253583e+000,4.902826e-002,-2.264225e+000,-2.267423e+000,1.370059e-006,1.370059e-006,,,,,,,,,,,,,,,,,,,,
1405595782.015,,-4.500000e+001,2.980050e+002,2.980050e+002,1,0,2.949300e-001,3.289590e+000,3.289590e+000,9.774680e-001,9.763367e-001,3.303000e+000,9.908776e-001,9.897463e-001,7.168869e-005,7.168869e-005,,,,,,,,,,,,,,,,,,,,
1405595782.015,,-4.500000e+001,2.980050e+002,2.980050e+002,1,0,3.564799e+000,3.315226e+000,3.315226e+000,1.007525e+000,1.001972e+000,3.300930e+000,9.932294e-001,9.876761e-001,7.224736e-005,7.224736e-005,,,,,,,,,,,,,,,,,,,,
1405595901.500,,-5.000000e+001,2.980132e+002,2.980050e+002,1,0,2.101515e+000,7.003998e-002,7.003998e-002,-2.252361e+000,-2.257576e+000,2.124275e-002,-2.301158e+000,-2.306374e+000,1.526352e-006,1.526352e-006,,,,,,,,,,,,,,,,,,,,
1405595919.234,,-5.000000e+001,2.979968e+002,2.979885e+002,1,0,1.907193e-001,3.245033e+000,3.245033e+000,9.140971e-001,9.127145e-001,3.268103e+000,9.371672e-001,9.357846e-001,7.071764e-005,7.071764e-005,,,,,,,,,,,,,,,,,,,,
1405595919.234,,-5.000000e+001,2.979968e+002,2.979885e+002,1,0,3.444353e+000,3.254036e+000,3.254036e+000,9.280545e-001,9.217176e-001,3.234571e+000,9.085895e-001,9.022527e-001,7.091384e-005,7.091384e-005,,,,,,,,,,,,,,,,,,,,
1405595937.468,,-5.000000e+001,2.979968e+002,2.980050e+002,1,0,2.282291e+000,3.576769e-001,3.576769e-001,-1.987807e+000,-1.991062e+000,3.216167e-001,-2.023867e+000,-2.027122e+000,7.794703e-006,7.794703e-006,,,,,,,,,,,,,,,,,,,,
1405596063.781,,-7.500000e+001,2.979968e+002,2.979968e+002,1,0,1.071946e-001,3.693960e+000,3.693960e+000,8.829568e-001,8.926280e-001,3.701940e+000,8.909367e-001,9.006078e-001,8.050074e-005,8.050074e-005,,,,,,,,,,,,,,,,,,,,
1405596063.781,,-7.500000e+001,2.979968e+002,2.979968e+002,1,0,3.317438e+000,3.600574e+000,3.600574e+000,7.575809e-001,7.992413e-001,3.588556e+000,7.455627e-001,7.872231e-001,7.846561e-005,7.846561e-005,,,,,,,,,,,,,,,,,,,,
1405596082.015,,-7.500000e+001,2.979968e+002,2.979968e+002,1,0,2.462471e+000,1.320231e+000,1.320231e+000,-1.584883e+000,-1.526819e+000,1.298309e+000,-1.606805e+000,-1.548740e+000,2.877117e-005,2.877117e-005,,,,,,,,,,,,,,,,,,,,
1405596117.250,,-7.500000e+001,2.979968e+002,2.980050e+002,1,0,4.744757e-002,1.862392e+000,1.862392e+000,4.152806e-001,4.281921e-001,1.864633e+000,4.175219e-001,4.304334e-001,8.117247e-005,8.117247e-005,,,,,,,,,,,,,,,,,,,,
1405596117.250,,-7.500000e+001,2.979968e+002,2.980050e+002,1,0,3.184857e+000,1.730247e+000,1.730247e+000,2.434787e-001,2.960470e-001,1.725616e+000,2.388479e-001,2.914162e-001,7.541292e-005,7.541292e-005,,,,,,,,,,,,,,,,,,,,
1405596242.484,,-1.000000e+002,2.979968e+002,2.979968e+002,1,0,2.640318e+000,2.336344e+000,2.336344e+000,-5.492473e-001,-3.370595e-001,2.346663e+000,-5.389290e-001,-3.267412e-001,1.018295e-004,1.018295e-004,,,,,,,,,,,,,,,,,,,,
1405596259.734,,-1.000000e+002,2.980050e+002,2.979968e+002,1,0,1.353414e-002,2.450026e+000,2.450026e+000,4.177252e-001,4.661309e-001,2.439753e+000,4.074520e-001,4.558576e-001,1.067843e-004,1.067843e-004,,,,,,,,,,,,,,,,,,,,
1405596259.734,,-1.000000e+002,2.980050e+002,2.979968e+002,1,0,3.046596e+000,2.218848e+000,2.218848e+000,4.778442e-002,2.349530e-001,2.240695e+000,6.963071e-002,2.567993e-001,9.670842e-005,9.670842e-005,,,,,,,,,,,,,,,,,,,,
1405596277.468,,-1.000000e+002,2.980050e+002,2.979968e+002,1,0,2.814391e+000,1.900082e+000,1.900082e+000,-2.843069e-001,-1.292508e-001,1.918519e+000,-2.658706e-001,-1.108145e-001,8.281502e-005,8.281502e-005,,,,,,,,,,,,,,,,,,,,
1405596403.703,,-7.500000e+001,2.979968e+002,2.980050e+002,1,0,6.566807e-003,1.603748e+000,1.603748e+000,4.001731e-001,3.959123e-001,1.604359e+000,4.007846e-001,3.965238e-001,6.989944e-005,6.989944e-005,,,,,,,,,,,,,,,,,,,,
1405596403.703,,-7.500000e+001,2.979968e+002,2.980050e+002,1,0,2.902155e+000,1.038850e+000,1.038850e+000,-1.532738e-001,-1.689854e-001,1.060419e+000,-1.317051e-001,-1.474167e-001,4.527834e-005,4.527834e-005,,,,,,,,,,,,,,,,,,,,
1405596420.937,,-7.500000e+001,2.979968e+002,2.980050e+002,1,0,2.983163e+000,1.202429e+000,1.202429e+000,-2.034922e-002,-2.743709e-002,1.205697e+000,-1.708193e-002,-2.416980e-002,5.240796e-005,5.240796e-005,,,,,,,,,,,,,,,,,,,,
1405596438.171,,-7.500000e+001,2.980132e+002,2.979968e+002,1,0,2.639650e-002,1.622974e+000,1.622974e+000,4.082398e-001,4.041442e-001,1.625297e+000,4.105622e-001,4.064666e-001,7.073743e-005,7.073743e-005,,,,,,,,,,,,,,,,,,,,
1405596438.171,,-7.500000e+001,2.980132e+002,2.979968e+002,1,0,2.751103e+000,8.125553e-001,8.125553e-001,-3.918196e-001,-4.062748e-001,8.454295e-001,-3.589453e-001,-3.734006e-001,3.541527e-005,3.541527e-005,,,,,,,,,,,,,,,,,,,,
1405596569.687,,-5.000000e+001,2.980050e+002,2.980050e+002,1,0,3.146209e+000,1.350444e+000,1.350444e+000,2.030065e-001,1.908277e-001,1.338562e+000,1.911246e-001,1.789458e-001,5.885932e-005,5.885932e-005,,,,,,,,,,,,,,,,,,,,
1405596586.921,,-5.000000e+001,2.980050e+002,2.980050e+002,1,0,7.122529e-002,1.581011e+000,1.581011e+000,4.143449e-001,4.091883e-001,1.591690e+000,4.250234e-001,4.198668e-001,6.890864e-005,6.890864e-005,,,,,,,,,,,,,,,,,,,,
1405596586.921,,-5.000000e+001,2.980050e+002,2.980050e+002,1,0,2.592829e+000,5.287331e-001,5.287332e-001,-6.256148e-001,-6.430900e-001,5.573698e-001,-5.969782e-001,-6.144534e-001,2.304492e-005,2.304492e-005,,,,,,,,,,,,,,,,,,,,
1405596605.156,,-5.000000e+001,2.980050e+002,2.979968e+002,1,0,3.302045e+000,1.524857e+000,1.524857e+000,3.665537e-001,3.558264e-001,1.514206e+000,3.559025e-001,3.451751e-001,6.646115e-005,6.646115e-005,,,,,,,,,,,,,,,,,,,,
1405596724.390,,-4.500000e+001,2.979968e+002,2.979968e+002,1,0,1.381670e-001,1.580706e+000,1.580706e+000,4.472705e-001,4.412742e-001,1.586333e+000,4.528974e-001,4.469011e-001,6.889537e-005,6.889537e-005,,,,,,,,,,,,,,,,,,,,
1405596724.390,,-4.500000e+001,2.979968e+002,2.979968e+002,1,0,2.427491e+000,2.523881e-001,2.523881e-001,-8.674771e-001,-8.870440e-001,2.765198e-001,-8.433454e-001,-8.629123e-001,1.100038e-005,1.100038e-005,,,,,,,,,,,,,,,,,,,,
1405596742.625,,-4.500000e+001,2.979968e+002,2.980050e+002,1,0,3.448905e+000,1.619160e+000,1.619160e+000,4.683947e-001,4.578286e-001,1.612265e+000,4.614996e-001,4.509336e-001,7.057136e-005,7.057136e-005,,,,,,,,,,,,,,,,,,,,
1405596759.859,,-4.500000e+001,2.979968e+002,2.980050e+002,1,0,2.239366e-001,1.635487e+000,1.635487e+000,4.877282e-001,4.826635e-001,1.633971e+000,4.862119e-001,4.811472e-001,7.128299e-005,7.128299e-005,,,,,,,,,,,,,,,,,,,,
1405596759.859,,-4.500000e+001,2.979968e+002,2.980050e+002,1,0,2.255949e+000,7.766961e-002,7.766961e-002,-1.059200e+000,-1.075154e+000,7.819015e-002,-1.058679e+000,-1.074633e+000,3.385244e-006,3.385244e-006,,,,,,,,,,,,,,,,,,,,
1405596879.171,,-4.000000e+001,2.979968e+002,2.980050e+002,1,0,3.584491e+000,1.647084e+000,1.647084e+000,5.076197e-001,4.945610e-001,1.647738e+000,5.082735e-001,4.952147e-001,7.178848e-005,7.178848e-005,,,,,,,,,,,,,,,,,,,,
1405596896.453,,-4.000000e+001,2.979968e+002,2.979968e+002,1,0,3.243973e-001,1.650594e+000,1.650594e+000,5.101263e-001,5.047261e-001,1.649138e+000,5.086703e-001,5.032700e-001,7.194145e-005,7.194145e-005,,,,,,,,,,,,,,,,,,,,
1405596914.187,,-4.000000e+001,2.979968e+002,2.979968e+002,1,0,2.079305e+000,-1.297037e-002,-1.297037e-002,-1.164307e+000,-1.164307e+000,-1.743782e-002,-1.168774e+000,-1.168774e+000,-5.653160e-007,-5.653160e-007,,,,,,,,,,,,,,,,,,,,
1405596914.187,,-4.000000e+001,2.979968e+002,2.979968e+002,1,0,3.706042e+000,1.650441e+000,1.650441e+000,5.085418e-001,4.991047e-001,1.653424e+000,5.115246e-001,5.020875e-001,7.193480e-005,7.193480e-005,,,,,,,,,,,,,,,,,,,,
1405597033.421,,-3.500000e+001,2.979968e+002,2.979968e+002,1,0,4.361896e-001,1.648000e+000,1.648000e+000,5.107306e-001,5.050452e-001,1.646367e+000,5.090984e-001,5.034130e-001,7.182842e-005,7.182842e-005,,,,,,,,,,,,,,,,,,,,
1405597051.156,,-3.500000e+001,2.979968e+002,2.980050e+002,1,0,1.899716e+000,2.899258e-002,2.899258e-002,-1.118911e+000,-1.119137e+000,1.862470e-002,-1.129279e+000,-1.129505e+000,1.263648e-006,1.263648e-006,,,,,,,,,,,,,,,,,,,,
1405597051.156,,-3.500000e+001,2.979968e+002,2.980050e+002,1,0,3.810287e+000,1.622822e+000,1.622822e+000,4.846342e-001,4.746922e-001,1.623753e+000,4.855652e-001,4.756233e-001,7.073105e-005,7.073105e-005,,,,,,,,,,,,,,,,,,,,
1405597068.921,,-3.500000e+001,2.980050e+002,2.979968e+002,1,0,5.566353e-001,1.635334e+000,1.635334e+000,4.846378e-001,4.799124e-001,1.629064e+000,4.783675e-001,4.736421e-001,7.127641e-005,7.127641e-005,,,,,,,,,,,,,,,,,,,,
1405597194.250,,-3.000000e+001,2.979968e+002,2.979968e+002,1,0,1.718663e+000,1.791437e-001,1.791437e-001,-9.468912e-001,-9.473273e-001,1.759639e-001,-9.500710e-001,-9.505070e-001,7.808019e-006,7.808019e-006,,,,,,,,,,,,,,,,,,,,
1405597194.250,,-3.000000e+001,2.979968e+002,2.979968e+002,1,0,3.893790e+000,1.565905e+000,1.565905e+000,4.492442e-001,4.394338e-001,1.568663e+000,4.520027e-001,4.421923e-001,6.825034e-005,6.825034e-005,,,,,,,,,,,,,,,,,,,,
1405597211.031,,-3.000000e+001,2.979885e+002,2.979968e+002,1,0,6.835588e-001,1.545915e+000,1.545915e+000,4.153824e-001,4.105966e-001,1.531553e+000,4.010207e-001,3.962349e-001,6.737909e-005,6.737909e-005,,,,,,,,,,,,,,,,,,,,
1405597229.265,,-3.000000e+001,2.979968e+002,2.980050e+002,1,0,1.538646e+000,4.379406e-001,4.379406e-001,-7.030734e-001,-7.036345e-001,4.392938e-001,-7.017203e-001,-7.022814e-001,1.908775e-005,1.908775e-005,,,,,,,,,,,,,,,,,,,,
1405597229.265,,-3.000000e+001,2.979968e+002,2.980050e+002,1,0,3.953645e+000,1.557360e+000,1.557360e+000,4.243873e-001,4.157845e-001,1.559541e+000,4.265691e-001,4.179662e-001,6.787790e-005,6.787790e-005,,,,,,,,,,,,,,,,,,,,
1405597347.250,,-2.500000e+001,2.979968e+002,2.979968e+002,1,0,8.162025e-001,1.420942e+000,1.420942e+000,3.009740e-001,2.960588e-001,1.402054e+000,2.820858e-001,2.771705e-001,6.193212e-005,6.193212e-005,,,,,,,,,,,,,,,,,,,,
1405597365.234,,-2.500000e+001,2.980050e+002,2.979968e+002,1,0,1.360990e+000,7.051302e-001,7.051302e-001,-4.227174e-001,-4.233792e-001,6.985869e-001,-4.292606e-001,-4.299225e-001,3.073328e-005,3.073328e-005,,,,,,,,,,,,,,,,,,,,
1405597365.234,,-2.500000e+001,2.980050e+002,2.979968e+002,1,0,3.987567e+000,1.523026e+000,1.523026e+000,4.022941e-001,3.945168e-001,1.528178e+000,4.074457e-001,3.996685e-001,6.638150e-005,6.638150e-005,,,,,,,,,,,,,,,,,,,,
1405597383.968,,-2.500000e+001,2.979968e+002,2.980050e+002,1,0,9.544083e-001,1.279031e+000,1.279031e+000,1.484623e-001,1.450090e-001,1.259308e+000,1.287396e-001,1.252863e-001,5.574689e-005,5.574689e-005,,,,,,,,,,,,,,,,,,,,
1405597502.218,,-2.000000e+001,2.979968e+002,2.979968e+002,1,0,1.186629e+000,9.537035e-001,9.537034e-001,-1.567211e-001,-1.575472e-001,9.366121e-001,-1.738123e-001,-1.746385e-001,4.156743e-005,4.156743e-005,,,,,,,,,,,,,,,,,,,,
1405597502.218,,-2.000000e+001,2.979968e+002,2.979968e+002,1,0,3.994334e+000,1.496017e+000,1.496017e+000,3.926980e-001,3.847667e-001,1.503689e+000,4.003697e-001,3.924384e-001,6.520434e-005,6.520434e-005,,,,,,,,,,,,,,,,,,,,
1405597520.281,,-2.000000e+001,2.979968e+002,2.980050e+002,1,0,1.098881e+000,1.070284e+000,1.070284e+000,-4.155638e-002,-4.472244e-002,1.057113e+000,-5.472793e-002,-5.789399e-002,4.664864e-005,4.664864e-005,,,,,,,,,,,,,,,,,,,,
1405597538.265,,-2.000000e+001,2.980050e+002,2.979968e+002,1,0,1.017867e+000,1.190985e+000,1.190985e+000,7.108658e-002,7.028925e-002,1.169957e+000,5.005914e-002,4.926181e-002,5.190941e-005,5.190941e-005,,,,,,,,,,,,,,,,,,,,
1405597538.265,,-2.000000e+001,2.980050e+002,2.979968e+002,1,0,3.974653e+000,1.512650e+000,1.512650e+000,3.984658e-001,3.919543e-001,1.523599e+000,4.094149e-001,4.029034e-001,6.592928e-005,6.592928e-005,,,,,,,,,,,,,,,,,,,,
1405597656.500,,-1.500000e+001,2.980050e+002,2.980050e+002,1,0,1.249978e+000,8.346812e-001,8.346812e-001,-2.605975e-001,-2.642366e-001,8.363011e-001,-2.589776e-001,-2.626167e-001,3.637984e-005,3.637984e-005,,,,,,,,,,,,,,,,,,,,
1405597674.234,,-1.500000e+001,2.979968e+002,2.979968e+002,1,0,8.547064e-001,1.357005e+000,1.357005e+000,2.525390e-001,2.517897e-001,1.342360e+000,2.378940e-001,2.371447e-001,5.914550e-005,5.914550e-005,,,,,,,,,,,,,,,,,,,,
1405597674.234,,-1.500000e+001,2.979968e+002,2.979968e+002,1,0,3.929828e+000,1.510971e+000,1.510971e+000,4.111077e-001,4.057556e-001,1.524356e+000,4.244918e-001,4.191397e-001,6.585615e-005,6.585615e-005,,,,,,,,,,,,,,,,,,,,
1405597691.468,,-1.500000e+001,2.979968e+002,2.979968e+002,1,0,1.408200e+000,6.123539e-001,6.123539e-001,-5.082278e-001,-5.112461e-001,6.330144e-001,-4.875673e-001,-4.905856e-001,2.668963e-005,2.668963e-005,,,,,,,,,,,,,,,,,,,,
1405597803.968,,-1.000000e+001,2.979968e+002,2.979968e+002,1,0,6.988643e-001,1.482437e+000,1.482437e+000,3.921992e-001,3.913076e-001,1.464286e+000,3.740489e-001,3.731574e-001,6.461248e-005,6.461248e-005,,,,,,,,,,,,,,,,,,,,
1405597803.968,,-1.000000e+001,2.979968e+002,2.979968e+002,1,0,3.862788e+000,1.517533e+000,1.517533e+000,4.320875e-001,4.264038e-001,1.530179e+000,4.447333e-001,4.390495e-001,6.614217e-005,6.614217e-005,,,,,,,,,,,,,,,,,,,,
1405597822.234,,-1.000000e+001,2.979968e+002,2.979968e+002,1,0,1.573506e+000,3.483688e-001,3.483688e-001,-7.451054e-001,-7.470810e-001,3.767135e-001,-7.167607e-001,-7.187363e-001,1.518377e-005,1.518377e-005,,,,,,,,,,,,,,,,,,,,
1405597839.968,,-1.000000e+001,2.979968e+002,2.980050e+002,1,0,5.520193e-001,1.562700e+000,1.562700e+000,4.672845e-001,4.665499e-001,1.551810e+000,4.563939e-001,4.556593e-001,6.811080e-005,6.811080e-005,,,,,,,,,,,,,,,,,,,,
1405597839.968,,-1.000000e+001,2.979968e+002,2.980050e+002,1,0,3.777095e+000,1.556749e+000,1.556749e+000,4.648435e-001,4.605988e-001,1.562067e+000,4.701610e-001,4.659163e-001,6.785142e-005,6.785142e-005,,,,,,,,,,,,,,,,,,,,
1405597964.953,,-5.000000e+000,2.980050e+002,2.980050e+002,1,0,1.745125e+000,1.130711e-001,1.130711e-001,-9.419077e-001,-9.439312e-001,1.359099e-001,-9.190689e-001,-9.210924e-001,4.928242e-006,4.928242e-006,,,,,,,,,,,,,,,,,,,,
1405597982.187,,-5.000000e+000,2.979968e+002,2.980050e+002,1,0,4.166526e-001,1.546831e+000,1.546831e+000,4.801080e-001,4.797988e-001,1.543011e+000,4.762887e-001,4.759796e-001,6.741915e-005,6.741915e-005,,,,,,,,,,,,,,,,,,,,
1405597982.187,,-5.000000e+000,2.979968e+002,2.980050e+002,1,0,3.676642e+000,1.543321e+000,1.543321e+000,4.779278e-001,4.762892e-001,1.541662e+000,4.762685e-001,4.746299e-001,6.726618e-005,6.726618e-005,,,,,,,,,,,,,,,,,,,,
1405597999.921,,-5.000000e+000,2.980050e+002,2.979968e+002,1,0,1.921702e+000,1.678518e-002,1.678518e-002,-1.067901e+000,-1.068754e+000,2.201996e-002,-1.062666e+000,-1.063519e+000,7.315879e-007,7.315879e-007,,,,,,,,,,,,,,,,,,,,
1405598118.671,,0.000000e+000,2.979968e+002,2.979968e+002,1,0,2.950747e-001,1.494186e+000,1.494186e+000,4.490943e-001,4.484417e-001,1.500600e+000,4.555080e-001,4.548554e-001,6.512464e-005,6.512464e-005,,,,,,,,,,,,,,,,,,,,
1405598118.671,,0.000000e+000,2.979968e+002,2.979968e+002,1,0,3.564804e+000,1.508530e+000,1.508530e+000,4.659889e-001,4.627854e-001,1.498965e+000,4.564239e-001,4.532204e-001,6.574982e-005,6.574982e-005,,,,,,,,,,,,,,,,,,,,
1405598135.906,,0.000000e+000,2.980050e+002,2.979968e+002,1,0,2.101401e+000,1.953185e-002,1.953185e-002,-1.048113e+000,-1.048050e+000,1.165769e-002,-1.055987e+000,-1.055924e+000,8.513026e-007,8.513026e-007,,,,,,,,,,,,,,,,,,,,
1405598154.140,,0.000000e+000,2.979968e+002,2.979968e+002,1,0,1.908472e-001,1.461989e+000,1.461989e+000,4.074757e-001,4.077952e-001,1.480415e+000,4.259019e-001,4.262214e-001,6.372133e-005,6.372133e-005,,,,,,,,,,,,,,,,,,,,
1405598154.140,,0.000000e+000,2.979968e+002,2.979968e+002,1,0,3.444484e+000,1.485641e+000,1.485641e+000,4.299825e-001,4.314470e-001,1.467094e+000,4.114360e-001,4.129004e-001,6.475220e-005,6.475220e-005,,,,,,,,,,,,,,,,,,,,
1405598272.875,,5.000000e+000,2.979968e+002,2.979968e+002,1,0,2.282332e+000,1.229896e-001,1.229896e-001,-9.031941e-001,-9.024169e-001,1.161695e-001,-9.100142e-001,-9.092369e-001,5.360544e-006,5.360544e-006,,,,,,,,,,,,,,,,,,,,
1405598290.625,,5.000000e+000,2.979968e+002,2.979968e+002,1,0,1.072859e-001,1.371807e+000,1.371807e+000,3.510997e-001,3.520660e-001,1.402741e+000,3.820338e-001,3.830001e-001,5.979068e-005,5.979068e-005,,,,,,,,,,,,,,,,,,,,
1405598290.625,,5.000000e+000,2.979968e+002,2.979968e+002,1,0,3.317519e+000,1.373180e+000,1.373180e+000,3.492767e-001,3.534395e-001,1.340564e+000,3.166599e-001,3.208227e-001,5.985054e-005,5.985054e-005,,,,,,,,,,,,,,,,,,,,
1405598308.906,,5.000000e+000,2.979968e+002,2.979968e+002,1,0,2.462559e+000,3.349407e-001,3.349406e-001,-6.954796e-001,-6.935652e-001,3.264160e-001,-7.040043e-001,-7.020900e-001,1.459850e-005,1.459850e-005,,,,,,,,,,,,,,,,,,,,
1405598434.156,,1.000000e+001,2.979968e+002,2.979968e+002,1,0,4.744927e-002,1.283914e+000,1.283914e+000,3.018454e-001,3.025809e-001,1.325867e+000,3.437985e-001,3.445340e-001,5.595979e-005,5.595979e-005,,,,,,,,,,,,,,,,,,,,
1405598434.156,,1.000000e+001,2.979968e+002,2.979968e+002,1,0,3.184859e+000,1.214026e+000,1.214026e+000,2.296989e-001,2.326935e-001,1.173573e+000,1.892453e-001,1.922399e-001,5.291373e-005,5.291373e-005,,,,,,,,,,,,,,,,,,,,
1405598451.390,,1.000000e+001,2.979968e+002,2.980050e+002,1,0,2.640355e+000,5.621510e-001,5.621510e-001,-4.343390e-001,-4.314662e-001,5.431637e-001,-4.533262e-001,-4.504534e-001,2.450153e-005,2.450153e-005,,,,,,,,,,,,,,,,,,,,
1405598469.125,,1.000000e+001,2.980050e+002,2.979968e+002,1,0,1.355188e-002,1.284677e+000,1.284677e+000,2.814044e-001,2.831072e-001,1.332683e+000,3.294104e-001,3.311131e-001,5.599305e-005,5.599305e-005,,,,,,,,,,,,,,,,,,,,
1405598469.125,,1.000000e+001,2.980050e+002,2.979968e+002,1,0,3.046607e+000,1.088900e+000,1.088900e+000,8.074703e-002,8.733094e-002,1.053846e+000,4.569282e-002,5.227673e-002,4.746008e-005,4.746008e-005,,,,,,,,,,,,,,,,,,,,
1405598587.109,,1.500000e+001,2.979968e+002,2.979968e+002,1,0,2.814215e+000,7.492294e-001,7.492294e-001,-1.886741e-001,-1.851390e-001,7.142323e-001,-2.236712e-001,-2.201361e-001,3.265539e-005,3.265539e-005,,,,,,,,,,,,,,,,,,,,
1405598604.843,,1.500000e+001,2.979968e+002,2.980050e+002,1,0,6.653599e-003,1.198767e+000,1.198767e+000,2.555660e-001,2.576561e-001,1.252673e+000,3.094716e-001,3.115617e-001,5.224863e-005,5.224863e-005,,,,,,,,,,,,,,,,,,,,
1405598604.843,,1.500000e+001,2.979968e+002,2.980050e+002,1,0,2.902218e+000,8.503982e-001,8.503982e-001,-9.842012e-002,-9.071273e-002,8.288242e-001,-1.199941e-001,-1.122867e-001,3.706487e-005,3.706487e-005,,,,,,,,,,,,,,,,,,,,
1405598623.078,,1.500000e+001,2.979968e+002,2.980050e+002,1,0,2.983050e+000,9.880368e-001,9.880368e-001,2.112974e-002,2.749991e-002,9.376267e-001,-2.928030e-002,-2.291012e-002,4.306388e-005,4.306388e-005,,,,,,,,,,,,,,,,,,,,
1405598740.078,,2.000000e+001,2.980050e+002,2.979968e+002,1,0,2.634560e-002,1.103854e+000,1.103855e+000,2.293928e-001,2.322115e-001,1.162890e+000,2.884285e-001,2.912471e-001,4.811181e-005,4.811181e-005,,,,,,,,,,,,,,,,,,,,
1405598740.078,,2.000000e+001,2.980050e+002,2.979968e+002,1,0,2.751063e+000,6.018250e-001,6.018250e-001,-2.797662e-001,-2.698181e-001,5.970337e-001,-2.845576e-001,-2.746094e-001,2.623071e-005,2.623071e-005,,,,,,,,,,,,,,,,,,,,
1405598758.562,,2.000000e+001,2.979968e+002,2.979968e+002,1,0,3.146281e+000,1.060366e+000,1.060366e+000,1.752013e-001,1.823167e-001,1.005939e+000,1.207751e-001,1.278905e-001,4.621634e-005,4.621634e-005,,,,,,,,,,,,,,,,,,,,
1405598776.093,,2.000000e+001,2.980050e+002,2.979968e+002,1,0,7.123102e-002,1.124760e+000,1.124760e+000,2.512761e-001,2.557364e-001,1.176713e+000,3.032292e-001,3.076894e-001,4.902297e-005,4.902297e-005,,,,,,,,,,,,,,,,,,,,
1405598776.093,,2.000000e+001,2.980050e+002,2.979968e+002,1,0,2.592859e+000,4.016236e-001,4.016236e-001,-4.825151e-001,-4.673997e-001,4.204757e-001,-4.636630e-001,-4.485477e-001,1.750488e-005,1.750488e-005,,,,,,,,,,,,,,,,,,,,
1405598895.578,,2.500000e+001,2.980050e+002,2.979968e+002,1,0,3.302023e+000,8.922086e-001,8.922086e-001,2.180722e-001,2.291523e-001,8.415895e-001,1.674531e-001,1.785331e-001,3.888715e-005,3.888715e-005,,,,,,,,,,,,,,,,,,,,
1405598913.562,,2.500000e+001,2.980050e+002,2.980050e+002,1,0,1.381800e-001,8.513138e-001,8.513138e-001,1.898942e-001,1.959883e-001,8.951644e-001,2.337447e-001,2.398388e-001,3.710474e-005,3.710474e-005,,,,,,,,,,,,,,,,,,,,
1405598913.562,,2.500000e+001,2.980050e+002,2.980050e+002,1,0,2.427496e+000,1.356548e-001,1.356548e-001,-5.395567e-001,-5.196707e-001,1.668931e-001,-5.083185e-001,-4.884325e-001,5.912549e-006,5.912549e-006,,,,,,,,,,,,,,,,,,,,
1405598931.046,,2.500000e+001,2.979968e+002,2.979968e+002,1,0,3.448844e+000,9.257790e-001,9.257790e-001,2.628864e-001,2.760163e-001,8.912309e-001,2.283383e-001,2.414682e-001,4.035032e-005,4.035032e-005,,,,,,,,,,,,,,,,,,,,
1405599065.828,,3.000000e+001,2.979968e+002,2.979968e+002,1,0,2.238762e-001,-5.012665e-001,-5.012665e-001,-2.084828e-001,-1.629702e-001,-4.510075e-001,-1.582238e-001,-1.127112e-001,-1.092391e-005,-1.092391e-005,,,,,,,,,,,,,,,,,,,,
1405599065.828,,3.000000e+001,2.979968e+002,2.979968e+002,1,0,2.255944e+000,-1.261940e-001,-1.261940e-001,6.873758e-002,2.121023e-001,-5.368225e-002,1.412494e-001,2.846141e-001,-2.750099e-006,-2.750099e-006,,,,,,,,,,,,,,,,,,,,
1405599083.562,,3.000000e+001,2.979968e+002,2.979968e+002,1,0,3.584493e+000,-4.715109e-001,-4.715110e-001,-1.583393e-001,-6.453875e-002,-4.943367e-001,-1.811650e-001,-8.736449e-002,-1.027546e-005,-1.027546e-005,,,,,,,,,,,,,,,,,,,,
1405599101.796,,3.000000e+001,2.979968e+002,2.979968e+002,1,0,3.244836e-001,-6.016724e-001,-6.016724e-001,-2.053977e-001,-1.589175e-001,-5.715788e-001,-1.753041e-001,-1.288239e-001,-1.311202e-005,-1.311202e-005,,,,,,,,,,,,,,,,,,,,
1405599220.281,,3.500000e+001,2.980050e+002,2.979968e+002,1,0,2.079267e+000,-4.425184e-002,-4.425184e-002,1.534099e+000,1.534099e+000,-1.907303e-002,1.559278e+000,1.559278e+000,-9.643632e-007,-9.643632e-007,,,,,,,,,,,,,,,,,,,,
1405599220.281,,3.500000e+001,2.980050e+002,2.979968e+002,1,0,3.706025e+000,-2.203436e+000,-2.203436e+000,-7.084286e-001,-6.250855e-001,-2.178297e+000,-6.832895e-001,-5.999464e-001,-4.801863e-005,-4.801863e-005,,,,,,,,,,,,,,,,,,,,
1405599238.015,,3.500000e+001,2.979885e+002,2.980050e+002,1,0,4.361642e-001,-2.261727e+000,-2.261727e+000,-6.797946e-001,-6.356726e-001,-2.283614e+000,-7.016822e-001,-6.575601e-001,-4.928893e-005,-4.928893e-005,,,,,,,,,,,,,,,,,,,,
1405599256.765,,3.500000e+001,2.979968e+002,2.979968e+002,1,0,1.899491e+000,1.815851e-002,1.815851e-002,1.665441e+000,1.667466e+000,9.445703e-002,1.741739e+000,1.743765e+000,3.957214e-007,3.957214e-007,,,,,,,,,,,,,,,,,,,,
1405599256.765,,3.500000e+001,2.979968e+002,2.979968e+002,1,0,3.810221e+000,-2.288736e+000,-2.288736e+000,-7.285563e-001,-6.394278e-001,-2.223031e+000,-6.628515e-001,-5.737230e-001,-4.987753e-005,-4.987753e-005,,,,,,,,,,,,,,,,,,,,
1405599374.500,,4.000000e+001,2.979968e+002,2.979968e+002,1,0,5.565777e-001,-2.932371e+000,-2.932371e+000,-7.791066e-001,-7.290781e-001,-2.997668e+000,-8.444037e-001,-7.943752e-001,-6.390399e-005,-6.390399e-005,,,,,,,,,,,,,,,,,,,,
1405599392.234,,4.000000e+001,2.979885e+002,2.980050e+002,1,0,1.718893e+000,-2.966399e-001,-2.966399e-001,1.930378e+000,1.934931e+000,-2.293974e-001,1.997620e+000,2.002173e+000,-6.464555e-006,-6.464555e-006,,,,,,,,,,,,,,,,,,,,
1405599392.234,,4.000000e+001,2.979885e+002,2.980050e+002,1,0,3.893809e+000,-3.064058e+000,-3.064058e+000,-9.349319e-001,-8.324876e-001,-2.946622e+000,-8.174955e-001,-7.150512e-001,-6.677380e-005,-6.677380e-005,,,,,,,,,,,,,,,,,,,,
1405599409.796,,4.000000e+001,2.979968e+002,2.980050e+002,1,0,6.834214e-001,-2.692801e+000,-2.692801e+000,-5.809187e-001,-5.252161e-001,-2.782623e+000,-6.707408e-001,-6.150382e-001,-5.868313e-005,-5.868313e-005,,,,,,,,,,,,,,,,,,,,
1405599529.781,,4.500000e+001,2.979968e+002,2.979968e+002,1,0,1.538818e+000,-7.121494e-001,-7.121494e-001,1.647339e+000,1.654478e+000,-7.265987e-001,1.632889e+000,1.640029e+000,-1.551958e-005,-1.551958e-005,,,,,,,,,,,,,,,,,,,,
1405599529.781,,4.500000e+001,2.979968e+002,2.979968e+002,1,0,3.953619e+000,-3.247322e+000,-3.247322e+000,-9.901711e-001,-8.806944e-001,-3.086603e+000,-8.294525e-001,-7.199757e-001,-7.076756e-005,-7.076756e-005,,,,,,,,,,,,,,,,,,,,
1405599547.515,,4.500000e+001,2.980050e+002,2.980050e+002,1,0,8.160677e-001,-2.635578e+000,-2.635578e+000,-3.527173e-001,-2.907040e-001,-2.748422e+000,-4.655606e-001,-4.035473e-001,-5.743608e-005,-5.743608e-005,,,,,,,,,,,,,,,,,,,,
1405599565.781,,4.500000e+001,2.979968e+002,2.980050e+002,1,0,1.360750e+000,-1.187933e+000,-1.187933e+000,1.172518e+000,1.182444e+000,-1.276708e+000,1.083744e+000,1.093669e+000,-2.588814e-005,-2.588814e-005,,,,,,,,,,,,,,,,,,,,
1405599565.781,,4.500000e+001,2.979968e+002,2.980050e+002,1,0,3.987437e+000,-3.235878e+000,-3.235878e+000,-9.821259e-001,-8.655005e-001,-3.055991e+000,-8.022398e-001,-6.856143e-001,-7.051815e-005,-7.051815e-005,,,,,,,,,,,,,,,,,,,,
1405599684.015,,5.000000e+001,2.979968e+002,2.980132e+002,1,0,9.543690e-001,-2.497482e+000,-2.497482e+000,-3.843169e-002,2.637672e-002,-2.627623e+000,-1.685727e-001,-1.037643e-001,-5.442658e-005,-5.442658e-005,,,,,,,,,,,,,,,,,,,,
1405599702.000,,5.000000e+001,2.979968e+002,2.980050e+002,1,0,1.187120e+000,-1.823786e+000,-1.823786e+000,6.768228e-001,6.898290e-001,-1.967316e+000,5.332931e-001,5.462992e-001,-3.974501e-005,-3.974501e-005,,,,,,,,,,,,,,,,,,,,
1405599702.000,,5.000000e+001,2.979968e+002,2.980050e+002,1,0,3.994412e+000,-3.454390e+000,-3.454390e+000,-1.065634e+000,-9.407749e-001,-3.254991e+000,-8.662345e-001,-7.413754e-001,-7.528008e-005,-7.528008e-005,,,,,,,,,,,,,,,,,,,,
1405599719.984,,5.000000e+001,2.979968e+002,2.979968e+002,1,0,1.098653e+000,-2.070223e+000,-2.070223e+000,4.020515e-001,4.719653e-001,-2.220137e+000,2.521379e-001,3.220518e-001,-4.511550e-005,-4.511550e-005,,,,,,,,,,,,,,,,,,,,
1405599844.718,,7.500000e+001,2.980050e+002,2.980050e+002,1,0,1.018025e+000,-2.524491e+000,-2.524491e+000,1.678201e-001,1.870677e-001,-2.731466e+000,-3.915469e-002,-1.990700e-002,-5.501505e-005,-5.501505e-005,,,,,,,,,,,,,,,,,,,,
1405599844.718,,7.500000e+001,2.980050e+002,2.980050e+002,1,0,3.974637e+000,-3.763390e+000,-3.763390e+000,-1.209021e+000,-1.051831e+000,-3.528746e+000,-9.743766e-001,-8.171871e-001,-8.201379e-005,-8.201379e-005,,,,,,,,,,,,,,,,,,,,
1405599862.468,,7.500000e+001,2.980050e+002,2.980050e+002,1,0,1.249916e+000,-1.726585e+000,-1.726585e+000,8.970129e-001,9.873142e-001,-1.884812e+000,7.387853e-001,8.290865e-001,-3.762665e-005,-3.762665e-005,,,,,,,,,,,,,,,,,,,,
1405599880.218,,7.500000e+001,2.980050e+002,2.979968e+002,1,0,8.549845e-001,-2.974181e+000,-2.974181e+000,-2.995930e-001,-2.765098e-001,-3.192100e+000,-5.175117e-001,-4.944284e-001,-6.481494e-005,-6.481494e-005,,,,,,,,,,,,,,,,,,,,
1405599880.218,,7.500000e+001,2.980050e+002,2.979968e+002,1,0,3.929888e+000,-3.762474e+000,-3.762475e+000,-1.229683e+000,-1.064803e+000,-3.557376e+000,-1.024585e+000,-8.597043e-001,-8.199384e-005,-8.199384e-005,,,,,,,,,,,,,,,,,,,,
1405600021.687,,1.000000e+002,2.979885e+002,2.979968e+002,1,0,1.408143e+000,-5.999939e-001,-5.999939e-001,7.269051e-001,7.805228e-001,-6.578777e-001,6.690212e-001,7.226389e-001,-2.615071e-005,-2.615071e-005,,,,,,,,,,,,,,,,,,,,
1405600039.421,,1.000000e+002,2.979968e+002,2.979968e+002,1,0,6.992390e-001,-1.719718e+000,-1.719718e+000,-3.546607e-001,-3.399162e-001,-1.823469e+000,-4.584118e-001,-4.436673e-001,-7.495384e-005,-7.495384e-005,,,,,,,,,,,,,,,,,,,,
1405600039.421,,1.000000e+002,2.979968e+002,2.979968e+002,1,0,3.862907e+000,-1.942961e+000,-1.942961e+000,-6.571552e-001,-5.631591e-001,-1.849264e+000,-5.634582e-001,-4.694622e-001,-8.468388e-005,-8.468388e-005,,,,,,,,,,,,,,,,,,,,
1405600057.656,,1.000000e+002,2.980050e+002,2.979968e+002,1,0,1.573439e+000,-3.360088e-001,-3.360088e-001,9.830294e-001,1.039735e+000,-3.448364e-001,9.742018e-001,1.030908e+000,-1.464493e-005,-1.464493e-005,,,,,,,,,,,,,,,,,,,,
1405600057.656,,1.000000e+002,2.980050e+002,2.979968e+002,1,0,2.255860e+000,-1.077303e-001,-1.077303e-001,1.148932e+000,1.268013e+000,-1.889303e-003,1.254773e+000,1.373855e+000,-4.695423e-006,-4.695423e-006,,,,,,,,,,,,,,,,,,,,