File: Sample Data Files/2014-07-16 EB on isolated PMN-PT no Ti spontaneous in situ/Ni-NiO_298K_SiO2_PMN-PT_5.0Tprebias_075V_Au_back.rso.raw
[Header]
TITLE,MPMS RSO Measurement
BYAPP,MPMS Measurement,2.1,Raw with ABS
FILEOPENTIME, 1405604427.546000 7/17/2014, 6:40:27 AM

INFO, APPNAME, MPMS MultiVu Application, Revision 1.58,  Build 076

INFO, NAME, EB in situ
INFO, WEIGHT, 0.000
INFO, AREA, 0.000
INFO, LENGTH, 0.000
INFO, SHAPE, 0
INFO, COMMENT,
INFO, SEQUENCE FILE: MHcurveUpTo100.seq


INFO, BACKGROUND DATA FILE:, None


STARTUPAXIS,X,8,LINEAR,AUTO,0.000000,0.000000
STARTUPAXIS,Y1,9,LINEAR,AUTO,0.000000,0.000000


STARTUPGROUP,Longitudinal
FIELDGROUP,Longitudinal,1,2,3,4,5,6,7,8,9,10,11,12,13,14,15,16,17,18,19,20,21,22
FIELDGROUP,Transverse,1,2,3,4,5,6,7,8,23,24,25,26,27,28,29,30,31,32,33,34,35,36

PLOT_APPEARANCE,ALL,HORZ_GRID_ON,VERT_GRID_ON,MARKERS_ONLY

[Data]
Time,Comment,Field (Oe),Start Temperature (K),End Temperature (K),Scan,Rejected,Position (cm),Long Voltage,Long Average Voltage,Long Detrended Voltage,Long Demeaned Voltage,Long Reg Fit,Long Detrended Fit,Long Demeaned Fit,Long Scaled Response,Long Avg. Scaled Response,Long Background Response,Long Response [w/ABS],Long Detrended Resp. [w/ABS],Long Fit [w/ABS],Long Detrended Fit [w/ABS],Trans Voltage,Trans Average Voltage,Trans Detrended Voltage,Trans Demeaned Voltage,Trans Reg Fit,Trans Detrended Fit,Trans Demeaned Fit,Trans Scaled Response,Trans Avg. Scaled Response,Trans Background Response,Trans Response [w/ABS],Trans Detrended Resp. [w/ABS],Trans Adjusted Fit,Trans Detrended Fit [w/ABS],
1405604427.531,,1.000000e+002,2.979968e+002,2.980050e+002,1,0,2.079547e+000,-2.197333e-002,-2.197333e-002,1.334209e+000,1.334209e+000,3.349891e-002,1.389681e+000,1.389681e+000,-9.577067e-007,-9.577067e-007,,,,,,,,,,,,,,,,,,,,
1405604427.531,,1.000000e+002,2.979968e+002,2.980050e+002,1,0,3.706004e+000,-1.902066e+000,-1.902066e+000,-6.211895e-001,-5.458839e-001,-1.889116e+000,-6.082393e-001,-5.329337e-001,-8.290148e-005,-8.290148e-005,,,,,,,,,,,,,,,,,,,,
1405604446.265,,1.000000e+002,2.980050e+002,2.979968e+002,1,0,4.362057e-001,-1.909238e+000,-1.909238e+000,-5.912511e-001,-5.513998e-001,-1.927819e+000,-6.098319e-001,-5.699806e-001,-8.321406e-005,-8.321406e-005,,,,,,,,,,,,,,,,,,,,
1405604465.000,,1.000000e+002,2.979885e+002,2.979968e+002,1,0,1.899852e+000,-3.799554e-002,-3.799554e-002,1.308823e+000,1.310650e+000,3.381412e-002,1.380633e+000,1.382459e+000,-1.656034e-006,-1.656034e-006,,,,,,,,,,,,,,,,,,,,
1405604465.000,,1.000000e+002,2.979885e+002,2.979968e+002,1,0,3.810216e+000,-1.900082e+000,-1.900082e+000,-6.318106e-001,-5.514373e-001,-1.843388e+000,-5.751161e-001,-4.947428e-001,-8.281502e-005,-8.281502e-005,,,,,,,,,,,,,,,,,,,,
1405604589.687,,7.500000e+001,2.979968e+002,2.979968e+002,1,0,5.564857e-001,-1.807153e+000,-1.807154e+000,-5.009764e-001,-4.637394e-001,-1.854845e+000,-5.486678e-001,-5.114307e-001,-7.876490e-005,-7.876490e-005,,,,,,,,,,,,,,,,,,,,
1405604607.687,,7.500000e+001,2.980050e+002,2.980050e+002,1,0,1.718702e+000,-2.017274e-001,-2.017273e-001,1.132126e+000,1.135412e+000,-1.686740e-001,1.165180e+000,1.168465e+000,-8.792299e-006,-8.792299e-006,,,,,,,,,,,,,,,,,,,,
1405604607.687,,7.500000e+001,2.980050e+002,2.980050e+002,1,0,3.893683e+000,-1.870479e+000,-1.870479e+000,-6.072637e-001,-5.333403e-001,-1.786453e+000,-5.232370e-001,-4.493136e-001,-8.152497e-005,-8.152497e-005,,,,,,,,,,,,,,,,,,,,
1405604624.921,,7.500000e+001,2.979968e+002,2.980050e+002,1,0,6.833497e-001,-1.656087e+000,-1.656087e+000,-3.839810e-001,-3.443748e-001,-1.723477e+000,-4.513707e-001,-4.117645e-001,-7.218065e-005,-7.218065e-005,,,,,,,,,,,,,,,,,,,,
1405604757.234,,5.000000e+001,2.980050e+002,2.980050e+002,1,0,1.538723e+000,-4.144414e-001,-4.144413e-001,8.500674e-001,8.544524e-001,-4.328745e-001,8.316343e-001,8.360192e-001,-1.806349e-005,-1.806349e-005,,,,,,,,,,,,,,,,,,,,
1405604757.234,,5.000000e+001,2.980050e+002,2.980050e+002,1,0,3.953542e+000,-1.769463e+000,-1.769463e+000,-5.678051e-001,-5.005695e-001,-1.670671e+000,-4.690132e-001,-4.017775e-001,-7.712233e-005,-7.712233e-005,,,,,,,,,,,,,,,,,,,,
1405604774.468,,5.000000e+001,2.979968e+002,2.980050e+002,1,0,8.160601e-001,-1.466720e+000,-1.466720e+000,-2.225942e-001,-1.852553e-001,-1.536781e+000,-2.926553e-001,-2.553164e-001,-6.392721e-005,-6.392721e-005,,,,,,,,,,,,,,,,,,,,
1405604792.718,,5.000000e+001,2.980050e+002,2.980050e+002,1,0,1.360799e+000,-6.817835e-001,-6.817835e-001,5.906230e-001,5.967053e-001,-7.428365e-001,5.295699e-001,5.356522e-001,-2.971564e-005,-2.971564e-005,,,,,,,,,,,,,,,,,,,,
1405604792.718,,5.000000e+001,2.980050e+002,2.980050e+002,1,0,3.987414e+000,-1.771447e+000,-1.771447e+000,-5.644250e-001,-4.929581e-001,-1.658065e+000,-4.510429e-001,-3.795760e-001,-7.720880e-005,-7.720880e-005,,,,,,,,,,,,,,,,,,,,
1405604904.640,,4.500000e+001,2.980050e+002,2.980050e+002,1,0,9.542817e-001,-1.263619e+000,-1.263619e+000,-3.822068e-002,-9.185076e-004,-1.338116e+000,-1.127175e-001,-7.541537e-002,-5.507506e-005,-5.507506e-005,,,,,,,,,,,,,,,,,,,,
1405604922.375,,4.500000e+001,2.979968e+002,2.979968e+002,1,0,1.186797e+000,-9.347820e-001,-9.347820e-001,3.154244e-001,3.227807e-001,-1.016030e+000,2.341763e-001,2.415326e-001,-4.074264e-005,-4.074264e-005,,,,,,,,,,,,,,,,,,,,
1405604922.375,,4.500000e+001,2.979968e+002,2.979968e+002,1,0,3.994329e+000,-1.741081e+000,-1.741081e+000,-5.541384e-001,-4.835184e-001,-1.628219e+000,-4.412765e-001,-3.706565e-001,-7.588533e-005,-7.588533e-005,,,,,,,,,,,,,,,,,,,,
1405604940.359,,4.500000e+001,2.980050e+002,2.979968e+002,1,0,1.098666e+000,-1.034577e+000,-1.034577e+000,1.779821e-001,2.180059e-001,-1.115578e+000,9.698161e-002,1.370054e-001,-4.509225e-005,-4.509225e-005,,,,,,,,,,,,,,,,,,,,
1405605060.125,,4.000000e+001,2.979968e+002,2.980050e+002,1,0,1.017992e+000,-1.178777e+000,-1.178777e+000,6.564268e-002,7.410514e-002,-1.268533e+000,-2.411322e-002,-1.565075e-002,-5.137725e-005,-5.137725e-005,,,,,,,,,,,,,,,,,,,,
1405605060.125,,4.000000e+001,2.979968e+002,2.980050e+002,1,0,3.974640e+000,-1.733146e+000,-1.733146e+000,-5.493737e-001,-4.802636e-001,-1.627789e+000,-4.440161e-001,-3.749059e-001,-7.553952e-005,-7.553952e-005,,,,,,,,,,,,,,,,,,,,
1405605077.875,,4.000000e+001,2.979968e+002,2.980050e+002,1,0,1.249832e+000,-7.892087e-001,-7.892087e-001,3.999763e-001,4.403111e-001,-8.617919e-001,3.273930e-001,3.677278e-001,-3.439782e-005,-3.439782e-005,,,,,,,,,,,,,,,,,,,,
1405605096.125,,4.000000e+001,2.980050e+002,2.980050e+002,1,0,8.549841e-001,-1.357463e+000,-1.357463e+000,-1.434639e-001,-1.333454e-001,-1.454183e+000,-2.401832e-001,-2.300646e-001,-5.916531e-005,-5.916531e-005,,,,,,,,,,,,,,,,,,,,
1405605096.125,,4.000000e+001,2.980050e+002,2.980050e+002,1,0,3.929878e+000,-1.711326e+000,-1.711325e+000,-5.594828e-001,-4.872074e-001,-1.618275e+000,-4.664322e-001,-3.941568e-001,-7.458846e-005,-7.458846e-005,,,,,,,,,,,,,,,,,,,,
1405605213.875,,3.500000e+001,2.979968e+002,2.979968e+002,1,0,1.408020e+000,-5.595569e-001,-5.595568e-001,6.188036e-001,6.581095e-001,-6.081396e-001,5.702209e-001,6.095268e-001,-2.438841e-005,-2.438841e-005,,,,,,,,,,,,,,,,,,,,
1405605230.625,,3.500000e+001,2.979968e+002,2.979968e+002,1,0,6.991716e-001,-1.505783e+000,-1.505783e+000,-3.220422e-001,-3.110657e-001,-1.582332e+000,-3.985907e-001,-3.876143e-001,-6.562989e-005,-6.562989e-005,,,,,,,,,,,,,,,,,,,,
1405605230.625,,3.500000e+001,2.979968e+002,2.979968e+002,1,0,3.862892e+000,-1.683401e+000,-1.683401e+000,-5.586585e-001,-4.886835e-001,-1.612030e+000,-4.872871e-001,-4.173120e-001,-7.337140e-005,-7.337140e-005,,,,,,,,,,,,,,,,,,,,
1405605248.390,,3.500000e+001,2.979968e+002,2.980050e+002,1,0,1.573395e+000,-3.048799e-001,-3.048799e-001,8.442239e-001,8.870988e-001,-3.149673e-001,8.341364e-001,8.770114e-001,-1.328826e-005,-1.328826e-005,,,,,,,,,,,,,,,,,,,,
1405605367.187,,3.000000e+001,2.979885e+002,2.979968e+002,1,0,5.522149e-001,-1.599017e+000,-1.599017e+000,-4.293281e-001,-4.173793e-001,-1.657197e+000,-4.875077e-001,-4.755589e-001,-6.969355e-005,-6.969355e-005,,,,,,,,,,,,,,,,,,,,
1405605367.187,,3.000000e+001,2.979885e+002,2.979968e+002,1,0,3.777210e+000,-1.662648e+000,-1.662648e+000,-5.500482e-001,-4.810104e-001,-1.618421e+000,-5.058206e-001,-4.367828e-001,-7.246693e-005,-7.246693e-005,,,,,,,,,,,,,,,,,,,,
1405605384.687,,3.000000e+001,2.979968e+002,2.979968e+002,1,0,1.745010e+000,-1.355022e-001,-1.355022e-001,9.977995e-001,1.040244e+000,-9.218594e-002,1.041116e+000,1.083560e+000,-5.905895e-006,-5.905895e-006,,,,,,,,,,,,,,,,,,,,
1405605402.484,,3.000000e+001,2.980050e+002,2.980050e+002,1,0,4.165956e-001,-1.647237e+000,-1.647237e+000,-4.942261e-001,-4.805660e-001,-1.678137e+000,-5.251268e-001,-5.114667e-001,-7.179521e-005,-7.179521e-005,,,,,,,,,,,,,,,,,,,,
1405605402.484,,3.000000e+001,2.980050e+002,2.980050e+002,1,0,3.676676e+000,-1.633351e+000,-1.633351e+000,-5.390785e-001,-4.666800e-001,-1.619404e+000,-5.251321e-001,-4.527336e-001,-7.118998e-005,-7.118998e-005,,,,,,,,,,,,,,,,,,,,
1405605521.281,,2.500000e+001,2.979968e+002,2.979968e+002,1,0,1.921514e+000,-3.418073e-002,-3.418073e-002,1.064286e+000,1.104884e+000,4.647820e-002,1.144945e+000,1.185543e+000,-1.489776e-006,-1.489776e-006,,,,,,,,,,,,,,,,,,,,
1405605539.015,,2.500000e+001,2.980050e+002,2.979968e+002,1,0,2.951092e-001,-1.619923e+000,-1.619923e+000,-5.033924e-001,-4.889327e-001,-1.617407e+000,-5.008770e-001,-4.864173e-001,-7.060475e-005,-7.060475e-005,,,,,,,,,,,,,,,,,,,,
1405605539.015,,2.500000e+001,2.980050e+002,2.979968e+002,1,0,3.564952e+000,-1.552782e+000,-1.552782e+000,-4.927759e-001,-4.217920e-001,-1.562131e+000,-5.021251e-001,-4.311413e-001,-6.767840e-005,-6.767840e-005,,,,,,,,,,,,,,,,,,,,
1405605556.781,,2.500000e+001,2.979968e+002,2.980132e+002,1,0,2.101180e+000,-2.090518e-002,-2.090518e-002,1.060041e+000,1.104239e+000,6.324611e-002,1.144192e+000,1.188391e+000,-9.111577e-007,-9.111577e-007,,,,,,,,,,,,,,,,,,,,
1405605674.859,,2.000000e+001,2.980050e+002,2.979968e+002,1,0,1.908047e-001,-1.561327e+000,-1.561327e+000,-4.848808e-001,-4.701970e-001,-1.527380e+000,-4.509337e-001,-4.362499e-001,-6.805087e-005,-6.805087e-005,,,,,,,,,,,,,,,,,,,,
1405605674.859,,2.000000e+001,2.980050e+002,2.979968e+002,1,0,3.444562e+000,-1.431318e+000,-1.431318e+000,-4.074890e-001,-3.401880e-001,-1.462338e+000,-4.385090e-001,-3.712081e-001,-6.238440e-005,-6.238440e-005,,,,,,,,,,,,,,,,,,,,
1405605692.218,,2.000000e+001,2.979968e+002,2.980050e+002,1,0,2.282064e+000,-1.258889e-001,-1.258889e-001,9.161018e-001,9.596907e-001,-8.180188e-002,9.601887e-001,1.003778e+000,-5.486901e-006,-5.486901e-006,,,,,,,,,,,,,,,,,,,,
1405605709.953,,2.000000e+001,2.980050e+002,2.980050e+002,1,0,1.072471e-001,-1.552477e+000,-1.552477e+000,-4.766431e-001,-4.600275e-001,-1.493967e+000,-4.181333e-001,-4.015176e-001,-6.766513e-005,-6.766513e-005,,,,,,,,,,,,,,,,,,,,
1405605709.953,,2.000000e+001,2.980050e+002,2.980050e+002,1,0,3.317626e+000,-1.328776e+000,-1.328776e+000,-3.079019e-001,-2.363268e-001,-1.375805e+000,-3.549316e-001,-2.833564e-001,-5.791507e-005,-5.791507e-005,,,,,,,,,,,,,,,,,,,,
1405605823.218,,1.500000e+001,2.980050e+002,2.980050e+002,1,0,2.462240e+000,-2.900784e-001,-2.900784e-001,7.103203e-001,7.515672e-001,-3.012937e-001,6.991050e-001,7.403519e-001,-1.264316e-005,-1.264316e-005,,,,,,,,,,,,,,,,,,,,
1405605840.734,,1.500000e+001,2.980050e+002,2.979968e+002,1,0,4.745172e-002,-1.457259e+000,-1.457259e+000,-4.418875e-001,-4.248185e-001,-1.384130e+000,-3.687587e-001,-3.516897e-001,-6.351506e-005,-6.351506e-005,,,,,,,,,,,,,,,,,,,,
1405605840.734,,1.500000e+001,2.980050e+002,2.979968e+002,1,0,3.185018e+000,-1.120029e+000,-1.120029e+000,-1.570843e-001,-8.758903e-002,-1.177956e+000,-2.150109e-001,-1.455156e-001,-4.881682e-005,-4.881682e-005,,,,,,,,,,,,,,,,,,,,
1405605858.484,,1.500000e+001,2.979968e+002,2.980050e+002,1,0,2.640013e+000,-4.705954e-001,-4.705954e-001,5.113692e-001,5.557302e-001,-5.261084e-001,4.558562e-001,5.002172e-001,-2.051104e-005,-2.051104e-005,,,,,,,,,,,,,,,,,,,,
1405605976.843,,1.000000e+001,2.980050e+002,2.979968e+002,1,0,1.361841e-002,-1.339000e+000,-1.339000e+000,-4.031415e-001,-3.864560e-001,-1.259263e+000,-3.234051e-001,-3.067197e-001,-5.836073e-005,-5.836073e-005,,,,,,,,,,,,,,,,,,,,
1405605976.843,,1.000000e+001,2.980050e+002,2.979968e+002,1,0,3.046833e+000,-8.777124e-001,-8.777123e-001,1.031422e-002,7.483131e-002,-9.416075e-001,-5.358100e-002,1.093608e-002,-3.825538e-005,-3.825538e-005,,,,,,,,,,,,,,,,,,,,
1405605995.328,,1.000000e+001,2.979968e+002,2.979968e+002,1,0,2.813837e+000,-6.146428e-001,-6.146428e-001,2.883762e-001,3.306607e-001,-6.899339e-001,2.130851e-001,2.553696e-001,-2.678940e-005,-2.678940e-005,,,,,,,,,,,,,,,,,,,,
1405606013.843,,1.000000e+001,2.979968e+002,2.979968e+002,1,0,6.652400e-003,-1.320841e+000,-1.320841e+000,-4.025670e-001,-3.840432e-001,-1.237398e+000,-3.191234e-001,-3.005997e-001,-5.756929e-005,-5.756929e-005,,,,,,,,,,,,,,,,,,,,
1405606013.843,,1.000000e+001,2.979968e+002,2.979968e+002,1,0,2.902393e+000,-6.932279e-001,-6.932279e-001,1.752636e-001,2.435699e-001,-7.605155e-001,1.079760e-001,1.762823e-001,-3.021456e-005,-3.021456e-005,,,,,,,,,,,,,,,,,,,,
1405606131.812,,5.000000e+000,2.979968e+002,2.979885e+002,1,0,2.982982e+000,-6.871243e-001,-6.871243e-001,1.022002e-001,1.398582e-001,-7.618145e-001,2.750994e-002,6.516802e-002,-2.994855e-005,-2.994855e-005,,,,,,,,,,,,,,,,,,,,
1405606149.390,,5.000000e+000,2.980050e+002,2.979968e+002,1,0,2.641521e-002,-1.143529e+000,-1.143529e+000,-3.523236e-001,-3.348075e-001,-1.068658e+000,-2.774534e-001,-2.599373e-001,-4.984108e-005,-4.984108e-005,,,,,,,,,,,,,,,,,,,,
1405606149.390,,5.000000e+000,2.980050e+002,2.979968e+002,1,0,2.751291e+000,-4.271065e-001,-4.271065e-001,3.197931e-001,3.816145e-001,-4.811317e-001,2.657679e-001,3.275894e-001,-1.861558e-005,-1.861558e-005,,,,,,,,,,,,,,,,,,,,
1405606167.640,,5.000000e+000,2.979968e+002,2.980050e+002,1,0,3.145983e+000,-8.085879e-001,-8.085879e-001,-5.110409e-002,-1.052231e-002,-8.765696e-001,-1.190858e-001,-7.850403e-002,-3.524258e-005,-3.524258e-005,,,,,,,,,,,,,,,,,,,,
1405606286.906,,0.000000e+000,2.979968e+002,2.979968e+002,1,0,7.109272e-002,-7.034516e-001,-7.034516e-001,-2.219447e-001,-2.085319e-001,-6.395573e-001,-1.580503e-001,-1.446376e-001,-3.066019e-005,-3.066019e-005,,,,,,,,,,,,,,,,,,,,
1405606286.906,,0.000000e+000,2.979968e+002,2.979968e+002,1,0,2.592962e+000,-1.228370e-001,-1.228370e-001,3.266284e-001,3.720827e-001,-1.334506e-001,3.160148e-001,3.614691e-001,-5.353895e-006,-5.353895e-006,,,,,,,,,,,,,,,,,,,,
1405606304.140,,0.000000e+000,2.979968e+002,2.979968e+002,1,0,3.301888e+000,-4.756310e-001,-4.756310e-001,-5.093316e-002,-2.090016e-002,-5.232570e-001,-9.855922e-002,-6.852621e-002,-2.073055e-005,-2.073055e-005,,,,,,,,,,,,,,,,,,,,
1405606321.875,,0.000000e+000,2.980050e+002,2.979968e+002,1,0,1.381574e-001,-6.215094e-001,-6.215094e-001,-2.066807e-001,-1.926550e-001,-5.697037e-001,-1.548750e-001,-1.408492e-001,-2.708871e-005,-2.708871e-005,,,,,,,,,,,,,,,,,,,,
1405606321.875,,0.000000e+000,2.980050e+002,2.979968e+002,1,0,2.427703e+000,-2.166814e-002,-2.166814e-002,3.614180e-001,4.071863e-001,5.601535e-003,3.886877e-001,4.344560e-001,-9.444138e-007,-9.444138e-007,,,,,,,,,,,,,,,,,,,,
1405606457.703,,-5.000000e+000,2.980050e+002,2.979968e+002,1,0,3.448748e+000,6.755272e-001,6.755272e-001,2.600518e-001,3.291094e-001,5.898822e-001,1.744068e-001,2.434644e-001,1.472154e-005,1.472154e-005,,,,,,,,,,,,,,,,,,,,
1405606474.953,,-5.000000e+000,2.980050e+002,2.979968e+002,1,0,2.237955e-001,6.022828e-001,6.022828e-001,1.408616e-001,1.756268e-001,6.504114e-001,1.889903e-001,2.237554e-001,1.312535e-005,1.312535e-005,,,,,,,,,,,,,,,,,,,,
1405606474.953,,-5.000000e+000,2.980050e+002,2.979968e+002,1,0,2.256086e+000,1.399274e-001,1.399274e-001,-3.962389e-001,-2.867286e-001,2.602665e-001,-2.758999e-001,-1.663895e-001,3.049391e-006,3.049391e-006,,,,,,,,,,,,,,,,,,,,
1405606492.203,,-5.000000e+000,2.979968e+002,2.980050e+002,1,0,3.584362e+000,7.538072e-001,7.538072e-001,2.259245e-001,2.994939e-001,7.212292e-001,1.933465e-001,2.669159e-001,1.642747e-005,1.642747e-005,,,,,,,,,,,,,,,,,,,,
1405606616.859,,-1.000000e+001,2.980050e+002,2.979968e+002,1,0,3.242780e-001,1.750847e+000,1.750847e+000,5.215956e-001,5.442877e-001,1.768326e+000,5.390750e-001,5.617671e-001,3.815561e-005,3.815561e-005,,,,,,,,,,,,,,,,,,,,
1405606634.843,,-1.000000e+001,2.980050e+002,2.979968e+002,1,0,2.079523e+000,2.731407e-002,2.731407e-002,-1.258857e+000,-1.258857e+000,6.341873e-002,-1.222753e+000,-1.222753e+000,5.952462e-007,5.952462e-007,,,,,,,,,,,,,,,,,,,,
1405606634.843,,-1.000000e+001,2.980050e+002,2.979968e+002,1,0,3.705984e+000,1.863155e+000,1.863155e+000,5.278069e-001,5.769837e-001,1.870765e+000,5.354166e-001,5.845934e-001,4.060311e-005,4.060311e-005,,,,,,,,,,,,,,,,,,,,
1405606653.078,,-1.000000e+001,2.979968e+002,2.979968e+002,1,0,4.361361e-001,1.861324e+000,1.861324e+000,5.559533e-001,5.812062e-001,1.854426e+000,5.490556e-001,5.743085e-001,4.056320e-005,4.056320e-005,,,,,,,,,,,,,,,,,,,,
1405606772.656,,-1.500000e+001,2.979968e+002,2.979968e+002,1,0,1.899688e+000,-1.709037e-002,-1.709037e-002,-1.602993e+000,-1.602348e+000,-9.979539e-003,-1.595882e+000,-1.595237e+000,-3.724444e-007,-3.724444e-007,,,,,,,,,,,,,,,,,,,,
1405606772.656,,-1.500000e+001,2.979968e+002,2.979968e+002,1,0,3.810166e+000,2.230445e+000,2.230445e+000,6.168022e-001,6.451876e-001,2.259757e+000,6.461143e-001,6.744998e-001,4.860732e-005,4.860732e-005,,,,,,,,,,,,,,,,,,,,
1405606791.156,,-1.500000e+001,2.979968e+002,2.979885e+002,1,0,5.563844e-001,2.288125e+000,2.288125e+000,6.658962e-001,6.837089e-001,2.253402e+000,6.311734e-001,6.489861e-001,4.986432e-005,4.986432e-005,,,,,,,,,,,,,,,,,,,,
1405606809.390,,-1.500000e+001,2.979885e+002,2.979968e+002,1,0,1.718835e+000,2.258370e-001,2.258370e-001,-1.414764e+000,-1.413130e+000,2.140480e-001,-1.426553e+000,-1.424919e+000,4.921586e-006,4.921586e-006,,,,,,,,,,,,,,,,,,,,
1405606809.390,,-1.500000e+001,2.979885e+002,2.979968e+002,1,0,3.893694e+000,2.228004e+000,2.228004e+000,5.522765e-001,5.890369e-001,2.283812e+000,6.080850e-001,6.448455e-001,4.855411e-005,4.855411e-005,,,,,,,,,,,,,,,,,,,,
1405606929.234,,-2.000000e+001,2.980050e+002,2.979968e+002,1,0,6.833704e-001,2.399976e+000,2.399976e+000,6.321335e-001,6.438828e-001,2.346633e+000,5.787914e-001,5.905406e-001,5.230181e-005,5.230181e-005,,,,,,,,,,,,,,,,,,,,
1405606946.468,,-2.000000e+001,2.979968e+002,2.979968e+002,1,0,1.538527e+000,6.302072e-001,6.302072e-001,-1.162033e+000,-1.160244e+000,6.124002e-001,-1.179840e+000,-1.178051e+000,1.373388e-005,1.373388e-005,,,,,,,,,,,,,,,,,,,,
1405606946.468,,-2.000000e+001,2.979968e+002,2.979968e+002,1,0,3.953510e+000,2.402417e+000,2.402417e+000,5.845438e-001,6.119658e-001,2.459244e+000,6.413711e-001,6.687931e-001,5.235502e-005,5.235502e-005,,,,,,,,,,,,,,,,,,,,
1405606964.203,,-2.000000e+001,2.979968e+002,2.979968e+002,1,0,8.159149e-001,2.296976e+000,2.296976e+000,4.520968e-001,4.664366e-001,2.234710e+000,3.898314e-001,4.041712e-001,5.005717e-005,5.005717e-005,,,,,,,,,,,,,,,,,,,,
1405607081.984,,-2.500000e+001,2.979968e+002,2.979968e+002,1,0,1.361112e+000,1.202582e+000,1.202582e+000,-7.627847e-001,-7.613859e-001,1.167433e+000,-7.979332e-001,-7.965344e-001,2.620742e-005,2.620742e-005,,,,,,,,,,,,,,,,,,,,
1405607081.984,,-2.500000e+001,2.979968e+002,2.979968e+002,1,0,3.987507e+000,2.625202e+000,2.625202e+000,6.447986e-001,6.612344e-001,2.673213e+000,6.928099e-001,7.092457e-001,5.721006e-005,5.721006e-005,,,,,,,,,,,,,,,,,,,,
1405607099.296,,-2.500000e+001,2.979968e+002,2.979968e+002,1,0,9.541745e-001,2.266152e+000,2.266152e+000,2.452840e-001,2.531438e-001,2.207099e+000,1.862310e-001,1.940908e-001,4.938541e-005,4.938541e-005,,,,,,,,,,,,,,,,,,,,
1405607116.843,,-2.500000e+001,2.980050e+002,2.979968e+002,1,0,1.187110e+000,1.726737e+000,1.726737e+000,-2.979600e-001,-2.960968e-001,1.669689e+000,-3.550083e-001,-3.531451e-001,3.763015e-005,3.763015e-005,,,,,,,,,,,,,,,,,,,,
1405607116.843,,-2.500000e+001,2.980050e+002,2.979968e+002,1,0,3.994427e+000,2.687307e+000,2.687307e+000,6.465868e-001,6.644733e-001,2.738226e+000,6.975052e-001,7.153916e-001,5.856350e-005,5.856350e-005,,,,,,,,,,,,,,,,,,,,
1405607228.609,,-3.000000e+001,2.980050e+002,2.980050e+002,1,0,1.098593e+000,2.023225e+000,2.023225e+000,-9.668246e-002,-9.218669e-002,1.989004e+000,-1.309034e-001,-1.264076e-001,4.409137e-005,4.409137e-005,,,,,,,,,,,,,,,,,,,,
1405607246.718,,-3.000000e+001,2.980050e+002,2.979968e+002,1,0,1.018132e+000,2.242500e+000,2.242500e+000,1.208524e-001,1.225505e-001,2.185192e+000,6.354415e-002,6.524229e-002,4.886996e-005,4.886996e-005,,,,,,,,,,,,,,,,,,,,
1405607246.718,,-3.000000e+001,2.980050e+002,2.979968e+002,1,0,3.974692e+000,2.838832e+000,2.838832e+000,7.050140e-001,7.188821e-001,2.884306e+000,7.504880e-001,7.643561e-001,6.186558e-005,6.186558e-005,,,,,,,,,,,,,,,,,,,,
1405607264.453,,-3.000000e+001,2.979968e+002,2.980050e+002,1,0,1.249718e+000,1.624195e+000,1.624195e+000,-5.160809e-001,-5.075419e-001,1.620278e+000,-5.199981e-001,-5.114591e-001,3.539547e-005,3.539547e-005,,,,,,,,,,,,,,,,,,,,
1405607383.375,,-3.500000e+001,2.979968e+002,2.979968e+002,1,0,8.549660e-001,2.627644e+000,2.627644e+000,4.767170e-001,4.767139e-001,2.588361e+000,4.374342e-001,4.374311e-001,5.726322e-005,5.726322e-005,,,,,,,,,,,,,,,,,,,,
1405607383.375,,-3.500000e+001,2.979968e+002,2.979968e+002,1,0,3.929865e+000,2.927183e+000,2.927183e+000,7.762752e-001,7.762532e-001,2.958434e+000,8.075261e-001,8.075042e-001,6.379095e-005,6.379095e-005,,,,,,,,,,,,,,,,,,,,
1405607400.875,,-3.500000e+001,2.980050e+002,2.979968e+002,1,0,1.408031e+000,1.173131e+000,1.173131e+000,-9.978550e-001,-9.923449e-001,1.208189e+000,-9.627976e-001,-9.572874e-001,2.556560e-005,2.556560e-005,,,,,,,,,,,,,,,,,,,,
1405607418.796,,-3.500000e+001,2.979968e+002,2.979885e+002,1,0,6.993255e-001,2.967315e+000,2.967315e+000,7.516289e-001,7.528851e-001,2.929677e+000,7.139917e-001,7.152479e-001,6.466553e-005,6.466553e-005,,,,,,,,,,,,,,,,,,,,
1405607418.796,,-3.500000e+001,2.979968e+002,2.979885e+002,1,0,3.862955e+000,3.057192e+000,3.057192e+000,8.347539e-001,8.427620e-001,3.082360e+000,8.599221e-001,8.679302e-001,6.662419e-005,6.662419e-005,,,,,,,,,,,,,,,,,,,,
1405607538.718,,-4.000000e+001,2.980132e+002,2.980050e+002,1,0,1.573268e+000,7.090976e-001,7.090976e-001,-1.496533e+000,-1.495102e+000,7.627999e-001,-1.442831e+000,-1.441400e+000,1.545308e-005,1.545308e-005,,,,,,,,,,,,,,,,,,,,
1405607557.203,,-4.000000e+001,2.979968e+002,2.980050e+002,1,0,5.524772e-001,3.110752e+000,3.110752e+000,9.129557e-001,9.137914e-001,3.097210e+000,8.994140e-001,9.002497e-001,6.779137e-005,6.779137e-005,,,,,,,,,,,,,,,,,,,,
1405607557.203,,-4.000000e+001,2.979968e+002,2.980050e+002,1,0,3.777286e+000,3.125706e+000,3.125706e+000,9.239169e-001,9.287455e-001,3.130899e+000,9.291101e-001,9.339387e-001,6.811726e-005,6.811726e-005,,,,,,,,,,,,,,,,,,,,
1405607574.500,,-4.000000e+001,2.979968e+002,2.980050e+002,1,0,1.744852e+000,2.972503e-001,2.972503e-001,-1.908242e+000,-1.905036e+000,3.309028e-001,-1.874590e+000,-1.871383e+000,6.477857e-006,6.477857e-006,,,,,,,,,,,,,,,,,,,,
1405607693.250,,-4.500000e+001,2.979968e+002,2.979968e+002,1,0,4.168209e-001,3.202765e+000,3.202765e+000,9.722778e-001,9.725637e-001,3.204243e+000,9.737562e-001,9.740422e-001,6.979654e-005,6.979654e-005,,,,,,,,,,,,,,,,,,,,
1405607693.250,,-4.500000e+001,2.979968e+002,2.979968e+002,1,0,3.676878e+000,3.206885e+000,3.206885e+000,9.751680e-001,9.766836e-001,3.205428e+000,9.737108e-001,9.752264e-001,6.988633e-005,6.988633e-005,,,,,,,,,,,,,,,,,,,,
1405607711.031,,-4.500000e+001,2.980050e+002,2.979968e+002,1,0,1.921370e+000,1.034577e-001,1.034577e-001,-2.169764e+000,-2.168347e+000,9.115639e-002,-2.182065e+000,-2.180649e+000,2.254612e-006,2.254612e-006,,,,,,,,,,,,,,,,,,,,
1405607728.781,,-4.500000e+001,2.979968e+002,2.979968e+002,1,0,2.950509e-001,3.211158e+000,3.211158e+000,9.441753e-001,9.449790e-001,3.222769e+000,9.557868e-001,9.565904e-001,6.997944e-005,6.997944e-005,,,,,,,,,,,,,,,,,,,,
1405607728.781,,-4.500000e+001,2.979968e+002,2.979968e+002,1,0,3.564957e+000,3.241066e+000,3.241066e+000,9.709418e-001,9.748871e-001,3.228178e+000,9.580539e-001,9.619992e-001,7.063122e-005,7.063122e-005,,,,,,,,,,,,,,,,,,,,
1405607848.531,,-5.000000e+001,2.979885e+002,2.980050e+002,1,0,2.101215e+000,1.327555e-001,1.327555e-001,-2.183622e+000,-2.181277e+000,8.866685e-002,-2.227710e+000,-2.225366e+000,2.893085e-006,2.893085e-006,,,,,,,,,,,,,,,,,,,,
1405607866.328,,-5.000000e+001,2.979968e+002,2.980050e+002,1,0,1.908111e-001,3.197730e+000,3.197729e+000,8.836122e-001,8.846076e-001,3.220825e+000,9.067076e-001,9.077029e-001,6.968678e-005,6.968678e-005,,,,,,,,,,,,,,,,,,,,
1405607866.328,,-5.000000e+001,2.979968e+002,2.980050e+002,1,0,3.444594e+000,3.216346e+000,3.216346e+000,8.986621e-001,9.032240e-001,3.196692e+000,8.790083e-001,8.835702e-001,7.009247e-005,7.009247e-005,,,,,,,,,,,,,,,,,,,,
1405607884.562,,-5.000000e+001,2.979968e+002,2.979885e+002,1,0,2.282190e+000,4.062014e-001,4.062014e-001,-1.924516e+000,-1.919233e+000,3.694767e-001,-1.961241e+000,-1.955957e+000,8.852176e-006,8.852176e-006,,,,,,,,,,,,,,,,,,,,
1405608027.171,,-7.500000e+001,2.979968e+002,2.979968e+002,1,0,1.073390e-001,1.928312e+000,1.928312e+000,4.340424e-001,4.493349e-001,1.931147e+000,4.368768e-001,4.521693e-001,8.404560e-005,8.404560e-005,,,,,,,,,,,,,,,,,,,,
1405608027.171,,-7.500000e+001,2.979968e+002,2.979968e+002,1,0,3.317777e+000,1.915036e+000,1.915036e+000,3.701840e-001,4.360592e-001,1.910441e+000,3.655888e-001,4.314641e-001,8.346698e-005,8.346698e-005,,,,,,,,,,,,,,,,,,,,
1405608045.406,,-7.500000e+001,2.979968e+002,2.979968e+002,1,0,2.462111e+000,7.702872e-001,7.702872e-001,-7.798561e-001,-7.325431e-001,7.601328e-001,-7.900104e-001,-7.426974e-001,3.357301e-005,3.357301e-005,,,,,,,,,,,,,,,,,,,,
1405608063.156,,-7.500000e+001,2.979968e+002,2.980050e+002,1,0,4.751282e-002,1.908322e+000,1.908322e+000,4.054160e-001,4.233031e-001,1.911742e+000,4.088357e-001,4.267229e-001,8.317435e-005,8.317435e-005,,,,,,,,,,,,,,,,,,,,
1405608063.156,,-7.500000e+001,2.979968e+002,2.980050e+002,1,0,3.185178e+000,1.794794e+000,1.794793e+000,2.369479e-001,3.097742e-001,1.790918e+000,2.330728e-001,3.058990e-001,7.822618e-005,7.822618e-005,,,,,,,,,,,,,,,,,,,,
1405608194.031,,-1.000000e+002,2.980050e+002,2.979968e+002,1,0,2.639974e+000,1.879177e+000,1.879177e+000,-5.466316e-001,-3.984352e-001,1.895150e+000,-5.306588e-001,-3.824624e-001,8.190387e-005,8.190387e-005,,,,,,,,,,,,,,,,,,,,
1405608211.765,,-1.000000e+002,2.979968e+002,2.979968e+002,1,0,1.357112e-002,2.994476e+000,2.994476e+000,4.163184e-001,5.118430e-001,2.981516e+000,4.033583e-001,4.988828e-001,1.305141e-004,1.305141e-004,,,,,,,,,,,,,,,,,,,,
1405608211.765,,-1.000000e+002,2.979968e+002,2.979968e+002,1,0,3.046863e+000,2.901089e+000,2.901089e+000,4.909484e-002,4.184563e-001,2.920194e+000,6.819932e-002,4.375608e-001,1.264439e-004,1.264439e-004,,,,,,,,,,,,,,,,,,,,
1405608229.250,,-1.000000e+002,2.979968e+002,2.979968e+002,1,0,2.813790e+000,2.751396e+000,2.751396e+000,-2.753171e-001,-5.321050e-002,2.762909e+000,-2.638041e-001,-4.169750e-002,1.199195e-004,1.199195e-004,,,,,,,,,,,,,,,,,,,,
1405608363.062,,-7.500000e+001,2.979968e+002,2.979968e+002,1,0,6.652776e-003,1.590777e+000,1.590777e+000,3.912801e-001,3.878791e-001,1.591786e+000,3.922890e-001,3.888880e-001,6.933413e-005,6.933413e-005,,,,,,,,,,,,,,,,,,,,
1405608363.062,,-7.500000e+001,2.979968e+002,2.979968e+002,1,0,2.902531e+000,1.035798e+000,1.035798e+000,-1.545589e-001,-1.671000e-001,1.059490e+000,-1.308669e-001,-1.434079e-001,4.514533e-005,4.514533e-005,,,,,,,,,,,,,,,,,,,,
1405608380.828,,-7.500000e+001,2.979968e+002,2.979968e+002,1,0,2.982867e+000,1.174047e+000,1.174047e+000,-2.282550e-002,-3.155828e-002,1.178475e+000,-1.839771e-002,-2.713048e-002,5.117091e-005,5.117091e-005,,,,,,,,,,,,,,,,,,,,
1405608399.140,,-7.500000e+001,2.980050e+002,2.980050e+002,1,0,2.640740e-002,1.619312e+000,1.619312e+000,4.002583e-001,3.976927e-001,1.621100e+000,4.020463e-001,3.994807e-001,7.057782e-005,7.057782e-005,,,,,,,,,,,,,,,,,,,,
1405608399.140,,-7.500000e+001,2.980050e+002,2.980050e+002,1,0,2.751383e+000,8.281198e-001,8.281198e-001,-3.844447e-001,-3.934997e-001,8.591490e-001,-3.534155e-001,-3.624705e-001,3.609365e-005,3.609365e-005,,,,,,,,,,,,,,,,,,,,
1405608529.953,,-5.000000e+001,2.979968e+002,2.980050e+002,1,0,3.145861e+000,1.325877e+000,1.325877e+000,1.941461e-001,1.827992e-001,1.314803e+000,1.830729e-001,1.717260e-001,5.778855e-005,5.778855e-005,,,,,,,,,,,,,,,,,,,,
1405608548.234,,-5.000000e+001,2.979968e+002,2.979968e+002,1,0,7.117647e-002,1.541795e+000,1.541795e+000,4.007920e-001,3.973657e-001,1.552140e+000,4.111370e-001,4.077107e-001,6.719938e-005,6.719938e-005,,,,,,,,,,,,,,,,,,,,
1405608548.234,,-5.000000e+001,2.979968e+002,2.979968e+002,1,0,2.593162e+000,5.229347e-001,5.229347e-001,-6.098833e-001,-6.214948e-001,5.508333e-001,-5.819846e-001,-5.935961e-001,2.279219e-005,2.279219e-005,,,,,,,,,,,,,,,,,,,,
1405608566.484,,-5.000000e+001,2.979968e+002,2.979968e+002,1,0,3.301713e+000,1.484115e+000,1.484115e+000,3.550743e-001,3.469418e-001,1.472164e+000,3.431228e-001,3.349903e-001,6.468540e-005,6.468540e-005,,,,,,,,,,,,,,,,,,,,
1405608686.968,,-4.500000e+001,2.979968e+002,2.979968e+002,1,0,1.380477e-001,1.555529e+000,1.555528e+000,4.304573e-001,4.258610e-001,1.561931e+000,4.368600e-001,4.322637e-001,6.779799e-005,6.779799e-005,,,,,,,,,,,,,,,,,,,,
1405608686.968,,-4.500000e+001,2.979968e+002,2.979968e+002,1,0,2.427755e+000,2.743614e-001,2.743614e-001,-8.403077e-001,-8.553060e-001,2.958080e-001,-8.188611e-001,-8.338594e-001,1.195809e-005,1.195809e-005,,,,,,,,,,,,,,,,,,,,
1405608705.750,,-4.500000e+001,2.979968e+002,2.979968e+002,1,0,3.448650e+000,1.590167e+000,1.590167e+000,4.521723e-001,4.431343e-001,1.582879e+000,4.448846e-001,4.358466e-001,6.930772e-005,6.930772e-005,,,,,,,,,,,,,,,,,,,,
1405608724.000,,-4.500000e+001,2.979968e+002,2.979968e+002,1,0,2.237510e-001,1.619160e+000,1.619160e+000,4.708533e-001,4.675908e-001,1.617578e+000,4.692713e-001,4.660088e-001,7.057136e-005,7.057136e-005,,,,,,,,,,,,,,,,,,,,
1405608724.000,,-4.500000e+001,2.979968e+002,2.979968e+002,1,0,2.256275e+000,1.158177e-001,1.158177e-001,-1.025474e+000,-1.035751e+000,1.155423e-001,-1.025749e+000,-1.036026e+000,5.047938e-006,5.047938e-006,,,,,,,,,,,,,,,,,,,,
1405608843.000,,-4.000000e+001,2.979968e+002,2.979885e+002,1,0,3.584330e+000,1.591540e+000,1.591540e+000,4.895485e-001,4.801328e-001,1.590966e+000,4.889740e-001,4.795583e-001,6.936760e-005,6.936760e-005,,,,,,,,,,,,,,,,,,,,
1405608860.750,,-4.000000e+001,2.980050e+002,2.979968e+002,1,0,3.241996e-001,1.612903e+000,1.612903e+000,4.909635e-001,4.864112e-001,1.611578e+000,4.896381e-001,4.850858e-001,7.029871e-005,7.029871e-005,,,,,,,,,,,,,,,,,,,,
1405608878.234,,-4.000000e+001,2.980050e+002,2.979968e+002,1,0,2.079669e+000,-3.051851e-004,-3.051851e-004,-1.121750e+000,-1.121750e+000,-5.302310e-003,-1.126747e+000,-1.126747e+000,-1.330155e-008,-1.330155e-008,,,,,,,,,,,,,,,,,,,,
1405608878.234,,-4.000000e+001,2.980050e+002,2.979968e+002,1,0,3.705866e+000,1.605121e+000,1.605121e+000,4.903318e-001,4.836761e-001,1.607979e+000,4.931895e-001,4.865338e-001,6.995953e-005,6.995953e-005,,,,,,,,,,,,,,,,,,,,
1405608997.984,,-3.500000e+001,2.980050e+002,2.979885e+002,1,0,4.360510e-001,1.591998e+000,1.591998e+000,4.907717e-001,4.855453e-001,1.589938e+000,4.887115e-001,4.834851e-001,6.938759e-005,6.938759e-005,,,,,,,,,,,,,,,,,,,,
1405609015.718,,-3.500000e+001,2.980050e+002,2.979968e+002,1,0,1.900033e+000,3.723258e-002,3.723258e-002,-1.071991e+000,-1.072172e+000,2.746259e-002,-1.081761e+000,-1.081942e+000,1.622790e-006,1.622790e-006,,,,,,,,,,,,,,,,,,,,
1405609015.718,,-3.500000e+001,2.980050e+002,2.979968e+002,1,0,3.810150e+000,1.566057e+000,1.566057e+000,4.646480e-001,4.566523e-001,1.568423e+000,4.670138e-001,4.590181e-001,6.825696e-005,6.825696e-005,,,,,,,,,,,,,,,,,,,,
1405609034.453,,-3.500000e+001,2.979968e+002,2.979968e+002,1,0,5.564092e-001,1.565600e+000,1.565600e+000,4.672475e-001,4.635684e-001,1.558512e+000,4.601600e-001,4.564810e-001,6.823700e-005,6.823700e-005,,,,,,,,,,,,,,,,,,,,
1405609160.234,,-3.000000e+001,2.979968e+002,2.980050e+002,1,0,1.718843e+000,1.857051e-001,1.857051e-001,-9.009479e-001,-9.013796e-001,1.838674e-001,-9.027856e-001,-9.032173e-001,8.094004e-006,8.094004e-006,,,,,,,,,,,,,,,,,,,,
1405609160.234,,-3.000000e+001,2.979968e+002,2.980050e+002,1,0,3.893749e+000,1.506394e+000,1.506394e+000,4.290234e-001,4.193089e-001,1.510313e+000,4.329428e-001,4.232283e-001,6.565653e-005,6.565653e-005,,,,,,,,,,,,,,,,,,,,
1405609177.968,,-3.000000e+001,2.979968e+002,2.979968e+002,1,0,6.833294e-001,1.488693e+000,1.488693e+000,3.999982e-001,3.966018e-001,1.474310e+000,3.856155e-001,3.822191e-001,6.488504e-005,6.488504e-005,,,,,,,,,,,,,,,,,,,,
1405609195.718,,-3.000000e+001,2.979968e+002,2.979885e+002,1,0,1.538540e+000,4.297006e-001,4.297006e-001,-6.666432e-001,-6.670442e-001,4.326108e-001,-6.637330e-001,-6.641340e-001,1.872861e-005,1.872861e-005,,,,,,,,,,,,,,,,,,,,
1405609195.718,,-3.000000e+001,2.979968e+002,2.979885e+002,1,0,3.953544e+000,1.496170e+000,1.496170e+000,4.055736e-001,3.994251e-001,1.499390e+000,4.087938e-001,4.026453e-001,6.521093e-005,6.521093e-005,,,,,,,,,,,,,,,,,,,,
1405609315.562,,-2.500000e+001,2.980050e+002,2.979968e+002,1,0,8.159298e-001,1.370434e+000,1.370434e+000,2.911213e-001,2.871891e-001,1.351177e+000,2.718643e-001,2.679322e-001,5.973071e-005,5.973071e-005,,,,,,,,,,,,,,,,,,,,
1405609333.343,,-2.500000e+001,2.979968e+002,2.980050e+002,1,0,1.360763e+000,6.842250e-001,6.842250e-001,-3.926619e-001,-3.931614e-001,6.770923e-001,-3.997945e-001,-4.002941e-001,2.982213e-005,2.982213e-005,,,,,,,,,,,,,,,,,,,,
1405609333.343,,-2.500000e+001,2.979968e+002,2.980050e+002,1,0,3.987436e+000,1.453597e+000,1.453597e+000,3.820798e-001,3.762102e-001,1.460047e+000,3.885301e-001,3.826605e-001,6.335539e-005,6.335539e-005,,,,,,,,,,,,,,,,,,,,
1405609351.593,,-2.500000e+001,2.979968e+002,2.979968e+002,1,0,9.542428e-001,1.231422e+000,1.231422e+000,1.468912e-001,1.445149e-001,1.211460e+000,1.269292e-001,1.245530e-001,5.367184e-005,5.367184e-005,,,,,,,,,,,,,,,,,,,,
1405609469.906,,-2.000000e+001,2.979968e+002,2.979968e+002,1,0,1.186802e+000,9.202856e-001,9.202856e-001,-1.397647e-001,-1.404464e-001,9.031904e-001,-1.568599e-001,-1.575416e-001,4.011091e-005,4.011091e-005,,,,,,,,,,,,,,,,,,,,
1405609469.906,,-2.000000e+001,2.979968e+002,2.979968e+002,1,0,3.994372e+000,1.424604e+000,1.424604e+000,3.704157e-001,3.638721e-001,1.433656e+000,3.794677e-001,3.729241e-001,6.209177e-005,6.209177e-005,,,,,,,,,,,,,,,,,,,,
1405609487.140,,-2.000000e+001,2.980050e+002,2.979968e+002,1,0,1.098681e+000,1.028016e+000,1.028016e+000,-3.074425e-002,-3.358316e-002,1.014071e+000,-4.468923e-002,-4.752815e-002,4.480637e-005,4.480637e-005,,,,,,,,,,,,,,,,,,,,
1405609505.375,,-2.000000e+001,2.979968e+002,2.979968e+002,1,0,1.018037e+000,1.132694e+000,1.132694e+000,7.420893e-002,7.375526e-002,1.111766e+000,5.328090e-002,5.282724e-002,4.936881e-005,4.936881e-005,,,,,,,,,,,,,,,,,,,,
1405609505.375,,-2.000000e+001,2.979968e+002,2.979968e+002,1,0,3.974672e+000,1.431471e+000,1.431471e+000,3.762363e-001,3.725314e-001,1.442872e+000,3.876374e-001,3.839325e-001,6.239105e-005,6.239105e-005,,,,,,,,,,,,,,,,,,,,
1405609615.921,,-1.500000e+001,2.980050e+002,2.980050e+002,1,0,1.249772e+000,7.922605e-001,7.922605e-001,-2.341926e-001,-2.374182e-001,7.929295e-001,-2.335236e-001,-2.367492e-001,3.453092e-005,3.453092e-005,,,,,,,,,,,,,,,,,,,,
1405609633.187,,-1.500000e+001,2.980050e+002,2.979968e+002,1,0,8.549464e-001,1.290323e+000,1.290323e+000,2.448402e-001,2.443042e-001,1.272944e+000,2.274614e-001,2.269254e-001,5.623910e-005,5.623910e-005,,,,,,,,,,,,,,,,,,,,
1405609633.187,,-1.500000e+001,2.980050e+002,2.979968e+002,1,0,3.929862e+000,1.427045e+000,1.427045e+000,3.848556e-001,3.810271e-001,1.440634e+000,3.984446e-001,3.946161e-001,6.219821e-005,6.219821e-005,,,,,,,,,,,,,,,,,,,,
1405609650.453,,-1.500000e+001,2.980050e+002,2.980050e+002,1,0,1.408067e+000,5.825983e-001,5.825983e-001,-4.639013e-001,-4.643139e-001,6.000213e-001,-4.464783e-001,-4.468909e-001,2.539273e-005,2.539273e-005,,,,,,,,,,,,,,,,,,,,
1405609768.203,,-1.000000e+001,2.979968e+002,2.980050e+002,1,0,6.990123e-001,1.369671e+000,1.369671e+000,3.682378e-001,3.677182e-001,1.351374e+000,3.499414e-001,3.494219e-001,5.969754e-005,5.969754e-005,,,,,,,,,,,,,,,,,,,,
1405609768.203,,-1.000000e+001,2.979968e+002,2.980050e+002,1,0,3.862855e+000,1.399732e+000,1.399731e+000,4.010912e-001,3.977789e-001,1.411404e+000,4.127635e-001,4.094512e-001,6.100775e-005,6.100775e-005,,,,,,,,,,,,,,,,,,,,
1405609786.437,,-1.000000e+001,2.980050e+002,2.979968e+002,1,0,1.573367e+000,3.317362e-001,3.317362e-001,-6.790557e-001,-6.802727e-001,3.584039e-001,-6.523880e-001,-6.536050e-001,1.445883e-005,1.445883e-005,,,,,,,,,,,,,,,,,,,,
1405609804.687,,-1.000000e+001,2.979968e+002,2.979968e+002,1,0,5.521338e-001,1.462294e+000,1.462294e+000,4.348180e-001,4.344910e-001,1.451222e+000,4.237460e-001,4.234190e-001,6.373457e-005,6.373457e-005,,,,,,,,,,,,,,,,,,,,
1405609804.687,,-1.000000e+001,2.979968e+002,2.979968e+002,1,0,3.777187e+000,1.455885e+000,1.455886e+000,4.299715e-001,4.280822e-001,1.461408e+000,4.354942e-001,4.336048e-001,6.345524e-005,6.345524e-005,,,,,,,,,,,,,,,,,,,,
1405609929.484,,-5.000000e+000,2.979968e+002,2.980132e+002,1,0,1.744959e+000,1.353496e-001,1.353496e-001,-8.527124e-001,-8.531667e-001,1.598856e-001,-8.281763e-001,-8.286306e-001,5.899259e-006,5.899259e-006,,,,,,,,,,,,,,,,,,,,
1405609947.750,,-5.000000e+000,2.979968e+002,2.979968e+002,1,0,4.166989e-001,1.436811e+000,1.436811e+000,4.383990e-001,4.386396e-001,1.431945e+000,4.335330e-001,4.337736e-001,6.262392e-005,6.262392e-005,,,,,,,,,,,,,,,,,,,,
1405609947.750,,-5.000000e+000,2.979968e+002,2.979968e+002,1,0,3.676769e+000,1.435591e+000,1.435591e+000,4.361433e-001,4.374189e-001,1.432968e+000,4.335205e-001,4.347961e-001,6.257071e-005,6.257071e-005,,,,,,,,,,,,,,,,,,,,
1405609964.984,,-5.000000e+000,2.979968e+002,2.979968e+002,1,0,1.921530e+000,1.617481e-002,1.617481e-002,-9.697801e-001,-9.688693e-001,2.336360e-002,-9.625914e-001,-9.616805e-001,7.049846e-007,7.049846e-007,,,,,,,,,,,,,,,,,,,,
1405610084.234,,0.000000e+000,2.980050e+002,2.980050e+002,1,0,2.951018e-001,1.342814e+000,1.342814e+000,3.991137e-001,3.994036e-001,1.348883e+000,4.051827e-001,4.054725e-001,5.852705e-005,5.852705e-005,,,,,,,,,,,,,,,,,,,,
1405610084.234,,0.000000e+000,2.980050e+002,2.980050e+002,1,0,3.564951e+000,1.360973e+000,1.360973e+000,4.161392e-001,4.175620e-001,1.350657e+000,4.058233e-001,4.072461e-001,5.931850e-005,5.931850e-005,,,,,,,,,,,,,,,,,,,,
1405610101.968,,0.000000e+000,2.979885e+002,2.980050e+002,1,0,2.101348e+000,7.782220e-003,7.782220e-003,-9.437934e-001,-9.421166e-001,4.916144e-003,-9.466594e-001,-9.449827e-001,3.391909e-007,3.391909e-007,,,,,,,,,,,,,,,,,,,,
1405610120.203,,0.000000e+000,2.980050e+002,2.979968e+002,1,0,1.908625e-001,1.314127e+000,1.314127e+000,3.591466e-001,3.600279e-001,1.332278e+000,3.772976e-001,3.781788e-001,5.727670e-005,5.727670e-005,,,,,,,,,,,,,,,,,,,,
1405610120.203,,0.000000e+000,2.980050e+002,2.979968e+002,1,0,3.444630e+000,1.339763e+000,1.339763e+000,3.816243e-001,3.856635e-001,1.320871e+000,3.627330e-001,3.667722e-001,5.839403e-005,5.839403e-005,,,,,,,,,,,,,,,,,,,,
1405610239.187,,5.000000e+000,2.980050e+002,2.979968e+002,1,0,2.282201e+000,1.014740e-001,1.014740e-001,-8.017552e-001,-8.003441e-001,9.773853e-002,-8.054907e-001,-8.040797e-001,4.422781e-006,4.422781e-006,,,,,,,,,,,,,,,,,,,,
1405610257.171,,5.000000e+000,2.979968e+002,2.979968e+002,1,0,1.073011e-001,1.205023e+000,1.205023e+000,2.966762e-001,2.978437e-001,1.236700e+000,3.283529e-001,3.295205e-001,5.252136e-005,5.252136e-005,,,,,,,,,,,,,,,,,,,,
1405610257.171,,5.000000e+000,2.979968e+002,2.979968e+002,1,0,3.317650e+000,1.212500e+000,1.212500e+000,3.002913e-001,3.053207e-001,1.178919e+000,2.667101e-001,2.717395e-001,5.284724e-005,5.284724e-005,,,,,,,,,,,,,,,,,,,,
1405610275.156,,5.000000e+000,2.980132e+002,2.979968e+002,1,0,2.462244e+000,2.960295e-001,2.960295e-001,-6.194872e-001,-6.154493e-001,2.858028e-001,-6.297139e-001,-6.256760e-001,1.290255e-005,1.290255e-005,,,,,,,,,,,,,,,,,,,,
1405610395.171,,1.000000e+001,2.979968e+002,2.979968e+002,1,0,4.749826e-002,1.097140e+000,1.097140e+000,2.419668e-001,2.436761e-001,1.140394e+000,2.852207e-001,2.869300e-001,4.781922e-005,4.781922e-005,,,,,,,,,,,,,,,,,,,,
1405610395.171,,1.000000e+001,2.979968e+002,2.979968e+002,1,0,3.185102e+000,1.044954e+000,1.044954e+000,1.845301e-001,1.914895e-001,1.006713e+000,1.462889e-001,1.532483e-001,4.554465e-005,4.554465e-005,,,,,,,,,,,,,,,,,,,,
1405610412.656,,1.000000e+001,2.979968e+002,2.979968e+002,1,0,2.640178e+000,4.753258e-001,4.753258e-001,-3.846892e-001,-3.794328e-001,4.564596e-001,-4.035553e-001,-3.982990e-001,2.071723e-005,2.071723e-005,,,,,,,,,,,,,,,,,,,,
1405610429.890,,1.000000e+001,2.979968e+002,2.979968e+002,1,0,1.359655e-002,1.079592e+000,1.079592e+000,2.233344e-001,2.259922e-001,1.129010e+000,2.727519e-001,2.754097e-001,4.705438e-005,4.705438e-005,,,,,,,,,,,,,,,,,,,,
1405610429.890,,1.000000e+001,2.979968e+002,2.979968e+002,1,0,3.046834e+000,9.204382e-001,9.204382e-001,5.656152e-002,6.683820e-002,8.864177e-001,2.254098e-002,3.281766e-002,4.011760e-005,4.011760e-005,,,,,,,,,,,,,,,,,,,,
1405610548.125,,1.500000e+001,2.979968e+002,2.980050e+002,1,0,2.813992e+000,5.984680e-001,5.984679e-001,-1.683916e-001,-1.624683e-001,5.633041e-001,-2.035554e-001,-1.976321e-001,2.608441e-005,2.608441e-005,,,,,,,,,,,,,,,,,,,,
1405610565.859,,1.500000e+001,2.979968e+002,2.980132e+002,1,0,6.604312e-003,9.561449e-001,9.561449e-001,1.836041e-001,1.871960e-001,1.014352e+000,2.418112e-001,2.454031e-001,4.167387e-005,4.167387e-005,,,,,,,,,,,,,,,,,,,,
1405610565.859,,1.500000e+001,2.979968e+002,2.980132e+002,1,0,2.902422e+000,6.846828e-001,6.846828e-001,-9.751120e-002,-8.426613e-002,6.634285e-001,-1.187654e-001,-1.055204e-001,2.984211e-005,2.984211e-005,,,,,,,,,,,,,,,,,,,,
1405610583.625,,1.500000e+001,2.980132e+002,2.980050e+002,1,0,2.982922e+000,7.930235e-001,7.930235e-001,4.555520e-003,1.407743e-002,7.432965e-001,-4.517144e-002,-3.564954e-002,3.456417e-005,3.456417e-005,,,,,,,,,,,,,,,,,,,,
1405610702.453,,2.000000e+001,2.980050e+002,2.979968e+002,1,0,2.643287e-002,7.913449e-001,7.913449e-001,1.412351e-001,1.452289e-001,8.547179e-001,2.046081e-001,2.086019e-001,3.449099e-005,3.449099e-005,,,,,,,,,,,,,,,,,,,,
1405610702.453,,2.000000e+001,2.980050e+002,2.979968e+002,1,0,2.751324e+000,4.264962e-001,4.264962e-001,-2.337157e-001,-2.196198e-001,4.184135e-001,-2.417984e-001,-2.277025e-001,1.858896e-005,1.858896e-005,,,,,,,,,,,,,,,,,,,,
1405610719.937,,2.000000e+001,2.979968e+002,2.980050e+002,1,0,3.145980e+000,7.811213e-001,7.811213e-001,1.176781e-001,1.282492e-001,7.284571e-001,6.501396e-002,7.558501e-002,3.404539e-005,3.404539e-005,,,,,,,,,,,,,,,,,,,,
1405610738.421,,2.000000e+001,2.980050e+002,2.979885e+002,1,0,7.121947e-002,8.122501e-001,8.122501e-001,1.585484e-001,1.640902e-001,8.682866e-001,2.145849e-001,2.201266e-001,3.540215e-005,3.540215e-005,,,,,,,,,,,,,,,,,,,,
1405610738.421,,2.000000e+001,2.980050e+002,2.979885e+002,1,0,2.593050e+000,2.816859e-001,2.816858e-001,-3.852546e-001,-3.664742e-001,2.931029e-001,-3.738375e-001,-3.550571e-001,1.227736e-005,1.227736e-005,,,,,,,,,,,,,,,,,,,,
1405610857.406,,2.500000e+001,2.980050e+002,2.979968e+002,1,0,3.301739e+000,4.742576e-001,4.742576e-001,1.052021e-001,1.167514e-001,4.257449e-001,5.668937e-002,6.823868e-002,2.067064e-005,2.067064e-005,,,,,,,,,,,,,,,,,,,,
1405610875.390,,2.500000e+001,2.979968e+002,2.980050e+002,1,0,1.381373e-001,4.138310e-001,4.138310e-001,5.909781e-002,6.567898e-002,4.658176e-001,1.110844e-001,1.176656e-001,1.803693e-005,1.803693e-005,,,,,,,,,,,,,,,,,,,,
1405610875.390,,2.500000e+001,2.979968e+002,2.980050e+002,1,0,2.427826e+000,3.143406e-002,3.143407e-002,-3.381934e-001,-3.167180e-001,5.359051e-002,-3.160369e-001,-2.945615e-001,1.370062e-006,1.370062e-006,,,,,,,,,,,,,,,,,,,,
1405610893.625,,2.500000e+001,2.980050e+002,2.980050e+002,1,0,3.448699e+000,4.858547e-001,4.858547e-001,1.322328e-001,1.471368e-001,4.472841e-001,9.366220e-002,1.085662e-001,2.117610e-005,2.117610e-005,,,,,,,,,,,,,,,,,,,,
1405611024.125,,3.000000e+001,2.980050e+002,2.979968e+002,1,0,2.237421e-001,-8.546708e-001,-8.546709e-001,-3.274956e-001,-2.876504e-001,-8.133628e-001,-2.861875e-001,-2.463424e-001,-1.862552e-005,-1.862552e-005,,,,,,,,,,,,,,,,,,,,
1405611024.125,,3.000000e+001,2.980050e+002,2.979968e+002,1,0,2.256075e+000,-1.263466e-001,-1.263466e-001,3.151616e-001,4.406738e-001,-6.851569e-002,3.729925e-001,4.985048e-001,-2.753424e-006,-2.753424e-006,,,,,,,,,,,,,,,,,,,,
1405611042.375,,3.000000e+001,2.979968e+002,2.980050e+002,1,0,3.584311e+000,-7.719657e-001,-7.719657e-001,-2.670313e-001,-1.811773e-001,-7.885404e-001,-2.836060e-001,-1.977520e-001,-1.682316e-005,-1.682316e-005,,,,,,,,,,,,,,,,,,,,
1405611060.359,,3.000000e+001,2.980050e+002,2.979968e+002,1,0,3.242798e-001,-8.732871e-001,-8.732871e-001,-3.063844e-001,-2.641639e-001,-8.563433e-001,-2.894406e-001,-2.472201e-001,-1.903122e-005,-1.903122e-005,,,,,,,,,,,,,,,,,,,,
1405611178.343,,3.500000e+001,2.979968e+002,2.979885e+002,1,0,2.079478e+000,-5.813776e-002,-5.813776e-002,1.468052e+000,1.468052e+000,-3.146187e-002,1.494728e+000,1.494728e+000,-1.266974e-006,-1.266974e-006,,,,,,,,,,,,,,,,,,,,
1405611178.343,,3.500000e+001,2.979968e+002,2.979885e+002,1,0,3.705899e+000,-2.121647e+000,-2.121647e+000,-6.788319e-001,-5.954570e-001,-2.097905e+000,-6.550904e-001,-5.717155e-001,-4.623622e-005,-4.623622e-005,,,,,,,,,,,,,,,,,,,,
1405611196.609,,3.500000e+001,2.979968e+002,2.979885e+002,1,0,4.360808e-001,-2.147588e+000,-2.147588e+000,-6.463490e-001,-6.014352e-001,-2.170702e+000,-6.694636e-001,-6.245499e-001,-4.680154e-005,-4.680154e-005,,,,,,,,,,,,,,,,,,,,
1405611213.843,,3.500000e+001,2.979968e+002,2.979968e+002,1,0,1.899734e+000,-2.578814e-002,-2.578814e-002,1.574085e+000,1.576194e+000,5.005542e-002,1.649928e+000,1.652038e+000,-5.619909e-007,-5.619909e-007,,,,,,,,,,,,,,,,,,,,
1405611213.843,,3.500000e+001,2.979968e+002,2.979968e+002,1,0,3.810121e+000,-2.206336e+000,-2.206336e+000,-6.971790e-001,-6.043530e-001,-2.138194e+000,-6.290376e-001,-5.362115e-001,-4.808181e-005,-4.808181e-005,,,,,,,,,,,,,,,,,,,,
1405611332.593,,4.000000e+001,2.979968e+002,2.980050e+002,1,0,5.562953e-001,-2.643971e+000,-2.643971e+000,-7.131467e-001,-6.622779e-001,-2.707591e+000,-7.767671e-001,-7.258983e-001,-5.761901e-005,-5.761901e-005,,,,,,,,,,,,,,,,,,,,
1405611350.828,,4.000000e+001,2.980050e+002,2.979968e+002,1,0,1.718942e+000,-2.351451e-001,-2.351451e-001,1.775591e+000,1.780149e+000,-1.682397e-001,1.842497e+000,1.847055e+000,-5.124424e-006,-5.124424e-006,,,,,,,,,,,,,,,,,,,,
1405611350.828,,4.000000e+001,2.980050e+002,2.979968e+002,1,0,3.893686e+000,-2.779168e+000,-2.779168e+000,-8.664327e-001,-7.638736e-001,-2.664040e+000,-7.513049e-001,-6.487458e-001,-6.056530e-005,-6.056530e-005,,,,,,,,,,,,,,,,,,,,
1405611368.593,,4.000000e+001,2.979968e+002,2.980050e+002,1,0,6.832839e-001,-2.448958e+000,-2.448958e+000,-5.219679e-001,-4.672817e-001,-2.540714e+000,-6.137240e-001,-5.590378e-001,-5.336916e-005,-5.336916e-005,,,,,,,,,,,,,,,,,,,,
1405611486.578,,4.500000e+001,2.980050e+002,2.979968e+002,1,0,1.538933e+000,-6.422620e-001,-6.422620e-001,1.540458e+000,1.547551e+000,-6.546230e-001,1.528097e+000,1.535190e+000,-1.399655e-005,-1.399655e-005,,,,,,,,,,,,,,,,,,,,
1405611486.578,,4.500000e+001,2.980050e+002,2.979968e+002,1,0,3.953593e+000,-3.013398e+000,-3.013398e+000,-9.323446e-001,-8.235848e-001,-2.856336e+000,-7.752833e-001,-6.665235e-001,-6.566974e-005,-6.566974e-005,,,,,,,,,,,,,,,,,,,,
1405611505.312,,4.500000e+001,2.979968e+002,2.979885e+002,1,0,8.159567e-001,-2.430647e+000,-2.430647e+000,-3.247850e-001,-2.643530e-001,-2.541433e+000,-4.355712e-001,-3.751392e-001,-5.297009e-005,-5.297009e-005,,,,,,,,,,,,,,,,,,,,
1405611522.546,,4.500000e+001,2.979885e+002,2.979968e+002,1,0,1.360875e+000,-1.051210e+000,-1.051210e+000,1.101833e+000,1.111632e+000,-1.138123e+000,1.014920e+000,1.024719e+000,-2.290859e-005,-2.290859e-005,,,,,,,,,,,,,,,,,,,,
1405611522.546,,4.500000e+001,2.979885e+002,2.979968e+002,1,0,3.987439e+000,-2.977538e+000,-2.977538e+000,-9.298371e-001,-8.146963e-001,-2.799119e+000,-7.514173e-001,-6.362765e-001,-6.488828e-005,-6.488828e-005,,,,,,,,,,,,,,,,,,,,
1405611642.078,,5.000000e+001,2.979968e+002,2.979968e+002,1,0,9.542311e-001,-2.366100e+000,-2.366100e+000,-4.114637e-002,2.341509e-002,-2.490902e+000,-1.659487e-001,-1.013873e-001,-5.156342e-005,-5.156342e-005,,,,,,,,,,,,,,,,,,,,
1405611660.312,,5.000000e+001,2.979968e+002,2.979968e+002,1,0,1.187136e+000,-1.727042e+000,-1.727042e+000,6.445127e-001,6.576579e-001,-1.868680e+000,5.028754e-001,5.160205e-001,-3.763671e-005,-3.763671e-005,,,,,,,,,,,,,,,,,,,,
1405611660.312,,5.000000e+001,2.979968e+002,2.979968e+002,1,0,3.994431e+000,-3.280129e+000,-3.280129e+000,-1.021622e+000,-8.954291e-001,-3.084747e+000,-8.262399e-001,-7.000465e-001,-7.148249e-005,-7.148249e-005,,,,,,,,,,,,,,,,,,,,
1405611677.546,,5.000000e+001,2.979968e+002,2.979885e+002,1,0,1.098553e+000,-1.965240e+000,-1.965239e+000,3.839620e-001,4.528400e-001,-2.114729e+000,2.344727e-001,3.033507e-001,-4.282764e-005,-4.282764e-005,,,,,,,,,,,,,,,,,,,,
1405611803.343,,7.500000e+001,2.979968e+002,2.980050e+002,1,0,1.018245e+000,-2.476272e+000,-2.476272e+000,1.616141e-001,1.807802e-001,-2.682330e+000,-4.444390e-002,-2.527785e-002,-5.396423e-005,-5.396423e-005,,,,,,,,,,,,,,,,,,,,
1405611803.343,,7.500000e+001,2.979968e+002,2.980050e+002,1,0,3.974663e+000,-3.685415e+000,-3.685415e+000,-1.184886e+000,-1.028363e+000,-3.451204e+000,-9.506742e-001,-7.941515e-001,-8.031452e-005,-8.031452e-005,,,,,,,,,,,,,,,,,,,,
1405611821.140,,7.500000e+001,2.980050e+002,2.979968e+002,1,0,1.249708e+000,-1.695151e+000,-1.695151e+000,8.627879e-001,9.557304e-001,-1.846804e+000,7.111347e-001,8.040773e-001,-3.694162e-005,-3.694162e-005,,,,,,,,,,,,,,,,,,,,
1405611838.625,,7.500000e+001,2.979968e+002,2.979968e+002,1,0,8.551784e-001,-2.882778e+000,-2.882778e+000,-2.898265e-001,-2.662199e-001,-3.101134e+000,-5.081824e-001,-4.845757e-001,-6.282304e-005,-6.282304e-005,,,,,,,,,,,,,,,,,,,,
1405611838.625,,7.500000e+001,2.979968e+002,2.979968e+002,1,0,3.929934e+000,-3.652303e+000,-3.652303e+000,-1.204363e+000,-1.035744e+000,-3.446991e+000,-9.990515e-001,-8.304324e-001,-7.959292e-005,-7.959292e-005,,,,,,,,,,,,,,,,,,,,
1405611962.875,,1.000000e+002,2.979968e+002,2.980050e+002,1,0,1.407972e+000,-1.206092e+000,-1.206092e+000,1.429799e+000,1.533895e+000,-1.324106e+000,1.311784e+000,1.415880e+000,-2.628373e-005,-2.628373e-005,,,,,,,,,,,,,,,,,,,,
1405611980.109,,1.000000e+002,2.979968e+002,2.979885e+002,1,0,6.991305e-001,-3.400983e+000,-3.400983e+000,-6.975952e-001,-6.679904e-001,-3.606487e+000,-9.030999e-001,-8.734951e-001,-7.411585e-005,-7.411585e-005,,,,,,,,,,,,,,,,,,,,
1405611980.109,,1.000000e+002,2.979968e+002,2.979885e+002,1,0,3.862880e+000,-3.839228e+000,-3.839228e+000,-1.294967e+000,-1.106236e+000,-3.652995e+000,-1.108734e+000,-9.200029e-001,-8.366632e-005,-8.366632e-005,,,,,,,,,,,,,,,,,,,,
1405611997.843,,1.000000e+002,2.980050e+002,2.979885e+002,1,0,1.573309e+000,-6.929228e-001,-6.929228e-001,1.927131e+000,2.037724e+000,-7.066815e-001,1.913372e+000,2.023965e+000,-1.510051e-005,-1.510051e-005,,,,,,,,,,,,,,,,,,,,
1405611997.843,,1.000000e+002,2.980050e+002,2.979885e+002,1,0,2.256148e+000,-2.340770e-001,-2.340770e-001,2.264325e+000,2.496569e+000,-2.938075e-002,2.469022e+000,2.701266e+000,-5.101118e-006,-5.101118e-006,,,,,,,,,,,,,,,,,,,,