File: Sample Data Files/2014-07-16 EB on isolated PMN-PT no Ti spontaneous in situ/Ni-NiO_298K_SiO2_PMN-PT_5.0Tprebias_150V_Au_back.rso.raw
[Header]
TITLE,MPMS RSO Measurement
BYAPP,MPMS Measurement,2.1,Raw with ABS
FILEOPENTIME, 1405584047.765000 7/17/2014, 1:00:47 AM

INFO, APPNAME, MPMS MultiVu Application, Revision 1.58,  Build 076

INFO, NAME, EB in situ
INFO, WEIGHT, 0.000
INFO, AREA, 0.000
INFO, LENGTH, 0.000
INFO, SHAPE, 0
INFO, COMMENT,
INFO, SEQUENCE FILE: MHcurveUpTo100.seq


INFO, BACKGROUND DATA FILE:, None


STARTUPAXIS,X,8,LINEAR,AUTO,0.000000,0.000000
STARTUPAXIS,Y1,9,LINEAR,AUTO,0.000000,0.000000


STARTUPGROUP,Longitudinal
FIELDGROUP,Longitudinal,1,2,3,4,5,6,7,8,9,10,11,12,13,14,15,16,17,18,19,20,21,22
FIELDGROUP,Transverse,1,2,3,4,5,6,7,8,23,24,25,26,27,28,29,30,31,32,33,34,35,36

PLOT_APPEARANCE,ALL,HORZ_GRID_ON,VERT_GRID_ON,MARKERS_ONLY

[Data]
Time,Comment,Field (Oe),Start Temperature (K),End Temperature (K),Scan,Rejected,Position (cm),Long Voltage,Long Average Voltage,Long Detrended Voltage,Long Demeaned Voltage,Long Reg Fit,Long Detrended Fit,Long Demeaned Fit,Long Scaled Response,Long Avg. Scaled Response,Long Background Response,Long Response [w/ABS],Long Detrended Resp. [w/ABS],Long Fit [w/ABS],Long Detrended Fit [w/ABS],Trans Voltage,Trans Average Voltage,Trans Detrended Voltage,Trans Demeaned Voltage,Trans Reg Fit,Trans Detrended Fit,Trans Demeaned Fit,Trans Scaled Response,Trans Avg. Scaled Response,Trans Background Response,Trans Response [w/ABS],Trans Detrended Resp. [w/ABS],Trans Adjusted Fit,Trans Detrended Fit [w/ABS],
1405584047.765,,1.000000e+002,2.979968e+002,2.979968e+002,1,0,2.079422e+000,-4.394665e-002,-4.394665e-002,2.281090e+000,2.281090e+000,5.965286e-002,2.384690e+000,2.384690e+000,-9.577067e-007,-9.577067e-007,,,,,,,,,,,,,,,,,,,,
1405584047.765,,1.000000e+002,2.979968e+002,2.979968e+002,1,0,3.705964e+000,-3.240608e+000,-3.240608e+000,-1.063363e+000,-9.155707e-001,-3.220958e+000,-1.043712e+000,-8.959203e-001,-7.062089e-005,-7.062089e-005,,,,,,,,,,,,,,,,,,,,
1405584066.000,,1.000000e+002,2.979968e+002,2.980050e+002,1,0,4.361555e-001,-3.239235e+000,-3.239235e+000,-1.017833e+000,-9.416809e-001,-3.268177e+000,-1.046775e+000,-9.706230e-001,-7.059096e-005,-7.059096e-005,,,,,,,,,,,,,,,,,,,,
1405584084.250,,1.000000e+002,2.980050e+002,2.979968e+002,1,0,1.899588e+000,-9.231850e-002,-9.231849e-002,2.220142e+000,2.223603e+000,3.692155e-002,2.349382e+000,2.352843e+000,-2.011849e-006,-2.011849e-006,,,,,,,,,,,,,,,,,,,,
1405584084.250,,1.000000e+002,2.980050e+002,2.979968e+002,1,0,3.810177e+000,-3.260597e+000,-3.260597e+000,-1.096951e+000,-9.446764e-001,-3.155369e+000,-9.917219e-001,-8.394477e-001,-7.105651e-005,-7.105651e-005,,,,,,,,,,,,,,,,,,,,
1405584208.234,,7.500000e+001,2.979968e+002,2.980050e+002,1,0,5.563807e-001,-2.825098e+000,-2.825099e+000,-7.875688e-001,-7.196932e-001,-2.915862e+000,-8.783324e-001,-8.104568e-001,-6.156605e-005,-6.156605e-005,,,,,,,,,,,,,,,,,,,,
1405584226.468,,7.500000e+001,2.979885e+002,2.980050e+002,1,0,1.718768e+000,-3.735465e-001,-3.735466e-001,1.741033e+000,1.746982e+000,-3.245807e-001,1.789999e+000,1.795948e+000,-8.140525e-006,-8.140525e-006,,,,,,,,,,,,,,,,,,,,
1405584226.468,,7.500000e+001,2.979885e+002,2.980050e+002,1,0,3.893708e+000,-2.981506e+000,-2.981506e+000,-9.948196e-001,-8.609774e-001,-2.822392e+000,-8.357052e-001,-7.018631e-001,-6.497456e-005,-6.497456e-005,,,,,,,,,,,,,,,,,,,,
1405584243.718,,7.500000e+001,2.979885e+002,2.979968e+002,1,0,6.832917e-001,-2.630696e+000,-2.630696e+000,-6.035387e-001,-5.302415e-001,-2.762260e+000,-7.351033e-001,-6.618061e-001,-5.732951e-005,-5.732951e-005,,,,,,,,,,,,,,,,,,,,
1405584374.984,,5.000000e+001,2.980050e+002,2.980050e+002,1,0,1.538915e+000,-6.593524e-001,-6.593524e-001,1.127315e+000,1.134826e+000,-7.058862e-001,1.080781e+000,1.088292e+000,-1.436899e-005,-1.436899e-005,,,,,,,,,,,,,,,,,,,,
1405584374.984,,5.000000e+001,2.980050e+002,2.980050e+002,1,0,3.953594e+000,-2.526933e+000,-2.526932e+000,-8.479316e-001,-7.327539e-001,-2.344990e+000,-6.659896e-001,-5.508119e-001,-5.506838e-005,-5.506838e-005,,,,,,,,,,,,,,,,,,,,
1405584393.296,,5.000000e+001,2.980050e+002,2.979968e+002,1,0,8.160095e-001,-1.992096e+000,-1.992096e+000,-3.099308e-001,-2.447214e-001,-2.130071e+000,-4.479065e-001,-3.826971e-001,-4.341291e-005,-4.341291e-005,,,,,,,,,,,,,,,,,,,,
1405584411.046,,5.000000e+001,2.980050e+002,2.979968e+002,1,0,1.360774e+000,-9.523301e-001,-9.523301e-001,7.839911e-001,7.948066e-001,-1.075503e+000,6.608181e-001,6.716336e-001,-2.075373e-005,-2.075373e-005,,,,,,,,,,,,,,,,,,,,
1405584411.046,,5.000000e+001,2.980050e+002,2.979968e+002,1,0,3.987402e+000,-2.468795e+000,-2.468795e+000,-8.487400e-001,-7.216581e-001,-2.261578e+000,-6.415231e-001,-5.144411e-001,-5.380141e-005,-5.380141e-005,,,,,,,,,,,,,,,,,,,,
1405584522.296,,4.500000e+001,2.979968e+002,2.979968e+002,1,0,9.543056e-001,-1.687979e+000,-1.687979e+000,-6.188594e-002,-9.763241e-005,-1.831766e+000,-2.056731e-001,-1.438848e-001,-3.678543e-005,-3.678543e-005,,,,,,,,,,,,,,,,,,,,
1405584540.546,,4.500000e+001,2.979968e+002,2.979968e+002,1,0,1.187224e+000,-1.232795e+000,-1.232795e+000,4.103262e-001,4.232179e-001,-1.395574e+000,2.475475e-001,2.604392e-001,-2.686580e-005,-2.686580e-005,,,,,,,,,,,,,,,,,,,,
1405584540.546,,4.500000e+001,2.979968e+002,2.979968e+002,1,0,3.994457e+000,-2.347178e+000,-2.347178e+000,-8.149257e-001,-6.911653e-001,-2.140744e+000,-6.084917e-001,-4.847313e-001,-5.115110e-005,-5.115110e-005,,,,,,,,,,,,,,,,,,,,
1405584558.781,,4.500000e+001,2.979885e+002,2.979968e+002,1,0,1.098603e+000,-1.318400e+000,-1.318400e+000,2.152628e-001,2.874889e-001,-1.466944e+000,6.671838e-002,1.389445e-001,-2.873134e-005,-2.873134e-005,,,,,,,,,,,,,,,,,,,,
1405584677.515,,4.000000e+001,2.979968e+002,2.979968e+002,1,0,1.017830e+000,-1.485031e+000,-1.485031e+000,8.338361e-002,9.801376e-002,-1.660593e+000,-9.217865e-002,-7.754850e-002,-3.236268e-005,-3.236268e-005,,,,,,,,,,,,,,,,,,,,
1405584677.515,,4.000000e+001,2.979968e+002,2.979968e+002,1,0,3.974584e+000,-2.244331e+000,-2.244331e+000,-7.807662e-001,-6.612867e-001,-2.056013e+000,-5.924485e-001,-4.729689e-001,-4.890981e-005,-4.890981e-005,,,,,,,,,,,,,,,,,,,,
1405584695.250,,4.000000e+001,2.980050e+002,2.979968e+002,1,0,1.249714e+000,-1.013825e+000,-1.013825e+000,4.744007e-001,5.452958e-001,-1.137148e+000,3.510776e-001,4.219728e-001,-2.209388e-005,-2.209388e-005,,,,,,,,,,,,,,,,,,,,
1405584713.484,,4.000000e+001,2.979968e+002,2.980050e+002,1,0,8.548526e-001,-1.703391e+000,-1.703391e+000,-1.746240e-001,-1.569901e-001,-1.888969e+000,-3.602024e-001,-3.425685e-001,-3.712131e-005,-3.712131e-005,,,,,,,,,,,,,,,,,,,,
1405584713.484,,4.000000e+001,2.979968e+002,2.980050e+002,1,0,3.929881e+000,-2.208472e+000,-2.208472e+000,-7.880278e-001,-6.620715e-001,-2.040312e+000,-6.198681e-001,-4.939117e-001,-4.812835e-005,-4.812835e-005,,,,,,,,,,,,,,,,,,,,
1405584839.421,,3.500000e+001,2.980050e+002,2.979968e+002,1,0,1.408065e+000,-7.527390e-001,-7.527390e-001,7.107539e-001,7.793748e-001,-8.302042e-001,6.332887e-001,7.019096e-001,-1.640415e-005,-1.640415e-005,,,,,,,,,,,,,,,,,,,,
1405584858.578,,3.500000e+001,2.979968e+002,2.979968e+002,1,0,6.991436e-001,-1.828822e+000,-1.828822e+000,-3.820184e-001,-3.628109e-001,-1.977716e+000,-5.309129e-001,-5.117053e-001,-3.985480e-005,-3.985480e-005,,,,,,,,,,,,,,,,,,,,
1405584858.578,,3.500000e+001,2.979968e+002,2.979968e+002,1,0,3.862867e+000,-2.087619e+000,-2.087619e+000,-7.440562e-001,-6.216078e-001,-1.964337e+000,-6.207743e-001,-4.983258e-001,-4.549466e-005,-4.549466e-005,,,,,,,,,,,,,,,,,,,,
1405584876.812,,3.500000e+001,2.980050e+002,2.979968e+002,1,0,1.573338e+000,-4.403821e-001,-4.403821e-001,9.743150e-001,1.049049e+000,-4.552818e-001,9.594153e-001,1.034149e+000,-9.597075e-006,-9.597075e-006,,,,,,,,,,,,,,,,,,,,
1405584995.609,,3.000000e+001,2.979968e+002,2.979968e+002,1,0,5.521757e-001,-1.893979e+000,-1.893979e+000,-4.967288e-001,-4.771694e-001,-1.997502e+000,-6.002522e-001,-5.806928e-001,-4.127476e-005,-4.127476e-005,,,,,,,,,,,,,,,,,,,,
1405584995.609,,3.000000e+001,2.979968e+002,2.979968e+002,1,0,3.777223e+000,-1.986755e+000,-1.986755e+000,-6.829554e-001,-5.699457e-001,-1.918315e+000,-6.145154e-001,-5.015057e-001,-4.329660e-005,-4.329660e-005,,,,,,,,,,,,,,,,,,,,
1405585013.375,,3.000000e+001,2.979968e+002,2.980050e+002,1,0,1.744972e+000,-2.027955e-001,-2.027955e-001,1.109552e+000,1.180923e+000,-1.302138e-001,1.182133e+000,1.253505e+000,-4.419445e-006,-4.419445e-006,,,,,,,,,,,,,,,,,,,,
1405585031.609,,3.000000e+001,2.980050e+002,2.980050e+002,1,0,4.165443e-001,-1.942961e+000,-1.942961e+000,-5.803639e-001,-5.573157e-001,-1.990126e+000,-6.275293e-001,-6.044811e-001,-4.234221e-005,-4.234221e-005,,,,,,,,,,,,,,,,,,,,
1405585031.609,,3.000000e+001,2.980050e+002,2.980050e+002,1,0,3.676697e+000,-1.906034e+000,-1.906034e+000,-6.425440e-001,-5.203884e-001,-1.891025e+000,-6.275352e-001,-5.053796e-001,-4.153747e-005,-4.153747e-005,,,,,,,,,,,,,,,,,,,,
1405585150.359,,2.500000e+001,2.979968e+002,2.979968e+002,1,0,1.921542e+000,-8.636738e-002,-8.636738e-002,1.152191e+000,1.220374e+000,4.370443e-002,1.282263e+000,1.350446e+000,-1.882172e-006,-1.882172e-006,,,,,,,,,,,,,,,,,,,,
1405585168.890,,2.500000e+001,2.979968e+002,2.979968e+002,1,0,2.949809e-001,-1.829585e+000,-1.829585e+000,-5.787385e-001,-5.546412e-001,-1.811864e+000,-5.610183e-001,-5.369210e-001,-3.987146e-005,-3.987146e-005,,,,,,,,,,,,,,,,,,,,
1405585168.890,,2.500000e+001,2.979968e+002,2.979968e+002,1,0,3.564862e+000,-1.693930e+000,-1.693930e+000,-5.372823e-001,-4.189866e-001,-1.718014e+000,-5.613662e-001,-4.430704e-001,-3.691519e-005,-3.691519e-005,,,,,,,,,,,,,,,,,,,,
1405585187.171,,2.500000e+001,2.979968e+002,2.979968e+002,1,0,2.101372e+000,-3.738517e-002,-3.738517e-002,1.184647e+000,1.258399e+000,1.011465e-001,1.323179e+000,1.396931e+000,-8.147213e-007,-8.147213e-007,,,,,,,,,,,,,,,,,,,,
1405585304.656,,2.000000e+001,2.980050e+002,2.980050e+002,1,0,1.908237e-001,-1.740471e+000,-1.740471e+000,-5.525025e-001,-5.294766e-001,-1.662763e+000,-4.747944e-001,-4.517686e-001,-3.792945e-005,-3.792945e-005,,,,,,,,,,,,,,,,,,,,
1405585304.656,,2.000000e+001,2.980050e+002,2.980050e+002,1,0,3.444604e+000,-1.492203e+000,-1.492203e+000,-3.867435e-001,-2.812085e-001,-1.556847e+000,-4.513878e-001,-3.458529e-001,-3.251903e-005,-3.251903e-005,,,,,,,,,,,,,,,,,,,,
1405585322.390,,2.000000e+001,2.979968e+002,2.979968e+002,1,0,2.282268e+000,-1.127659e-001,-1.127659e-001,1.019689e+000,1.088521e+000,-2.979947e-002,1.102655e+000,1.171487e+000,-2.457467e-006,-2.457467e-006,,,,,,,,,,,,,,,,,,,,
1405585340.125,,2.000000e+001,2.979968e+002,2.979968e+002,1,0,1.072904e-001,-1.734062e+000,-1.734062e+000,-5.567276e-001,-5.295994e-001,-1.612729e+000,-4.353952e-001,-4.082670e-001,-3.778978e-005,-3.778978e-005,,,,,,,,,,,,,,,,,,,,
1405585340.125,,2.000000e+001,2.979968e+002,2.979968e+002,1,0,3.317640e+000,-1.337016e+000,-1.337016e+000,-2.494136e-001,-1.325536e-001,-1.432508e+000,-3.449061e-001,-2.280461e-001,-2.913711e-005,-2.913711e-005,,,,,,,,,,,,,,,,,,,,
1405585458.656,,1.500000e+001,2.979968e+002,2.979968e+002,1,0,2.462448e+000,-2.325510e-001,-2.325510e-001,8.110856e-001,8.795049e-001,-2.403350e-001,8.033017e-001,8.717209e-001,-5.067904e-006,-5.067904e-006,,,,,,,,,,,,,,,,,,,,
1405585476.640,,1.500000e+001,2.979968e+002,2.979968e+002,1,0,4.741370e-002,-1.576586e+000,-1.576586e+000,-5.117145e-001,-4.850644e-001,-1.428184e+000,-3.633118e-001,-3.366617e-001,-3.435799e-005,-3.435799e-005,,,,,,,,,,,,,,,,,,,,
1405585476.640,,1.500000e+001,2.979968e+002,2.979968e+002,1,0,3.184988e+000,-1.037171e+000,-1.037172e+000,-5.415372e-002,5.435026e-002,-1.153386e+000,-1.703679e-001,-6.186390e-002,-2.260272e-005,-2.260272e-005,,,,,,,,,,,,,,,,,,,,
1405585495.375,,1.500000e+001,2.979968e+002,2.979968e+002,1,0,2.640088e+000,-3.192236e-001,-3.192236e-001,6.454391e-001,7.179427e-001,-4.119045e-001,5.527583e-001,6.252619e-001,-6.956729e-006,-6.956729e-006,,,,,,,,,,,,,,,,,,,,
1405585612.875,,1.000000e+001,2.980050e+002,2.980050e+002,1,0,1.357983e-002,-1.398205e+000,-1.398206e+000,-4.618608e-001,-4.390333e-001,-1.238807e+000,-3.024619e-001,-2.796344e-001,-3.047062e-005,-3.047062e-005,,,,,,,,,,,,,,,,,,,,
1405585612.875,,1.000000e+001,2.980050e+002,2.980050e+002,1,0,3.046778e+000,-7.356486e-001,-7.356487e-001,1.352571e-001,2.235235e-001,-8.642030e-001,6.702785e-003,9.496915e-002,-1.603174e-005,-1.603174e-005,,,,,,,,,,,,,,,,,,,,
1405585630.859,,1.000000e+001,2.980050e+002,2.979968e+002,1,0,2.814126e+000,-4.788354e-001,-4.788354e-001,4.217147e-001,4.865852e-001,-6.184754e-001,2.820747e-001,3.469452e-001,-1.043510e-005,-1.043510e-005,,,,,,,,,,,,,,,,,,,,
1405585649.093,,1.000000e+001,2.979968e+002,2.980050e+002,1,0,6.611506e-003,-1.350902e+000,-1.350902e+000,-4.645366e-001,-4.332008e-001,-1.184641e+000,-2.982757e-001,-2.669399e-001,-2.943975e-005,-2.943975e-005,,,,,,,,,,,,,,,,,,,,
1405585649.093,,1.000000e+001,2.979968e+002,2.980050e+002,1,0,2.902392e+000,-5.041658e-001,-5.041658e-001,2.979845e-001,4.135353e-001,-6.281612e-001,1.739891e-001,2.895399e-001,-1.098711e-005,-1.098711e-005,,,,,,,,,,,,,,,,,,,,
1405585768.593,,5.000000e+000,2.979885e+002,2.979968e+002,1,0,2.982933e+000,-5.702384e-001,-5.702384e-001,2.302911e-001,2.869436e-001,-7.156177e-001,8.491178e-002,1.415642e-001,-1.242702e-005,-1.242702e-005,,,,,,,,,,,,,,,,,,,,
1405585787.109,,5.000000e+000,2.979968e+002,2.979885e+002,1,0,2.638450e-002,-1.163213e+000,-1.163213e+000,-4.071485e-001,-3.774338e-001,-1.008750e+000,-2.526857e-001,-2.229710e-001,-2.534952e-005,-2.534952e-005,,,,,,,,,,,,,,,,,,,,
1405585787.109,,5.000000e+000,2.979968e+002,2.979885e+002,1,0,2.751244e+000,-2.720725e-001,-2.720725e-001,4.088314e-001,5.137067e-001,-3.577225e-001,3.231815e-001,4.280567e-001,-5.929187e-006,-5.929187e-006,,,,,,,,,,,,,,,,,,,,
1405585805.343,,5.000000e+000,2.979885e+002,2.979968e+002,1,0,3.145999e+000,-6.364635e-001,-6.364635e-001,6.815763e-002,1.364654e-001,-7.718232e-001,-6.720208e-002,1.105726e-003,-1.387024e-005,-1.387024e-005,,,,,,,,,,,,,,,,,,,,
1405585923.578,,0.000000e+000,2.979968e+002,2.980050e+002,1,0,7.110588e-002,-9.439375e-001,-9.439375e-001,-3.311840e-001,-3.080398e-001,-8.115001e-001,-1.987467e-001,-1.756024e-001,-2.057093e-005,-2.057093e-005,,,,,,,,,,,,,,,,,,,,
1405585923.578,,0.000000e+000,2.979968e+002,2.980050e+002,1,0,2.592911e+000,-1.361126e-001,-1.361126e-001,4.213519e-001,4.997851e-001,-1.507736e-001,4.066908e-001,4.851241e-001,-2.966257e-006,-2.966257e-006,,,,,,,,,,,,,,,,,,,,
1405585942.390,,0.000000e+000,2.979968e+002,2.980050e+002,1,0,3.301879e+000,-5.244606e-001,-5.244606e-001,-3.025364e-002,2.864337e-002,-6.239498e-001,-1.297428e-001,-7.084584e-002,-1.142940e-005,-1.142940e-005,,,,,,,,,,,,,,,,,,,,
1405585959.687,,0.000000e+000,2.979968e+002,2.979885e+002,1,0,1.381764e-001,-8.270516e-001,-8.270516e-001,-3.168561e-001,-2.885571e-001,-7.225146e-001,-2.123192e-001,-1.840202e-001,-1.802367e-005,-1.802367e-005,,,,,,,,,,,,,,,,,,,,
1405585959.687,,0.000000e+000,2.979968e+002,2.979885e+002,1,0,2.427711e+000,1.846370e-002,1.846370e-002,4.646139e-001,5.569581e-001,7.606165e-002,5.222118e-001,6.145561e-001,4.023735e-007,4.023735e-007,,,,,,,,,,,,,,,,,,,,
1405586077.937,,-5.000000e+000,2.979968e+002,2.979968e+002,1,0,3.448784e+000,-3.437910e-001,-3.437910e-001,-1.778246e-002,-2.555549e-004,-3.957492e-001,-6.974070e-002,-5.221379e-002,-7.492125e-006,-7.492125e-006,,,,,,,,,,,,,,,,,,,,
1405586095.437,,-5.000000e+000,2.979968e+002,2.979968e+002,1,0,2.238370e-001,-4.565569e-001,-4.565569e-001,-1.735286e-001,-1.608854e-001,-3.835526e-001,-1.005242e-001,-8.788100e-002,-9.949595e-006,-9.949595e-006,,,,,,,,,,,,,,,,,,,,
1405586095.437,,-5.000000e+000,2.979968e+002,2.979968e+002,1,0,2.256086e+000,-2.075259e-002,-2.075259e-002,2.350929e-001,2.749190e-001,7.113695e-002,3.269824e-001,3.668085e-001,-4.522543e-007,-4.522543e-007,,,,,,,,,,,,,,,,,,,,
1405586112.921,,-5.000000e+000,2.979968e+002,2.980050e+002,1,0,3.584395e+000,-2.829066e-001,-2.829066e-001,-7.302435e-002,-4.683743e-002,-3.022862e-001,-9.240396e-002,-6.621705e-002,-6.165290e-006,-6.165290e-006,,,,,,,,,,,,,,,,,,,,
1405586237.656,,-1.000000e+001,2.979968e+002,2.979968e+002,1,0,3.242768e-001,9.704886e-002,9.704886e-002,3.911911e-002,9.517302e-002,7.535142e-002,1.742166e-002,7.347558e-002,2.114953e-006,2.114953e-006,,,,,,,,,,,,,,,,,,,,
1405586254.906,,-1.000000e+001,2.980050e+002,2.979968e+002,1,0,2.079517e+000,-6.591998e-002,-6.591998e-002,-1.174138e-001,-1.174138e-001,3.912193e-002,-1.237192e-002,-1.237192e-002,-1.436572e-006,-1.436572e-006,,,,,,,,,,,,,,,,,,,,
1405586254.906,,-1.000000e+001,2.980050e+002,2.979968e+002,1,0,3.705998e+000,1.361126e-001,1.361126e-001,2.123213e-002,8.461870e-002,1.247439e-001,9.863464e-003,7.325004e-002,2.966255e-006,2.966255e-006,,,,,,,,,,,,,,,,,,,,
1405586273.656,,-1.000000e+001,2.980050e+002,2.980050e+002,1,0,4.361502e-001,1.942503e-001,1.942503e-001,4.771087e-002,7.300206e-002,1.646353e-001,1.809581e-002,4.338700e-002,4.233231e-006,4.233231e-006,,,,,,,,,,,,,,,,,,,,
1405586390.906,,-1.500000e+001,2.979968e+002,2.979968e+002,1,0,1.899602e+000,-5.920591e-002,-5.920591e-002,-4.101155e-001,-4.091134e-001,-3.106968e-002,-3.819793e-001,-3.809771e-001,-1.290254e-006,-1.290254e-006,,,,,,,,,,,,,,,,,,,,
1405586390.906,,-1.500000e+001,2.979968e+002,2.979968e+002,1,0,3.810154e+000,5.119480e-001,5.119480e-001,1.179473e-001,1.620405e-001,5.475030e-001,1.535023e-001,1.975955e-001,1.115670e-005,1.115670e-005,,,,,,,,,,,,,,,,,,,,
1405586408.203,,-1.500000e+001,2.979968e+002,2.979968e+002,1,0,5.564099e-001,6.117435e-001,6.117435e-001,1.955319e-001,2.219583e-001,5.696130e-001,1.534013e-001,1.798278e-001,1.333151e-005,1.333151e-005,,,,,,,,,,,,,,,,,,,,
1405586426.703,,-1.500000e+001,2.979968e+002,2.980050e+002,1,0,1.718945e+000,5.478073e-002,5.478073e-002,-3.662989e-001,-3.639953e-001,6.486867e-002,-3.562109e-001,-3.539074e-001,1.193817e-006,1.193817e-006,,,,,,,,,,,,,,,,,,,,
1405586426.703,,-1.500000e+001,2.979968e+002,2.980050e+002,1,0,3.893747e+000,5.633717e-001,5.633717e-001,9.276652e-002,1.445956e-001,6.216109e-001,1.510057e-001,2.028348e-001,1.227736e-005,1.227736e-005,,,,,,,,,,,,,,,,,,,,
1405586551.703,,-2.000000e+001,2.979968e+002,2.979968e+002,1,0,6.834167e-001,9.300516e-001,9.300516e-001,2.817152e-001,2.985048e-001,8.735023e-001,2.251659e-001,2.419555e-001,2.026828e-005,2.026828e-005,,,,,,,,,,,,,,,,,,,,
1405586569.937,,-2.000000e+001,2.979968e+002,2.980050e+002,1,0,1.538669e+000,2.914518e-001,2.914518e-001,-4.078996e-001,-4.054267e-001,2.789773e-001,-4.203741e-001,-4.179011e-001,6.351504e-006,6.351504e-006,,,,,,,,,,,,,,,,,,,,
1405586569.937,,-2.000000e+001,2.979968e+002,2.980050e+002,1,0,3.953572e+000,9.193701e-001,9.193701e-001,1.845731e-001,2.224917e-001,9.825720e-001,2.477750e-001,2.856936e-001,2.003550e-005,2.003550e-005,,,,,,,,,,,,,,,,,,,,
1405586588.203,,-2.000000e+001,2.980050e+002,2.979968e+002,1,0,8.159958e-001,9.614856e-001,9.614856e-001,2.290831e-001,2.480217e-001,8.964777e-001,1.640752e-001,1.830137e-001,2.095331e-005,2.095331e-005,,,,,,,,,,,,,,,,,,,,
1405586706.953,,-2.500000e+001,2.980050e+002,2.979968e+002,1,0,1.360732e+000,5.911435e-001,5.911435e-001,-3.047822e-001,-3.031547e-001,5.552391e-001,-3.406867e-001,-3.390592e-001,1.288257e-005,1.288257e-005,,,,,,,,,,,,,,,,,,,,
1405586706.953,,-2.500000e+001,2.980050e+002,2.979968e+002,1,0,3.987412e+000,1.187628e+000,1.187628e+000,2.742061e-001,2.933295e-001,1.248652e+000,3.352300e-001,3.543535e-001,2.588153e-005,2.588153e-005,,,,,,,,,,,,,,,,,,,,
1405586724.281,,-2.500000e+001,2.979968e+002,2.980050e+002,1,0,9.542776e-001,1.115451e+000,1.115452e+000,1.805471e-001,1.973706e-001,1.049792e+000,1.148874e-001,1.317110e-001,2.430862e-005,2.430862e-005,,,,,,,,,,,,,,,,,,,,
1405586741.984,,-2.500000e+001,2.979968e+002,2.980050e+002,1,0,1.187075e+000,8.967865e-001,8.967864e-001,-7.823387e-002,-7.513022e-002,8.381835e-001,-1.368367e-001,-1.337331e-001,1.954333e-005,1.954333e-005,,,,,,,,,,,,,,,,,,,,
1405586741.984,,-2.500000e+001,2.979968e+002,2.980050e+002,1,0,3.994341e+000,1.281778e+000,1.281777e+000,2.800658e-001,3.098608e-001,1.344980e+000,3.432687e-001,3.730636e-001,2.793330e-005,2.793330e-005,,,,,,,,,,,,,,,,,,,,
1405586860.218,,-3.000000e+001,2.979968e+002,2.980050e+002,1,0,1.098691e+000,1.103091e+000,1.103091e+000,9.233212e-003,2.002442e-002,1.055815e+000,-3.804352e-002,-2.725232e-002,2.403926e-005,2.403926e-005,,,,,,,,,,,,,,,,,,,,
1405586877.453,,-3.000000e+001,2.980050e+002,2.979968e+002,1,0,1.017841e+000,1.238289e+000,1.238289e+000,1.242024e-001,1.268264e-001,1.178717e+000,6.463093e-002,6.725490e-002,2.698555e-005,2.698555e-005,,,,,,,,,,,,,,,,,,,,
1405586877.453,,-3.000000e+001,2.980050e+002,2.979968e+002,1,0,3.974618e+000,1.492355e+000,1.492355e+000,3.594639e-001,3.808930e-001,1.545433e+000,4.125420e-001,4.339710e-001,3.252233e-005,3.252233e-005,,,,,,,,,,,,,,,,,,,,
1405586895.687,,-3.000000e+001,2.979968e+002,2.980050e+002,1,0,1.249802e+000,8.987701e-001,8.987701e-001,-2.222199e-001,-2.079726e-001,8.757139e-001,-2.452762e-001,-2.310289e-001,1.958656e-005,1.958656e-005,,,,,,,,,,,,,,,,,,,,
1405587013.937,,-3.500000e+001,2.979968e+002,2.979968e+002,1,0,8.550130e-001,1.534623e+000,1.534623e+000,3.262166e-001,3.262641e-001,1.486778e+000,2.783714e-001,2.784189e-001,3.344345e-005,3.344345e-005,,,,,,,,,,,,,,,,,,,,
1405587013.937,,-3.500000e+001,2.979968e+002,2.979968e+002,1,0,3.929835e+000,1.648610e+000,1.648610e+000,4.399115e-001,4.402508e-001,1.689395e+000,4.806963e-001,4.810355e-001,3.592751e-005,3.592751e-005,,,,,,,,,,,,,,,,,,,,
1405587032.187,,-3.500000e+001,2.979968e+002,2.980050e+002,1,0,1.408119e+000,7.209998e-001,7.209998e-001,-5.453410e-001,-5.341422e-001,7.362848e-001,-5.300559e-001,-5.188572e-001,1.571247e-005,1.571247e-005,,,,,,,,,,,,,,,,,,,,
1405587050.421,,-3.500000e+001,2.980050e+002,2.979968e+002,1,0,6.990101e-001,1.760002e+000,1.760002e+000,4.764705e-001,4.802636e-001,1.718904e+000,4.353717e-001,4.391648e-001,3.835505e-005,3.835505e-005,,,,,,,,,,,,,,,,,,,,
1405587050.421,,-3.500000e+001,2.980050e+002,2.979968e+002,1,0,3.862834e+000,1.784112e+000,1.784112e+000,4.801922e-001,5.043732e-001,1.816016e+000,5.120963e-001,5.362773e-001,3.888046e-005,3.888046e-005,,,,,,,,,,,,,,,,,,,,
1405587169.906,,-4.000000e+001,2.980050e+002,2.979885e+002,1,0,1.573383e+000,4.675436e-001,4.675436e-001,-9.179800e-001,-9.164493e-001,5.069862e-001,-8.785374e-001,-8.770067e-001,1.018899e-005,1.018899e-005,,,,,,,,,,,,,,,,,,,,
1405587187.890,,-4.000000e+001,2.979968e+002,2.979968e+002,1,0,5.521340e-001,1.991485e+000,1.991485e+000,5.964608e-001,5.984015e-001,1.971695e+000,5.766704e-001,5.786111e-001,4.339965e-005,4.339965e-005,,,,,,,,,,,,,,,,,,,,
1405587187.890,,-4.000000e+001,2.979968e+002,2.979968e+002,1,0,3.777187e+000,1.985077e+000,1.985076e+000,5.807797e-001,5.919926e-001,1.996385e+000,5.920877e-001,6.033007e-001,4.325998e-005,4.325998e-005,,,,,,,,,,,,,,,,,,,,
1405587206.375,,-4.000000e+001,2.979968e+002,2.979968e+002,1,0,1.744954e+000,2.044740e-001,2.044740e-001,-1.193405e+000,-1.186157e+000,2.360153e-001,-1.161863e+000,-1.154616e+000,4.456021e-006,4.456021e-006,,,,,,,,,,,,,,,,,,,,
1405587317.906,,-4.500000e+001,2.980050e+002,2.979968e+002,1,0,4.166907e-001,2.152165e+000,2.152165e+000,6.572052e-001,6.590796e-001,2.149007e+000,6.540473e-001,6.559217e-001,4.690126e-005,4.690126e-005,,,,,,,,,,,,,,,,,,,,
1405587317.906,,-4.500000e+001,2.980050e+002,2.979968e+002,1,0,3.676766e+000,2.158116e+000,2.158116e+000,6.550964e-001,6.650307e-001,2.157047e+000,6.540268e-001,6.639612e-001,4.703095e-005,4.703095e-005,,,,,,,,,,,,,,,,,,,,
1405587336.187,,-4.500000e+001,2.979968e+002,2.979968e+002,1,0,1.921515e+000,7.995849e-002,7.995850e-002,-1.458456e+000,-1.449228e+000,8.303596e-002,-1.455379e+000,-1.446151e+000,1.742503e-006,1.742503e-006,,,,,,,,,,,,,,,,,,,,
1405587353.734,,-4.500000e+001,2.979968e+002,2.980050e+002,1,0,2.949970e-001,2.152318e+000,2.152318e+000,6.311556e-001,6.319964e-001,2.159269e+000,6.381069e-001,6.389477e-001,4.690458e-005,4.690458e-005,,,,,,,,,,,,,,,,,,,,
1405587353.734,,-4.500000e+001,2.979968e+002,2.980050e+002,1,0,3.564869e+000,2.173376e+000,2.173376e+000,6.489266e-001,6.530542e-001,2.163704e+000,6.392547e-001,6.433823e-001,4.736349e-005,4.736349e-005,,,,,,,,,,,,,,,,,,,,
1405587473.218,,-5.000000e+001,2.979968e+002,2.979968e+002,1,0,2.101214e+000,5.279702e-002,5.279702e-002,-1.556125e+000,-1.552304e+000,2.773871e-002,-1.581184e+000,-1.577363e+000,1.150583e-006,1.150583e-006,,,,,,,,,,,,,,,,,,,,
1405587490.953,,-5.000000e+001,2.979968e+002,2.979968e+002,1,0,1.907882e-001,2.232124e+000,2.232124e+000,6.156035e-001,6.188110e-001,2.252284e+000,6.357632e-001,6.389707e-001,4.864374e-005,4.864374e-005,,,,,,,,,,,,,,,,,,,,
1405587490.953,,-5.000000e+001,2.979968e+002,2.979968e+002,1,0,3.444561e+000,2.262337e+000,2.262337e+000,6.343234e-001,6.490244e-001,2.240945e+000,6.129310e-001,6.276320e-001,4.930216e-005,4.930216e-005,,,,,,,,,,,,,,,,,,,,
1405587507.937,,-5.000000e+001,2.979968e+002,2.979968e+002,1,0,2.282091e+000,2.690206e-001,2.690206e-001,-1.384315e+000,-1.377863e+000,2.445401e-001,-1.408795e+000,-1.402344e+000,5.862654e-006,5.862654e-006,,,,,,,,,,,,,,,,,,,,
1405587630.937,,-7.500000e+001,2.980132e+002,2.980050e+002,1,0,1.072394e-001,3.379467e+000,3.379467e+000,7.092386e-001,7.464638e-001,3.388528e+000,7.182995e-001,7.555246e-001,7.364714e-005,7.364714e-005,,,,,,,,,,,,,,,,,,,,
1405587630.937,,-7.500000e+001,2.980132e+002,2.980050e+002,1,0,3.317604e+000,3.390149e+000,3.390149e+000,5.967908e-001,7.571452e-001,3.386731e+000,5.933733e-001,7.537277e-001,7.387992e-005,7.387992e-005,,,,,,,,,,,,,,,,,,,,
1405587648.671,,-7.500000e+001,2.980050e+002,2.979968e+002,1,0,2.462204e+000,1.329997e+000,1.329997e+000,-1.311366e+000,-1.217794e+000,1.307528e+000,-1.333835e+000,-1.240263e+000,2.898399e-005,2.898399e-005,,,,,,,,,,,,,,,,,,,,
1405587665.921,,-7.500000e+001,2.979968e+002,2.980132e+002,1,0,4.744866e-002,3.261360e+000,3.261360e+000,6.648175e-001,7.008498e-001,3.268810e+000,6.722666e-001,7.082989e-001,7.107330e-005,7.107330e-005,,,,,,,,,,,,,,,,,,,,
1405587665.921,,-7.500000e+001,2.979968e+002,2.980132e+002,1,0,3.184995e+000,3.085879e+000,3.085879e+000,3.786654e-001,5.253685e-001,3.077636e+000,3.704221e-001,5.171251e-001,6.724912e-005,6.724912e-005,,,,,,,,,,,,,,,,,,,,
1405587822.406,,-1.000000e+002,2.980050e+002,2.979968e+002,1,0,2.639959e+000,4.130680e-001,4.130680e-001,-9.900592e-002,-5.966446e-002,4.147057e-001,-9.736822e-002,-5.802676e-002,9.001777e-005,9.001777e-005,,,,,,,,,,,,,,,,,,,,
1405587840.406,,-1.000000e+002,2.980050e+002,2.979885e+002,1,0,1.357313e-002,4.533525e-001,4.533525e-001,7.281870e-002,8.465242e-002,4.516049e-001,7.107115e-002,8.290488e-002,9.879675e-005,9.879675e-005,,,,,,,,,,,,,,,,,,,,
1405587840.406,,-1.000000e+002,2.980050e+002,2.979885e+002,1,0,3.046810e+000,4.216132e-001,4.216132e-001,7.156107e-003,5.291319e-002,4.250579e-001,1.060075e-002,5.635783e-002,9.187998e-005,9.187998e-005,,,,,,,,,,,,,,,,,,,,
1405587858.390,,-1.000000e+002,2.979968e+002,2.979968e+002,1,0,2.814121e+000,3.654591e-001,3.654591e-001,-5.208478e-002,-2.330977e-002,3.689884e-001,-4.855556e-002,-1.978055e-002,7.964262e-005,7.964262e-005,,,,,,,,,,,,,,,,,,,,
1405588000.640,,-7.500000e+001,2.980050e+002,2.979968e+002,1,0,6.625892e-003,1.330149e+000,1.330149e+000,3.222078e-001,3.190608e-001,1.334150e+000,3.262083e-001,3.230612e-001,5.797464e-005,5.797464e-005,,,,,,,,,,,,,,,,,,,,
1405588000.640,,-7.500000e+001,2.980050e+002,2.979968e+002,1,0,2.902381e+000,8.571123e-001,8.571123e-001,-1.423714e-001,-1.539761e-001,8.768483e-001,-1.226354e-001,-1.342402e-001,3.735729e-005,3.735729e-005,,,,,,,,,,,,,,,,,,,,
1405588017.625,,-7.500000e+001,2.979968e+002,2.979968e+002,1,0,2.983121e+000,9.822383e-001,9.822382e-001,-3.049441e-002,-3.689152e-002,9.851142e-001,-2.761843e-002,-3.401554e-002,4.281091e-005,4.281091e-005,,,,,,,,,,,,,,,,,,,,
1405588035.359,,-7.500000e+001,2.979968e+002,2.979968e+002,1,0,2.640020e-002,1.325419e+000,1.325419e+000,3.309869e-001,3.280433e-001,1.328862e+000,3.344299e-001,3.314863e-001,5.776846e-005,5.776846e-005,,,,,,,,,,,,,,,,,,,,
1405588035.359,,-7.500000e+001,2.979968e+002,2.979968e+002,1,0,2.751275e+000,6.469924e-001,6.469924e-001,-3.399939e-001,-3.503831e-001,6.750852e-001,-3.119010e-001,-3.222902e-001,2.819920e-005,2.819920e-005,,,,,,,,,,,,,,,,,,,,
1405588178.875,,-5.000000e+001,2.980050e+002,2.979968e+002,1,0,3.146072e+000,9.863582e-001,9.863582e-001,1.333280e-001,1.258391e-001,9.755145e-001,1.224843e-001,1.149954e-001,4.299058e-005,4.299058e-005,,,,,,,,,,,,,,,,,,,,
1405588196.609,,-5.000000e+001,2.979968e+002,2.979968e+002,1,0,7.116242e-002,1.153294e+000,1.153294e+000,2.935328e-001,2.902629e-001,1.165837e+000,3.060749e-001,3.028050e-001,5.026652e-005,5.026652e-005,,,,,,,,,,,,,,,,,,,,
1405588196.609,,-5.000000e+001,2.979968e+002,2.979968e+002,1,0,2.592987e+000,3.671377e-001,3.671377e-001,-4.848124e-001,-4.958939e-001,3.870859e-001,-4.648642e-001,-4.759457e-001,1.600175e-005,1.600175e-005,,,,,,,,,,,,,,,,,,,,
1405588215.609,,-5.000000e+001,2.979968e+002,2.979968e+002,1,0,3.301835e+000,1.122471e+000,1.122471e+000,2.585474e-001,2.513837e-001,1.111920e+000,2.479969e-001,2.408332e-001,4.892307e-005,4.892307e-005,,,,,,,,,,,,,,,,,,,,
1405588335.843,,-4.500000e+001,2.979968e+002,2.979968e+002,1,0,1.381009e-001,1.133610e+000,1.133610e+000,3.100625e-001,3.055735e-001,1.140084e+000,3.165363e-001,3.120473e-001,4.940860e-005,4.940860e-005,,,,,,,,,,,,,,,,,,,,
1405588335.843,,-4.500000e+001,2.979968e+002,2.979968e+002,1,0,2.427639e+000,1.725822e-001,1.725822e-001,-6.408061e-001,-6.554543e-001,1.859739e-001,-6.274144e-001,-6.420627e-001,7.522025e-006,7.522025e-006,,,,,,,,,,,,,,,,,,,,
1405588354.078,,-4.500000e+001,2.979968e+002,2.979968e+002,1,0,3.448753e+000,1.150548e+000,1.150548e+000,3.278617e-001,3.207346e-001,1.142949e+000,3.202632e-001,3.131361e-001,5.014683e-005,5.014683e-005,,,,,,,,,,,,,,,,,,,,
1405588372.312,,-4.500000e+001,2.979968e+002,2.980050e+002,1,0,2.236934e-001,1.164891e+000,1.164891e+000,3.433921e-001,3.403072e-001,1.163152e+000,3.416529e-001,3.385680e-001,5.077201e-005,5.077201e-005,,,,,,,,,,,,,,,,,,,,
1405588372.312,,-4.500000e+001,2.979968e+002,2.980050e+002,1,0,2.255950e+000,4.272591e-002,4.272591e-002,-7.721409e-001,-7.818583e-001,4.091650e-002,-7.739503e-001,-7.836677e-001,1.862217e-006,1.862217e-006,,,,,,,,,,,,,,,,,,,,
1405588492.562,,-4.000000e+001,2.979968e+002,2.979968e+002,1,0,3.584383e+000,1.126591e+000,1.126591e+000,3.470678e-001,3.385652e-001,1.126806e+000,3.472829e-001,3.387803e-001,4.910269e-005,4.910269e-005,,,,,,,,,,,,,,,,,,,,
1405588510.796,,-4.000000e+001,2.979968e+002,2.979968e+002,1,0,3.242167e-001,1.150853e+000,1.150853e+000,3.497627e-001,3.464084e-001,1.149106e+000,3.480152e-001,3.446609e-001,5.016016e-005,5.016016e-005,,,,,,,,,,,,,,,,,,,,
1405588529.031,,-4.000000e+001,2.979968e+002,2.979968e+002,1,0,2.079385e+000,-7.782220e-003,-7.782220e-003,-8.085525e-001,-8.085525e-001,-1.004366e-002,-8.108140e-001,-8.108140e-001,-3.391896e-007,-3.391896e-007,,,,,,,,,,,,,,,,,,,,
1405588529.031,,-4.000000e+001,2.979968e+002,2.979968e+002,1,0,3.705954e+000,1.145665e+000,1.145665e+000,3.505956e-001,3.448945e-001,1.149931e+000,3.548617e-001,3.491607e-001,4.993403e-005,4.993403e-005,,,,,,,,,,,,,,,,,,,,
1405588648.812,,-3.500000e+001,2.980050e+002,2.980050e+002,1,0,4.361478e-001,1.098209e+000,1.098209e+000,3.443376e-001,3.402967e-001,1.093960e+000,3.400889e-001,3.360479e-001,4.786567e-005,4.786567e-005,,,,,,,,,,,,,,,,,,,,
1405588666.562,,-3.500000e+001,2.980050e+002,2.980050e+002,1,0,1.899900e+000,1.892148e-002,1.892148e-002,-7.390592e-001,-7.391865e-001,1.990486e-002,-7.380757e-001,-7.382031e-001,8.246967e-007,8.246967e-007,,,,,,,,,,,,,,,,,,,,
1405588666.562,,-3.500000e+001,2.980050e+002,2.980050e+002,1,0,3.810207e+000,1.075320e+000,1.075320e+000,3.228146e-001,3.172117e-001,1.081462e+000,3.289573e-001,3.233544e-001,4.686805e-005,4.686805e-005,,,,,,,,,,,,,,,,,,,,
1405588684.328,,-3.500000e+001,2.980050e+002,2.979968e+002,1,0,5.564117e-001,1.102023e+000,1.102023e+000,3.380509e-001,3.351923e-001,1.089845e+000,3.258724e-001,3.230138e-001,4.803193e-005,4.803193e-005,,,,,,,,,,,,,,,,,,,,
1405588803.328,,-3.000000e+001,2.979968e+002,2.979968e+002,1,0,1.718795e+000,1.345866e-001,1.345866e-001,-5.842063e-001,-5.844237e-001,1.390563e-001,-5.797366e-001,-5.799541e-001,5.865991e-006,5.865991e-006,,,,,,,,,,,,,,,,,,,,
1405588803.328,,-3.000000e+001,2.979968e+002,2.979968e+002,1,0,3.893715e+000,1.003143e+000,1.003143e+000,2.890245e-001,2.841331e-001,1.011768e+000,2.976486e-001,2.927572e-001,4.372225e-005,4.372225e-005,,,,,,,,,,,,,,,,,,,,
1405588821.062,,-3.000000e+001,2.979968e+002,2.979968e+002,1,0,6.833757e-001,1.017182e+000,1.017182e+000,2.887993e-001,2.862302e-001,1.000038e+000,2.716553e-001,2.690862e-001,4.433412e-005,4.433412e-005,,,,,,,,,,,,,,,,,,,,
1405588839.296,,-3.000000e+001,2.979885e+002,2.979968e+002,1,0,1.538544e+000,3.257851e-001,3.257851e-001,-4.170747e-001,-4.173211e-001,3.279843e-001,-4.148755e-001,-4.151219e-001,1.419942e-005,1.419942e-005,,,,,,,,,,,,,,,,,,,,
1405588839.296,,-3.000000e+001,2.979885e+002,2.979968e+002,1,0,3.953483e+000,1.011841e+000,1.011841e+000,2.725138e-001,2.687349e-001,1.021384e+000,2.820570e-001,2.782781e-001,4.410134e-005,4.410134e-005,,,,,,,,,,,,,,,,,,,,
1405588958.828,,-2.500000e+001,2.979968e+002,2.979968e+002,1,0,8.160408e-001,8.911405e-001,8.911405e-001,2.165072e-001,2.150519e-001,8.697190e-001,1.950858e-001,1.936305e-001,3.884059e-005,3.884059e-005,,,,,,,,,,,,,,,,,,,,
1405588977.062,,-2.500000e+001,2.980132e+002,2.980050e+002,1,0,1.360783e+000,4.614398e-001,4.614399e-001,-2.142801e-001,-2.144292e-001,4.501088e-001,-2.256112e-001,-2.257603e-001,2.011198e-005,2.011198e-005,,,,,,,,,,,,,,,,,,,,
1405588977.062,,-2.500000e+001,2.980132e+002,2.980050e+002,1,0,3.987419e+000,9.196753e-001,9.196753e-001,2.455584e-001,2.438062e-001,9.332853e-001,2.591684e-001,2.574162e-001,4.008429e-005,4.008429e-005,,,,,,,,,,,,,,,,,,,,
1405588995.546,,-2.500000e+001,2.980050e+002,2.979968e+002,1,0,9.543019e-001,8.207953e-001,8.207953e-001,1.302619e-001,1.291955e-001,7.970923e-001,1.065589e-001,1.054925e-001,3.577458e-005,3.577458e-005,,,,,,,,,,,,,,,,,,,,
1405589114.296,,-2.000000e+001,2.979968e+002,2.979968e+002,1,0,1.187172e+000,6.028932e-001,6.028932e-001,-4.348767e-002,-4.365724e-002,5.807852e-001,-6.559563e-002,-6.576520e-002,2.627727e-005,2.627727e-005,,,,,,,,,,,,,,,,,,,,
1405589114.296,,-2.000000e+001,2.979968e+002,2.979968e+002,1,0,3.994444e+000,8.713034e-001,8.713034e-001,2.263810e-001,2.247530e-001,8.881236e-001,2.432012e-001,2.415732e-001,3.797601e-005,3.797601e-005,,,,,,,,,,,,,,,,,,,,
1405589132.031,,-2.000000e+001,2.979968e+002,2.979968e+002,1,0,1.098671e+000,6.636250e-001,6.636250e-001,2.571028e-002,2.429271e-002,6.398820e-001,1.967305e-003,5.497336e-004,2.892428e-005,2.892428e-005,,,,,,,,,,,,,,,,,,,,
1405589149.765,,-2.000000e+001,2.979968e+002,2.979968e+002,1,0,1.018153e+000,7.341228e-001,7.341228e-001,8.328197e-002,8.307379e-002,7.112470e-001,6.040624e-002,6.019807e-002,3.199695e-005,3.199695e-005,,,,,,,,,,,,,,,,,,,,
1405589149.765,,-2.000000e+001,2.979968e+002,2.979968e+002,1,0,3.974658e+000,8.784753e-001,8.784753e-001,2.291264e-001,2.274264e-001,8.973884e-001,2.480395e-001,2.463394e-001,3.828860e-005,3.828860e-005,,,,,,,,,,,,,,,,,,,,
1405589261.500,,-1.500000e+001,2.980050e+002,2.980050e+002,1,0,1.249822e+000,4.895169e-001,4.895169e-001,-8.951721e-002,-9.028742e-002,4.758237e-001,-1.032104e-001,-1.039806e-001,2.133574e-005,2.133574e-005,,,,,,,,,,,,,,,,,,,,
1405589279.234,,-1.500000e+001,2.979968e+002,2.979968e+002,1,0,8.549377e-001,7.704398e-001,7.704397e-001,1.802434e-001,1.802893e-001,7.475120e-001,1.573157e-001,1.573616e-001,3.357985e-005,3.357985e-005,,,,,,,,,,,,,,,,,,,,
1405589279.234,,-1.500000e+001,2.979968e+002,2.979968e+002,1,0,3.929858e+000,8.125553e-001,8.125553e-001,2.220773e-001,2.224048e-001,8.334186e-001,2.429406e-001,2.432681e-001,3.541547e-005,3.541547e-005,,,,,,,,,,,,,,,,,,,,
1405589296.968,,-1.500000e+001,2.979968e+002,2.980050e+002,1,0,1.408060e+000,3.717155e-001,3.717155e-001,-2.287134e-001,-2.286227e-001,3.744466e-001,-2.259823e-001,-2.258916e-001,1.620133e-005,1.620133e-005,,,,,,,,,,,,,,,,,,,,
1405589416.718,,-1.000000e+001,2.979968e+002,2.979968e+002,1,0,6.989685e-001,7.809687e-001,7.809687e-001,2.349817e-001,2.353144e-001,7.573630e-001,2.113761e-001,2.117088e-001,3.403877e-005,3.403877e-005,,,,,,,,,,,,,,,,,,,,
1405589416.718,,-1.000000e+001,2.979968e+002,2.979968e+002,1,0,3.862837e+000,7.673879e-001,7.673879e-001,2.196128e-001,2.217337e-001,7.850751e-001,2.373000e-001,2.394208e-001,3.344685e-005,3.344685e-005,,,,,,,,,,,,,,,,,,,,
1405589434.453,,-1.000000e+001,2.979968e+002,2.979968e+002,1,0,1.573356e+000,2.139348e-001,2.139347e-001,-3.421821e-001,-3.401891e-001,2.305638e-001,-3.255530e-001,-3.235601e-001,9.324415e-006,9.324415e-006,,,,,,,,,,,,,,,,,,,,
1405589452.703,,-1.000000e+001,2.979968e+002,2.980050e+002,1,0,5.522096e-001,8.281198e-001,8.281198e-001,2.577813e-001,2.583882e-001,8.127915e-001,2.424530e-001,2.430599e-001,3.609387e-005,3.609387e-005,,,,,,,,,,,,,,,,,,,,
1405589452.703,,-1.000000e+001,2.979968e+002,2.980050e+002,1,0,3.777222e+000,8.098087e-001,8.098087e-001,2.365705e-001,2.400771e-001,8.191696e-001,2.459314e-001,2.494380e-001,3.529577e-005,3.529577e-005,,,,,,,,,,,,,,,,,,,,
1405589572.437,,-5.000000e+000,2.979968e+002,2.980050e+002,1,0,1.745038e+000,8.758812e-002,8.758812e-002,-4.270608e-001,-4.246808e-001,1.125770e-001,-4.020720e-001,-3.996920e-001,3.817559e-006,3.817559e-006,,,,,,,,,,,,,,,,,,,,
1405589591.171,,-5.000000e+000,2.980050e+002,2.979968e+002,1,0,4.165556e-001,7.309183e-001,7.309183e-001,2.351156e-001,2.361153e-001,7.216348e-001,2.258321e-001,2.268319e-001,3.185733e-005,3.185733e-005,,,,,,,,,,,,,,,,,,,,
1405589591.171,,-5.000000e+000,2.980050e+002,2.979968e+002,1,0,3.676720e+000,7.243568e-001,7.243568e-001,2.242555e-001,2.295539e-001,7.259056e-001,2.258042e-001,2.311026e-001,3.157134e-005,3.157134e-005,,,,,,,,,,,,,,,,,,,,
1405589608.718,,-5.000000e+000,2.980050e+002,2.979968e+002,1,0,1.921613e+000,6.866665e-003,6.866665e-003,-5.066389e-001,-5.035193e-001,2.670603e-002,-4.867996e-001,-4.836800e-001,2.992859e-007,2.992859e-007,,,,,,,,,,,,,,,,,,,,
1405589728.218,,0.000000e+000,2.979968e+002,2.980050e+002,1,0,2.950630e-001,6.189154e-001,6.189154e-001,1.864464e-001,1.877236e-001,6.234958e-001,1.910268e-001,1.923041e-001,2.697565e-005,2.697565e-005,,,,,,,,,,,,,,,,,,,,
1405589728.218,,0.000000e+000,2.979968e+002,2.980050e+002,1,0,3.564907e+000,6.378368e-001,6.378369e-001,2.003751e-001,2.066451e-001,6.271427e-001,1.896809e-001,1.959509e-001,2.780035e-005,2.780035e-005,,,,,,,,,,,,,,,,,,,,
1405589745.953,,0.000000e+000,2.979968e+002,2.980050e+002,1,0,2.101273e+000,-1.495407e-002,-1.495407e-002,-4.817566e-001,-4.773539e-001,-6.799244e-004,-4.674824e-001,-4.630798e-001,-6.517785e-007,-6.517785e-007,,,,,,,,,,,,,,,,,,,,
1405589763.687,,0.000000e+000,2.979968e+002,2.979968e+002,1,0,1.907857e-001,6.102176e-001,6.102176e-001,1.537311e-001,1.556145e-001,6.306049e-001,1.741185e-001,1.760018e-001,2.659656e-005,2.659656e-005,,,,,,,,,,,,,,,,,,,,
1405589763.687,,0.000000e+000,2.979968e+002,2.979968e+002,1,0,3.444542e+000,6.428724e-001,6.428724e-001,1.796373e-001,1.882693e-001,6.235558e-001,1.603207e-001,1.689527e-001,2.801983e-005,2.801983e-005,,,,,,,,,,,,,,,,,,,,
1405589882.671,,5.000000e+000,2.979968e+002,2.980050e+002,1,0,2.282171e+000,-9.155553e-004,-9.155553e-004,-3.925011e-001,-3.889609e-001,2.847818e-003,-3.887378e-001,-3.851975e-001,-3.990479e-008,-3.990479e-008,,,,,,,,,,,,,,,,,,,,
1405589900.687,,5.000000e+000,2.979968e+002,2.979968e+002,1,0,1.072735e-001,5.142369e-001,5.142369e-001,1.003703e-001,1.023107e-001,5.503069e-001,1.364403e-001,1.383807e-001,2.241319e-005,2.241319e-005,,,,,,,,,,,,,,,,,,,,
1405589900.687,,5.000000e+000,2.979968e+002,2.979968e+002,1,0,3.317606e+000,5.449080e-001,5.449080e-001,1.246230e-001,1.329819e-001,5.156631e-001,9.537812e-002,1.037370e-001,2.375000e-005,2.375000e-005,,,,,,,,,,,,,,,,,,,,
1405589918.921,,5.000000e+000,2.979885e+002,2.979968e+002,1,0,2.462299e+000,1.159703e-001,1.159703e-001,-3.100745e-001,-3.028023e-001,1.049188e-001,-3.211260e-001,-3.138538e-001,5.054607e-006,5.054607e-006,,,,,,,,,,,,,,,,,,,,
1405590043.671,,1.000000e+001,2.980050e+002,2.979968e+002,1,0,4.748706e-002,4.135258e-001,4.135258e-001,5.484783e-002,5.746171e-002,4.640392e-001,1.053613e-001,1.079752e-001,1.802366e-005,1.802366e-005,,,,,,,,,,,,,,,,,,,,
1405590043.671,,1.000000e+001,2.980050e+002,2.979968e+002,1,0,3.185053e+000,4.319895e-001,4.319895e-001,6.528320e-002,7.592541e-002,3.953004e-001,2.859413e-002,3.923634e-002,1.882840e-005,1.882840e-005,,,,,,,,,,,,,,,,,,,,
1405590061.171,,1.000000e+001,2.980050e+002,2.979968e+002,1,0,2.640134e+000,1.785333e-001,1.785333e-001,-1.867117e-001,-1.789351e-001,1.573574e-001,-2.078876e-001,-2.001110e-001,7.781431e-006,7.781431e-006,,,,,,,,,,,,,,,,,,,,
1405590078.906,,1.000000e+001,2.979968e+002,2.979968e+002,1,0,1.351758e-002,4.054384e-001,4.054384e-001,4.257837e-002,4.569376e-002,4.628729e-001,1.000128e-001,1.031282e-001,1.767116e-005,1.767116e-005,,,,,,,,,,,,,,,,,,,,
1405590078.906,,1.000000e+001,2.979968e+002,2.979968e+002,1,0,3.046724e+000,3.778192e-001,3.778192e-001,6.028359e-003,1.807451e-002,3.452650e-001,-2.652576e-002,-1.447961e-002,1.646737e-005,1.646737e-005,,,,,,,,,,,,,,,,,,,,
1405590214.671,,1.500000e+001,2.980050e+002,2.979968e+002,1,0,2.814091e+000,4.281747e-001,4.281747e-001,-1.632701e-001,-1.444197e-001,3.591104e-001,-2.323344e-001,-2.134840e-001,9.331062e-006,9.331062e-006,,,,,,,,,,,,,,,,,,,,
1405590233.156,,1.500000e+001,2.980050e+002,2.979968e+002,1,0,6.541170e-003,5.922117e-001,5.922117e-001,2.475413e-002,3.307480e-002,7.229191e-001,1.554616e-001,1.637822e-001,1.290586e-005,1.290586e-005,,,,,,,,,,,,,,,,,,,,
1405590233.156,,1.500000e+001,2.980050e+002,2.979968e+002,1,0,2.902327e+000,4.759361e-001,4.759361e-001,-1.138832e-001,-8.320072e-002,4.234395e-001,-1.663798e-001,-1.356974e-001,1.037191e-005,1.037191e-005,,,,,,,,,,,,,,,,,,,,
1405590251.203,,1.500000e+001,2.979968e+002,2.980050e+002,1,0,2.982931e+000,5.653554e-001,5.653554e-001,-2.062896e-002,-1.079977e-003,4.773155e-001,-1.086689e-001,-8.911988e-002,1.232059e-005,1.232059e-005,,,,,,,,,,,,,,,,,,,,
1405590370.687,,2.000000e+001,2.980050e+002,2.979968e+002,1,0,2.642514e-002,3.831599e-001,3.831599e-001,-3.322987e-002,-2.454370e-002,5.269576e-001,1.105678e-001,1.192540e-001,8.350066e-006,8.350066e-006,,,,,,,,,,,,,,,,,,,,
1405590370.687,,2.000000e+001,2.980050e+002,2.979968e+002,1,0,2.751259e+000,2.392651e-001,2.392651e-001,-1.990955e-001,-1.684385e-001,2.019119e-001,-2.364487e-001,-2.057916e-001,5.214219e-006,5.214219e-006,,,,,,,,,,,,,,,,,,,,
1405590388.421,,2.000000e+001,2.979968e+002,2.980050e+002,1,0,3.146027e+000,5.018769e-001,5.018769e-001,7.187028e-002,9.482002e-002,4.065372e-001,-2.346944e-002,-5.196929e-004,1.093722e-005,1.093722e-005,,,,,,,,,,,,,,,,,,,,
1405590406.156,,2.000000e+001,2.980050e+002,2.979968e+002,1,0,7.116169e-002,3.985718e-001,3.985717e-001,-8.801580e-003,1.234859e-003,5.238267e-001,1.164533e-001,1.264898e-001,8.685931e-006,8.685931e-006,,,,,,,,,,,,,,,,,,,,
1405590406.156,,2.000000e+001,2.980050e+002,2.979968e+002,1,0,2.592959e+000,1.164281e-001,1.164281e-001,-3.149211e-001,-2.809088e-001,1.137474e-001,-3.176018e-001,-2.835894e-001,2.537276e-006,2.537276e-006,,,,,,,,,,,,,,,,,,,,
1405590525.171,,2.500000e+001,2.979968e+002,2.979968e+002,1,0,3.301826e+000,3.241066e-001,3.241066e-001,8.413648e-002,1.129726e-001,2.249298e-001,-1.504027e-002,1.379587e-002,7.063135e-006,7.063135e-006,,,,,,,,,,,,,,,,,,,,
1405590543.671,,2.500000e+001,2.979968e+002,2.979968e+002,1,0,1.381502e-001,2.052370e-001,2.052370e-001,-5.006716e-002,-3.484422e-002,3.131645e-001,5.786034e-002,7.308328e-002,4.472654e-006,4.472654e-006,,,,,,,,,,,,,,,,,,,,
1405590543.671,,2.500000e+001,2.979968e+002,2.979968e+002,1,0,2.427647e+000,-4.730369e-003,-4.730369e-003,-2.944864e-001,-2.448116e-001,4.480652e-002,-2.449495e-001,-1.952747e-001,-1.030872e-007,-1.030872e-007,,,,,,,,,,,,,,,,,,,,
1405590562.203,,2.500000e+001,2.979968e+002,2.979968e+002,1,0,3.448736e+000,3.639332e-001,3.639332e-001,9.604328e-002,1.303322e-001,2.887207e-001,2.083072e-002,5.511962e-002,7.931063e-006,7.931063e-006,,,,,,,,,,,,,,,,,,,,
1405590676.437,,3.000000e+001,2.979968e+002,2.979968e+002,1,0,2.237734e-001,-1.252785e-001,-1.252785e-001,-1.281467e-001,-1.459465e-001,-2.668006e-002,-2.954828e-002,-4.734813e-002,-2.730146e-006,-2.730146e-006,,,,,,,,,,,,,,,,,,,,
1405590676.437,,3.000000e+001,2.979968e+002,2.979968e+002,1,0,2.255982e+000,-7.034516e-002,-7.034516e-002,-3.494372e-002,-9.101323e-002,2.624342e-002,6.164486e-002,5.575353e-003,-1.533006e-006,-1.533006e-006,,,,,,,,,,,,,,,,,,,,
1405590694.421,,3.000000e+001,2.979968e+002,2.980132e+002,1,0,3.584424e+000,-1.083407e-002,-1.083407e-002,1.136697e-003,-3.182497e-002,-4.718619e-002,-3.521542e-002,-6.817709e-002,-2.361028e-007,-2.361028e-007,,,,,,,,,,,,,,,,,,,,
1405590711.671,,3.000000e+001,2.979968e+002,2.979968e+002,1,0,3.242448e-001,-8.102664e-002,-8.102664e-002,-8.471171e-002,-1.008893e-001,-3.533548e-002,-3.902055e-002,-5.519809e-002,-1.765783e-006,-1.765783e-006,,,,,,,,,,,,,,,,,,,,
1405590824.156,,3.500000e+001,2.979968e+002,2.980050e+002,1,0,2.079544e+000,-4.165776e-002,-4.165776e-002,4.254575e-001,4.254575e-001,-4.362033e-002,4.234949e-001,4.234949e-001,-9.078315e-007,-9.078315e-007,,,,,,,,,,,,,,,,,,,,
1405590824.156,,3.500000e+001,2.979968e+002,2.980050e+002,1,0,3.706002e+000,-5.999939e-001,-5.999939e-001,-2.153446e-001,-1.328786e-001,-5.727908e-001,-1.881415e-001,-1.056755e-001,-1.307543e-005,-1.307543e-005,,,,,,,,,,,,,,,,,,,,
1405590841.421,,3.500000e+001,2.979968e+002,2.980050e+002,1,0,4.361279e-001,-5.946531e-001,-5.946531e-001,-1.712850e-001,-1.282137e-001,-6.081235e-001,-1.847553e-001,-1.416841e-001,-1.295905e-005,-1.295905e-005,,,,,,,,,,,,,,,,,,,,
1405590858.703,,3.500000e+001,2.980050e+002,2.979968e+002,1,0,1.899754e+000,1.648000e-002,1.648000e-002,4.803506e-001,4.824024e-001,5.470473e-002,5.185754e-001,5.206272e-001,3.591421e-007,3.591421e-007,,,,,,,,,,,,,,,,,,,,
1405590858.703,,3.500000e+001,2.980050e+002,2.979968e+002,1,0,3.810227e+000,-6.189154e-001,-6.189154e-001,-2.432715e-001,-1.529929e-001,-5.526244e-001,-1.769805e-001,-8.670196e-002,-1.348778e-005,-1.348778e-005,,,,,,,,,,,,,,,,,,,,
1405590977.937,,4.000000e+001,2.979968e+002,2.979885e+002,1,0,5.564705e-001,-9.628590e-001,-9.628590e-001,-2.383738e-001,-1.945649e-001,-1.019444e+000,-2.949589e-001,-2.511501e-001,-2.098320e-005,-2.098320e-005,,,,,,,,,,,,,,,,,,,,
1405590996.718,,4.000000e+001,2.980050e+002,2.979968e+002,1,0,1.718711e+000,-5.630665e-002,-5.630665e-002,7.202696e-001,7.242326e-001,-1.314991e-002,7.634263e-001,7.673893e-001,-1.227068e-006,-1.227068e-006,,,,,,,,,,,,,,,,,,,,
1405590996.718,,4.000000e+001,2.980050e+002,2.979968e+002,1,0,3.893696e+000,-1.089663e+000,-1.089663e+000,-3.982921e-001,-3.091242e-001,-9.826040e-001,-2.912327e-001,-2.020648e-001,-2.374660e-005,-2.374660e-005,,,,,,,,,,,,,,,,,,,,
1405591015.015,,4.000000e+001,2.979968e+002,2.979968e+002,1,0,6.834198e-001,-8.623005e-001,-8.623005e-001,-1.491189e-001,-1.006234e-001,-9.406687e-001,-2.274871e-001,-1.789916e-001,-1.879177e-005,-1.879177e-005,,,,,,,,,,,,,,,,,,,,
1405591132.546,,4.500000e+001,2.979968e+002,2.979968e+002,1,0,1.538721e+000,-2.708518e-001,-2.708518e-001,7.735542e-001,7.794833e-001,-2.903273e-001,7.540787e-001,7.600077e-001,-5.902562e-006,-5.902562e-006,,,,,,,,,,,,,,,,,,,,
1405591132.546,,4.500000e+001,2.979968e+002,2.979968e+002,1,0,3.953544e+000,-1.479843e+000,-1.479843e+000,-5.204199e-001,-4.295075e-001,-1.332677e+000,-3.732542e-001,-2.823418e-001,-3.224960e-005,-3.224960e-005,,,,,,,,,,,,,,,,,,,,
1405591150.046,,4.500000e+001,2.979968e+002,2.980050e+002,1,0,8.159475e-001,-1.138951e+000,-1.138951e+000,-1.033181e-001,-5.213070e-002,-1.240754e+000,-2.051216e-001,-1.539342e-001,-2.482069e-005,-2.482069e-005,,,,,,,,,,,,,,,,,,,,
1405591167.781,,4.500000e+001,2.980050e+002,2.980050e+002,1,0,1.360973e+000,-4.635762e-001,-4.635762e-001,5.965897e-001,6.049556e-001,-5.514971e-001,5.086688e-001,5.170346e-001,-1.010253e-005,-1.010253e-005,,,,,,,,,,,,,,,,,,,,
1405591167.781,,4.500000e+001,2.980050e+002,2.980050e+002,1,0,3.987454e+000,-1.503800e+000,-1.503800e+000,-5.335670e-001,-4.352678e-001,-1.336620e+000,-3.663877e-001,-2.680885e-001,-3.277169e-005,-3.277169e-005,,,,,,,,,,,,,,,,,,,,
1405591287.015,,5.000000e+001,2.979968e+002,2.979968e+002,1,0,9.542855e-001,-1.302225e+000,-1.302225e+000,1.396347e-002,6.994700e-002,-1.425535e+000,-1.093472e-001,-5.336368e-002,-2.837884e-005,-2.837884e-005,,,,,,,,,,,,,,,,,,,,
1405591305.250,,5.000000e+001,2.979968e+002,2.980050e+002,1,0,1.186828e+000,-9.544664e-001,-9.544664e-001,4.078497e-001,4.191217e-001,-1.095729e+000,2.665872e-001,2.778592e-001,-2.080029e-005,-2.080029e-005,,,,,,,,,,,,,,,,,,,,
1405591305.250,,5.000000e+001,2.979968e+002,2.980050e+002,1,0,3.994332e+000,-1.926939e+000,-1.926939e+000,-6.615616e-001,-5.533506e-001,-1.741852e+000,-4.764752e-001,-3.682642e-001,-4.199297e-005,-4.199297e-005,,,,,,,,,,,,,,,,,,,,
1405591323.312,,5.000000e+001,2.980050e+002,2.980050e+002,1,0,1.098693e+000,-1.066012e+000,-1.066012e+000,2.467132e-001,3.087840e-001,-1.197090e+000,1.156352e-001,1.777060e-001,-2.323114e-005,-2.323114e-005,,,,,,,,,,,,,,,,,,,,
1405591441.812,,7.500000e+001,2.980050e+002,2.979885e+002,1,0,1.018185e+000,-1.828517e+000,-1.828516e+000,1.504276e-001,1.682911e-001,-2.031008e+000,-5.206420e-002,-3.420067e-002,-3.984800e-005,-3.984800e-005,,,,,,,,,,,,,,,,,,,,
1405591441.812,,7.500000e+001,2.980050e+002,2.979885e+002,1,0,3.974678e+000,-2.800989e+000,-2.800989e+000,-9.500669e-001,-8.041813e-001,-2.575200e+000,-7.242783e-001,-5.783927e-001,-6.104064e-005,-6.104064e-005,,,,,,,,,,,,,,,,,,,,
1405591459.546,,7.500000e+001,2.979968e+002,2.979968e+002,1,0,1.249710e+000,-1.228980e+000,-1.228980e+000,6.576855e-001,7.440606e-001,-1.369932e+000,5.167339e-001,6.031091e-001,-2.678259e-005,-2.678259e-005,,,,,,,,,,,,,,,,,,,,
1405591477.281,,7.500000e+001,2.979968e+002,2.979968e+002,1,0,8.550853e-001,-2.125767e+000,-2.125767e+000,-1.892249e-001,-1.673667e-001,-2.337072e+000,-4.005302e-001,-3.786721e-001,-4.632584e-005,-4.632584e-005,,,,,,,,,,,,,,,,,,,,
1405591477.281,,7.500000e+001,2.979968e+002,2.979968e+002,1,0,3.929835e+000,-2.762536e+000,-2.762536e+000,-9.602649e-001,-8.041356e-001,-2.564385e+000,-7.621145e-001,-6.059852e-001,-6.020264e-005,-6.020264e-005,,,,,,,,,,,,,,,,,,,,
1405591609.765,,1.000000e+002,2.980050e+002,2.979968e+002,1,0,1.408098e+000,-1.013062e+000,-1.013062e+000,1.214204e+000,1.315981e+000,-1.121191e+000,1.106075e+000,1.207852e+000,-2.207713e-005,-2.207713e-005,,,,,,,,,,,,,,,,,,,,
1405591628.500,,1.000000e+002,2.979968e+002,2.979968e+002,1,0,6.989642e-001,-2.929624e+000,-2.929624e+000,-5.839900e-001,-5.573556e-001,-3.132276e+000,-7.866420e-001,-7.600076e-001,-6.384379e-005,-6.384379e-005,,,,,,,,,,,,,,,,,,,,
1405591628.500,,1.000000e+002,2.979968e+002,2.979968e+002,1,0,3.862823e+000,-3.339030e+000,-3.339030e+000,-1.136555e+000,-9.667614e-001,-3.159563e+000,-9.570885e-001,-7.872946e-001,-7.276575e-005,-7.276575e-005,,,,,,,,,,,,,,,,,,,,
1405591646.234,,1.000000e+002,2.979968e+002,2.980050e+002,1,0,1.573367e+000,-5.964842e-001,-5.964842e-001,1.634561e+000,1.739336e+000,-6.067881e-001,1.624257e+000,1.729032e+000,-1.299887e-005,-1.299887e-005,,,,,,,,,,,,,,,,,,,,
1405591646.234,,1.000000e+002,2.979968e+002,2.980050e+002,1,0,2.256120e+000,-1.937925e-001,-1.937925e-001,1.922001e+000,2.142027e+000,1.851788e-002,2.134311e+000,2.354338e+000,-4.223220e-006,-4.223220e-006,,,,,,,,,,,,,,,,,,,,