File: Sample Data Files/2014-07-16 EB on isolated PMN-PT no Ti spontaneous in situ/Ni-NiO_298K_SiO2_PMN-PT_5.0Tprebias_unpoled_Au_back.rso.dat
[Header]
TITLE,MPMS RSO Measurement
BYAPP,MPMS Measurement,1.1,Summary
FILEOPENTIME, 1405532254.140000 7/16/2014, 10:37:34 AM

INFO, APPNAME, MPMS MultiVu Application, Revision 1.58,  Build 076

INFO, NAME, EB in situ
INFO, WEIGHT, 0.000
INFO, AREA, 0.000
INFO, LENGTH, 0.000
INFO, SHAPE, 0
INFO, COMMENT,
INFO, SEQUENCE FILE: MHcurveUpTo100.seq


INFO, BACKGROUND DATA FILE:, None


STARTUPAXIS,X,4,LINEAR,AUTO,0.000000,0.000000
STARTUPAXIS,Y1,5,LINEAR,AUTO,0.000000,0.000000


STARTUPGROUP,Longitudinal
FIELDGROUP,Longitudinal,1,2,3,4,5,6,7,8,9,10,11,19,20,21,22,23,35
FIELDGROUP,Transverse,1,2,3,4,12,13,14,15,16,17,18,24,25,26,27,28,35

PLOT_APPEARANCE,ALL,HORZ_GRID_ON,VERT_GRID_ON,MARKERS_AND_LINES

[Data]
Time,Comment,Field (Oe),Temperature (K),Long Moment (emu),Long Scan Std Dev,Long Offset (cm),Long Offset Std Dev,Long Algorithm,Long Reg Fit,Long Reg Factor,Trans Moment (emu),Trans Scan Std Dev,Trans Offset (cm),Trans Offset Std Dev,Trans Algorithm,Trans Reg Fit,Trans Reg Factor,Long Moment [w/o ABS] (emu),Long Scan Std Dev [w/o ABS],Long Offset [w/o ABS] (cm),Long Offset Std Dev [w/o ABS],Long Reg Fit [w/o ABS],Trans Moment [w/o ABS] (emu),Trans Scan Std Dev [w/o ABS],Trans Offset [w/o ABS] (cm),Trans Offset Std Dev [w/o ABS],Trans Reg Fit [w/o ABS],RSO Position (deg),Amplitude (cm),Frequency,Cycles to Average,Scans per Measurement,Delta Temp (K),Error,EC Comp. Running,Using ABS,
1405532254.140,,1.000000e+002,2.980009e+002,3.864319e-005,0.000000e+000,-1.126373e-002,0.000000e+000,3,8.550057e-001,1.825000e+000,,,,,,,,,,,,,,,,,,0,4.000000e+000,5.000000e-001,5,1,8.209229e-003,0,,0,
1405532272.046,,1.000000e+002,2.980009e+002,3.865900e-005,0.000000e+000,-9.237801e-003,0.000000e+000,3,8.550340e-001,1.825000e+000,,,,,,,,,,,,,,,,,,0,4.000000e+000,5.000000e-001,5,1,8.209229e-003,0,,0,
1405532289.781,,1.000000e+002,2.979968e+002,3.860791e-005,0.000000e+000,-1.242433e-002,0.000000e+000,3,8.534678e-001,1.825000e+000,,,,,,,,,,,,,,,,,,0,4.000000e+000,5.000000e-001,5,1,0.000000e+000,0,,0,
1405532413.812,,7.500000e+001,2.980009e+002,3.772656e-005,0.000000e+000,-6.993839e-003,0.000000e+000,3,8.676378e-001,1.825000e+000,,,,,,,,,,,,,,,,,,0,4.000000e+000,5.000000e-001,5,1,8.209229e-003,0,,0,
1405532431.265,,7.500000e+001,2.980009e+002,3.791011e-005,0.000000e+000,-9.426887e-003,0.000000e+000,3,8.646059e-001,1.825000e+000,,,,,,,,,,,,,,,,,,0,4.000000e+000,5.000000e-001,5,1,8.209229e-003,0,,0,
1405532448.000,,7.500000e+001,2.980009e+002,3.802310e-005,0.000000e+000,-1.225297e-002,0.000000e+000,3,8.683828e-001,1.825000e+000,,,,,,,,,,,,,,,,,,0,4.000000e+000,5.000000e-001,5,1,8.209229e-003,0,,0,
1405532594.328,,5.000000e+001,2.980009e+002,3.711761e-005,0.000000e+000,-5.981559e-003,0.000000e+000,3,8.776861e-001,1.825000e+000,,,,,,,,,,,,,,,,,,0,4.000000e+000,5.000000e-001,5,1,8.209229e-003,0,,0,
1405532612.578,,5.000000e+001,2.979968e+002,3.644003e-005,0.000000e+000,1.222915e-003,0.000000e+000,3,8.787616e-001,1.825000e+000,,,,,,,,,,,,,,,,,,0,4.000000e+000,5.000000e-001,5,1,0.000000e+000,0,,0,
1405532630.812,,5.000000e+001,2.980009e+002,3.637742e-005,0.000000e+000,-9.152021e-004,0.000000e+000,3,8.795426e-001,1.825000e+000,,,,,,,,,,,,,,,,,,0,4.000000e+000,5.000000e-001,5,1,8.209229e-003,0,,0,
1405532743.062,,4.500000e+001,2.980009e+002,3.593372e-005,0.000000e+000,-4.479504e-003,0.000000e+000,3,8.834519e-001,1.825000e+000,,,,,,,,,,,,,,,,,,0,4.000000e+000,5.000000e-001,5,1,8.209229e-003,0,,0,
1405532760.796,,4.500000e+001,2.980050e+002,3.632207e-005,0.000000e+000,-4.005509e-003,0.000000e+000,3,8.813556e-001,1.825000e+000,,,,,,,,,,,,,,,,,,0,4.000000e+000,5.000000e-001,5,1,0.000000e+000,0,,0,
1405532778.781,,4.500000e+001,2.979968e+002,3.620364e-005,0.000000e+000,-1.242274e-003,0.000000e+000,3,8.811542e-001,1.825000e+000,,,,,,,,,,,,,,,,,,0,4.000000e+000,5.000000e-001,5,1,1.651001e-002,0,,0,
1405532895.515,,4.000000e+001,2.980009e+002,3.600611e-005,0.000000e+000,-3.858030e-003,0.000000e+000,3,8.831147e-001,1.825000e+000,,,,,,,,,,,,,,,,,,0,4.000000e+000,5.000000e-001,5,1,8.209229e-003,0,,0,
1405532913.515,,4.000000e+001,2.980050e+002,3.606422e-005,0.000000e+000,-5.078461e-003,0.000000e+000,3,8.820922e-001,1.825000e+000,,,,,,,,,,,,,,,,,,0,4.000000e+000,5.000000e-001,5,1,0.000000e+000,0,,0,
1405532931.781,,4.000000e+001,2.979968e+002,3.617329e-005,0.000000e+000,-4.758659e-003,0.000000e+000,3,8.842099e-001,1.825000e+000,,,,,,,,,,,,,,,,,,0,4.000000e+000,5.000000e-001,5,1,0.000000e+000,0,,0,
1405533050.515,,3.500000e+001,2.980009e+002,3.564909e-005,0.000000e+000,-2.008144e-003,0.000000e+000,3,8.862046e-001,1.825000e+000,,,,,,,,,,,,,,,,,,0,4.000000e+000,5.000000e-001,5,1,8.209229e-003,0,,0,
1405533067.750,,3.500000e+001,2.979968e+002,3.572664e-005,0.000000e+000,-2.874044e-003,0.000000e+000,3,8.853481e-001,1.825000e+000,,,,,,,,,,,,,,,,,,0,4.000000e+000,5.000000e-001,5,1,1.651001e-002,0,,0,
1405533086.484,,3.500000e+001,2.979926e+002,3.566778e-005,0.000000e+000,-3.159787e-003,0.000000e+000,3,8.854211e-001,1.825000e+000,,,,,,,,,,,,,,,,,,0,4.000000e+000,5.000000e-001,5,1,8.300781e-003,0,,0,
1405533205.250,,3.000000e+001,2.980009e+002,3.532736e-005,0.000000e+000,-7.295802e-004,0.000000e+000,3,8.884437e-001,1.825000e+000,,,,,,,,,,,,,,,,,,0,4.000000e+000,5.000000e-001,5,1,8.209229e-003,0,,0,
1405533222.296,,3.000000e+001,2.980009e+002,3.540896e-005,0.000000e+000,-1.383086e-003,0.000000e+000,3,8.905053e-001,1.825000e+000,,,,,,,,,,,,,,,,,,0,4.000000e+000,5.000000e-001,5,1,8.209229e-003,0,,0,
1405533239.781,,3.000000e+001,2.980050e+002,3.542615e-005,0.000000e+000,-2.939802e-003,0.000000e+000,3,8.898190e-001,1.825000e+000,,,,,,,,,,,,,,,,,,0,4.000000e+000,5.000000e-001,5,1,0.000000e+000,0,,0,
1405533357.765,,2.500000e+001,2.980050e+002,3.517934e-005,0.000000e+000,-2.643982e-004,0.000000e+000,3,8.900887e-001,1.825000e+000,,,,,,,,,,,,,,,,,,0,4.000000e+000,5.000000e-001,5,1,0.000000e+000,0,,0,
1405533376.000,,2.500000e+001,2.980009e+002,3.534745e-005,0.000000e+000,-2.624716e-003,0.000000e+000,3,8.905437e-001,1.825000e+000,,,,,,,,,,,,,,,,,,0,4.000000e+000,5.000000e-001,5,1,8.209229e-003,0,,0,
1405533393.984,,2.500000e+001,2.979968e+002,3.519879e-005,0.000000e+000,-4.221661e-003,0.000000e+000,3,8.910792e-001,1.825000e+000,,,,,,,,,,,,,,,,,,0,4.000000e+000,5.000000e-001,5,1,0.000000e+000,0,,0,
1405533512.750,,2.000000e+001,2.979968e+002,3.482391e-005,0.000000e+000,-2.393252e-003,0.000000e+000,3,8.943049e-001,1.825000e+000,,,,,,,,,,,,,,,,,,0,4.000000e+000,5.000000e-001,5,1,0.000000e+000,0,,0,
1405533530.484,,2.000000e+001,2.980009e+002,3.479154e-005,0.000000e+000,-3.966243e-003,0.000000e+000,3,8.940583e-001,1.825000e+000,,,,,,,,,,,,,,,,,,0,4.000000e+000,5.000000e-001,5,1,8.209229e-003,0,,0,
1405533548.218,,2.000000e+001,2.980050e+002,3.478170e-005,0.000000e+000,8.924609e-004,0.000000e+000,3,8.923591e-001,1.825000e+000,,,,,,,,,,,,,,,,,,0,4.000000e+000,5.000000e-001,5,1,0.000000e+000,0,,0,
1405533666.234,,1.500000e+001,2.980009e+002,3.439670e-005,0.000000e+000,-2.035032e-003,0.000000e+000,3,8.949283e-001,1.825000e+000,,,,,,,,,,,,,,,,,,0,4.000000e+000,5.000000e-001,5,1,8.209229e-003,0,,0,
1405533683.968,,1.500000e+001,2.979926e+002,3.452044e-005,0.000000e+000,-1.488682e-003,0.000000e+000,3,8.970630e-001,1.825000e+000,,,,,,,,,,,,,,,,,,0,4.000000e+000,5.000000e-001,5,1,8.300781e-003,0,,0,
1405533702.203,,1.500000e+001,2.979968e+002,3.445113e-005,0.000000e+000,-4.959885e-003,0.000000e+000,3,8.974826e-001,1.825000e+000,,,,,,,,,,,,,,,,,,0,4.000000e+000,5.000000e-001,5,1,1.651001e-002,0,,0,
1405533838.703,,1.000000e+001,2.979968e+002,3.411292e-005,0.000000e+000,-3.293580e-003,0.000000e+000,3,8.975649e-001,1.825000e+000,,,,,,,,,,,,,,,,,,0,4.000000e+000,5.000000e-001,5,1,0.000000e+000,0,,0,
1405533856.187,,1.000000e+001,2.979968e+002,3.417121e-005,0.000000e+000,-3.189467e-003,0.000000e+000,3,8.963134e-001,1.825000e+000,,,,,,,,,,,,,,,,,,0,4.000000e+000,5.000000e-001,5,1,0.000000e+000,0,,0,
1405533874.171,,1.000000e+001,2.979968e+002,3.416339e-005,0.000000e+000,-2.834514e-003,0.000000e+000,3,8.982306e-001,1.825000e+000,,,,,,,,,,,,,,,,,,0,4.000000e+000,5.000000e-001,5,1,0.000000e+000,0,,0,
1405533992.687,,5.000000e+000,2.980050e+002,3.338555e-005,0.000000e+000,-3.593310e-003,0.000000e+000,3,9.023622e-001,1.825000e+000,,,,,,,,,,,,,,,,,,0,4.000000e+000,5.000000e-001,5,1,0.000000e+000,0,,0,
1405534011.250,,5.000000e+000,2.979968e+002,3.356715e-005,0.000000e+000,-5.834938e-003,0.000000e+000,3,9.021490e-001,1.825000e+000,,,,,,,,,,,,,,,,,,0,4.000000e+000,5.000000e-001,5,1,0.000000e+000,0,,0,
1405534028.234,,5.000000e+000,2.980009e+002,3.358733e-005,0.000000e+000,-8.862874e-003,0.000000e+000,3,9.017683e-001,1.825000e+000,,,,,,,,,,,,,,,,,,0,4.000000e+000,5.000000e-001,5,1,8.209229e-003,0,,0,
1405534163.484,,0.000000e+000,2.980009e+002,3.261325e-005,0.000000e+000,-4.715917e-003,0.000000e+000,3,9.011560e-001,1.825000e+000,,,,,,,,,,,,,,,,,,0,4.000000e+000,5.000000e-001,5,1,8.209229e-003,0,,0,
1405534181.718,,0.000000e+000,2.980009e+002,3.273797e-005,0.000000e+000,-5.997860e-003,0.000000e+000,3,9.051664e-001,1.825000e+000,,,,,,,,,,,,,,,,,,0,4.000000e+000,5.000000e-001,5,1,8.209229e-003,0,,0,
1405534198.953,,0.000000e+000,2.980009e+002,3.277095e-005,0.000000e+000,-5.903151e-003,0.000000e+000,3,9.042731e-001,1.825000e+000,,,,,,,,,,,,,,,,,,0,4.000000e+000,5.000000e-001,5,1,8.209229e-003,0,,0,
1405534317.468,,-5.000000e+000,2.980009e+002,3.121395e-005,0.000000e+000,-6.761734e-003,0.000000e+000,3,9.068254e-001,1.825000e+000,,,,,,,,,,,,,,,,,,0,4.000000e+000,5.000000e-001,5,1,8.209229e-003,0,,0,
1405534335.718,,-5.000000e+000,2.980050e+002,3.115671e-005,0.000000e+000,-7.441870e-003,0.000000e+000,3,9.054474e-001,1.825000e+000,,,,,,,,,,,,,,,,,,0,4.000000e+000,5.000000e-001,5,1,0.000000e+000,0,,0,
1405534354.015,,-5.000000e+000,2.980009e+002,3.097902e-005,0.000000e+000,-5.921957e-003,0.000000e+000,3,9.051321e-001,1.825000e+000,,,,,,,,,,,,,,,,,,0,4.000000e+000,5.000000e-001,5,1,8.209229e-003,0,,0,
1405534480.265,,-1.000000e+001,2.980009e+002,2.451672e-005,0.000000e+000,2.878771e-004,0.000000e+000,3,8.880326e-001,1.825000e+000,,,,,,,,,,,,,,,,,,0,4.000000e+000,5.000000e-001,5,1,8.209229e-003,0,,0,
1405534498.031,,-1.000000e+001,2.980009e+002,2.350176e-005,0.000000e+000,6.149380e-003,0.000000e+000,3,8.871049e-001,1.825000e+000,,,,,,,,,,,,,,,,,,0,4.000000e+000,5.000000e-001,5,1,8.209229e-003,0,,0,
1405534515.765,,-1.000000e+001,2.980009e+002,2.275008e-005,0.000000e+000,7.029998e-003,0.000000e+000,3,8.849144e-001,1.825000e+000,,,,,,,,,,,,,,,,,,0,4.000000e+000,5.000000e-001,5,1,8.209229e-003,0,,0,
1405534634.750,,-1.500000e+001,2.979968e+002,8.657529e-007,0.000000e+000,0.000000e+000,0.000000e+000,3,0.000000e+000,1.825000e+000,,,,,,,,,,,,,,,,,,0,4.000000e+000,5.000000e-001,5,1,0.000000e+000,0,,0,
1405534652.046,,-1.500000e+001,2.980009e+002,8.411106e-008,0.000000e+000,-9.950082e-001,0.000000e+000,3,0.000000e+000,1.825000e+000,,,,,,,,,,,,,,,,,,0,4.000000e+000,5.000000e-001,5,1,8.209229e-003,0,,0,
1405534687.765,,-1.500000e+001,2.979968e+002,-4.507598e-006,0.000000e+000,-2.205893e-001,0.000000e+000,3,5.188422e-001,1.825000e+000,,,,,,,,,,,,,,,,,,0,4.000000e+000,5.000000e-001,5,1,0.000000e+000,0,,0,
1405534804.531,,-2.000000e+001,2.980050e+002,-1.938657e-005,0.000000e+000,-2.874949e-002,0.000000e+000,3,9.002913e-001,1.825000e+000,,,,,,,,,,,,,,,,,,0,4.000000e+000,5.000000e-001,5,1,0.000000e+000,0,,0,
1405534822.765,,-2.000000e+001,2.980009e+002,-2.008671e-005,0.000000e+000,-2.344611e-002,0.000000e+000,3,9.096829e-001,1.825000e+000,,,,,,,,,,,,,,,,,,0,4.000000e+000,5.000000e-001,5,1,8.209229e-003,0,,0,
1405534840.750,,-2.000000e+001,2.980009e+002,-2.051588e-005,0.000000e+000,-2.271298e-002,0.000000e+000,3,9.095656e-001,1.825000e+000,,,,,,,,,,,,,,,,,,0,4.000000e+000,5.000000e-001,5,1,8.209229e-003,0,,0,
1405534958.765,,-2.500000e+001,2.980009e+002,-2.401417e-005,0.000000e+000,-5.875637e-003,0.000000e+000,3,9.282527e-001,1.825000e+000,,,,,,,,,,,,,,,,,,0,4.000000e+000,5.000000e-001,5,1,8.209229e-003,0,,0,
1405535024.703,,-2.500000e+001,2.980009e+002,-2.447757e-005,0.000000e+000,-8.772783e-004,0.000000e+000,3,9.335182e-001,1.825000e+000,,,,,,,,,,,,,,,,,,0,4.000000e+000,5.000000e-001,5,1,8.209229e-003,0,,0,
1405535042.187,,-2.500000e+001,2.979968e+002,-2.473843e-005,0.000000e+000,-2.319757e-003,0.000000e+000,3,9.344714e-001,1.825000e+000,,,,,,,,,,,,,,,,,,0,4.000000e+000,5.000000e-001,5,1,0.000000e+000,0,,0,
1405535160.671,,-3.000000e+001,2.980009e+002,-2.583253e-005,0.000000e+000,7.605316e-004,0.000000e+000,3,9.423149e-001,1.825000e+000,,,,,,,,,,,,,,,,,,0,4.000000e+000,5.000000e-001,5,1,8.209229e-003,0,,0,
1405535178.906,,-3.000000e+001,2.980009e+002,-2.587616e-005,0.000000e+000,3.178611e-004,0.000000e+000,3,9.426600e-001,1.825000e+000,,,,,,,,,,,,,,,,,,0,4.000000e+000,5.000000e-001,5,1,8.209229e-003,0,,0,
1405535196.906,,-3.000000e+001,2.980009e+002,-2.606405e-005,0.000000e+000,9.083244e-004,0.000000e+000,3,9.428927e-001,1.825000e+000,,,,,,,,,,,,,,,,,,0,4.000000e+000,5.000000e-001,5,1,8.209229e-003,0,,0,
1405535309.984,,-3.500000e+001,2.980091e+002,-2.683149e-005,0.000000e+000,5.653220e-003,0.000000e+000,3,9.507620e-001,1.825000e+000,,,,,,,,,,,,,,,,,,0,4.000000e+000,5.000000e-001,5,1,8.209229e-003,0,,0,
1405535352.625,,-3.500000e+001,2.980009e+002,-2.689180e-005,0.000000e+000,1.801840e-003,0.000000e+000,3,9.512002e-001,1.825000e+000,,,,,,,,,,,,,,,,,,0,4.000000e+000,5.000000e-001,5,1,8.209229e-003,0,,0,
1405535385.609,,-3.500000e+001,2.980009e+002,-2.684547e-005,0.000000e+000,8.823554e-003,0.000000e+000,3,9.470485e-001,1.825000e+000,,,,,,,,,,,,,,,,,,0,4.000000e+000,5.000000e-001,5,1,8.209229e-003,0,,0,
1405535521.593,,-4.000000e+001,2.979968e+002,-2.750269e-005,0.000000e+000,6.751784e-003,0.000000e+000,3,9.498258e-001,1.825000e+000,,,,,,,,,,,,,,,,,,0,4.000000e+000,5.000000e-001,5,1,0.000000e+000,0,,0,
1405535539.828,,-4.000000e+001,2.980050e+002,-2.734888e-005,0.000000e+000,6.723812e-003,0.000000e+000,3,9.496785e-001,1.825000e+000,,,,,,,,,,,,,,,,,,0,4.000000e+000,5.000000e-001,5,1,0.000000e+000,0,,0,
1405535558.093,,-4.000000e+001,2.980009e+002,-2.736918e-005,0.000000e+000,6.026529e-003,0.000000e+000,3,9.550688e-001,1.825000e+000,,,,,,,,,,,,,,,,,,0,4.000000e+000,5.000000e-001,5,1,8.209229e-003,0,,0,
1405535669.125,,-4.500000e+001,2.980050e+002,-2.789341e-005,0.000000e+000,1.236032e-002,0.000000e+000,3,9.619017e-001,1.825000e+000,,,,,,,,,,,,,,,,,,0,4.000000e+000,5.000000e-001,5,1,0.000000e+000,0,,0,
1405535686.859,,-4.500000e+001,2.980009e+002,-2.772865e-005,0.000000e+000,1.077016e-002,0.000000e+000,3,9.598637e-001,1.825000e+000,,,,,,,,,,,,,,,,,,0,4.000000e+000,5.000000e-001,5,1,8.209229e-003,0,,0,
1405535704.593,,-4.500000e+001,2.979968e+002,-2.781715e-005,0.000000e+000,1.120716e-002,0.000000e+000,3,9.586383e-001,1.825000e+000,,,,,,,,,,,,,,,,,,0,4.000000e+000,5.000000e-001,5,1,0.000000e+000,0,,0,
1405535822.828,,-5.000000e+001,2.980009e+002,-2.813583e-005,0.000000e+000,1.371265e-002,0.000000e+000,3,9.607749e-001,1.825000e+000,,,,,,,,,,,,,,,,,,0,4.000000e+000,5.000000e-001,5,1,8.209229e-003,0,,0,
1405535840.828,,-5.000000e+001,2.980050e+002,-2.812296e-005,0.000000e+000,1.439837e-002,0.000000e+000,3,9.619166e-001,1.825000e+000,,,,,,,,,,,,,,,,,,0,4.000000e+000,5.000000e-001,5,1,0.000000e+000,0,,0,
1405535859.312,,-5.000000e+001,2.980009e+002,-2.808720e-005,0.000000e+000,1.055321e-002,0.000000e+000,3,9.637861e-001,1.825000e+000,,,,,,,,,,,,,,,,,,0,4.000000e+000,5.000000e-001,5,1,8.209229e-003,0,,0,
1405536007.343,,-7.500000e+001,2.979968e+002,-2.966457e-005,0.000000e+000,3.258522e-002,0.000000e+000,3,9.611916e-001,1.825000e+000,,,,,,,,,,,,,,,,,,0,4.000000e+000,5.000000e-001,5,1,0.000000e+000,0,,0,
1405536025.078,,-7.500000e+001,2.980009e+002,-2.991110e-005,0.000000e+000,2.713061e-002,0.000000e+000,3,9.739645e-001,1.825000e+000,,,,,,,,,,,,,,,,,,0,4.000000e+000,5.000000e-001,5,1,8.209229e-003,0,,0,
1405536042.312,,-7.500000e+001,2.979968e+002,-2.976880e-005,0.000000e+000,2.441862e-002,0.000000e+000,3,9.721208e-001,1.825000e+000,,,,,,,,,,,,,,,,,,0,4.000000e+000,5.000000e-001,5,1,0.000000e+000,0,,0,
1405536173.046,,-1.000000e+002,2.979968e+002,-3.049684e-005,0.000000e+000,3.214543e-002,0.000000e+000,3,9.668628e-001,1.825000e+000,,,,,,,,,,,,,,,,,,0,4.000000e+000,5.000000e-001,5,1,0.000000e+000,0,,0,
1405536191.296,,-1.000000e+002,2.979968e+002,-3.064750e-005,0.000000e+000,3.580632e-002,0.000000e+000,3,9.533726e-001,1.825000e+000,,,,,,,,,,,,,,,,,,0,4.000000e+000,5.000000e-001,5,1,0.000000e+000,0,,0,
1405536226.781,,-1.000000e+002,2.980009e+002,-3.081088e-005,0.000000e+000,3.351916e-002,0.000000e+000,3,9.640223e-001,1.825000e+000,,,,,,,,,,,,,,,,,,0,4.000000e+000,5.000000e-001,5,1,8.209229e-003,0,,0,
1405536352.765,,-7.500000e+001,2.980009e+002,-3.037556e-005,0.000000e+000,2.977126e-002,0.000000e+000,3,9.711920e-001,1.825000e+000,,,,,,,,,,,,,,,,,,0,4.000000e+000,5.000000e-001,5,1,8.209229e-003,0,,0,
1405536370.500,,-7.500000e+001,2.980009e+002,-3.036385e-005,0.000000e+000,2.954549e-002,0.000000e+000,3,9.712041e-001,1.825000e+000,,,,,,,,,,,,,,,,,,0,4.000000e+000,5.000000e-001,5,1,8.209229e-003,0,,0,
1405536388.234,,-7.500000e+001,2.979968e+002,-3.034843e-005,0.000000e+000,2.956343e-002,0.000000e+000,3,9.713951e-001,1.825000e+000,,,,,,,,,,,,,,,,,,0,4.000000e+000,5.000000e-001,5,1,0.000000e+000,0,,0,
1405536519.546,,-5.000000e+001,2.979968e+002,-2.984577e-005,0.000000e+000,2.887774e-002,0.000000e+000,3,9.739289e-001,1.825000e+000,,,,,,,,,,,,,,,,,,0,4.000000e+000,5.000000e-001,5,1,0.000000e+000,0,,0,
1405536537.281,,-5.000000e+001,2.980050e+002,-2.984316e-005,0.000000e+000,2.856592e-002,0.000000e+000,3,9.742436e-001,1.825000e+000,,,,,,,,,,,,,,,,,,0,4.000000e+000,5.000000e-001,5,1,0.000000e+000,0,,0,
1405536555.515,,-5.000000e+001,2.979968e+002,-2.982923e-005,0.000000e+000,2.903081e-002,0.000000e+000,3,9.733954e-001,1.825000e+000,,,,,,,,,,,,,,,,,,0,4.000000e+000,5.000000e-001,5,1,0.000000e+000,0,,0,
1405536666.500,,-4.500000e+001,2.980009e+002,-2.972881e-005,0.000000e+000,2.872625e-002,0.000000e+000,3,9.745709e-001,1.825000e+000,,,,,,,,,,,,,,,,,,0,4.000000e+000,5.000000e-001,5,1,8.209229e-003,0,,0,
1405536684.812,,-4.500000e+001,2.980050e+002,-2.972380e-005,0.000000e+000,2.878679e-002,0.000000e+000,3,9.741554e-001,1.825000e+000,,,,,,,,,,,,,,,,,,0,4.000000e+000,5.000000e-001,5,1,0.000000e+000,0,,0,
1405536702.812,,-4.500000e+001,2.979968e+002,-2.971427e-005,0.000000e+000,2.896219e-002,0.000000e+000,3,9.739020e-001,1.825000e+000,,,,,,,,,,,,,,,,,,0,4.000000e+000,5.000000e-001,5,1,0.000000e+000,0,,0,
1405536820.312,,-4.000000e+001,2.980009e+002,-2.956972e-005,0.000000e+000,2.897505e-002,0.000000e+000,3,9.741693e-001,1.825000e+000,,,,,,,,,,,,,,,,,,0,4.000000e+000,5.000000e-001,5,1,8.209229e-003,0,,0,
1405536838.046,,-4.000000e+001,2.979968e+002,-2.957804e-005,0.000000e+000,2.902842e-002,0.000000e+000,3,9.737088e-001,1.825000e+000,,,,,,,,,,,,,,,,,,0,4.000000e+000,5.000000e-001,5,1,0.000000e+000,0,,0,
1405536855.531,,-4.000000e+001,2.979968e+002,-2.957237e-005,0.000000e+000,2.908674e-002,0.000000e+000,3,9.737905e-001,1.825000e+000,,,,,,,,,,,,,,,,,,0,4.000000e+000,5.000000e-001,5,1,0.000000e+000,0,,0,
1405536974.515,,-3.500000e+001,2.980009e+002,-2.944117e-005,0.000000e+000,2.858072e-002,0.000000e+000,3,9.737359e-001,1.825000e+000,,,,,,,,,,,,,,,,,,0,4.000000e+000,5.000000e-001,5,1,8.209229e-003,0,,0,
1405536992.765,,-3.500000e+001,2.980009e+002,-2.943696e-005,0.000000e+000,2.860860e-002,0.000000e+000,3,9.732956e-001,1.825000e+000,,,,,,,,,,,,,,,,,,0,4.000000e+000,5.000000e-001,5,1,8.209229e-003,0,,0,
1405537010.000,,-3.500000e+001,2.980009e+002,-2.943937e-005,0.000000e+000,2.873444e-002,0.000000e+000,3,9.734370e-001,1.825000e+000,,,,,,,,,,,,,,,,,,0,4.000000e+000,5.000000e-001,5,1,8.209229e-003,0,,0,
1405537128.750,,-3.000000e+001,2.980050e+002,-2.928365e-005,0.000000e+000,2.899694e-002,0.000000e+000,3,9.723333e-001,1.825000e+000,,,,,,,,,,,,,,,,,,0,4.000000e+000,5.000000e-001,5,1,0.000000e+000,0,,0,
1405537146.984,,-3.000000e+001,2.979926e+002,-2.928197e-005,0.000000e+000,2.903476e-002,0.000000e+000,3,9.719204e-001,1.825000e+000,,,,,,,,,,,,,,,,,,0,4.000000e+000,5.000000e-001,5,1,8.300781e-003,0,,0,
1405537165.218,,-3.000000e+001,2.979885e+002,-2.929094e-005,0.000000e+000,2.878161e-002,0.000000e+000,3,9.721327e-001,1.825000e+000,,,,,,,,,,,,,,,,,,0,4.000000e+000,5.000000e-001,5,1,0.000000e+000,0,,0,
1405537284.453,,-2.500000e+001,2.980009e+002,-2.911237e-005,0.000000e+000,2.888992e-002,0.000000e+000,3,9.710703e-001,1.825000e+000,,,,,,,,,,,,,,,,,,0,4.000000e+000,5.000000e-001,5,1,8.209229e-003,0,,0,
1405537302.187,,-2.500000e+001,2.979968e+002,-2.911991e-005,0.000000e+000,2.894242e-002,0.000000e+000,3,9.710008e-001,1.825000e+000,,,,,,,,,,,,,,,,,,0,4.000000e+000,5.000000e-001,5,1,0.000000e+000,0,,0,
1405537320.453,,-2.500000e+001,2.979968e+002,-2.911617e-005,0.000000e+000,2.869801e-002,0.000000e+000,3,9.707786e-001,1.825000e+000,,,,,,,,,,,,,,,,,,0,4.000000e+000,5.000000e-001,5,1,0.000000e+000,0,,0,
1405537436.781,,-2.000000e+001,2.980009e+002,-2.894752e-005,0.000000e+000,2.869833e-002,0.000000e+000,3,9.696691e-001,1.825000e+000,,,,,,,,,,,,,,,,,,0,4.000000e+000,5.000000e-001,5,1,8.209229e-003,0,,0,
1405537454.515,,-2.000000e+001,2.979968e+002,-2.894764e-005,0.000000e+000,2.873211e-002,0.000000e+000,3,9.697504e-001,1.825000e+000,,,,,,,,,,,,,,,,,,0,4.000000e+000,5.000000e-001,5,1,0.000000e+000,0,,0,
1405537471.750,,-2.000000e+001,2.980009e+002,-2.894459e-005,0.000000e+000,2.870061e-002,0.000000e+000,3,9.699271e-001,1.825000e+000,,,,,,,,,,,,,,,,,,0,4.000000e+000,5.000000e-001,5,1,8.209229e-003,0,,0,
1405537590.984,,-1.500000e+001,2.980009e+002,-2.875444e-005,0.000000e+000,2.848644e-002,0.000000e+000,3,9.682801e-001,1.825000e+000,,,,,,,,,,,,,,,,,,0,4.000000e+000,5.000000e-001,5,1,8.209229e-003,0,,0,
1405537609.234,,-1.500000e+001,2.980009e+002,-2.874978e-005,0.000000e+000,2.841972e-002,0.000000e+000,3,9.683748e-001,1.825000e+000,,,,,,,,,,,,,,,,,,0,4.000000e+000,5.000000e-001,5,1,8.209229e-003,0,,0,
1405537627.484,,-1.500000e+001,2.980009e+002,-2.874391e-005,0.000000e+000,2.833567e-002,0.000000e+000,3,9.687257e-001,1.825000e+000,,,,,,,,,,,,,,,,,,0,4.000000e+000,5.000000e-001,5,1,8.209229e-003,0,,0,
1405537747.781,,-1.000000e+001,2.979926e+002,-2.854932e-005,0.000000e+000,2.838077e-002,0.000000e+000,3,9.663455e-001,1.825000e+000,,,,,,,,,,,,,,,,,,0,4.000000e+000,5.000000e-001,5,1,8.300781e-003,0,,0,
1405537765.015,,-1.000000e+001,2.979926e+002,-2.854059e-005,0.000000e+000,2.849179e-002,0.000000e+000,3,9.664091e-001,1.825000e+000,,,,,,,,,,,,,,,,,,0,4.000000e+000,5.000000e-001,5,1,8.300781e-003,0,,0,
1405537783.265,,-1.000000e+001,2.979968e+002,-2.853714e-005,0.000000e+000,2.849802e-002,0.000000e+000,3,9.658842e-001,1.825000e+000,,,,,,,,,,,,,,,,,,0,4.000000e+000,5.000000e-001,5,1,0.000000e+000,0,,0,
1405537900.000,,-5.000000e+000,2.980009e+002,-2.831732e-005,0.000000e+000,2.808856e-002,0.000000e+000,3,9.637662e-001,1.825000e+000,,,,,,,,,,,,,,,,,,0,4.000000e+000,5.000000e-001,5,1,8.209229e-003,0,,0,
1405537917.796,,-5.000000e+000,2.980050e+002,-2.831163e-005,0.000000e+000,2.818221e-002,0.000000e+000,3,9.635383e-001,1.825000e+000,,,,,,,,,,,,,,,,,,0,4.000000e+000,5.000000e-001,5,1,0.000000e+000,0,,0,
1405537935.531,,-5.000000e+000,2.980009e+002,-2.832800e-005,0.000000e+000,2.806205e-002,0.000000e+000,3,9.644600e-001,1.825000e+000,,,,,,,,,,,,,,,,,,0,4.000000e+000,5.000000e-001,5,1,8.209229e-003,0,,0,
1405538054.281,,0.000000e+000,2.979968e+002,-2.807122e-005,0.000000e+000,2.752381e-002,0.000000e+000,3,9.618615e-001,1.825000e+000,,,,,,,,,,,,,,,,,,0,4.000000e+000,5.000000e-001,5,1,0.000000e+000,0,,0,
1405538072.515,,0.000000e+000,2.980009e+002,-2.805591e-005,0.000000e+000,2.782806e-002,0.000000e+000,3,9.612520e-001,1.825000e+000,,,,,,,,,,,,,,,,,,0,4.000000e+000,5.000000e-001,5,1,8.209229e-003,0,,0,
1405538089.781,,0.000000e+000,2.979968e+002,-2.805597e-005,0.000000e+000,2.781272e-002,0.000000e+000,3,9.613554e-001,1.825000e+000,,,,,,,,,,,,,,,,,,0,4.000000e+000,5.000000e-001,5,1,0.000000e+000,0,,0,
1405538207.515,,5.000000e+000,2.979968e+002,-2.777084e-005,0.000000e+000,2.746131e-002,0.000000e+000,3,9.583085e-001,1.825000e+000,,,,,,,,,,,,,,,,,,0,4.000000e+000,5.000000e-001,5,1,0.000000e+000,0,,0,
1405538225.750,,5.000000e+000,2.980009e+002,-2.776617e-005,0.000000e+000,2.730948e-002,0.000000e+000,3,9.586020e-001,1.825000e+000,,,,,,,,,,,,,,,,,,0,4.000000e+000,5.000000e-001,5,1,8.209229e-003,0,,0,
1405538242.484,,5.000000e+000,2.979968e+002,-2.776737e-005,0.000000e+000,2.712902e-002,0.000000e+000,3,9.580716e-001,1.825000e+000,,,,,,,,,,,,,,,,,,0,4.000000e+000,5.000000e-001,5,1,0.000000e+000,0,,0,
1405538367.234,,1.000000e+001,2.980050e+002,-2.745902e-005,0.000000e+000,2.624574e-002,0.000000e+000,3,9.552215e-001,1.825000e+000,,,,,,,,,,,,,,,,,,0,4.000000e+000,5.000000e-001,5,1,0.000000e+000,0,,0,
1405538385.484,,1.000000e+001,2.980050e+002,-2.743102e-005,0.000000e+000,2.643268e-002,0.000000e+000,3,9.544811e-001,1.825000e+000,,,,,,,,,,,,,,,,,,0,4.000000e+000,5.000000e-001,5,1,0.000000e+000,0,,0,
1405538403.734,,1.000000e+001,2.980009e+002,-2.745078e-005,0.000000e+000,2.655638e-002,0.000000e+000,3,9.546556e-001,1.825000e+000,,,,,,,,,,,,,,,,,,0,4.000000e+000,5.000000e-001,5,1,8.209229e-003,0,,0,
1405538522.500,,1.500000e+001,2.979968e+002,-2.709662e-005,0.000000e+000,2.567894e-002,0.000000e+000,3,9.513136e-001,1.825000e+000,,,,,,,,,,,,,,,,,,0,4.000000e+000,5.000000e-001,5,1,0.000000e+000,0,,0,
1405538539.796,,1.500000e+001,2.979968e+002,-2.710338e-005,0.000000e+000,2.578459e-002,0.000000e+000,3,9.514405e-001,1.825000e+000,,,,,,,,,,,,,,,,,,0,4.000000e+000,5.000000e-001,5,1,0.000000e+000,0,,0,
1405538557.828,,1.500000e+001,2.979968e+002,-2.708958e-005,0.000000e+000,2.565607e-002,0.000000e+000,3,9.511773e-001,1.825000e+000,,,,,,,,,,,,,,,,,,0,4.000000e+000,5.000000e-001,5,1,0.000000e+000,0,,0,
1405538675.843,,2.000000e+001,2.980009e+002,-2.667789e-005,0.000000e+000,2.479704e-002,0.000000e+000,3,9.470236e-001,1.825000e+000,,,,,,,,,,,,,,,,,,0,4.000000e+000,5.000000e-001,5,1,8.209229e-003,0,,0,
1405538694.078,,2.000000e+001,2.979968e+002,-2.666907e-005,0.000000e+000,2.462959e-002,0.000000e+000,3,9.473282e-001,1.825000e+000,,,,,,,,,,,,,,,,,,0,4.000000e+000,5.000000e-001,5,1,0.000000e+000,0,,0,
1405538711.812,,2.000000e+001,2.979926e+002,-2.666332e-005,0.000000e+000,2.482416e-002,0.000000e+000,3,9.468499e-001,1.825000e+000,,,,,,,,,,,,,,,,,,0,4.000000e+000,5.000000e-001,5,1,8.300781e-003,0,,0,
1405538830.578,,2.500000e+001,2.980009e+002,-2.607941e-005,0.000000e+000,2.353895e-002,0.000000e+000,3,9.417474e-001,1.825000e+000,,,,,,,,,,,,,,,,,,0,4.000000e+000,5.000000e-001,5,1,8.209229e-003,0,,0,
1405538848.812,,2.500000e+001,2.980050e+002,-2.607230e-005,0.000000e+000,2.316635e-002,0.000000e+000,3,9.418809e-001,1.825000e+000,,,,,,,,,,,,,,,,,,0,4.000000e+000,5.000000e-001,5,1,0.000000e+000,0,,0,
1405538866.109,,2.500000e+001,2.980009e+002,-2.606418e-005,0.000000e+000,2.304627e-002,0.000000e+000,3,9.416238e-001,1.825000e+000,,,,,,,,,,,,,,,,,,0,4.000000e+000,5.000000e-001,5,1,8.209229e-003,0,,0,
1405538979.656,,3.000000e+001,2.980050e+002,-2.502823e-005,0.000000e+000,2.061846e-002,0.000000e+000,3,9.343151e-001,1.825000e+000,,,,,,,,,,,,,,,,,,0,4.000000e+000,5.000000e-001,5,1,0.000000e+000,0,,0,
1405538996.953,,3.000000e+001,2.979968e+002,-2.498607e-005,0.000000e+000,2.074980e-002,0.000000e+000,3,9.340978e-001,1.825000e+000,,,,,,,,,,,,,,,,,,0,4.000000e+000,5.000000e-001,5,1,0.000000e+000,0,,0,
1405539014.187,,3.000000e+001,2.979968e+002,-2.493191e-005,0.000000e+000,2.056763e-002,0.000000e+000,3,9.341857e-001,1.825000e+000,,,,,,,,,,,,,,,,,,0,4.000000e+000,5.000000e-001,5,1,0.000000e+000,0,,0,
1405539127.218,,3.500000e+001,2.979968e+002,-2.057870e-005,0.000000e+000,3.121408e-002,0.000000e+000,3,9.154926e-001,1.825000e+000,,,,,,,,,,,,,,,,,,0,4.000000e+000,5.000000e-001,5,1,0.000000e+000,0,,0,
1405539145.203,,3.500000e+001,2.979968e+002,-2.003654e-005,0.000000e+000,3.309936e-002,0.000000e+000,3,9.128450e-001,1.825000e+000,,,,,,,,,,,,,,,,,,0,4.000000e+000,5.000000e-001,5,1,0.000000e+000,0,,0,
1405539162.203,,3.500000e+001,2.980009e+002,-1.954733e-005,0.000000e+000,3.542158e-002,0.000000e+000,3,9.102637e-001,1.825000e+000,,,,,,,,,,,,,,,,,,0,4.000000e+000,5.000000e-001,5,1,8.209229e-003,0,,0,
1405539280.453,,4.000000e+001,2.980009e+002,6.448282e-006,0.000000e+000,-3.727008e-001,0.000000e+000,3,7.262540e-001,1.825000e+000,,,,,,,,,,,,,,,,,,0,4.000000e+000,5.000000e-001,5,1,8.209229e-003,0,,0,
1405539299.437,,4.000000e+001,2.979968e+002,8.536365e-006,0.000000e+000,-2.624432e-001,0.000000e+000,3,7.858701e-001,1.825000e+000,,,,,,,,,,,,,,,,,,0,4.000000e+000,5.000000e-001,5,1,1.651001e-002,0,,0,
1405539316.734,,4.000000e+001,2.979926e+002,1.015804e-005,0.000000e+000,-2.130837e-001,0.000000e+000,3,8.158461e-001,1.825000e+000,,,,,,,,,,,,,,,,,,0,4.000000e+000,5.000000e-001,5,1,8.300781e-003,0,,0,
1405539430.234,,4.500000e+001,2.980050e+002,2.725288e-005,0.000000e+000,-4.521662e-002,0.000000e+000,3,9.181172e-001,1.825000e+000,,,,,,,,,,,,,,,,,,0,4.000000e+000,5.000000e-001,5,1,0.000000e+000,0,,0,
1405539448.000,,4.500000e+001,2.979968e+002,2.780935e-005,0.000000e+000,-4.198362e-002,0.000000e+000,3,9.193368e-001,1.825000e+000,,,,,,,,,,,,,,,,,,0,4.000000e+000,5.000000e-001,5,1,0.000000e+000,0,,0,
1405539466.296,,4.500000e+001,2.979968e+002,2.819340e-005,0.000000e+000,-3.960248e-002,0.000000e+000,3,9.201126e-001,1.825000e+000,,,,,,,,,,,,,,,,,,0,4.000000e+000,5.000000e-001,5,1,0.000000e+000,0,,0,
1405539585.546,,5.000000e+001,2.979968e+002,3.148156e-005,0.000000e+000,-2.221796e-002,0.000000e+000,3,9.203373e-001,1.825000e+000,,,,,,,,,,,,,,,,,,0,4.000000e+000,5.000000e-001,5,1,0.000000e+000,0,,0,
1405539604.281,,5.000000e+001,2.980009e+002,3.157725e-005,0.000000e+000,-2.216753e-002,0.000000e+000,3,9.207452e-001,1.825000e+000,,,,,,,,,,,,,,,,,,0,4.000000e+000,5.000000e-001,5,1,8.209229e-003,0,,0,
1405539622.515,,5.000000e+001,2.979968e+002,3.166045e-005,0.000000e+000,-2.193362e-002,0.000000e+000,3,9.208767e-001,1.825000e+000,,,,,,,,,,,,,,,,,,0,4.000000e+000,5.000000e-001,5,1,1.651001e-002,0,,0,
1405539765.234,,7.500000e+001,2.980050e+002,3.516220e-005,0.000000e+000,3.780816e-004,0.000000e+000,3,9.018837e-001,1.825000e+000,,,,,,,,,,,,,,,,,,0,4.000000e+000,5.000000e-001,5,1,0.000000e+000,0,,0,
1405539782.718,,7.500000e+001,2.980050e+002,3.516222e-005,0.000000e+000,4.781172e-004,0.000000e+000,3,9.017125e-001,1.825000e+000,,,,,,,,,,,,,,,,,,0,4.000000e+000,5.000000e-001,5,1,0.000000e+000,0,,0,
1405539800.203,,7.500000e+001,2.980050e+002,3.516619e-005,0.000000e+000,5.018419e-004,0.000000e+000,3,9.015674e-001,1.825000e+000,,,,,,,,,,,,,,,,,,0,4.000000e+000,5.000000e-001,5,1,0.000000e+000,0,,0,
1405539931.453,,1.000000e+002,2.980009e+002,3.622151e-005,0.000000e+000,5.396928e-003,0.000000e+000,3,8.885266e-001,1.825000e+000,,,,,,,,,,,,,,,,,,0,4.000000e+000,5.000000e-001,5,1,8.209229e-003,0,,0,
1405539949.687,,1.000000e+002,2.979968e+002,3.622968e-005,0.000000e+000,5.219299e-003,0.000000e+000,3,8.882433e-001,1.825000e+000,,,,,,,,,,,,,,,,,,0,4.000000e+000,5.000000e-001,5,1,0.000000e+000,0,,0,
1405539967.953,,1.000000e+002,2.979968e+002,3.622988e-005,0.000000e+000,5.412753e-003,0.000000e+000,3,8.882017e-001,1.825000e+000,,,,,,,,,,,,,,,,,,0,4.000000e+000,5.000000e-001,5,1,0.000000e+000,0,,0,