File: Sample Data Files/2014-07-16 EB on isolated PMN-PT no Ti spontaneous in situ/Ni-NiO_298K_SiO2_PMN-PT_5.0Tprebias_unpoled_Au_back.rso.raw
[Header]
TITLE,MPMS RSO Measurement
BYAPP,MPMS Measurement,2.1,Raw with ABS
FILEOPENTIME, 1405532254.156000 7/16/2014, 10:37:34 AM

INFO, APPNAME, MPMS MultiVu Application, Revision 1.58,  Build 076

INFO, NAME, EB in situ
INFO, WEIGHT, 0.000
INFO, AREA, 0.000
INFO, LENGTH, 0.000
INFO, SHAPE, 0
INFO, COMMENT,
INFO, SEQUENCE FILE: MHcurveUpTo100.seq


INFO, BACKGROUND DATA FILE:, None


STARTUPAXIS,X,8,LINEAR,AUTO,0.000000,0.000000
STARTUPAXIS,Y1,9,LINEAR,AUTO,0.000000,0.000000


STARTUPGROUP,Longitudinal
FIELDGROUP,Longitudinal,1,2,3,4,5,6,7,8,9,10,11,12,13,14,15,16,17,18,19,20,21,22
FIELDGROUP,Transverse,1,2,3,4,5,6,7,8,23,24,25,26,27,28,29,30,31,32,33,34,35,36

PLOT_APPEARANCE,ALL,HORZ_GRID_ON,VERT_GRID_ON,MARKERS_ONLY

[Data]
Time,Comment,Field (Oe),Start Temperature (K),End Temperature (K),Scan,Rejected,Position (cm),Long Voltage,Long Average Voltage,Long Detrended Voltage,Long Demeaned Voltage,Long Reg Fit,Long Detrended Fit,Long Demeaned Fit,Long Scaled Response,Long Avg. Scaled Response,Long Background Response,Long Response [w/ABS],Long Detrended Resp. [w/ABS],Long Fit [w/ABS],Long Detrended Fit [w/ABS],Trans Voltage,Trans Average Voltage,Trans Detrended Voltage,Trans Demeaned Voltage,Trans Reg Fit,Trans Detrended Fit,Trans Demeaned Fit,Trans Scaled Response,Trans Avg. Scaled Response,Trans Background Response,Trans Response [w/ABS],Trans Detrended Resp. [w/ABS],Trans Adjusted Fit,Trans Detrended Fit [w/ABS],
1405532254.140,,1.000000e+002,2.979968e+002,2.980050e+002,1,0,2.079679e+000,-1.246986e+000,-1.246986e+000,5.469978e-002,5.469978e-002,-1.242859e+000,5.882752e-002,5.882752e-002,-1.358746e-003,-1.358746e-003,,,,,,,,,,,,,,,,,,,,
1405532254.140,,1.000000e+002,2.979968e+002,2.980050e+002,1,0,3.705796e+000,-1.570635e+000,-1.570635e+000,-2.707895e-002,-2.689490e-001,-1.569308e+000,-2.575143e-002,-2.676215e-001,-1.711402e-003,-1.711402e-003,,,,,,,,,,,,,,,,,,,,
1405532272.046,,1.000000e+002,2.980050e+002,2.979968e+002,1,0,4.358971e-001,-1.299478e+000,-1.299478e+000,-2.477227e-002,-1.354359e-001,-1.300552e+000,-2.584658e-002,-1.365103e-001,-1.415943e-003,-1.415943e-003,,,,,,,,,,,,,,,,,,,,
1405532289.781,,1.000000e+002,2.979968e+002,2.979968e+002,1,0,1.899970e+000,-8.592486e-001,-8.592486e-001,5.351197e-002,4.898244e-002,-8.539131e-001,5.884748e-002,5.431795e-002,-9.362580e-004,-9.362580e-004,,,,,,,,,,,,,,,,,,,,
1405532289.781,,1.000000e+002,2.979968e+002,2.979968e+002,1,0,3.810075e+000,-1.134983e+000,-1.134983e+000,-2.745301e-002,-2.267523e-001,-1.131744e+000,-2.421398e-002,-2.235133e-001,-1.236705e-003,-1.236705e-003,,,,,,,,,,,,,,,,,,,,
1405532413.812,,7.500000e+001,2.979968e+002,2.980050e+002,1,0,5.562802e-001,-4.780725e-001,-4.780725e-001,-2.048084e-002,-6.793389e-002,-4.807581e-001,-2.316644e-002,-7.061949e-002,-5.209204e-004,-5.209204e-004,,,,,,,,,,,,,,,,,,,,
1405532431.265,,7.500000e+001,2.980050e+002,2.979968e+002,1,0,1.719063e+000,-3.814813e-001,-3.814814e-001,4.908673e-002,4.449159e-002,-3.802452e-001,5.032293e-002,4.572779e-002,-4.156722e-004,-4.156722e-004,,,,,,,,,,,,,,,,,,,,
1405532431.265,,7.500000e+001,2.980050e+002,2.979968e+002,1,0,3.893694e+000,-5.569628e-001,-5.569628e-001,-2.759923e-002,-1.309898e-001,-5.515118e-001,-2.214821e-002,-1.255388e-001,-6.068815e-004,-6.068815e-004,,,,,,,,,,,,,,,,,,,,
1405532448.000,,7.500000e+001,2.979968e+002,2.980050e+002,1,0,6.831868e-001,-5.684072e-001,-5.684072e-001,-1.395163e-002,-6.667340e-002,-5.733081e-001,-1.885245e-002,-7.157421e-002,-6.193516e-004,-6.193516e-004,,,,,,,,,,,,,,,,,,,,
1405532594.328,,5.000000e+001,2.980050e+002,2.979968e+002,1,0,1.538682e+000,-1.408734e+000,-1.408734e+000,1.942658e-001,1.708336e-001,-1.417067e+000,1.859328e-001,1.625006e-001,-3.069996e-004,-3.069996e-004,,,,,,,,,,,,,,,,,,,,
1405532594.328,,5.000000e+001,2.980050e+002,2.979968e+002,1,0,3.953475e+000,-2.065950e+000,-2.065950e+000,-1.270891e-001,-4.863824e-001,-2.040970e+000,-1.021086e-001,-4.614018e-001,-4.502239e-004,-4.502239e-004,,,,,,,,,,,,,,,,,,,,
1405532612.578,,5.000000e+001,2.979968e+002,2.979968e+002,1,0,8.157927e-001,-2.415998e+000,-2.415998e+000,-4.027645e-002,-2.693148e-001,-2.438612e+000,-6.289092e-002,-2.919292e-001,-5.265083e-004,-5.265083e-004,,,,,,,,,,,,,,,,,,,,
1405532630.812,,5.000000e+001,2.979968e+002,2.980050e+002,1,0,1.361287e+000,-2.013764e+000,-2.013764e+000,1.324330e-001,9.784293e-002,-2.030674e+000,1.155229e-001,8.093286e-002,-4.388511e-004,-4.388511e-004,,,,,,,,,,,,,,,,,,,,
1405532630.812,,5.000000e+001,2.979968e+002,2.980050e+002,1,0,3.987472e+000,-2.648701e+000,-2.648701e+000,-1.306618e-001,-5.370946e-001,-2.614793e+000,-9.675344e-002,-5.031862e-001,-5.772204e-004,-5.772204e-004,,,,,,,,,,,,,,,,,,,,
1405532743.062,,4.500000e+001,2.979968e+002,2.980050e+002,1,0,9.540667e-001,-1.484420e+000,-1.484420e+000,1.842937e-003,-1.423786e-001,-1.508256e+000,-2.199308e-002,-1.662146e-001,-3.234936e-004,-3.234936e-004,,,,,,,,,,,,,,,,,,,,
1405532760.796,,4.500000e+001,2.980050e+002,2.980050e+002,1,0,1.186926e+000,-1.697745e+000,-1.697745e+000,7.377040e-002,3.722608e-002,-1.717629e+000,5.388569e-002,1.734138e-002,-3.699825e-004,-3.699825e-004,,,,,,,,,,,,,,,,,,,,
1405532760.796,,4.500000e+001,2.980050e+002,2.980050e+002,1,0,3.994368e+000,-2.215796e+000,-2.215796e+000,-1.300002e-001,-4.808257e-001,-2.181244e+000,-9.544811e-002,-4.462736e-001,-4.828794e-004,-4.828794e-004,,,,,,,,,,,,,,,,,,,,
1405532778.781,,4.500000e+001,2.980050e+002,2.979885e+002,1,0,1.098474e+000,-1.957305e+000,-1.957305e+000,4.671577e-002,-1.648601e-001,-1.981314e+000,2.270666e-002,-1.888692e-001,-4.265474e-004,-4.265474e-004,,,,,,,,,,,,,,,,,,,,
1405532895.515,,4.000000e+001,2.979968e+002,2.980050e+002,1,0,1.018342e+000,-1.554765e+000,-1.554765e+000,2.134739e-002,-1.616883e-002,-1.578561e+000,-2.448454e-003,-3.996468e-002,-3.388238e-004,-3.388238e-004,,,,,,,,,,,,,,,,,,,,
1405532895.515,,4.000000e+001,2.979968e+002,2.980050e+002,1,0,3.974715e+000,-1.974242e+000,-1.974242e+000,-1.292632e-001,-4.356457e-001,-1.941867e+000,-9.688788e-002,-4.032704e-001,-4.302388e-004,-4.302388e-004,,,,,,,,,,,,,,,,,,,,
1405532913.515,,4.000000e+001,2.980050e+002,2.980050e+002,1,0,1.249575e+000,-1.706748e+000,-1.706748e+000,9.883781e-002,-1.003020e-001,-1.729764e+000,7.582135e-002,-1.233184e-001,-3.719447e-004,-3.719447e-004,,,,,,,,,,,,,,,,,,,,
1405532931.781,,4.000000e+001,2.979968e+002,2.979968e+002,1,0,8.549630e-001,-1.786096e+000,-1.786096e+000,-2.439211e-002,-7.330918e-002,-1.812235e+000,-5.053137e-002,-9.944844e-002,-3.892367e-004,-3.892367e-004,,,,,,,,,,,,,,,,,,,,
1405532931.781,,4.000000e+001,2.979968e+002,2.979968e+002,1,0,3.929897e+000,-2.192145e+000,-2.192145e+000,-1.299504e-001,-4.793581e-001,-2.164468e+000,-1.022741e-001,-4.516817e-001,-4.777253e-004,-4.777253e-004,,,,,,,,,,,,,,,,,,,,
1405533050.515,,3.500000e+001,2.980050e+002,2.979968e+002,1,0,1.407904e+000,-1.193121e+000,-1.193121e+000,1.448944e-001,1.067114e-002,-1.207592e+000,1.304237e-001,-3.799558e-003,-2.600123e-004,-2.600123e-004,,,,,,,,,,,,,,,,,,,,
1405533067.750,,3.500000e+001,2.979885e+002,2.980050e+002,1,0,6.991469e-001,-1.308176e+000,-1.308176e+000,-6.672689e-002,-1.055124e-001,-1.328708e+000,-8.725926e-002,-1.260448e-001,-2.850857e-004,-2.850857e-004,,,,,,,,,,,,,,,,,,,,
1405533067.750,,3.500000e+001,2.979885e+002,2.980050e+002,1,0,3.862914e+000,-1.579028e+000,-1.579028e+000,-1.291067e-001,-3.763641e-001,-1.558023e+000,-1.081022e-001,-3.553597e-001,-3.441114e-004,-3.441114e-004,,,,,,,,,,,,,,,,,,,,
1405533086.484,,3.500000e+001,2.979885e+002,2.979968e+002,1,0,1.573160e+000,-1.270333e+000,-1.270333e+000,1.960305e-001,2.745211e-002,-1.276772e+000,1.895911e-001,2.101266e-002,-2.768387e-004,-2.768387e-004,,,,,,,,,,,,,,,,,,,,
1405533205.250,,3.000000e+001,2.979968e+002,2.980050e+002,1,0,5.524002e-001,-1.003601e+000,-1.003601e+000,-9.468978e-002,-1.255494e-001,-1.018549e+000,-1.096377e-001,-1.404973e-001,-2.187110e-004,-2.187110e-004,,,,,,,,,,,,,,,,,,,,
1405533205.250,,3.000000e+001,2.979968e+002,2.980050e+002,1,0,3.777310e+000,-1.183813e+000,-1.183813e+000,-1.274613e-001,-3.057612e-001,-1.170555e+000,-1.142032e-001,-2.925031e-001,-2.579839e-004,-2.579839e-004,,,,,,,,,,,,,,,,,,,,
1405533222.296,,3.000000e+001,2.979968e+002,2.980050e+002,1,0,1.744761e+000,-1.017029e+000,-1.017029e+000,2.286725e-001,1.058663e-001,-1.006092e+000,2.396095e-001,1.168033e-001,-2.216373e-004,-2.216373e-004,,,,,,,,,,,,,,,,,,,,
1405533239.781,,3.000000e+001,2.980050e+002,2.980050e+002,1,0,4.168230e-001,-1.097446e+000,-1.097446e+000,-1.109815e-001,-1.474596e-001,-1.105820e+000,-1.193556e-001,-1.558337e-001,-2.391622e-004,-2.391622e-004,,,,,,,,,,,,,,,,,,,,
1405533239.781,,3.000000e+001,2.980050e+002,2.980050e+002,1,0,3.676918e+000,-1.265297e+000,-1.265297e+000,-1.219778e-001,-3.153114e-001,-1.262694e+000,-1.193748e-001,-3.127084e-001,-2.757415e-004,-2.757415e-004,,,,,,,,,,,,,,,,,,,,
1405533357.765,,2.500000e+001,2.980050e+002,2.980050e+002,1,0,1.921388e+000,-5.600147e-001,-5.600147e-001,2.446885e-001,1.700496e-001,-5.357295e-001,2.689736e-001,1.943348e-001,-1.220419e-004,-1.220419e-004,,,,,,,,,,,,,,,,,,,,
1405533376.000,,2.500000e+001,2.979968e+002,2.980050e+002,1,0,2.951133e-001,-1.017029e+000,-1.017029e+000,-1.191463e-001,-1.476535e-001,-1.016268e+000,-1.183851e-001,-1.468922e-001,-2.216375e-004,-2.216375e-004,,,,,,,,,,,,,,,,,,,,
1405533376.000,,2.500000e+001,2.979968e+002,2.980050e+002,1,0,3.565041e+000,-1.124149e+000,-1.124149e+000,-1.148293e-001,-2.547736e-001,-1.128000e+000,-1.186796e-001,-2.586239e-001,-2.449817e-004,-2.449817e-004,,,,,,,,,,,,,,,,,,,,
1405533393.984,,2.500000e+001,2.979968e+002,2.979968e+002,1,0,2.101141e+000,-7.213050e-001,-7.213050e-001,2.454462e-001,1.456529e-001,-7.004223e-001,2.663288e-001,1.665355e-001,-1.571913e-004,-1.571913e-004,,,,,,,,,,,,,,,,,,,,
1405533512.750,,2.000000e+001,2.979968e+002,2.979968e+002,1,0,1.908478e-001,-4.915006e-001,-4.915006e-001,-1.198034e-001,-1.246320e-001,-4.821661e-001,-1.104689e-001,-1.152976e-001,-1.071110e-004,-1.071110e-004,,,,,,,,,,,,,,,,,,,,
1405533512.750,,2.000000e+001,2.979968e+002,2.979968e+002,1,0,3.444707e+000,-4.857021e-001,-4.857021e-001,-9.670213e-002,-1.188335e-001,-4.971006e-001,-1.081006e-001,-1.302320e-001,-1.058473e-004,-1.058473e-004,,,,,,,,,,,,,,,,,,,,
1405533530.484,,2.000000e+001,2.979968e+002,2.980050e+002,1,0,2.281953e+000,-4.004028e-001,-4.004028e-001,2.164827e-001,1.689554e-001,-3.898114e-001,2.270742e-001,1.795469e-001,-8.725836e-005,-8.725836e-005,,,,,,,,,,,,,,,,,,,,
1405533548.218,,2.000000e+001,2.980050e+002,2.980050e+002,1,0,1.072767e-001,-1.059603e+000,-1.059603e+000,-1.160449e-001,-1.570858e-001,-1.046112e+000,-1.025543e-001,-1.435953e-001,-2.309154e-004,-2.309154e-004,,,,,,,,,,,,,,,,,,,,
1405533548.218,,2.000000e+001,2.980050e+002,2.980050e+002,1,0,3.317796e+000,-1.151616e+000,-1.151616e+000,-7.230739e-002,-2.490992e-001,-1.167866e+000,-8.855716e-002,-2.653490e-001,-2.509675e-004,-2.509675e-004,,,,,,,,,,,,,,,,,,,,
1405533666.234,,1.500000e+001,2.980050e+002,2.979968e+002,1,0,2.462303e+000,-2.652059e-001,-2.652059e-001,1.743050e-001,1.448535e-001,-2.702438e-001,1.692671e-001,1.398156e-001,-5.779539e-005,-5.779539e-005,,,,,,,,,,,,,,,,,,,,
1405533683.968,,1.500000e+001,2.979968e+002,2.979885e+002,1,0,4.740111e-002,-8.122501e-001,-8.122501e-001,-1.143598e-001,-1.409507e-001,-7.937490e-001,-9.585869e-002,-1.224496e-001,-1.770108e-004,-1.770108e-004,,,,,,,,,,,,,,,,,,,,
1405533683.968,,1.500000e+001,2.979968e+002,2.979885e+002,1,0,3.185178e+000,-8.230842e-001,-8.230842e-001,-4.352161e-002,-1.517848e-001,-8.394409e-001,-5.987832e-002,-1.681415e-001,-1.793719e-004,-1.793719e-004,,,,,,,,,,,,,,,,,,,,
1405533702.203,,1.500000e+001,2.979885e+002,2.980050e+002,1,0,2.639990e+000,-6.688131e-001,-6.688131e-001,1.214537e-001,4.470176e-002,-6.833433e-001,1.069235e-001,3.017157e-002,-1.457521e-004,-1.457521e-004,,,,,,,,,,,,,,,,,,,,
1405533838.703,,1.000000e+001,2.979968e+002,2.979968e+002,1,0,1.347587e-002,-1.385388e+000,-1.385388e+000,-2.225133e-001,-2.557474e-001,-1.345454e+000,-1.825792e-001,-2.158134e-001,-1.509564e-004,-1.509564e-004,,,,,,,,,,,,,,,,,,,,
1405533838.703,,1.000000e+001,2.979968e+002,2.979968e+002,1,0,3.046933e+000,-1.267892e+000,-1.267892e+000,-9.745812e-003,-1.382512e-001,-1.304871e+000,-4.672537e-002,-1.752307e-001,-1.381536e-004,-1.381536e-004,,,,,,,,,,,,,,,,,,,,
1405533856.187,,1.000000e+001,2.979968e+002,2.979968e+002,1,0,2.813656e+000,-6.797998e-001,-6.797998e-001,1.359873e-001,9.685284e-002,-7.194853e-001,9.630185e-002,5.716735e-002,-7.407324e-005,-7.407324e-005,,,,,,,,,,,,,,,,,,,,
1405533874.171,,1.000000e+001,2.979968e+002,2.979968e+002,1,0,6.576251e-003,-1.219367e+000,-1.219367e+000,-2.243445e-001,-2.546524e-001,-1.176272e+000,-1.812498e-001,-2.115577e-001,-1.328663e-004,-1.328663e-004,,,,,,,,,,,,,,,,,,,,
1405533874.171,,1.000000e+001,2.979968e+002,2.979968e+002,1,0,2.902587e+000,-9.959716e-001,-9.959716e-001,8.050355e-002,-3.125697e-002,-1.036837e+000,3.963824e-002,-7.212228e-002,-1.085244e-004,-1.085244e-004,,,,,,,,,,,,,,,,,,,,
1405533992.687,,5.000000e+000,2.980050e+002,2.980050e+002,1,0,2.982888e+000,-7.519761e-001,-7.519761e-001,2.876859e-002,-2.208579e-002,-7.903415e-001,-9.596834e-003,-6.045121e-002,-8.193784e-005,-8.193784e-005,,,,,,,,,,,,,,,,,,,,
1405534011.250,,5.000000e+000,2.979968e+002,2.979968e+002,1,0,2.626210e-002,-1.314432e+000,-1.314432e+000,-2.219596e-001,-2.611334e-001,-1.275380e+000,-1.829077e-001,-2.220815e-001,-1.432249e-004,-1.432249e-004,,,,,,,,,,,,,,,,,,,,
1405534011.250,,5.000000e+000,2.979968e+002,2.979968e+002,1,0,2.751430e+000,-1.025575e+000,-1.025575e+000,1.659848e-001,2.772415e-002,-1.058263e+000,1.332961e-001,-4.964471e-003,-1.117500e-004,-1.117500e-004,,,,,,,,,,,,,,,,,,,,
1405534028.234,,5.000000e+000,2.980050e+002,2.979968e+002,1,0,3.145737e+000,-9.718620e-001,-9.718620e-001,-5.714132e-002,-1.340683e-001,-1.015718e+000,-1.009975e-001,-1.779245e-001,-1.058973e-004,-1.058973e-004,,,,,,,,,,,,,,,,,,,,
1405534163.484,,0.000000e+000,2.979968e+002,2.980050e+002,1,0,7.099834e-002,-9.643849e-001,-9.643849e-001,-5.332354e-001,-4.842080e-001,-8.972962e-001,-4.661466e-001,-4.171193e-001,-4.203307e-005,-4.203307e-005,,,,,,,,,,,,,,,,,,,,
1405534163.484,,0.000000e+000,2.979968e+002,2.980050e+002,1,0,2.593190e+000,3.149510e-001,3.149510e-001,6.289797e-001,7.951279e-001,2.696354e-001,5.836641e-001,7.498122e-001,1.372725e-005,1.372725e-005,,,,,,,,,,,,,,,,,,,,
1405534181.718,,0.000000e+000,2.980050e+002,2.979968e+002,1,0,3.301583e+000,-1.444288e+000,-1.444288e+000,-3.253976e-001,-2.901618e-001,-1.527406e+000,-4.085152e-001,-3.732795e-001,-6.294983e-005,-6.294983e-005,,,,,,,,,,,,,,,,,,,,
1405534198.953,,0.000000e+000,2.979968e+002,2.980050e+002,1,0,1.380251e-001,-2.438887e+000,-2.438887e+000,-5.612679e-001,-5.839143e-001,-2.377650e+000,-5.000310e-001,-5.226774e-001,-1.062998e-004,-1.062998e-004,,,,,,,,,,,,,,,,,,,,
1405534198.953,,0.000000e+000,2.979968e+002,2.980050e+002,1,0,2.427872e+000,-1.065706e+000,-1.065706e+000,8.631648e-001,7.892660e-001,-1.073782e+000,8.550893e-001,7.811905e-001,-4.644920e-005,-4.644920e-005,,,,,,,,,,,,,,,,,,,,
1405534317.468,,-5.000000e+000,2.980050e+002,2.979968e+002,1,0,3.448576e+000,-1.313364e+000,-1.313364e+000,-4.397662e-001,-3.375313e-001,-1.362060e+000,-4.884623e-001,-3.862274e-001,-5.724343e-005,-5.724343e-005,,,,,,,,,,,,,,,,,,,,
1405534335.718,,-5.000000e+000,2.980050e+002,2.980050e+002,1,0,2.235842e-001,-2.146672e+000,-2.146672e+000,-5.418343e-001,-5.711579e-001,-2.111150e+000,-5.063118e-001,-5.356355e-001,-9.356344e-005,-9.356344e-005,,,,,,,,,,,,,,,,,,,,
1405534335.718,,-5.000000e+000,2.980050e+002,2.980050e+002,1,0,2.256165e+000,-6.814783e-001,-6.814783e-001,9.864053e-001,8.940358e-001,-6.247616e-001,1.043122e+000,9.507524e-001,-2.970247e-005,-2.970247e-005,,,,,,,,,,,,,,,,,,,,
1405534354.015,,-5.000000e+000,2.980050e+002,2.979968e+002,1,0,3.584201e+000,-2.054659e+000,-2.054659e+000,-5.021527e-001,-5.599818e-001,-2.075490e+000,-5.229836e-001,-5.808127e-001,-8.955300e-005,-8.955300e-005,,,,,,,,,,,,,,,,,,,,
1405534480.265,,-1.000000e+001,2.979968e+002,2.980050e+002,1,0,3.240724e-001,-1.897336e+000,-1.897336e+000,-4.132095e-001,-4.593054e-001,-1.897520e+000,-4.133940e-001,-4.594899e-001,-8.269599e-005,-8.269599e-005,,,,,,,,,,,,,,,,,,,,
1405534498.031,,-1.000000e+001,2.979968e+002,2.980050e+002,1,0,2.079628e+000,2.731407e-002,2.731407e-002,8.301697e-001,8.301697e-001,9.698830e-002,8.998439e-001,8.998439e-001,1.190492e-006,1.190492e-006,,,,,,,,,,,,,,,,,,,,
1405534498.031,,-1.000000e+001,2.979968e+002,2.980050e+002,1,0,3.705766e+000,-1.318705e+000,-1.318705e+000,-4.137952e-001,-5.158492e-001,-1.298794e+000,-3.938845e-001,-4.959385e-001,-5.747618e-005,-5.747618e-005,,,,,,,,,,,,,,,,,,,,
1405534515.765,,-1.000000e+001,2.979968e+002,2.980050e+002,1,0,4.358892e-001,-1.659597e+000,-1.659597e+000,-3.587045e-001,-4.040371e-001,-1.683207e+000,-3.823145e-001,-4.276471e-001,-7.233406e-005,-7.233406e-005,,,,,,,,,,,,,,,,,,,,
1405534634.750,,-1.500000e+001,2.979968e+002,2.979968e+002,1,0,1.900128e+000,6.054872e-001,6.054872e-001,-2.235276e-002,-1.906151e-002,6.606709e-001,3.283088e-002,3.612214e-002,2.639034e-005,2.639034e-005,,,,,,,,,,,,,,,,,,,,
1405534634.750,,-1.500000e+001,2.979968e+002,2.979968e+002,1,0,3.810066e+000,7.022309e-001,7.022309e-001,-6.713321e-002,7.768220e-002,7.556646e-001,-1.369950e-002,1.311159e-001,3.060695e-005,3.060695e-005,,,,,,,,,,,,,,,,,,,,
1405534652.046,,-1.500000e+001,2.979968e+002,2.980050e+002,1,0,5.561831e-001,1.013367e+000,1.013367e+000,5.092847e-002,1.776538e-001,9.645721e-001,2.133490e-003,1.288589e-001,4.416791e-005,4.416791e-005,,,,,,,,,,,,,,,,,,,,
1405534687.765,,-1.500000e+001,2.979968e+002,2.979968e+002,1,0,1.719126e+000,-2.093417e+000,-2.093417e+000,-3.794606e-001,-4.007666e-001,-2.060418e+000,-3.464615e-001,-3.677676e-001,-4.562111e-005,-4.562111e-005,,,,,,,,,,,,,,,,,,,,
1405534687.765,,-1.500000e+001,2.979968e+002,2.979968e+002,1,0,3.893624e+000,-2.208319e+000,-2.208319e+000,-3.628289e-002,-5.156689e-001,-2.070431e+000,1.016053e-001,-3.777807e-001,-4.812513e-005,-4.812513e-005,,,,,,,,,,,,,,,,,,,,
1405534804.531,,-2.000000e+001,2.980050e+002,2.980050e+002,1,0,6.830057e-001,3.638569e+000,3.638569e+000,5.703324e-001,6.973488e-001,3.531004e+000,4.627670e-001,5.897834e-001,7.929403e-005,7.929403e-005,,,,,,,,,,,,,,,,,,,,
1405534822.765,,-2.000000e+001,2.980050e+002,2.979968e+002,1,0,1.538903e+000,9.022797e-001,9.022797e-001,-1.031281e+000,-1.012703e+000,8.928285e-001,-1.040732e+000,-1.022154e+000,1.966306e-005,1.966306e-005,,,,,,,,,,,,,,,,,,,,
1405534822.765,,-2.000000e+001,2.980050e+002,2.979968e+002,1,0,3.953513e+000,2.615894e+000,2.615894e+000,4.160487e-001,7.009112e-001,2.741378e+000,5.415322e-001,8.263947e-001,5.700724e-005,5.700724e-005,,,,,,,,,,,,,,,,,,,,
1405534840.750,,-2.000000e+001,2.979968e+002,2.980050e+002,1,0,8.155761e-001,2.303690e+000,2.303690e+000,4.303895e-001,3.834482e-001,2.192460e+000,3.191593e-001,2.722181e-001,5.020348e-005,5.020348e-005,,,,,,,,,,,,,,,,,,,,
1405534958.765,,-2.500000e+001,2.979968e+002,2.980050e+002,1,0,1.361156e+000,2.142399e+000,2.142399e+000,-7.014848e-001,-6.854651e-001,2.069561e+000,-7.743236e-001,-7.583039e-001,4.668852e-005,4.668852e-005,,,,,,,,,,,,,,,,,,,,
1405534958.765,,-2.500000e+001,2.979968e+002,2.980050e+002,1,0,3.987438e+000,3.518326e+000,3.518326e+000,5.022303e-001,6.904619e-001,3.651031e+000,6.349348e-001,8.231664e-001,7.667359e-005,7.667359e-005,,,,,,,,,,,,,,,,,,,,
1405535024.703,,-2.500000e+001,2.980050e+002,2.979968e+002,1,0,9.538722e-001,1.478469e+000,1.478469e+000,2.611974e-001,2.009714e-001,1.374817e+000,1.575448e-001,9.731877e-002,3.221973e-005,3.221973e-005,,,,,,,,,,,,,,,,,,,,
1405535042.187,,-2.500000e+001,2.979968e+002,2.979968e+002,1,0,1.187184e+000,3.167821e-001,3.167821e-001,-2.935711e-001,-3.370597e-001,2.467318e-001,-3.636214e-001,-4.071101e-001,6.903516e-006,6.903516e-006,,,,,,,,,,,,,,,,,,,,
1405535042.187,,-2.500000e+001,2.979968e+002,2.979968e+002,1,0,3.994419e+000,7.663198e-001,7.663198e-001,5.299691e-001,1.124779e-001,8.877276e-001,6.513770e-001,2.338858e-001,1.670012e-005,1.670012e-005,,,,,,,,,,,,,,,,,,,,
1405535160.671,,-3.000000e+001,2.980050e+002,2.979968e+002,1,0,1.098204e+000,2.183447e+000,2.183447e+000,-8.310843e-002,3.448486e-003,2.109916e+000,-1.566386e-001,-7.008171e-002,4.758303e-005,4.758303e-005,,,,,,,,,,,,,,,,,,,,
1405535178.906,,-3.000000e+001,2.979968e+002,2.980050e+002,1,0,1.018517e+000,1.420026e+000,1.420026e+000,1.286271e-001,1.196848e-001,1.318040e+000,2.664106e-002,1.769876e-002,3.094610e-005,3.094610e-005,,,,,,,,,,,,,,,,,,,,
1405535178.906,,-3.000000e+001,2.979968e+002,2.980050e+002,1,0,3.974741e+000,1.817835e+000,1.817835e+000,5.905222e-001,5.174935e-001,1.927000e+000,6.996873e-001,6.266586e-001,3.961539e-005,3.961539e-005,,,,,,,,,,,,,,,,,,,,
1405535196.906,,-3.000000e+001,2.980050e+002,2.979968e+002,1,0,1.249453e+000,1.350597e+000,1.350597e+000,-4.747552e-001,-5.919926e-001,1.293010e+000,-5.323414e-001,-6.495788e-001,2.943304e-005,2.943304e-005,,,,,,,,,,,,,,,,,,,,
1405535309.984,,-3.500000e+001,2.980132e+002,2.980050e+002,1,0,8.552159e-001,2.842189e+000,2.842189e+000,4.498262e-001,4.522543e-001,2.787520e+000,3.951575e-001,3.975856e-001,6.193871e-005,6.193871e-005,,,,,,,,,,,,,,,,,,,,
1405535309.984,,-3.500000e+001,2.980132e+002,2.980050e+002,1,0,3.929950e+000,3.089999e+000,3.089999e+000,6.827211e-001,7.000647e-001,3.174286e+000,7.670081e-001,7.843516e-001,6.733915e-005,6.733915e-005,,,,,,,,,,,,,,,,,,,,
1405535352.625,,-3.500000e+001,2.979968e+002,2.980050e+002,1,0,1.407746e+000,3.524888e-001,3.524888e-001,-9.805673e-002,-9.322071e-002,3.532420e-001,-9.730354e-002,-9.246752e-002,7.681651e-005,7.681651e-005,,,,,,,,,,,,,,,,,,,,
1405535385.609,,-3.500000e+001,2.979968e+002,2.980050e+002,1,0,6.993749e-001,3.531754e+000,3.531754e+000,7.115955e-001,7.384813e-001,3.492874e+000,6.727151e-001,6.996009e-001,7.696615e-005,7.696615e-005,,,,,,,,,,,,,,,,,,,,
1405535385.609,,-3.500000e+001,2.979968e+002,2.980050e+002,1,0,3.862977e+000,3.717307e+000,3.717307e+000,7.526368e-001,9.240339e-001,3.785260e+000,8.205897e-001,9.919868e-001,8.100983e-005,8.100983e-005,,,,,,,,,,,,,,,,,,,,
1405535521.593,,-4.000000e+001,2.979968e+002,2.979968e+002,1,0,1.573101e+000,7.438887e-001,7.438887e-001,-7.138466e-001,-6.308914e-001,7.399433e-001,-7.177919e-001,-6.348367e-001,3.242254e-005,3.242254e-005,,,,,,,,,,,,,,,,,,,,
1405535539.828,,-4.000000e+001,2.980050e+002,2.980050e+002,1,0,5.526503e-001,2.983032e+000,2.983032e+000,4.276180e-001,4.449239e-001,2.982868e+000,4.274540e-001,4.447598e-001,1.300160e-004,1.300160e-004,,,,,,,,,,,,,,,,,,,,
1405535539.828,,-4.000000e+001,2.980050e+002,2.980050e+002,1,0,3.777464e+000,3.060396e+000,3.060396e+000,4.222988e-001,5.222883e-001,3.082077e+000,4.439799e-001,5.439694e-001,1.333880e-004,1.333880e-004,,,,,,,,,,,,,,,,,,,,
1405535558.093,,-4.000000e+001,2.979968e+002,2.980050e+002,1,0,1.744675e+000,7.737968e-001,7.737968e-001,-9.411743e-001,-8.429602e-001,7.963833e-001,-9.185879e-001,-8.203738e-001,3.372609e-005,3.372609e-005,,,,,,,,,,,,,,,,,,,,
1405535669.125,,-4.500000e+001,2.980050e+002,2.980050e+002,1,0,4.168836e-001,2.798395e+000,2.798395e+000,4.719236e-001,5.251997e-001,2.797817e+000,4.713455e-001,5.246215e-001,1.219685e-004,1.219685e-004,,,,,,,,,,,,,,,,,,,,
1405535669.125,,-4.500000e+001,2.980050e+002,2.980050e+002,1,0,3.676915e+000,3.029572e+000,3.029572e+000,4.740145e-001,7.563775e-001,3.026901e+000,4.713435e-001,7.537065e-001,1.320445e-004,1.320445e-004,,,,,,,,,,,,,,,,,,,,
1405535686.859,,-4.500000e+001,2.980050e+002,2.979968e+002,1,0,1.921271e+000,9.762871e-001,9.762871e-001,-1.066510e+000,-9.267036e-001,9.869230e-001,-1.055874e+000,-9.160677e-001,4.255165e-005,4.255165e-005,,,,,,,,,,,,,,,,,,,,
1405535704.593,,-4.500000e+001,2.979968e+002,2.979968e+002,1,0,2.952735e-001,2.364727e+000,2.364727e+000,4.563360e-001,4.811790e-001,2.372012e+000,4.636213e-001,4.884644e-001,1.030670e-004,1.030670e-004,,,,,,,,,,,,,,,,,,,,
1405535704.593,,-4.500000e+001,2.979968e+002,2.979968e+002,1,0,3.565186e+000,2.480087e+000,2.480087e+000,4.745823e-001,5.965388e-001,2.470295e+000,4.647904e-001,5.867469e-001,1.080950e-004,1.080950e-004,,,,,,,,,,,,,,,,,,,,
1405535822.828,,-5.000000e+001,2.979968e+002,2.980050e+002,1,0,2.100990e+000,4.094058e-001,4.094058e-001,-1.050266e+000,-9.683048e-001,3.874078e-001,-1.072264e+000,-9.903028e-001,1.784402e-005,1.784402e-005,,,,,,,,,,,,,,,,,,,,
1405535840.828,,-5.000000e+001,2.980050e+002,2.980050e+002,1,0,1.909187e-001,2.353587e+000,2.353587e+000,4.216200e-001,4.471158e-001,2.372588e+000,4.406207e-001,4.661165e-001,1.025815e-004,1.025815e-004,,,,,,,,,,,,,,,,,,,,
1405535840.828,,-5.000000e+001,2.980050e+002,2.980050e+002,1,0,3.444823e+000,2.471541e+000,2.471541e+000,4.482139e-001,5.650698e-001,2.452031e+000,4.287032e-001,5.455590e-001,1.077225e-004,1.077225e-004,,,,,,,,,,,,,,,,,,,,
1405535859.312,,-5.000000e+001,2.980050e+002,2.979968e+002,1,0,2.281870e+000,9.248635e-001,9.248635e-001,-9.350718e-001,-8.449899e-001,9.276404e-001,-9.322948e-001,-8.422129e-001,4.031032e-005,4.031032e-005,,,,,,,,,,,,,,,,,,,,
1405536007.343,,-7.500000e+001,2.979968e+002,2.979968e+002,1,0,1.073879e-001,1.031373e+000,1.031373e+000,1.634953e-001,2.055927e-001,1.037317e+000,1.694392e-001,2.115366e-001,1.123811e-004,1.123811e-004,,,,,,,,,,,,,,,,,,,,
1405536007.343,,-7.500000e+001,2.979968e+002,2.979968e+002,1,0,3.317954e+000,1.148106e+000,1.148106e+000,1.409834e-001,3.223260e-001,1.147759e+000,1.406364e-001,3.219790e-001,1.251007e-004,1.251007e-004,,,,,,,,,,,,,,,,,,,,
1405536025.078,,-7.500000e+001,2.980050e+002,2.979968e+002,1,0,2.462026e+000,6.723228e-001,6.723228e-001,-3.088991e-001,-2.837482e-001,6.696786e-001,-3.115432e-001,-2.863923e-001,7.325807e-005,7.325807e-005,,,,,,,,,,,,,,,,,,,,
1405536042.312,,-7.500000e+001,2.979968e+002,2.979968e+002,1,0,4.744218e-002,1.135289e+000,1.135289e+000,1.584459e-001,1.925992e-001,1.137352e+000,1.605093e-001,1.946626e-001,1.237041e-004,1.237041e-004,,,,,,,,,,,,,,,,,,,,
1405536042.312,,-7.500000e+001,2.979968e+002,2.979968e+002,1,0,3.185305e+000,1.168859e+000,1.168859e+000,8.711690e-002,2.261695e-001,1.174005e+000,9.226281e-002,2.313154e-001,1.273620e-004,1.273620e-004,,,,,,,,,,,,,,,,,,,,
1405536173.046,,-1.000000e+002,2.979968e+002,2.979968e+002,1,0,2.639787e+000,1.624195e+000,1.624195e+000,-2.145796e-001,-7.813489e-002,1.626473e+000,-2.123013e-001,-7.585657e-002,1.769762e-004,1.769762e-004,,,,,,,,,,,,,,,,,,,,
1405536191.296,,-1.000000e+002,2.979968e+002,2.979968e+002,1,0,1.349962e-002,1.187017e+000,1.187017e+000,1.547763e-001,1.871184e-001,1.188597e+000,1.563560e-001,1.886980e-001,1.293403e-004,1.293403e-004,,,,,,,,,,,,,,,,,,,,
1405536191.296,,-1.000000e+002,2.979968e+002,2.979968e+002,1,0,3.047110e+000,1.133610e+000,1.133610e+000,8.655136e-003,1.337109e-001,1.146878e+000,2.192301e-002,1.469788e-001,1.235209e-004,1.235209e-004,,,,,,,,,,,,,,,,,,,,
1405536226.781,,-1.000000e+002,2.979968e+002,2.980050e+002,1,0,2.813723e+000,1.757561e+000,1.757561e+000,-5.546156e-001,-5.679095e-001,1.769288e+000,-5.428882e-001,-5.561821e-001,3.830162e-005,3.830162e-005,,,,,,,,,,,,,,,,,,,,
1405536352.765,,-7.500000e+001,2.980050e+002,2.979968e+002,1,0,6.570259e-003,3.007904e+000,3.007904e+000,7.643301e-001,7.737563e-001,3.017538e+000,7.739639e-001,7.833900e-001,6.554984e-005,6.554984e-005,,,,,,,,,,,,,,,,,,,,
1405536352.765,,-7.500000e+001,2.980050e+002,2.979968e+002,1,0,2.902695e+000,1.938688e+000,1.938688e+000,-3.302189e-001,-2.954597e-001,2.001587e+000,-2.673197e-001,-2.325606e-001,4.224892e-005,4.224892e-005,,,,,,,,,,,,,,,,,,,,
1405536370.500,,-7.500000e+001,2.980050e+002,2.979968e+002,1,0,2.982555e+000,2.235939e+000,2.235939e+000,-4.399852e-002,-2.436209e-002,2.234173e+000,-4.576377e-002,-2.612734e-002,4.872676e-005,4.872676e-005,,,,,,,,,,,,,,,,,,,,
1405536388.234,,-7.500000e+001,2.979968e+002,2.979968e+002,1,0,2.624837e-002,3.099612e+000,3.099612e+000,7.784735e-001,7.952306e-001,3.113841e+000,7.927016e-001,8.094587e-001,6.754840e-005,6.754840e-005,,,,,,,,,,,,,,,,,,,,
1405536388.234,,-7.500000e+001,2.979968e+002,2.979968e+002,1,0,2.751557e+000,1.575213e+000,1.575213e+000,-7.883118e-001,-7.291690e-001,1.655557e+000,-7.079677e-001,-6.488249e-001,3.432787e-005,3.432787e-005,,,,,,,,,,,,,,,,,,,,
1405536519.546,,-5.000000e+001,2.979968e+002,2.979968e+002,1,0,3.145755e+000,2.588275e+000,2.588275e+000,4.016716e-001,4.153564e-001,2.550297e+000,3.636934e-001,3.773782e-001,5.640519e-005,5.640519e-005,,,,,,,,,,,,,,,,,,,,
1405536537.281,,-5.000000e+001,2.980050e+002,2.980050e+002,1,0,7.097316e-002,2.927793e+000,2.927793e+000,7.892616e-001,7.949214e-001,2.961235e+000,8.227034e-001,8.283632e-001,6.380417e-005,6.380417e-005,,,,,,,,,,,,,,,,,,,,
1405536537.281,,-5.000000e+001,2.980050e+002,2.980050e+002,1,0,2.593276e+000,9.068576e-001,9.068575e-001,-1.245195e+000,-1.226014e+000,9.834883e-001,-1.168564e+000,-1.149384e+000,1.976277e-005,1.976277e-005,,,,,,,,,,,,,,,,,,,,
1405536555.515,,-5.000000e+001,2.979968e+002,2.979968e+002,1,0,3.301404e+000,2.898953e+000,2.898953e+000,7.204070e-001,7.453549e-001,2.862804e+000,6.842580e-001,7.092059e-001,6.317567e-005,6.317567e-005,,,,,,,,,,,,,,,,,,,,
1405536666.500,,-4.500000e+001,2.979968e+002,2.980050e+002,1,0,1.379901e-001,2.987762e+000,2.987762e+000,8.541009e-001,8.630254e-001,3.012660e+000,8.789985e-001,8.879230e-001,6.511107e-005,6.511107e-005,,,,,,,,,,,,,,,,,,,,
1405536666.500,,-4.500000e+001,2.979968e+002,2.980050e+002,1,0,2.427915e+000,4.333628e-001,4.333628e-001,-1.720496e+000,-1.691374e+000,5.047964e-001,-1.649062e+000,-1.619940e+000,9.444098e-006,9.444098e-006,,,,,,,,,,,,,,,,,,,,
1405536684.812,,-4.500000e+001,2.980050e+002,2.980050e+002,1,0,3.448405e+000,3.012330e+000,3.012330e+000,9.182873e-001,9.191415e-001,2.988801e+000,8.947589e-001,8.956132e-001,6.564646e-005,6.564646e-005,,,,,,,,,,,,,,,,,,,,
1405536702.812,,-4.500000e+001,2.979968e+002,2.979968e+002,1,0,2.235212e-001,3.023011e+000,3.023011e+000,9.308398e-001,9.348238e-001,3.035649e+000,9.434775e-001,9.474614e-001,6.587924e-005,6.587924e-005,,,,,,,,,,,,,,,,,,,,
1405536702.812,,-4.500000e+001,2.979968e+002,2.979968e+002,1,0,2.256212e+000,0.000000e+000,0.000000e+000,-2.100737e+000,-2.088187e+000,3.549165e-002,-2.065245e+000,-2.052696e+000,0.000000e+000,0.000000e+000,,,,,,,,,,,,,,,,,,,,
1405536820.312,,-4.000000e+001,2.980050e+002,2.979968e+002,1,0,3.584095e+000,3.086795e+000,3.086795e+000,1.001733e+000,1.012907e+000,3.073634e+000,9.885724e-001,9.997456e-001,6.726928e-005,6.726928e-005,,,,,,,,,,,,,,,,,,,,
1405536838.046,,-4.000000e+001,2.979968e+002,2.979968e+002,1,0,3.240127e-001,3.073214e+000,3.073214e+000,9.724798e-001,9.805691e-001,3.090473e+000,9.897391e-001,9.978285e-001,6.697333e-005,6.697333e-005,,,,,,,,,,,,,,,,,,,,
1405536855.531,,-4.000000e+001,2.979968e+002,2.979968e+002,1,0,2.079691e+000,-1.251259e-001,-1.251259e-001,-2.219630e+000,-2.219630e+000,-1.836243e-001,-2.278128e+000,-2.278128e+000,-2.726819e-006,-2.726819e-006,,,,,,,,,,,,,,,,,,,,
1405536855.531,,-4.000000e+001,2.979968e+002,2.979968e+002,1,0,3.705752e+000,3.122654e+000,3.122654e+000,1.009034e+000,1.028150e+000,3.110810e+000,9.971905e-001,1.016306e+000,6.805075e-005,6.805075e-005,,,,,,,,,,,,,,,,,,,,
1405536974.515,,-3.500000e+001,2.980050e+002,2.979968e+002,1,0,4.358622e-001,2.969146e+000,2.969146e+000,9.755989e-001,9.741116e-001,2.988073e+000,9.945260e-001,9.930387e-001,6.470544e-005,6.470544e-005,,,,,,,,,,,,,,,,,,,,
1405536992.765,,-3.500000e+001,2.980050e+002,2.979968e+002,1,0,1.899879e+000,-8.590961e-002,-8.590961e-002,-2.145521e+000,-2.145278e+000,-1.422715e-001,-2.201883e+000,-2.201640e+000,-1.872195e-006,-1.872195e-006,,,,,,,,,,,,,,,,,,,,
1405536992.765,,-3.500000e+001,2.980050e+002,2.979968e+002,1,0,3.809990e+000,3.042543e+000,3.042543e+000,9.724718e-001,9.831746e-001,3.019733e+000,9.496623e-001,9.603651e-001,6.630495e-005,6.630495e-005,,,,,,,,,,,,,,,,,,,,
1405537010.000,,-3.500000e+001,2.979968e+002,2.980050e+002,1,0,5.561082e-001,2.998596e+000,2.998596e+000,9.227015e-001,9.319994e-001,3.011923e+000,9.360284e-001,9.453263e-001,6.534724e-005,6.534724e-005,,,,,,,,,,,,,,,,,,,,
1405537128.750,,-3.000000e+001,2.980050e+002,2.980050e+002,1,0,1.719062e+000,1.573229e-001,1.573229e-001,-1.827171e+000,-1.826734e+000,1.295311e-001,-1.854963e+000,-1.854526e+000,3.428479e-006,3.428479e-006,,,,,,,,,,,,,,,,,,,,
1405537128.750,,-3.000000e+001,2.980050e+002,2.980050e+002,1,0,3.893606e+000,2.908719e+000,2.908719e+000,9.148198e-001,9.246625e-001,2.880903e+000,8.870035e-001,8.968462e-001,6.338862e-005,6.338862e-005,,,,,,,,,,,,,,,,,,,,
1405537146.984,,-3.000000e+001,2.979968e+002,2.979885e+002,1,0,6.830383e-001,2.847987e+000,2.847987e+000,7.896065e-001,7.985661e-001,2.847497e+000,7.891166e-001,7.980762e-001,6.206511e-005,6.206511e-005,,,,,,,,,,,,,,,,,,,,
1405537165.218,,-3.000000e+001,2.979885e+002,2.979885e+002,1,0,1.539009e+000,6.578265e-001,6.578265e-001,-1.358288e+000,-1.357004e+000,6.483946e-001,-1.367720e+000,-1.366436e+000,1.433576e-005,1.433576e-005,,,,,,,,,,,,,,,,,,,,
1405537165.218,,-3.000000e+001,2.979885e+002,2.979885e+002,1,0,3.953499e+000,2.903989e+000,2.903989e+000,8.694691e-001,8.891585e-001,2.871464e+000,8.369438e-001,8.566332e-001,6.328553e-005,6.328553e-005,,,,,,,,,,,,,,,,,,,,
1405537284.453,,-2.500000e+001,2.980050e+002,2.979968e+002,1,0,8.156493e-001,2.555467e+000,2.555467e+000,5.636114e-001,5.680656e-001,2.550102e+000,5.582463e-001,5.627005e-001,5.569036e-005,5.569036e-005,,,,,,,,,,,,,,,,,,,,
1405537302.187,,-2.500000e+001,2.979968e+002,2.979968e+002,1,0,1.361237e+000,1.266366e+000,1.266366e+000,-8.124083e-001,-8.101950e-001,1.241741e+000,-8.370333e-001,-8.348199e-001,2.759744e-005,2.759744e-005,,,,,,,,,,,,,,,,,,,,
1405537302.187,,-2.500000e+001,2.979968e+002,2.979968e+002,1,0,3.987423e+000,2.933287e+000,2.933286e+000,8.307188e-001,8.567259e-001,2.904525e+000,8.019576e-001,8.279648e-001,6.392403e-005,6.392403e-005,,,,,,,,,,,,,,,,,,,,
1405537320.453,,-2.500000e+001,2.979968e+002,2.979968e+002,1,0,9.538941e-001,2.304453e+000,2.304453e+000,2.643340e-001,2.741323e-001,2.298036e+000,2.579175e-001,2.677157e-001,5.022009e-005,5.022009e-005,,,,,,,,,,,,,,,,,,,,
1405537436.781,,-2.000000e+001,2.980050e+002,2.979968e+002,1,0,1.187273e+000,1.638081e+000,1.638081e+000,-3.010315e-001,-2.999778e-001,1.598837e+000,-3.402759e-001,-3.392222e-001,3.569811e-005,3.569811e-005,,,,,,,,,,,,,,,,,,,,
1405537436.781,,-2.000000e+001,2.980050e+002,2.979968e+002,1,0,3.994393e+000,2.761773e+000,2.761773e+000,8.135982e-001,8.237139e-001,2.738858e+000,7.906837e-001,8.007995e-001,6.018632e-005,6.018632e-005,,,,,,,,,,,,,,,,,,,,
1405537454.515,,-2.000000e+001,2.979968e+002,2.979968e+002,1,0,1.098362e+000,1.912900e+000,1.912900e+000,-1.099369e-001,-9.797788e-002,1.920510e+000,-1.023276e-001,-9.036851e-002,4.168715e-005,4.168715e-005,,,,,,,,,,,,,,,,,,,,
1405537471.750,,-2.000000e+001,2.979968e+002,2.980050e+002,1,0,1.018523e+000,2.146977e+000,2.146977e+000,1.390677e-001,1.409979e-001,2.108650e+000,1.007409e-001,1.026711e-001,4.678830e-005,4.678830e-005,,,,,,,,,,,,,,,,,,,,
1405537471.750,,-2.000000e+001,2.979968e+002,2.980050e+002,1,0,3.974733e+000,2.842341e+000,2.842341e+000,8.205988e-001,8.363621e-001,2.830031e+000,8.082888e-001,8.240521e-001,6.194213e-005,6.194213e-005,,,,,,,,,,,,,,,,,,,,
1405537590.984,,-1.500000e+001,2.980050e+002,2.979968e+002,1,0,1.249556e+000,1.461074e+000,1.461074e+000,-5.407385e-001,-5.295972e-001,1.491609e+000,-5.102033e-001,-4.990619e-001,3.184067e-005,3.184067e-005,,,,,,,,,,,,,,,,,,,,
1405537609.234,,-1.500000e+001,2.979968e+002,2.980050e+002,1,0,8.554066e-001,2.511978e+000,2.511979e+000,5.030234e-001,5.068209e-001,2.479736e+000,4.707806e-001,4.745781e-001,5.474267e-005,5.474267e-005,,,,,,,,,,,,,,,,,,,,
1405537609.234,,-1.500000e+001,2.979968e+002,2.980050e+002,1,0,3.929959e+000,2.877438e+000,2.877438e+000,8.451545e-001,8.722799e-001,2.873421e+000,8.411383e-001,8.682637e-001,6.270700e-005,6.270700e-005,,,,,,,,,,,,,,,,,,,,
1405537627.484,,-1.500000e+001,2.980050e+002,2.979968e+002,1,0,1.407772e+000,1.002991e+000,1.002991e+000,-1.029392e+000,-1.017760e+000,1.069501e+000,-9.628816e-001,-9.512496e-001,2.185783e-005,2.185783e-005,,,,,,,,,,,,,,,,,,,,
1405537747.781,,-1.000000e+001,2.979968e+002,2.979885e+002,1,0,6.995653e-001,2.704703e+000,2.704703e+000,7.756446e-001,7.776395e-001,2.673792e+000,7.447341e-001,7.467290e-001,5.894267e-005,5.894267e-005,,,,,,,,,,,,,,,,,,,,
1405537747.781,,-1.000000e+001,2.979968e+002,2.979885e+002,1,0,3.863046e+000,2.826472e+000,2.826472e+000,8.866908e-001,8.994085e-001,2.826620e+000,8.868389e-001,8.995565e-001,6.159634e-005,6.159634e-005,,,,,,,,,,,,,,,,,,,,
1405537765.015,,-1.000000e+001,2.979885e+002,2.979968e+002,1,0,1.573103e+000,4.077273e-001,4.077273e-001,-1.511751e+000,-1.503932e+000,4.899491e-001,-1.429529e+000,-1.421710e+000,8.885463e-006,8.885463e-006,,,,,,,,,,,,,,,,,,,,
1405537783.265,,-1.000000e+001,2.979968e+002,2.979968e+002,1,0,5.525765e-001,2.932066e+000,2.932066e+000,9.283288e-001,9.333035e-001,2.913609e+000,9.098718e-001,9.148465e-001,6.389752e-005,6.389752e-005,,,,,,,,,,,,,,,,,,,,
1405537783.265,,-1.000000e+001,2.979968e+002,2.979968e+002,1,0,3.777431e+000,2.971129e+000,2.971129e+000,9.436244e-001,9.723672e-001,2.965066e+000,9.375612e-001,9.663039e-001,6.474882e-005,6.474882e-005,,,,,,,,,,,,,,,,,,,,
1405537900.000,,-5.000000e+000,2.979968e+002,2.980050e+002,1,0,1.744730e+000,1.007111e-001,1.007111e-001,-1.911882e+000,-1.890357e+000,1.587716e-001,-1.853821e+000,-1.832297e+000,2.194764e-006,2.194764e-006,,,,,,,,,,,,,,,,,,,,
1405537917.796,,-5.000000e+000,2.980050e+002,2.980050e+002,1,0,4.167175e-001,2.941069e+000,2.941069e+000,9.620306e-001,9.678674e-001,2.937786e+000,9.587478e-001,9.645846e-001,6.409375e-005,6.409375e-005,,,,,,,,,,,,,,,,,,,,
1405537917.796,,-5.000000e+000,2.980050e+002,2.980050e+002,1,0,3.676905e+000,2.969604e+000,2.969604e+000,9.654674e-001,9.964023e-001,2.962826e+000,9.586896e-001,9.896245e-001,6.471560e-005,6.471560e-005,,,,,,,,,,,,,,,,,,,,
1405537935.531,,-5.000000e+000,2.980050e+002,2.979968e+002,1,0,1.921330e+000,-1.669362e-001,-1.669362e-001,-2.155180e+000,-2.134391e+000,-1.538590e-001,-2.142103e+000,-2.121314e+000,-3.637987e-006,-3.637987e-006,,,,,,,,,,,,,,,,,,,,
1405538054.281,,0.000000e+000,2.979968e+002,2.979968e+002,1,0,2.952378e-001,2.862636e+000,2.862636e+000,9.138998e-001,9.208604e-001,2.878242e+000,9.295060e-001,9.364666e-001,6.238452e-005,6.238452e-005,,,,,,,,,,,,,,,,,,,,
1405538054.281,,0.000000e+000,2.979968e+002,2.979968e+002,1,0,3.565159e+000,2.922758e+000,2.922758e+000,9.468119e-001,9.809819e-001,2.907520e+000,9.315745e-001,9.657446e-001,6.369472e-005,6.369472e-005,,,,,,,,,,,,,,,,,,,,
1405538072.515,,0.000000e+000,2.980050e+002,2.979968e+002,1,0,2.100947e+000,-1.310770e-001,-1.310770e-001,-2.128043e+000,-2.110557e+000,-1.517003e-001,-2.148666e+000,-2.131180e+000,-2.856519e-006,-2.856519e-006,,,,,,,,,,,,,,,,,,,,
1405538089.781,,0.000000e+000,2.979968e+002,2.979968e+002,1,0,1.909433e-001,2.773064e+000,2.773064e+000,8.290361e-001,8.358071e-001,2.814006e+000,8.699775e-001,8.767486e-001,6.043251e-005,6.043251e-005,,,,,,,,,,,,,,,,,,,,
1405538089.781,,0.000000e+000,2.979968e+002,2.979968e+002,1,0,3.444901e+000,2.838832e+000,2.838832e+000,8.705405e-001,9.015744e-001,2.810227e+000,8.419360e-001,8.729699e-001,6.186576e-005,6.186576e-005,,,,,,,,,,,,,,,,,,,,
1405538207.515,,5.000000e+000,2.979968e+002,2.979968e+002,1,0,2.282157e+000,4.043702e-002,4.043702e-002,-1.854847e+000,-1.844285e+000,1.773219e-002,-1.877552e+000,-1.866990e+000,8.812308e-007,8.812308e-007,,,,,,,,,,,,,,,,,,,,
1405538225.750,,5.000000e+000,2.979968e+002,2.980050e+002,1,0,1.073164e-001,2.639546e+000,2.639546e+000,7.320168e-001,7.392429e-001,2.704826e+000,7.972968e-001,8.045229e-001,5.752276e-005,5.752276e-005,,,,,,,,,,,,,,,,,,,,
1405538225.750,,5.000000e+000,2.979968e+002,2.980050e+002,1,0,3.317783e+000,2.653432e+000,2.653432e+000,7.220011e-001,7.531289e-001,2.597775e+000,6.663442e-001,6.974720e-001,5.782537e-005,5.782537e-005,,,,,,,,,,,,,,,,,,,,
1405538242.484,,5.000000e+000,2.979968e+002,2.979968e+002,1,0,2.462082e+000,5.249184e-001,5.249184e-001,-1.413860e+000,-1.393124e+000,4.928687e-001,-1.445910e+000,-1.425174e+000,1.143937e-005,1.143937e-005,,,,,,,,,,,,,,,,,,,,
1405538367.234,,1.000000e+001,2.980050e+002,2.980050e+002,1,0,4.739653e-002,2.515183e+000,2.515183e+000,6.496743e-001,6.570442e-001,2.604154e+000,7.386452e-001,7.460151e-001,5.481253e-005,5.481253e-005,,,,,,,,,,,,,,,,,,,,
1405538367.234,,1.000000e+001,2.980050e+002,2.980050e+002,1,0,3.185190e+000,2.380291e+000,2.380291e+000,4.921464e-001,5.221524e-001,2.309761e+000,4.216160e-001,4.516220e-001,5.187288e-005,5.187288e-005,,,,,,,,,,,,,,,,,,,,
1405538385.484,,1.000000e+001,2.980050e+002,2.980050e+002,1,0,2.639768e+000,1.057466e+000,1.057466e+000,-8.851725e-001,-8.594071e-001,1.003668e+000,-9.389713e-001,-9.132059e-001,2.304501e-005,2.304501e-005,,,,,,,,,,,,,,,,,,,,
1405538403.734,,1.000000e+001,2.980050e+002,2.979968e+002,1,0,1.354884e-002,2.520371e+000,2.520371e+000,6.024956e-001,6.145468e-001,2.626335e+000,7.084595e-001,7.205107e-001,5.492560e-005,5.492560e-005,,,,,,,,,,,,,,,,,,,,
1405538403.734,,1.000000e+001,2.980050e+002,2.979968e+002,1,0,3.046956e+000,2.129429e+000,2.129429e+000,1.770066e-001,2.236047e-001,2.071851e+000,1.194283e-001,1.660264e-001,4.640593e-005,4.640593e-005,,,,,,,,,,,,,,,,,,,,
1405538522.500,,1.500000e+001,2.979968e+002,2.979968e+002,1,0,2.813692e+000,1.489761e+000,1.489761e+000,-3.693759e-001,-3.448895e-001,1.402197e+000,-4.569397e-001,-4.324533e-001,3.246584e-005,3.246584e-005,,,,,,,,,,,,,,,,,,,,
1405538539.796,,1.500000e+001,2.979968e+002,2.979968e+002,1,0,6.578187e-003,2.467727e+000,2.467727e+000,5.755296e-001,5.875561e-001,2.586277e+000,6.940796e-001,7.061062e-001,5.377831e-005,5.377831e-005,,,,,,,,,,,,,,,,,,,,
1405538539.796,,1.500000e+001,2.979968e+002,2.979968e+002,1,0,2.902575e+000,1.723533e+000,1.723533e+000,-2.009856e-001,-1.566378e-001,1.695743e+000,-2.287757e-001,-1.844279e-001,3.756035e-005,3.756035e-005,,,,,,,,,,,,,,,,,,,,
1405538557.828,,1.500000e+001,2.979968e+002,2.979968e+002,1,0,2.982849e+000,2.000031e+000,2.000031e+000,8.756465e-002,1.167161e-001,1.881705e+000,-3.076118e-002,-1.609683e-003,4.358597e-005,4.358597e-005,,,,,,,,,,,,,,,,,,,,
1405538675.843,,2.000000e+001,2.980050e+002,2.979968e+002,1,0,2.621154e-002,2.352062e+000,2.352062e+000,5.736092e-001,5.859181e-001,2.479319e+000,7.008670e-001,7.131759e-001,5.125763e-005,5.125763e-005,,,,,,,,,,,,,,,,,,,,
1405538675.843,,2.000000e+001,2.980050e+002,2.979968e+002,1,0,2.751404e+000,1.184271e+000,1.184271e+000,-6.253158e-001,-5.818727e-001,1.199428e+000,-6.101585e-001,-5.667154e-001,2.580839e-005,2.580839e-005,,,,,,,,,,,,,,,,,,,,
1405538694.078,,2.000000e+001,2.979968e+002,2.979968e+002,1,0,3.145833e+000,2.320170e+000,2.320170e+000,4.610040e-001,4.887987e-001,2.193042e+000,3.338766e-001,3.616713e-001,5.056263e-005,5.056263e-005,,,,,,,,,,,,,,,,,,,,
1405538711.812,,2.000000e+001,2.979885e+002,2.979968e+002,1,0,7.103048e-002,2.443312e+000,2.443312e+000,6.237875e-001,6.347765e-001,2.557713e+000,7.381886e-001,7.491776e-001,5.324622e-005,5.324622e-005,,,,,,,,,,,,,,,,,,,,
1405538711.812,,2.000000e+001,2.979885e+002,2.979968e+002,1,0,2.593152e+000,7.463301e-001,7.463301e-001,-1.099446e+000,-1.062205e+000,8.114952e-001,-1.034281e+000,-9.970402e-001,1.626450e-005,1.626450e-005,,,,,,,,,,,,,,,,,,,,
1405538830.578,,2.500000e+001,2.980050e+002,2.979968e+002,1,0,3.301659e+000,2.553484e+000,2.553484e+000,7.240134e-001,7.577796e-001,2.436610e+000,6.071396e-001,6.409059e-001,5.564713e-005,5.564713e-005,,,,,,,,,,,,,,,,,,,,
1405538848.812,,2.500000e+001,2.980050e+002,2.980050e+002,1,0,1.379389e-001,2.459792e+000,2.459792e+000,6.804993e-001,6.963838e-001,2.554235e+000,7.749428e-001,7.908274e-001,5.360534e-005,5.360534e-005,,,,,,,,,,,,,,,,,,,,
1405538848.812,,2.500000e+001,2.980050e+002,2.980050e+002,1,0,2.427704e+000,2.746666e-001,2.746666e-001,-1.540575e+000,-1.488742e+000,3.820758e-001,-1.433166e+000,-1.381332e+000,5.985708e-006,5.985708e-006,,,,,,,,,,,,,,,,,,,,
1405538866.109,,2.500000e+001,2.980050e+002,2.979968e+002,1,0,3.448573e+000,2.685934e+000,2.685934e+000,8.683956e-001,9.075667e-001,2.607690e+000,7.901512e-001,8.293222e-001,5.853357e-005,5.853357e-005,,,,,,,,,,,,,,,,,,,,
1405538979.656,,3.000000e+001,2.980050e+002,2.980050e+002,1,0,2.236539e-001,2.448653e+000,2.448653e+000,7.341315e-001,7.553011e-001,2.513855e+000,7.993342e-001,8.205038e-001,5.336256e-005,5.336256e-005,,,,,,,,,,,,,,,,,,,,
1405538979.656,,3.000000e+001,2.980050e+002,2.980050e+002,1,0,2.256220e+000,-9.140294e-002,-9.140293e-002,-1.851439e+000,-1.784754e+000,3.448558e-002,-1.725550e+000,-1.658866e+000,-1.991910e-006,-1.991910e-006,,,,,,,,,,,,,,,,,,,,
1405538996.953,,3.000000e+001,2.979968e+002,2.979968e+002,1,0,3.584252e+000,2.650990e+000,2.650990e+000,8.814347e-001,9.292445e-001,2.607355e+000,8.377991e-001,8.856089e-001,5.777203e-005,5.777203e-005,,,,,,,,,,,,,,,,,,,,
1405539014.187,,3.000000e+001,2.979968e+002,2.979968e+002,1,0,3.241575e-001,2.510147e+000,2.510147e+000,7.951163e-001,8.178908e-001,2.551548e+000,8.365167e-001,8.592912e-001,5.470269e-005,5.470269e-005,,,,,,,,,,,,,,,,,,,,
1405539127.218,,3.500000e+001,2.979968e+002,2.979968e+002,1,0,2.079599e+000,-1.950133e-001,-1.950133e-001,-1.557535e+000,-1.557535e+000,-2.235058e-001,-1.586028e+000,-1.586028e+000,-4.249849e-006,-4.249849e-006,,,,,,,,,,,,,,,,,,,,
1405539127.218,,3.500000e+001,2.979968e+002,2.979968e+002,1,0,3.705887e+000,2.145451e+000,2.145451e+000,7.114270e-001,7.829297e-001,2.128231e+000,6.942070e-001,7.657096e-001,4.675498e-005,4.675498e-005,,,,,,,,,,,,,,,,,,,,
1405539145.203,,3.500000e+001,2.979968e+002,2.979968e+002,1,0,4.360588e-001,2.006439e+000,2.006439e+000,6.594319e-001,6.965628e-001,2.024336e+000,6.773288e-001,7.144597e-001,4.372555e-005,4.372555e-005,,,,,,,,,,,,,,,,,,,,
1405539162.203,,3.500000e+001,2.979968e+002,2.980050e+002,1,0,1.899656e+000,-1.297037e-001,-1.297037e-001,-1.431329e+000,-1.429561e+000,-1.548147e-001,-1.456440e+000,-1.454672e+000,-2.826582e-006,-2.826582e-006,,,,,,,,,,,,,,,,,,,,
1405539162.203,,3.500000e+001,2.979968e+002,2.980050e+002,1,0,3.810122e+000,2.004151e+000,2.004151e+000,6.264990e-001,7.042937e-001,2.010832e+000,6.331807e-001,7.109754e-001,4.367567e-005,4.367567e-005,,,,,,,,,,,,,,,,,,,,
1405539280.453,,4.000000e+001,2.979968e+002,2.980050e+002,1,0,5.562865e-001,-5.655079e-001,-5.655080e-001,-6.022659e-002,1.381034e-002,-5.604224e-001,-5.514100e-002,1.889592e-002,-1.232389e-005,-1.232389e-005,,,,,,,,,,,,,,,,,,,,
1405539299.437,,4.000000e+001,2.980050e+002,2.979885e+002,1,0,1.718889e+000,-8.178961e-002,-8.178961e-002,6.575547e-001,6.636128e-001,-7.866898e-002,6.606753e-001,6.667335e-001,-1.782408e-006,-1.782408e-006,,,,,,,,,,,,,,,,,,,,
1405539299.437,,4.000000e+001,2.980050e+002,2.979885e+002,1,0,3.893736e+000,-8.455153e-001,-8.455153e-001,-2.364217e-001,-1.001129e-001,-7.901758e-001,-1.810822e-001,-4.477334e-002,-1.842598e-005,-1.842598e-005,,,,,,,,,,,,,,,,,,,,
1405539316.734,,4.000000e+001,2.979885e+002,2.979968e+002,1,0,6.832544e-001,-9.012116e-001,-9.012116e-001,-8.539331e-002,-1.462418e-002,-9.291487e-001,-1.133305e-001,-4.256135e-002,-1.963975e-005,-1.963975e-005,,,,,,,,,,,,,,,,,,,,
1405539430.234,,4.500000e+001,2.980050e+002,2.980050e+002,1,0,1.538941e+000,-8.275094e-001,-8.275094e-001,1.494993e+000,1.504064e+000,-8.535348e-001,1.468967e+000,1.478038e+000,-1.803357e-005,-1.803357e-005,,,,,,,,,,,,,,,,,,,,
1405539430.234,,4.500000e+001,2.980050e+002,2.980050e+002,1,0,3.953562e+000,-3.012787e+000,-3.012787e+000,-8.203032e-001,-6.812143e-001,-2.908290e+000,-7.158055e-001,-5.767167e-001,-6.565644e-005,-6.565644e-005,,,,,,,,,,,,,,,,,,,,
1405539448.000,,4.500000e+001,2.979968e+002,2.979968e+002,1,0,8.158098e-001,-2.618335e+000,-2.618335e+000,-3.243506e-001,-2.459667e-001,-2.686484e+000,-3.924994e-001,-3.141155e-001,-5.706032e-005,-5.706032e-005,,,,,,,,,,,,,,,,,,,,
1405539466.296,,4.500000e+001,2.979968e+002,2.979968e+002,1,0,1.360889e+000,-1.252785e+000,-1.252785e+000,1.102457e+000,1.116122e+000,-1.350688e+000,1.004554e+000,1.018219e+000,-2.730143e-005,-2.730143e-005,,,,,,,,,,,,,,,,,,,,
1405539466.296,,4.500000e+001,2.979968e+002,2.979968e+002,1,0,3.987489e+000,-3.045595e+000,-3.045595e+000,-8.372517e-001,-6.766882e-001,-2.923161e+000,-7.148176e-001,-5.542541e-001,-6.637139e-005,-6.637139e-005,,,,,,,,,,,,,,,,,,,,
1405539585.546,,5.000000e+001,2.979968e+002,2.979968e+002,1,0,9.540994e-001,-2.601551e+000,-2.601550e+000,-5.845219e-002,2.957702e-002,-2.688814e+000,-1.457160e-001,-5.768681e-002,-5.669449e-005,-5.669449e-005,,,,,,,,,,,,,,,,,,,,
1405539604.281,,5.000000e+001,2.979968e+002,2.980050e+002,1,0,1.187298e+000,-1.913663e+000,-1.913663e+000,6.733420e-001,6.908627e-001,-2.062203e+000,5.248025e-001,5.423231e-001,-4.170366e-005,-4.170366e-005,,,,,,,,,,,,,,,,,,,,
1405539604.281,,5.000000e+001,2.979968e+002,2.980050e+002,1,0,3.994457e+000,-3.395489e+000,-3.395489e+000,-9.591613e-001,-7.909636e-001,-3.247609e+000,-8.112808e-001,-6.430831e-001,-7.399647e-005,-7.399647e-005,,,,,,,,,,,,,,,,,,,,
1405539622.515,,5.000000e+001,2.980050e+002,2.979885e+002,1,0,1.098554e+000,-2.168493e+000,-2.168493e+000,3.630127e-001,4.599776e-001,-2.272261e+000,2.592441e-001,3.562090e-001,-4.725705e-005,-4.725705e-005,,,,,,,,,,,,,,,,,,,,
1405539765.234,,7.500000e+001,2.980050e+002,2.980050e+002,1,0,1.017981e+000,-1.299173e+000,-1.299173e+000,8.804483e-002,9.650385e-002,-1.406233e+000,-1.901477e-002,-1.055574e-002,-5.662453e-005,-5.662453e-005,,,,,,,,,,,,,,,,,,,,
1405539765.234,,7.500000e+001,2.980050e+002,2.980050e+002,1,0,3.974659e+000,-1.920225e+000,-1.920225e+000,-5.936299e-001,-5.245478e-001,-1.802066e+000,-4.754710e-001,-4.063890e-001,-8.369311e-005,-8.369311e-005,,,,,,,,,,,,,,,,,,,,
1405539782.718,,7.500000e+001,2.980050e+002,2.980050e+002,1,0,1.249619e+000,-9.399701e-001,-9.399701e-001,4.375468e-001,4.773983e-001,-1.017405e+000,3.601123e-001,3.999639e-001,-4.096865e-005,-4.096865e-005,,,,,,,,,,,,,,,,,,,,
1405539800.203,,7.500000e+001,2.980050e+002,2.980050e+002,1,0,8.551959e-001,-1.524552e+000,-1.524552e+000,-1.414325e-001,-1.314911e-001,-1.635362e+000,-2.522427e-001,-2.423013e-001,-6.644770e-005,-6.644770e-005,,,,,,,,,,,,,,,,,,,,
1405539800.203,,7.500000e+001,2.980050e+002,2.980050e+002,1,0,3.929961e+000,-1.926481e+000,-1.926481e+000,-6.044298e-001,-5.334198e-001,-1.821954e+000,-4.999024e-001,-4.288925e-001,-8.396579e-005,-8.396579e-005,,,,,,,,,,,,,,,,,,,,
1405539931.453,,1.000000e+002,2.980050e+002,2.979968e+002,1,0,1.407852e+000,-6.964324e-001,-6.964324e-001,7.066531e-001,7.537659e-001,-7.541767e-001,6.489088e-001,6.960216e-001,-3.035398e-005,-3.035398e-005,,,,,,,,,,,,,,,,,,,,
1405539949.687,,1.000000e+002,2.979968e+002,2.979968e+002,1,0,6.994103e-001,-1.771905e+000,-1.771905e+000,-3.441831e-001,-3.308223e-001,-1.878050e+000,-4.503284e-001,-4.369676e-001,-7.722840e-005,-7.722840e-005,,,,,,,,,,,,,,,,,,,,
1405539949.687,,1.000000e+002,2.979968e+002,2.979968e+002,1,0,3.862957e+000,-2.002319e+000,-2.002319e+000,-6.464117e-001,-5.612370e-001,-1.907923e+000,-5.520151e-001,-4.668404e-001,-8.727102e-005,-8.727102e-005,,,,,,,,,,,,,,,,,,,,
1405539967.953,,1.000000e+002,2.979968e+002,2.979968e+002,1,0,1.573254e+000,-4.301584e-001,-4.301584e-001,9.547417e-001,1.006054e+000,-4.367305e-001,9.481696e-001,9.994817e-001,-1.874844e-005,-1.874844e-005,,,,,,,,,,,,,,,,,,,,
1405539967.953,,1.000000e+002,2.979968e+002,2.979968e+002,1,0,2.256079e+000,-2.134770e-001,-2.134770e-001,1.114980e+000,1.222735e+000,-9.849784e-002,1.229959e+000,1.337714e+000,-9.304386e-006,-9.304386e-006,,,,,,,,,,,,,,,,,,,,