File: Sample Data Files/2014-07-16 EB on isolated PMN-PT no Ti spontaneous in situ/Ni-NiO_298K_SiO2_PMN-PT_5.0Tprebias_400V_Au_back.rso.raw
[Header]
TITLE,MPMS RSO Measurement
BYAPP,MPMS Measurement,2.1,Raw with ABS
FILEOPENTIME, 1405548582.796000 7/16/2014, 3:09:42 PM

INFO, APPNAME, MPMS MultiVu Application, Revision 1.58,  Build 076

INFO, NAME, EB in situ
INFO, WEIGHT, 0.000
INFO, AREA, 0.000
INFO, LENGTH, 0.000
INFO, SHAPE, 0
INFO, COMMENT,
INFO, SEQUENCE FILE: MHcurveUpTo100.seq


INFO, BACKGROUND DATA FILE:, None


STARTUPAXIS,X,8,LINEAR,AUTO,0.000000,0.000000
STARTUPAXIS,Y1,9,LINEAR,AUTO,0.000000,0.000000


STARTUPGROUP,Longitudinal
FIELDGROUP,Longitudinal,1,2,3,4,5,6,7,8,9,10,11,12,13,14,15,16,17,18,19,20,21,22
FIELDGROUP,Transverse,1,2,3,4,5,6,7,8,23,24,25,26,27,28,29,30,31,32,33,34,35,36

PLOT_APPEARANCE,ALL,HORZ_GRID_ON,VERT_GRID_ON,MARKERS_ONLY

[Data]
Time,Comment,Field (Oe),Start Temperature (K),End Temperature (K),Scan,Rejected,Position (cm),Long Voltage,Long Average Voltage,Long Detrended Voltage,Long Demeaned Voltage,Long Reg Fit,Long Detrended Fit,Long Demeaned Fit,Long Scaled Response,Long Avg. Scaled Response,Long Background Response,Long Response [w/ABS],Long Detrended Resp. [w/ABS],Long Fit [w/ABS],Long Detrended Fit [w/ABS],Trans Voltage,Trans Average Voltage,Trans Detrended Voltage,Trans Demeaned Voltage,Trans Reg Fit,Trans Detrended Fit,Trans Demeaned Fit,Trans Scaled Response,Trans Avg. Scaled Response,Trans Background Response,Trans Response [w/ABS],Trans Detrended Resp. [w/ABS],Trans Adjusted Fit,Trans Detrended Fit [w/ABS],
1405548582.796,,1.000000e+002,2.979885e+002,2.979885e+002,1,0,2.079601e+000,-3.509628e-002,-3.509629e-002,3.169258e-001,3.169258e-001,1.055219e-002,3.625743e-001,3.625743e-001,-1.529670e-006,-1.529670e-006,,,,,,,,,,,,,,,,,,,,
1405548582.796,,1.000000e+002,2.979885e+002,2.979885e+002,1,0,3.810018e+000,-4.910428e-001,-4.910428e-001,-1.956025e-001,-1.390207e-001,-4.501902e-001,-1.547499e-001,-9.816813e-002,-2.140208e-005,-2.140208e-005,,,,,,,,,,,,,,,,,,,,
1405548601.031,,1.000000e+002,2.979968e+002,2.980050e+002,1,0,6.830465e-001,-3.881954e-001,-3.881955e-001,-6.926166e-002,-3.877813e-002,-4.547606e-001,-1.358268e-001,-1.053432e-001,-1.691948e-005,-1.691948e-005,,,,,,,,,,,,,,,,,,,,
1405548618.765,,1.000000e+002,2.980050e+002,2.979968e+002,1,0,1.361159e+000,-1.562548e-001,-1.562548e-001,1.946725e-001,1.998171e-001,-2.361208e-001,1.148065e-001,1.199510e-001,-6.810358e-006,-6.810358e-006,,,,,,,,,,,,,,,,,,,,
1405548618.765,,1.000000e+002,2.980050e+002,2.979968e+002,1,0,3.994390e+000,-5.473495e-001,-5.473495e-001,-2.530118e-001,-1.912776e-001,-4.290766e-001,-1.347389e-001,-7.300472e-002,-2.385621e-005,-2.385621e-005,,,,,,,,,,,,,,,,,,,,
1405548745.562,,7.500000e+001,2.979968e+002,2.980050e+002,1,0,1.249458e+000,-2.395703e-001,-2.395703e-001,1.144705e-001,1.391515e-001,-3.033909e-001,5.064990e-002,7.533088e-002,-1.044169e-005,-1.044169e-005,,,,,,,,,,,,,,,,,,,,
1405548763.328,,7.500000e+001,2.980050e+002,2.979968e+002,1,0,6.992959e-001,-4.014710e-001,-4.014710e-001,-3.019298e-002,-2.281183e-002,-4.885791e-001,-1.173011e-001,-1.099199e-001,-1.749814e-005,-1.749814e-005,,,,,,,,,,,,,,,,,,,,
1405548763.328,,7.500000e+001,2.980050e+002,2.979968e+002,1,0,3.777311e+000,-5.030976e-001,-5.030977e-001,-1.724160e-001,-1.244385e-001,-4.678401e-001,-1.371584e-001,-8.918095e-002,-2.192754e-005,-2.192754e-005,,,,,,,,,,,,,,,,,,,,
1405548782.062,,7.500000e+001,2.980050e+002,2.980050e+002,1,0,1.921299e+000,-1.005585e-001,-1.005585e-001,2.208509e-001,2.512165e-001,-2.342536e-002,2.979840e-001,3.283496e-001,-4.382848e-006,-4.382848e-006,,,,,,,,,,,,,,,,,,,,
1405548907.359,,5.000000e+001,2.979968e+002,2.979968e+002,1,0,1.910705e-001,-4.640339e-001,-4.640339e-001,-1.496526e-001,-1.414143e-001,-4.125970e-001,-9.821575e-002,-8.997744e-002,-2.022499e-005,-2.022499e-005,,,,,,,,,,,,,,,,,,,,
1405548907.359,,5.000000e+001,2.979968e+002,2.979968e+002,1,0,3.317974e+000,-2.882473e-001,-2.882473e-001,-4.073154e-003,3.437227e-002,-3.499117e-001,-6.573752e-002,-2.729210e-002,-1.256331e-005,-1.256331e-005,,,,,,,,,,,,,,,,,,,,
1405548942.828,,5.000000e+001,2.980050e+002,2.980050e+002,1,0,2.639693e+000,-1.548814e-001,-1.548814e-001,3.854564e-001,4.431869e-001,-2.550562e-001,2.852817e-001,3.430121e-001,-3.375266e-006,-3.375266e-006,,,,,,,,,,,,,,,,,,,,
1405548961.062,,5.000000e+001,2.979968e+002,2.979968e+002,1,0,6.503903e-003,-9.437850e-001,-9.437849e-001,-3.820772e-001,-3.565963e-001,-7.185313e-001,-1.568236e-001,-1.313426e-001,-2.056751e-005,-2.056751e-005,,,,,,,,,,,,,,,,,,,,
1405548961.062,,5.000000e+001,2.979968e+002,2.979968e+002,1,0,2.751464e+000,-1.782281e-001,-1.782281e-001,3.134071e-001,4.089605e-001,-2.836678e-001,2.079674e-001,3.035208e-001,-3.884050e-006,-3.884050e-006,,,,,,,,,,,,,,,,,,,,
1405549080.546,,4.500000e+001,2.980050e+002,2.980050e+002,1,0,3.301461e+000,-5.172887e-001,-5.172887e-001,4.503317e-002,1.031779e-001,-6.788672e-001,-1.165452e-001,-5.840051e-002,-1.127306e-005,-1.127306e-005,,,,,,,,,,,,,,,,,,,,
1405549098.781,,4.500000e+001,2.980132e+002,2.980050e+002,1,0,2.234939e-001,-8.239998e-001,-8.239998e-001,-2.985594e-001,-2.686232e-001,-7.186001e-001,-1.931597e-001,-1.632236e-001,-1.795709e-005,-1.795709e-005,,,,,,,,,,,,,,,,,,,,
1405549116.578,,4.500000e+001,2.979968e+002,2.980050e+002,1,0,2.079527e+000,-1.283303e-001,-1.283303e-001,4.265664e-001,4.265664e-001,-5.422157e-002,5.006751e-001,5.006751e-001,-2.796651e-006,-2.796651e-006,,,,,,,,,,,,,,,,,,,,
1405549116.578,,4.500000e+001,2.979968e+002,2.980050e+002,1,0,3.809928e+000,-7.620472e-001,-7.620472e-001,-2.756731e-001,-2.071505e-001,-7.033091e-001,-2.169350e-001,-1.484123e-001,-1.660698e-005,-1.660698e-005,,,,,,,,,,,,,,,,,,,,
1405549234.062,,4.000000e+001,2.980050e+002,2.980050e+002,1,0,6.830761e-001,-6.381420e-001,-6.381420e-001,-8.145248e-002,-4.697633e-002,-7.446155e-001,-1.879259e-001,-1.534498e-001,-1.390677e-005,-1.390677e-005,,,,,,,,,,,,,,,,,,,,
1405549251.546,,4.000000e+001,2.980050e+002,2.979968e+002,1,0,1.361417e+000,-3.053377e-001,-3.053377e-001,2.494681e-001,2.554075e-001,-4.271480e-001,1.276578e-001,1.335972e-001,-6.654102e-006,-6.654102e-006,,,,,,,,,,,,,,,,,,,,
1405549251.546,,4.000000e+001,2.980050e+002,2.979968e+002,1,0,3.994446e+000,-8.442945e-001,-8.442945e-001,-3.548228e-001,-2.835493e-001,-6.733879e-001,-1.839162e-001,-1.126427e-001,-1.839937e-005,-1.839937e-005,,,,,,,,,,,,,,,,,,,,
1405549269.078,,4.000000e+001,2.980050e+002,2.979968e+002,1,0,1.249523e+000,-3.427229e-001,-3.427229e-001,1.745188e-001,2.165153e-001,-4.565966e-001,6.064506e-002,1.026416e-001,-7.468822e-006,-7.468822e-006,,,,,,,,,,,,,,,,,,,,
1405549389.062,,3.500000e+001,2.979968e+002,2.979968e+002,1,0,6.995214e-001,-5.696280e-001,-5.696280e-001,-3.392518e-002,-2.353776e-002,-7.119740e-001,-1.762712e-001,-1.658838e-001,-1.241368e-005,-1.241368e-005,,,,,,,,,,,,,,,,,,,,
1405549389.062,,3.500000e+001,2.979968e+002,2.979968e+002,1,0,3.777452e+000,-7.292398e-001,-7.292398e-001,-2.506678e-001,-1.831495e-001,-6.772361e-001,-1.986642e-001,-1.311459e-001,-1.589204e-005,-1.589204e-005,,,,,,,,,,,,,,,,,,,,
1405549407.562,,3.500000e+001,2.980050e+002,2.979968e+002,1,0,1.921230e+000,-2.056947e-001,-2.056947e-001,3.051576e-001,3.500308e-001,-9.037091e-002,4.204815e-001,4.653546e-001,-4.482626e-006,-4.482626e-006,,,,,,,,,,,,,,,,,,,,
1405549425.812,,3.500000e+001,2.979968e+002,2.979968e+002,1,0,1.909445e-001,-7.762383e-001,-7.762383e-001,-2.635343e-001,-2.455087e-001,-6.804768e-001,-1.677728e-001,-1.497472e-001,-1.691626e-005,-1.691626e-005,,,,,,,,,,,,,,,,,,,,
1405549425.812,,3.500000e+001,2.979968e+002,2.979968e+002,1,0,3.317854e+000,-4.409924e-001,-4.409925e-001,5.617592e-003,8.973712e-002,-5.545802e-001,-1.079701e-001,-2.385062e-002,-9.610377e-006,-9.610377e-006,,,,,,,,,,,,,,,,,,,,
1405549544.796,,3.000000e+001,2.980050e+002,2.979968e+002,1,0,2.639620e+000,-2.005066e-001,-2.005066e-001,3.293489e-001,3.683134e-001,-2.857813e-001,2.440742e-001,2.830388e-001,-4.369565e-006,-4.369565e-006,,,,,,,,,,,,,,,,,,,,
1405549562.546,,3.000000e+001,2.980050e+002,2.979885e+002,1,0,6.626224e-003,-8.333079e-001,-8.333079e-001,-3.258775e-001,-3.060538e-001,-6.324489e-001,-1.250185e-001,-1.051947e-001,-1.815996e-005,-1.815996e-005,,,,,,,,,,,,,,,,,,,,
1405549562.546,,3.000000e+001,2.980050e+002,2.979885e+002,1,0,2.751544e+000,-1.846370e-001,-1.846370e-001,2.682782e-001,3.426172e-001,-2.713967e-001,1.815185e-001,2.558575e-001,-4.023724e-006,-4.023724e-006,,,,,,,,,,,,,,,,,,,,
1405549580.281,,3.000000e+001,2.980050e+002,2.979968e+002,1,0,3.301503e+000,-4.150517e-001,-4.150517e-001,4.927648e-002,1.042503e-001,-5.573812e-001,-9.305295e-002,-3.807908e-002,-9.045065e-006,-9.045065e-006,,,,,,,,,,,,,,,,,,,,
1405549698.515,,2.500000e+001,2.979968e+002,2.979968e+002,1,0,2.235194e-001,-7.596057e-001,-7.596057e-001,-2.451549e-001,-2.252790e-001,-6.668736e-001,-1.524227e-001,-1.325468e-001,-1.655381e-005,-1.655381e-005,,,,,,,,,,,,,,,,,,,,
1405549716.765,,2.500000e+001,2.979968e+002,2.980050e+002,1,0,2.079724e+000,-1.590014e-001,-1.590014e-001,3.363820e-001,3.363820e-001,-9.287778e-002,4.025057e-001,4.025057e-001,-3.465060e-006,-3.465060e-006,,,,,,,,,,,,,,,,,,,,
1405549716.765,,2.500000e+001,2.979968e+002,2.980050e+002,1,0,3.809994e+000,-6.700339e-001,-6.700339e-001,-2.256508e-001,-1.746504e-001,-6.203188e-001,-1.759357e-001,-1.249353e-001,-1.460180e-005,-1.460180e-005,,,,,,,,,,,,,,,,,,,,
1405549734.546,,2.500000e+001,2.979968e+002,2.979968e+002,1,0,6.829920e-001,-5.516220e-001,-5.516220e-001,-6.460396e-002,-3.513807e-002,-6.496515e-001,-1.626334e-001,-1.331676e-001,-1.202130e-005,-1.202130e-005,,,,,,,,,,,,,,,,,,,,
1405549853.062,,2.000000e+001,2.979968e+002,2.979968e+002,1,0,1.361089e+000,-2.977081e-001,-2.977081e-001,1.979003e-001,2.023502e-001,-4.057449e-001,8.986346e-002,9.431338e-002,-6.487845e-006,-6.487845e-006,,,,,,,,,,,,,,,,,,,,
1405549853.062,,2.000000e+001,2.979968e+002,2.979968e+002,1,0,3.994371e+000,-7.388532e-001,-7.388531e-001,-2.921939e-001,-2.387949e-001,-5.955574e-001,-1.488982e-001,-9.549916e-002,-1.610156e-005,-1.610156e-005,,,,,,,,,,,,,,,,,,,,
1405549871.546,,2.000000e+001,2.979968e+002,2.979885e+002,1,0,1.249552e+000,-3.334147e-001,-3.334147e-001,1.387514e-001,1.666081e-001,-4.367941e-001,3.537198e-002,6.322864e-002,-7.265987e-006,-7.265987e-006,,,,,,,,,,,,,,,,,,,,
1405549889.781,,2.000000e+001,2.979885e+002,2.979968e+002,1,0,6.995426e-001,-4.919584e-001,-4.919584e-001,-2.395898e-002,-1.425931e-002,-6.176858e-001,-1.496864e-001,-1.399867e-001,-1.072107e-005,-1.072107e-005,,,,,,,,,,,,,,,,,,,,
1405549889.781,,2.000000e+001,2.979885e+002,2.979968e+002,1,0,3.777469e+000,-6.270028e-001,-6.270028e-001,-2.123515e-001,-1.493037e-001,-5.802673e-001,-1.656161e-001,-1.025682e-001,-1.366405e-005,-1.366405e-005,,,,,,,,,,,,,,,,,,,,
1405550009.562,,1.500000e+001,2.980050e+002,2.979968e+002,1,0,1.921275e+000,-1.568651e-001,-1.568651e-001,2.250271e-001,2.624191e-001,-6.420919e-002,3.176830e-001,3.550750e-001,-3.418507e-006,-3.418507e-006,,,,,,,,,,,,,,,,,,,,
1405550027.390,,1.500000e+001,2.979968e+002,2.979968e+002,1,0,1.909828e-001,-6.277657e-001,-6.277657e-001,-2.119240e-001,-1.978624e-001,-5.415217e-001,-1.256800e-001,-1.116184e-001,-1.368068e-005,-1.368068e-005,,,,,,,,,,,,,,,,,,,,
1405550027.390,,1.500000e+001,2.979968e+002,2.979968e+002,1,0,3.317918e+000,-3.474532e-001,-3.474532e-001,1.682949e-002,8.245006e-002,-4.385091e-001,-7.422636e-002,-8.605778e-003,-7.571927e-006,-7.571927e-006,,,,,,,,,,,,,,,,,,,,
1405550045.656,,1.500000e+001,2.979968e+002,2.979968e+002,1,0,2.639837e+000,-3.875851e-002,-3.875851e-002,2.814577e-001,3.273986e-001,-1.102467e-001,2.099696e-001,2.559105e-001,-8.446506e-007,-8.446506e-007,,,,,,,,,,,,,,,,,,,,
1405550165.140,,1.000000e+001,2.979968e+002,2.979968e+002,1,0,6.613108e-003,-6.357006e-001,-6.357005e-001,-2.683555e-001,-2.501138e-001,-4.582105e-001,-9.086542e-002,-7.262376e-002,-1.385361e-005,-1.385361e-005,,,,,,,,,,,,,,,,,,,,
1405550165.140,,1.000000e+001,2.979968e+002,2.979968e+002,1,0,2.751564e+000,-1.022370e-001,-1.022370e-001,2.149435e-001,2.833497e-001,-1.706753e-001,1.465052e-001,2.149114e-001,-2.228016e-006,-2.228016e-006,,,,,,,,,,,,,,,,,,,,
1405550183.625,,1.000000e+001,2.979968e+002,2.979968e+002,1,0,3.301470e+000,-2.545244e-001,-2.545244e-001,5.662513e-002,1.019226e-001,-3.729145e-001,-6.176496e-002,-1.646748e-002,-5.546764e-006,-5.546764e-006,,,,,,,,,,,,,,,,,,,,
1405550201.359,,1.000000e+001,2.979968e+002,2.979968e+002,1,0,2.236149e-001,-6.456191e-001,-6.456191e-001,-2.029514e-001,-1.794058e-001,-5.614972e-001,-1.188295e-001,-9.528396e-002,-1.406976e-005,-1.406976e-005,,,,,,,,,,,,,,,,,,,,
1405550319.625,,5.000000e+000,2.980050e+002,2.979968e+002,1,0,2.079777e+000,-1.411481e-001,-1.411481e-001,2.358721e-001,2.358721e-001,-8.553112e-002,2.914891e-001,2.914891e-001,-3.075994e-006,-3.075994e-006,,,,,,,,,,,,,,,,,,,,
1405550319.625,,5.000000e+000,2.980050e+002,2.979968e+002,1,0,3.810055e+000,-5.037080e-001,-5.037080e-001,-1.672372e-001,-1.266878e-001,-4.648928e-001,-1.284220e-001,-8.787259e-002,-1.097714e-005,-1.097714e-005,,,,,,,,,,,,,,,,,,,,
1405550337.109,,5.000000e+000,2.980050e+002,2.979968e+002,1,0,6.830407e-001,-4.008606e-001,-4.008606e-001,-3.209543e-002,-8.922786e-003,-4.882754e-001,-1.195102e-001,-9.633759e-002,-8.735824e-006,-8.735824e-006,,,,,,,,,,,,,,,,,,,,
1405550354.671,,5.000000e+000,2.979968e+002,2.980050e+002,1,0,1.361407e+000,-1.924192e-001,-1.924192e-001,1.551999e-001,1.591763e-001,-2.839727e-001,6.364636e-002,6.762275e-002,-4.193329e-006,-4.193329e-006,,,,,,,,,,,,,,,,,,,,
1405550354.671,,5.000000e+000,2.979968e+002,2.980050e+002,1,0,3.994451e+000,-5.421613e-001,-5.421613e-001,-2.382826e-001,-1.905659e-001,-4.202321e-001,-1.163533e-001,-6.863660e-002,-1.181514e-005,-1.181514e-005,,,,,,,,,,,,,,,,,,,,
1405550473.406,,0.000000e+000,2.979968e+002,2.979968e+002,1,0,1.249421e+000,-4.524369e-001,-4.524369e-001,1.131526e-001,1.121517e-001,-5.442646e-001,2.132486e-002,2.032393e-002,-9.859813e-006,-9.859813e-006,,,,,,,,,,,,,,,,,,,,
1405550491.640,,0.000000e+000,2.979968e+002,2.979968e+002,1,0,6.992933e-001,-4.815821e-001,-4.815821e-001,-2.097626e-003,-1.520574e-003,-5.856279e-001,-1.061435e-001,-1.055664e-001,-1.049496e-005,-1.049496e-005,,,,,,,,,,,,,,,,,,,,
1405550491.640,,0.000000e+000,2.979968e+002,2.979968e+002,1,0,3.777379e+000,-6.274605e-001,-6.274605e-001,-1.511499e-001,-1.473990e-001,-5.911717e-001,-1.148610e-001,-1.111102e-001,-1.367405e-005,-1.367405e-005,,,,,,,,,,,,,,,,,,,,
1405550509.421,,0.000000e+000,2.980050e+002,2.980050e+002,1,0,1.921266e+000,-2.848903e-001,-2.848903e-001,1.551101e-001,1.650783e-001,-2.049291e-001,2.350713e-001,2.450396e-001,-6.208523e-006,-6.208523e-006,,,,,,,,,,,,,,,,,,,,
1405550627.671,,-5.000000e+000,2.979885e+002,2.979968e+002,1,0,1.909626e-001,-8.374279e-001,-8.374279e-001,-1.522435e-001,-1.631585e-001,-7.709200e-001,-8.573558e-002,-9.665060e-002,-1.824979e-005,-1.824979e-005,,,,,,,,,,,,,,,,,,,,
1405550627.671,,-5.000000e+000,2.979885e+002,2.979968e+002,1,0,3.317955e+000,-7.084872e-001,-7.084872e-001,1.671892e-002,-3.421783e-002,-7.839468e-001,-5.874068e-002,-1.096774e-001,-1.543983e-005,-1.543983e-005,,,,,,,,,,,,,,,,,,,,
1405550644.906,,-5.000000e+000,2.979968e+002,2.979968e+002,1,0,2.639846e+000,-4.632710e-001,-4.632710e-001,1.903758e-001,1.697769e-001,-5.360103e-001,1.176365e-001,9.703761e-002,-1.009591e-005,-1.009591e-005,,,,,,,,,,,,,,,,,,,,
1405550663.203,,-5.000000e+000,2.979968e+002,2.980050e+002,1,0,6.625262e-003,-7.869197e-001,-7.869198e-001,-2.127258e-001,-2.178212e-001,-6.434873e-001,-6.929336e-002,-7.438880e-002,-1.714908e-005,-1.714908e-005,,,,,,,,,,,,,,,,,,,,
1405550663.203,,-5.000000e+000,2.979968e+002,2.980050e+002,1,0,2.751535e+000,-4.423658e-001,-4.423658e-001,1.458407e-001,1.267327e-001,-5.041352e-001,8.407126e-002,6.496334e-002,-9.640333e-006,-9.640333e-006,,,,,,,,,,,,,,,,,,,,
1405550782.437,,-1.000000e+001,2.979968e+002,2.980050e+002,1,0,3.301524e+000,-9.414960e-001,-9.414960e-001,4.652006e-002,-2.465892e-002,-1.049725e+000,-6.170922e-002,-1.328882e-001,-2.051770e-005,-2.051770e-005,,,,,,,,,,,,,,,,,,,,
1405550800.671,,-1.000000e+001,2.979968e+002,2.980050e+002,1,0,2.236328e-001,-9.547716e-001,-9.547716e-001,-1.294871e-001,-1.552811e-001,-9.049380e-001,-7.965351e-002,-1.054475e-001,-2.080701e-005,-2.080701e-005,,,,,,,,,,,,,,,,,,,,
1405550818.656,,-1.000000e+001,2.980050e+002,2.980050e+002,1,0,2.079705e+000,-5.748161e-001,-5.748161e-001,1.631123e-001,1.631123e-001,-5.532485e-001,1.846799e-001,1.846799e-001,-1.252677e-005,-1.252677e-005,,,,,,,,,,,,,,,,,,,,
1405550818.656,,-1.000000e+001,2.980050e+002,2.980050e+002,1,0,3.810014e+000,-8.973968e-001,-8.973967e-001,-1.220289e-001,-1.594684e-001,-8.509728e-001,-7.560498e-002,-1.130444e-001,-1.955666e-005,-1.955666e-005,,,,,,,,,,,,,,,,,,,,
1405550937.421,,-1.500000e+001,2.979968e+002,2.980050e+002,1,0,6.830001e-001,-1.136509e+000,-1.136509e+000,3.084831e-002,-2.906024e-002,-1.166313e+000,1.045037e-003,-5.886352e-002,-2.476755e-005,-2.476755e-005,,,,,,,,,,,,,,,,,,,,
1405550954.968,,-1.500000e+001,2.980050e+002,2.979968e+002,1,0,1.361024e+000,-8.462783e-001,-8.462783e-001,1.546240e-001,1.471136e-001,-8.661816e-001,1.347206e-001,1.272102e-001,-1.844265e-005,-1.844265e-005,,,,,,,,,,,,,,,,,,,,
1405550954.968,,-1.500000e+001,2.980050e+002,2.979968e+002,1,0,3.994376e+000,-1.241188e+000,-1.241188e+000,-1.576709e-001,-2.477960e-001,-1.116024e+000,-3.250755e-002,-1.226327e-001,-2.704877e-005,-2.704877e-005,,,,,,,,,,,,,,,,,,,,
1405550972.718,,-1.500000e+001,2.980050e+002,2.980050e+002,1,0,1.249494e+000,-8.745078e-001,-8.745079e-001,1.148511e-001,7.506263e-002,-8.718646e-001,1.174944e-001,7.770592e-002,-1.905785e-005,-1.905785e-005,,,,,,,,,,,,,,,,,,,,
1405551098.734,,-2.000000e+001,2.980050e+002,2.980050e+002,1,0,6.995686e-001,-1.261788e+000,-1.261788e+000,7.595795e-002,4.872918e-002,-1.296424e+000,4.132146e-002,1.409268e-002,-2.749769e-005,-2.749769e-005,,,,,,,,,,,,,,,,,,,,
1405551098.734,,-2.000000e+001,2.980050e+002,2.980050e+002,1,0,3.777473e+000,-1.590625e+000,-1.590625e+000,-1.031207e-001,-2.801077e-001,-1.514214e+000,-2.670993e-002,-2.036970e-001,-3.466391e-005,-3.466391e-005,,,,,,,,,,,,,,,,,,,,
1405551116.468,,-2.000000e+001,2.979968e+002,2.979968e+002,1,0,1.921288e+000,-1.222266e+000,-1.222266e+000,6.589249e-002,-2.386642e-002,-1.212963e+000,7.519558e-002,-1.456332e-002,-2.663641e-005,-2.663641e-005,,,,,,,,,,,,,,,,,,,,
1405551133.703,,-2.000000e+001,2.979968e+002,2.979968e+002,1,0,1.910166e-001,-1.173131e+000,-1.173131e+000,-6.399592e-002,-9.288549e-002,-1.143452e+000,-3.431638e-002,-6.320596e-002,-2.556563e-005,-2.556563e-005,,,,,,,,,,,,,,,,,,,,
1405551133.703,,-2.000000e+001,2.979968e+002,2.979968e+002,1,0,3.317981e+000,-1.220435e+000,-1.220435e+000,-5.371163e-003,-1.401892e-001,-1.265668e+000,-5.060381e-002,-1.854218e-001,-2.659651e-005,-2.659651e-005,,,,,,,,,,,,,,,,,,,,
1405551254.453,,-2.500000e+001,2.979968e+002,2.979968e+002,1,0,2.639657e+000,-1.621601e+000,-1.621601e+000,7.244673e-002,-1.017054e-001,-1.737216e+000,-4.316864e-002,-2.173208e-001,-3.533895e-005,-3.533895e-005,,,,,,,,,,,,,,,,,,,,
1405551272.687,,-2.500000e+001,2.979968e+002,2.979968e+002,1,0,6.545093e-003,-1.560564e+000,-1.560564e+000,-1.123057e-001,-1.770957e-001,-1.483726e+000,-3.546732e-002,-1.002573e-001,-3.400880e-005,-3.400880e-005,,,,,,,,,,,,,,,,,,,,
1405551272.687,,-2.500000e+001,2.979968e+002,2.979968e+002,1,0,2.751456e+000,-1.606342e+000,-1.606342e+000,2.008901e-002,-2.228733e-001,-1.676168e+000,-4.973723e-002,-2.926996e-001,-3.500641e-005,-3.500641e-005,,,,,,,,,,,,,,,,,,,,
1405551290.921,,-2.500000e+001,2.979968e+002,2.979968e+002,1,0,3.301478e+000,-1.351054e+000,-1.351054e+000,3.690472e-002,-1.028631e-001,-1.426009e+000,-3.805003e-002,-1.778178e-001,-2.944303e-005,-2.944303e-005,,,,,,,,,,,,,,,,,,,,
1405551410.171,,-3.000000e+001,2.979968e+002,2.980050e+002,1,0,2.235629e-001,-1.926023e+000,-1.926023e+000,-3.639920e-002,-1.663226e-001,-1.889331e+000,2.934225e-004,-1.296300e-001,-4.197309e-005,-4.197309e-005,,,,,,,,,,,,,,,,,,,,
1405551428.156,,-3.000000e+001,2.979968e+002,2.979968e+002,1,0,2.079629e+000,-1.512650e+000,-1.512650e+000,6.288624e-002,6.288624e-002,-1.564385e+000,1.115108e-002,1.115108e-002,-3.296461e-005,-3.296461e-005,,,,,,,,,,,,,,,,,,,,
1405551428.156,,-3.000000e+001,2.979968e+002,2.979968e+002,1,0,3.809982e+000,-1.859798e+000,-1.859798e+000,-4.081497e-002,-2.842618e-001,-1.834040e+000,-1.505730e-002,-2.585042e-001,-4.052987e-005,-4.052987e-005,,,,,,,,,,,,,,,,,,,,
1405551445.890,,-3.000000e+001,2.979968e+002,2.979968e+002,1,0,6.830164e-001,-1.469466e+000,-1.469466e+000,7.146353e-002,-4.491329e-002,-1.474393e+000,6.653697e-002,-4.983985e-002,-3.202352e-005,-3.202352e-005,,,,,,,,,,,,,,,,,,,,
1405551556.937,,-3.500000e+001,2.979968e+002,2.979968e+002,1,0,1.361247e+000,-1.960204e+000,-1.960204e+000,7.009051e-002,3.129959e-002,-2.015583e+000,1.471160e-002,-2.407932e-002,-4.271796e-005,-4.271796e-005,,,,,,,,,,,,,,,,,,,,
1405551556.937,,-3.500000e+001,2.979968e+002,2.979968e+002,1,0,3.994434e+000,-2.526628e+000,-2.526627e+000,-6.963280e-002,-5.351238e-001,-2.469264e+000,-1.226953e-002,-4.777606e-001,-5.506181e-005,-5.506181e-005,,,,,,,,,,,,,,,,,,,,
1405551575.171,,-3.500000e+001,2.979968e+002,2.980050e+002,1,0,1.249606e+000,-1.844386e+000,-1.844386e+000,9.826300e-002,-1.376375e-001,-1.933525e+000,9.124495e-003,-2.267760e-001,-4.019399e-005,-4.019399e-005,,,,,,,,,,,,,,,,,,,,
1405551593.406,,-3.500000e+001,2.980050e+002,2.980050e+002,1,0,6.991779e-001,-1.505631e+000,-1.505631e+000,5.099624e-002,-8.462787e-003,-1.567906e+000,-1.127928e-002,-7.073832e-002,-3.281162e-005,-3.281162e-005,,,,,,,,,,,,,,,,,,,,
1405551593.406,,-3.500000e+001,2.980050e+002,2.980050e+002,1,0,3.777331e+000,-1.915952e+000,-1.915952e+000,-3.230044e-002,-4.187841e-001,-1.898490e+000,-1.483878e-002,-4.013225e-001,-4.175360e-005,-4.175360e-005,,,,,,,,,,,,,,,,,,,,
1405551712.390,,-4.000000e+001,2.979968e+002,2.979968e+002,1,0,1.921448e+000,-2.345347e+000,-2.345347e+000,-2.593675e-002,-3.519671e-001,-2.318633e+000,7.773340e-004,-3.252530e-001,-5.111122e-005,-5.111122e-005,,,,,,,,,,,,,,,,,,,,
1405551729.875,,-4.000000e+001,2.980050e+002,2.979968e+002,1,0,1.908699e-001,-1.915036e+000,-1.915036e+000,-5.216362e-002,-1.626045e-001,-1.862852e+000,2.072006e-005,-1.104201e-001,-4.173363e-005,-4.173363e-005,,,,,,,,,,,,,,,,,,,,
1405551729.875,,-4.000000e+001,2.980050e+002,2.979968e+002,1,0,3.317735e+000,-2.234107e+000,-2.234107e+000,3.371502e-002,-4.816755e-001,-2.268102e+000,-2.796501e-004,-5.156702e-001,-4.868701e-005,-4.868701e-005,,,,,,,,,,,,,,,,,,,,
1405551747.609,,-4.000000e+001,2.979968e+002,2.979968e+002,1,0,2.639900e+000,-1.777245e+000,-1.777245e+000,1.749117e-003,-2.850868e-001,-1.779184e+000,-1.892261e-004,-2.870251e-001,-3.873080e-005,-3.873080e-005,,,,,,,,,,,,,,,,,,,,
1405551865.609,,-4.500000e+001,2.979885e+002,2.980050e+002,1,0,6.622372e-003,-2.287668e+000,-2.287668e+000,-8.161274e-002,-2.534521e-001,-2.205939e+000,1.161993e-004,-1.717231e-001,-4.985420e-005,-4.985420e-005,,,,,,,,,,,,,,,,,,,,
1405551865.609,,-4.500000e+001,2.979885e+002,2.980050e+002,1,0,2.751414e+000,-2.684256e+000,-2.684256e+000,-5.642675e-003,-6.500401e-001,-2.680144e+000,-1.531146e-003,-6.459286e-001,-5.849688e-005,-5.849688e-005,,,,,,,,,,,,,,,,,,,,
1405551883.843,,-4.500000e+001,2.979968e+002,2.980050e+002,1,0,3.301654e+000,-2.105167e+000,-2.105167e+000,3.105008e-002,-3.494804e-001,-2.137013e+000,-7.966831e-004,-3.813272e-001,-4.587704e-005,-4.587704e-005,,,,,,,,,,,,,,,,,,,,
1405551902.078,,-4.500000e+001,2.979968e+002,2.980050e+002,1,0,2.236255e-001,-1.735588e+000,-1.735588e+000,-2.175420e-002,-1.872625e-001,-1.713854e+000,-2.055988e-005,-1.655289e-001,-3.782295e-005,-3.782295e-005,,,,,,,,,,,,,,,,,,,,
1405552021.828,,-5.000000e+001,2.980050e+002,2.979968e+002,1,0,2.079624e+000,-1.998505e+000,-1.998505e+000,-8.793449e-002,-8.793449e-002,-1.951003e+000,-4.043245e-002,-4.043245e-002,-4.355257e-005,-4.355257e-005,,,,,,,,,,,,,,,,,,,,
1405552021.828,,-5.000000e+001,2.980050e+002,2.979968e+002,1,0,3.810079e+000,-2.341685e+000,-2.341685e+000,-2.282415e-003,-4.311152e-001,-2.323256e+000,1.614734e-002,-4.126854e-001,-5.103136e-005,-5.103136e-005,,,,,,,,,,,,,,,,,,,,
1405552040.078,,-5.000000e+001,2.980050e+002,2.979968e+002,1,0,6.831176e-001,-1.828517e+000,-1.828516e+000,9.161230e-002,-1.100414e-001,-1.891859e+000,2.826997e-002,-1.733837e-001,-3.984809e-005,-3.984809e-005,,,,,,,,,,,,,,,,,,,,
1405552058.312,,-5.000000e+001,2.979968e+002,2.980050e+002,1,0,1.361026e+000,-1.492355e+000,-1.492355e+000,4.582419e-002,1.581419e-002,-1.512225e+000,2.595391e-002,-4.056096e-003,-3.252227e-005,-3.252227e-005,,,,,,,,,,,,,,,,,,,,
1405552058.312,,-5.000000e+001,2.979968e+002,2.980050e+002,1,0,3.994374e+000,-1.893674e+000,-1.893674e+000,-2.538414e-002,-3.855042e-001,-1.840275e+000,2.801471e-002,-3.321054e-001,-4.126803e-005,-4.126803e-005,,,,,,,,,,,,,,,,,,,,
1405552209.046,,-7.500000e+001,2.980050e+002,2.979968e+002,1,0,1.249615e+000,-7.409894e-001,-7.409894e-001,8.290379e-003,-8.748227e-002,-7.476203e-001,1.659422e-003,-9.411323e-002,-8.074017e-005,-8.074017e-005,,,,,,,,,,,,,,,,,,,,
1405552226.531,,-7.500000e+001,2.979968e+002,2.980050e+002,1,0,6.994315e-001,-5.565050e-001,-5.565050e-001,2.352390e-002,-3.792048e-004,-5.598564e-001,2.017250e-002,-3.730595e-003,-6.063826e-005,-6.063826e-005,,,,,,,,,,,,,,,,,,,,
1405552226.531,,-7.500000e+001,2.979968e+002,2.980050e+002,1,0,3.777334e+000,-6.949065e-001,-6.949065e-001,1.658950e-002,-1.387807e-001,-6.914792e-001,2.001676e-002,-1.353534e-001,-7.571885e-005,-7.571885e-005,,,,,,,,,,,,,,,,,,,,
1405552244.046,,-7.500000e+001,2.979968e+002,2.980050e+002,1,0,1.921448e+000,-6.358532e-001,-6.358532e-001,-4.010835e-002,-1.269782e-001,-6.331573e-001,-3.741243e-002,-1.242822e-001,-6.928424e-005,-6.928424e-005,,,,,,,,,,,,,,,,,,,,
1405552394.265,,-1.000000e+002,2.980050e+002,2.979968e+002,1,0,1.909519e-001,2.716147e-001,2.716147e-001,1.409006e-001,9.189656e-002,2.615202e-001,1.308061e-001,8.180207e-002,5.919159e-006,5.919159e-006,,,,,,,,,,,,,,,,,,,,
1405552394.265,,-1.000000e+002,2.980050e+002,2.979968e+002,1,0,3.317836e+000,5.035554e-003,5.035554e-003,5.400276e-002,-1.746826e-001,2.087660e-002,6.984381e-002,-1.588416e-001,1.097372e-007,1.097372e-007,,,,,,,,,,,,,,,,,,,,
1405552412.000,,-1.000000e+002,2.979968e+002,2.979968e+002,1,0,2.639906e+000,-9.221168e-001,-9.221168e-001,-2.295974e-001,-4.114184e-001,-9.280643e-001,-2.355450e-001,-4.173660e-001,-2.009521e-005,-2.009521e-005,,,,,,,,,,,,,,,,,,,,
1405552430.250,,-1.000000e+002,2.979968e+002,2.979968e+002,1,0,6.575245e-003,-3.770562e-001,-3.770562e-001,1.077516e-001,5.055270e-002,-3.847253e-001,1.000824e-001,4.288355e-002,-8.216990e-006,-8.216990e-006,,,,,,,,,,,,,,,,,,,,
1405552430.250,,-1.000000e+002,2.979968e+002,2.979968e+002,1,0,2.751417e+000,-8.351390e-001,-8.351390e-001,-1.930344e-001,-4.075302e-001,-8.238441e-001,-1.817395e-001,-3.962353e-001,-1.819975e-005,-1.819975e-005,,,,,,,,,,,,,,,,,,,,
1405552555.234,,-7.500000e+001,2.980050e+002,2.979885e+002,1,0,3.301731e+000,2.211066e-001,2.211066e-001,3.117736e-002,4.554003e-003,2.281295e-001,3.820023e-002,1.157688e-002,4.818472e-006,4.818472e-006,,,,,,,,,,,,,,,,,,,,
1405552573.718,,-7.500000e+001,2.979968e+002,2.979968e+002,1,0,2.237083e-001,2.952666e-001,2.952666e-001,1.084383e-001,1.001195e-001,2.836141e-001,9.678587e-002,8.846700e-002,6.434606e-006,6.434606e-006,,,,,,,,,,,,,,,,,,,,
1405552591.703,,-7.500000e+001,2.979968e+002,2.980050e+002,1,0,2.079628e+000,-4.928739e-002,-4.928739e-002,-2.836560e-001,-2.836560e-001,-3.632134e-002,-2.706899e-001,-2.706899e-001,-1.074097e-006,-1.074097e-006,,,,,,,,,,,,,,,,,,,,
1405552591.703,,-7.500000e+001,2.979968e+002,2.980050e+002,1,0,3.810115e+000,3.204444e-001,3.204443e-001,1.108024e-001,8.607577e-002,3.318742e-001,1.222323e-001,9.750561e-002,6.983294e-006,6.983294e-006,,,,,,,,,,,,,,,,,,,,
1405552723.703,,-5.000000e+001,2.980050e+002,2.979885e+002,1,0,6.832299e-001,2.200385e-001,2.200385e-001,1.242253e-001,1.101314e-001,1.748324e-001,7.901920e-002,6.492537e-002,4.795206e-006,4.795206e-006,,,,,,,,,,,,,,,,,,,,
1405552741.468,,-5.000000e+001,2.979968e+002,2.980050e+002,1,0,1.361198e+000,9.781183e-002,9.781183e-002,2.374678e-003,6.624013e-004,8.641482e-002,-9.022326e-003,-1.073460e-002,2.131572e-006,2.131572e-006,,,,,,,,,,,,,,,,,,,,
1405552741.468,,-5.000000e+001,2.979968e+002,2.980050e+002,1,0,3.994435e+000,1.231422e-001,1.231422e-001,4.654008e-002,2.599276e-002,1.544499e-001,7.784782e-002,5.730050e-002,2.683586e-006,2.683586e-006,,,,,,,,,,,,,,,,,,,,
1405552759.203,,-5.000000e+001,2.980050e+002,2.980050e+002,1,0,1.249507e+000,1.570177e-001,1.570177e-001,5.658827e-002,4.243686e-002,1.141581e-001,1.372860e-002,-4.228055e-004,3.421821e-006,3.421821e-006,,,,,,,,,,,,,,,,,,,,
1405552877.937,,-4.500000e+001,2.980050e+002,2.979968e+002,1,0,6.994143e-001,1.115452e-001,1.115452e-001,1.004376e-001,9.571970e-002,8.155802e-002,7.045051e-002,6.573257e-002,2.430858e-006,2.430858e-006,,,,,,,,,,,,,,,,,,,,
1405552877.937,,-4.500000e+001,2.980050e+002,2.979968e+002,1,0,3.777373e+000,3.036592e-002,3.036592e-002,4.520709e-002,1.454047e-002,5.077577e-002,6.561694e-002,3.495032e-002,6.617520e-007,6.617520e-007,,,,,,,,,,,,,,,,,,,,
1405552896.718,,-4.500000e+001,2.979968e+002,2.979968e+002,1,0,1.921472e+000,-9.506516e-002,-9.506515e-002,-1.407820e-001,-1.576321e-001,-6.993456e-002,-1.156514e-001,-1.325015e-001,-2.071716e-006,-2.071716e-006,,,,,,,,,,,,,,,,,,,,
1405552914.203,,-4.500000e+001,2.979968e+002,2.980050e+002,1,0,1.908525e-001,7.065035e-002,7.065035e-002,2.758832e-002,2.068138e-002,8.891276e-002,4.585073e-002,3.894380e-002,1.539654e-006,1.539654e-006,,,,,,,,,,,,,,,,,,,,
1405552914.203,,-4.500000e+001,2.979968e+002,2.980050e+002,1,0,3.317785e+000,4.272591e-002,4.272591e-002,2.498929e-002,-7.243048e-003,2.303826e-002,5.301645e-003,-2.693070e-002,9.311083e-007,9.311083e-007,,,,,,,,,,,,,,,,,,,,
1405553032.015,,-4.000000e+001,2.979968e+002,2.980050e+002,1,0,2.640082e+000,-1.017792e-001,-1.017792e-001,-9.952072e-002,-1.149499e-001,-1.219335e-001,-1.196750e-001,-1.351042e-001,-2.218034e-006,-2.218034e-006,,,,,,,,,,,,,,,,,,,,
1405553050.000,,-4.000000e+001,2.980050e+002,2.979885e+002,1,0,6.541179e-003,-1.617481e-002,-1.617481e-002,-2.714442e-002,-3.404351e-002,3.949457e-002,2.852496e-002,2.162587e-002,-3.524912e-007,-3.524912e-007,,,,,,,,,,,,,,,,,,,,
1405553050.000,,-4.000000e+001,2.980050e+002,2.979885e+002,1,0,2.751314e+000,-9.689627e-002,-9.689627e-002,-8.889338e-002,-1.147650e-001,-1.105544e-001,-1.025515e-001,-1.284231e-001,-2.111622e-006,-2.111622e-006,,,,,,,,,,,,,,,,,,,,
1405553068.250,,-4.000000e+001,2.979885e+002,2.980050e+002,1,0,3.301685e+000,-2.868740e-002,-2.868740e-002,2.000212e-002,-2.950812e-003,-5.285210e-002,-4.162582e-003,-2.711551e-002,-6.251730e-007,-6.251730e-007,,,,,,,,,,,,,,,,,,,,
1405553188.484,,-3.500000e+001,2.980050e+002,2.979885e+002,1,0,2.237579e-001,-6.103702e-004,-6.103702e-004,1.654340e-002,7.130492e-003,1.471199e-002,3.186576e-002,2.245285e-002,-1.330156e-008,-1.330156e-008,,,,,,,,,,,,,,,,,,,,
1405553206.718,,-3.500000e+001,2.979968e+002,2.979968e+002,1,0,2.079560e+000,-7.232887e-002,-7.232887e-002,-1.257534e-001,-1.257534e-001,-4.016896e-002,-9.359351e-002,-9.359351e-002,-1.576235e-006,-1.576235e-006,,,,,,,,,,,,,,,,,,,,
1405553206.718,,-3.500000e+001,2.979968e+002,2.979968e+002,1,0,3.810148e+000,6.500442e-002,6.500442e-002,2.474455e-002,1.157988e-002,8.483354e-002,4.457367e-002,3.140900e-002,1.416616e-006,1.416616e-006,,,,,,,,,,,,,,,,,,,,
1405553225.000,,-3.500000e+001,2.980050e+002,2.980050e+002,1,0,6.832622e-001,9.277627e-002,9.277627e-002,1.051845e-001,9.434729e-002,3.970640e-002,5.211460e-002,4.127742e-002,2.021837e-006,2.021837e-006,,,,,,,,,,,,,,,,,,,,
1405553345.000,,-3.000000e+001,2.979968e+002,2.979968e+002,1,0,1.360815e+000,4.593036e-002,4.593036e-002,4.930304e-002,4.780033e-002,1.881927e-002,2.219195e-002,2.068925e-002,1.000943e-006,1.000943e-006,,,,,,,,,,,,,,,,,,,,
1405553345.000,,-3.000000e+001,2.979968e+002,2.979968e+002,1,0,3.994377e+000,-3.051851e-002,-3.051851e-002,-1.061610e-002,-2.864853e-002,2.245571e-002,4.235812e-002,2.432568e-002,-6.650783e-007,-6.650783e-007,,,,,,,,,,,,,,,,,,,,
1405553362.734,,-3.000000e+001,2.980050e+002,2.980050e+002,1,0,1.249634e+000,5.981628e-002,5.981628e-002,8.375221e-002,7.503368e-002,8.052744e-003,3.198868e-002,2.327014e-002,1.303554e-006,1.303554e-006,,,,,,,,,,,,,,,,,,,,
1405553380.468,,-3.000000e+001,2.980050e+002,2.979968e+002,1,0,6.994236e-001,7.461775e-002,7.461776e-002,9.349433e-002,9.130866e-002,2.261827e-002,4.149484e-002,3.930917e-002,1.626117e-006,1.626117e-006,,,,,,,,,,,,,,,,,,,,
1405553380.468,,-3.000000e+001,2.980050e+002,2.979968e+002,1,0,3.777338e+000,-2.441481e-002,-2.441481e-002,6.482960e-003,-7.723907e-003,-2.655601e-003,2.824217e-002,1.403530e-002,-5.320626e-007,-5.320626e-007,,,,,,,,,,,,,,,,,,,,
1405553499.500,,-2.500000e+001,2.979968e+002,2.979968e+002,1,0,1.921474e+000,-1.217689e-001,-1.217689e-001,-7.387874e-002,-8.342418e-002,-5.852706e-002,-1.063694e-002,-2.018239e-002,-2.653664e-006,-2.653664e-006,,,,,,,,,,,,,,,,,,,,
1405553517.781,,-2.500000e+001,2.979968e+002,2.979968e+002,1,0,1.908545e-001,-7.950072e-002,-7.950072e-002,-1.688170e-002,-1.833329e-002,-5.178725e-002,1.083178e-002,9.380188e-003,-1.732530e-006,-1.732530e-006,,,,,,,,,,,,,,,,,,,,
1405553517.781,,-2.500000e+001,2.979968e+002,2.979968e+002,1,0,3.317757e+000,-6.515702e-002,-6.515702e-002,2.784505e-003,-3.989585e-003,-1.112636e-001,-4.332212e-002,-5.009621e-002,-1.419943e-006,-1.419943e-006,,,,,,,,,,,,,,,,,,,,
1405553535.765,,-2.500000e+001,2.979968e+002,2.979968e+002,1,0,2.639887e+000,-8.362071e-002,-8.362072e-002,-6.117250e-002,-6.400535e-002,-1.000038e-001,-7.755554e-002,-8.038838e-002,-1.822315e-006,-1.822315e-006,,,,,,,,,,,,,,,,,,,,
1405553654.515,,-2.000000e+001,2.979885e+002,2.980050e+002,1,0,6.672290e-003,-1.557970e-001,-1.557970e-001,-9.013239e-002,-1.040071e-001,-6.376478e-002,1.899816e-003,-1.197491e-002,-3.395228e-006,-3.395228e-006,,,,,,,,,,,,,,,,,,,,
1405553654.515,,-2.000000e+001,2.979885e+002,2.980050e+002,1,0,2.751385e+000,-1.405377e-001,-1.405377e-001,-3.671764e-002,-8.874787e-002,-1.287164e-001,-2.489634e-002,-7.692657e-002,-3.062688e-006,-3.062688e-006,,,,,,,,,,,,,,,,,,,,
1405553672.531,,-2.000000e+001,2.979968e+002,2.979968e+002,1,0,3.301744e+000,-2.365184e-002,-2.365185e-002,1.736713e-002,-9.108154e-003,-6.965503e-002,-2.863605e-002,-5.511134e-002,-5.154362e-007,-5.154362e-007,,,,,,,,,,,,,,,,,,,,
1405553690.015,,-2.000000e+001,2.980050e+002,2.980050e+002,1,0,2.236968e-001,-6.210517e-002,-6.210517e-002,-2.462814e-002,-3.483663e-002,-3.449825e-002,2.978781e-003,-7.229716e-003,-1.353436e-006,-1.353436e-006,,,,,,,,,,,,,,,,,,,,
1405553802.562,,-1.500000e+001,2.979968e+002,2.979968e+002,1,0,2.079355e+000,-1.829585e-001,-1.829585e-001,-7.290205e-002,-7.290205e-002,-1.107017e-001,-6.453171e-004,-6.453171e-004,-3.987150e-006,-3.987150e-006,,,,,,,,,,,,,,,,,,,,
1405553802.562,,-1.500000e+001,2.979968e+002,2.979968e+002,1,0,3.810064e+000,-1.768548e-001,-1.768548e-001,-6.872308e-003,-6.679834e-002,-1.684347e-001,1.547786e-003,-5.837824e-002,-3.854134e-006,-3.854134e-006,,,,,,,,,,,,,,,,,,,,
1405553820.343,,-1.500000e+001,2.979968e+002,2.979968e+002,1,0,6.832834e-001,-2.578814e-002,-2.578814e-002,7.820483e-002,5.130123e-002,-1.028594e-001,1.133560e-003,-2.577004e-002,-5.619920e-007,-5.619920e-007,,,,,,,,,,,,,,,,,,,,
1405553838.093,,-1.500000e+001,2.980050e+002,2.980050e+002,1,0,1.360948e+000,-3.204443e-002,-3.204444e-002,6.130896e-002,5.700080e-002,-9.336262e-002,-9.225681e-006,-4.317388e-003,-6.983332e-007,-6.983332e-007,,,,,,,,,,,,,,,,,,,,
1405553838.093,,-1.500000e+001,2.980050e+002,2.980050e+002,1,0,3.994392e+000,-1.712088e-001,-1.712088e-001,-3.046566e-002,-8.216361e-002,-1.406818e-001,6.140769e-005,-5.163654e-002,-3.731095e-006,-3.731095e-006,,,,,,,,,,,,,,,,,,,,
1405553957.093,,-1.000000e+001,2.980050e+002,2.979968e+002,1,0,1.249685e+000,3.357036e-003,3.357036e-003,1.160238e-001,8.379808e-002,-1.072457e-001,5.421105e-003,-2.680463e-002,7.315875e-008,7.315875e-008,,,,,,,,,,,,,,,,,,,,
1405553975.328,,-1.000000e+001,2.979968e+002,2.979885e+002,1,0,6.993574e-001,1.556444e-002,1.556444e-002,5.803585e-002,4.969887e-002,-4.900592e-002,-6.534510e-003,-1.487148e-002,3.391906e-007,3.391906e-007,,,,,,,,,,,,,,,,,,,,
1405553975.328,,-1.000000e+001,2.979968e+002,2.979885e+002,1,0,3.777320e+000,-1.025422e-001,-1.025422e-001,-1.421744e-002,-6.840776e-002,-9.692493e-002,-8.600179e-003,-6.279050e-002,-2.234667e-006,-2.234667e-006,,,,,,,,,,,,,,,,,,,,
1405553993.562,,-1.000000e+001,2.979968e+002,2.979968e+002,1,0,1.921477e+000,-8.911405e-002,-8.911405e-002,-9.506624e-003,-4.088945e-002,-5.874367e-002,2.086375e-002,-1.051908e-002,-1.942032e-006,-1.942032e-006,,,,,,,,,,,,,,,,,,,,
1405554112.546,,-5.000000e+000,2.979968e+002,2.980050e+002,1,0,1.908747e-001,-2.429273e-001,-2.429273e-001,-7.778434e-002,-9.167509e-002,-1.838911e-001,-1.874812e-002,-3.263886e-002,-5.294036e-006,-5.294036e-006,,,,,,,,,,,,,,,,,,,,
1405554112.546,,-5.000000e+000,2.979968e+002,2.980050e+002,1,0,3.317728e+000,-1.925718e-001,-1.925718e-001,2.350393e-002,-4.131953e-002,-2.311747e-001,-1.509896e-002,-7.992242e-002,-4.196654e-006,-4.196654e-006,,,,,,,,,,,,,,,,,,,,
1405554130.531,,-5.000000e+000,2.980050e+002,2.979968e+002,1,0,2.639978e+000,-1.580859e-001,-1.580859e-001,4.521011e-003,-2.900079e-002,-1.435190e-001,1.908791e-002,-1.443389e-002,-3.445114e-006,-3.445114e-006,,,,,,,,,,,,,,,,,,,,
1405554147.765,,-5.000000e+000,2.980050e+002,2.980050e+002,1,0,6.592386e-003,-2.595599e-001,-2.595599e-001,-1.354803e-001,-1.489041e-001,-1.399890e-001,-1.590928e-002,-2.933308e-002,-5.656504e-006,-5.656504e-006,,,,,,,,,,,,,,,,,,,,
1405554147.765,,-5.000000e+000,2.980050e+002,2.980050e+002,1,0,2.751308e+000,-1.431318e-001,-1.431318e-001,1.786332e-002,-3.247593e-002,-1.486955e-001,1.229963e-002,-3.803962e-002,-3.119225e-006,-3.119225e-006,,,,,,,,,,,,,,,,,,,,
1405554266.515,,0.000000e+000,2.979968e+002,2.979968e+002,1,0,3.301831e+000,-1.355022e-001,-1.355022e-001,1.683867e-002,5.205579e-002,-2.006451e-001,-4.830425e-002,-1.308712e-002,-2.952956e-006,-2.952956e-006,,,,,,,,,,,,,,,,,,,,
1405554284.265,,0.000000e+000,2.979968e+002,2.979968e+002,1,0,2.236961e-001,-2.203436e-001,-2.203436e-001,-4.236893e-002,-2.094999e-002,-1.884070e-001,-1.043233e-002,1.098661e-002,-4.801879e-006,-4.801879e-006,,,,,,,,,,,,,,,,,,,,
1405554302.000,,0.000000e+000,2.979968e+002,2.980050e+002,1,0,2.079528e+000,-9.598072e-002,-9.598071e-002,7.454912e-002,7.454912e-002,-1.451898e-001,2.534007e-002,2.534007e-002,-2.091677e-006,-2.091677e-006,,,,,,,,,,,,,,,,,,,,
1405554302.000,,0.000000e+000,2.979968e+002,2.980050e+002,1,0,3.810148e+000,-1.762444e-001,-1.762444e-001,-5.698243e-002,-5.714566e-003,-1.408735e-001,-2.161151e-002,2.965635e-002,-3.840838e-006,-3.840838e-006,,,,,,,,,,,,,,,,,,,,
1405554420.281,,5.000000e+000,2.980050e+002,2.980050e+002,1,0,6.832816e-001,-1.866207e-001,-1.866207e-001,7.621428e-002,1.005303e-001,-1.970969e-001,6.573804e-002,9.005405e-002,-4.066963e-006,-4.066963e-006,,,,,,,,,,,,,,,,,,,,
1405554438.062,,5.000000e+000,2.979968e+002,2.979885e+002,1,0,1.361148e+000,-1.266518e-002,-1.266518e-002,1.836715e-001,1.884788e-001,-3.192326e-002,1.644135e-001,1.692207e-001,-2.760081e-007,-2.760081e-007,,,,,,,,,,,,,,,,,,,,
1405554438.062,,5.000000e+000,2.979968e+002,2.979885e+002,1,0,3.994439e+000,-2.586444e-001,-2.586444e-001,-1.151871e-001,-5.750041e-002,-1.629297e-001,-1.947247e-002,3.821427e-002,-5.636552e-006,-5.636552e-006,,,,,,,,,,,,,,,,,,,,
1405554455.359,,5.000000e+000,2.980050e+002,2.979968e+002,1,0,1.249666e+000,-9.765923e-003,-9.765923e-003,1.615003e-001,1.956231e-001,-7.603103e-003,1.636631e-001,1.977859e-001,-2.128256e-007,-2.128256e-007,,,,,,,,,,,,,,,,,,,,
1405554580.609,,1.000000e+001,2.979968e+002,2.979885e+002,1,0,6.994313e-001,-1.905881e-001,-1.905881e-001,9.881517e-002,1.075833e-001,-2.306781e-001,5.872521e-002,6.749329e-002,-4.153422e-006,-4.153422e-006,,,,,,,,,,,,,,,,,,,,
1405554580.609,,1.000000e+001,2.979968e+002,2.979885e+002,1,0,3.777340e+000,-3.390606e-001,-3.390606e-001,-9.788182e-002,-4.088929e-002,-2.763849e-001,-3.520610e-002,2.178642e-002,-7.389034e-006,-7.389034e-006,,,,,,,,,,,,,,,,,,,,
1405554598.343,,1.000000e+001,2.979968e+002,2.979968e+002,1,0,1.921527e+000,-1.551866e-001,-1.551866e-001,8.551930e-002,1.272089e-001,-1.379952e-001,1.027107e-001,1.444003e-001,-3.381929e-006,-3.381929e-006,,,,,,,,,,,,,,,,,,,,
1405554616.078,,1.000000e+001,2.979968e+002,2.979968e+002,1,0,1.908285e-001,-3.018281e-001,-3.018281e-001,-7.145649e-002,-5.563810e-002,-2.751272e-001,-4.475564e-002,-2.893725e-002,-6.577637e-006,-6.577637e-006,,,,,,,,,,,,,,,,,,,,
1405554616.078,,1.000000e+001,2.979968e+002,2.979968e+002,1,0,3.317700e+000,-1.940977e-001,-1.940977e-001,-2.172691e-002,5.209222e-002,-2.397934e-001,-6.742262e-002,6.396517e-003,-4.229906e-006,-4.229906e-006,,,,,,,,,,,,,,,,,,,,
1405554734.843,,1.500000e+001,2.979968e+002,2.980050e+002,1,0,2.639867e+000,-2.388073e-001,-2.388073e-001,7.876586e-002,1.226116e-001,-3.549960e-001,-3.742277e-002,6.422997e-003,-5.204245e-006,-5.204245e-006,,,,,,,,,,,,,,,,,,,,
1405554752.078,,1.500000e+001,2.980050e+002,2.979968e+002,1,0,6.669687e-003,-4.148991e-001,-4.148991e-001,-1.568009e-001,-1.359427e-001,-3.402289e-001,-8.213072e-002,-6.127247e-002,-9.041752e-006,-9.041752e-006,,,,,,,,,,,,,,,,,,,,
1405554752.078,,1.500000e+001,2.980050e+002,2.979968e+002,1,0,2.751330e+000,-1.721244e-001,-1.721244e-001,2.861363e-002,1.068321e-001,-2.580010e-001,-5.726297e-002,2.095547e-002,-3.751047e-006,-3.751047e-006,,,,,,,,,,,,,,,,,,,,
1405554770.812,,1.500000e+001,2.979968e+002,2.979885e+002,1,0,3.301749e+000,-2.043214e-001,-2.043214e-001,9.293351e-003,6.586701e-002,-2.950706e-001,-8.145589e-002,-2.488223e-002,-4.452706e-006,-4.452706e-006,,,,,,,,,,,,,,,,,,,,
1405554889.625,,2.000000e+001,2.980050e+002,2.980050e+002,1,0,2.236496e-001,-4.239021e-001,-4.239021e-001,-1.086770e-001,-8.471820e-002,-3.918617e-001,-7.663667e-002,-5.267784e-002,-9.237947e-006,-9.237947e-006,,,,,,,,,,,,,,,,,,,,
1405554907.921,,2.000000e+001,2.980050e+002,2.979968e+002,1,0,2.079561e+000,-1.214637e-001,-1.214637e-001,1.746917e-001,1.746917e-001,-1.687025e-001,1.274529e-001,1.274529e-001,-2.647014e-006,-2.647014e-006,,,,,,,,,,,,,,,,,,,,
1405554907.921,,2.000000e+001,2.980050e+002,2.979968e+002,1,0,3.810163e+000,-3.535569e-001,-3.535569e-001,-1.222987e-001,-5.740157e-002,-2.842352e-001,-5.297695e-002,1.192018e-002,-7.704940e-006,-7.704940e-006,,,,,,,,,,,,,,,,,,,,
1405554925.687,,2.000000e+001,2.979968e+002,2.979968e+002,1,0,6.832621e-001,-2.192755e-001,-2.192755e-001,4.647512e-002,8.037271e-002,-2.463596e-001,1.939101e-002,5.328859e-002,-4.778592e-006,-4.778592e-006,,,,,,,,,,,,,,,,,,,,
1405555044.234,,2.500000e+001,2.980050e+002,2.980050e+002,1,0,1.361181e+000,-1.268044e-001,-1.268044e-001,2.192715e-001,2.244390e-001,-1.536113e-001,1.924646e-001,1.976321e-001,-2.763402e-006,-2.763402e-006,,,,,,,,,,,,,,,,,,,,
1405555044.234,,2.500000e+001,2.980050e+002,2.980050e+002,1,0,3.994459e+000,-4.849391e-001,-4.849391e-001,-1.957056e-001,-1.336958e-001,-3.404334e-001,-5.119983e-002,1.081002e-002,-1.056810e-005,-1.056810e-005,,,,,,,,,,,,,,,,,,,,
1405555061.500,,2.500000e+001,2.979968e+002,2.979885e+002,1,0,1.249649e+000,-1.295511e-001,-1.295511e-001,1.777313e-001,2.143997e-001,-1.448678e-001,1.624146e-001,1.990829e-001,-2.823259e-006,-2.823259e-006,,,,,,,,,,,,,,,,,,,,
1405555079.750,,2.500000e+001,2.979968e+002,2.979968e+002,1,0,6.991392e-001,-2.542192e-001,-2.542192e-001,6.659703e-002,7.769117e-002,-3.244711e-001,-3.654909e-003,7.439226e-003,-5.540105e-006,-5.540105e-006,,,,,,,,,,,,,,,,,,,,
1405555079.750,,2.500000e+001,2.979968e+002,2.979968e+002,1,0,3.777245e+000,-4.078799e-001,-4.078799e-001,-1.480814e-001,-7.596955e-002,-3.312987e-001,-7.150022e-002,6.116629e-004,-8.888775e-006,-8.888775e-006,,,,,,,,,,,,,,,,,,,,
1405555197.250,,3.000000e+001,2.979968e+002,2.979968e+002,1,0,1.921556e+000,-1.399274e-001,-1.399274e-001,1.657704e-001,2.050166e-001,-5.565425e-002,2.500436e-001,2.892897e-001,-3.049384e-006,-3.049384e-006,,,,,,,,,,,,,,,,,,,,
1405555215.484,,3.000000e+001,2.980050e+002,2.979968e+002,1,0,1.907664e-001,-5.026398e-001,-5.026398e-001,-1.452308e-001,-1.289271e-001,-4.724579e-001,-1.150488e-001,-9.874508e-002,-1.095384e-005,-1.095384e-005,,,,,,,,,,,,,,,,,,,,
1405555215.484,,3.000000e+001,2.980050e+002,2.979968e+002,1,0,3.317622e+000,-3.279214e-001,-3.279214e-001,-3.029266e-002,4.579139e-002,-4.123320e-001,-1.147032e-001,-3.861919e-002,-7.146266e-006,-7.146266e-006,,,,,,,,,,,,,,,,,,,,
1405555233.218,,3.000000e+001,2.980050e+002,2.979968e+002,1,0,2.640147e+000,-1.493881e-001,-1.493881e-001,1.449213e-001,1.982992e-001,-2.655562e-001,2.875317e-002,8.213106e-002,-3.255558e-006,-3.255558e-006,,,,,,,,,,,,,,,,,,,,
1405555346.453,,3.500000e+001,2.980050e+002,2.979968e+002,1,0,6.568928e-003,-6.405836e-001,-6.405835e-001,-2.451947e-001,-2.249000e-001,-5.113814e-001,-1.159926e-001,-9.569791e-002,-1.395999e-005,-1.395999e-005,,,,,,,,,,,,,,,,,,,,
1405555346.453,,3.500000e+001,2.980050e+002,2.979968e+002,1,0,2.751243e+000,-2.186651e-001,-2.186651e-001,1.209134e-001,1.970184e-001,-3.140758e-001,2.550276e-002,1.016077e-001,-4.765284e-006,-4.765284e-006,,,,,,,,,,,,,,,,,,,,
1405555364.515,,3.500000e+001,2.980050e+002,2.979968e+002,1,0,3.301831e+000,-3.210547e-001,-3.210547e-001,1.383134e-002,7.055792e-002,-4.525907e-001,-1.177047e-001,-6.097808e-002,-6.996620e-006,-6.996620e-006,,,,,,,,,,,,,,,,,,,,
1405555382.000,,3.500000e+001,2.979968e+002,2.979968e+002,1,0,2.237426e-001,-5.049288e-001,-5.049288e-001,-1.740542e-001,-1.441725e-001,-4.588138e-001,-1.279393e-001,-9.805757e-002,-1.100372e-005,-1.100372e-005,,,,,,,,,,,,,,,,,,,,
1405555499.750,,4.000000e+001,2.980050e+002,2.979968e+002,1,0,2.079479e+000,-1.451155e-001,-1.451155e-001,2.705343e-001,2.705343e-001,-1.133429e-001,3.023070e-001,3.023070e-001,-3.162445e-006,-3.162445e-006,,,,,,,,,,,,,,,,,,,,
1405555499.750,,4.000000e+001,2.980050e+002,2.979968e+002,1,0,3.810203e+000,-5.536058e-001,-5.536057e-001,-1.945222e-001,-1.379559e-001,-4.801878e-001,-1.211043e-001,-6.453791e-002,-1.206451e-005,-1.206451e-005,,,,,,,,,,,,,,,,,,,,
1405555517.484,,4.000000e+001,2.979968e+002,2.980050e+002,1,0,6.832849e-001,-3.575243e-001,-3.575243e-001,-3.492159e-003,2.904192e-002,-4.358956e-001,-8.186342e-002,-4.932934e-002,-7.791386e-006,-7.791386e-006,,,,,,,,,,,,,,,,,,,,
1405555535.218,,4.000000e+001,2.979968e+002,2.980050e+002,1,0,1.360755e+000,-1.373333e-001,-1.373333e-001,2.351517e-001,2.410215e-001,-2.002983e-001,1.721867e-001,1.780564e-001,-2.992850e-006,-2.992850e-006,,,,,,,,,,,,,,,,,,,,
1405555535.218,,4.000000e+001,2.979968e+002,2.980050e+002,1,0,3.994345e+000,-5.697806e-001,-5.697806e-001,-2.618626e-001,-1.914258e-001,-4.052645e-001,-9.734656e-002,-2.690977e-002,-1.241700e-005,-1.241700e-005,,,,,,,,,,,,,,,,,,,,
1405555645.953,,4.500000e+001,2.979968e+002,2.979968e+002,1,0,1.249792e+000,-1.887570e-001,-1.887570e-001,1.817904e-001,2.177485e-001,-2.643026e-001,1.062448e-001,1.422029e-001,-4.113504e-006,-4.113504e-006,,,,,,,,,,,,,,,,,,,,
1405555663.187,,4.500000e+001,2.979968e+002,2.980050e+002,1,0,6.991378e-001,-3.903317e-001,-3.903317e-001,1.245640e-002,2.353671e-002,-5.087718e-001,-1.059837e-001,-9.490338e-002,-8.506339e-006,-8.506339e-006,,,,,,,,,,,,,,,,,,,,
1405555663.187,,4.500000e+001,2.979968e+002,2.980050e+002,1,0,3.777241e+000,-5.574206e-001,-5.574206e-001,-2.155741e-001,-1.435521e-001,-4.882206e-001,-1.463742e-001,-7.435215e-002,-1.214764e-005,-1.214764e-005,,,,,,,,,,,,,,,,,,,,
1405555681.171,,4.500000e+001,2.979968e+002,2.979968e+002,1,0,1.921613e+000,-8.392590e-002,-8.392590e-002,2.368993e-001,2.817653e-001,3.439673e-002,3.552219e-001,4.000880e-001,-1.828963e-006,-1.828963e-006,,,,,,,,,,,,,,,,,,,,
1405555800.671,,5.000000e+001,2.980050e+002,2.979885e+002,1,0,1.908660e-001,-7.222205e-001,-7.222205e-001,-2.209695e-001,-2.008476e-001,-6.585135e-001,-1.572625e-001,-1.371406e-001,-1.573905e-005,-1.573905e-005,,,,,,,,,,,,,,,,,,,,
1405555800.671,,5.000000e+001,2.980050e+002,2.979885e+002,1,0,3.317722e+000,-4.515213e-001,-4.515213e-001,-2.405026e-002,6.985158e-002,-5.579737e-001,-1.305027e-001,-3.660083e-002,-9.839815e-006,-9.839815e-006,,,,,,,,,,,,,,,,,,,,
1405555818.406,,5.000000e+001,2.979885e+002,2.979968e+002,1,0,2.640165e+000,-1.492355e-001,-1.492355e-001,2.512458e-001,3.186367e-001,-2.586063e-001,1.418750e-001,2.092659e-001,-3.252227e-006,-3.252227e-006,,,,,,,,,,,,,,,,,,,,
1405555837.140,,5.000000e+001,2.979968e+002,2.979968e+002,1,0,6.560646e-003,-7.214576e-001,-7.214575e-001,-3.031815e-001,-2.723691e-001,-5.513785e-001,-1.331025e-001,-1.022901e-001,-1.572242e-005,-1.572242e-005,,,,,,,,,,,,,,,,,,,,
1405555837.140,,5.000000e+001,2.979968e+002,2.979968e+002,1,0,2.751300e+000,-1.509140e-001,-1.509140e-001,1.826280e-001,2.981744e-001,-2.446905e-001,8.885152e-002,2.043979e-001,-3.288806e-006,-3.288806e-006,,,,,,,,,,,,,,,,,,,,
1405555960.375,,7.500000e+001,2.979968e+002,2.979968e+002,1,0,3.301785e+000,-4.628132e-001,-4.628132e-001,4.003487e-002,1.238973e-001,-6.393158e-001,-1.364677e-001,-5.260533e-002,-1.008587e-005,-1.008587e-005,,,,,,,,,,,,,,,,,,,,
1405555979.171,,7.500000e+001,2.979968e+002,2.980050e+002,1,0,2.236580e-001,-8.612323e-001,-8.612323e-001,-3.224969e-001,-2.804924e-001,-7.506110e-001,-2.118756e-001,-1.698710e-001,-1.876843e-005,-1.876843e-005,,,,,,,,,,,,,,,,,,,,
1405555996.468,,7.500000e+001,2.979968e+002,2.979968e+002,1,0,2.079270e+000,-7.080294e-002,-7.080294e-002,4.684831e-001,4.684831e-001,-1.206200e-003,5.380798e-001,5.380798e-001,-1.542975e-006,-1.542975e-006,,,,,,,,,,,,,,,,,,,,
1405555996.468,,7.500000e+001,2.979968e+002,2.979968e+002,1,0,3.810132e+000,-7.303079e-001,-7.303079e-001,-2.933910e-001,-1.910219e-001,-6.669449e-001,-2.300280e-001,-1.276588e-001,-1.591526e-005,-1.591526e-005,,,,,,,,,,,,,,,,,,,,
1405556128.890,,1.000000e+002,2.980050e+002,2.979968e+002,1,0,6.833293e-001,-7.748650e-001,-7.748650e-001,-1.382098e-001,-7.409567e-002,-9.027956e-001,-2.661404e-001,-2.020263e-001,-1.688623e-005,-1.688623e-005,,,,,,,,,,,,,,,,,,,,
1405556146.968,,1.000000e+002,2.979968e+002,2.979968e+002,1,0,1.360866e+000,-3.053377e-001,-3.053377e-001,3.757553e-001,3.867381e-001,-4.687927e-001,2.123004e-001,2.232831e-001,-6.654066e-006,-6.654066e-006,,,,,,,,,,,,,,,,,,,,
1405556146.968,,1.000000e+002,2.979968e+002,2.979968e+002,1,0,3.994424e+000,-1.054415e+000,-1.054415e+000,-4.941316e-001,-3.623387e-001,-8.241869e-001,-2.639040e-001,-1.321111e-001,-2.297831e-005,-2.297831e-005,,,,,,,,,,,,,,,,,,,,
1405556165.203,,1.000000e+002,2.979968e+002,2.979968e+002,1,0,1.249775e+000,-3.770562e-001,-3.770562e-001,2.508233e-001,3.244050e-001,-5.133054e-001,1.145741e-001,1.881558e-001,-8.216990e-006,-8.216990e-006,,,,,,,,,,,,,,,,,,,,
1405556165.203,,1.000000e+002,2.979968e+002,2.979968e+002,1,0,2.256085e+000,-9.933775e-002,-9.933775e-002,4.365646e-001,6.021234e-001,1.282413e-001,6.641436e-001,8.297025e-001,-2.164816e-006,-2.164816e-006,,,,,,,,,,,,,,,,,,,,