File: Sample Data Files/2014-07-16 EB on isolated PMN-PT no Ti spontaneous in situ/Ni-NiO_298K_SiO2_PMN-PT_5.0Tprebias_000V_Au_back_poled.rso.raw
[Header]
TITLE,MPMS RSO Measurement
BYAPP,MPMS Measurement,2.1,Raw with ABS
FILEOPENTIME, 1405557353.062000 7/16/2014, 5:35:53 PM

INFO, APPNAME, MPMS MultiVu Application, Revision 1.58,  Build 076

INFO, NAME, EB in situ
INFO, WEIGHT, 0.000
INFO, AREA, 0.000
INFO, LENGTH, 0.000
INFO, SHAPE, 0
INFO, COMMENT,
INFO, SEQUENCE FILE: MHcurveUpTo100.seq


INFO, BACKGROUND DATA FILE:, None


STARTUPAXIS,X,8,LINEAR,AUTO,0.000000,0.000000
STARTUPAXIS,Y1,9,LINEAR,AUTO,0.000000,0.000000


STARTUPGROUP,Longitudinal
FIELDGROUP,Longitudinal,1,2,3,4,5,6,7,8,9,10,11,12,13,14,15,16,17,18,19,20,21,22
FIELDGROUP,Transverse,1,2,3,4,5,6,7,8,23,24,25,26,27,28,29,30,31,32,33,34,35,36

PLOT_APPEARANCE,ALL,HORZ_GRID_ON,VERT_GRID_ON,MARKERS_ONLY

[Data]
Time,Comment,Field (Oe),Start Temperature (K),End Temperature (K),Scan,Rejected,Position (cm),Long Voltage,Long Average Voltage,Long Detrended Voltage,Long Demeaned Voltage,Long Reg Fit,Long Detrended Fit,Long Demeaned Fit,Long Scaled Response,Long Avg. Scaled Response,Long Background Response,Long Response [w/ABS],Long Detrended Resp. [w/ABS],Long Fit [w/ABS],Long Detrended Fit [w/ABS],Trans Voltage,Trans Average Voltage,Trans Detrended Voltage,Trans Demeaned Voltage,Trans Reg Fit,Trans Detrended Fit,Trans Demeaned Fit,Trans Scaled Response,Trans Avg. Scaled Response,Trans Background Response,Trans Response [w/ABS],Trans Detrended Resp. [w/ABS],Trans Adjusted Fit,Trans Detrended Fit [w/ABS],
1405557353.062,,1.000000e+002,2.979968e+002,2.979968e+002,1,0,2.079543e+000,-3.326517e-002,-3.326518e-002,1.397530e+000,1.397530e+000,1.862664e-002,1.449422e+000,1.449422e+000,-1.449861e-006,-1.449861e-006,,,,,,,,,,,,,,,,,,,,
1405557353.062,,1.000000e+002,2.979968e+002,2.979968e+002,1,0,3.705858e+000,-1.996979e+000,-1.996979e+000,-6.442966e-001,-5.661830e-001,-1.987097e+000,-6.344147e-001,-5.563011e-001,-8.703824e-005,-8.703824e-005,,,,,,,,,,,,,,,,,,,,
1405557370.812,,1.000000e+002,2.980050e+002,2.979968e+002,1,0,4.360172e-001,-2.015595e+000,-2.015595e+000,-6.212837e-001,-5.825945e-001,-2.030068e+000,-6.357569e-001,-5.970677e-001,-8.784963e-005,-8.784963e-005,,,,,,,,,,,,,,,,,,,,
1405557389.078,,1.000000e+002,2.980050e+002,2.979968e+002,1,0,1.899583e+000,-7.889035e-002,-7.889035e-002,1.363598e+000,1.365370e+000,-9.892581e-003,1.432596e+000,1.434368e+000,-3.438433e-006,-3.438433e-006,,,,,,,,,,,,,,,,,,,,
1405557389.078,,1.000000e+002,2.980050e+002,2.979968e+002,1,0,3.810050e+000,-2.022462e+000,-2.022462e+000,-6.561530e-001,-5.782015e-001,-1.967571e+000,-6.012629e-001,-5.233114e-001,-8.814892e-005,-8.814892e-005,,,,,,,,,,,,,,,,,,,,
1405557514.093,,7.500000e+001,2.980050e+002,2.979885e+002,1,0,5.564428e-001,-1.971343e+000,-1.971343e+000,-5.403785e-001,-5.052936e-001,-2.015762e+000,-5.847971e-001,-5.497123e-001,-8.592111e-005,-8.592111e-005,,,,,,,,,,,,,,,,,,,,
1405557532.093,,7.500000e+001,2.979968e+002,2.979968e+002,1,0,1.718627e+000,-2.545244e-001,-2.545244e-001,1.196804e+000,1.199890e+000,-2.240717e-001,1.227257e+000,1.230343e+000,-1.109346e-005,-1.109346e-005,,,,,,,,,,,,,,,,,,,,
1405557532.093,,7.500000e+001,2.979968e+002,2.979968e+002,1,0,3.893568e+000,-2.026582e+000,-2.026582e+000,-6.415943e-001,-5.721670e-001,-1.942318e+000,-5.573312e-001,-4.879040e-001,-8.832868e-005,-8.832868e-005,,,,,,,,,,,,,,,,,,,,
1405557549.828,,7.500000e+001,2.979968e+002,2.980050e+002,1,0,6.833405e-001,-1.834010e+000,-1.834010e+000,-4.182273e-001,-3.800755e-001,-1.899293e+000,-4.835104e-001,-4.453585e-001,-7.993543e-005,-7.993543e-005,,,,,,,,,,,,,,,,,,,,
1405557681.062,,5.000000e+001,2.979968e+002,2.980050e+002,1,0,1.538824e+000,-5.316324e-001,-5.316324e-001,9.340253e-001,9.381608e-001,-5.535183e-001,9.121395e-001,9.162749e-001,-2.317129e-005,-2.317129e-005,,,,,,,,,,,,,,,,,,,,
1405557681.062,,5.000000e+001,2.979968e+002,2.980050e+002,1,0,3.953565e+000,-2.024903e+000,-2.024903e+000,-6.185201e-001,-5.551099e-001,-1.924175e+000,-5.177923e-001,-4.543821e-001,-8.825573e-005,-8.825573e-005,,,,,,,,,,,,,,,,,,,,
1405557698.328,,5.000000e+001,2.980050e+002,2.979968e+002,1,0,8.160122e-001,-1.660207e+000,-1.660207e+000,-2.560355e-001,-2.206959e-001,-1.729843e+000,-3.256717e-001,-2.903321e-001,-7.236039e-005,-7.236039e-005,,,,,,,,,,,,,,,,,,,,
1405557715.812,,5.000000e+001,2.980050e+002,2.979968e+002,1,0,1.360840e+000,-8.081301e-001,-8.081301e-001,6.433012e-001,6.489972e-001,-8.725996e-001,5.788318e-001,5.845277e-001,-3.522248e-005,-3.522248e-005,,,,,,,,,,,,,,,,,,,,
1405557715.812,,5.000000e+001,2.980050e+002,2.979968e+002,1,0,3.987436e+000,-2.002625e+000,-2.002625e+000,-6.124248e-001,-5.454972e-001,-1.888348e+000,-4.981479e-001,-4.312203e-001,-8.728472e-005,-8.728472e-005,,,,,,,,,,,,,,,,,,,,
1405557831.359,,4.500000e+001,2.980050e+002,2.980050e+002,1,0,9.541737e-001,-1.487930e+000,-1.487930e+000,-5.487779e-002,-1.908243e-002,-1.561082e+000,-1.280302e-001,-9.223485e-002,-6.485169e-005,-6.485169e-005,,,,,,,,,,,,,,,,,,,,
1405557849.093,,4.500000e+001,2.979968e+002,2.979968e+002,1,0,1.187049e+000,-1.090579e+000,-1.090579e+000,3.445583e-001,3.515292e-001,-1.176174e+000,2.589631e-001,2.659341e-001,-4.753308e-005,-4.753308e-005,,,,,,,,,,,,,,,,,,,,
1405557849.093,,4.500000e+001,2.979968e+002,2.979968e+002,1,0,3.994450e+000,-1.983245e+000,-1.983245e+000,-6.080587e-001,-5.411372e-001,-1.867556e+000,-4.923698e-001,-4.254483e-001,-8.644011e-005,-8.644011e-005,,,,,,,,,,,,,,,,,,,,
1405557867.578,,4.500000e+001,2.980050e+002,2.980050e+002,1,0,1.098636e+000,-1.220893e+000,-1.220893e+000,1.881668e-001,2.266791e-001,-1.303076e+000,1.059836e-001,1.444958e-001,-5.321284e-005,-5.321284e-005,,,,,,,,,,,,,,,,,,,,
1405557984.578,,4.000000e+001,2.980050e+002,2.980050e+002,1,0,1.017810e+000,-1.399121e+000,-1.399121e+000,6.560133e-002,7.349670e-002,-1.492735e+000,-2.801229e-002,-2.011693e-002,-6.098097e-005,-6.098097e-005,,,,,,,,,,,,,,,,,,,,
1405557984.578,,4.000000e+001,2.980050e+002,2.980050e+002,1,0,3.974667e+000,-2.018189e+000,-2.018189e+000,-6.100500e-001,-5.455712e-001,-1.910384e+000,-5.022454e-001,-4.377666e-001,-8.796318e-005,-8.796318e-005,,,,,,,,,,,,,,,,,,,,
1405558001.312,,4.000000e+001,2.979968e+002,2.979968e+002,1,0,1.249751e+000,-9.645375e-001,-9.645375e-001,4.450597e-001,4.833665e-001,-1.039218e+000,3.703787e-001,4.086856e-001,-4.203956e-005,-4.203956e-005,,,,,,,,,,,,,,,,,,,,
1405558018.578,,4.000000e+001,2.979968e+002,2.979968e+002,1,0,8.550956e-001,-1.586962e+000,-1.586962e+000,-1.718430e-001,-1.619250e-001,-1.686307e+000,-2.711872e-001,-2.612692e-001,-6.916808e-005,-6.916808e-005,,,,,,,,,,,,,,,,,,,,
1405558018.578,,4.000000e+001,2.979968e+002,2.979968e+002,1,0,3.929981e+000,-1.976379e+000,-1.976379e+000,-6.221844e-001,-5.513412e-001,-1.881626e+000,-5.274320e-001,-4.565887e-001,-8.614086e-005,-8.614086e-005,,,,,,,,,,,,,,,,,,,,
1405558135.875,,3.500000e+001,2.980050e+002,2.980050e+002,1,0,1.407927e+000,-7.052827e-001,-7.052827e-001,7.127624e-001,7.500156e-001,-7.582433e-001,6.598018e-001,6.970550e-001,-3.073991e-005,-3.073991e-005,,,,,,,,,,,,,,,,,,,,
1405558154.109,,3.500000e+001,2.980050e+002,2.979968e+002,1,0,6.991772e-001,-1.799371e+000,-1.799371e+000,-3.782709e-001,-3.675551e-001,-1.878294e+000,-4.571939e-001,-4.464781e-001,-7.842600e-005,-7.842600e-005,,,,,,,,,,,,,,,,,,,,
1405558154.109,,3.500000e+001,2.980050e+002,2.979968e+002,1,0,3.862962e+000,-1.996368e+000,-1.996368e+000,-6.328648e-001,-5.645521e-001,-1.923709e+000,-5.602059e-001,-4.918932e-001,-8.701216e-005,-8.701216e-005,,,,,,,,,,,,,,,,,,,,
1405558172.406,,3.500000e+001,2.980050e+002,2.979968e+002,1,0,1.573316e+000,-4.062014e-001,-4.062014e-001,9.754682e-001,1.016297e+000,-4.188332e-001,9.628364e-001,1.003665e+000,-1.770438e-005,-1.770438e-005,,,,,,,,,,,,,,,,,,,,
1405558291.390,,3.000000e+001,2.980050e+002,2.979968e+002,1,0,5.523639e-001,-1.955016e+000,-1.955016e+000,-5.114311e-001,-5.001800e-001,-2.015060e+000,-5.714754e-001,-5.602243e-001,-8.520983e-005,-8.520983e-005,,,,,,,,,,,,,,,,,,,,
1405558291.390,,3.000000e+001,2.980050e+002,2.979968e+002,1,0,3.777301e+000,-2.029634e+000,-2.029634e+000,-6.398041e-001,-5.747979e-001,-1.983682e+000,-5.938521e-001,-5.288459e-001,-8.846207e-005,-8.846207e-005,,,,,,,,,,,,,,,,,,,,
1405558308.875,,3.000000e+001,2.979968e+002,2.979968e+002,1,0,1.744943e+000,-2.090518e-001,-2.090518e-001,1.182122e+000,1.222977e+000,-1.613903e-001,1.229784e+000,1.270638e+000,-9.111573e-006,-9.111573e-006,,,,,,,,,,,,,,,,,,,,
1405558326.640,,3.000000e+001,2.979968e+002,2.979968e+002,1,0,4.166965e-001,-2.003082e+000,-2.003082e+000,-5.836231e-001,-5.704339e-001,-2.037284e+000,-6.178249e-001,-6.046357e-001,-8.730483e-005,-8.730483e-005,,,,,,,,,,,,,,,,,,,,
1405558326.640,,3.000000e+001,2.979968e+002,2.979968e+002,1,0,3.676769e+000,-1.995453e+000,-1.995453e+000,-6.327071e-001,-5.628043e-001,-1.980601e+000,-6.178551e-001,-5.479524e-001,-8.697229e-005,-8.697229e-005,,,,,,,,,,,,,,,,,,,,
1405558445.390,,2.500000e+001,2.979968e+002,2.979968e+002,1,0,1.921533e+000,-9.445479e-002,-9.445479e-002,1.298803e+000,1.339968e+000,-4.760556e-003,1.388497e+000,1.429662e+000,-4.116837e-006,-4.116837e-006,,,,,,,,,,,,,,,,,,,,
1405558463.125,,2.500000e+001,2.979968e+002,2.980050e+002,1,0,2.951452e-001,-2.020631e+000,-2.020631e+000,-6.106693e-001,-5.963607e-001,-2.017680e+000,-6.077186e-001,-5.934100e-001,-8.806971e-005,-8.806971e-005,,,,,,,,,,,,,,,,,,,,
1405558463.125,,2.500000e+001,2.979968e+002,2.980050e+002,1,0,3.564911e+000,-1.953490e+000,-1.953490e+000,-5.994623e-001,-5.292199e-001,-1.963255e+000,-6.092271e-001,-5.389847e-001,-8.514337e-005,-8.514337e-005,,,,,,,,,,,,,,,,,,,,
1405558480.859,,2.500000e+001,2.979968e+002,2.980050e+002,1,0,2.101352e+000,-8.774072e-002,-8.774071e-002,1.288536e+000,1.333242e+000,4.986235e-003,1.381263e+000,1.425969e+000,-3.824202e-006,-3.824202e-006,,,,,,,,,,,,,,,,,,,,
1405558592.343,,2.000000e+001,2.979968e+002,2.980050e+002,1,0,1.908495e-001,-2.014679e+000,-2.014679e+000,-6.043245e-001,-5.891737e-001,-1.980983e+000,-5.706277e-001,-5.554769e-001,-8.781037e-005,-8.781037e-005,,,,,,,,,,,,,,,,,,,,
1405558592.343,,2.000000e+001,2.979968e+002,2.980050e+002,1,0,3.444457e+000,-1.881771e+000,-1.881771e+000,-5.257066e-001,-4.562656e-001,-1.913003e+000,-5.569382e-001,-4.874971e-001,-8.201753e-005,-8.201753e-005,,,,,,,,,,,,,,,,,,,,
1405558610.578,,2.000000e+001,2.979968e+002,2.979968e+002,1,0,2.282197e+000,-2.325510e-001,-2.325510e-001,1.145676e+000,1.190464e+000,-1.871126e-001,1.191115e+000,1.235902e+000,-1.013580e-005,-1.013580e-005,,,,,,,,,,,,,,,,,,,,
1405558628.078,,2.000000e+001,2.980050e+002,2.979968e+002,1,0,1.073675e-001,-1.991485e+000,-1.991485e+000,-5.910064e-001,-5.738109e-001,-1.931507e+000,-5.310277e-001,-5.138322e-001,-8.679945e-005,-8.679945e-005,,,,,,,,,,,,,,,,,,,,
1405558628.078,,2.000000e+001,2.980050e+002,2.979968e+002,1,0,3.317613e+000,-1.753288e+000,-1.753288e+000,-4.096868e-001,-3.356140e-001,-1.799950e+000,-4.563484e-001,-3.822756e-001,-7.641757e-005,-7.641757e-005,,,,,,,,,,,,,,,,,,,,
1405558747.828,,1.500000e+001,2.979968e+002,2.979968e+002,1,0,2.462358e+000,-4.774621e-001,-4.774621e-001,9.093391e-001,9.510279e-001,-4.918708e-001,8.949304e-001,9.366191e-001,-2.081033e-005,-2.081033e-005,,,,,,,,,,,,,,,,,,,,
1405558765.562,,1.500000e+001,2.979968e+002,2.979968e+002,1,0,4.754835e-002,-1.969054e+000,-1.969054e+000,-5.688261e-001,-5.512911e-001,-1.894851e+000,-4.946232e-001,-4.770882e-001,-8.582183e-005,-8.582183e-005,,,,,,,,,,,,,,,,,,,,
1405558765.562,,1.500000e+001,2.979968e+002,2.979968e+002,1,0,3.185007e+000,-1.591998e+000,-1.591998e+000,-2.456275e-001,-1.742350e-001,-1.649287e+000,-3.029169e-001,-2.315243e-001,-6.938772e-005,-6.938772e-005,,,,,,,,,,,,,,,,,,,,
1405558783.796,,1.500000e+001,2.979968e+002,2.980050e+002,1,0,2.640179e+000,-7.379375e-001,-7.379376e-001,6.352661e-001,6.813673e-001,-7.994226e-001,5.737811e-001,6.198823e-001,-3.216323e-005,-3.216323e-005,,,,,,,,,,,,,,,,,,,,
1405558903.031,,1.000000e+001,2.979968e+002,2.979968e+002,1,0,1.356185e-002,-1.933042e+000,-1.933042e+000,-5.539356e-001,-5.360442e-001,-1.850145e+000,-4.710377e-001,-4.531463e-001,-8.425228e-005,-8.425228e-005,,,,,,,,,,,,,,,,,,,,
1405558903.031,,1.000000e+001,2.979968e+002,2.979968e+002,1,0,3.046781e+000,-1.373943e+000,-1.373943e+000,-4.612499e-002,2.305484e-002,-1.437748e+000,-1.099294e-001,-4.074955e-002,-5.988377e-005,-5.988377e-005,,,,,,,,,,,,,,,,,,,,
1405558921.281,,1.000000e+001,2.980050e+002,2.979968e+002,1,0,2.813874e+000,-1.004669e+000,-1.004669e+000,3.439242e-001,3.883142e-001,-1.085646e+000,2.629476e-001,3.073376e-001,-4.378884e-005,-4.378884e-005,,,,,,,,,,,,,,,,,,,,
1405558939.031,,1.000000e+001,2.980050e+002,2.979885e+002,1,0,6.539955e-003,-1.924345e+000,-1.924345e+000,-5.549747e-001,-5.349420e-001,-1.836270e+000,-4.668999e-001,-4.468672e-001,-8.387319e-005,-8.387319e-005,,,,,,,,,,,,,,,,,,,,
1405558939.031,,1.000000e+001,2.980050e+002,2.979885e+002,1,0,2.902372e+000,-1.128117e+000,-1.128117e+000,1.874154e-001,2.612859e-001,-1.200071e+000,1.154613e-001,1.893318e-001,-4.916933e-005,-4.916933e-005,,,,,,,,,,,,,,,,,,,,
1405559057.296,,5.000000e+000,2.980050e+002,2.979968e+002,1,0,2.983042e+000,-1.272012e+000,-1.272012e+000,6.580023e-002,1.092410e-001,-1.351440e+000,-1.362868e-002,2.981210e-002,-5.544106e-005,-5.544106e-005,,,,,,,,,,,,,,,,,,,,
1405559076.031,,5.000000e+000,2.979968e+002,2.979968e+002,1,0,2.634635e-002,-1.906797e+000,-1.906796e+000,-5.512556e-001,-5.316198e-001,-1.827499e+000,-4.719583e-001,-4.523225e-001,-8.310838e-005,-8.310838e-005,,,,,,,,,,,,,,,,,,,,
1405559076.031,,5.000000e+000,2.979968e+002,2.979968e+002,1,0,2.751305e+000,-8.726768e-001,-8.726768e-001,4.331968e-001,5.024999e-001,-9.409537e-001,3.649200e-001,4.342230e-001,-3.803592e-005,-3.803592e-005,,,,,,,,,,,,,,,,,,,,
1405559094.265,,5.000000e+000,2.979968e+002,2.980050e+002,1,0,3.145914e+000,-1.498154e+000,-1.498154e+000,-1.749415e-001,-1.294203e-001,-1.569864e+000,-2.466516e-001,-2.011304e-001,-6.529754e-005,-6.529754e-005,,,,,,,,,,,,,,,,,,,,
1405559213.000,,0.000000e+000,2.979968e+002,2.979968e+002,1,0,7.105745e-002,-1.873684e+000,-1.873684e+000,-5.494800e-001,-5.304185e-001,-1.807219e+000,-4.830153e-001,-4.639539e-001,-8.166519e-005,-8.166519e-005,,,,,,,,,,,,,,,,,,,,
1405559213.000,,0.000000e+000,2.979968e+002,2.979968e+002,1,0,2.592990e+000,-6.096072e-001,-6.096072e-001,6.690609e-001,7.336582e-001,-6.525391e-001,6.261290e-001,6.907263e-001,-2.656995e-005,-2.656995e-005,,,,,,,,,,,,,,,,,,,,
1405559230.765,,0.000000e+000,2.979968e+002,2.979968e+002,1,0,3.301764e+000,-1.652577e+000,-1.652577e+000,-3.597748e-001,-3.155993e-001,-1.708339e+000,-4.155369e-001,-3.713615e-001,-7.202818e-005,-7.202818e-005,,,,,,,,,,,,,,,,,,,,
1405559249.000,,0.000000e+000,2.979968e+002,2.979885e+002,1,0,1.381021e-001,-1.879330e+000,-1.879330e+000,-5.672566e-001,-5.444999e-001,-1.826654e+000,-5.145811e-001,-4.918244e-001,-8.191127e-005,-8.191127e-005,,,,,,,,,,,,,,,,,,,,
1405559249.000,,0.000000e+000,2.979968e+002,2.979885e+002,1,0,2.427747e+000,-3.569140e-001,-3.569140e-001,9.036573e-001,9.779160e-001,-3.565341e-001,9.040372e-001,9.782959e-001,-1.555622e-005,-1.555622e-005,,,,,,,,,,,,,,,,,,,,
1405559366.796,,-5.000000e+000,2.980050e+002,2.979885e+002,1,0,3.448655e+000,-1.543321e+000,-1.543321e+000,-4.070512e-001,-3.756907e-001,-1.581857e+000,-4.455875e-001,-4.142270e-001,-6.726618e-005,-6.726618e-005,,,,,,,,,,,,,,,,,,,,
1405559384.546,,-5.000000e+000,2.979968e+002,2.980050e+002,1,0,2.236865e-001,-1.599628e+000,-1.599628e+000,-4.862866e-001,-4.701982e-001,-1.568445e+000,-4.551036e-001,-4.390152e-001,-6.972032e-005,-6.972032e-005,,,,,,,,,,,,,,,,,,,,
1405559384.546,,-5.000000e+000,2.979968e+002,2.980050e+002,1,0,2.256042e+000,-1.603748e-001,-1.603748e-001,9.183763e-001,9.690548e-001,-1.019903e-001,9.767607e-001,1.027439e+000,-6.989989e-006,-6.989989e-006,,,,,,,,,,,,,,,,,,,,
1405559402.781,,-5.000000e+000,2.979968e+002,2.979968e+002,1,0,3.584253e+000,-1.518754e+000,-1.518754e+000,-4.496071e-001,-4.146941e-001,-1.535105e+000,-4.659587e-001,-4.310457e-001,-6.619540e-005,-6.619540e-005,,,,,,,,,,,,,,,,,,,,
1405559543.281,,-1.000000e+001,2.979968e+002,2.979968e+002,1,0,3.241859e-001,5.333109e-001,5.333109e-001,1.859492e-001,2.126329e-001,5.432288e-001,1.958671e-001,2.225507e-001,1.162227e-005,1.162227e-005,,,,,,,,,,,,,,,,,,,,
1405559561.515,,-1.000000e+001,2.979968e+002,2.979968e+002,1,0,2.079365e+000,-1.286355e-001,-1.286355e-001,-6.094397e-001,-6.094397e-001,-7.850795e-002,-5.593122e-001,-5.593122e-001,-2.803310e-006,-2.803310e-006,,,,,,,,,,,,,,,,,,,,
1405559561.515,,-1.000000e+001,2.979968e+002,2.979968e+002,1,0,3.705826e+000,7.631153e-001,7.631153e-001,2.312656e-001,2.823111e-001,7.786068e-001,2.467570e-001,2.978025e-001,1.663031e-005,1.663031e-005,,,,,,,,,,,,,,,,,,,,
1405559579.828,,-1.000000e+001,2.979968e+002,2.979968e+002,1,0,4.360739e-001,9.805597e-001,9.805597e-001,3.156940e-001,3.396267e-001,9.613286e-001,2.964628e-001,3.203956e-001,2.136901e-005,2.136901e-005,,,,,,,,,,,,,,,,,,,,
1405559698.609,,-1.500000e+001,2.979968e+002,2.979968e+002,1,0,1.899814e+000,-1.129185e-001,-1.129185e-001,-1.780699e+000,-1.780273e+000,-1.059181e-001,-1.773699e+000,-1.773272e+000,-2.460793e-006,-2.460793e-006,,,,,,,,,,,,,,,,,,,,
1405559698.609,,-1.500000e+001,2.979968e+002,2.979968e+002,1,0,3.810096e+000,2.360759e+000,2.360759e+000,6.746490e-001,6.934050e-001,2.394036e+000,7.079258e-001,7.266818e-001,5.144720e-005,5.144720e-005,,,,,,,,,,,,,,,,,,,,
1405559716.843,,-1.500000e+001,2.979968e+002,2.979968e+002,1,0,5.564493e-001,2.503891e+000,2.503891e+000,7.393923e-001,7.513486e-001,2.464696e+000,7.001970e-001,7.121533e-001,5.456643e-005,5.456643e-005,,,,,,,,,,,,,,,,,,,,
1405559735.078,,-1.500000e+001,2.979968e+002,2.979968e+002,1,0,1.718545e+000,1.855525e-001,1.855525e-001,-1.626213e+000,-1.625412e+000,1.724005e-001,-1.639365e+000,-1.638564e+000,4.043682e-006,4.043682e-006,,,,,,,,,,,,,,,,,,,,
1405559735.078,,-1.500000e+001,2.979968e+002,2.979968e+002,1,0,3.893565e+000,2.450942e+000,2.450942e+000,6.219538e-001,6.399773e-001,2.513738e+000,6.847499e-001,7.027735e-001,5.341251e-005,5.341251e-005,,,,,,,,,,,,,,,,,,,,
1405559853.359,,-2.000000e+001,2.979968e+002,2.980050e+002,1,0,6.833858e-001,2.658315e+000,2.658315e+000,7.088299e-001,7.082301e-001,2.596700e+000,6.472152e-001,6.466154e-001,5.793170e-005,5.793170e-005,,,,,,,,,,,,,,,,,,,,
1405559871.593,,-2.000000e+001,2.979968e+002,2.980050e+002,1,0,1.538705e+000,6.714072e-001,6.714072e-001,-1.331946e+000,-1.331412e+000,6.492711e-001,-1.354082e+000,-1.353548e+000,1.463174e-005,1.463174e-005,,,,,,,,,,,,,,,,,,,,
1405559871.593,,-2.000000e+001,2.979968e+002,2.980050e+002,1,0,3.953550e+000,2.668538e+000,2.668539e+000,6.575262e-001,6.657197e-001,2.732711e+000,7.216987e-001,7.298923e-001,5.815450e-005,5.815450e-005,,,,,,,,,,,,,,,,,,,,
1405559889.093,,-2.000000e+001,2.980050e+002,2.980050e+002,1,0,8.159946e-001,2.498245e+000,2.498245e+000,4.972408e-001,5.026158e-001,2.429749e+000,4.287443e-001,4.341193e-001,5.444336e-005,5.444336e-005,,,,,,,,,,,,,,,,,,,,
1405560007.093,,-2.500000e+001,2.979968e+002,2.979968e+002,1,0,1.360993e+000,1.252785e+000,1.252785e+000,-8.545943e-001,-8.548907e-001,1.215175e+000,-8.922039e-001,-8.925003e-001,2.730148e-005,2.730148e-005,,,,,,,,,,,,,,,,,,,,
1405560007.093,,-2.500000e+001,2.979968e+002,2.979968e+002,1,0,3.987484e+000,2.787408e+000,2.787408e+000,6.832150e-001,6.797326e-001,2.848467e+000,7.442738e-001,7.407913e-001,6.074495e-005,6.074495e-005,,,,,,,,,,,,,,,,,,,,
1405560025.328,,-2.500000e+001,2.979968e+002,2.979968e+002,1,0,9.542797e-001,2.392804e+000,2.392804e+000,2.442669e-001,2.447298e-001,2.328441e+000,1.799041e-001,1.803670e-001,5.214549e-005,5.214549e-005,,,,,,,,,,,,,,,,,,,,
1405560043.609,,-2.500000e+001,2.979968e+002,2.979968e+002,1,0,1.187137e+000,1.779992e+000,1.779992e+000,-3.510800e-001,-3.509271e-001,1.720214e+000,-4.108583e-001,-4.107054e-001,3.879071e-005,3.879071e-005,,,,,,,,,,,,,,,,,,,,
1405560043.609,,-2.500000e+001,2.979968e+002,2.979968e+002,1,0,3.994470e+000,2.816859e+000,2.816859e+000,6.844717e-001,6.859393e-001,2.879785e+000,7.473982e-001,7.488658e-001,6.138676e-005,6.138676e-005,,,,,,,,,,,,,,,,,,,,
1405560162.843,,-3.000000e+001,2.980050e+002,2.979968e+002,1,0,1.098742e+000,2.125462e+000,2.125462e+000,-1.121891e-001,-1.191366e-001,2.088169e+000,-1.494813e-001,-1.564288e-001,4.631938e-005,4.631938e-005,,,,,,,,,,,,,,,,,,,,
1405560179.609,,-3.000000e+001,2.979968e+002,2.979968e+002,1,0,1.018090e+000,2.384564e+000,2.384564e+000,1.289996e-001,1.277256e-001,2.322813e+000,6.724898e-002,6.597495e-002,5.196589e-005,5.196589e-005,,,,,,,,,,,,,,,,,,,,
1405560179.609,,-3.000000e+001,2.979968e+002,2.979968e+002,1,0,3.974701e+000,3.019196e+000,3.019196e+000,7.727625e-001,7.623580e-001,3.071708e+000,8.252746e-001,8.148701e-001,6.579620e-005,6.579620e-005,,,,,,,,,,,,,,,,,,,,
1405560197.343,,-3.000000e+001,2.979968e+002,2.979968e+002,1,0,1.249745e+000,1.712088e+000,1.712088e+000,-5.746980e-001,-5.811818e-001,1.709635e+000,-5.771514e-001,-5.836352e-001,3.731089e-005,3.731089e-005,,,,,,,,,,,,,,,,,,,,
1405560315.140,,-3.500000e+001,2.979968e+002,2.979968e+002,1,0,8.550593e-001,2.827693e+000,2.827693e+000,5.216956e-001,5.196004e-001,2.786663e+000,4.806659e-001,4.785707e-001,6.162280e-005,6.162280e-005,,,,,,,,,,,,,,,,,,,,
1405560315.140,,-3.500000e+001,2.979968e+002,2.979968e+002,1,0,3.929986e+000,3.139134e+000,3.139134e+000,8.460074e-001,8.310418e-001,3.178179e+000,8.850525e-001,8.700869e-001,6.840992e-005,6.840992e-005,,,,,,,,,,,,,,,,,,,,
1405560332.875,,-3.500000e+001,2.979968e+002,2.979968e+002,1,0,1.408042e+000,1.249428e+000,1.249428e+000,-1.087862e+000,-1.094279e+000,1.286351e+000,-1.050938e+000,-1.057355e+000,2.722829e-005,2.722829e-005,,,,,,,,,,,,,,,,,,,,
1405560351.140,,-3.500000e+001,2.979968e+002,2.980050e+002,1,0,6.991297e-001,3.171789e+000,3.171789e+000,8.222998e-001,8.207462e-001,3.132175e+000,7.826861e-001,7.811325e-001,6.912155e-005,6.912155e-005,,,,,,,,,,,,,,,,,,,,
1405560351.140,,-3.500000e+001,2.979968e+002,2.980050e+002,1,0,3.862903e+000,3.254189e+000,3.254189e+000,9.130508e-001,9.031463e-001,3.282689e+000,9.415506e-001,9.316461e-001,7.091727e-005,7.091727e-005,,,,,,,,,,,,,,,,,,,,
1405560468.875,,-4.000000e+001,2.979968e+002,2.980050e+002,1,0,1.573384e+000,7.292398e-001,7.292398e-001,-1.612542e+000,-1.621775e+000,7.808146e-001,-1.560967e+000,-1.570200e+000,1.589203e-005,1.589203e-005,,,,,,,,,,,,,,,,,,,,
1405560486.640,,-4.000000e+001,2.979968e+002,2.980050e+002,1,0,5.521102e-001,3.343303e+000,3.343303e+000,9.876195e-001,9.850028e-001,3.329306e+000,9.736224e-001,9.710057e-001,7.285926e-005,7.285926e-005,,,,,,,,,,,,,,,,,,,,
1405560486.640,,-4.000000e+001,2.979968e+002,2.980050e+002,1,0,3.777185e+000,3.342387e+000,3.342387e+000,9.992062e-001,9.840872e-001,3.348639e+000,1.005458e+000,9.903393e-001,7.283931e-005,7.283931e-005,,,,,,,,,,,,,,,,,,,,
1405560504.375,,-4.000000e+001,2.980050e+002,2.979968e+002,1,0,1.745054e+000,3.099155e-001,3.099155e-001,-2.062358e+000,-2.071349e+000,3.442118e-001,-2.028062e+000,-2.037053e+000,6.753864e-006,6.753864e-006,,,,,,,,,,,,,,,,,,,,
1405560616.875,,-4.500000e+001,2.979968e+002,2.979968e+002,1,0,4.165588e-001,3.465377e+000,3.465377e+000,1.044724e+000,1.043074e+000,3.464966e+000,1.044313e+000,1.042662e+000,7.551954e-005,7.551954e-005,,,,,,,,,,,,,,,,,,,,
1405560616.875,,-4.500000e+001,2.979968e+002,2.979968e+002,1,0,3.676654e+000,3.463851e+000,3.463851e+000,1.050296e+000,1.041548e+000,3.457814e+000,1.044259e+000,1.035511e+000,7.548628e-005,7.548628e-005,,,,,,,,,,,,,,,,,,,,
1405560634.625,,-4.500000e+001,2.979968e+002,2.980050e+002,1,0,1.921604e+000,6.881924e-002,6.881924e-002,-2.329756e+000,-2.331720e+000,5.828633e-002,-2.340289e+000,-2.342253e+000,1.499749e-006,1.499749e-006,,,,,,,,,,,,,,,,,,,,
1405560652.859,,-4.500000e+001,2.980050e+002,2.979968e+002,1,0,2.951580e-001,3.421430e+000,3.421430e+000,1.008754e+000,1.007362e+000,3.436686e+000,1.024010e+000,1.022619e+000,7.456182e-005,7.456182e-005,,,,,,,,,,,,,,,,,,,,
1405560652.859,,-4.500000e+001,2.980050e+002,2.979968e+002,1,0,3.564903e+000,3.450423e+000,3.450423e+000,1.043186e+000,1.036355e+000,3.433592e+000,1.026356e+000,1.019524e+000,7.519365e-005,7.519365e-005,,,,,,,,,,,,,,,,,,,,
1405560770.593,,-5.000000e+001,2.980050e+002,2.979885e+002,1,0,2.101277e+000,1.333659e-001,1.333659e-001,-2.329646e+000,-2.335814e+000,8.959238e-002,-2.373420e+000,-2.379587e+000,2.906387e-006,2.906387e-006,,,,,,,,,,,,,,,,,,,,
1405560788.578,,-5.000000e+001,2.979885e+002,2.979968e+002,1,0,1.909397e-001,3.418531e+000,3.418531e+000,9.407510e-001,9.397554e-001,3.442170e+000,9.643900e-001,9.633944e-001,7.449861e-005,7.449861e-005,,,,,,,,,,,,,,,,,,,,
1405560788.578,,-5.000000e+001,2.979885e+002,2.979968e+002,1,0,3.444561e+000,3.433790e+000,3.433790e+000,9.595779e-001,9.550147e-001,3.408359e+000,9.341465e-001,9.295833e-001,7.483114e-005,7.483114e-005,,,,,,,,,,,,,,,,,,,,
1405560806.593,,-5.000000e+001,2.979968e+002,2.980050e+002,1,0,2.282260e+000,3.894162e-001,3.894162e-001,-2.060019e+000,-2.065448e+000,3.570770e-001,-2.092359e+000,-2.097787e+000,8.486383e-006,8.486383e-006,,,,,,,,,,,,,,,,,,,,
1405560947.828,,-7.500000e+001,2.979968e+002,2.979968e+002,1,0,1.073612e-001,1.857662e+000,1.857662e+000,4.486789e-001,4.558383e-001,1.861856e+000,4.528727e-001,4.600321e-001,8.096630e-005,8.096630e-005,,,,,,,,,,,,,,,,,,,,
1405560947.828,,-7.500000e+001,2.979968e+002,2.979968e+002,1,0,3.317628e+000,1.818903e+000,1.818903e+000,3.862394e-001,4.170798e-001,1.810560e+000,3.778962e-001,4.087366e-001,7.927701e-005,7.927701e-005,,,,,,,,,,,,,,,,,,,,
1405560966.062,,-7.500000e+001,2.979968e+002,2.980050e+002,1,0,2.462245e+000,5.815302e-001,5.815302e-001,-8.137360e-001,-8.028290e-001,5.715196e-001,-8.237466e-001,-8.128396e-001,2.534603e-005,2.534603e-005,,,,,,,,,,,,,,,,,,,,
1405560983.296,,-7.500000e+001,2.979968e+002,2.979968e+002,1,0,4.747215e-002,1.795404e+000,1.795404e+000,4.177164e-001,4.233325e-001,1.801342e+000,4.236546e-001,4.292706e-001,7.825279e-005,7.825279e-005,,,,,,,,,,,,,,,,,,,,
1405560983.296,,-7.500000e+001,2.979968e+002,2.979968e+002,1,0,3.185009e+000,1.642811e+000,1.642811e+000,2.478744e-001,2.707399e-001,1.634727e+000,2.397905e-001,2.626560e-001,7.160204e-005,7.160204e-005,,,,,,,,,,,,,,,,,,,,
1405561115.296,,-1.000000e+002,2.980050e+002,2.980050e+002,1,0,2.639955e+000,3.517258e-001,3.517258e-001,-5.613759e-001,-6.333671e-001,3.613047e-001,-5.517970e-001,-6.237881e-001,1.532996e-005,1.532996e-005,,,,,,,,,,,,,,,,,,,,
1405561133.546,,-1.000000e+002,2.980050e+002,2.979968e+002,1,0,1.348637e-002,1.606189e+000,1.606189e+000,4.231966e-001,4.179653e-001,1.595426e+000,4.124337e-001,4.072024e-001,7.000569e-005,7.000569e-005,,,,,,,,,,,,,,,,,,,,
1405561133.546,,-1.000000e+002,2.980050e+002,2.979968e+002,1,0,3.046723e+000,1.221809e+000,1.221809e+000,5.381254e-002,3.358471e-002,1.235425e+000,6.742946e-002,4.720163e-002,5.325248e-005,5.325248e-005,,,,,,,,,,,,,,,,,,,,
1405561151.781,,-1.000000e+002,2.979968e+002,2.980132e+002,1,0,2.813875e+000,1.010468e+000,1.010468e+000,-2.961575e-001,-3.072371e-001,1.032196e+000,-2.744295e-001,-2.855091e-001,4.404120e-005,4.404120e-005,,,,,,,,,,,,,,,,,,,,
1405561277.562,,-7.500000e+001,2.980050e+002,2.979968e+002,1,0,6.592497e-003,1.583758e+000,1.583758e+000,4.039126e-001,3.932483e-001,1.586712e+000,4.068667e-001,3.962024e-001,6.902820e-005,6.902820e-005,,,,,,,,,,,,,,,,,,,,
1405561277.562,,-7.500000e+001,2.980050e+002,2.979968e+002,1,0,2.902372e+000,9.932249e-001,9.932249e-001,-1.579602e-001,-1.972848e-001,1.012763e+000,-1.384218e-001,-1.777464e-001,4.328977e-005,4.328977e-005,,,,,,,,,,,,,,,,,,,,
1405561296.046,,-7.500000e+001,2.979968e+002,2.980050e+002,1,0,2.982962e+000,1.159093e+000,1.159093e+000,-2.355111e-002,-4.191804e-002,1.160811e+000,-2.183330e-002,-4.020023e-002,5.051914e-005,5.051914e-005,,,,,,,,,,,,,,,,,,,,
1405561313.781,,-7.500000e+001,2.979968e+002,2.980050e+002,1,0,2.635591e-002,1.624043e+000,1.624043e+000,4.131180e-001,4.047990e-001,1.628134e+000,4.172092e-001,4.088902e-001,7.078399e-005,7.078399e-005,,,,,,,,,,,,,,,,,,,,
1405561313.781,,-7.500000e+001,2.979968e+002,2.980050e+002,1,0,2.751273e+000,7.901242e-001,7.901242e-001,-3.997582e-001,-4.291193e-001,8.200522e-001,-3.698302e-001,-3.991913e-001,3.443761e-005,3.443761e-005,,,,,,,,,,,,,,,,,,,,
1405561446.281,,-5.000000e+001,2.980050e+002,2.980050e+002,1,0,3.146140e+000,1.369976e+000,1.369976e+000,2.094963e-001,1.900976e-001,1.355278e+000,1.947981e-001,1.753994e-001,5.971062e-005,5.971062e-005,,,,,,,,,,,,,,,,,,,,
1405561464.515,,-5.000000e+001,2.979968e+002,2.979968e+002,1,0,7.102139e-002,1.583758e+000,1.583758e+000,4.242319e-001,4.153124e-001,1.595958e+000,4.364315e-001,4.275119e-001,6.902835e-005,6.902835e-005,,,,,,,,,,,,,,,,,,,,
1405561464.515,,-5.000000e+001,2.979968e+002,2.979968e+002,1,0,2.592949e+000,4.924162e-001,4.924161e-001,-6.458021e-001,-6.760294e-001,5.203452e-001,-6.178731e-001,-6.481004e-001,2.146204e-005,2.146204e-005,,,,,,,,,,,,,,,,,,,,
1405561482.250,,-5.000000e+001,2.979968e+002,2.979968e+002,1,0,3.301882e+000,1.542558e+000,1.542558e+000,3.780191e-001,3.601881e-001,1.529161e+000,3.646221e-001,3.467911e-001,6.723264e-005,6.723264e-005,,,,,,,,,,,,,,,,,,,,
1405561601.500,,-4.500000e+001,2.979968e+002,2.979968e+002,1,0,1.379917e-001,1.610462e+000,1.610462e+000,4.609605e-001,4.515039e-001,1.616374e+000,4.668728e-001,4.574162e-001,7.019227e-005,7.019227e-005,,,,,,,,,,,,,,,,,,,,
1405561601.500,,-4.500000e+001,2.979968e+002,2.979968e+002,1,0,2.427631e+000,2.299570e-001,2.299570e-001,-8.981423e-001,-9.290009e-001,2.541052e-001,-8.739942e-001,-9.048526e-001,1.002272e-005,1.002272e-005,,,,,,,,,,,,,,,,,,,,
1405561619.234,,-4.500000e+001,2.979968e+002,2.980050e+002,1,0,3.448602e+000,1.633961e+000,1.633961e+000,4.837727e-001,4.648641e-001,1.625524e+000,4.753356e-001,4.564270e-001,7.121648e-005,7.121648e-005,,,,,,,,,,,,,,,,,,,,
1405561637.250,,-4.500000e+001,2.980050e+002,2.979968e+002,1,0,2.237269e-001,1.674856e+000,1.674856e+000,5.011771e-001,4.918648e-001,1.675041e+000,5.013622e-001,4.920499e-001,7.299890e-005,7.299890e-005,,,,,,,,,,,,,,,,,,,,
1405561637.250,,-4.500000e+001,2.980050e+002,2.979968e+002,1,0,2.256138e+000,5.691702e-002,5.691702e-002,-1.096740e+000,-1.126074e+000,5.816828e-002,-1.095489e+000,-1.124823e+000,2.480739e-006,2.480739e-006,,,,,,,,,,,,,,,,,,,,
1405561755.734,,-4.000000e+001,2.979968e+002,2.979968e+002,1,0,3.584278e+000,1.684927e+000,1.684927e+000,5.261238e-001,5.061318e-001,1.685249e+000,5.264455e-001,5.064535e-001,7.343788e-005,7.343788e-005,,,,,,,,,,,,,,,,,,,,
1405561773.734,,-4.000000e+001,2.979968e+002,2.980050e+002,1,0,3.242094e-001,1.693625e+000,1.693625e+000,5.276805e-001,5.181504e-001,1.692551e+000,5.266065e-001,5.170765e-001,7.381698e-005,7.381698e-005,,,,,,,,,,,,,,,,,,,,
1405561792.000,,-4.000000e+001,2.980050e+002,2.979968e+002,1,0,2.079571e+000,-3.158666e-002,-3.158666e-002,-1.209473e+000,-1.209473e+000,-3.390078e-002,-1.211788e+000,-1.211788e+000,-1.376711e-006,-1.376711e-006,,,,,,,,,,,,,,,,,,,,
1405561792.000,,-4.000000e+001,2.980050e+002,2.979968e+002,1,0,3.705825e+000,1.687979e+000,1.687979e+000,5.272945e-001,5.100919e-001,1.691091e+000,5.304067e-001,5.132041e-001,7.357090e-005,7.357090e-005,,,,,,,,,,,,,,,,,,,,
1405561910.484,,-3.500000e+001,2.980050e+002,2.979968e+002,1,0,4.358732e-001,1.667837e+000,1.667837e+000,5.313091e-001,5.199661e-001,1.666265e+000,5.297377e-001,5.183947e-001,7.269302e-005,7.269302e-005,,,,,,,,,,,,,,,,,,,,
1405561928.218,,-3.500000e+001,2.980050e+002,2.979968e+002,1,0,1.899912e+000,1.068148e-003,1.068148e-003,-1.164250e+000,-1.164718e+000,-9.248829e-003,-1.174567e+000,-1.175035e+000,4.655546e-008,4.655546e-008,,,,,,,,,,,,,,,,,,,,
1405561928.218,,-3.500000e+001,2.980050e+002,2.979968e+002,1,0,3.809919e+000,1.647237e+000,1.647237e+000,5.020064e-001,4.814509e-001,1.651290e+000,5.060599e-001,4.855045e-001,7.179517e-005,7.179517e-005,,,,,,,,,,,,,,,,,,,,
1405561945.953,,-3.500000e+001,2.979885e+002,2.979968e+002,1,0,5.561047e-001,1.676382e+000,1.676382e+000,5.055456e-001,4.960616e-001,1.669139e+000,4.983028e-001,4.888189e-001,7.306547e-005,7.306547e-005,,,,,,,,,,,,,,,,,,,,
1405562064.453,,-3.000000e+001,2.980050e+002,2.979968e+002,1,0,1.719033e+000,1.609851e-001,1.609851e-001,-9.902716e-001,-9.913994e-001,1.586307e-001,-9.926260e-001,-9.937539e-001,7.016576e-006,7.016576e-006,,,,,,,,,,,,,,,,,,,,
1405562064.453,,-3.000000e+001,2.980050e+002,2.979968e+002,1,0,3.893676e+000,1.594134e+000,1.594134e+000,4.671258e-001,4.417498e-001,1.600219e+000,4.732108e-001,4.478348e-001,6.948073e-005,6.948073e-005,,,,,,,,,,,,,,,,,,,,
1405562081.937,,-3.000000e+001,2.979968e+002,2.979968e+002,1,0,6.833012e-001,1.589557e+000,1.589557e+000,4.355072e-001,4.259988e-001,1.574242e+000,4.201930e-001,4.106846e-001,6.928121e-005,6.928121e-005,,,,,,,,,,,,,,,,,,,,
1405562099.671,,-3.000000e+001,2.979968e+002,2.979968e+002,1,0,1.538513e+000,4.457228e-001,4.457228e-001,-7.354763e-001,-7.364687e-001,4.498601e-001,-7.313390e-001,-7.323314e-001,1.942694e-005,1.942694e-005,,,,,,,,,,,,,,,,,,,,
1405562099.671,,-3.000000e+001,2.979968e+002,2.979968e+002,1,0,3.953433e+000,1.608173e+000,1.608173e+000,4.411984e-001,4.259814e-001,1.613385e+000,4.464104e-001,4.311934e-001,7.009260e-005,7.009260e-005,,,,,,,,,,,,,,,,,,,,
1405562217.906,,-2.500000e+001,2.979968e+002,2.979968e+002,1,0,8.158339e-001,1.463973e+000,1.463973e+000,3.165575e-001,3.072151e-001,1.444785e+000,2.973691e-001,2.880267e-001,6.380765e-005,6.380765e-005,,,,,,,,,,,,,,,,,,,,
1405562236.390,,-2.500000e+001,2.980050e+002,2.980050e+002,1,0,1.360934e+000,7.382428e-001,7.382427e-001,-4.424052e-001,-4.438602e-001,7.313770e-001,-4.492710e-001,-4.507259e-001,3.217650e-005,3.217650e-005,,,,,,,,,,,,,,,,,,,,
1405562236.390,,-2.500000e+001,2.980050e+002,2.980050e+002,1,0,3.987429e+000,1.584063e+000,1.584063e+000,4.190560e-001,4.019604e-001,1.593736e+000,4.287286e-001,4.116330e-001,6.904181e-005,6.904181e-005,,,,,,,,,,,,,,,,,,,,
1405562254.375,,-2.500000e+001,2.979968e+002,2.979968e+002,1,0,9.541952e-001,1.312906e+000,1.312906e+000,1.565526e-001,1.460540e-001,1.292536e+000,1.361824e-001,1.256838e-001,5.722337e-005,5.722337e-005,,,,,,,,,,,,,,,,,,,,
1405562372.625,,-2.000000e+001,2.980050e+002,2.979968e+002,1,0,1.187006e+000,9.964293e-001,9.964293e-001,-1.680591e-001,-1.701877e-001,9.798186e-001,-1.846698e-001,-1.867985e-001,4.342966e-005,4.342966e-005,,,,,,,,,,,,,,,,,,,,
1405562372.625,,-2.000000e+001,2.980050e+002,2.979968e+002,1,0,3.994394e+000,1.556597e+000,1.556597e+000,4.104146e-001,3.899795e-001,1.569336e+000,4.231543e-001,4.027191e-001,6.784470e-005,6.784470e-005,,,,,,,,,,,,,,,,,,,,
1405562389.859,,-2.000000e+001,2.979968e+002,2.980050e+002,1,0,1.098421e+000,1.102023e+000,1.102023e+000,-4.320236e-002,-5.281222e-002,1.088292e+000,-5.693324e-002,-6.654310e-002,4.803200e-005,4.803200e-005,,,,,,,,,,,,,,,,,,,,
1405562408.093,,-2.000000e+001,2.980050e+002,2.980050e+002,1,0,1.018260e+000,1.219825e+000,1.219825e+000,7.355076e-002,7.119119e-002,1.198830e+000,5.255610e-002,5.019653e-002,5.316641e-005,5.316641e-005,,,,,,,,,,,,,,,,,,,,
1405562408.093,,-2.000000e+001,2.980050e+002,2.980050e+002,1,0,3.974729e+000,1.549119e+000,1.549120e+000,4.197558e-001,4.004860e-001,1.562218e+000,4.328545e-001,4.135847e-001,6.751881e-005,6.751881e-005,,,,,,,,,,,,,,,,,,,,
1405562527.093,,-1.500000e+001,2.980050e+002,2.979968e+002,1,0,1.249588e+000,8.516190e-001,8.516190e-001,-2.753412e-001,-2.889940e-001,8.508923e-001,-2.760679e-001,-2.897207e-001,3.711807e-005,3.711807e-005,,,,,,,,,,,,,,,,,,,,
1405562546.078,,-1.500000e+001,2.980132e+002,2.979885e+002,1,0,8.548454e-001,1.412702e+000,1.412702e+000,2.690971e-001,2.661029e-001,1.396026e+000,2.524213e-001,2.494271e-001,6.157304e-005,6.157304e-005,,,,,,,,,,,,,,,,,,,,
1405562546.078,,-1.500000e+001,2.980132e+002,2.979885e+002,1,0,3.929902e+000,1.562395e+000,1.562395e+000,4.371834e-001,4.157962e-001,1.576863e+000,4.516517e-001,4.302645e-001,6.809746e-005,6.809746e-005,,,,,,,,,,,,,,,,,,,,
1405562564.562,,-1.500000e+001,2.980050e+002,2.979968e+002,1,0,1.407881e+000,5.996887e-001,5.996887e-001,-5.396926e-001,-5.479990e-001,6.196852e-001,-5.196962e-001,-5.280025e-001,2.613761e-005,2.613761e-005,,,,,,,,,,,,,,,,,,,,
1405562682.562,,-1.000000e+001,2.979968e+002,2.980050e+002,1,0,6.991971e-001,1.556444e+000,1.556444e+000,4.185634e-001,4.153184e-001,1.538457e+000,4.005763e-001,3.973312e-001,6.783812e-005,6.783812e-005,,,,,,,,,,,,,,,,,,,,
1405562682.562,,-1.000000e+001,2.979968e+002,2.980050e+002,1,0,3.862941e+000,1.584826e+000,1.584826e+000,4.643880e-001,4.437007e-001,1.597752e+000,4.773135e-001,4.566262e-001,6.907516e-005,6.907516e-005,,,,,,,,,,,,,,,,,,,,
1405562700.046,,-1.000000e+001,2.979968e+002,2.980050e+002,1,0,1.573223e+000,3.225806e-001,3.225806e-001,-8.014942e-001,-8.109738e-001,3.514281e-001,-7.726468e-001,-7.821264e-001,1.405978e-005,1.405978e-005,,,,,,,,,,,,,,,,,,,,
1405562718.046,,-1.000000e+001,2.980050e+002,2.979968e+002,1,0,5.525305e-001,1.662648e+000,1.662648e+000,4.998530e-001,4.972231e-001,1.652539e+000,4.897441e-001,4.871142e-001,7.246707e-005,7.246707e-005,,,,,,,,,,,,,,,,,,,,
1405562718.046,,-1.000000e+001,2.980050e+002,2.979968e+002,1,0,3.777375e+000,1.652272e+000,1.652272e+000,5.020416e-001,4.868468e-001,1.655101e+000,5.048707e-001,4.896759e-001,7.201482e-005,7.201482e-005,,,,,,,,,,,,,,,,,,,,
1405562836.031,,-5.000000e+000,2.980050e+002,2.980050e+002,1,0,1.744863e+000,9.765923e-002,9.765923e-002,-1.025417e+000,-1.036614e+000,1.204377e-001,-1.002639e+000,-1.013835e+000,4.256511e-006,4.256511e-006,,,,,,,,,,,,,,,,,,,,
1405562853.265,,-5.000000e+000,2.979968e+002,2.979968e+002,1,0,4.168783e-001,1.657460e+000,1.657460e+000,5.213333e-001,5.187554e-001,1.653818e+000,5.176910e-001,5.151131e-001,7.224097e-005,7.224097e-005,,,,,,,,,,,,,,,,,,,,
1405562853.265,,-5.000000e+000,2.979968e+002,2.979968e+002,1,0,3.676882e+000,1.644490e+000,1.644490e+000,5.194479e-001,5.057851e-001,1.642710e+000,5.176678e-001,5.040050e-001,7.167565e-005,7.167565e-005,,,,,,,,,,,,,,,,,,,,
1405562871.250,,-5.000000e+000,2.979968e+002,2.979968e+002,1,0,1.921445e+000,-2.380444e-002,-2.380444e-002,-1.159235e+000,-1.167043e+000,-2.093900e-002,-1.156369e+000,-1.164178e+000,-1.037525e-006,-1.037525e-006,,,,,,,,,,,,,,,,,,,,
1405562991.031,,0.000000e+000,2.979968e+002,2.979968e+002,1,0,2.952665e-001,1.612903e+000,1.612903e+000,4.938892e-001,4.906583e-001,1.622112e+000,5.030975e-001,4.998666e-001,7.029897e-005,7.029897e-005,,,,,,,,,,,,,,,,,,,,
1405562991.031,,0.000000e+000,2.979968e+002,2.979968e+002,1,0,3.565033e+000,1.621296e+000,1.621296e+000,5.149116e-001,4.990509e-001,1.610578e+000,5.041934e-001,4.883326e-001,7.066476e-005,7.066476e-005,,,,,,,,,,,,,,,,,,,,
1405563009.296,,0.000000e+000,2.979968e+002,2.979968e+002,1,0,2.101192e+000,-2.288888e-002,-2.288888e-002,-1.154759e+000,-1.160954e+000,-3.068595e-002,-1.162556e+000,-1.168751e+000,-9.976202e-007,-9.976202e-007,,,,,,,,,,,,,,,,,,,,
1405563026.781,,0.000000e+000,2.979968e+002,2.979968e+002,1,0,1.909183e-001,1.604816e+000,1.604816e+000,4.524032e-001,4.502274e-001,1.623752e+000,4.713390e-001,4.691632e-001,6.994648e-005,6.994648e-005,,,,,,,,,,,,,,,,,,,,
1405563026.781,,0.000000e+000,2.979968e+002,2.979968e+002,1,0,3.444653e+000,1.622364e+000,1.622364e+000,4.777479e-001,4.677755e-001,1.600819e+000,4.562030e-001,4.462305e-001,7.071132e-005,7.071132e-005,,,,,,,,,,,,,,,,,,,,
1405563145.015,,5.000000e+000,2.980050e+002,2.980050e+002,1,0,2.282120e+000,1.086459e-001,1.086459e-001,-1.011225e+000,-1.021046e+000,1.025211e-001,-1.017350e+000,-1.027171e+000,4.735369e-006,4.735369e-006,,,,,,,,,,,,,,,,,,,,
1405563162.750,,5.000000e+000,2.979968e+002,2.979968e+002,1,0,1.074009e-001,1.543626e+000,1.543626e+000,4.006487e-001,3.982873e-001,1.575904e+000,4.329261e-001,4.305646e-001,6.727948e-005,6.727948e-005,,,,,,,,,,,,,,,,,,,,
1405563162.750,,5.000000e+000,2.979968e+002,2.979968e+002,1,0,3.317758e+000,1.531419e+000,1.531419e+000,3.962523e-001,3.860799e-001,1.497305e+000,3.621389e-001,3.519665e-001,6.674742e-005,6.674742e-005,,,,,,,,,,,,,,,,,,,,
1405563180.484,,5.000000e+000,2.979968e+002,2.979968e+002,1,0,2.462238e+000,3.679006e-001,3.679006e-001,-7.759449e-001,-7.820675e-001,3.602807e-001,-7.835649e-001,-7.896875e-001,1.603508e-005,1.603508e-005,,,,,,,,,,,,,,,,,,,,
1405563305.234,,1.000000e+001,2.979968e+002,2.979968e+002,1,0,4.755239e-002,1.466872e+000,1.466872e+000,3.580944e-001,3.553710e-001,1.510155e+000,4.013769e-001,3.986535e-001,6.393410e-005,6.393410e-005,,,,,,,,,,,,,,,,,,,,
1405563305.234,,1.000000e+001,2.979968e+002,2.979968e+002,1,0,3.185150e+000,1.373485e+000,1.373486e+000,2.730723e-001,2.619843e-001,1.329272e+000,2.288592e-001,2.177712e-001,5.986381e-005,5.986381e-005,,,,,,,,,,,,,,,,,,,,
1405563322.484,,1.000000e+001,2.979968e+002,2.980050e+002,1,0,2.640075e+000,6.372265e-001,6.372265e-001,-4.936680e-001,-4.972739e-001,6.201581e-001,-5.107363e-001,-5.143423e-001,2.777372e-005,2.777372e-005,,,,,,,,,,,,,,,,,,,,
1405563340.218,,1.000000e+001,2.980050e+002,2.980050e+002,1,0,1.353713e-002,1.457412e+000,1.457411e+000,3.380573e-001,3.358362e-001,1.504359e+000,3.850052e-001,3.827841e-001,6.352175e-005,6.352175e-005,,,,,,,,,,,,,,,,,,,,
1405563340.218,,1.000000e+001,2.980050e+002,2.980050e+002,1,0,3.046789e+000,1.216468e+000,1.216468e+000,1.034808e-001,9.489250e-002,1.177595e+000,6.460823e-002,5.601990e-002,5.302014e-005,5.302014e-005,,,,,,,,,,,,,,,,,,,,
1405563452.953,,1.500000e+001,2.979968e+002,2.980050e+002,1,0,2.813990e+000,8.763390e-001,8.763390e-001,-2.123511e-001,-2.146276e-001,8.389118e-001,-2.497784e-001,-2.520548e-001,3.819550e-005,3.819550e-005,,,,,,,,,,,,,,,,,,,,
1405563471.187,,1.500000e+001,2.979968e+002,2.979968e+002,1,0,6.507094e-003,1.425214e+000,1.425214e+000,3.227857e-001,3.214455e-001,1.479909e+000,3.774800e-001,3.761398e-001,6.211840e-005,6.211840e-005,,,,,,,,,,,,,,,,,,,,
1405563471.187,,1.500000e+001,2.979968e+002,2.979968e+002,1,0,2.902447e+000,9.962767e-001,9.962767e-001,-1.025501e-001,-1.074922e-001,9.733183e-001,-1.255085e-001,-1.304506e-001,4.342302e-005,4.342302e-005,,,,,,,,,,,,,,,,,,,,
1405563488.984,,1.500000e+001,2.979968e+002,2.979968e+002,1,0,2.982816e+000,1.136357e+000,1.136357e+000,3.662179e-002,3.340566e-002,1.081635e+000,-1.809980e-002,-2.131593e-002,4.952845e-005,4.952845e-005,,,,,,,,,,,,,,,,,,,,
1405563607.031,,2.000000e+001,2.980050e+002,2.980050e+002,1,0,2.632186e-002,1.395764e+000,1.395764e+000,3.211303e-001,3.196723e-001,1.455527e+000,3.808936e-001,3.794357e-001,6.083477e-005,6.083477e-005,,,,,,,,,,,,,,,,,,,,
1405563607.031,,2.000000e+001,2.980050e+002,2.980050e+002,1,0,2.751372e+000,7.391583e-001,7.391583e-001,-3.317876e-001,-3.369334e-001,7.375977e-001,-3.333482e-001,-3.384939e-001,3.221642e-005,3.221642e-005,,,,,,,,,,,,,,,,,,,,
1405563625.015,,2.000000e+001,2.979968e+002,2.980050e+002,1,0,3.145852e+000,1.323740e+000,1.323740e+000,2.389680e-001,2.359947e-001,1.265414e+000,1.806419e-001,1.776686e-001,5.769560e-005,5.769560e-005,,,,,,,,,,,,,,,,,,,,
1405563642.250,,2.000000e+001,2.980050e+002,2.979968e+002,1,0,7.106149e-002,1.465651e+000,1.465651e+000,3.503917e-001,3.492287e-001,1.516545e+000,4.012850e-001,4.001220e-001,6.388083e-005,6.388083e-005,,,,,,,,,,,,,,,,,,,,
1405563642.250,,2.000000e+001,2.980050e+002,2.979968e+002,1,0,2.593114e+000,5.238502e-001,5.238502e-001,-5.886314e-001,-5.925725e-001,5.486167e-001,-5.638649e-001,-5.678059e-001,2.283216e-005,2.283216e-005,,,,,,,,,,,,,,,,,,,,
1405563759.484,,2.500000e+001,2.980050e+002,2.980050e+002,1,0,3.301772e+000,1.429792e+000,1.429792e+000,3.796382e-001,3.798528e-001,1.376289e+000,3.261353e-001,3.263499e-001,6.231786e-005,6.231786e-005,,,,,,,,,,,,,,,,,,,,
1405563776.718,,2.500000e+001,2.980050e+002,2.980050e+002,1,0,1.380059e-001,1.432234e+000,1.432234e+000,3.767358e-001,3.769641e-001,1.472847e+000,4.173489e-001,4.175771e-001,6.242428e-005,6.242428e-005,,,,,,,,,,,,,,,,,,,,
1405563776.718,,2.500000e+001,2.980050e+002,2.980050e+002,1,0,2.427670e+000,2.368236e-001,2.368236e-001,-8.191909e-001,-8.184460e-001,2.790399e-001,-7.769746e-001,-7.762297e-001,1.032202e-005,1.032202e-005,,,,,,,,,,,,,,,,,,,,
1405563794.453,,2.500000e+001,2.980050e+002,2.980050e+002,1,0,3.448533e+000,1.529282e+000,1.529282e+000,4.593651e-001,4.612436e-001,1.495100e+000,4.251828e-001,4.270613e-001,6.665418e-005,6.665418e-005,,,,,,,,,,,,,,,,,,,,
1405563913.015,,3.000000e+001,2.980050e+002,2.979968e+002,1,0,2.236381e-001,1.270333e+000,1.270333e+000,3.597882e-001,3.634052e-001,1.295483e+000,3.849379e-001,3.885549e-001,5.536777e-005,5.536777e-005,,,,,,,,,,,,,,,,,,,,
1405563913.015,,3.000000e+001,2.980050e+002,2.979968e+002,1,0,2.256066e+000,1.846370e-002,1.846370e-002,-8.998578e-001,-8.884640e-001,6.179429e-002,-8.565271e-001,-8.451334e-001,8.047448e-007,8.047448e-007,,,,,,,,,,,,,,,,,,,,
1405563931.250,,3.000000e+001,2.980050e+002,2.979968e+002,1,0,3.584240e+000,1.328928e+000,1.328928e+000,4.168071e-001,4.267553e-001,1.312272e+000,4.001505e-001,4.100987e-001,5.792167e-005,5.792167e-005,,,,,,,,,,,,,,,,,,,,
1405563948.546,,3.000000e+001,2.979968e+002,2.979968e+002,1,0,3.242488e-001,1.280404e+000,1.280404e+000,3.841137e-001,3.892210e-001,1.291446e+000,3.951554e-001,4.002627e-001,5.580672e-005,5.580672e-005,,,,,,,,,,,,,,,,,,,,
1405564078.015,,3.500000e+001,2.980050e+002,2.979968e+002,1,0,2.079634e+000,-8.728293e-002,-8.728294e-002,3.736978e-001,3.736978e-001,-1.381833e-001,3.227974e-001,3.227974e-001,-1.902123e-006,-1.902123e-006,,,,,,,,,,,,,,,,,,,,
1405564078.015,,3.500000e+001,2.980050e+002,2.979968e+002,1,0,3.705822e+000,-5.333109e-001,-5.333109e-001,-1.661667e-001,-7.233027e-002,-5.228276e-001,-1.556834e-001,-6.184694e-002,-1.162224e-005,-1.162224e-005,,,,,,,,,,,,,,,,,,,,
1405564095.296,,3.500000e+001,2.979968e+002,2.980132e+002,1,0,4.360858e-001,-7.466353e-001,-7.466353e-001,-1.903703e-001,-1.447613e-001,-7.393003e-001,-1.830353e-001,-1.374263e-001,-1.627113e-005,-1.627113e-005,,,,,,,,,,,,,,,,,,,,
1405564113.031,,3.500000e+001,2.979968e+002,2.980050e+002,1,0,1.899910e+000,2.044740e-002,2.044740e-002,7.291229e-001,7.311835e-001,2.841563e-002,7.370911e-001,7.391517e-001,4.456023e-007,4.456023e-007,,,,,,,,,,,,,,,,,,,,
1405564113.031,,3.500000e+001,2.979968e+002,2.980050e+002,1,0,3.810060e+000,-9.100620e-001,-9.100620e-001,-2.899923e-001,-1.993259e-001,-8.605224e-001,-2.404528e-001,-1.497864e-001,-1.983263e-005,-1.983263e-005,,,,,,,,,,,,,,,,,,,,
1405564232.812,,4.000000e+001,2.979885e+002,2.979968e+002,1,0,5.563579e-001,-2.920316e+000,-2.920316e+000,-7.573016e-001,-7.095180e-001,-2.973822e+000,-8.108073e-001,-7.630236e-001,-6.364129e-005,-6.364129e-005,,,,,,,,,,,,,,,,,,,,
1405564251.109,,4.000000e+001,2.979968e+002,2.979968e+002,1,0,1.718996e+000,-3.093051e-001,-3.093051e-001,1.951019e+000,1.955361e+000,-2.390682e-001,2.021255e+000,2.025598e+000,-6.740563e-006,-6.740563e-006,,,,,,,,,,,,,,,,,,,,
1405564251.109,,4.000000e+001,2.979968e+002,2.979968e+002,1,0,3.893649e+000,-3.075198e+000,-3.075198e+000,-9.082295e-001,-8.105319e-001,-2.968895e+000,-8.019267e-001,-7.042291e-001,-6.701655e-005,-6.701655e-005,,,,,,,,,,,,,,,,,,,,
1405564268.875,,4.000000e+001,2.979968e+002,2.979968e+002,1,0,6.832336e-001,-2.802057e+000,-2.802057e+000,-5.684326e-001,-5.133488e-001,-2.883526e+000,-6.499019e-001,-5.948181e-001,-6.106411e-005,-6.106411e-005,,,,,,,,,,,,,,,,,,,,
1405564380.359,,4.500000e+001,2.979968e+002,2.979968e+002,1,0,1.538550e+000,-8.212531e-001,-8.212531e-001,1.723946e+000,1.730453e+000,-8.351238e-001,1.710075e+000,1.716582e+000,-1.789723e-005,-1.789723e-005,,,,,,,,,,,,,,,,,,,,
1405564380.359,,4.500000e+001,2.979968e+002,2.979968e+002,1,0,3.953431e+000,-3.468123e+000,-3.468123e+000,-1.016192e+000,-9.164176e-001,-3.312792e+000,-8.608606e-001,-7.610862e-001,-7.557940e-005,-7.557940e-005,,,,,,,,,,,,,,,,,,,,
1405564398.843,,4.500000e+001,2.979968e+002,2.979885e+002,1,0,8.159820e-001,-2.856838e+000,-2.856838e+000,-3.750961e-001,-3.158476e-001,-2.960512e+000,-4.787705e-001,-4.195220e-001,-6.225790e-005,-6.225790e-005,,,,,,,,,,,,,,,,,,,,
1405564417.578,,4.500000e+001,2.979968e+002,2.979968e+002,1,0,1.360813e+000,-1.284066e+000,-1.284066e+000,1.234081e+000,1.244095e+000,-1.378896e+000,1.139251e+000,1.149265e+000,-2.798313e-005,-2.798313e-005,,,,,,,,,,,,,,,,,,,,
1405564417.578,,4.500000e+001,2.979968e+002,2.979968e+002,1,0,3.987385e+000,-3.418378e+000,-3.418378e+000,-1.007879e+000,-8.902168e-001,-3.244862e+000,-8.343627e-001,-7.167001e-001,-7.449531e-005,-7.449531e-005,,,,,,,,,,,,,,,,,,,,
1405564536.578,,5.000000e+001,2.980050e+002,2.979968e+002,1,0,9.542171e-001,-2.658467e+000,-2.658467e+000,-4.586231e-002,1.885891e-002,-2.779174e+000,-1.665689e-001,-1.018476e-001,-5.793486e-005,-5.793486e-005,,,,,,,,,,,,,,,,,,,,
1405564554.562,,5.000000e+001,2.979968e+002,2.979885e+002,1,0,1.187200e+000,-1.941435e+000,-1.941435e+000,7.010189e-001,7.140940e-001,-2.085122e+000,5.573322e-001,5.704074e-001,-4.230888e-005,-4.230888e-005,,,,,,,,,,,,,,,,,,,,
1405564554.562,,5.000000e+001,2.979968e+002,2.979885e+002,1,0,3.994416e+000,-3.609272e+000,-3.609272e+000,-1.079264e+000,-9.537425e-001,-3.415634e+000,-8.856266e-001,-7.601051e-001,-7.865534e-005,-7.865534e-005,,,,,,,,,,,,,,,,,,,,
1405564572.796,,5.000000e+001,2.979885e+002,2.979968e+002,1,0,1.098527e+000,-2.177038e+000,-2.177038e+000,4.106254e-001,4.804494e-001,-2.321530e+000,2.661337e-001,3.359578e-001,-4.744327e-005,-4.744327e-005,,,,,,,,,,,,,,,,,,,,
1405564714.296,,7.500000e+001,2.980050e+002,2.979968e+002,1,0,1.017964e+000,-1.345866e+000,-1.345866e+000,7.973153e-002,8.958554e-002,-1.449939e+000,-2.434080e-002,-1.448679e-002,-5.865967e-005,-5.865967e-005,,,,,,,,,,,,,,,,,,,,
1405564714.296,,7.500000e+001,2.980050e+002,2.979968e+002,1,0,3.974711e+000,-1.973022e+000,-1.973022e+000,-6.180442e-001,-5.375698e-001,-1.857685e+000,-5.027073e-001,-4.222329e-001,-8.599427e-005,-8.599427e-005,,,,,,,,,,,,,,,,,,,,
1405564732.546,,7.500000e+001,2.979968e+002,2.980050e+002,1,0,1.249668e+000,-9.044161e-001,-9.044160e-001,4.517761e-001,4.992822e-001,-9.812902e-001,3.749019e-001,4.224080e-001,-3.941903e-005,-3.941903e-005,,,,,,,,,,,,,,,,,,,,
1405564749.312,,7.500000e+001,2.979968e+002,2.979968e+002,1,0,8.548103e-001,-1.570025e+000,-1.570025e+000,-1.614804e-001,-1.497543e-001,-1.678645e+000,-2.701004e-001,-2.583743e-001,-6.842962e-005,-6.842962e-005,,,,,,,,,,,,,,,,,,,,
1405564749.312,,7.500000e+001,2.979968e+002,2.979968e+002,1,0,3.929888e+000,-1.966613e+000,-1.966613e+000,-6.301001e-001,-5.463423e-001,-1.864990e+000,-5.284775e-001,-4.447197e-001,-8.571494e-005,-8.571494e-005,,,,,,,,,,,,,,,,,,,,
1405564880.578,,1.000000e+002,2.980050e+002,2.980050e+002,1,0,1.407939e+000,-6.468398e-001,-6.468398e-001,7.307943e-001,7.867826e-001,-7.036183e-001,6.740158e-001,7.300041e-001,-2.819249e-005,-2.819249e-005,,,,,,,,,,,,,,,,,,,,
1405564898.843,,1.000000e+002,2.979968e+002,2.979968e+002,1,0,6.991163e-001,-1.769158e+000,-1.769158e+000,-3.690252e-001,-3.532462e-001,-1.871114e+000,-4.709810e-001,-4.552020e-001,-7.710869e-005,-7.710869e-005,,,,,,,,,,,,,,,,,,,,
1405564898.843,,1.000000e+002,2.979968e+002,2.979968e+002,1,0,3.862871e+000,-1.982940e+000,-1.982940e+000,-6.676195e-001,-5.670284e-001,-1.891321e+000,-5.760006e-001,-4.754095e-001,-8.642637e-005,-8.642637e-005,,,,,,,,,,,,,,,,,,,,
1405564917.125,,1.000000e+002,2.979885e+002,2.979968e+002,1,0,1.573250e+000,-3.744621e-001,-3.744621e-001,9.934345e-001,1.052396e+000,-3.818587e-001,9.860380e-001,1.044999e+000,-1.632092e-005,-1.632092e-005,,,,,,,,,,,,,,,,,,,,
1405564917.125,,1.000000e+002,2.979885e+002,2.979968e+002,1,0,2.256166e+000,-1.298563e-001,-1.298563e-001,1.173183e+000,1.297002e+000,-2.009336e-002,1.282946e+000,1.406765e+000,-5.659780e-006,-5.659780e-006,,,,,,,,,,,,,,,,,,,,