File: Sample Data Files/2014-07-16 EB on isolated PMN-PT no Ti spontaneous in situ/Ni-NiO_298K_SiO2_PMN-PT_5.0Tprebias_000V_Au_back_poled.rso.dat
[Header]
TITLE,MPMS RSO Measurement
BYAPP,MPMS Measurement,1.1,Summary
FILEOPENTIME, 1405557353.062000 7/16/2014, 5:35:53 PM

INFO, APPNAME, MPMS MultiVu Application, Revision 1.58,  Build 076

INFO, NAME, EB in situ
INFO, WEIGHT, 0.000
INFO, AREA, 0.000
INFO, LENGTH, 0.000
INFO, SHAPE, 0
INFO, COMMENT,
INFO, SEQUENCE FILE: MHcurveUpTo100.seq


INFO, BACKGROUND DATA FILE:, None


STARTUPAXIS,X,4,LINEAR,AUTO,0.000000,0.000000
STARTUPAXIS,Y1,5,LINEAR,AUTO,0.000000,0.000000


STARTUPGROUP,Longitudinal
FIELDGROUP,Longitudinal,1,2,3,4,5,6,7,8,9,10,11,19,20,21,22,23,35
FIELDGROUP,Transverse,1,2,3,4,12,13,14,15,16,17,18,24,25,26,27,28,35

PLOT_APPEARANCE,ALL,HORZ_GRID_ON,VERT_GRID_ON,MARKERS_AND_LINES

[Data]
Time,Comment,Field (Oe),Temperature (K),Long Moment (emu),Long Scan Std Dev,Long Offset (cm),Long Offset Std Dev,Long Algorithm,Long Reg Fit,Long Reg Factor,Trans Moment (emu),Trans Scan Std Dev,Trans Offset (cm),Trans Offset Std Dev,Trans Algorithm,Trans Reg Fit,Trans Reg Factor,Long Moment [w/o ABS] (emu),Long Scan Std Dev [w/o ABS],Long Offset [w/o ABS] (cm),Long Offset Std Dev [w/o ABS],Long Reg Fit [w/o ABS],Trans Moment [w/o ABS] (emu),Trans Scan Std Dev [w/o ABS],Trans Offset [w/o ABS] (cm),Trans Offset Std Dev [w/o ABS],Trans Reg Fit [w/o ABS],RSO Position (deg),Amplitude (cm),Frequency,Cycles to Average,Scans per Measurement,Delta Temp (K),Error,EC Comp. Running,Using ABS,
1405557353.062,,1.000000e+002,2.979968e+002,3.787101e-005,0.000000e+000,4.719068e-003,0.000000e+000,3,8.955441e-001,1.825000e+000,,,,,,,,,,,,,,,,,,0,4.000000e+000,5.000000e-001,5,1,0.000000e+000,0,,0,
1405557370.812,,1.000000e+002,2.980009e+002,3.785613e-005,0.000000e+000,4.922495e-003,0.000000e+000,3,8.956674e-001,1.825000e+000,,,,,,,,,,,,,,,,,,0,4.000000e+000,5.000000e-001,5,1,8.209229e-003,0,,0,
1405557389.078,,1.000000e+002,2.980009e+002,3.786569e-005,0.000000e+000,4.871045e-003,0.000000e+000,3,8.956494e-001,1.825000e+000,,,,,,,,,,,,,,,,,,0,4.000000e+000,5.000000e-001,5,1,8.209229e-003,0,,0,
1405557514.093,,7.500000e+001,2.979968e+002,3.762502e-005,0.000000e+000,4.912414e-003,0.000000e+000,3,9.037430e-001,1.825000e+000,,,,,,,,,,,,,,,,,,0,4.000000e+000,5.000000e-001,5,1,1.651001e-002,0,,0,
1405557532.093,,7.500000e+001,2.979968e+002,3.762383e-005,0.000000e+000,4.919561e-003,0.000000e+000,3,9.036902e-001,1.825000e+000,,,,,,,,,,,,,,,,,,0,4.000000e+000,5.000000e-001,5,1,0.000000e+000,0,,0,
1405557549.828,,7.500000e+001,2.980009e+002,3.763357e-005,0.000000e+000,4.669446e-003,0.000000e+000,3,9.036629e-001,1.825000e+000,,,,,,,,,,,,,,,,,,0,4.000000e+000,5.000000e-001,5,1,8.209229e-003,0,,0,
1405557681.062,,5.000000e+001,2.980009e+002,3.719488e-005,0.000000e+000,4.828874e-003,0.000000e+000,3,9.124597e-001,1.825000e+000,,,,,,,,,,,,,,,,,,0,4.000000e+000,5.000000e-001,5,1,8.209229e-003,0,,0,
1405557698.328,,5.000000e+001,2.980009e+002,3.719492e-005,0.000000e+000,5.040029e-003,0.000000e+000,3,9.123122e-001,1.825000e+000,,,,,,,,,,,,,,,,,,0,4.000000e+000,5.000000e-001,5,1,8.209229e-003,0,,0,
1405557715.812,,5.000000e+001,2.980009e+002,3.719745e-005,0.000000e+000,4.925537e-003,0.000000e+000,3,9.121838e-001,1.825000e+000,,,,,,,,,,,,,,,,,,0,4.000000e+000,5.000000e-001,5,1,8.209229e-003,0,,0,
1405557831.359,,4.500000e+001,2.980050e+002,3.707405e-005,0.000000e+000,5.102601e-003,0.000000e+000,3,9.139146e-001,1.825000e+000,,,,,,,,,,,,,,,,,,0,4.000000e+000,5.000000e-001,5,1,0.000000e+000,0,,0,
1405557849.093,,4.500000e+001,2.979968e+002,3.706573e-005,0.000000e+000,5.128515e-003,0.000000e+000,3,9.141240e-001,1.825000e+000,,,,,,,,,,,,,,,,,,0,4.000000e+000,5.000000e-001,5,1,0.000000e+000,0,,0,
1405557867.578,,4.500000e+001,2.980050e+002,3.705795e-005,0.000000e+000,4.947011e-003,0.000000e+000,3,9.140087e-001,1.825000e+000,,,,,,,,,,,,,,,,,,0,4.000000e+000,5.000000e-001,5,1,0.000000e+000,0,,0,
1405557984.578,,4.000000e+001,2.980050e+002,3.693497e-005,0.000000e+000,5.206128e-003,0.000000e+000,3,9.158019e-001,1.825000e+000,,,,,,,,,,,,,,,,,,0,4.000000e+000,5.000000e-001,5,1,0.000000e+000,0,,0,
1405558001.312,,4.000000e+001,2.979968e+002,3.693934e-005,0.000000e+000,4.991827e-003,0.000000e+000,3,9.159548e-001,1.825000e+000,,,,,,,,,,,,,,,,,,0,4.000000e+000,5.000000e-001,5,1,0.000000e+000,0,,0,
1405558018.578,,4.000000e+001,2.979968e+002,3.692810e-005,0.000000e+000,4.992536e-003,0.000000e+000,3,9.160424e-001,1.825000e+000,,,,,,,,,,,,,,,,,,0,4.000000e+000,5.000000e-001,5,1,0.000000e+000,0,,0,
1405558135.875,,3.500000e+001,2.980050e+002,3.677129e-005,0.000000e+000,4.909461e-003,0.000000e+000,3,9.178779e-001,1.825000e+000,,,,,,,,,,,,,,,,,,0,4.000000e+000,5.000000e-001,5,1,0.000000e+000,0,,0,
1405558154.109,,3.500000e+001,2.980009e+002,3.677039e-005,0.000000e+000,5.131758e-003,0.000000e+000,3,9.179174e-001,1.825000e+000,,,,,,,,,,,,,,,,,,0,4.000000e+000,5.000000e-001,5,1,8.209229e-003,0,,0,
1405558172.406,,3.500000e+001,2.980009e+002,3.676378e-005,0.000000e+000,5.079310e-003,0.000000e+000,3,9.179404e-001,1.825000e+000,,,,,,,,,,,,,,,,,,0,4.000000e+000,5.000000e-001,5,1,8.209229e-003,0,,0,
1405558291.390,,3.000000e+001,2.980009e+002,3.661315e-005,0.000000e+000,5.055416e-003,0.000000e+000,3,9.196655e-001,1.825000e+000,,,,,,,,,,,,,,,,,,0,4.000000e+000,5.000000e-001,5,1,8.209229e-003,0,,0,
1405558308.875,,3.000000e+001,2.979968e+002,3.659959e-005,0.000000e+000,5.250567e-003,0.000000e+000,3,9.196212e-001,1.825000e+000,,,,,,,,,,,,,,,,,,0,4.000000e+000,5.000000e-001,5,1,0.000000e+000,0,,0,
1405558326.640,,3.000000e+001,2.979968e+002,3.660803e-005,0.000000e+000,5.263711e-003,0.000000e+000,3,9.196642e-001,1.825000e+000,,,,,,,,,,,,,,,,,,0,4.000000e+000,5.000000e-001,5,1,0.000000e+000,0,,0,
1405558445.390,,2.500000e+001,2.979968e+002,3.638032e-005,0.000000e+000,4.715898e-003,0.000000e+000,3,9.220837e-001,1.825000e+000,,,,,,,,,,,,,,,,,,0,4.000000e+000,5.000000e-001,5,1,0.000000e+000,0,,0,
1405558463.125,,2.500000e+001,2.980009e+002,3.637844e-005,0.000000e+000,4.653935e-003,0.000000e+000,3,9.222783e-001,1.825000e+000,,,,,,,,,,,,,,,,,,0,4.000000e+000,5.000000e-001,5,1,8.209229e-003,0,,0,
1405558480.859,,2.500000e+001,2.980009e+002,3.637405e-005,0.000000e+000,4.803079e-003,0.000000e+000,3,9.219911e-001,1.825000e+000,,,,,,,,,,,,,,,,,,0,4.000000e+000,5.000000e-001,5,1,8.209229e-003,0,,0,
1405558592.343,,2.000000e+001,2.980009e+002,3.616072e-005,0.000000e+000,4.714686e-003,0.000000e+000,3,9.240579e-001,1.825000e+000,,,,,,,,,,,,,,,,,,0,4.000000e+000,5.000000e-001,5,1,8.209229e-003,0,,0,
1405558610.578,,2.000000e+001,2.979968e+002,3.614065e-005,0.000000e+000,4.679860e-003,0.000000e+000,3,9.240489e-001,1.825000e+000,,,,,,,,,,,,,,,,,,0,4.000000e+000,5.000000e-001,5,1,0.000000e+000,0,,0,
1405558628.078,,2.000000e+001,2.980009e+002,3.615008e-005,0.000000e+000,4.684987e-003,0.000000e+000,3,9.240762e-001,1.825000e+000,,,,,,,,,,,,,,,,,,0,4.000000e+000,5.000000e-001,5,1,8.209229e-003,0,,0,
1405558747.828,,1.500000e+001,2.979968e+002,3.587674e-005,0.000000e+000,4.941576e-003,0.000000e+000,3,9.261070e-001,1.825000e+000,,,,,,,,,,,,,,,,,,0,4.000000e+000,5.000000e-001,5,1,0.000000e+000,0,,0,
1405558765.562,,1.500000e+001,2.979968e+002,3.587047e-005,0.000000e+000,4.793450e-003,0.000000e+000,3,9.261910e-001,1.825000e+000,,,,,,,,,,,,,,,,,,0,4.000000e+000,5.000000e-001,5,1,0.000000e+000,0,,0,
1405558783.796,,1.500000e+001,2.980009e+002,3.586402e-005,0.000000e+000,4.767589e-003,0.000000e+000,3,9.260435e-001,1.825000e+000,,,,,,,,,,,,,,,,,,0,4.000000e+000,5.000000e-001,5,1,8.209229e-003,0,,0,
1405558903.031,,1.000000e+001,2.979968e+002,3.552955e-005,0.000000e+000,4.515867e-003,0.000000e+000,3,9.280773e-001,1.825000e+000,,,,,,,,,,,,,,,,,,0,4.000000e+000,5.000000e-001,5,1,0.000000e+000,0,,0,
1405558921.281,,1.000000e+001,2.980009e+002,3.551948e-005,0.000000e+000,4.495549e-003,0.000000e+000,3,9.285970e-001,1.825000e+000,,,,,,,,,,,,,,,,,,0,4.000000e+000,5.000000e-001,5,1,8.209229e-003,0,,0,
1405558939.031,,1.000000e+001,2.979968e+002,3.552086e-005,0.000000e+000,4.583587e-003,0.000000e+000,3,9.282182e-001,1.825000e+000,,,,,,,,,,,,,,,,,,0,4.000000e+000,5.000000e-001,5,1,1.651001e-002,0,,0,
1405559057.296,,5.000000e+000,2.980009e+002,3.504752e-005,0.000000e+000,4.124471e-003,0.000000e+000,3,9.305224e-001,1.825000e+000,,,,,,,,,,,,,,,,,,0,4.000000e+000,5.000000e-001,5,1,8.209229e-003,0,,0,
1405559076.031,,5.000000e+000,2.979968e+002,3.503961e-005,0.000000e+000,3.973545e-003,0.000000e+000,3,9.306003e-001,1.825000e+000,,,,,,,,,,,,,,,,,,0,4.000000e+000,5.000000e-001,5,1,0.000000e+000,0,,0,
1405559094.265,,5.000000e+000,2.980009e+002,3.502773e-005,0.000000e+000,4.116623e-003,0.000000e+000,3,9.305294e-001,1.825000e+000,,,,,,,,,,,,,,,,,,0,4.000000e+000,5.000000e-001,5,1,8.209229e-003,0,,0,
1405559213.000,,0.000000e+000,2.979968e+002,3.411041e-005,0.000000e+000,4.151142e-003,0.000000e+000,3,9.319831e-001,1.825000e+000,,,,,,,,,,,,,,,,,,0,4.000000e+000,5.000000e-001,5,1,0.000000e+000,0,,0,
1405559230.765,,0.000000e+000,2.979968e+002,3.406359e-005,0.000000e+000,4.253894e-003,0.000000e+000,3,9.322581e-001,1.825000e+000,,,,,,,,,,,,,,,,,,0,4.000000e+000,5.000000e-001,5,1,0.000000e+000,0,,0,
1405559249.000,,0.000000e+000,2.979926e+002,3.401727e-005,0.000000e+000,4.036670e-003,0.000000e+000,3,9.321524e-001,1.825000e+000,,,,,,,,,,,,,,,,,,0,4.000000e+000,5.000000e-001,5,1,8.300781e-003,0,,0,
1405559366.796,,-5.000000e+000,2.979968e+002,2.913453e-005,0.000000e+000,1.530959e-002,0.000000e+000,3,9.231241e-001,1.825000e+000,,,,,,,,,,,,,,,,,,0,4.000000e+000,5.000000e-001,5,1,1.651001e-002,0,,0,
1405559384.546,,-5.000000e+000,2.980009e+002,2.843101e-005,0.000000e+000,1.702633e-002,0.000000e+000,3,9.218177e-001,1.825000e+000,,,,,,,,,,,,,,,,,,0,4.000000e+000,5.000000e-001,5,1,8.209229e-003,0,,0,
1405559402.781,,-5.000000e+000,2.979968e+002,2.777406e-005,0.000000e+000,1.863929e-002,0.000000e+000,3,9.202611e-001,1.825000e+000,,,,,,,,,,,,,,,,,,0,4.000000e+000,5.000000e-001,5,1,0.000000e+000,0,,0,
1405559543.281,,-1.000000e+001,2.979968e+002,-6.295379e-006,0.000000e+000,-2.264711e-001,0.000000e+000,3,6.878693e-001,1.825000e+000,,,,,,,,,,,,,,,,,,0,4.000000e+000,5.000000e-001,5,1,0.000000e+000,0,,0,
1405559561.515,,-1.000000e+001,2.979968e+002,-8.251761e-006,0.000000e+000,-1.729281e-001,0.000000e+000,3,7.665263e-001,1.825000e+000,,,,,,,,,,,,,,,,,,0,4.000000e+000,5.000000e-001,5,1,0.000000e+000,0,,0,
1405559579.828,,-1.000000e+001,2.979968e+002,-9.840713e-006,0.000000e+000,-1.436564e-001,0.000000e+000,3,8.082805e-001,1.825000e+000,,,,,,,,,,,,,,,,,,0,4.000000e+000,5.000000e-001,5,1,0.000000e+000,0,,0,
1405559698.609,,-1.500000e+001,2.979968e+002,-2.307687e-005,0.000000e+000,-3.983894e-002,0.000000e+000,3,9.328030e-001,1.825000e+000,,,,,,,,,,,,,,,,,,0,4.000000e+000,5.000000e-001,5,1,0.000000e+000,0,,0,
1405559716.843,,-1.500000e+001,2.979968e+002,-2.364392e-005,0.000000e+000,-3.687348e-002,0.000000e+000,3,9.347459e-001,1.825000e+000,,,,,,,,,,,,,,,,,,0,4.000000e+000,5.000000e-001,5,1,0.000000e+000,0,,0,
1405559735.078,,-1.500000e+001,2.979968e+002,-2.405062e-005,0.000000e+000,-3.455212e-002,0.000000e+000,3,9.363533e-001,1.825000e+000,,,,,,,,,,,,,,,,,,0,4.000000e+000,5.000000e-001,5,1,0.000000e+000,0,,0,
1405559853.359,,-2.000000e+001,2.980009e+002,-2.639300e-005,0.000000e+000,-1.688411e-002,0.000000e+000,3,9.479039e-001,1.825000e+000,,,,,,,,,,,,,,,,,,0,4.000000e+000,5.000000e-001,5,1,8.209229e-003,0,,0,
1405559871.593,,-2.000000e+001,2.980009e+002,-2.652970e-005,0.000000e+000,-1.567927e-002,0.000000e+000,3,9.481868e-001,1.825000e+000,,,,,,,,,,,,,,,,,,0,4.000000e+000,5.000000e-001,5,1,8.209229e-003,0,,0,
1405559889.093,,-2.000000e+001,2.980050e+002,-2.663340e-005,0.000000e+000,-1.483992e-002,0.000000e+000,3,9.484262e-001,1.825000e+000,,,,,,,,,,,,,,,,,,0,4.000000e+000,5.000000e-001,5,1,0.000000e+000,0,,0,
1405560007.093,,-2.500000e+001,2.979968e+002,-2.802130e-005,0.000000e+000,-2.036441e-003,0.000000e+000,3,9.568998e-001,1.825000e+000,,,,,,,,,,,,,,,,,,0,4.000000e+000,5.000000e-001,5,1,0.000000e+000,0,,0,
1405560025.328,,-2.500000e+001,2.979968e+002,-2.818814e-005,0.000000e+000,-1.120198e-003,0.000000e+000,3,9.572296e-001,1.825000e+000,,,,,,,,,,,,,,,,,,0,4.000000e+000,5.000000e-001,5,1,0.000000e+000,0,,0,
1405560043.609,,-2.500000e+001,2.979968e+002,-2.832001e-005,0.000000e+000,-3.730885e-004,0.000000e+000,3,9.573746e-001,1.825000e+000,,,,,,,,,,,,,,,,,,0,4.000000e+000,5.000000e-001,5,1,0.000000e+000,0,,0,
1405560162.843,,-3.000000e+001,2.980009e+002,-2.994868e-005,0.000000e+000,1.303915e-002,0.000000e+000,3,9.646593e-001,1.825000e+000,,,,,,,,,,,,,,,,,,0,4.000000e+000,5.000000e-001,5,1,8.209229e-003,0,,0,
1405560179.609,,-3.000000e+001,2.979968e+002,-3.004860e-005,0.000000e+000,1.380924e-002,0.000000e+000,3,9.647891e-001,1.825000e+000,,,,,,,,,,,,,,,,,,0,4.000000e+000,5.000000e-001,5,1,0.000000e+000,0,,0,
1405560197.343,,-3.000000e+001,2.979968e+002,-3.013560e-005,0.000000e+000,1.420695e-002,0.000000e+000,3,9.649853e-001,1.825000e+000,,,,,,,,,,,,,,,,,,0,4.000000e+000,5.000000e-001,5,1,0.000000e+000,0,,0,
1405560315.140,,-3.500000e+001,2.979968e+002,-3.052740e-005,0.000000e+000,1.935963e-002,0.000000e+000,3,9.699474e-001,1.825000e+000,,,,,,,,,,,,,,,,,,0,4.000000e+000,5.000000e-001,5,1,0.000000e+000,0,,0,
1405560332.875,,-3.500000e+001,2.979968e+002,-3.051025e-005,0.000000e+000,1.925302e-002,0.000000e+000,3,9.699119e-001,1.825000e+000,,,,,,,,,,,,,,,,,,0,4.000000e+000,5.000000e-001,5,1,0.000000e+000,0,,0,
1405560351.140,,-3.500000e+001,2.980009e+002,-3.052972e-005,0.000000e+000,1.934581e-002,0.000000e+000,3,9.695178e-001,1.825000e+000,,,,,,,,,,,,,,,,,,0,4.000000e+000,5.000000e-001,5,1,8.209229e-003,0,,0,
1405560468.875,,-4.000000e+001,2.980009e+002,-3.071146e-005,0.000000e+000,2.119503e-002,0.000000e+000,3,9.732365e-001,1.825000e+000,,,,,,,,,,,,,,,,,,0,4.000000e+000,5.000000e-001,5,1,8.209229e-003,0,,0,
1405560486.640,,-4.000000e+001,2.980009e+002,-3.071395e-005,0.000000e+000,2.126909e-002,0.000000e+000,3,9.734866e-001,1.825000e+000,,,,,,,,,,,,,,,,,,0,4.000000e+000,5.000000e-001,5,1,8.209229e-003,0,,0,
1405560504.375,,-4.000000e+001,2.980009e+002,-3.070984e-005,0.000000e+000,2.094741e-002,0.000000e+000,3,9.734917e-001,1.825000e+000,,,,,,,,,,,,,,,,,,0,4.000000e+000,5.000000e-001,5,1,8.209229e-003,0,,0,
1405560616.875,,-4.500000e+001,2.979968e+002,-3.085607e-005,0.000000e+000,2.228050e-002,0.000000e+000,3,9.767990e-001,1.825000e+000,,,,,,,,,,,,,,,,,,0,4.000000e+000,5.000000e-001,5,1,0.000000e+000,0,,0,
1405560634.625,,-4.500000e+001,2.980009e+002,-3.087126e-005,0.000000e+000,2.259196e-002,0.000000e+000,3,9.765640e-001,1.825000e+000,,,,,,,,,,,,,,,,,,0,4.000000e+000,5.000000e-001,5,1,8.209229e-003,0,,0,
1405560652.859,,-4.500000e+001,2.980009e+002,-3.085483e-005,0.000000e+000,2.213102e-002,0.000000e+000,3,9.765521e-001,1.825000e+000,,,,,,,,,,,,,,,,,,0,4.000000e+000,5.000000e-001,5,1,8.209229e-003,0,,0,
1405560770.593,,-5.000000e+001,2.979968e+002,-3.102122e-005,0.000000e+000,2.500179e-002,0.000000e+000,3,9.797641e-001,1.825000e+000,,,,,,,,,,,,,,,,,,0,4.000000e+000,5.000000e-001,5,1,1.651001e-002,0,,0,
1405560788.578,,-5.000000e+001,2.979926e+002,-3.102410e-005,0.000000e+000,2.472768e-002,0.000000e+000,3,9.797315e-001,1.825000e+000,,,,,,,,,,,,,,,,,,0,4.000000e+000,5.000000e-001,5,1,8.300781e-003,0,,0,
1405560806.593,,-5.000000e+001,2.980009e+002,-3.104135e-005,0.000000e+000,2.474716e-002,0.000000e+000,3,9.799429e-001,1.825000e+000,,,,,,,,,,,,,,,,,,0,4.000000e+000,5.000000e-001,5,1,8.209229e-003,0,,0,
1405560947.828,,-7.500000e+001,2.979968e+002,-3.156920e-005,0.000000e+000,2.816151e-002,0.000000e+000,3,9.846572e-001,1.825000e+000,,,,,,,,,,,,,,,,,,0,4.000000e+000,5.000000e-001,5,1,0.000000e+000,0,,0,
1405560966.062,,-7.500000e+001,2.980009e+002,-3.158953e-005,0.000000e+000,2.812743e-002,0.000000e+000,3,9.844128e-001,1.825000e+000,,,,,,,,,,,,,,,,,,0,4.000000e+000,5.000000e-001,5,1,8.209229e-003,0,,0,
1405560983.296,,-7.500000e+001,2.979968e+002,-3.157218e-005,0.000000e+000,2.830588e-002,0.000000e+000,3,9.846355e-001,1.825000e+000,,,,,,,,,,,,,,,,,,0,4.000000e+000,5.000000e-001,5,1,0.000000e+000,0,,0,
1405561115.296,,-1.000000e+002,2.980050e+002,-3.199522e-005,0.000000e+000,2.920626e-002,0.000000e+000,3,9.768746e-001,1.825000e+000,,,,,,,,,,,,,,,,,,0,4.000000e+000,5.000000e-001,5,1,0.000000e+000,0,,0,
1405561133.546,,-1.000000e+002,2.980009e+002,-3.201958e-005,0.000000e+000,2.796044e-002,0.000000e+000,3,9.774333e-001,1.825000e+000,,,,,,,,,,,,,,,,,,0,4.000000e+000,5.000000e-001,5,1,8.209229e-003,0,,0,
1405561151.781,,-1.000000e+002,2.980050e+002,-3.204992e-005,0.000000e+000,2.856615e-002,0.000000e+000,3,9.775047e-001,1.825000e+000,,,,,,,,,,,,,,,,,,0,4.000000e+000,5.000000e-001,5,1,1.641846e-002,0,,0,
1405561277.562,,-7.500000e+001,2.980009e+002,-3.187271e-005,0.000000e+000,2.821690e-002,0.000000e+000,3,9.829735e-001,1.825000e+000,,,,,,,,,,,,,,,,,,0,4.000000e+000,5.000000e-001,5,1,8.209229e-003,0,,0,
1405561296.046,,-7.500000e+001,2.980009e+002,-3.189380e-005,0.000000e+000,2.839990e-002,0.000000e+000,3,9.824284e-001,1.825000e+000,,,,,,,,,,,,,,,,,,0,4.000000e+000,5.000000e-001,5,1,8.209229e-003,0,,0,
1405561313.781,,-7.500000e+001,2.980009e+002,-3.188014e-005,0.000000e+000,2.799982e-002,0.000000e+000,3,9.829733e-001,1.825000e+000,,,,,,,,,,,,,,,,,,0,4.000000e+000,5.000000e-001,5,1,8.209229e-003,0,,0,
1405561446.281,,-5.000000e+001,2.980050e+002,-3.163488e-005,0.000000e+000,2.758439e-002,0.000000e+000,3,9.841214e-001,1.825000e+000,,,,,,,,,,,,,,,,,,0,4.000000e+000,5.000000e-001,5,1,0.000000e+000,0,,0,
1405561464.515,,-5.000000e+001,2.979968e+002,-3.162182e-005,0.000000e+000,2.746939e-002,0.000000e+000,3,9.841800e-001,1.825000e+000,,,,,,,,,,,,,,,,,,0,4.000000e+000,5.000000e-001,5,1,0.000000e+000,0,,0,
1405561482.250,,-5.000000e+001,2.979968e+002,-3.162590e-005,0.000000e+000,2.750966e-002,0.000000e+000,3,9.841133e-001,1.825000e+000,,,,,,,,,,,,,,,,,,0,4.000000e+000,5.000000e-001,5,1,0.000000e+000,0,,0,
1405561601.500,,-4.500000e+001,2.979968e+002,-3.155016e-005,0.000000e+000,2.772850e-002,0.000000e+000,3,9.831982e-001,1.825000e+000,,,,,,,,,,,,,,,,,,0,4.000000e+000,5.000000e-001,5,1,0.000000e+000,0,,0,
1405561619.234,,-4.500000e+001,2.980009e+002,-3.154591e-005,0.000000e+000,2.806183e-002,0.000000e+000,3,9.830597e-001,1.825000e+000,,,,,,,,,,,,,,,,,,0,4.000000e+000,5.000000e-001,5,1,8.209229e-003,0,,0,
1405561637.250,,-4.500000e+001,2.980009e+002,-3.155252e-005,0.000000e+000,2.791506e-002,0.000000e+000,3,9.833872e-001,1.825000e+000,,,,,,,,,,,,,,,,,,0,4.000000e+000,5.000000e-001,5,1,8.209229e-003,0,,0,
1405561755.734,,-4.000000e+001,2.979968e+002,-3.148079e-005,0.000000e+000,2.806428e-002,0.000000e+000,3,9.823573e-001,1.825000e+000,,,,,,,,,,,,,,,,,,0,4.000000e+000,5.000000e-001,5,1,0.000000e+000,0,,0,
1405561773.734,,-4.000000e+001,2.980009e+002,-3.145901e-005,0.000000e+000,2.767775e-002,0.000000e+000,3,9.826433e-001,1.825000e+000,,,,,,,,,,,,,,,,,,0,4.000000e+000,5.000000e-001,5,1,8.209229e-003,0,,0,
1405561792.000,,-4.000000e+001,2.980009e+002,-3.146851e-005,0.000000e+000,2.777245e-002,0.000000e+000,3,9.823684e-001,1.825000e+000,,,,,,,,,,,,,,,,,,0,4.000000e+000,5.000000e-001,5,1,8.209229e-003,0,,0,
1405561910.484,,-3.500000e+001,2.980009e+002,-3.136820e-005,0.000000e+000,2.783344e-002,0.000000e+000,3,9.810017e-001,1.825000e+000,,,,,,,,,,,,,,,,,,0,4.000000e+000,5.000000e-001,5,1,8.209229e-003,0,,0,
1405561928.218,,-3.500000e+001,2.980009e+002,-3.138949e-005,0.000000e+000,2.769095e-002,0.000000e+000,3,9.812757e-001,1.825000e+000,,,,,,,,,,,,,,,,,,0,4.000000e+000,5.000000e-001,5,1,8.209229e-003,0,,0,
1405561945.953,,-3.500000e+001,2.979926e+002,-3.137268e-005,0.000000e+000,2.768956e-002,0.000000e+000,3,9.810296e-001,1.825000e+000,,,,,,,,,,,,,,,,,,0,4.000000e+000,5.000000e-001,5,1,8.300781e-003,0,,0,
1405562064.453,,-3.000000e+001,2.980009e+002,-3.128569e-005,0.000000e+000,2.762086e-002,0.000000e+000,3,9.798097e-001,1.825000e+000,,,,,,,,,,,,,,,,,,0,4.000000e+000,5.000000e-001,5,1,8.209229e-003,0,,0,
1405562081.937,,-3.000000e+001,2.979968e+002,-3.128745e-005,0.000000e+000,2.748760e-002,0.000000e+000,3,9.796028e-001,1.825000e+000,,,,,,,,,,,,,,,,,,0,4.000000e+000,5.000000e-001,5,1,0.000000e+000,0,,0,
1405562099.671,,-3.000000e+001,2.979968e+002,-3.128174e-005,0.000000e+000,2.764345e-002,0.000000e+000,3,9.795220e-001,1.825000e+000,,,,,,,,,,,,,,,,,,0,4.000000e+000,5.000000e-001,5,1,0.000000e+000,0,,0,
1405562217.906,,-2.500000e+001,2.979968e+002,-3.118316e-005,0.000000e+000,2.754437e-002,0.000000e+000,3,9.783086e-001,1.825000e+000,,,,,,,,,,,,,,,,,,0,4.000000e+000,5.000000e-001,5,1,0.000000e+000,0,,0,
1405562236.390,,-2.500000e+001,2.980050e+002,-3.117387e-005,0.000000e+000,2.785054e-002,0.000000e+000,3,9.777044e-001,1.825000e+000,,,,,,,,,,,,,,,,,,0,4.000000e+000,5.000000e-001,5,1,0.000000e+000,0,,0,
1405562254.375,,-2.500000e+001,2.979968e+002,-3.117682e-005,0.000000e+000,2.748949e-002,0.000000e+000,3,9.779636e-001,1.825000e+000,,,,,,,,,,,,,,,,,,0,4.000000e+000,5.000000e-001,5,1,0.000000e+000,0,,0,
1405562372.625,,-2.000000e+001,2.980009e+002,-3.104680e-005,0.000000e+000,2.693756e-002,0.000000e+000,3,9.760529e-001,1.825000e+000,,,,,,,,,,,,,,,,,,0,4.000000e+000,5.000000e-001,5,1,8.209229e-003,0,,0,
1405562389.859,,-2.000000e+001,2.980009e+002,-3.105509e-005,0.000000e+000,2.733186e-002,0.000000e+000,3,9.760831e-001,1.825000e+000,,,,,,,,,,,,,,,,,,0,4.000000e+000,5.000000e-001,5,1,8.209229e-003,0,,0,
1405562408.093,,-2.000000e+001,2.980050e+002,-3.104770e-005,0.000000e+000,2.732700e-002,0.000000e+000,3,9.761887e-001,1.825000e+000,,,,,,,,,,,,,,,,,,0,4.000000e+000,5.000000e-001,5,1,0.000000e+000,0,,0,
1405562527.093,,-1.500000e+001,2.980009e+002,-3.090859e-005,0.000000e+000,2.728204e-002,0.000000e+000,3,9.736080e-001,1.825000e+000,,,,,,,,,,,,,,,,,,0,4.000000e+000,5.000000e-001,5,1,8.209229e-003,0,,0,
1405562546.078,,-1.500000e+001,2.980009e+002,-3.090755e-005,0.000000e+000,2.728584e-002,0.000000e+000,3,9.738761e-001,1.825000e+000,,,,,,,,,,,,,,,,,,0,4.000000e+000,5.000000e-001,5,1,2.471924e-002,0,,0,
1405562564.562,,-1.500000e+001,2.980009e+002,-3.090405e-005,0.000000e+000,2.711842e-002,0.000000e+000,3,9.733946e-001,1.825000e+000,,,,,,,,,,,,,,,,,,0,4.000000e+000,5.000000e-001,5,1,8.209229e-003,0,,0,
1405562682.562,,-1.000000e+001,2.980009e+002,-3.075550e-005,0.000000e+000,2.729986e-002,0.000000e+000,3,9.713441e-001,1.825000e+000,,,,,,,,,,,,,,,,,,0,4.000000e+000,5.000000e-001,5,1,8.209229e-003,0,,0,
1405562700.046,,-1.000000e+001,2.980009e+002,-3.075132e-005,0.000000e+000,2.693674e-002,0.000000e+000,3,9.714633e-001,1.825000e+000,,,,,,,,,,,,,,,,,,0,4.000000e+000,5.000000e-001,5,1,8.209229e-003,0,,0,
1405562718.046,,-1.000000e+001,2.980009e+002,-3.075413e-005,0.000000e+000,2.715140e-002,0.000000e+000,3,9.714936e-001,1.825000e+000,,,,,,,,,,,,,,,,,,0,4.000000e+000,5.000000e-001,5,1,8.209229e-003,0,,0,
1405562836.031,,-5.000000e+000,2.980050e+002,-3.058385e-005,0.000000e+000,2.692100e-002,0.000000e+000,3,9.689914e-001,1.825000e+000,,,,,,,,,,,,,,,,,,0,4.000000e+000,5.000000e-001,5,1,0.000000e+000,0,,0,
1405562853.265,,-5.000000e+000,2.979968e+002,-3.057914e-005,0.000000e+000,2.671435e-002,0.000000e+000,3,9.688187e-001,1.825000e+000,,,,,,,,,,,,,,,,,,0,4.000000e+000,5.000000e-001,5,1,0.000000e+000,0,,0,
1405562871.250,,-5.000000e+000,2.979968e+002,-3.057003e-005,0.000000e+000,2.711367e-002,0.000000e+000,3,9.684762e-001,1.825000e+000,,,,,,,,,,,,,,,,,,0,4.000000e+000,5.000000e-001,5,1,0.000000e+000,0,,0,
1405562991.031,,0.000000e+000,2.979968e+002,-3.037639e-005,0.000000e+000,2.673564e-002,0.000000e+000,3,9.661506e-001,1.825000e+000,,,,,,,,,,,,,,,,,,0,4.000000e+000,5.000000e-001,5,1,0.000000e+000,0,,0,
1405563009.296,,0.000000e+000,2.979968e+002,-3.037336e-005,0.000000e+000,2.663859e-002,0.000000e+000,3,9.657311e-001,1.825000e+000,,,,,,,,,,,,,,,,,,0,4.000000e+000,5.000000e-001,5,1,0.000000e+000,0,,0,
1405563026.781,,0.000000e+000,2.979968e+002,-3.037790e-005,0.000000e+000,2.686083e-002,0.000000e+000,3,9.656923e-001,1.825000e+000,,,,,,,,,,,,,,,,,,0,4.000000e+000,5.000000e-001,5,1,0.000000e+000,0,,0,
1405563145.015,,5.000000e+000,2.980050e+002,-3.012141e-005,0.000000e+000,2.660840e-002,0.000000e+000,3,9.628367e-001,1.825000e+000,,,,,,,,,,,,,,,,,,0,4.000000e+000,5.000000e-001,5,1,0.000000e+000,0,,0,
1405563162.750,,5.000000e+000,2.979968e+002,-3.012706e-005,0.000000e+000,2.654332e-002,0.000000e+000,3,9.626287e-001,1.825000e+000,,,,,,,,,,,,,,,,,,0,4.000000e+000,5.000000e-001,5,1,0.000000e+000,0,,0,
1405563180.484,,5.000000e+000,2.979968e+002,-3.012778e-005,0.000000e+000,2.670249e-002,0.000000e+000,3,9.628662e-001,1.825000e+000,,,,,,,,,,,,,,,,,,0,4.000000e+000,5.000000e-001,5,1,0.000000e+000,0,,0,
1405563305.234,,1.000000e+001,2.979968e+002,-2.984355e-005,0.000000e+000,2.643851e-002,0.000000e+000,3,9.592807e-001,1.825000e+000,,,,,,,,,,,,,,,,,,0,4.000000e+000,5.000000e-001,5,1,0.000000e+000,0,,0,
1405563322.484,,1.000000e+001,2.980009e+002,-2.984567e-005,0.000000e+000,2.668943e-002,0.000000e+000,3,9.593426e-001,1.825000e+000,,,,,,,,,,,,,,,,,,0,4.000000e+000,5.000000e-001,5,1,8.209229e-003,0,,0,
1405563340.218,,1.000000e+001,2.980050e+002,-2.983875e-005,0.000000e+000,2.662679e-002,0.000000e+000,3,9.592368e-001,1.825000e+000,,,,,,,,,,,,,,,,,,0,4.000000e+000,5.000000e-001,5,1,0.000000e+000,0,,0,
1405563452.953,,1.500000e+001,2.980009e+002,-2.949854e-005,0.000000e+000,2.671708e-002,0.000000e+000,3,9.554073e-001,1.825000e+000,,,,,,,,,,,,,,,,,,0,4.000000e+000,5.000000e-001,5,1,8.209229e-003,0,,0,
1405563471.187,,1.500000e+001,2.979968e+002,-2.950529e-005,0.000000e+000,2.637443e-002,0.000000e+000,3,9.557450e-001,1.825000e+000,,,,,,,,,,,,,,,,,,0,4.000000e+000,5.000000e-001,5,1,0.000000e+000,0,,0,
1405563488.984,,1.500000e+001,2.979968e+002,-2.949116e-005,0.000000e+000,2.665887e-002,0.000000e+000,3,9.554517e-001,1.825000e+000,,,,,,,,,,,,,,,,,,0,4.000000e+000,5.000000e-001,5,1,0.000000e+000,0,,0,
1405563607.031,,2.000000e+001,2.980050e+002,-2.902649e-005,0.000000e+000,2.574759e-002,0.000000e+000,3,9.512940e-001,1.825000e+000,,,,,,,,,,,,,,,,,,0,4.000000e+000,5.000000e-001,5,1,0.000000e+000,0,,0,
1405563625.015,,2.000000e+001,2.980009e+002,-2.902268e-005,0.000000e+000,2.557028e-002,0.000000e+000,3,9.511174e-001,1.825000e+000,,,,,,,,,,,,,,,,,,0,4.000000e+000,5.000000e-001,5,1,8.209229e-003,0,,0,
1405563642.250,,2.000000e+001,2.980009e+002,-2.901232e-005,0.000000e+000,2.557926e-002,0.000000e+000,3,9.514651e-001,1.825000e+000,,,,,,,,,,,,,,,,,,0,4.000000e+000,5.000000e-001,5,1,8.209229e-003,0,,0,
1405563759.484,,2.500000e+001,2.980050e+002,-2.817202e-005,0.000000e+000,2.580428e-002,0.000000e+000,3,9.456148e-001,1.825000e+000,,,,,,,,,,,,,,,,,,0,4.000000e+000,5.000000e-001,5,1,0.000000e+000,0,,0,
1405563776.718,,2.500000e+001,2.980050e+002,-2.814771e-005,0.000000e+000,2.566941e-002,0.000000e+000,3,9.452782e-001,1.825000e+000,,,,,,,,,,,,,,,,,,0,4.000000e+000,5.000000e-001,5,1,0.000000e+000,0,,0,
1405563794.453,,2.500000e+001,2.980050e+002,-2.813398e-005,0.000000e+000,2.552151e-002,0.000000e+000,3,9.454584e-001,1.825000e+000,,,,,,,,,,,,,,,,,,0,4.000000e+000,5.000000e-001,5,1,0.000000e+000,0,,0,
1405563913.015,,3.000000e+001,2.980009e+002,-2.441792e-005,0.000000e+000,3.886907e-002,0.000000e+000,3,9.355118e-001,1.825000e+000,,,,,,,,,,,,,,,,,,0,4.000000e+000,5.000000e-001,5,1,8.209229e-003,0,,0,
1405563931.250,,3.000000e+001,2.980009e+002,-2.404982e-005,0.000000e+000,4.059039e-002,0.000000e+000,3,9.344380e-001,1.825000e+000,,,,,,,,,,,,,,,,,,0,4.000000e+000,5.000000e-001,5,1,8.209229e-003,0,,0,
1405563948.546,,3.000000e+001,2.979968e+002,-2.372222e-005,0.000000e+000,4.163240e-002,0.000000e+000,3,9.336801e-001,1.825000e+000,,,,,,,,,,,,,,,,,,0,4.000000e+000,5.000000e-001,5,1,0.000000e+000,0,,0,
1405564078.015,,3.500000e+001,2.980009e+002,6.945513e-006,0.000000e+000,-4.123357e-001,0.000000e+000,3,7.878174e-001,1.825000e+000,,,,,,,,,,,,,,,,,,0,4.000000e+000,5.000000e-001,5,1,8.209229e-003,0,,0,
1405564095.296,,3.500000e+001,2.980050e+002,8.557165e-006,0.000000e+000,-3.167460e-001,0.000000e+000,3,8.166581e-001,1.825000e+000,,,,,,,,,,,,,,,,,,0,4.000000e+000,5.000000e-001,5,1,1.641846e-002,0,,0,
1405564113.031,,3.500000e+001,2.980009e+002,1.004945e-005,0.000000e+000,-2.611060e-001,0.000000e+000,3,8.371048e-001,1.825000e+000,,,,,,,,,,,,,,,,,,0,4.000000e+000,5.000000e-001,5,1,8.209229e-003,0,,0,
1405564232.812,,4.000000e+001,2.979926e+002,2.836243e-005,0.000000e+000,-6.203176e-002,0.000000e+000,3,9.230514e-001,1.825000e+000,,,,,,,,,,,,,,,,,,0,4.000000e+000,5.000000e-001,5,1,8.300781e-003,0,,0,
1405564251.109,,4.000000e+001,2.979968e+002,2.893390e-005,0.000000e+000,-5.917050e-002,0.000000e+000,3,9.239455e-001,1.825000e+000,,,,,,,,,,,,,,,,,,0,4.000000e+000,5.000000e-001,5,1,0.000000e+000,0,,0,
1405564268.875,,4.000000e+001,2.979968e+002,2.935031e-005,0.000000e+000,-5.751713e-002,0.000000e+000,3,9.248395e-001,1.825000e+000,,,,,,,,,,,,,,,,,,0,4.000000e+000,5.000000e-001,5,1,0.000000e+000,0,,0,
1405564380.359,,4.500000e+001,2.979968e+002,3.235421e-005,0.000000e+000,-3.463502e-002,0.000000e+000,3,9.241634e-001,1.825000e+000,,,,,,,,,,,,,,,,,,0,4.000000e+000,5.000000e-001,5,1,0.000000e+000,0,,0,
1405564398.843,,4.500000e+001,2.979926e+002,3.249129e-005,0.000000e+000,-3.347337e-002,0.000000e+000,3,9.245041e-001,1.825000e+000,,,,,,,,,,,,,,,,,,0,4.000000e+000,5.000000e-001,5,1,8.300781e-003,0,,0,
1405564417.578,,4.500000e+001,2.979968e+002,3.261845e-005,0.000000e+000,-3.272716e-002,0.000000e+000,3,9.244251e-001,1.825000e+000,,,,,,,,,,,,,,,,,,0,4.000000e+000,5.000000e-001,5,1,0.000000e+000,0,,0,
1405564536.578,,5.000000e+001,2.980009e+002,3.417322e-005,0.000000e+000,-1.919194e-002,0.000000e+000,3,9.220749e-001,1.825000e+000,,,,,,,,,,,,,,,,,,0,4.000000e+000,5.000000e-001,5,1,8.209229e-003,0,,0,
1405564554.562,,5.000000e+001,2.979926e+002,3.430677e-005,0.000000e+000,-1.839121e-002,0.000000e+000,3,9.224089e-001,1.825000e+000,,,,,,,,,,,,,,,,,,0,4.000000e+000,5.000000e-001,5,1,8.300781e-003,0,,0,
1405564572.796,,5.000000e+001,2.979926e+002,3.443343e-005,0.000000e+000,-1.700319e-002,0.000000e+000,3,9.224560e-001,1.825000e+000,,,,,,,,,,,,,,,,,,0,4.000000e+000,5.000000e-001,5,1,8.300781e-003,0,,0,
1405564714.296,,7.500000e+001,2.980009e+002,3.706442e-005,0.000000e+000,3.021472e-003,0.000000e+000,3,9.094063e-001,1.825000e+000,,,,,,,,,,,,,,,,,,0,4.000000e+000,5.000000e-001,5,1,8.209229e-003,0,,0,
1405564732.546,,7.500000e+001,2.980009e+002,3.706828e-005,0.000000e+000,3.130556e-003,0.000000e+000,3,9.092450e-001,1.825000e+000,,,,,,,,,,,,,,,,,,0,4.000000e+000,5.000000e-001,5,1,8.209229e-003,0,,0,
1405564749.312,,7.500000e+001,2.979968e+002,3.706873e-005,0.000000e+000,3.166578e-003,0.000000e+000,3,9.091861e-001,1.825000e+000,,,,,,,,,,,,,,,,,,0,4.000000e+000,5.000000e-001,5,1,0.000000e+000,0,,0,
1405564880.578,,1.000000e+002,2.980050e+002,3.775581e-005,0.000000e+000,6.727516e-003,0.000000e+000,3,8.961686e-001,1.825000e+000,,,,,,,,,,,,,,,,,,0,4.000000e+000,5.000000e-001,5,1,0.000000e+000,0,,0,
1405564898.843,,1.000000e+002,2.979968e+002,3.775877e-005,0.000000e+000,6.513356e-003,0.000000e+000,3,8.958150e-001,1.825000e+000,,,,,,,,,,,,,,,,,,0,4.000000e+000,5.000000e-001,5,1,0.000000e+000,0,,0,
1405564917.125,,1.000000e+002,2.979926e+002,3.775169e-005,0.000000e+000,6.486765e-003,0.000000e+000,3,8.959512e-001,1.825000e+000,,,,,,,,,,,,,,,,,,0,4.000000e+000,5.000000e-001,5,1,8.300781e-003,0,,0,