File: Sample Data Files/2014-07-16 EB on isolated PMN-PT no Ti spontaneous in situ/Ni-NiO_298K_SiO2_PMN-PT_5.0Tprebias_050V_Au_back.rso.dat
[Header]
TITLE,MPMS RSO Measurement
BYAPP,MPMS Measurement,1.1,Summary
FILEOPENTIME, 1405592468.125000 7/17/2014, 3:21:08 AM

INFO, APPNAME, MPMS MultiVu Application, Revision 1.58,  Build 076

INFO, NAME, EB in situ
INFO, WEIGHT, 0.000
INFO, AREA, 0.000
INFO, LENGTH, 0.000
INFO, SHAPE, 0
INFO, COMMENT,
INFO, SEQUENCE FILE: MHcurveUpTo100.seq


INFO, BACKGROUND DATA FILE:, None


STARTUPAXIS,X,4,LINEAR,AUTO,0.000000,0.000000
STARTUPAXIS,Y1,5,LINEAR,AUTO,0.000000,0.000000


STARTUPGROUP,Longitudinal
FIELDGROUP,Longitudinal,1,2,3,4,5,6,7,8,9,10,11,19,20,21,22,23,35
FIELDGROUP,Transverse,1,2,3,4,12,13,14,15,16,17,18,24,25,26,27,28,35

PLOT_APPEARANCE,ALL,HORZ_GRID_ON,VERT_GRID_ON,MARKERS_AND_LINES

[Data]
Time,Comment,Field (Oe),Temperature (K),Long Moment (emu),Long Scan Std Dev,Long Offset (cm),Long Offset Std Dev,Long Algorithm,Long Reg Fit,Long Reg Factor,Trans Moment (emu),Trans Scan Std Dev,Trans Offset (cm),Trans Offset Std Dev,Trans Algorithm,Trans Reg Fit,Trans Reg Factor,Long Moment [w/o ABS] (emu),Long Scan Std Dev [w/o ABS],Long Offset [w/o ABS] (cm),Long Offset Std Dev [w/o ABS],Long Reg Fit [w/o ABS],Trans Moment [w/o ABS] (emu),Trans Scan Std Dev [w/o ABS],Trans Offset [w/o ABS] (cm),Trans Offset Std Dev [w/o ABS],Trans Reg Fit [w/o ABS],RSO Position (deg),Amplitude (cm),Frequency,Cycles to Average,Scans per Measurement,Delta Temp (K),Error,EC Comp. Running,Using ABS,
1405592468.125,,1.000000e+002,2.980050e+002,3.705458e-005,0.000000e+000,1.575544e-003,0.000000e+000,3,8.936553e-001,1.825000e+000,,,,,,,,,,,,,,,,,,0,4.000000e+000,5.000000e-001,5,1,0.000000e+000,0,,0,
1405592486.375,,1.000000e+002,2.980009e+002,3.704800e-005,0.000000e+000,1.796321e-003,0.000000e+000,3,8.935068e-001,1.825000e+000,,,,,,,,,,,,,,,,,,0,4.000000e+000,5.000000e-001,5,1,8.209229e-003,0,,0,
1405592503.640,,1.000000e+002,2.980009e+002,3.705719e-005,0.000000e+000,1.656859e-003,0.000000e+000,3,8.938633e-001,1.825000e+000,,,,,,,,,,,,,,,,,,0,4.000000e+000,5.000000e-001,5,1,8.209229e-003,0,,0,
1405592627.968,,7.500000e+001,2.980050e+002,3.648044e-005,0.000000e+000,2.024875e-003,0.000000e+000,3,9.009512e-001,1.825000e+000,,,,,,,,,,,,,,,,,,0,4.000000e+000,5.000000e-001,5,1,0.000000e+000,0,,0,
1405592645.218,,7.500000e+001,2.979968e+002,3.649361e-005,0.000000e+000,2.104108e-003,0.000000e+000,3,9.012445e-001,1.825000e+000,,,,,,,,,,,,,,,,,,0,4.000000e+000,5.000000e-001,5,1,0.000000e+000,0,,0,
1405592662.953,,7.500000e+001,2.979968e+002,3.648553e-005,0.000000e+000,2.158868e-003,0.000000e+000,3,9.011899e-001,1.825000e+000,,,,,,,,,,,,,,,,,,0,4.000000e+000,5.000000e-001,5,1,0.000000e+000,0,,0,
1405592793.984,,5.000000e+001,2.979968e+002,3.543742e-005,0.000000e+000,3.129148e-003,0.000000e+000,3,9.087493e-001,1.825000e+000,,,,,,,,,,,,,,,,,,0,4.000000e+000,5.000000e-001,5,1,0.000000e+000,0,,0,
1405592812.718,,5.000000e+001,2.980009e+002,3.542610e-005,0.000000e+000,3.261071e-003,0.000000e+000,3,9.088025e-001,1.825000e+000,,,,,,,,,,,,,,,,,,0,4.000000e+000,5.000000e-001,5,1,8.209229e-003,0,,0,
1405592830.953,,5.000000e+001,2.980009e+002,3.542161e-005,0.000000e+000,3.116984e-003,0.000000e+000,3,9.085969e-001,1.825000e+000,,,,,,,,,,,,,,,,,,0,4.000000e+000,5.000000e-001,5,1,8.209229e-003,0,,0,
1405592949.218,,4.500000e+001,2.980009e+002,3.511803e-005,0.000000e+000,3.468603e-003,0.000000e+000,3,9.103889e-001,1.825000e+000,,,,,,,,,,,,,,,,,,0,4.000000e+000,5.000000e-001,5,1,8.209229e-003,0,,0,
1405592967.453,,4.500000e+001,2.980009e+002,3.511693e-005,0.000000e+000,3.569282e-003,0.000000e+000,3,9.102688e-001,1.825000e+000,,,,,,,,,,,,,,,,,,0,4.000000e+000,5.000000e-001,5,1,8.209229e-003,0,,0,
1405592984.953,,4.500000e+001,2.979968e+002,3.510090e-005,0.000000e+000,3.645672e-003,0.000000e+000,3,9.103149e-001,1.825000e+000,,,,,,,,,,,,,,,,,,0,4.000000e+000,5.000000e-001,5,1,0.000000e+000,0,,0,
1405593103.781,,4.000000e+001,2.979968e+002,3.474523e-005,0.000000e+000,4.309334e-003,0.000000e+000,3,9.119319e-001,1.825000e+000,,,,,,,,,,,,,,,,,,0,4.000000e+000,5.000000e-001,5,1,0.000000e+000,0,,0,
1405593121.546,,4.000000e+001,2.980009e+002,3.473878e-005,0.000000e+000,4.249964e-003,0.000000e+000,3,9.116288e-001,1.825000e+000,,,,,,,,,,,,,,,,,,0,4.000000e+000,5.000000e-001,5,1,8.209229e-003,0,,0,
1405593139.343,,4.000000e+001,2.979968e+002,3.475016e-005,0.000000e+000,3.922133e-003,0.000000e+000,3,9.115518e-001,1.825000e+000,,,,,,,,,,,,,,,,,,0,4.000000e+000,5.000000e-001,5,1,1.651001e-002,0,,0,
1405593257.984,,3.500000e+001,2.979968e+002,3.431907e-005,0.000000e+000,4.656719e-003,0.000000e+000,3,9.131625e-001,1.825000e+000,,,,,,,,,,,,,,,,,,0,4.000000e+000,5.000000e-001,5,1,0.000000e+000,0,,0,
1405593275.968,,3.500000e+001,2.979968e+002,3.431324e-005,0.000000e+000,4.668874e-003,0.000000e+000,3,9.130682e-001,1.825000e+000,,,,,,,,,,,,,,,,,,0,4.000000e+000,5.000000e-001,5,1,0.000000e+000,0,,0,
1405593294.203,,3.500000e+001,2.979968e+002,3.431272e-005,0.000000e+000,4.530566e-003,0.000000e+000,3,9.130847e-001,1.825000e+000,,,,,,,,,,,,,,,,,,0,4.000000e+000,5.000000e-001,5,1,0.000000e+000,0,,0,
1405593413.437,,3.000000e+001,2.980009e+002,3.383882e-005,0.000000e+000,5.670642e-003,0.000000e+000,3,9.144282e-001,1.825000e+000,,,,,,,,,,,,,,,,,,0,4.000000e+000,5.000000e-001,5,1,8.209229e-003,0,,0,
1405593430.828,,3.000000e+001,2.980009e+002,3.381708e-005,0.000000e+000,5.703924e-003,0.000000e+000,3,9.146547e-001,1.825000e+000,,,,,,,,,,,,,,,,,,0,4.000000e+000,5.000000e-001,5,1,8.209229e-003,0,,0,
1405593449.484,,3.000000e+001,2.980009e+002,3.382386e-005,0.000000e+000,5.483828e-003,0.000000e+000,3,9.146142e-001,1.825000e+000,,,,,,,,,,,,,,,,,,0,4.000000e+000,5.000000e-001,5,1,8.209229e-003,0,,0,
1405593568.546,,2.500000e+001,2.979926e+002,3.321202e-005,0.000000e+000,6.519827e-003,0.000000e+000,3,9.158608e-001,1.825000e+000,,,,,,,,,,,,,,,,,,0,4.000000e+000,5.000000e-001,5,1,8.300781e-003,0,,0,
1405593587.437,,2.500000e+001,2.979968e+002,3.320325e-005,0.000000e+000,6.510291e-003,0.000000e+000,3,9.162785e-001,1.825000e+000,,,,,,,,,,,,,,,,,,0,4.000000e+000,5.000000e-001,5,1,0.000000e+000,0,,0,
1405593605.171,,2.500000e+001,2.979968e+002,3.320406e-005,0.000000e+000,6.750389e-003,0.000000e+000,3,9.158766e-001,1.825000e+000,,,,,,,,,,,,,,,,,,0,4.000000e+000,5.000000e-001,5,1,0.000000e+000,0,,0,
1405593723.281,,2.000000e+001,2.979968e+002,3.244371e-005,0.000000e+000,8.044517e-003,0.000000e+000,3,9.170148e-001,1.825000e+000,,,,,,,,,,,,,,,,,,0,4.000000e+000,5.000000e-001,5,1,0.000000e+000,0,,0,
1405593741.015,,2.000000e+001,2.979926e+002,3.243102e-005,0.000000e+000,8.205623e-003,0.000000e+000,3,9.170666e-001,1.825000e+000,,,,,,,,,,,,,,,,,,0,4.000000e+000,5.000000e-001,5,1,8.300781e-003,0,,0,
1405593758.796,,2.000000e+001,2.980009e+002,3.243152e-005,0.000000e+000,8.171708e-003,0.000000e+000,3,9.169509e-001,1.825000e+000,,,,,,,,,,,,,,,,,,0,4.000000e+000,5.000000e-001,5,1,8.209229e-003,0,,0,
1405593877.546,,1.500000e+001,2.979926e+002,3.144083e-005,0.000000e+000,1.041991e-002,0.000000e+000,3,9.176586e-001,1.825000e+000,,,,,,,,,,,,,,,,,,0,4.000000e+000,5.000000e-001,5,1,8.300781e-003,0,,0,
1405593895.781,,1.500000e+001,2.979926e+002,3.142687e-005,0.000000e+000,9.949780e-003,0.000000e+000,3,9.181145e-001,1.825000e+000,,,,,,,,,,,,,,,,,,0,4.000000e+000,5.000000e-001,5,1,8.300781e-003,0,,0,
1405593914.015,,1.500000e+001,2.979968e+002,3.141961e-005,0.000000e+000,1.011157e-002,0.000000e+000,3,9.179258e-001,1.825000e+000,,,,,,,,,,,,,,,,,,0,4.000000e+000,5.000000e-001,5,1,0.000000e+000,0,,0,
1405594033.250,,1.000000e+001,2.980009e+002,3.010569e-005,0.000000e+000,1.308067e-002,0.000000e+000,3,9.180305e-001,1.825000e+000,,,,,,,,,,,,,,,,,,0,4.000000e+000,5.000000e-001,5,1,8.209229e-003,0,,0,
1405594050.500,,1.000000e+001,2.979968e+002,3.007248e-005,0.000000e+000,1.321668e-002,0.000000e+000,3,9.177334e-001,1.825000e+000,,,,,,,,,,,,,,,,,,0,4.000000e+000,5.000000e-001,5,1,0.000000e+000,0,,0,
1405594068.734,,1.000000e+001,2.979968e+002,3.004349e-005,0.000000e+000,1.355882e-002,0.000000e+000,3,9.178553e-001,1.825000e+000,,,,,,,,,,,,,,,,,,0,4.000000e+000,5.000000e-001,5,1,0.000000e+000,0,,0,
1405594187.484,,5.000000e+000,2.979968e+002,2.786624e-005,0.000000e+000,1.956736e-002,0.000000e+000,3,9.166624e-001,1.825000e+000,,,,,,,,,,,,,,,,,,0,4.000000e+000,5.000000e-001,5,1,0.000000e+000,0,,0,
1405594204.750,,5.000000e+000,2.979968e+002,2.779737e-005,0.000000e+000,1.962053e-002,0.000000e+000,3,9.166075e-001,1.825000e+000,,,,,,,,,,,,,,,,,,0,4.000000e+000,5.000000e-001,5,1,0.000000e+000,0,,0,
1405594222.484,,5.000000e+000,2.979968e+002,2.771617e-005,0.000000e+000,2.002261e-002,0.000000e+000,3,9.163614e-001,1.825000e+000,,,,,,,,,,,,,,,,,,0,4.000000e+000,5.000000e-001,5,1,0.000000e+000,0,,0,
1405594343.968,,0.000000e+000,2.979968e+002,2.092440e-005,0.000000e+000,5.365155e-002,0.000000e+000,3,8.996797e-001,1.825000e+000,,,,,,,,,,,,,,,,,,0,4.000000e+000,5.000000e-001,5,1,0.000000e+000,0,,0,
1405594362.453,,0.000000e+000,2.980009e+002,2.033335e-005,0.000000e+000,5.810926e-002,0.000000e+000,3,8.972257e-001,1.825000e+000,,,,,,,,,,,,,,,,,,0,4.000000e+000,5.000000e-001,5,1,8.209229e-003,0,,0,
1405594380.703,,0.000000e+000,2.980091e+002,1.983502e-005,0.000000e+000,6.180882e-002,0.000000e+000,3,8.954253e-001,1.825000e+000,,,,,,,,,,,,,,,,,,0,4.000000e+000,5.000000e-001,5,1,8.209229e-003,0,,0,
1405594516.234,,-5.000000e+000,2.979968e+002,-3.760775e-006,0.000000e+000,-4.258688e-001,0.000000e+000,3,4.227081e-001,1.825000e+000,,,,,,,,,,,,,,,,,,0,4.000000e+000,5.000000e-001,5,1,0.000000e+000,0,,0,
1405594534.468,,-5.000000e+000,2.979968e+002,-4.499951e-006,0.000000e+000,-3.353571e-001,0.000000e+000,3,5.331523e-001,1.825000e+000,,,,,,,,,,,,,,,,,,0,4.000000e+000,5.000000e-001,5,1,0.000000e+000,0,,0,
1405594552.203,,-5.000000e+000,2.979968e+002,-5.113317e-006,0.000000e+000,-2.862276e-001,0.000000e+000,3,5.978806e-001,1.825000e+000,,,,,,,,,,,,,,,,,,0,4.000000e+000,5.000000e-001,5,1,0.000000e+000,0,,0,
1405594676.703,,-1.000000e+001,2.979968e+002,-1.738731e-005,0.000000e+000,-6.200762e-002,0.000000e+000,3,9.043640e-001,1.825000e+000,,,,,,,,,,,,,,,,,,0,4.000000e+000,5.000000e-001,5,1,1.651001e-002,0,,0,
1405594694.937,,-1.000000e+001,2.979968e+002,-1.805977e-005,0.000000e+000,-5.879411e-002,0.000000e+000,3,9.084554e-001,1.825000e+000,,,,,,,,,,,,,,,,,,0,4.000000e+000,5.000000e-001,5,1,0.000000e+000,0,,0,
1405594713.171,,-1.000000e+001,2.980050e+002,-1.856278e-005,0.000000e+000,-5.670949e-002,0.000000e+000,3,9.115291e-001,1.825000e+000,,,,,,,,,,,,,,,,,,0,4.000000e+000,5.000000e-001,5,1,0.000000e+000,0,,0,
1405594827.343,,-1.500000e+001,2.979968e+002,-2.308624e-005,0.000000e+000,-2.674579e-002,0.000000e+000,3,9.384584e-001,1.825000e+000,,,,,,,,,,,,,,,,,,0,4.000000e+000,5.000000e-001,5,1,0.000000e+000,0,,0,
1405594845.093,,-1.500000e+001,2.980009e+002,-2.327906e-005,0.000000e+000,-2.536104e-002,0.000000e+000,3,9.391878e-001,1.825000e+000,,,,,,,,,,,,,,,,,,0,4.000000e+000,5.000000e-001,5,1,8.209229e-003,0,,0,
1405594863.359,,-1.500000e+001,2.980009e+002,-2.342667e-005,0.000000e+000,-2.400134e-002,0.000000e+000,3,9.400657e-001,1.825000e+000,,,,,,,,,,,,,,,,,,0,4.000000e+000,5.000000e-001,5,1,8.209229e-003,0,,0,
1405594980.109,,-2.000000e+001,2.979926e+002,-2.525655e-005,0.000000e+000,-9.968360e-003,0.000000e+000,3,9.514924e-001,1.825000e+000,,,,,,,,,,,,,,,,,,0,4.000000e+000,5.000000e-001,5,1,8.300781e-003,0,,0,
1405594997.843,,-2.000000e+001,2.979926e+002,-2.539410e-005,0.000000e+000,-8.652819e-003,0.000000e+000,3,9.519057e-001,1.825000e+000,,,,,,,,,,,,,,,,,,0,4.000000e+000,5.000000e-001,5,1,8.300781e-003,0,,0,
1405595015.578,,-2.000000e+001,2.980009e+002,-2.550792e-005,0.000000e+000,-7.944502e-003,0.000000e+000,3,9.517596e-001,1.825000e+000,,,,,,,,,,,,,,,,,,0,4.000000e+000,5.000000e-001,5,1,8.209229e-003,0,,0,
1405595134.328,,-2.500000e+001,2.979968e+002,-2.743218e-005,0.000000e+000,5.018932e-003,0.000000e+000,3,9.602050e-001,1.825000e+000,,,,,,,,,,,,,,,,,,0,4.000000e+000,5.000000e-001,5,1,0.000000e+000,0,,0,
1405595153.062,,-2.500000e+001,2.980009e+002,-2.762833e-005,0.000000e+000,5.986873e-003,0.000000e+000,3,9.602885e-001,1.825000e+000,,,,,,,,,,,,,,,,,,0,4.000000e+000,5.000000e-001,5,1,8.209229e-003,0,,0,
1405595171.296,,-2.500000e+001,2.980050e+002,-2.778147e-005,0.000000e+000,7.377511e-003,0.000000e+000,3,9.608162e-001,1.825000e+000,,,,,,,,,,,,,,,,,,0,4.000000e+000,5.000000e-001,5,1,0.000000e+000,0,,0,
1405595290.031,,-3.000000e+001,2.979968e+002,-2.887180e-005,0.000000e+000,1.489175e-002,0.000000e+000,3,9.667083e-001,1.825000e+000,,,,,,,,,,,,,,,,,,0,4.000000e+000,5.000000e-001,5,1,0.000000e+000,0,,0,
1405595307.765,,-3.000000e+001,2.980009e+002,-2.887722e-005,0.000000e+000,1.501502e-002,0.000000e+000,3,9.666600e-001,1.825000e+000,,,,,,,,,,,,,,,,,,0,4.000000e+000,5.000000e-001,5,1,8.209229e-003,0,,0,
1405595325.515,,-3.000000e+001,2.979968e+002,-2.888655e-005,0.000000e+000,1.489658e-002,0.000000e+000,3,9.667912e-001,1.825000e+000,,,,,,,,,,,,,,,,,,0,4.000000e+000,5.000000e-001,5,1,0.000000e+000,0,,0,
1405595443.781,,-3.500000e+001,2.980050e+002,-2.922024e-005,0.000000e+000,1.626189e-002,0.000000e+000,3,9.704713e-001,1.825000e+000,,,,,,,,,,,,,,,,,,0,4.000000e+000,5.000000e-001,5,1,0.000000e+000,0,,0,
1405595461.078,,-3.500000e+001,2.980050e+002,-2.921481e-005,0.000000e+000,1.592816e-002,0.000000e+000,3,9.703788e-001,1.825000e+000,,,,,,,,,,,,,,,,,,0,4.000000e+000,5.000000e-001,5,1,0.000000e+000,0,,0,
1405595478.328,,-3.500000e+001,2.979968e+002,-2.922725e-005,0.000000e+000,1.605571e-002,0.000000e+000,3,9.703925e-001,1.825000e+000,,,,,,,,,,,,,,,,,,0,4.000000e+000,5.000000e-001,5,1,0.000000e+000,0,,0,
1405595596.578,,-4.000000e+001,2.979968e+002,-2.953089e-005,0.000000e+000,1.799549e-002,0.000000e+000,3,9.743416e-001,1.825000e+000,,,,,,,,,,,,,,,,,,0,4.000000e+000,5.000000e-001,5,1,0.000000e+000,0,,0,
1405595614.812,,-4.000000e+001,2.979968e+002,-2.955092e-005,0.000000e+000,1.798886e-002,0.000000e+000,3,9.742668e-001,1.825000e+000,,,,,,,,,,,,,,,,,,0,4.000000e+000,5.000000e-001,5,1,0.000000e+000,0,,0,
1405595633.046,,-4.000000e+001,2.979968e+002,-2.954396e-005,0.000000e+000,1.813914e-002,0.000000e+000,3,9.742627e-001,1.825000e+000,,,,,,,,,,,,,,,,,,0,4.000000e+000,5.000000e-001,5,1,0.000000e+000,0,,0,
1405595745.296,,-4.500000e+001,2.980091e+002,-2.983370e-005,0.000000e+000,2.042702e-002,0.000000e+000,3,9.777602e-001,1.825000e+000,,,,,,,,,,,,,,,,,,0,4.000000e+000,5.000000e-001,5,1,8.209229e-003,0,,0,
1405595763.781,,-4.500000e+001,2.980050e+002,-2.984265e-005,0.000000e+000,2.061654e-002,0.000000e+000,3,9.780617e-001,1.825000e+000,,,,,,,,,,,,,,,,,,0,4.000000e+000,5.000000e-001,5,1,0.000000e+000,0,,0,
1405595782.015,,-4.500000e+001,2.980050e+002,-2.984062e-005,0.000000e+000,2.062241e-002,0.000000e+000,3,9.780384e-001,1.825000e+000,,,,,,,,,,,,,,,,,,0,4.000000e+000,5.000000e-001,5,1,0.000000e+000,0,,0,
1405595901.500,,-5.000000e+001,2.980091e+002,-3.010403e-005,0.000000e+000,2.246418e-002,0.000000e+000,3,9.804643e-001,1.825000e+000,,,,,,,,,,,,,,,,,,0,4.000000e+000,5.000000e-001,5,1,8.209229e-003,0,,0,
1405595919.234,,-5.000000e+001,2.979926e+002,-3.009800e-005,0.000000e+000,2.239214e-002,0.000000e+000,3,9.806553e-001,1.825000e+000,,,,,,,,,,,,,,,,,,0,4.000000e+000,5.000000e-001,5,1,8.300781e-003,0,,0,
1405595937.468,,-5.000000e+001,2.980009e+002,-3.010162e-005,0.000000e+000,2.242653e-002,0.000000e+000,3,9.804457e-001,1.825000e+000,,,,,,,,,,,,,,,,,,0,4.000000e+000,5.000000e-001,5,1,8.209229e-003,0,,0,
1405596063.781,,-7.500000e+001,2.979968e+002,-3.098350e-005,0.000000e+000,2.583344e-002,0.000000e+000,3,9.826926e-001,1.825000e+000,,,,,,,,,,,,,,,,,,0,4.000000e+000,5.000000e-001,5,1,0.000000e+000,0,,0,
1405596082.015,,-7.500000e+001,2.979968e+002,-3.098904e-005,0.000000e+000,2.521871e-002,0.000000e+000,3,9.828571e-001,1.825000e+000,,,,,,,,,,,,,,,,,,0,4.000000e+000,5.000000e-001,5,1,0.000000e+000,0,,0,
1405596117.250,,-7.500000e+001,2.980009e+002,-3.100133e-005,0.000000e+000,2.516950e-002,0.000000e+000,3,9.830225e-001,1.825000e+000,,,,,,,,,,,,,,,,,,0,4.000000e+000,5.000000e-001,5,1,8.209229e-003,0,,0,
1405596242.484,,-1.000000e+002,2.979968e+002,-3.163708e-005,0.000000e+000,2.539182e-002,0.000000e+000,3,9.743016e-001,1.825000e+000,,,,,,,,,,,,,,,,,,0,4.000000e+000,5.000000e-001,5,1,0.000000e+000,0,,0,
1405596259.734,,-1.000000e+002,2.980009e+002,-3.153072e-005,0.000000e+000,2.541723e-002,0.000000e+000,3,9.738007e-001,1.825000e+000,,,,,,,,,,,,,,,,,,0,4.000000e+000,5.000000e-001,5,1,8.209229e-003,0,,0,
1405596277.468,,-1.000000e+002,2.980009e+002,-3.158324e-005,0.000000e+000,2.609622e-002,0.000000e+000,3,9.727593e-001,1.825000e+000,,,,,,,,,,,,,,,,,,0,4.000000e+000,5.000000e-001,5,1,8.209229e-003,0,,0,
1405596403.703,,-7.500000e+001,2.980009e+002,-3.127650e-005,0.000000e+000,2.516108e-002,0.000000e+000,3,9.813102e-001,1.825000e+000,,,,,,,,,,,,,,,,,,0,4.000000e+000,5.000000e-001,5,1,8.209229e-003,0,,0,
1405596420.937,,-7.500000e+001,2.980009e+002,-3.127501e-005,0.000000e+000,2.548303e-002,0.000000e+000,3,9.811133e-001,1.825000e+000,,,,,,,,,,,,,,,,,,0,4.000000e+000,5.000000e-001,5,1,8.209229e-003,0,,0,
1405596438.171,,-7.500000e+001,2.980050e+002,-3.127000e-005,0.000000e+000,2.536961e-002,0.000000e+000,3,9.811189e-001,1.825000e+000,,,,,,,,,,,,,,,,,,0,4.000000e+000,5.000000e-001,5,1,1.641846e-002,0,,0,
1405596569.687,,-5.000000e+001,2.980050e+002,-3.070529e-005,0.000000e+000,2.591966e-002,0.000000e+000,3,9.836651e-001,1.825000e+000,,,,,,,,,,,,,,,,,,0,4.000000e+000,5.000000e-001,5,1,0.000000e+000,0,,0,
1405596586.921,,-5.000000e+001,2.980050e+002,-3.071392e-005,0.000000e+000,2.532047e-002,0.000000e+000,3,9.838370e-001,1.825000e+000,,,,,,,,,,,,,,,,,,0,4.000000e+000,5.000000e-001,5,1,0.000000e+000,0,,0,
1405596605.156,,-5.000000e+001,2.980009e+002,-3.070411e-005,0.000000e+000,2.557884e-002,0.000000e+000,3,9.837440e-001,1.825000e+000,,,,,,,,,,,,,,,,,,0,4.000000e+000,5.000000e-001,5,1,8.209229e-003,0,,0,
1405596724.390,,-4.500000e+001,2.979968e+002,-3.054132e-005,0.000000e+000,2.569799e-002,0.000000e+000,3,9.832494e-001,1.825000e+000,,,,,,,,,,,,,,,,,,0,4.000000e+000,5.000000e-001,5,1,0.000000e+000,0,,0,
1405596742.625,,-4.500000e+001,2.980009e+002,-3.053182e-005,0.000000e+000,2.575211e-002,0.000000e+000,3,9.832293e-001,1.825000e+000,,,,,,,,,,,,,,,,,,0,4.000000e+000,5.000000e-001,5,1,8.209229e-003,0,,0,
1405596759.859,,-4.500000e+001,2.980009e+002,-3.054926e-005,0.000000e+000,2.577800e-002,0.000000e+000,3,9.833527e-001,1.825000e+000,,,,,,,,,,,,,,,,,,0,4.000000e+000,5.000000e-001,5,1,8.209229e-003,0,,0,
1405596879.171,,-4.000000e+001,2.980009e+002,-3.036674e-005,0.000000e+000,2.578504e-002,0.000000e+000,3,9.825696e-001,1.825000e+000,,,,,,,,,,,,,,,,,,0,4.000000e+000,5.000000e-001,5,1,8.209229e-003,0,,0,
1405596896.453,,-4.000000e+001,2.979968e+002,-3.037012e-005,0.000000e+000,2.607660e-002,0.000000e+000,3,9.825520e-001,1.825000e+000,,,,,,,,,,,,,,,,,,0,4.000000e+000,5.000000e-001,5,1,0.000000e+000,0,,0,
1405596914.187,,-4.000000e+001,2.979968e+002,-3.036071e-005,0.000000e+000,2.613547e-002,0.000000e+000,3,9.825858e-001,1.825000e+000,,,,,,,,,,,,,,,,,,0,4.000000e+000,5.000000e-001,5,1,0.000000e+000,0,,0,
1405597033.421,,-3.500000e+001,2.979968e+002,-3.015592e-005,0.000000e+000,2.640113e-002,0.000000e+000,3,9.814889e-001,1.825000e+000,,,,,,,,,,,,,,,,,,0,4.000000e+000,5.000000e-001,5,1,0.000000e+000,0,,0,
1405597051.156,,-3.500000e+001,2.980009e+002,-3.015604e-005,0.000000e+000,2.605662e-002,0.000000e+000,3,9.815226e-001,1.825000e+000,,,,,,,,,,,,,,,,,,0,4.000000e+000,5.000000e-001,5,1,8.209229e-003,0,,0,
1405597068.921,,-3.500000e+001,2.980009e+002,-3.016656e-005,0.000000e+000,2.634896e-002,0.000000e+000,3,9.814905e-001,1.825000e+000,,,,,,,,,,,,,,,,,,0,4.000000e+000,5.000000e-001,5,1,8.209229e-003,0,,0,
1405597194.250,,-3.000000e+001,2.979968e+002,-2.991611e-005,0.000000e+000,2.651589e-002,0.000000e+000,3,9.798893e-001,1.825000e+000,,,,,,,,,,,,,,,,,,0,4.000000e+000,5.000000e-001,5,1,0.000000e+000,0,,0,
1405597211.031,,-3.000000e+001,2.979926e+002,-2.992991e-005,0.000000e+000,2.646961e-002,0.000000e+000,3,9.799002e-001,1.825000e+000,,,,,,,,,,,,,,,,,,0,4.000000e+000,5.000000e-001,5,1,8.300781e-003,0,,0,
1405597229.265,,-3.000000e+001,2.980009e+002,-2.993395e-005,0.000000e+000,2.650551e-002,0.000000e+000,3,9.800550e-001,1.825000e+000,,,,,,,,,,,,,,,,,,0,4.000000e+000,5.000000e-001,5,1,8.209229e-003,0,,0,
1405597347.250,,-2.500000e+001,2.979968e+002,-2.967712e-005,0.000000e+000,2.699374e-002,0.000000e+000,3,9.781262e-001,1.825000e+000,,,,,,,,,,,,,,,,,,0,4.000000e+000,5.000000e-001,5,1,0.000000e+000,0,,0,
1405597365.234,,-2.500000e+001,2.980009e+002,-2.966746e-005,0.000000e+000,2.676671e-002,0.000000e+000,3,9.783061e-001,1.825000e+000,,,,,,,,,,,,,,,,,,0,4.000000e+000,5.000000e-001,5,1,8.209229e-003,0,,0,
1405597383.968,,-2.500000e+001,2.980009e+002,-2.966549e-005,0.000000e+000,2.700216e-002,0.000000e+000,3,9.781883e-001,1.825000e+000,,,,,,,,,,,,,,,,,,0,4.000000e+000,5.000000e-001,5,1,8.209229e-003,0,,0,
1405597502.218,,-2.000000e+001,2.979968e+002,-2.936504e-005,0.000000e+000,2.717499e-002,0.000000e+000,3,9.760063e-001,1.825000e+000,,,,,,,,,,,,,,,,,,0,4.000000e+000,5.000000e-001,5,1,0.000000e+000,0,,0,
1405597520.281,,-2.000000e+001,2.980009e+002,-2.937228e-005,0.000000e+000,2.712790e-002,0.000000e+000,3,9.756610e-001,1.825000e+000,,,,,,,,,,,,,,,,,,0,4.000000e+000,5.000000e-001,5,1,8.209229e-003,0,,0,
1405597538.265,,-2.000000e+001,2.980009e+002,-2.936775e-005,0.000000e+000,2.721010e-002,0.000000e+000,3,9.758568e-001,1.825000e+000,,,,,,,,,,,,,,,,,,0,4.000000e+000,5.000000e-001,5,1,8.209229e-003,0,,0,
1405597656.500,,-1.500000e+001,2.980050e+002,-2.902218e-005,0.000000e+000,2.784262e-002,0.000000e+000,3,9.735059e-001,1.825000e+000,,,,,,,,,,,,,,,,,,0,4.000000e+000,5.000000e-001,5,1,0.000000e+000,0,,0,
1405597674.234,,-1.500000e+001,2.979968e+002,-2.902809e-005,0.000000e+000,2.793538e-002,0.000000e+000,3,9.737128e-001,1.825000e+000,,,,,,,,,,,,,,,,,,0,4.000000e+000,5.000000e-001,5,1,0.000000e+000,0,,0,
1405597691.468,,-1.500000e+001,2.979968e+002,-2.902841e-005,0.000000e+000,2.783664e-002,0.000000e+000,3,9.734008e-001,1.825000e+000,,,,,,,,,,,,,,,,,,0,4.000000e+000,5.000000e-001,5,1,0.000000e+000,0,,0,
1405597803.968,,-1.000000e+001,2.979968e+002,-2.862084e-005,0.000000e+000,2.869655e-002,0.000000e+000,3,9.709662e-001,1.825000e+000,,,,,,,,,,,,,,,,,,0,4.000000e+000,5.000000e-001,5,1,0.000000e+000,0,,0,
1405597822.234,,-1.000000e+001,2.979968e+002,-2.860761e-005,0.000000e+000,2.866754e-002,0.000000e+000,3,9.709592e-001,1.825000e+000,,,,,,,,,,,,,,,,,,0,4.000000e+000,5.000000e-001,5,1,0.000000e+000,0,,0,
1405597839.968,,-1.000000e+001,2.980009e+002,-2.861792e-005,0.000000e+000,2.838804e-002,0.000000e+000,3,9.709039e-001,1.825000e+000,,,,,,,,,,,,,,,,,,0,4.000000e+000,5.000000e-001,5,1,8.209229e-003,0,,0,
1405597964.953,,-5.000000e+000,2.980050e+002,-2.812317e-005,0.000000e+000,2.984619e-002,0.000000e+000,3,9.675660e-001,1.825000e+000,,,,,,,,,,,,,,,,,,0,4.000000e+000,5.000000e-001,5,1,0.000000e+000,0,,0,
1405597982.187,,-5.000000e+000,2.980009e+002,-2.812594e-005,0.000000e+000,2.960672e-002,0.000000e+000,3,9.676538e-001,1.825000e+000,,,,,,,,,,,,,,,,,,0,4.000000e+000,5.000000e-001,5,1,8.209229e-003,0,,0,
1405597999.921,,-5.000000e+000,2.980009e+002,-2.812004e-005,0.000000e+000,2.952565e-002,0.000000e+000,3,9.675512e-001,1.825000e+000,,,,,,,,,,,,,,,,,,0,4.000000e+000,5.000000e-001,5,1,8.209229e-003,0,,0,
1405598118.671,,0.000000e+000,2.979968e+002,-2.755582e-005,0.000000e+000,3.086699e-002,0.000000e+000,3,9.642517e-001,1.825000e+000,,,,,,,,,,,,,,,,,,0,4.000000e+000,5.000000e-001,5,1,0.000000e+000,0,,0,
1405598135.906,,0.000000e+000,2.980009e+002,-2.755525e-005,0.000000e+000,3.087205e-002,0.000000e+000,3,9.641109e-001,1.825000e+000,,,,,,,,,,,,,,,,,,0,4.000000e+000,5.000000e-001,5,1,8.209229e-003,0,,0,
1405598154.140,,0.000000e+000,2.979968e+002,-2.754045e-005,0.000000e+000,3.089110e-002,0.000000e+000,3,9.640296e-001,1.825000e+000,,,,,,,,,,,,,,,,,,0,4.000000e+000,5.000000e-001,5,1,0.000000e+000,0,,0,
1405598272.875,,5.000000e+000,2.979968e+002,-2.677826e-005,0.000000e+000,3.264810e-002,0.000000e+000,3,9.598077e-001,1.825000e+000,,,,,,,,,,,,,,,,,,0,4.000000e+000,5.000000e-001,5,1,0.000000e+000,0,,0,
1405598290.625,,5.000000e+000,2.979968e+002,-2.676505e-005,0.000000e+000,3.287568e-002,0.000000e+000,3,9.593747e-001,1.825000e+000,,,,,,,,,,,,,,,,,,0,4.000000e+000,5.000000e-001,5,1,0.000000e+000,0,,0,
1405598308.906,,5.000000e+000,2.979968e+002,-2.677263e-005,0.000000e+000,3.300025e-002,0.000000e+000,3,9.595349e-001,1.825000e+000,,,,,,,,,,,,,,,,,,0,4.000000e+000,5.000000e-001,5,1,0.000000e+000,0,,0,
1405598434.156,,1.000000e+001,2.979968e+002,-2.584251e-005,0.000000e+000,3.551779e-002,0.000000e+000,3,9.547988e-001,1.825000e+000,,,,,,,,,,,,,,,,,,0,4.000000e+000,5.000000e-001,5,1,0.000000e+000,0,,0,
1405598451.390,,1.000000e+001,2.980009e+002,-2.583078e-005,0.000000e+000,3.560511e-002,0.000000e+000,3,9.540523e-001,1.825000e+000,,,,,,,,,,,,,,,,,,0,4.000000e+000,5.000000e-001,5,1,8.209229e-003,0,,0,
1405598469.125,,1.000000e+001,2.980009e+002,-2.582377e-005,0.000000e+000,3.574577e-002,0.000000e+000,3,9.542430e-001,1.825000e+000,,,,,,,,,,,,,,,,,,0,4.000000e+000,5.000000e-001,5,1,8.209229e-003,0,,0,
1405598587.109,,1.500000e+001,2.979968e+002,-2.460663e-005,0.000000e+000,3.977586e-002,0.000000e+000,3,9.480472e-001,1.825000e+000,,,,,,,,,,,,,,,,,,0,4.000000e+000,5.000000e-001,5,1,0.000000e+000,0,,0,
1405598604.843,,1.500000e+001,2.980009e+002,-2.459429e-005,0.000000e+000,3.955547e-002,0.000000e+000,3,9.478703e-001,1.825000e+000,,,,,,,,,,,,,,,,,,0,4.000000e+000,5.000000e-001,5,1,8.209229e-003,0,,0,
1405598623.078,,1.500000e+001,2.980009e+002,-2.458081e-005,0.000000e+000,3.985098e-002,0.000000e+000,3,9.478758e-001,1.825000e+000,,,,,,,,,,,,,,,,,,0,4.000000e+000,5.000000e-001,5,1,8.209229e-003,0,,0,
1405598740.078,,2.000000e+001,2.980009e+002,-2.259109e-005,0.000000e+000,4.784223e-002,0.000000e+000,3,9.379430e-001,1.825000e+000,,,,,,,,,,,,,,,,,,0,4.000000e+000,5.000000e-001,5,1,8.209229e-003,0,,0,
1405598758.562,,2.000000e+001,2.979968e+002,-2.254708e-005,0.000000e+000,4.825630e-002,0.000000e+000,3,9.382240e-001,1.825000e+000,,,,,,,,,,,,,,,,,,0,4.000000e+000,5.000000e-001,5,1,0.000000e+000,0,,0,
1405598776.093,,2.000000e+001,2.980009e+002,-2.250200e-005,0.000000e+000,4.845613e-002,0.000000e+000,3,9.374892e-001,1.825000e+000,,,,,,,,,,,,,,,,,,0,4.000000e+000,5.000000e-001,5,1,8.209229e-003,0,,0,
1405598895.578,,2.500000e+001,2.980009e+002,-1.707015e-005,0.000000e+000,8.215097e-002,0.000000e+000,3,9.058108e-001,1.825000e+000,,,,,,,,,,,,,,,,,,0,4.000000e+000,5.000000e-001,5,1,8.209229e-003,0,,0,
1405598913.562,,2.500000e+001,2.980050e+002,-1.676523e-005,0.000000e+000,8.554086e-002,0.000000e+000,3,9.040345e-001,1.825000e+000,,,,,,,,,,,,,,,,,,0,4.000000e+000,5.000000e-001,5,1,0.000000e+000,0,,0,
1405598931.046,,2.500000e+001,2.979968e+002,-1.650377e-005,0.000000e+000,8.769809e-002,0.000000e+000,3,9.016833e-001,1.825000e+000,,,,,,,,,,,,,,,,,,0,4.000000e+000,5.000000e-001,5,1,0.000000e+000,0,,0,
1405599065.828,,3.000000e+001,2.979968e+002,6.582840e-006,0.000000e+000,-4.849977e-001,0.000000e+000,3,8.066111e-001,1.825000e+000,,,,,,,,,,,,,,,,,,0,4.000000e+000,5.000000e-001,5,1,0.000000e+000,0,,0,
1405599083.562,,3.000000e+001,2.979968e+002,7.074158e-006,0.000000e+000,-4.346891e-001,0.000000e+000,3,8.118407e-001,1.825000e+000,,,,,,,,,,,,,,,,,,0,4.000000e+000,5.000000e-001,5,1,0.000000e+000,0,,0,
1405599101.796,,3.000000e+001,2.979968e+002,7.541740e-006,0.000000e+000,-3.980048e-001,0.000000e+000,3,8.189819e-001,1.825000e+000,,,,,,,,,,,,,,,,,,0,4.000000e+000,5.000000e-001,5,1,0.000000e+000,0,,0,
1405599220.281,,3.500000e+001,2.980009e+002,2.138740e-005,0.000000e+000,-9.043217e-002,0.000000e+000,3,9.081466e-001,1.825000e+000,,,,,,,,,,,,,,,,,,0,4.000000e+000,5.000000e-001,5,1,8.209229e-003,0,,0,
1405599238.015,,3.500000e+001,2.979968e+002,2.199271e-005,0.000000e+000,-8.711016e-002,0.000000e+000,3,9.098330e-001,1.825000e+000,,,,,,,,,,,,,,,,,,0,4.000000e+000,5.000000e-001,5,1,1.651001e-002,0,,0,
1405599256.765,,3.500000e+001,2.979968e+002,2.250039e-005,0.000000e+000,-8.429073e-002,0.000000e+000,3,9.108925e-001,1.825000e+000,,,,,,,,,,,,,,,,,,0,4.000000e+000,5.000000e-001,5,1,0.000000e+000,0,,0,
1405599374.500,,4.000000e+001,2.979968e+002,2.884830e-005,0.000000e+000,-4.543223e-002,0.000000e+000,3,9.189623e-001,1.825000e+000,,,,,,,,,,,,,,,,,,0,4.000000e+000,5.000000e-001,5,1,0.000000e+000,0,,0,
1405599392.234,,4.000000e+001,2.979968e+002,2.901512e-005,0.000000e+000,-4.408462e-002,0.000000e+000,3,9.191831e-001,1.825000e+000,,,,,,,,,,,,,,,,,,0,4.000000e+000,5.000000e-001,5,1,1.651001e-002,0,,0,
1405599409.796,,4.000000e+001,2.980009e+002,2.915458e-005,0.000000e+000,-4.308012e-002,0.000000e+000,3,9.193411e-001,1.825000e+000,,,,,,,,,,,,,,,,,,0,4.000000e+000,5.000000e-001,5,1,8.209229e-003,0,,0,
1405599529.781,,4.500000e+001,2.979968e+002,3.106083e-005,0.000000e+000,-3.140561e-002,0.000000e+000,3,9.193349e-001,1.825000e+000,,,,,,,,,,,,,,,,,,0,4.000000e+000,5.000000e-001,5,1,0.000000e+000,0,,0,
1405599547.515,,4.500000e+001,2.980050e+002,3.116627e-005,0.000000e+000,-3.064888e-002,0.000000e+000,3,9.191140e-001,1.825000e+000,,,,,,,,,,,,,,,,,,0,4.000000e+000,5.000000e-001,5,1,0.000000e+000,0,,0,
1405599565.781,,4.500000e+001,2.980009e+002,3.126476e-005,0.000000e+000,-3.019194e-002,0.000000e+000,3,9.194379e-001,1.825000e+000,,,,,,,,,,,,,,,,,,0,4.000000e+000,5.000000e-001,5,1,8.209229e-003,0,,0,
1405599684.015,,5.000000e+001,2.980050e+002,3.326141e-005,0.000000e+000,-1.674002e-002,0.000000e+000,3,9.192680e-001,1.825000e+000,,,,,,,,,,,,,,,,,,0,4.000000e+000,5.000000e-001,5,1,1.641846e-002,0,,0,
1405599702.000,,5.000000e+001,2.980009e+002,3.343174e-005,0.000000e+000,-1.542330e-002,0.000000e+000,3,9.195867e-001,1.825000e+000,,,,,,,,,,,,,,,,,,0,4.000000e+000,5.000000e-001,5,1,8.209229e-003,0,,0,
1405599719.984,,5.000000e+001,2.979968e+002,3.356875e-005,0.000000e+000,-1.452061e-002,0.000000e+000,3,9.197658e-001,1.825000e+000,,,,,,,,,,,,,,,,,,0,4.000000e+000,5.000000e-001,5,1,0.000000e+000,0,,0,
1405599844.718,,7.500000e+001,2.980050e+002,3.602333e-005,0.000000e+000,4.835498e-004,0.000000e+000,3,9.061227e-001,1.825000e+000,,,,,,,,,,,,,,,,,,0,4.000000e+000,5.000000e-001,5,1,0.000000e+000,0,,0,
1405599862.468,,7.500000e+001,2.980050e+002,3.601809e-005,0.000000e+000,4.831991e-004,0.000000e+000,3,9.061198e-001,1.825000e+000,,,,,,,,,,,,,,,,,,0,4.000000e+000,5.000000e-001,5,1,0.000000e+000,0,,0,
1405599880.218,,7.500000e+001,2.980009e+002,3.603506e-005,0.000000e+000,4.992515e-004,0.000000e+000,3,9.061804e-001,1.825000e+000,,,,,,,,,,,,,,,,,,0,4.000000e+000,5.000000e-001,5,1,8.209229e-003,0,,0,
1405600021.687,,1.000000e+002,2.979926e+002,3.704790e-005,0.000000e+000,2.860504e-003,0.000000e+000,3,8.937746e-001,1.825000e+000,,,,,,,,,,,,,,,,,,0,4.000000e+000,5.000000e-001,5,1,8.300781e-003,0,,0,
1405600039.421,,1.000000e+002,2.979968e+002,3.705190e-005,0.000000e+000,2.957855e-003,0.000000e+000,3,8.939150e-001,1.825000e+000,,,,,,,,,,,,,,,,,,0,4.000000e+000,5.000000e-001,5,1,0.000000e+000,0,,0,
1405600057.656,,1.000000e+002,2.980009e+002,3.704677e-005,0.000000e+000,2.984418e-003,0.000000e+000,3,8.938238e-001,1.825000e+000,,,,,,,,,,,,,,,,,,0,4.000000e+000,5.000000e-001,5,1,8.209229e-003,0,,0,