File: Sample Data Files/2014-07-16 EB on isolated PMN-PT no Ti spontaneous in situ/Ni-NiO_298K_SiO2_PMN-PT_5.0Tprebias_400V_Au_back.rso.dat
[Header]
TITLE,MPMS RSO Measurement
BYAPP,MPMS Measurement,1.1,Summary
FILEOPENTIME, 1405548582.796000 7/16/2014, 3:09:42 PM

INFO, APPNAME, MPMS MultiVu Application, Revision 1.58,  Build 076

INFO, NAME, EB in situ
INFO, WEIGHT, 0.000
INFO, AREA, 0.000
INFO, LENGTH, 0.000
INFO, SHAPE, 0
INFO, COMMENT,
INFO, SEQUENCE FILE: MHcurveUpTo100.seq


INFO, BACKGROUND DATA FILE:, None


STARTUPAXIS,X,4,LINEAR,AUTO,0.000000,0.000000
STARTUPAXIS,Y1,5,LINEAR,AUTO,0.000000,0.000000


STARTUPGROUP,Longitudinal
FIELDGROUP,Longitudinal,1,2,3,4,5,6,7,8,9,10,11,19,20,21,22,23,35
FIELDGROUP,Transverse,1,2,3,4,12,13,14,15,16,17,18,24,25,26,27,28,35

PLOT_APPEARANCE,ALL,HORZ_GRID_ON,VERT_GRID_ON,MARKERS_AND_LINES

[Data]
Time,Comment,Field (Oe),Temperature (K),Long Moment (emu),Long Scan Std Dev,Long Offset (cm),Long Offset Std Dev,Long Algorithm,Long Reg Fit,Long Reg Factor,Trans Moment (emu),Trans Scan Std Dev,Trans Offset (cm),Trans Offset Std Dev,Trans Algorithm,Trans Reg Fit,Trans Reg Factor,Long Moment [w/o ABS] (emu),Long Scan Std Dev [w/o ABS],Long Offset [w/o ABS] (cm),Long Offset Std Dev [w/o ABS],Long Reg Fit [w/o ABS],Trans Moment [w/o ABS] (emu),Trans Scan Std Dev [w/o ABS],Trans Offset [w/o ABS] (cm),Trans Offset Std Dev [w/o ABS],Trans Reg Fit [w/o ABS],RSO Position (deg),Amplitude (cm),Frequency,Cycles to Average,Scans per Measurement,Delta Temp (K),Error,EC Comp. Running,Using ABS,
1405548582.796,,1.000000e+002,2.979885e+002,9.363133e-006,0.000000e+000,7.383101e-002,0.000000e+000,3,6.122775e-001,1.825000e+000,,,,,,,,,,,,,,,,,,0,4.000000e+000,5.000000e-001,5,1,0.000000e+000,0,,0,
1405548601.031,,1.000000e+002,2.980009e+002,9.377916e-006,0.000000e+000,7.363009e-002,0.000000e+000,3,6.132801e-001,1.825000e+000,,,,,,,,,,,,,,,,,,0,4.000000e+000,5.000000e-001,5,1,8.209229e-003,0,,0,
1405548618.765,,1.000000e+002,2.980009e+002,9.405810e-006,0.000000e+000,7.222626e-002,0.000000e+000,3,6.142175e-001,1.825000e+000,,,,,,,,,,,,,,,,,,0,4.000000e+000,5.000000e-001,5,1,8.209229e-003,0,,0,
1405548745.562,,7.500000e+001,2.980009e+002,8.148569e-006,0.000000e+000,8.373601e-002,0.000000e+000,3,5.960253e-001,1.825000e+000,,,,,,,,,,,,,,,,,,0,4.000000e+000,5.000000e-001,5,1,8.209229e-003,0,,0,
1405548763.328,,7.500000e+001,2.980009e+002,8.168501e-006,0.000000e+000,8.400905e-002,0.000000e+000,3,5.966856e-001,1.825000e+000,,,,,,,,,,,,,,,,,,0,4.000000e+000,5.000000e-001,5,1,8.209229e-003,0,,0,
1405548782.062,,7.500000e+001,2.980050e+002,8.143809e-006,0.000000e+000,8.564248e-002,0.000000e+000,3,5.961427e-001,1.825000e+000,,,,,,,,,,,,,,,,,,0,4.000000e+000,5.000000e-001,5,1,0.000000e+000,0,,0,
1405548907.359,,5.000000e+001,2.979968e+002,6.771654e-006,0.000000e+000,1.011592e-001,0.000000e+000,3,5.716938e-001,1.825000e+000,,,,,,,,,,,,,,,,,,0,4.000000e+000,5.000000e-001,5,1,0.000000e+000,0,,0,
1405548942.828,,5.000000e+001,2.980050e+002,6.781558e-006,0.000000e+000,1.037733e-001,0.000000e+000,3,5.720872e-001,1.825000e+000,,,,,,,,,,,,,,,,,,0,4.000000e+000,5.000000e-001,5,1,0.000000e+000,0,,0,
1405548961.062,,5.000000e+001,2.979968e+002,6.783863e-006,0.000000e+000,1.027580e-001,0.000000e+000,3,5.710932e-001,1.825000e+000,,,,,,,,,,,,,,,,,,0,4.000000e+000,5.000000e-001,5,1,0.000000e+000,0,,0,
1405549080.546,,4.500000e+001,2.980050e+002,6.495065e-006,0.000000e+000,1.062388e-001,0.000000e+000,3,5.654051e-001,1.825000e+000,,,,,,,,,,,,,,,,,,0,4.000000e+000,5.000000e-001,5,1,0.000000e+000,0,,0,
1405549098.781,,4.500000e+001,2.980091e+002,6.487608e-006,0.000000e+000,1.069126e-001,0.000000e+000,3,5.644948e-001,1.825000e+000,,,,,,,,,,,,,,,,,,0,4.000000e+000,5.000000e-001,5,1,8.209229e-003,0,,0,
1405549116.578,,4.500000e+001,2.980009e+002,6.475685e-006,0.000000e+000,1.084222e-001,0.000000e+000,3,5.633493e-001,1.825000e+000,,,,,,,,,,,,,,,,,,0,4.000000e+000,5.000000e-001,5,1,8.209229e-003,0,,0,
1405549234.062,,4.000000e+001,2.980050e+002,6.182280e-006,0.000000e+000,1.109180e-001,0.000000e+000,3,5.568855e-001,1.825000e+000,,,,,,,,,,,,,,,,,,0,4.000000e+000,5.000000e-001,5,1,0.000000e+000,0,,0,
1405549251.546,,4.000000e+001,2.980009e+002,6.180161e-006,0.000000e+000,1.105101e-001,0.000000e+000,3,5.569922e-001,1.825000e+000,,,,,,,,,,,,,,,,,,0,4.000000e+000,5.000000e-001,5,1,8.209229e-003,0,,0,
1405549269.078,,4.000000e+001,2.980009e+002,6.175683e-006,0.000000e+000,1.115221e-001,0.000000e+000,3,5.558671e-001,1.825000e+000,,,,,,,,,,,,,,,,,,0,4.000000e+000,5.000000e-001,5,1,8.209229e-003,0,,0,
1405549389.062,,3.500000e+001,2.979968e+002,5.875201e-006,0.000000e+000,1.164292e-001,0.000000e+000,3,5.471967e-001,1.825000e+000,,,,,,,,,,,,,,,,,,0,4.000000e+000,5.000000e-001,5,1,0.000000e+000,0,,0,
1405549407.562,,3.500000e+001,2.980009e+002,5.880680e-006,0.000000e+000,1.163856e-001,0.000000e+000,3,5.496632e-001,1.825000e+000,,,,,,,,,,,,,,,,,,0,4.000000e+000,5.000000e-001,5,1,8.209229e-003,0,,0,
1405549425.812,,3.500000e+001,2.979968e+002,5.876155e-006,0.000000e+000,1.163955e-001,0.000000e+000,3,5.459555e-001,1.825000e+000,,,,,,,,,,,,,,,,,,0,4.000000e+000,5.000000e-001,5,1,0.000000e+000,0,,0,
1405549544.796,,3.000000e+001,2.980009e+002,5.556707e-006,0.000000e+000,1.221473e-001,0.000000e+000,3,5.372528e-001,1.825000e+000,,,,,,,,,,,,,,,,,,0,4.000000e+000,5.000000e-001,5,1,8.209229e-003,0,,0,
1405549562.546,,3.000000e+001,2.979968e+002,5.559903e-006,0.000000e+000,1.225671e-001,0.000000e+000,3,5.384636e-001,1.825000e+000,,,,,,,,,,,,,,,,,,0,4.000000e+000,5.000000e-001,5,1,1.651001e-002,0,,0,
1405549580.281,,3.000000e+001,2.980009e+002,5.555978e-006,0.000000e+000,1.232747e-001,0.000000e+000,3,5.377069e-001,1.825000e+000,,,,,,,,,,,,,,,,,,0,4.000000e+000,5.000000e-001,5,1,8.209229e-003,0,,0,
1405549698.515,,2.500000e+001,2.979968e+002,5.236871e-006,0.000000e+000,1.302680e-001,0.000000e+000,3,5.275481e-001,1.825000e+000,,,,,,,,,,,,,,,,,,0,4.000000e+000,5.000000e-001,5,1,0.000000e+000,0,,0,
1405549716.765,,2.500000e+001,2.980009e+002,5.223008e-006,0.000000e+000,1.285695e-001,0.000000e+000,3,5.266626e-001,1.825000e+000,,,,,,,,,,,,,,,,,,0,4.000000e+000,5.000000e-001,5,1,8.209229e-003,0,,0,
1405549734.546,,2.500000e+001,2.979968e+002,5.241869e-006,0.000000e+000,1.295829e-001,0.000000e+000,3,5.282083e-001,1.825000e+000,,,,,,,,,,,,,,,,,,0,4.000000e+000,5.000000e-001,5,1,0.000000e+000,0,,0,
1405549853.062,,2.000000e+001,2.979968e+002,4.898244e-006,0.000000e+000,1.338184e-001,0.000000e+000,3,5.133588e-001,1.825000e+000,,,,,,,,,,,,,,,,,,0,4.000000e+000,5.000000e-001,5,1,0.000000e+000,0,,0,
1405549871.546,,2.000000e+001,2.979926e+002,4.893253e-006,0.000000e+000,1.394357e-001,0.000000e+000,3,5.127776e-001,1.825000e+000,,,,,,,,,,,,,,,,,,0,4.000000e+000,5.000000e-001,5,1,8.300781e-003,0,,0,
1405549889.781,,2.000000e+001,2.979926e+002,4.889035e-006,0.000000e+000,1.337212e-001,0.000000e+000,3,5.139472e-001,1.825000e+000,,,,,,,,,,,,,,,,,,0,4.000000e+000,5.000000e-001,5,1,8.300781e-003,0,,0,
1405550009.562,,1.500000e+001,2.980009e+002,4.547524e-006,0.000000e+000,1.430942e-001,0.000000e+000,3,4.976541e-001,1.825000e+000,,,,,,,,,,,,,,,,,,0,4.000000e+000,5.000000e-001,5,1,8.209229e-003,0,,0,
1405550027.390,,1.500000e+001,2.979968e+002,4.542718e-006,0.000000e+000,1.453982e-001,0.000000e+000,3,4.984535e-001,1.825000e+000,,,,,,,,,,,,,,,,,,0,4.000000e+000,5.000000e-001,5,1,0.000000e+000,0,,0,
1405550045.656,,1.500000e+001,2.979968e+002,4.536263e-006,0.000000e+000,1.459733e-001,0.000000e+000,3,4.957781e-001,1.825000e+000,,,,,,,,,,,,,,,,,,0,4.000000e+000,5.000000e-001,5,1,0.000000e+000,0,,0,
1405550165.140,,1.000000e+001,2.979968e+002,4.180939e-006,0.000000e+000,1.462368e-001,0.000000e+000,3,4.793175e-001,1.825000e+000,,,,,,,,,,,,,,,,,,0,4.000000e+000,5.000000e-001,5,1,0.000000e+000,0,,0,
1405550183.625,,1.000000e+001,2.979968e+002,4.162944e-006,0.000000e+000,1.495543e-001,0.000000e+000,3,4.767050e-001,1.825000e+000,,,,,,,,,,,,,,,,,,0,4.000000e+000,5.000000e-001,5,1,0.000000e+000,0,,0,
1405550201.359,,1.000000e+001,2.979968e+002,4.181212e-006,0.000000e+000,1.534331e-001,0.000000e+000,3,4.769361e-001,1.825000e+000,,,,,,,,,,,,,,,,,,0,4.000000e+000,5.000000e-001,5,1,0.000000e+000,0,,0,
1405550319.625,,5.000000e+000,2.980009e+002,3.799187e-006,0.000000e+000,1.467492e-001,0.000000e+000,3,4.547015e-001,1.825000e+000,,,,,,,,,,,,,,,,,,0,4.000000e+000,5.000000e-001,5,1,8.209229e-003,0,,0,
1405550337.109,,5.000000e+000,2.980009e+002,3.777169e-006,0.000000e+000,1.500802e-001,0.000000e+000,3,4.499843e-001,1.825000e+000,,,,,,,,,,,,,,,,,,0,4.000000e+000,5.000000e-001,5,1,8.209229e-003,0,,0,
1405550354.671,,5.000000e+000,2.980009e+002,3.776963e-006,0.000000e+000,1.495457e-001,0.000000e+000,3,4.488912e-001,1.825000e+000,,,,,,,,,,,,,,,,,,0,4.000000e+000,5.000000e-001,5,1,8.209229e-003,0,,0,
1405550473.406,,0.000000e+000,2.979968e+002,3.393327e-006,0.000000e+000,1.495692e-001,0.000000e+000,3,4.180268e-001,1.825000e+000,,,,,,,,,,,,,,,,,,0,4.000000e+000,5.000000e-001,5,1,0.000000e+000,0,,0,
1405550491.640,,0.000000e+000,2.979968e+002,3.389611e-006,0.000000e+000,1.551819e-001,0.000000e+000,3,4.198489e-001,1.825000e+000,,,,,,,,,,,,,,,,,,0,4.000000e+000,5.000000e-001,5,1,0.000000e+000,0,,0,
1405550509.421,,0.000000e+000,2.980050e+002,3.383573e-006,0.000000e+000,1.489533e-001,0.000000e+000,3,4.183775e-001,1.825000e+000,,,,,,,,,,,,,,,,,,0,4.000000e+000,5.000000e-001,5,1,0.000000e+000,0,,0,
1405550627.671,,-5.000000e+000,2.979926e+002,2.926866e-006,0.000000e+000,9.127637e-002,0.000000e+000,3,3.750732e-001,1.825000e+000,,,,,,,,,,,,,,,,,,0,4.000000e+000,5.000000e-001,5,1,8.300781e-003,0,,0,
1405550644.906,,-5.000000e+000,2.979968e+002,2.928198e-006,0.000000e+000,8.518395e-002,0.000000e+000,3,3.733376e-001,1.825000e+000,,,,,,,,,,,,,,,,,,0,4.000000e+000,5.000000e-001,5,1,0.000000e+000,0,,0,
1405550663.203,,-5.000000e+000,2.980009e+002,2.921259e-006,0.000000e+000,8.417637e-002,0.000000e+000,3,3.732278e-001,1.825000e+000,,,,,,,,,,,,,,,,,,0,4.000000e+000,5.000000e-001,5,1,8.209229e-003,0,,0,
1405550782.437,,-1.000000e+001,2.980009e+002,2.489513e-006,0.000000e+000,-2.983933e-003,0.000000e+000,3,3.132157e-001,1.825000e+000,,,,,,,,,,,,,,,,,,0,4.000000e+000,5.000000e-001,5,1,8.209229e-003,0,,0,
1405550800.671,,-1.000000e+001,2.980009e+002,2.432362e-006,0.000000e+000,-2.110568e-002,0.000000e+000,3,2.997271e-001,1.825000e+000,,,,,,,,,,,,,,,,,,0,4.000000e+000,5.000000e-001,5,1,8.209229e-003,0,,0,
1405550818.656,,-1.000000e+001,2.980050e+002,2.447152e-006,0.000000e+000,-3.138446e-002,0.000000e+000,3,3.027868e-001,1.825000e+000,,,,,,,,,,,,,,,,,,0,4.000000e+000,5.000000e-001,5,1,0.000000e+000,0,,0,
1405550937.421,,-1.500000e+001,2.980009e+002,2.060927e-006,0.000000e+000,-3.527055e-001,0.000000e+000,3,2.310544e-001,1.825000e+000,,,,,,,,,,,,,,,,,,0,4.000000e+000,5.000000e-001,5,1,8.209229e-003,0,,0,
1405550954.968,,-1.500000e+001,2.980009e+002,2.065571e-006,0.000000e+000,-3.524790e-001,0.000000e+000,3,2.370521e-001,1.825000e+000,,,,,,,,,,,,,,,,,,0,4.000000e+000,5.000000e-001,5,1,8.209229e-003,0,,0,
1405550972.718,,-1.500000e+001,2.980050e+002,2.073959e-006,0.000000e+000,-3.640547e-001,0.000000e+000,3,2.381681e-001,1.825000e+000,,,,,,,,,,,,,,,,,,0,4.000000e+000,5.000000e-001,5,1,0.000000e+000,0,,0,
1405551098.734,,-2.000000e+001,2.980050e+002,1.736094e-006,0.000000e+000,-5.832165e-001,0.000000e+000,3,1.293205e-001,1.825000e+000,,,,,,,,,,,,,,,,,,0,4.000000e+000,5.000000e-001,5,1,0.000000e+000,0,,0,
1405551116.468,,-2.000000e+001,2.979968e+002,1.725006e-006,0.000000e+000,-5.994965e-001,0.000000e+000,3,1.239901e-001,1.825000e+000,,,,,,,,,,,,,,,,,,0,4.000000e+000,5.000000e-001,5,1,0.000000e+000,0,,0,
1405551133.703,,-2.000000e+001,2.979968e+002,1.735066e-006,0.000000e+000,-5.867208e-001,0.000000e+000,3,1.322490e-001,1.825000e+000,,,,,,,,,,,,,,,,,,0,4.000000e+000,5.000000e-001,5,1,0.000000e+000,0,,0,
1405551254.453,,-2.500000e+001,2.979968e+002,1.529460e-006,0.000000e+000,-7.336704e-001,0.000000e+000,3,1.658407e-001,1.825000e+000,,,,,,,,,,,,,,,,,,0,4.000000e+000,5.000000e-001,5,1,0.000000e+000,0,,0,
1405551272.687,,-2.500000e+001,2.979968e+002,1.559951e-006,0.000000e+000,-7.244648e-001,0.000000e+000,3,1.840085e-001,1.825000e+000,,,,,,,,,,,,,,,,,,0,4.000000e+000,5.000000e-001,5,1,0.000000e+000,0,,0,
1405551290.921,,-2.500000e+001,2.979968e+002,1.523619e-006,0.000000e+000,-7.373771e-001,0.000000e+000,3,1.618956e-001,1.825000e+000,,,,,,,,,,,,,,,,,,0,4.000000e+000,5.000000e-001,5,1,0.000000e+000,0,,0,
1405551410.171,,-3.000000e+001,2.980009e+002,1.500498e-006,0.000000e+000,-8.086095e-001,0.000000e+000,3,3.490050e-001,1.825000e+000,,,,,,,,,,,,,,,,,,0,4.000000e+000,5.000000e-001,5,1,8.209229e-003,0,,0,
1405551428.156,,-3.000000e+001,2.979968e+002,1.508103e-006,0.000000e+000,-8.084638e-001,0.000000e+000,3,3.559504e-001,1.825000e+000,,,,,,,,,,,,,,,,,,0,4.000000e+000,5.000000e-001,5,1,0.000000e+000,0,,0,
1405551445.890,,-3.000000e+001,2.979968e+002,1.481084e-006,0.000000e+000,-8.094835e-001,0.000000e+000,3,3.418544e-001,1.825000e+000,,,,,,,,,,,,,,,,,,0,4.000000e+000,5.000000e-001,5,1,0.000000e+000,0,,0,
1405551556.937,,-3.500000e+001,2.979968e+002,4.646742e-007,0.000000e+000,0.000000e+000,0.000000e+000,3,0.000000e+000,1.825000e+000,,,,,,,,,,,,,,,,,,0,4.000000e+000,5.000000e-001,5,1,0.000000e+000,0,,0,
1405551575.171,,-3.500000e+001,2.980009e+002,4.444834e-007,0.000000e+000,0.000000e+000,0.000000e+000,3,0.000000e+000,1.825000e+000,,,,,,,,,,,,,,,,,,0,4.000000e+000,5.000000e-001,5,1,8.209229e-003,0,,0,
1405551593.406,,-3.500000e+001,2.980050e+002,4.588215e-007,0.000000e+000,0.000000e+000,0.000000e+000,3,0.000000e+000,1.825000e+000,,,,,,,,,,,,,,,,,,0,4.000000e+000,5.000000e-001,5,1,0.000000e+000,0,,0,
1405551712.390,,-4.000000e+001,2.979968e+002,-3.616240e-008,0.000000e+000,1.170236e+000,0.000000e+000,3,0.000000e+000,1.825000e+000,,,,,,,,,,,,,,,,,,0,4.000000e+000,5.000000e-001,5,1,0.000000e+000,0,,0,
1405551729.875,,-4.000000e+001,2.980009e+002,-3.778005e-009,0.000000e+000,1.170821e+000,0.000000e+000,3,0.000000e+000,1.825000e+000,,,,,,,,,,,,,,,,,,0,4.000000e+000,5.000000e-001,5,1,8.209229e-003,0,,0,
1405551747.609,,-4.000000e+001,2.979968e+002,-4.445888e-009,0.000000e+000,1.170846e+000,0.000000e+000,3,0.000000e+000,1.825000e+000,,,,,,,,,,,,,,,,,,0,4.000000e+000,5.000000e-001,5,1,0.000000e+000,0,,0,
1405551865.609,,-4.500000e+001,2.979968e+002,-2.735913e-008,0.000000e+000,1.145269e+000,0.000000e+000,3,0.000000e+000,1.825000e+000,,,,,,,,,,,,,,,,,,0,4.000000e+000,5.000000e-001,5,1,1.651001e-002,0,,0,
1405551883.843,,-4.500000e+001,2.980009e+002,-1.081428e-008,0.000000e+000,1.147362e+000,0.000000e+000,3,0.000000e+000,1.825000e+000,,,,,,,,,,,,,,,,,,0,4.000000e+000,5.000000e-001,5,1,8.209229e-003,0,,0,
1405551902.078,,-4.500000e+001,2.980009e+002,3.400997e-009,0.000000e+000,1.145731e+000,0.000000e+000,3,0.000000e+000,1.825000e+000,,,,,,,,,,,,,,,,,,0,4.000000e+000,5.000000e-001,5,1,8.209229e-003,0,,0,
1405552021.828,,-5.000000e+001,2.980009e+002,-1.050369e-006,0.000000e+000,6.508822e-001,0.000000e+000,3,1.202793e-001,1.825000e+000,,,,,,,,,,,,,,,,,,0,4.000000e+000,5.000000e-001,5,1,8.209229e-003,0,,0,
1405552040.078,,-5.000000e+001,2.980009e+002,-1.054425e-006,0.000000e+000,6.647809e-001,0.000000e+000,3,1.118241e-001,1.825000e+000,,,,,,,,,,,,,,,,,,0,4.000000e+000,5.000000e-001,5,1,8.209229e-003,0,,0,
1405552058.312,,-5.000000e+001,2.980009e+002,-1.061376e-006,0.000000e+000,6.595188e-001,0.000000e+000,3,1.112471e-001,1.825000e+000,,,,,,,,,,,,,,,,,,0,4.000000e+000,5.000000e-001,5,1,8.209229e-003,0,,0,
1405552209.046,,-7.500000e+001,2.980009e+002,-2.998367e-006,0.000000e+000,2.514734e-001,0.000000e+000,3,8.584242e-001,1.825000e+000,,,,,,,,,,,,,,,,,,0,4.000000e+000,5.000000e-001,5,1,8.209229e-003,0,,0,
1405552226.531,,-7.500000e+001,2.980009e+002,-3.026256e-006,0.000000e+000,2.467576e-001,0.000000e+000,3,8.591359e-001,1.825000e+000,,,,,,,,,,,,,,,,,,0,4.000000e+000,5.000000e-001,5,1,8.209229e-003,0,,0,
1405552244.046,,-7.500000e+001,2.980009e+002,-3.015509e-006,0.000000e+000,2.471383e-001,0.000000e+000,3,8.542414e-001,1.825000e+000,,,,,,,,,,,,,,,,,,0,4.000000e+000,5.000000e-001,5,1,8.209229e-003,0,,0,
1405552394.265,,-1.000000e+002,2.980009e+002,-4.881202e-006,0.000000e+000,1.730262e-001,0.000000e+000,3,9.212251e-001,1.825000e+000,,,,,,,,,,,,,,,,,,0,4.000000e+000,5.000000e-001,5,1,8.209229e-003,0,,0,
1405552412.000,,-1.000000e+002,2.979968e+002,-4.826564e-006,0.000000e+000,1.714131e-001,0.000000e+000,3,9.141741e-001,1.825000e+000,,,,,,,,,,,,,,,,,,0,4.000000e+000,5.000000e-001,5,1,0.000000e+000,0,,0,
1405552430.250,,-1.000000e+002,2.979968e+002,-4.797838e-006,0.000000e+000,1.740956e-001,0.000000e+000,3,9.125091e-001,1.825000e+000,,,,,,,,,,,,,,,,,,0,4.000000e+000,5.000000e-001,5,1,0.000000e+000,0,,0,
1405552555.234,,-7.500000e+001,2.979968e+002,-3.610309e-006,0.000000e+000,2.053818e-001,0.000000e+000,3,9.031702e-001,1.825000e+000,,,,,,,,,,,,,,,,,,0,4.000000e+000,5.000000e-001,5,1,1.651001e-002,0,,0,
1405552573.718,,-7.500000e+001,2.979968e+002,-3.628930e-006,0.000000e+000,2.097883e-001,0.000000e+000,3,9.067107e-001,1.825000e+000,,,,,,,,,,,,,,,,,,0,4.000000e+000,5.000000e-001,5,1,0.000000e+000,0,,0,
1405552591.703,,-7.500000e+001,2.980009e+002,-3.611655e-006,0.000000e+000,2.046276e-001,0.000000e+000,3,9.044467e-001,1.825000e+000,,,,,,,,,,,,,,,,,,0,4.000000e+000,5.000000e-001,5,1,8.209229e-003,0,,0,
1405552723.703,,-5.000000e+001,2.979968e+002,-2.335572e-006,0.000000e+000,2.860950e-001,0.000000e+000,3,7.623572e-001,1.825000e+000,,,,,,,,,,,,,,,,,,0,4.000000e+000,5.000000e-001,5,1,1.651001e-002,0,,0,
1405552741.468,,-5.000000e+001,2.980009e+002,-2.327720e-006,0.000000e+000,2.877900e-001,0.000000e+000,3,7.608402e-001,1.825000e+000,,,,,,,,,,,,,,,,,,0,4.000000e+000,5.000000e-001,5,1,8.209229e-003,0,,0,
1405552759.203,,-5.000000e+001,2.980050e+002,-2.330665e-006,0.000000e+000,2.882029e-001,0.000000e+000,3,7.557198e-001,1.825000e+000,,,,,,,,,,,,,,,,,,0,4.000000e+000,5.000000e-001,5,1,0.000000e+000,0,,0,
1405552877.937,,-4.500000e+001,2.980009e+002,-2.079931e-006,0.000000e+000,3.135823e-001,0.000000e+000,3,7.041944e-001,1.825000e+000,,,,,,,,,,,,,,,,,,0,4.000000e+000,5.000000e-001,5,1,8.209229e-003,0,,0,
1405552896.718,,-4.500000e+001,2.979968e+002,-2.067944e-006,0.000000e+000,3.157727e-001,0.000000e+000,3,7.040935e-001,1.825000e+000,,,,,,,,,,,,,,,,,,0,4.000000e+000,5.000000e-001,5,1,0.000000e+000,0,,0,
1405552914.203,,-4.500000e+001,2.980009e+002,-2.073094e-006,0.000000e+000,3.183644e-001,0.000000e+000,3,6.994061e-001,1.825000e+000,,,,,,,,,,,,,,,,,,0,4.000000e+000,5.000000e-001,5,1,8.209229e-003,0,,0,
1405553032.015,,-4.000000e+001,2.980009e+002,-1.820322e-006,0.000000e+000,3.603221e-001,0.000000e+000,3,6.187727e-001,1.825000e+000,,,,,,,,,,,,,,,,,,0,4.000000e+000,5.000000e-001,5,1,8.209229e-003,0,,0,
1405553050.000,,-4.000000e+001,2.979968e+002,-1.828447e-006,0.000000e+000,3.587460e-001,0.000000e+000,3,6.189141e-001,1.825000e+000,,,,,,,,,,,,,,,,,,0,4.000000e+000,5.000000e-001,5,1,1.651001e-002,0,,0,
1405553068.250,,-4.000000e+001,2.979968e+002,-1.822079e-006,0.000000e+000,3.573916e-001,0.000000e+000,3,6.183341e-001,1.825000e+000,,,,,,,,,,,,,,,,,,0,4.000000e+000,5.000000e-001,5,1,1.651001e-002,0,,0,
1405553188.484,,-3.500000e+001,2.979968e+002,-1.584265e-006,0.000000e+000,4.155311e-001,0.000000e+000,3,5.089741e-001,1.825000e+000,,,,,,,,,,,,,,,,,,0,4.000000e+000,5.000000e-001,5,1,1.651001e-002,0,,0,
1405553206.718,,-3.500000e+001,2.979968e+002,-1.558877e-006,0.000000e+000,4.283969e-001,0.000000e+000,3,4.987673e-001,1.825000e+000,,,,,,,,,,,,,,,,,,0,4.000000e+000,5.000000e-001,5,1,0.000000e+000,0,,0,
1405553225.000,,-3.500000e+001,2.980050e+002,-1.572669e-006,0.000000e+000,4.138042e-001,0.000000e+000,3,5.068461e-001,1.825000e+000,,,,,,,,,,,,,,,,,,0,4.000000e+000,5.000000e-001,5,1,0.000000e+000,0,,0,
1405553345.000,,-3.000000e+001,2.979968e+002,-1.348201e-006,0.000000e+000,5.350170e-001,0.000000e+000,3,3.578874e-001,1.825000e+000,,,,,,,,,,,,,,,,,,0,4.000000e+000,5.000000e-001,5,1,0.000000e+000,0,,0,
1405553362.734,,-3.000000e+001,2.980050e+002,-1.338911e-006,0.000000e+000,5.382440e-001,0.000000e+000,3,3.424400e-001,1.825000e+000,,,,,,,,,,,,,,,,,,0,4.000000e+000,5.000000e-001,5,1,0.000000e+000,0,,0,
1405553380.468,,-3.000000e+001,2.980009e+002,-1.335785e-006,0.000000e+000,5.340660e-001,0.000000e+000,3,3.427387e-001,1.825000e+000,,,,,,,,,,,,,,,,,,0,4.000000e+000,5.000000e-001,5,1,8.209229e-003,0,,0,
1405553499.500,,-2.500000e+001,2.979968e+002,-1.048533e-006,0.000000e+000,7.800071e-001,0.000000e+000,3,9.091878e-003,1.825000e+000,,,,,,,,,,,,,,,,,,0,4.000000e+000,5.000000e-001,5,1,0.000000e+000,0,,0,
1405553517.781,,-2.500000e+001,2.979968e+002,-1.033238e-006,0.000000e+000,7.804615e-001,0.000000e+000,3,0.000000e+000,1.825000e+000,,,,,,,,,,,,,,,,,,0,4.000000e+000,5.000000e-001,5,1,0.000000e+000,0,,0,
1405553535.765,,-2.500000e+001,2.979968e+002,-1.046947e-006,0.000000e+000,7.854686e-001,0.000000e+000,3,8.146551e-003,1.825000e+000,,,,,,,,,,,,,,,,,,0,4.000000e+000,5.000000e-001,5,1,0.000000e+000,0,,0,
1405553654.515,,-2.000000e+001,2.979968e+002,-4.010808e-007,0.000000e+000,1.076600e+000,0.000000e+000,3,0.000000e+000,1.825000e+000,,,,,,,,,,,,,,,,,,0,4.000000e+000,5.000000e-001,5,1,1.651001e-002,0,,0,
1405553672.531,,-2.000000e+001,2.979968e+002,-4.121889e-007,0.000000e+000,1.074037e+000,0.000000e+000,3,0.000000e+000,1.825000e+000,,,,,,,,,,,,,,,,,,0,4.000000e+000,5.000000e-001,5,1,0.000000e+000,0,,0,
1405553690.015,,-2.000000e+001,2.980050e+002,-4.406070e-007,0.000000e+000,1.074620e+000,0.000000e+000,3,0.000000e+000,1.825000e+000,,,,,,,,,,,,,,,,,,0,4.000000e+000,5.000000e-001,5,1,0.000000e+000,0,,0,
1405553802.562,,-1.500000e+001,2.979968e+002,2.014471e-008,0.000000e+000,1.871788e+000,0.000000e+000,3,0.000000e+000,1.825000e+000,,,,,,,,,,,,,,,,,,0,4.000000e+000,5.000000e-001,5,1,0.000000e+000,0,,0,
1405553820.343,,-1.500000e+001,2.979968e+002,-4.453934e-008,0.000000e+000,0.000000e+000,0.000000e+000,3,0.000000e+000,1.825000e+000,,,,,,,,,,,,,,,,,,0,4.000000e+000,5.000000e-001,5,1,0.000000e+000,0,,0,
1405553838.093,,-1.500000e+001,2.980050e+002,8.079925e-010,0.000000e+000,1.900001e+000,0.000000e+000,3,0.000000e+000,1.825000e+000,,,,,,,,,,,,,,,,,,0,4.000000e+000,5.000000e-001,5,1,0.000000e+000,0,,0,
1405553957.093,,-1.000000e+001,2.980009e+002,2.639790e-007,0.000000e+000,0.000000e+000,0.000000e+000,3,0.000000e+000,1.825000e+000,,,,,,,,,,,,,,,,,,0,4.000000e+000,5.000000e-001,5,1,8.209229e-003,0,,0,
1405553975.328,,-1.000000e+001,2.979926e+002,2.659204e-007,0.000000e+000,0.000000e+000,0.000000e+000,3,0.000000e+000,1.825000e+000,,,,,,,,,,,,,,,,,,0,4.000000e+000,5.000000e-001,5,1,8.300781e-003,0,,0,
1405553993.562,,-1.000000e+001,2.979968e+002,2.728953e-007,0.000000e+000,0.000000e+000,0.000000e+000,3,0.000000e+000,1.825000e+000,,,,,,,,,,,,,,,,,,0,4.000000e+000,5.000000e-001,5,1,0.000000e+000,0,,0,
1405554112.546,,-5.000000e+000,2.980009e+002,5.920059e-007,0.000000e+000,0.000000e+000,0.000000e+000,3,0.000000e+000,1.825000e+000,,,,,,,,,,,,,,,,,,0,4.000000e+000,5.000000e-001,5,1,8.209229e-003,0,,0,
1405554130.531,,-5.000000e+000,2.980009e+002,6.052650e-007,0.000000e+000,0.000000e+000,0.000000e+000,3,0.000000e+000,1.825000e+000,,,,,,,,,,,,,,,,,,0,4.000000e+000,5.000000e-001,5,1,8.209229e-003,0,,0,
1405554147.765,,-5.000000e+000,2.980050e+002,6.017821e-007,0.000000e+000,0.000000e+000,0.000000e+000,3,0.000000e+000,1.825000e+000,,,,,,,,,,,,,,,,,,0,4.000000e+000,5.000000e-001,5,1,0.000000e+000,0,,0,
1405554266.515,,0.000000e+000,2.979968e+002,1.959088e-006,0.000000e+000,-7.468082e-001,0.000000e+000,3,4.918957e-001,1.825000e+000,,,,,,,,,,,,,,,,,,0,4.000000e+000,5.000000e-001,5,1,0.000000e+000,0,,0,
1405554284.265,,0.000000e+000,2.979968e+002,1.969079e-006,0.000000e+000,-7.446787e-001,0.000000e+000,3,4.939114e-001,1.825000e+000,,,,,,,,,,,,,,,,,,0,4.000000e+000,5.000000e-001,5,1,0.000000e+000,0,,0,
1405554302.000,,0.000000e+000,2.980009e+002,1.959634e-006,0.000000e+000,-7.494886e-001,0.000000e+000,3,4.892914e-001,1.825000e+000,,,,,,,,,,,,,,,,,,0,4.000000e+000,5.000000e-001,5,1,8.209229e-003,0,,0,
1405554420.281,,5.000000e+000,2.980050e+002,2.138264e-006,0.000000e+000,-6.688808e-001,0.000000e+000,3,4.633441e-001,1.825000e+000,,,,,,,,,,,,,,,,,,0,4.000000e+000,5.000000e-001,5,1,0.000000e+000,0,,0,
1405554438.062,,5.000000e+000,2.979926e+002,2.128913e-006,0.000000e+000,-6.758647e-001,0.000000e+000,3,4.579882e-001,1.825000e+000,,,,,,,,,,,,,,,,,,0,4.000000e+000,5.000000e-001,5,1,8.300781e-003,0,,0,
1405554455.359,,5.000000e+000,2.980009e+002,2.138569e-006,0.000000e+000,-6.748796e-001,0.000000e+000,3,4.588596e-001,1.825000e+000,,,,,,,,,,,,,,,,,,0,4.000000e+000,5.000000e-001,5,1,8.209229e-003,0,,0,
1405554580.609,,1.000000e+001,2.979926e+002,2.338548e-006,0.000000e+000,-5.965429e-001,0.000000e+000,3,4.412007e-001,1.825000e+000,,,,,,,,,,,,,,,,,,0,4.000000e+000,5.000000e-001,5,1,8.300781e-003,0,,0,
1405554598.343,,1.000000e+001,2.979968e+002,2.350313e-006,0.000000e+000,-5.981690e-001,0.000000e+000,3,4.446675e-001,1.825000e+000,,,,,,,,,,,,,,,,,,0,4.000000e+000,5.000000e-001,5,1,0.000000e+000,0,,0,
1405554616.078,,1.000000e+001,2.979968e+002,2.332142e-006,0.000000e+000,-5.957046e-001,0.000000e+000,3,4.367872e-001,1.825000e+000,,,,,,,,,,,,,,,,,,0,4.000000e+000,5.000000e-001,5,1,0.000000e+000,0,,0,
1405554734.843,,1.500000e+001,2.980009e+002,2.569129e-006,0.000000e+000,-5.084011e-001,0.000000e+000,3,4.350370e-001,1.825000e+000,,,,,,,,,,,,,,,,,,0,4.000000e+000,5.000000e-001,5,1,8.209229e-003,0,,0,
1405554752.078,,1.500000e+001,2.980009e+002,2.562892e-006,0.000000e+000,-5.111836e-001,0.000000e+000,3,4.345487e-001,1.825000e+000,,,,,,,,,,,,,,,,,,0,4.000000e+000,5.000000e-001,5,1,8.209229e-003,0,,0,
1405554770.812,,1.500000e+001,2.979926e+002,2.569614e-006,0.000000e+000,-5.060101e-001,0.000000e+000,3,4.363835e-001,1.825000e+000,,,,,,,,,,,,,,,,,,0,4.000000e+000,5.000000e-001,5,1,8.300781e-003,0,,0,
1405554889.625,,2.000000e+001,2.980050e+002,2.817206e-006,0.000000e+000,-4.251085e-001,0.000000e+000,3,4.392966e-001,1.825000e+000,,,,,,,,,,,,,,,,,,0,4.000000e+000,5.000000e-001,5,1,0.000000e+000,0,,0,
1405554907.921,,2.000000e+001,2.980009e+002,2.807933e-006,0.000000e+000,-4.232845e-001,0.000000e+000,3,4.379906e-001,1.825000e+000,,,,,,,,,,,,,,,,,,0,4.000000e+000,5.000000e-001,5,1,8.209229e-003,0,,0,
1405554925.687,,2.000000e+001,2.979968e+002,2.816849e-006,0.000000e+000,-4.231128e-001,0.000000e+000,3,4.385116e-001,1.825000e+000,,,,,,,,,,,,,,,,,,0,4.000000e+000,5.000000e-001,5,1,0.000000e+000,0,,0,
1405555044.234,,2.500000e+001,2.980050e+002,3.079590e-006,0.000000e+000,-3.186454e-001,0.000000e+000,3,4.418951e-001,1.825000e+000,,,,,,,,,,,,,,,,,,0,4.000000e+000,5.000000e-001,5,1,0.000000e+000,0,,0,
1405555061.500,,2.500000e+001,2.979926e+002,3.089996e-006,0.000000e+000,-3.204789e-001,0.000000e+000,3,4.407195e-001,1.825000e+000,,,,,,,,,,,,,,,,,,0,4.000000e+000,5.000000e-001,5,1,8.300781e-003,0,,0,
1405555079.750,,2.500000e+001,2.979968e+002,3.085541e-006,0.000000e+000,-3.172828e-001,0.000000e+000,3,4.418180e-001,1.825000e+000,,,,,,,,,,,,,,,,,,0,4.000000e+000,5.000000e-001,5,1,0.000000e+000,0,,0,
1405555197.250,,3.000000e+001,2.979968e+002,3.407311e-006,0.000000e+000,-2.386900e-001,0.000000e+000,3,4.559619e-001,1.825000e+000,,,,,,,,,,,,,,,,,,0,4.000000e+000,5.000000e-001,5,1,0.000000e+000,0,,0,
1405555215.484,,3.000000e+001,2.980009e+002,3.426269e-006,0.000000e+000,-2.412484e-001,0.000000e+000,3,4.562399e-001,1.825000e+000,,,,,,,,,,,,,,,,,,0,4.000000e+000,5.000000e-001,5,1,8.209229e-003,0,,0,
1405555233.218,,3.000000e+001,2.980009e+002,3.415569e-006,0.000000e+000,-2.368873e-001,0.000000e+000,3,4.576962e-001,1.825000e+000,,,,,,,,,,,,,,,,,,0,4.000000e+000,5.000000e-001,5,1,8.209229e-003,0,,0,
1405555346.453,,3.500000e+001,2.980009e+002,3.779907e-006,0.000000e+000,-1.438712e-001,0.000000e+000,3,4.665239e-001,1.825000e+000,,,,,,,,,,,,,,,,,,0,4.000000e+000,5.000000e-001,5,1,8.209229e-003,0,,0,
1405555364.515,,3.500000e+001,2.980009e+002,3.783382e-006,0.000000e+000,-1.474500e-001,0.000000e+000,3,4.669543e-001,1.825000e+000,,,,,,,,,,,,,,,,,,0,4.000000e+000,5.000000e-001,5,1,8.209229e-003,0,,0,
1405555382.000,,3.500000e+001,2.979968e+002,3.775074e-006,0.000000e+000,-1.481772e-001,0.000000e+000,3,4.694080e-001,1.825000e+000,,,,,,,,,,,,,,,,,,0,4.000000e+000,5.000000e-001,5,1,0.000000e+000,0,,0,
1405555499.750,,4.000000e+001,2.980009e+002,4.178933e-006,0.000000e+000,-1.008438e-001,0.000000e+000,3,4.844239e-001,1.825000e+000,,,,,,,,,,,,,,,,,,0,4.000000e+000,5.000000e-001,5,1,8.209229e-003,0,,0,
1405555517.484,,4.000000e+001,2.980009e+002,4.168680e-006,0.000000e+000,-9.656829e-002,0.000000e+000,3,4.867223e-001,1.825000e+000,,,,,,,,,,,,,,,,,,0,4.000000e+000,5.000000e-001,5,1,8.209229e-003,0,,0,
1405555535.218,,4.000000e+001,2.980009e+002,4.172918e-006,0.000000e+000,-9.535675e-002,0.000000e+000,3,4.868262e-001,1.825000e+000,,,,,,,,,,,,,,,,,,0,4.000000e+000,5.000000e-001,5,1,8.209229e-003,0,,0,
1405555645.953,,4.500000e+001,2.979968e+002,4.607692e-006,0.000000e+000,-2.548911e-002,0.000000e+000,3,4.993182e-001,1.825000e+000,,,,,,,,,,,,,,,,,,0,4.000000e+000,5.000000e-001,5,1,0.000000e+000,0,,0,
1405555663.187,,4.500000e+001,2.980009e+002,4.607472e-006,0.000000e+000,-2.742752e-002,0.000000e+000,3,4.990715e-001,1.825000e+000,,,,,,,,,,,,,,,,,,0,4.000000e+000,5.000000e-001,5,1,8.209229e-003,0,,0,
1405555681.171,,4.500000e+001,2.979968e+002,4.615846e-006,0.000000e+000,-2.319465e-002,0.000000e+000,3,4.991579e-001,1.825000e+000,,,,,,,,,,,,,,,,,,0,4.000000e+000,5.000000e-001,5,1,0.000000e+000,0,,0,
1405555800.671,,5.000000e+001,2.979968e+002,4.889028e-006,0.000000e+000,-2.308073e-002,0.000000e+000,3,5.204754e-001,1.825000e+000,,,,,,,,,,,,,,,,,,0,4.000000e+000,5.000000e-001,5,1,1.651001e-002,0,,0,
1405555818.406,,5.000000e+001,2.979926e+002,4.888915e-006,0.000000e+000,-2.479972e-002,0.000000e+000,3,5.212087e-001,1.825000e+000,,,,,,,,,,,,,,,,,,0,4.000000e+000,5.000000e-001,5,1,8.300781e-003,0,,0,
1405555837.140,,5.000000e+001,2.979968e+002,4.896854e-006,0.000000e+000,-2.350173e-002,0.000000e+000,3,5.208756e-001,1.825000e+000,,,,,,,,,,,,,,,,,,0,4.000000e+000,5.000000e-001,5,1,0.000000e+000,0,,0,
1405555960.375,,7.500000e+001,2.979968e+002,6.933998e-006,0.000000e+000,8.098931e-002,0.000000e+000,3,5.630122e-001,1.825000e+000,,,,,,,,,,,,,,,,,,0,4.000000e+000,5.000000e-001,5,1,0.000000e+000,0,,0,
1405555979.171,,7.500000e+001,2.980009e+002,6.948469e-006,0.000000e+000,8.066151e-002,0.000000e+000,3,5.643114e-001,1.825000e+000,,,,,,,,,,,,,,,,,,0,4.000000e+000,5.000000e-001,5,1,8.209229e-003,0,,0,
1405555996.468,,7.500000e+001,2.979968e+002,6.947262e-006,0.000000e+000,7.770424e-002,0.000000e+000,3,5.625955e-001,1.825000e+000,,,,,,,,,,,,,,,,,,0,4.000000e+000,5.000000e-001,5,1,0.000000e+000,0,,0,
1405556128.890,,1.000000e+002,2.980009e+002,9.085345e-006,0.000000e+000,8.188367e-002,0.000000e+000,3,6.042558e-001,1.825000e+000,,,,,,,,,,,,,,,,,,0,4.000000e+000,5.000000e-001,5,1,8.209229e-003,0,,0,
1405556146.968,,1.000000e+002,2.979968e+002,9.109202e-006,0.000000e+000,8.308011e-002,0.000000e+000,3,6.053090e-001,1.825000e+000,,,,,,,,,,,,,,,,,,0,4.000000e+000,5.000000e-001,5,1,0.000000e+000,0,,0,
1405556165.203,,1.000000e+002,2.979968e+002,9.132644e-006,0.000000e+000,8.285228e-002,0.000000e+000,3,6.071691e-001,1.825000e+000,,,,,,,,,,,,,,,,,,0,4.000000e+000,5.000000e-001,5,1,0.000000e+000,0,,0,