File: Sample Data Files/2014-07-16 EB on isolated PMN-PT no Ti spontaneous in situ/Ni-NiO_298K_SiO2_PMN-PT_5.0Tprebias_200V_Au_back.rso.raw
[Header]
TITLE,MPMS RSO Measurement
BYAPP,MPMS Measurement,2.1,Raw with ABS
FILEOPENTIME, 1405566236.062000 7/16/2014, 8:03:56 PM

INFO, APPNAME, MPMS MultiVu Application, Revision 1.58,  Build 076

INFO, NAME, EB in situ
INFO, WEIGHT, 0.000
INFO, AREA, 0.000
INFO, LENGTH, 0.000
INFO, SHAPE, 0
INFO, COMMENT,
INFO, SEQUENCE FILE: MHcurveUpTo100.seq


INFO, BACKGROUND DATA FILE:, None


STARTUPAXIS,X,8,LINEAR,AUTO,0.000000,0.000000
STARTUPAXIS,Y1,9,LINEAR,AUTO,0.000000,0.000000


STARTUPGROUP,Longitudinal
FIELDGROUP,Longitudinal,1,2,3,4,5,6,7,8,9,10,11,12,13,14,15,16,17,18,19,20,21,22
FIELDGROUP,Transverse,1,2,3,4,5,6,7,8,23,24,25,26,27,28,29,30,31,32,33,34,35,36

PLOT_APPEARANCE,ALL,HORZ_GRID_ON,VERT_GRID_ON,MARKERS_ONLY

[Data]
Time,Comment,Field (Oe),Start Temperature (K),End Temperature (K),Scan,Rejected,Position (cm),Long Voltage,Long Average Voltage,Long Detrended Voltage,Long Demeaned Voltage,Long Reg Fit,Long Detrended Fit,Long Demeaned Fit,Long Scaled Response,Long Avg. Scaled Response,Long Background Response,Long Response [w/ABS],Long Detrended Resp. [w/ABS],Long Fit [w/ABS],Long Detrended Fit [w/ABS],Trans Voltage,Trans Average Voltage,Trans Detrended Voltage,Trans Demeaned Voltage,Trans Reg Fit,Trans Detrended Fit,Trans Demeaned Fit,Trans Scaled Response,Trans Avg. Scaled Response,Trans Background Response,Trans Response [w/ABS],Trans Detrended Resp. [w/ABS],Trans Adjusted Fit,Trans Detrended Fit [w/ABS],
1405566236.046,,1.000000e+002,2.980050e+002,2.980050e+002,1,0,2.079396e+000,-3.555406e-002,-3.555406e-002,8.294190e-001,8.294190e-001,1.679965e-002,8.817726e-001,8.817726e-001,-1.549623e-006,-1.549623e-006,,,,,,,,,,,,,,,,,,,,
1405566236.046,,1.000000e+002,2.980050e+002,2.980050e+002,1,0,3.705854e+000,-1.190680e+000,-1.190680e+000,-3.944979e-001,-3.257067e-001,-1.182121e+000,-3.859390e-001,-3.171478e-001,-5.189573e-005,-5.189573e-005,,,,,,,,,,,,,,,,,,,,
1405566254.531,,1.000000e+002,2.980050e+002,2.979968e+002,1,0,4.360382e-001,-1.195410e+000,-1.195410e+000,-3.748136e-001,-3.389392e-001,-1.207602e+000,-3.870059e-001,-3.511314e-001,-5.210190e-005,-5.210190e-005,,,,,,,,,,,,,,,,,,,,
1405566271.265,,1.000000e+002,2.979968e+002,2.979968e+002,1,0,1.899729e+000,-4.913480e-002,-4.913480e-002,8.052921e-001,8.069299e-001,8.413631e-003,8.628406e-001,8.644783e-001,-2.141539e-006,-2.141539e-006,,,,,,,,,,,,,,,,,,,,
1405566271.265,,1.000000e+002,2.979968e+002,2.979968e+002,1,0,3.810106e+000,-1.202124e+000,-1.202124e+000,-4.181224e-001,-3.460594e-001,-1.152427e+000,-3.684254e-001,-2.963623e-001,-5.239453e-005,-5.239453e-005,,,,,,,,,,,,,,,,,,,,
1405566396.515,,7.500000e+001,2.979968e+002,2.980050e+002,1,0,5.564155e-001,-9.930723e-001,-9.930723e-001,-2.690525e-001,-2.385254e-001,-1.034111e+000,-3.100915e-001,-2.795644e-001,-4.328312e-005,-4.328312e-005,,,,,,,,,,,,,,,,,,,,
1405566414.265,,7.500000e+001,2.979968e+002,2.979968e+002,1,0,1.718970e+000,-1.361126e-001,-1.361126e-001,6.019963e-001,6.047533e-001,-1.195120e-001,6.185969e-001,6.213539e-001,-5.932474e-006,-5.932474e-006,,,,,,,,,,,,,,,,,,,,
1405566414.265,,7.500000e+001,2.979968e+002,2.979968e+002,1,0,3.893703e+000,-1.051515e+000,-1.051515e+000,-3.726827e-001,-3.106493e-001,-9.742566e-001,-2.954240e-001,-2.333907e-001,-4.583036e-005,-4.583036e-005,,,,,,,,,,,,,,,,,,,,
1405566432.000,,7.500000e+001,2.980132e+002,2.979968e+002,1,0,6.833810e-001,-9.125034e-001,-9.125034e-001,-1.990185e-001,-1.661274e-001,-9.758531e-001,-2.623683e-001,-2.294771e-001,-3.977152e-005,-3.977152e-005,,,,,,,,,,,,,,,,,,,,
1405566563.000,,5.000000e+001,2.979968e+002,2.979968e+002,1,0,1.538599e+000,-2.299570e-001,-2.299570e-001,3.855466e-001,3.890094e-001,-2.578089e-001,3.576947e-001,3.611575e-001,-1.002271e-005,-1.002271e-005,,,,,,,,,,,,,,,,,,,,
1405566563.000,,5.000000e+001,2.979968e+002,2.979968e+002,1,0,3.953432e+000,-8.813745e-001,-8.813745e-001,-3.155050e-001,-2.624081e-001,-7.931151e-001,-2.272456e-001,-1.741487e-001,-3.841485e-005,-3.841485e-005,,,,,,,,,,,,,,,,,,,,
1405566580.750,,5.000000e+001,2.980050e+002,2.979968e+002,1,0,8.158605e-001,-6.616413e-001,-6.616413e-001,-8.898068e-002,-5.921572e-002,-7.289776e-001,-1.563169e-001,-1.265520e-001,-2.883774e-005,-2.883774e-005,,,,,,,,,,,,,,,,,,,,
1405566599.031,,5.000000e+001,2.979968e+002,2.979968e+002,1,0,1.361191e+000,-3.201391e-001,-3.201392e-001,2.809253e-001,2.857130e-001,-3.843182e-001,2.167463e-001,2.215340e-001,-1.395332e-005,-1.395332e-005,,,,,,,,,,,,,,,,,,,,
1405566599.031,,5.000000e+001,2.979968e+002,2.979968e+002,1,0,3.987510e+000,-8.719138e-001,-8.719138e-001,-3.223176e-001,-2.660616e-001,-7.686637e-001,-2.190675e-001,-1.628115e-001,-3.800250e-005,-3.800250e-005,,,,,,,,,,,,,,,,,,,,
1405566712.031,,4.500000e+001,2.979968e+002,2.979968e+002,1,0,9.540649e-001,-5.516220e-001,-5.516220e-001,-3.124470e-003,2.598244e-002,-6.232725e-001,-7.477491e-002,-4.566801e-002,-2.404255e-005,-2.404255e-005,,,,,,,,,,,,,,,,,,,,
1405566729.765,,4.500000e+001,2.979968e+002,2.979968e+002,1,0,1.187303e+000,-4.048280e-001,-4.048280e-001,1.596858e-001,1.656003e-001,-4.869751e-001,7.753867e-002,8.345324e-002,-1.764450e-005,-1.764450e-005,,,,,,,,,,,,,,,,,,,,
1405566729.765,,4.500000e+001,2.979968e+002,2.979968e+002,1,0,3.994495e+000,-8.239998e-001,-8.239998e-001,-3.103512e-001,-2.535714e-001,-7.205649e-001,-2.069164e-001,-1.501365e-001,-3.591418e-005,-3.591418e-005,,,,,,,,,,,,,,,,,,,,
1405566747.250,,4.500000e+001,2.980050e+002,2.980050e+002,1,0,1.098494e+000,-4.431288e-001,-4.431288e-001,8.760646e-002,1.183895e-001,-5.142093e-001,1.652595e-002,4.730898e-002,-1.931385e-005,-1.931385e-005,,,,,,,,,,,,,,,,,,,,
1405566867.750,,4.000000e+001,2.979968e+002,2.980050e+002,1,0,1.018093e+000,-4.829554e-001,-4.829554e-001,5.353692e-002,6.007805e-002,-5.717788e-001,-3.528649e-002,-2.874535e-002,-2.104971e-005,-2.104971e-005,,,,,,,,,,,,,,,,,,,,
1405566867.750,,4.000000e+001,2.979968e+002,2.980050e+002,1,0,3.974661e+000,-7.844782e-001,-7.844783e-001,-2.948641e-001,-2.414448e-001,-6.896151e-001,-2.000009e-001,-1.465816e-001,-3.419165e-005,-3.419165e-005,,,,,,,,,,,,,,,,,,,,
1405566885.734,,4.000000e+001,2.979968e+002,2.979968e+002,1,0,1.249709e+000,-3.415021e-001,-3.415021e-001,1.727389e-001,2.033720e-001,-4.015606e-001,1.126805e-001,1.433136e-001,-1.488444e-005,-1.488444e-005,,,,,,,,,,,,,,,,,,,,
1405566903.468,,4.000000e+001,2.979968e+002,2.979885e+002,1,0,8.552613e-001,-5.458235e-001,-5.458235e-001,-3.379706e-002,-2.579433e-002,-6.361679e-001,-1.241415e-001,-1.161388e-001,-2.378983e-005,-2.378983e-005,,,,,,,,,,,,,,,,,,,,
1405566903.468,,4.000000e+001,2.979968e+002,2.979885e+002,1,0,3.929973e+000,-7.544175e-001,-7.544175e-001,-2.915508e-001,-2.343884e-001,-6.722251e-001,-2.093583e-001,-1.521959e-001,-3.288144e-005,-3.288144e-005,,,,,,,,,,,,,,,,,,,,
1405567025.718,,3.500000e+001,2.979968e+002,2.980050e+002,1,0,1.407841e+000,-2.459792e-001,-2.459792e-001,2.423366e-001,2.721896e-001,-2.821994e-001,2.061164e-001,2.359694e-001,-1.072106e-005,-1.072106e-005,,,,,,,,,,,,,,,,,,,,
1405567042.953,,3.500000e+001,2.980050e+002,2.980050e+002,1,0,6.991088e-001,-6.137272e-001,-6.137272e-001,-1.050649e-001,-9.652489e-002,-6.878871e-001,-1.792248e-001,-1.706848e-001,-2.674944e-005,-2.674944e-005,,,,,,,,,,,,,,,,,,,,
1405567042.953,,3.500000e+001,2.980050e+002,2.980050e+002,1,0,3.862945e+000,-7.325968e-001,-7.325968e-001,-2.698371e-001,-2.153945e-001,-6.709699e-001,-2.082101e-001,-1.537676e-001,-3.193039e-005,-3.193039e-005,,,,,,,,,,,,,,,,,,,,
1405567060.703,,3.500000e+001,2.980050e+002,2.979885e+002,1,0,1.573240e+000,-1.499985e-001,-1.499985e-001,3.205352e-001,3.537355e-001,-1.539348e-001,3.165989e-001,3.497992e-001,-6.537717e-006,-6.537717e-006,,,,,,,,,,,,,,,,,,,,
1405567179.468,,3.000000e+001,2.980050e+002,2.979968e+002,1,0,5.524858e-001,-6.389050e-001,-6.389050e-001,-1.505403e-001,-1.418352e-001,-6.890416e-001,-2.006769e-001,-1.919717e-001,-2.784683e-005,-2.784683e-005,,,,,,,,,,,,,,,,,,,,
1405567179.468,,3.000000e+001,2.980050e+002,2.979968e+002,1,0,3.777341e+000,-6.863613e-001,-6.863613e-001,-2.395878e-001,-1.892914e-001,-6.519491e-001,-2.051757e-001,-1.548793e-001,-2.991522e-005,-2.991522e-005,,,,,,,,,,,,,,,,,,,,
1405567196.953,,3.000000e+001,2.979968e+002,2.980050e+002,1,0,1.744776e+000,-9.674367e-002,-9.674367e-002,3.528969e-001,3.850490e-001,-5.872164e-002,3.909189e-001,4.230711e-001,-4.216597e-006,-4.216597e-006,,,,,,,,,,,,,,,,,,,,
1405567215.437,,3.000000e+001,2.979968e+002,2.979968e+002,1,0,4.167976e-001,-6.433302e-001,-6.433302e-001,-1.849306e-001,-1.745099e-001,-6.673817e-001,-2.089821e-001,-1.985614e-001,-2.803970e-005,-2.803970e-005,,,,,,,,,,,,,,,,,,,,
1405567215.437,,3.000000e+001,2.979968e+002,2.979968e+002,1,0,3.676875e+000,-6.280709e-001,-6.280710e-001,-2.144804e-001,-1.592506e-001,-6.225784e-001,-2.089879e-001,-1.537581e-001,-2.737462e-005,-2.737462e-005,,,,,,,,,,,,,,,,,,,,
1405567334.171,,2.500000e+001,2.979968e+002,2.980050e+002,1,0,1.921368e+000,-6.759850e-002,-6.759850e-002,3.598309e-001,3.897364e-001,-1.578558e-003,4.258509e-001,4.557563e-001,-2.946298e-006,-2.946298e-006,,,,,,,,,,,,,,,,,,,,
1405567352.468,,2.500000e+001,2.980050e+002,2.980050e+002,1,0,2.952246e-001,-6.239509e-001,-6.239509e-001,-1.964691e-001,-1.855130e-001,-6.138557e-001,-1.863738e-001,-1.754178e-001,-2.719506e-005,-2.719506e-005,,,,,,,,,,,,,,,,,,,,
1405567352.468,,2.500000e+001,2.980050e+002,2.980050e+002,1,0,3.565038e+000,-5.557420e-001,-5.557421e-001,-1.710886e-001,-1.173042e-001,-5.710796e-001,-1.864261e-001,-1.326416e-001,-2.422216e-005,-2.422216e-005,,,,,,,,,,,,,,,,,,,,
1405567370.203,,2.500000e+001,2.980050e+002,2.980050e+002,1,0,2.101068e+000,-2.929777e-002,-2.929777e-002,3.717271e-001,4.058024e-001,3.954102e-002,4.405659e-001,4.746412e-001,-1.276951e-006,-1.276951e-006,,,,,,,,,,,,,,,,,,,,
1405567481.453,,2.000000e+001,2.979968e+002,2.979968e+002,1,0,1.908966e-001,-6.210517e-001,-6.210517e-001,-1.986896e-001,-1.878746e-001,-5.804887e-001,-1.581267e-001,-1.473117e-001,-2.706871e-005,-2.706871e-005,,,,,,,,,,,,,,,,,,,,
1405567481.453,,2.000000e+001,2.979968e+002,2.979968e+002,1,0,3.444669e+000,-4.980621e-001,-4.980621e-001,-1.144535e-001,-6.488505e-002,-5.338429e-001,-1.502344e-001,-1.006659e-001,-2.170818e-005,-2.170818e-005,,,,,,,,,,,,,,,,,,,,
1405567498.500,,2.000000e+001,2.980050e+002,2.979968e+002,1,0,2.281982e+000,-4.364147e-002,-4.364147e-002,3.274629e-001,3.583374e-001,-2.456605e-003,3.686478e-001,3.995222e-001,-1.902126e-006,-1.902126e-006,,,,,,,,,,,,,,,,,,,,
1405567516.734,,2.000000e+001,2.980050e+002,2.979968e+002,1,0,1.073525e-001,-5.856502e-001,-5.856502e-001,-2.081488e-001,-1.953780e-001,-5.223708e-001,-1.448694e-001,-1.320986e-001,-2.552573e-005,-2.552573e-005,,,,,,,,,,,,,,,,,,,,
1405567516.734,,2.000000e+001,2.980050e+002,2.979968e+002,1,0,3.317779e+000,-3.985718e-001,-3.985717e-001,-6.331208e-002,-8.299559e-003,-4.498025e-001,-1.145429e-001,-5.953035e-002,-1.737186e-005,-1.737186e-005,,,,,,,,,,,,,,,,,,,,
1405567635.718,,1.500000e+001,2.979968e+002,2.979968e+002,1,0,2.462261e+000,-9.231850e-002,-9.231849e-002,2.729765e-001,3.012192e-001,-9.823857e-002,2.670564e-001,2.952991e-001,-4.023730e-006,-4.023730e-006,,,,,,,,,,,,,,,,,,,,
1405567653.953,,1.500000e+001,2.979968e+002,2.979968e+002,1,0,4.751218e-002,-5.522324e-001,-5.522324e-001,-1.973274e-001,-1.850443e-001,-4.758796e-001,-1.209746e-001,-1.086915e-001,-2.406922e-005,-2.406922e-005,,,,,,,,,,,,,,,,,,,,
1405567653.953,,1.500000e+001,2.979968e+002,2.979968e+002,1,0,3.185182e+000,-3.115940e-001,-3.115940e-001,5.584274e-003,5.559418e-002,-3.740593e-001,-5.688101e-002,-6.871104e-003,-1.358092e-005,-1.358092e-005,,,,,,,,,,,,,,,,,,,,
1405567671.687,,1.500000e+001,2.980050e+002,2.979885e+002,1,0,2.639822e+000,-9.582812e-002,-9.582812e-002,2.300415e-001,2.628372e-001,-1.425321e-001,1.833375e-001,2.161333e-001,-4.176698e-006,-4.176698e-006,,,,,,,,,,,,,,,,,,,,
1405567788.187,,1.000000e+001,2.980050e+002,2.979968e+002,1,0,1.351938e-002,-5.258339e-001,-5.258339e-001,-1.856297e-001,-1.752610e-001,-4.415916e-001,-1.013874e-001,-9.101871e-002,-2.291864e-005,-2.291864e-005,,,,,,,,,,,,,,,,,,,,
1405567788.187,,1.000000e+001,2.980050e+002,2.979968e+002,1,0,3.046884e+000,-2.450636e-001,-2.450636e-001,6.541683e-002,1.055093e-001,-3.093010e-001,1.179441e-003,4.127190e-002,-1.068118e-005,-1.068118e-005,,,,,,,,,,,,,,,,,,,,
1405567805.921,,1.000000e+001,2.979968e+002,2.979968e+002,1,0,2.813703e+000,-1.544237e-001,-1.544237e-001,1.651561e-001,1.947328e-001,-2.265755e-001,9.300420e-002,1.225810e-001,-6.730605e-006,-6.730605e-006,,,,,,,,,,,,,,,,,,,,
1405567841.187,,1.000000e+001,2.979968e+002,2.979968e+002,1,0,6.615223e-003,-9.814752e-001,-9.814753e-001,-3.730645e-001,-3.458602e-001,-8.081884e-001,-1.997777e-001,-1.725733e-001,-2.138896e-005,-2.138896e-005,,,,,,,,,,,,,,,,,,,,
1405567841.187,,1.000000e+001,2.979968e+002,2.979968e+002,1,0,2.902575e+000,-2.990814e-001,-2.990814e-001,2.362176e-001,3.365337e-001,-4.215691e-001,1.137299e-001,2.140460e-001,-6.517780e-006,-6.517780e-006,,,,,,,,,,,,,,,,,,,,
1405567960.421,,5.000000e+000,2.980050e+002,2.979885e+002,1,0,2.982931e+000,-3.363140e-001,-3.363140e-001,2.031523e-001,2.475177e-001,-4.877165e-001,5.174975e-002,9.611520e-002,-7.329180e-006,-7.329180e-006,,,,,,,,,,,,,,,,,,,,
1405567978.156,,5.000000e+000,2.979968e+002,2.979968e+002,1,0,2.638341e-002,-8.407850e-001,-8.407849e-001,-3.394547e-001,-3.154258e-001,-6.752189e-001,-1.738887e-001,-1.498598e-001,-1.832295e-005,-1.832295e-005,,,,,,,,,,,,,,,,,,,,
1405567978.156,,5.000000e+000,2.979968e+002,2.979968e+002,1,0,2.751445e+000,-1.422163e-001,-1.422163e-001,2.983350e-001,3.831428e-001,-2.276502e-001,2.129011e-001,2.977089e-001,-3.099272e-006,-3.099272e-006,,,,,,,,,,,,,,,,,,,,
1405567995.390,,5.000000e+000,2.979968e+002,2.979968e+002,1,0,3.145850e+000,-3.965880e-001,-3.965880e-001,9.140757e-002,1.493260e-001,-5.400424e-001,-5.204680e-002,5.871654e-003,-8.642713e-006,-8.642713e-006,,,,,,,,,,,,,,,,,,,,
1405568114.140,,0.000000e+000,2.980050e+002,2.980050e+002,1,0,7.107658e-002,-7.699820e-001,-7.699820e-001,-2.889971e-001,-2.672875e-001,-6.288130e-001,-1.478281e-001,-1.261185e-001,-1.677997e-005,-1.677997e-005,,,,,,,,,,,,,,,,,,,,
1405568114.140,,0.000000e+000,2.980050e+002,2.980050e+002,1,0,2.593071e+000,-1.324503e-001,-1.324503e-001,2.966727e-001,3.702441e-001,-1.502010e-001,2.789221e-001,3.524935e-001,-2.886448e-006,-2.886448e-006,,,,,,,,,,,,,,,,,,,,
1405568131.875,,0.000000e+000,2.979968e+002,2.979968e+002,1,0,3.301689e+000,-4.428236e-001,-4.428236e-001,7.191013e-003,5.401829e-002,-5.550416e-001,-1.050270e-001,-5.819970e-002,-9.650313e-006,-9.650313e-006,,,,,,,,,,,,,,,,,,,,
1405568149.109,,0.000000e+000,2.979968e+002,2.979968e+002,1,0,1.380381e-001,-7.107761e-001,-7.107761e-001,-2.697797e-001,-2.448928e-001,-6.003043e-001,-1.593079e-001,-1.344210e-001,-1.548972e-005,-1.548972e-005,,,,,,,,,,,,,,,,,,,,
1405568149.109,,0.000000e+000,2.979968e+002,2.979968e+002,1,0,2.427760e+000,-7.415998e-002,-7.415998e-002,3.105135e-001,3.917233e-001,-1.671554e-002,3.679579e-001,4.491678e-001,-1.616145e-006,-1.616145e-006,,,,,,,,,,,,,,,,,,,,
1405568267.656,,-5.000000e+000,2.979968e+002,2.979968e+002,1,0,3.448642e+000,-4.039125e-001,-4.039125e-001,-3.913615e-002,-2.185285e-003,-4.735103e-001,-1.087340e-001,-7.178313e-002,-8.802332e-006,-8.802332e-006,,,,,,,,,,,,,,,,,,,,
1405568285.140,,-5.000000e+000,2.979968e+002,2.980050e+002,1,0,2.237342e-001,-5.282754e-001,-5.282754e-001,-1.907917e-001,-1.752061e-001,-4.604238e-001,-1.229401e-001,-1.073545e-001,-1.151253e-005,-1.151253e-005,,,,,,,,,,,,,,,,,,,,
1405568285.140,,-5.000000e+000,2.979968e+002,2.980050e+002,1,0,2.256216e+000,-9.475998e-002,-9.475997e-002,2.092146e-001,2.583093e-001,1.855250e-002,3.225271e-001,3.716218e-001,-2.065073e-006,-2.065073e-006,,,,,,,,,,,,,,,,,,,,
1405568303.625,,-5.000000e+000,2.979968e+002,2.979968e+002,1,0,3.584259e+000,-3.761406e-001,-3.761406e-001,-9.825651e-002,-4.880390e-002,-4.101206e-001,-1.322365e-001,-8.278388e-002,-8.197109e-006,-8.197109e-006,,,,,,,,,,,,,,,,,,,,
1405568428.125,,-1.000000e+001,2.979968e+002,2.979968e+002,1,0,3.241465e-001,-2.877896e-001,-2.877896e-001,-1.014749e-001,-8.750078e-002,-2.621630e-001,-7.584830e-002,-6.187421e-002,-6.271700e-006,-6.271700e-006,,,,,,,,,,,,,,,,,,,,
1405568445.671,,-1.000000e+001,2.979968e+002,2.979968e+002,1,0,2.079638e+000,-3.006073e-002,-3.006073e-002,1.257082e-001,1.257082e-001,2.883192e-002,1.846009e-001,1.846009e-001,-6.551033e-007,-6.551033e-007,,,,,,,,,,,,,,,,,,,,
1405568445.671,,-1.000000e+001,2.979968e+002,2.979968e+002,1,0,3.705830e+000,-2.114933e-001,-2.114933e-001,-8.311527e-002,-5.572429e-002,-2.080180e-001,-7.964005e-002,-5.224907e-002,-4.609001e-006,-4.609001e-006,,,,,,,,,,,,,,,,,,,,
1405568463.656,,-1.000000e+001,2.980050e+002,2.980050e+002,1,0,4.359829e-001,-2.090518e-001,-2.090518e-001,-7.134045e-002,-5.607940e-002,-2.164342e-001,-7.872287e-002,-6.346183e-002,-4.555795e-006,-4.555795e-006,,,,,,,,,,,,,,,,,,,,
1405568581.890,,-1.500000e+001,2.979968e+002,2.979968e+002,1,0,1.899894e+000,-9.445479e-002,-9.445479e-002,4.243743e-002,4.442476e-002,-1.287031e-001,8.189099e-003,1.017644e-002,-2.058420e-006,-2.058420e-006,,,,,,,,,,,,,,,,,,,,
1405568581.890,,-1.500000e+001,2.979968e+002,2.979968e+002,1,0,3.810060e+000,-1.141392e-001,-1.141392e-001,-6.270248e-002,2.474032e-002,-5.850602e-002,-7.069266e-003,8.037354e-002,-2.487396e-006,-2.487396e-006,,,,,,,,,,,,,,,,,,,,
1405568600.156,,-1.500000e+001,2.979968e+002,2.979968e+002,1,0,5.563114e-001,-1.068148e-003,-1.068148e-003,3.430535e-002,5.757570e-002,-5.274042e-002,-1.736692e-002,5.903423e-003,-2.327777e-008,-2.327777e-008,,,,,,,,,,,,,,,,,,,,
1405568617.906,,-1.500000e+001,2.980050e+002,2.979968e+002,1,0,1.718822e+000,-3.906369e-002,-3.906369e-002,1.078660e-002,1.275977e-002,-1.695343e-002,3.289687e-002,3.487003e-002,-8.513014e-007,-8.513014e-007,,,,,,,,,,,,,,,,,,,,
1405568617.906,,-1.500000e+001,2.980050e+002,2.979968e+002,1,0,3.893607e+000,-9.140294e-002,-9.140293e-002,-8.397565e-002,-3.957947e-002,-2.220573e-002,-1.477844e-002,2.961773e-002,-1.991912e-006,-1.991912e-006,,,,,,,,,,,,,,,,,,,,
1405568736.656,,-2.000000e+001,2.980050e+002,2.979968e+002,1,0,6.832386e-001,1.866207e-001,1.866207e-001,1.117750e-001,1.259043e-001,1.193318e-001,4.448615e-002,5.861541e-002,4.066958e-006,4.066958e-006,,,,,,,,,,,,,,,,,,,,
1405568754.390,,-2.000000e+001,2.979968e+002,2.980050e+002,1,0,1.538878e+000,9.308145e-002,9.308145e-002,-4.426788e-002,-4.231303e-002,7.529328e-002,-6.205605e-002,-6.010120e-002,2.028491e-006,2.028491e-006,,,,,,,,,,,,,,,,,,,,
1405568754.390,,-2.000000e+001,2.979968e+002,2.980050e+002,1,0,3.953509e+000,1.376385e-001,1.376385e-001,-2.773038e-002,2.243996e-003,2.141513e-001,4.878243e-002,7.875681e-002,2.999506e-006,2.999506e-006,,,,,,,,,,,,,,,,,,,,
1405568772.125,,-2.000000e+001,2.980050e+002,2.980050e+002,1,0,8.158413e-001,2.616962e-001,2.616962e-001,1.183076e-001,1.376617e-001,1.837104e-001,4.032177e-002,5.967589e-002,5.703052e-006,5.703052e-006,,,,,,,,,,,,,,,,,,,,
1405568891.859,,-2.500000e+001,2.979968e+002,2.979968e+002,1,0,1.361376e+000,2.327036e-001,2.327036e-001,-3.027905e-002,-2.885805e-002,1.808542e-001,-8.212852e-002,-8.070752e-002,5.071225e-006,5.071225e-006,,,,,,,,,,,,,,,,,,,,
1405568891.859,,-2.500000e+001,2.979968e+002,2.979968e+002,1,0,3.987487e+000,3.309732e-001,3.309732e-001,5.271477e-002,6.941155e-002,4.072106e-001,1.289522e-001,1.456490e-001,7.212778e-006,7.212778e-006,,,,,,,,,,,,,,,,,,,,
1405568910.093,,-2.500000e+001,2.979968e+002,2.979968e+002,1,0,9.540957e-001,4.454176e-001,4.454176e-001,1.500451e-001,1.635298e-001,3.675516e-001,7.217900e-002,8.566377e-002,9.706822e-006,9.706822e-006,,,,,,,,,,,,,,,,,,,,
1405568928.421,,-2.500000e+001,2.980050e+002,2.979968e+002,1,0,1.187311e+000,4.065065e-001,4.065065e-001,5.997005e-002,6.305450e-002,3.331605e-001,-1.337600e-002,-1.029155e-002,8.858848e-006,8.858848e-006,,,,,,,,,,,,,,,,,,,,
1405568928.421,,-2.500000e+001,2.980050e+002,2.979968e+002,1,0,3.994441e+000,4.342784e-001,4.342784e-001,6.121564e-002,9.082636e-002,5.119742e-001,1.389114e-001,1.685221e-001,9.464069e-006,9.464069e-006,,,,,,,,,,,,,,,,,,,,
1405569047.156,,-3.000000e+001,2.980050e+002,2.980050e+002,1,0,1.098445e+000,5.342265e-001,5.342265e-001,9.828489e-002,1.081949e-001,4.649170e-001,2.897539e-002,3.888538e-002,1.164220e-005,1.164220e-005,,,,,,,,,,,,,,,,,,,,
1405569065.390,,-3.000000e+001,2.980050e+002,2.979968e+002,1,0,1.018336e+000,6.427198e-001,6.427198e-001,1.474593e-001,1.502265e-001,5.664884e-001,7.122789e-002,7.399505e-002,1.400655e-005,1.400655e-005,,,,,,,,,,,,,,,,,,,,
1405569065.390,,-3.000000e+001,2.980050e+002,2.979968e+002,1,0,3.974744e+000,6.457717e-001,6.457717e-001,1.306798e-001,1.532784e-001,7.149800e-001,1.998881e-001,2.224867e-001,1.407306e-005,1.407306e-005,,,,,,,,,,,,,,,,,,,,
1405569083.625,,-3.000000e+001,2.979968e+002,2.980050e+002,1,0,1.249466e+000,5.328532e-001,5.328532e-001,-7.050284e-003,7.645369e-003,4.795418e-001,-6.036169e-002,-4.566604e-002,1.161227e-005,1.161227e-005,,,,,,,,,,,,,,,,,,,,
1405569203.406,,-3.500000e+001,2.980050e+002,2.979968e+002,1,0,8.552547e-001,8.182012e-001,8.182012e-001,2.346063e-001,2.372921e-001,7.577522e-001,1.741573e-001,1.768430e-001,1.783074e-005,1.783074e-005,,,,,,,,,,,,,,,,,,,,
1405569203.406,,-3.500000e+001,2.980050e+002,2.979968e+002,1,0,3.930031e+000,7.943968e-001,7.943968e-001,1.943039e-001,2.134876e-001,8.491803e-001,2.490875e-001,2.682711e-001,1.731198e-005,1.731198e-005,,,,,,,,,,,,,,,,,,,,
1405569221.390,,-3.500000e+001,2.979968e+002,2.979968e+002,1,0,1.407825e+000,4.222236e-001,4.222236e-001,-1.803510e-001,-1.735016e-001,4.026463e-001,-1.999283e-001,-1.930788e-001,9.201354e-006,9.201354e-006,,,,,,,,,,,,,,,,,,,,
1405569239.453,,-3.500000e+001,2.979968e+002,2.979968e+002,1,0,6.994463e-001,9.054842e-001,9.054842e-001,2.945790e-001,2.978404e-001,8.495841e-001,2.386789e-001,2.419403e-001,1.973286e-005,1.973286e-005,,,,,,,,,,,,,,,,,,,,
1405569239.453,,-3.500000e+001,2.979968e+002,2.979968e+002,1,0,3.863035e+000,8.478042e-001,8.478042e-001,2.193687e-001,2.401604e-001,8.907574e-001,2.623218e-001,2.831136e-001,1.847587e-005,1.847587e-005,,,,,,,,,,,,,,,,,,,,
1405569358.187,,-4.000000e+001,2.980050e+002,2.979968e+002,1,0,1.573190e+000,3.221229e-001,3.221229e-001,-4.022719e-001,-3.914227e-001,3.398013e-001,-3.845934e-001,-3.737443e-001,7.019895e-006,7.019895e-006,,,,,,,,,,,,,,,,,,,,
1405569375.421,,-4.000000e+001,2.979968e+002,2.979968e+002,1,0,5.523556e-001,1.064791e+000,1.064791e+000,3.407725e-001,3.438953e-001,1.031980e+000,3.079616e-001,3.110844e-001,2.320456e-005,2.320456e-005,,,,,,,,,,,,,,,,,,,,
1405569375.421,,-4.000000e+001,2.979968e+002,2.979968e+002,1,0,3.777356e+000,1.027406e+000,1.027406e+000,2.884672e-001,3.065101e-001,1.049883e+000,3.109445e-001,3.289874e-001,2.238984e-005,2.238984e-005,,,,,,,,,,,,,,,,,,,,
1405569393.171,,-4.000000e+001,2.980050e+002,2.979968e+002,1,0,1.744780e+000,1.428266e-001,1.428266e-001,-5.819294e-001,-5.673591e-001,1.830250e-001,-5.417311e-001,-5.271608e-001,3.112564e-006,3.112564e-006,,,,,,,,,,,,,,,,,,,,
1405569511.921,,-4.500000e+001,2.980050e+002,2.979968e+002,1,0,4.167594e-001,1.216010e+000,1.216010e+000,3.613253e-001,3.664345e-001,1.202644e+000,3.479593e-001,3.530685e-001,2.650001e-005,2.650001e-005,,,,,,,,,,,,,,,,,,,,
1405569511.921,,-4.500000e+001,2.980050e+002,2.979968e+002,1,0,3.676852e+000,1.219520e+000,1.219520e+000,3.428657e-001,3.699441e-001,1.224499e+000,3.478451e-001,3.749235e-001,2.657649e-005,2.657649e-005,,,,,,,,,,,,,,,,,,,,
1405569530.171,,-4.500000e+001,2.979968e+002,2.979885e+002,1,0,1.921357e+000,1.100192e-001,1.100192e-001,-7.751915e-001,-7.629880e-001,1.362562e-001,-7.489545e-001,-7.367510e-001,2.397604e-006,2.397604e-006,,,,,,,,,,,,,,,,,,,,
1405569548.406,,-4.500000e+001,2.979885e+002,2.979968e+002,1,0,2.951688e-001,1.211280e+000,1.211280e+000,3.228671e-001,3.273199e-001,1.218116e+000,3.297035e-001,3.341563e-001,2.639692e-005,2.639692e-005,,,,,,,,,,,,,,,,,,,,
1405569548.406,,-4.500000e+001,2.979885e+002,2.979968e+002,1,0,3.565024e+000,1.245918e+000,1.245918e+000,3.400993e-001,3.619584e-001,1.233426e+000,3.276068e-001,3.494658e-001,2.715178e-005,2.715178e-005,,,,,,,,,,,,,,,,,,,,
1405569668.671,,-5.000000e+001,2.979968e+002,2.980050e+002,1,0,2.100999e+000,9.445479e-002,9.445479e-002,-8.792689e-001,-8.616200e-001,9.145641e-002,-8.822673e-001,-8.646184e-001,2.058413e-006,2.058413e-006,,,,,,,,,,,,,,,,,,,,
1405569686.921,,-5.000000e+001,2.980050e+002,2.979968e+002,1,0,1.910232e-001,1.272622e+000,1.272622e+000,3.111087e-001,3.184482e-001,1.293676e+000,3.321624e-001,3.395019e-001,2.773371e-005,2.773371e-005,,,,,,,,,,,,,,,,,,,,
1405569686.921,,-5.000000e+001,2.980050e+002,2.979968e+002,1,0,3.444802e+000,1.316416e+000,1.316416e+000,3.286030e-001,3.622422e-001,1.295676e+000,3.078626e-001,3.415018e-001,2.868810e-005,2.868810e-005,,,,,,,,,,,,,,,,,,,,
1405569705.203,,-5.000000e+001,2.979968e+002,2.979968e+002,1,0,2.282025e+000,1.564074e-001,1.564074e-001,-8.161892e-001,-7.989494e-001,1.465060e-001,-8.260906e-001,-8.088508e-001,3.408520e-006,3.408520e-006,,,,,,,,,,,,,,,,,,,,
1405569832.500,,-7.500000e+001,2.979968e+002,2.980050e+002,1,0,1.073380e-001,2.642903e+000,2.642903e+000,4.274976e-001,4.834793e-001,2.654396e+000,4.389908e-001,4.949725e-001,5.759554e-005,5.759554e-005,,,,,,,,,,,,,,,,,,,,
1405569832.500,,-7.500000e+001,2.979968e+002,2.980050e+002,1,0,3.317778e+000,2.745598e+000,2.745598e+000,3.450223e-001,5.861740e-001,2.737002e+000,3.364266e-001,5.775783e-001,5.983352e-005,5.983352e-005,,,,,,,,,,,,,,,,,,,,
1405569850.984,,-7.500000e+001,2.979968e+002,2.979968e+002,1,0,2.462070e+000,1.356090e+000,1.356090e+000,-9.005408e-001,-7.663373e-001,1.330076e+000,-9.265550e-001,-7.923515e-001,2.955263e-005,2.955263e-005,,,,,,,,,,,,,,,,,,,,
1405569869.218,,-7.500000e+001,2.979968e+002,2.979968e+002,1,0,4.747043e-002,2.494430e+000,2.494430e+000,3.948240e-001,4.456079e-001,2.509411e+000,4.098048e-001,4.605887e-001,5.435995e-005,5.435995e-005,,,,,,,,,,,,,,,,,,,,
1405569869.218,,-7.500000e+001,2.979968e+002,2.979968e+002,1,0,3.185171e+000,2.443312e+000,2.443312e+000,1.877264e-001,3.944895e-001,2.439052e+000,1.834661e-001,3.902292e-001,5.324595e-005,5.324595e-005,,,,,,,,,,,,,,,,,,,,
1405569993.453,,-1.000000e+002,2.979968e+002,2.979968e+002,1,0,2.639976e+000,1.919614e+000,1.919614e+000,-7.821773e-001,-6.163243e-001,1.931399e+000,-7.703928e-001,-6.045399e-001,4.183316e-005,4.183316e-005,,,,,,,,,,,,,,,,,,,,
1405570027.921,,-1.000000e+002,2.980050e+002,2.979968e+002,1,0,1.355245e-002,1.747642e+000,1.747642e+000,2.577161e-001,3.023316e-001,1.741903e+000,2.519769e-001,2.965924e-001,7.617093e-005,7.617093e-005,,,,,,,,,,,,,,,,,,,,
1405570027.921,,-1.000000e+002,2.980050e+002,2.979968e+002,1,0,3.046884e+000,1.611072e+000,1.611072e+000,-6.751905e-003,1.657612e-001,1.631033e+000,1.320921e-002,1.857224e-001,7.021852e-005,7.021852e-005,,,,,,,,,,,,,,,,,,,,
1405570046.171,,-1.000000e+002,2.979968e+002,2.979885e+002,1,0,2.813727e+000,1.298563e+000,1.298563e+000,-2.249879e-001,-1.226350e-001,1.314924e+000,-2.086268e-001,-1.062739e-001,5.659780e-005,5.659780e-005,,,,,,,,,,,,,,,,,,,,
1405570171.406,,-7.500000e+001,2.979968e+002,2.979968e+002,1,0,6.621922e-003,8.507035e-001,8.507035e-001,2.025317e-001,1.988587e-001,8.570175e-001,2.088456e-001,2.051727e-001,3.707796e-005,3.707796e-005,,,,,,,,,,,,,,,,,,,,
1405570171.406,,-7.500000e+001,2.979968e+002,2.979968e+002,1,0,2.902583e+000,5.066072e-001,5.066072e-001,-1.316934e-001,-1.452376e-001,5.240594e-001,-1.142413e-001,-1.277854e-001,2.208051e-005,2.208051e-005,,,,,,,,,,,,,,,,,,,,
1405570188.906,,-7.500000e+001,2.980050e+002,2.979968e+002,1,0,2.982766e+000,5.830562e-001,5.830562e-001,-5.558851e-002,-6.250215e-002,5.896908e-001,-4.895386e-002,-5.586749e-002,2.541254e-005,2.541254e-005,,,,,,,,,,,,,,,,,,,,
1405570207.390,,-7.500000e+001,2.980050e+002,2.980050e+002,1,0,2.629698e-002,8.568072e-001,8.568072e-001,2.080153e-001,2.042954e-001,8.628451e-001,2.140532e-001,2.103333e-001,3.734399e-005,3.734399e-005,,,,,,,,,,,,,,,,,,,,
1405570207.390,,-7.500000e+001,2.980050e+002,2.980050e+002,1,0,2.751468e+000,3.769036e-001,3.769036e-001,-2.624790e-001,-2.756082e-001,3.965715e-001,-2.428111e-001,-2.559403e-001,1.642737e-005,1.642737e-005,,,,,,,,,,,,,,,,,,,,
1405570340.437,,-5.000000e+001,2.980050e+002,2.979885e+002,1,0,3.145922e+000,5.687124e-001,5.687124e-001,5.745193e-002,4.762489e-002,5.582135e-001,4.695299e-002,3.712595e-002,2.478742e-005,2.478742e-005,,,,,,,,,,,,,,,,,,,,
1405570358.421,,-5.000000e+001,2.979968e+002,2.979968e+002,1,0,7.099726e-002,6.686605e-001,6.686605e-001,1.597336e-001,1.568989e-001,6.858199e-001,1.768929e-001,1.740582e-001,2.914368e-005,2.914368e-005,,,,,,,,,,,,,,,,,,,,
1405570358.421,,-5.000000e+001,2.979968e+002,2.979968e+002,1,0,2.593114e+000,1.716666e-001,1.716666e-001,-3.304885e-001,-3.400950e-001,1.810760e-001,-3.210791e-001,-3.306857e-001,7.482117e-006,7.482117e-006,,,,,,,,,,,,,,,,,,,,
1405570376.156,,-5.000000e+001,2.979968e+002,2.980050e+002,1,0,3.301644e+000,6.659139e-001,6.659139e-001,1.412805e-001,1.350549e-001,6.541650e-001,1.295317e-001,1.233061e-001,2.902396e-005,2.902396e-005,,,,,,,,,,,,,,,,,,,,
1405570496.906,,-4.500000e+001,2.979968e+002,2.980050e+002,1,0,1.380456e-001,6.401257e-001,6.401258e-001,1.701458e-001,1.662419e-001,6.500961e-001,1.801161e-001,1.762122e-001,2.790000e-005,2.790000e-005,,,,,,,,,,,,,,,,,,,,
1405570496.906,,-4.500000e+001,2.979968e+002,2.980050e+002,1,0,2.427840e+000,4.852443e-002,4.852443e-002,-4.126202e-001,-4.253595e-001,5.162425e-002,-4.095204e-001,-4.222597e-001,2.114946e-006,2.114946e-006,,,,,,,,,,,,,,,,,,,,
1405570514.140,,-4.500000e+001,2.980050e+002,2.980050e+002,1,0,3.448530e+000,6.649984e-001,6.649983e-001,1.869665e-001,1.806710e-001,6.553067e-001,1.772749e-001,1.709794e-001,2.898407e-005,2.898407e-005,,,,,,,,,,,,,,,,,,,,
1405570531.875,,-4.500000e+001,2.980050e+002,2.979968e+002,1,0,2.235965e-001,6.886501e-001,6.886502e-001,1.957828e-001,1.943615e-001,6.895519e-001,1.966846e-001,1.952633e-001,3.001494e-005,3.001494e-005,,,,,,,,,,,,,,,,,,,,
1405570531.875,,-4.500000e+001,2.980050e+002,2.979968e+002,1,0,2.256166e+000,3.967406e-003,3.967406e-003,-4.858443e-001,-4.903212e-001,4.077393e-003,-4.857343e-001,-4.902112e-001,1.729201e-007,1.729201e-007,,,,,,,,,,,,,,,,,,,,
1405570650.125,,-4.000000e+001,2.979968e+002,2.979968e+002,1,0,3.584222e+000,6.384472e-001,6.384472e-001,1.999096e-001,1.909482e-001,6.364979e-001,1.979602e-001,1.889988e-001,2.782685e-005,2.782685e-005,,,,,,,,,,,,,,,,,,,,
1405570667.875,,-4.000000e+001,2.979968e+002,2.979968e+002,1,0,3.240570e-001,6.549272e-001,6.549272e-001,2.039044e-001,2.020147e-001,6.510081e-001,1.999854e-001,1.980956e-001,2.854514e-005,2.854514e-005,,,,,,,,,,,,,,,,,,,,
1405570686.156,,-4.000000e+001,2.979968e+002,2.979968e+002,1,0,2.079687e+000,-3.311258e-002,-3.311258e-002,-4.851333e-001,-4.851333e-001,-2.874575e-002,-4.807664e-001,-4.807664e-001,-1.443219e-006,-1.443219e-006,,,,,,,,,,,,,,,,,,,,
1405570686.156,,-4.000000e+001,2.979968e+002,2.979968e+002,1,0,3.705794e+000,6.518754e-001,6.518754e-001,2.055682e-001,1.998547e-001,6.565122e-001,2.102050e-001,2.044915e-001,2.841212e-005,2.841212e-005,,,,,,,,,,,,,,,,,,,,
1405570805.218,,-3.500000e+001,2.980132e+002,2.979885e+002,1,0,4.359643e-001,6.311228e-001,6.311228e-001,2.052963e-001,2.013608e-001,6.225052e-001,1.966788e-001,1.927432e-001,2.750763e-005,2.750763e-005,,,,,,,,,,,,,,,,,,,,
1405570823.453,,-3.500000e+001,2.979968e+002,2.979968e+002,1,0,1.900032e+000,-1.525925e-002,-1.525925e-002,-4.198096e-001,-4.199822e-001,-4.449701e-003,-4.090000e-001,-4.091726e-001,-6.650780e-007,-6.650780e-007,,,,,,,,,,,,,,,,,,,,
1405570823.453,,-3.500000e+001,2.979968e+002,2.979968e+002,1,0,3.810077e+000,5.854976e-001,5.854976e-001,1.883691e-001,1.807747e-001,5.929704e-001,1.958419e-001,1.882475e-001,2.551904e-005,2.551904e-005,,,,,,,,,,,,,,,,,,,,
1405570841.937,,-3.500000e+001,2.979968e+002,2.979968e+002,1,0,5.562523e-001,6.071658e-001,6.071658e-001,2.110026e-001,2.076802e-001,5.915414e-001,1.953783e-001,1.920559e-001,2.646345e-005,2.646345e-005,,,,,,,,,,,,,,,,,,,,
1405570960.671,,-3.000000e+001,2.980050e+002,2.979968e+002,1,0,1.719027e+000,5.798517e-002,5.798517e-002,-3.087009e-001,-3.090745e-001,6.686819e-002,-2.998178e-001,-3.001915e-001,2.527298e-006,2.527298e-006,,,,,,,,,,,,,,,,,,,,
1405570960.671,,-3.000000e+001,2.980050e+002,2.979968e+002,1,0,3.893583e+000,5.218665e-001,5.218665e-001,1.632142e-001,1.548068e-001,5.360814e-001,1.774291e-001,1.690217e-001,2.274568e-005,2.274568e-005,,,,,,,,,,,,,,,,,,,,
1405570978.921,,-3.000000e+001,2.980050e+002,2.980050e+002,1,0,6.832164e-001,5.870235e-001,5.870236e-001,1.893857e-001,1.867222e-001,5.661358e-001,1.684979e-001,1.658344e-001,2.558556e-005,2.558556e-005,,,,,,,,,,,,,,,,,,,,
1405570995.656,,-3.000000e+001,2.980050e+002,2.979968e+002,1,0,1.538633e+000,2.038636e-001,2.038637e-001,-2.034812e-001,-2.036557e-001,2.052531e-001,-2.020918e-001,-2.022662e-001,8.885447e-006,8.885447e-006,,,,,,,,,,,,,,,,,,,,
1405570995.656,,-3.000000e+001,2.980050e+002,2.979968e+002,1,0,3.953390e+000,5.590991e-001,5.590991e-001,1.542549e-001,1.515798e-001,5.752408e-001,1.703966e-001,1.677215e-001,2.436847e-005,2.436847e-005,,,,,,,,,,,,,,,,,,,,
1405571115.406,,-2.500000e+001,2.980050e+002,2.979885e+002,1,0,8.158106e-001,5.038606e-001,5.038606e-001,1.554593e-001,1.527458e-001,4.777971e-001,1.293957e-001,1.266823e-001,2.196090e-005,2.196090e-005,,,,,,,,,,,,,,,,,,,,
1405571133.140,,-2.500000e+001,2.980050e+002,2.979968e+002,1,0,1.361321e+000,2.848903e-001,2.848903e-001,-7.811069e-002,-7.815194e-002,2.695066e-001,-9.349436e-002,-9.353560e-002,1.241702e-005,1.241702e-005,,,,,,,,,,,,,,,,,,,,
1405571133.140,,-2.500000e+001,2.980050e+002,2.979968e+002,1,0,3.987438e+000,4.977569e-001,4.977569e-001,1.351993e-001,1.347147e-001,5.175006e-001,1.549430e-001,1.544583e-001,2.169486e-005,2.169486e-005,,,,,,,,,,,,,,,,,,,,
1405571150.875,,-2.500000e+001,2.979968e+002,2.980050e+002,1,0,9.540027e-001,4.689169e-001,4.689169e-001,1.143578e-001,1.140217e-001,4.398342e-001,8.527517e-002,8.493900e-002,2.043787e-005,2.043787e-005,,,,,,,,,,,,,,,,,,,,
1405571269.640,,-2.000000e+001,2.979885e+002,2.979968e+002,1,0,1.187214e+000,3.555406e-001,3.555406e-001,2.325502e-002,2.306059e-002,3.265542e-001,-5.731376e-003,-5.925804e-003,1.549634e-005,1.549634e-005,,,,,,,,,,,,,,,,,,,,
1405571269.640,,-2.000000e+001,2.979885e+002,2.979968e+002,1,0,3.994410e+000,4.501480e-001,4.501480e-001,1.195345e-001,1.176680e-001,4.738351e-001,1.432216e-001,1.413551e-001,1.961983e-005,1.961983e-005,,,,,,,,,,,,,,,,,,,,
1405571287.875,,-2.000000e+001,2.979968e+002,2.980050e+002,1,0,1.098453e+000,3.975036e-001,3.975036e-001,6.105521e-002,6.230792e-002,3.668223e-001,3.037390e-002,3.162661e-002,1.732531e-005,1.732531e-005,,,,,,,,,,,,,,,,,,,,
1405571305.359,,-2.000000e+001,2.980050e+002,2.979968e+002,1,0,1.018238e+000,4.226813e-001,4.226814e-001,8.966799e-002,8.943903e-002,3.930327e-001,6.001930e-002,5.979034e-002,1.842269e-005,1.842269e-005,,,,,,,,,,,,,,,,,,,,
1405571305.359,,-2.000000e+001,2.980050e+002,2.979968e+002,1,0,3.974689e+000,4.512162e-001,4.512162e-001,1.198436e-001,1.179738e-001,4.768214e-001,1.454488e-001,1.435790e-001,1.966638e-005,1.966638e-005,,,,,,,,,,,,,,,,,,,,
1405571435.609,,-1.500000e+001,2.980050e+002,2.979968e+002,1,0,1.249616e+000,6.184576e-001,6.184576e-001,-6.585538e-004,-2.169430e-003,5.691628e-001,-4.995338e-002,-5.146426e-002,1.347783e-005,1.347783e-005,,,,,,,,,,,,,,,,,,,,
1405571453.843,,-1.500000e+001,2.979968e+002,2.980050e+002,1,0,8.551046e-001,8.992279e-001,8.992279e-001,2.703289e-001,2.712432e-001,8.392886e-001,2.103897e-001,2.113039e-001,1.959656e-005,1.959656e-005,,,,,,,,,,,,,,,,,,,,
1405571453.843,,-1.500000e+001,2.979968e+002,2.980050e+002,1,0,3.929930e+000,8.613849e-001,8.613849e-001,2.268700e-001,2.334002e-001,9.117254e-001,2.772105e-001,2.837407e-001,1.877186e-005,1.877186e-005,,,,,,,,,,,,,,,,,,,,
1405571471.625,,-1.500000e+001,2.980050e+002,2.980050e+002,1,0,1.407846e+000,4.403821e-001,4.403821e-001,-1.538489e-001,-1.502419e-001,4.165401e-001,-1.776909e-001,-1.740839e-001,9.597094e-006,9.597094e-006,,,,,,,,,,,,,,,,,,,,
1405571590.609,,-1.000000e+001,2.979968e+002,2.979968e+002,1,0,6.991988e-001,8.333079e-001,8.333079e-001,2.998997e-001,3.011191e-001,7.790366e-001,2.456284e-001,2.468479e-001,1.816000e-005,1.816000e-005,,,,,,,,,,,,,,,,,,,,
1405571590.609,,-1.000000e+001,2.979968e+002,2.979968e+002,1,0,3.862961e+000,7.568590e-001,7.568591e-001,2.168960e-001,2.246703e-001,7.997342e-001,2.597712e-001,2.675454e-001,1.649397e-005,1.649397e-005,,,,,,,,,,,,,,,,,,,,
1405571609.093,,-1.000000e+001,2.979968e+002,2.979968e+002,1,0,1.573223e+000,2.620014e-001,2.620014e-001,-2.932883e-001,-2.942474e-001,2.765001e-001,-2.787896e-001,-2.797487e-001,5.709708e-006,5.709708e-006,,,,,,,,,,,,,,,,,,,,
1405571627.343,,-1.000000e+001,2.979968e+002,2.979968e+002,1,0,5.522940e-001,8.534501e-001,8.534501e-001,3.015307e-001,3.029568e-001,8.133186e-001,2.613991e-001,2.628253e-001,1.859895e-005,1.859895e-005,,,,,,,,,,,,,,,,,,,,
1405571627.343,,-1.000000e+001,2.979968e+002,2.979968e+002,1,0,3.777325e+000,7.934812e-001,7.934812e-001,2.347479e-001,2.429879e-001,8.198678e-001,2.611345e-001,2.693745e-001,1.729207e-005,1.729207e-005,,,,,,,,,,,,,,,,,,,,
1405571746.078,,-5.000000e+000,2.980050e+002,2.980050e+002,1,0,1.744786e+000,8.026368e-002,8.026368e-002,-3.991862e-001,-3.968937e-001,1.250530e-001,-3.543969e-001,-3.521044e-001,1.749160e-006,1.749160e-006,,,,,,,,,,,,,,,,,,,,
1405571764.062,,-5.000000e+000,2.979968e+002,2.979968e+002,1,0,4.166676e-001,7.092502e-001,7.092502e-001,2.458493e-001,2.470507e-001,6.874900e-001,2.240891e-001,2.252905e-001,1.545646e-005,1.545646e-005,,,,,,,,,,,,,,,,,,,,
1405571764.062,,-5.000000e+000,2.979968e+002,2.979968e+002,1,0,3.676818e+000,6.898710e-001,6.898709e-001,2.213039e-001,2.276714e-001,6.909970e-001,2.224301e-001,2.287975e-001,1.503413e-005,1.503413e-005,,,,,,,,,,,,,,,,,,,,
1405571781.562,,-5.000000e+000,2.980050e+002,2.979968e+002,1,0,1.921375e+000,-3.845332e-002,-3.845332e-002,-5.161039e-001,-5.145570e-001,1.780188e-002,-4.598487e-001,-4.583018e-001,-8.380006e-007,-8.380006e-007,,,,,,,,,,,,,,,,,,,,
1405571901.046,,0.000000e+000,2.980050e+002,2.980050e+002,1,0,2.951823e-001,5.510117e-001,5.510117e-001,1.630654e-001,1.638411e-001,5.614535e-001,1.735072e-001,1.742830e-001,1.200802e-005,1.200802e-005,,,,,,,,,,,,,,,,,,,,
1405571901.046,,0.000000e+000,2.980050e+002,2.980050e+002,1,0,3.565051e+000,5.774102e-001,5.774102e-001,1.864316e-001,1.902397e-001,5.554854e-001,1.645067e-001,1.683148e-001,1.258332e-005,1.258332e-005,,,,,,,,,,,,,,,,,,,,
1405571919.281,,0.000000e+000,2.980050e+002,2.980050e+002,1,0,2.101175e+000,-1.260414e-001,-1.260414e-001,-5.016082e-001,-5.010003e-001,-7.902878e-002,-4.545956e-001,-4.539877e-001,-2.746781e-006,-2.746781e-006,,,,,,,,,,,,,,,,,,,,
1405571936.531,,0.000000e+000,2.979968e+002,2.979968e+002,1,0,1.909256e-001,5.227820e-001,5.227821e-001,1.049322e-001,1.080751e-001,5.719148e-001,1.540649e-001,1.572078e-001,1.139282e-005,1.139282e-005,,,,,,,,,,,,,,,,,,,,
1405571936.531,,0.000000e+000,2.979968e+002,2.979968e+002,1,0,3.444701e+000,5.934324e-001,5.934324e-001,1.643203e-001,1.787255e-001,5.530065e-001,1.238943e-001,1.382995e-001,1.293248e-005,1.293248e-005,,,,,,,,,,,,,,,,,,,,
1405572054.765,,5.000000e+000,2.979968e+002,2.979885e+002,1,0,2.282028e+000,-9.140294e-002,-9.140293e-002,-4.143817e-001,-4.098923e-001,-6.879251e-002,-3.917712e-001,-3.872819e-001,-1.991914e-006,-1.991914e-006,,,,,,,,,,,,,,,,,,,,
1405572073.000,,5.000000e+000,2.979968e+002,2.979968e+002,1,0,1.073644e-001,3.454695e-001,3.454695e-001,2.709952e-002,2.907825e-002,4.295570e-001,1.111870e-001,1.131657e-001,7.528704e-006,7.528704e-006,,,,,,,,,,,,,,,,,,,,
1405572073.000,,5.000000e+000,2.979968e+002,2.979968e+002,1,0,3.317744e+000,4.292428e-001,4.292428e-001,1.043278e-001,1.128516e-001,3.702564e-001,4.534139e-002,5.386513e-002,9.354349e-006,9.354349e-006,,,,,,,,,,,,,,,,,,,,
1405572090.734,,5.000000e+000,2.979968e+002,2.979885e+002,1,0,2.462322e+000,1.022370e-002,1.022370e-002,-3.387366e-001,-3.320102e-001,-7.154583e-003,-3.561149e-001,-3.493885e-001,2.228018e-007,2.228018e-007,,,,,,,,,,,,,,,,,,,,
1405572217.218,,1.000000e+001,2.980050e+002,2.979968e+002,1,0,4.739803e-002,2.014222e-001,2.014222e-001,-3.920816e-002,-3.707594e-002,3.177525e-001,7.712220e-002,7.925443e-002,4.389525e-006,4.389525e-006,,,,,,,,,,,,,,,,,,,,
1405572217.218,,1.000000e+001,2.980050e+002,2.979968e+002,1,0,3.185111e+000,2.900784e-001,2.900784e-001,4.289911e-002,5.158032e-002,2.189043e-001,-2.827497e-002,-1.959376e-002,6.321581e-006,6.321581e-006,,,,,,,,,,,,,,,,,,,,
1405572234.968,,1.000000e+001,2.980050e+002,2.979968e+002,1,0,2.639844e+000,5.096591e-002,5.096591e-002,-2.044601e-001,-1.962775e-001,5.429489e-003,-2.499966e-001,-2.418139e-001,1.110683e-006,1.110683e-006,,,,,,,,,,,,,,,,,,,,
1405572253.015,,1.000000e+001,2.979968e+002,2.979968e+002,1,0,1.354145e-002,2.142399e-001,2.142399e-001,-5.753686e-002,-5.234064e-002,3.447526e-001,7.297584e-002,7.817206e-002,4.668858e-006,4.668858e-006,,,,,,,,,,,,,,,,,,,,
1405572253.015,,1.000000e+001,2.979968e+002,2.979968e+002,1,0,3.046908e+000,2.705466e-001,2.705466e-001,-1.612602e-002,3.966004e-003,2.029112e-001,-8.376140e-002,-6.366938e-002,5.895930e-006,5.895930e-006,,,,,,,,,,,,,,,,,,,,
1405572371.765,,1.500000e+001,2.979968e+002,2.980050e+002,1,0,2.813863e+000,1.058992e-001,1.058992e-001,-9.335922e-002,-7.605025e-002,2.937093e-002,-1.698875e-001,-1.525786e-001,2.307825e-006,2.307825e-006,,,,,,,,,,,,,,,,,,,,
1405572390.765,,1.500000e+001,2.979968e+002,2.979968e+002,1,0,6.525130e-003,8.896146e-002,8.896145e-002,-1.010503e-001,-9.444469e-002,2.380835e-001,4.807173e-002,5.467735e-002,1.938706e-006,1.938706e-006,,,,,,,,,,,,,,,,,,,,
1405572390.765,,1.500000e+001,2.979968e+002,2.979968e+002,1,0,2.902502e+000,1.274148e-001,1.274148e-001,-8.034959e-002,-5.599137e-002,6.596489e-002,-1.417995e-001,-1.174413e-001,2.776706e-006,2.776706e-006,,,,,,,,,,,,,,,,,,,,
1405572408.500,,1.500000e+001,2.979968e+002,2.979885e+002,1,0,2.982961e+000,2.063051e-001,2.063051e-001,-2.262090e-002,-1.640350e-003,1.145646e-001,-1.143614e-001,-9.338087e-002,4.495936e-006,4.495936e-006,,,,,,,,,,,,,,,,,,,,
1405572528.250,,2.000000e+001,2.979968e+002,2.979968e+002,1,0,2.623638e-002,-5.142369e-002,-5.142369e-002,-1.343136e-001,-1.194992e-001,1.036637e-001,2.077380e-002,3.558816e-002,-1.120658e-006,-1.120658e-006,,,,,,,,,,,,,,,,,,,,
1405572528.250,,2.000000e+001,2.979968e+002,2.979968e+002,1,0,2.751334e+000,-9.002960e-003,-9.002960e-003,-1.293645e-001,-7.707850e-002,-4.817897e-002,-1.685405e-001,-1.162545e-001,-1.961983e-007,-1.961983e-007,,,,,,,,,,,,,,,,,,,,
1405572545.984,,2.000000e+001,2.980050e+002,2.980050e+002,1,0,3.145991e+000,1.112400e-001,1.112400e-001,1.621020e-002,5.704290e-002,-1.216445e-002,-1.071942e-001,-6.636152e-002,2.424213e-006,2.424213e-006,,,,,,,,,,,,,,,,,,,,
1405572564.218,,2.000000e+001,2.979968e+002,2.980050e+002,1,0,7.095731e-002,-1.617481e-002,-1.617481e-002,-1.165100e-001,-9.856763e-002,1.219223e-001,2.158714e-002,3.952950e-002,-3.524918e-007,-3.524918e-007,,,,,,,,,,,,,,,,,,,,
1405572564.218,,2.000000e+001,2.979968e+002,2.980050e+002,1,0,2.593057e+000,-4.150517e-002,-4.150517e-002,-1.847027e-001,-1.238980e-001,-2.099780e-002,-1.641953e-001,-1.033906e-001,-9.045074e-007,-9.045074e-007,,,,,,,,,,,,,,,,,,,,
1405572681.968,,2.500000e+001,2.979968e+002,2.980050e+002,1,0,3.301833e+000,5.584887e-002,5.584887e-002,5.416649e-002,1.242065e-002,4.187399e-003,2.505011e-003,-3.924083e-002,1.217094e-006,1.217094e-006,,,,,,,,,,,,,,,,,,,,
1405572699.453,,2.500000e+001,2.980050e+002,2.980050e+002,1,0,1.379538e-001,-1.042207e-001,-1.042207e-001,-1.406306e-001,-1.589746e-001,3.902895e-002,2.619058e-003,-1.572499e-002,-2.271244e-006,-2.271244e-006,,,,,,,,,,,,,,,,,,,,
1405572699.453,,2.500000e+001,2.980050e+002,2.980050e+002,1,0,2.427685e+000,-9.201331e-002,-9.201331e-002,-8.690771e-002,-1.467673e-001,-9.658230e-003,-4.552634e-003,-6.441218e-002,-2.005212e-006,-2.005212e-006,,,,,,,,,,,,,,,,,,,,
1405572717.484,,2.500000e+001,2.980050e+002,2.979968e+002,1,0,3.448638e+000,8.651998e-002,8.651997e-002,4.989958e-002,1.499727e-002,3.868440e-002,2.064012e-003,-3.283830e-002,1.885498e-006,1.885498e-006,,,,,,,,,,,,,,,,,,,,
1405572838.234,,3.000000e+001,2.979968e+002,2.979885e+002,1,0,2.236562e-001,-2.371288e-001,-2.371288e-001,-8.295003e-002,-3.266630e-002,-1.734813e-001,-1.930249e-002,3.098124e-002,-5.167658e-006,-5.167658e-006,,,,,,,,,,,,,,,,,,,,
1405572838.234,,3.000000e+001,2.979968e+002,2.979885e+002,1,0,2.256092e+000,-1.351970e-001,-1.351970e-001,-8.912823e-002,6.926553e-002,-5.339720e-002,-7.328422e-003,1.510653e-001,-2.946297e-006,-2.946297e-006,,,,,,,,,,,,,,,,,,,,
1405572856.000,,3.000000e+001,2.980050e+002,2.979968e+002,1,0,3.584259e+000,-1.480148e-001,-1.480148e-001,-2.292221e-002,8.507600e-002,-1.803956e-001,-5.530307e-002,5.269514e-002,-3.225630e-006,-3.225630e-006,,,,,,,,,,,,,,,,,,,,
1405572873.265,,3.000000e+001,2.980050e+002,2.979968e+002,1,0,3.241400e-001,-1.864681e-001,-1.864681e-001,-3.416350e-002,1.753062e-002,-1.445078e-001,7.796759e-003,5.949087e-002,-4.063629e-006,-4.063629e-006,,,,,,,,,,,,,,,,,,,,
1405572992.000,,3.500000e+001,2.980050e+002,2.979968e+002,1,0,2.079648e+000,-8.133183e-002,-8.133183e-002,2.265538e-001,2.265538e-001,-1.435288e-001,1.643569e-001,1.643569e-001,-1.772433e-006,-1.772433e-006,,,,,,,,,,,,,,,,,,,,
1405572992.000,,3.500000e+001,2.980050e+002,2.979968e+002,1,0,3.705865e+000,-3.141881e-001,-3.141881e-001,-1.122979e-001,-6.302416e-003,-2.855027e-001,-8.361250e-002,2.238297e-002,-6.846978e-006,-6.846978e-006,,,,,,,,,,,,,,,,,,,,
1405573009.750,,3.500000e+001,2.979885e+002,2.980050e+002,1,0,4.359617e-001,-2.662740e-001,-2.662740e-001,-5.392717e-002,4.594028e-004,-2.555410e-001,-4.319413e-002,1.119244e-002,-5.802805e-006,-5.802805e-006,,,,,,,,,,,,,,,,,,,,
1405573026.984,,3.500000e+001,2.980050e+002,2.980050e+002,1,0,1.899872e+000,-2.716147e-002,-2.716147e-002,2.673312e-001,2.698438e-001,-5.288706e-002,2.416056e-001,2.441182e-001,-5.919194e-007,-5.919194e-007,,,,,,,,,,,,,,,,,,,,
1405573026.984,,3.500000e+001,2.980050e+002,2.980050e+002,1,0,3.810097e+000,-3.231910e-001,-3.231910e-001,-1.367400e-001,-2.618578e-002,-2.592889e-001,-7.283781e-002,3.771636e-002,-7.043176e-006,-7.043176e-006,,,,,,,,,,,,,,,,,,,,
1405573144.750,,4.000000e+001,2.979968e+002,2.979968e+002,1,0,5.564002e-001,-4.364147e-001,-4.364147e-001,-6.257502e-002,-1.140976e-002,-4.710681e-001,-9.722839e-002,-4.606313e-002,-9.510611e-006,-9.510611e-006,,,,,,,,,,,,,,,,,,,,
1405573162.296,,4.000000e+001,2.979885e+002,2.979968e+002,1,0,1.718672e+000,1.144444e-002,1.144444e-002,3.927572e-001,3.972317e-001,4.228985e-002,4.236026e-001,4.280771e-001,2.494041e-007,2.494041e-007,,,,,,,,,,,,,,,,,,,,
1405573162.296,,4.000000e+001,2.979885e+002,2.979968e+002,1,0,3.893633e+000,-5.162206e-001,-5.162206e-001,-2.311086e-001,-1.304334e-001,-4.045988e-001,-1.194869e-001,-1.881158e-002,-1.124979e-005,-1.124979e-005,,,,,,,,,,,,,,,,,,,,
1405573180.031,,4.000000e+001,2.979968e+002,2.980050e+002,1,0,6.833280e-001,-3.456221e-001,-3.456221e-001,5.985422e-003,6.208983e-002,-4.011256e-001,-4.951809e-002,6.586313e-003,-7.532005e-006,-7.532005e-006,,,,,,,,,,,,,,,,,,,,
1405573297.515,,4.500000e+001,2.979968e+002,2.979968e+002,1,0,1.538628e+000,-8.758812e-002,-8.758812e-002,4.609227e-001,4.672699e-001,-1.016723e-001,4.468385e-001,4.531857e-001,-1.908772e-006,-1.908772e-006,,,,,,,,,,,,,,,,,,,,
1405573297.515,,4.500000e+001,2.979968e+002,2.979968e+002,1,0,3.953514e+000,-7.835627e-001,-7.835627e-001,-3.260291e-001,-2.287047e-001,-6.366818e-001,-1.791482e-001,-8.182377e-002,-1.707586e-005,-1.707586e-005,,,,,,,,,,,,,,,,,,,,
1405573315.250,,4.500000e+001,2.979968e+002,2.979968e+002,1,0,8.158265e-001,-5.415509e-001,-5.415509e-001,1.747245e-002,6.933069e-002,-6.267991e-001,-6.777573e-002,-1.591748e-002,-1.180180e-005,-1.180180e-005,,,,,,,,,,,,,,,,,,,,
1405573332.984,,4.500000e+001,2.980050e+002,2.979968e+002,1,0,1.361141e+000,-1.358074e-001,-1.358074e-001,3.985992e-001,4.070484e-001,-2.137407e-001,3.206658e-001,3.291150e-001,-2.959594e-006,-2.959594e-006,,,,,,,,,,,,,,,,,,,,
1405573332.984,,4.500000e+001,2.980050e+002,2.979968e+002,1,0,3.987525e+000,-7.885983e-001,-7.885983e-001,-3.450206e-001,-2.457426e-001,-6.213871e-001,-1.778094e-001,-7.853132e-002,-1.718560e-005,-1.718560e-005,,,,,,,,,,,,,,,,,,,,
1405573452.734,,5.000000e+001,2.980050e+002,2.979968e+002,1,0,9.541392e-001,-6.775109e-001,-6.775109e-001,6.404428e-002,1.165618e-001,-7.930205e-001,-5.146535e-002,1.052141e-003,-1.476471e-005,-1.476471e-005,,,,,,,,,,,,,,,,,,,,
1405573469.968,,5.000000e+001,2.979968e+002,2.979885e+002,1,0,1.186818e+000,-4.782251e-001,-4.782251e-001,3.030804e-001,3.138553e-001,-6.161488e-001,1.651566e-001,1.759315e-001,-1.042176e-005,-1.042176e-005,,,,,,,,,,,,,,,,,,,,
1405573469.968,,5.000000e+001,2.979968e+002,2.979885e+002,1,0,3.994382e+000,-1.140019e+000,-1.140019e+000,-4.513779e-001,-3.479386e-001,-9.571080e-001,-2.684670e-001,-1.650277e-001,-2.484395e-005,-2.484395e-005,,,,,,,,,,,,,,,,,,,,
1405573487.765,,5.000000e+001,2.979885e+002,2.980050e+002,1,0,1.098558e+000,-4.745628e-001,-4.745628e-001,1.955441e-001,2.523007e-001,-5.918931e-001,7.821383e-002,1.349704e-001,-1.034195e-005,-1.034195e-005,,,,,,,,,,,,,,,,,,,,
1405573613.500,,7.500000e+001,2.980050e+002,2.979968e+002,1,0,1.017909e+000,-1.094394e+000,-1.094394e+000,1.461276e-001,1.629099e-001,-1.296984e+000,-5.646277e-002,-3.968048e-002,-2.384961e-005,-2.384961e-005,,,,,,,,,,,,,,,,,,,,
1405573613.500,,7.500000e+001,2.980050e+002,2.979968e+002,1,0,3.974685e+000,-1.811884e+000,-1.811884e+000,-6.916357e-001,-5.545803e-001,-1.593518e+000,-4.732699e-001,-3.362145e-001,-3.948554e-005,-3.948554e-005,,,,,,,,,,,,,,,,,,,,
1405573630.984,,7.500000e+001,2.979968e+002,2.980050e+002,1,0,1.249569e+000,-8.027894e-001,-8.027894e-001,4.356558e-001,5.141096e-001,-9.333532e-001,3.050919e-001,3.835457e-001,-1.749481e-005,-1.749481e-005,,,,,,,,,,,,,,,,,,,,
1405573648.218,,7.500000e+001,2.980050e+002,2.979885e+002,1,0,8.551553e-001,-1.266213e+000,-1.266213e+000,-7.164185e-002,-5.179286e-002,-1.471732e+000,-2.771608e-001,-2.573118e-001,-2.759399e-005,-2.759399e-005,,,,,,,,,,,,,,,,,,,,
1405573648.218,,7.500000e+001,2.980050e+002,2.979885e+002,1,0,3.929978e+000,-1.761834e+000,-1.761834e+000,-6.891920e-001,-5.474135e-001,-1.570825e+000,-4.981831e-001,-3.564045e-001,-3.839481e-005,-3.839481e-005,,,,,,,,,,,,,,,,,,,,
1405573779.515,,1.000000e+002,2.979968e+002,2.980050e+002,1,0,1.407901e+000,-7.003998e-001,-7.003998e-001,8.450767e-001,9.418262e-001,-7.927678e-001,7.527087e-001,8.494582e-001,-1.526345e-005,-1.526345e-005,,,,,,,,,,,,,,,,,,,,
1405573797.781,,1.000000e+002,2.979968e+002,2.979968e+002,1,0,6.994142e-001,-1.992553e+000,-1.992553e+000,-3.686881e-001,-3.419194e-001,-2.195165e+000,-5.712998e-001,-5.445311e-001,-4.342269e-005,-4.342269e-005,,,,,,,,,,,,,,,,,,,,
1405573797.781,,1.000000e+002,2.979968e+002,2.979968e+002,1,0,3.863025e+000,-2.340617e+000,-2.340617e+000,-8.606334e-001,-6.899831e-001,-2.164285e+000,-6.843014e-001,-5.136511e-001,-5.100785e-005,-5.100785e-005,,,,,,,,,,,,,,,,,,,,
1405573816.015,,1.000000e+002,2.980050e+002,2.979968e+002,1,0,1.573141e+000,-3.805658e-001,-3.805658e-001,1.123590e+000,1.225066e+000,-3.831145e-001,1.121042e+000,1.222517e+000,-8.293473e-006,-8.293473e-006,,,,,,,,,,,,,,,,,,,,
1405573816.015,,1.000000e+002,2.980050e+002,2.979968e+002,1,0,2.256144e+000,-8.316294e-002,-8.316294e-002,1.309370e+000,1.522469e+000,1.384675e-001,1.531001e+000,1.744099e+000,-1.812327e-006,-1.812327e-006,,,,,,,,,,,,,,,,,,,,