File: Sample Data Files/2014-07-16 EB on isolated PMN-PT no Ti spontaneous in situ/Ni-NiO_298K_SiO2_PMN-PT_5.0Tprebias_075V_Au_back.rso.dat
[Header]
TITLE,MPMS RSO Measurement
BYAPP,MPMS Measurement,1.1,Summary
FILEOPENTIME, 1405604427.531000 7/17/2014, 6:40:27 AM

INFO, APPNAME, MPMS MultiVu Application, Revision 1.58,  Build 076

INFO, NAME, EB in situ
INFO, WEIGHT, 0.000
INFO, AREA, 0.000
INFO, LENGTH, 0.000
INFO, SHAPE, 0
INFO, COMMENT,
INFO, SEQUENCE FILE: MHcurveUpTo100.seq


INFO, BACKGROUND DATA FILE:, None


STARTUPAXIS,X,4,LINEAR,AUTO,0.000000,0.000000
STARTUPAXIS,Y1,5,LINEAR,AUTO,0.000000,0.000000


STARTUPGROUP,Longitudinal
FIELDGROUP,Longitudinal,1,2,3,4,5,6,7,8,9,10,11,19,20,21,22,23,35
FIELDGROUP,Transverse,1,2,3,4,12,13,14,15,16,17,18,24,25,26,27,28,35

PLOT_APPEARANCE,ALL,HORZ_GRID_ON,VERT_GRID_ON,MARKERS_AND_LINES

[Data]
Time,Comment,Field (Oe),Temperature (K),Long Moment (emu),Long Scan Std Dev,Long Offset (cm),Long Offset Std Dev,Long Algorithm,Long Reg Fit,Long Reg Factor,Trans Moment (emu),Trans Scan Std Dev,Trans Offset (cm),Trans Offset Std Dev,Trans Algorithm,Trans Reg Fit,Trans Reg Factor,Long Moment [w/o ABS] (emu),Long Scan Std Dev [w/o ABS],Long Offset [w/o ABS] (cm),Long Offset Std Dev [w/o ABS],Long Reg Fit [w/o ABS],Trans Moment [w/o ABS] (emu),Trans Scan Std Dev [w/o ABS],Trans Offset [w/o ABS] (cm),Trans Offset Std Dev [w/o ABS],Trans Reg Fit [w/o ABS],RSO Position (deg),Amplitude (cm),Frequency,Cycles to Average,Scans per Measurement,Delta Temp (K),Error,EC Comp. Running,Using ABS,
1405604427.531,,1.000000e+002,2.980009e+002,3.638191e-005,0.000000e+000,-1.312176e-003,0.000000e+000,3,8.924828e-001,1.825000e+000,,,,,,,,,,,,,,,,,,0,4.000000e+000,5.000000e-001,5,1,8.209229e-003,0,,0,
1405604446.265,,1.000000e+002,2.980009e+002,3.638767e-005,0.000000e+000,-1.392582e-003,0.000000e+000,3,8.920962e-001,1.825000e+000,,,,,,,,,,,,,,,,,,0,4.000000e+000,5.000000e-001,5,1,8.209229e-003,0,,0,
1405604465.000,,1.000000e+002,2.979926e+002,3.638835e-005,0.000000e+000,-1.511590e-003,0.000000e+000,3,8.924254e-001,1.825000e+000,,,,,,,,,,,,,,,,,,0,4.000000e+000,5.000000e-001,5,1,8.300781e-003,0,,0,
1405604589.687,,7.500000e+001,2.979968e+002,3.549901e-005,0.000000e+000,-4.750373e-004,0.000000e+000,3,8.991026e-001,1.825000e+000,,,,,,,,,,,,,,,,,,0,4.000000e+000,5.000000e-001,5,1,0.000000e+000,0,,0,
1405604607.687,,7.500000e+001,2.980050e+002,3.550103e-005,0.000000e+000,-2.124669e-004,0.000000e+000,3,8.991296e-001,1.825000e+000,,,,,,,,,,,,,,,,,,0,4.000000e+000,5.000000e-001,5,1,0.000000e+000,0,,0,
1405604624.921,,7.500000e+001,2.980009e+002,3.549480e-005,0.000000e+000,-2.690390e-004,0.000000e+000,3,8.988117e-001,1.825000e+000,,,,,,,,,,,,,,,,,,0,4.000000e+000,5.000000e-001,5,1,8.209229e-003,0,,0,
1405604757.234,,5.000000e+001,2.980050e+002,3.377161e-005,0.000000e+000,2.652842e-003,0.000000e+000,3,9.053355e-001,1.825000e+000,,,,,,,,,,,,,,,,,,0,4.000000e+000,5.000000e-001,5,1,0.000000e+000,0,,0,
1405604774.468,,5.000000e+001,2.980009e+002,3.377731e-005,0.000000e+000,2.480931e-003,0.000000e+000,3,9.054675e-001,1.825000e+000,,,,,,,,,,,,,,,,,,0,4.000000e+000,5.000000e-001,5,1,8.209229e-003,0,,0,
1405604792.718,,5.000000e+001,2.980050e+002,3.377481e-005,0.000000e+000,2.537896e-003,0.000000e+000,3,9.053394e-001,1.825000e+000,,,,,,,,,,,,,,,,,,0,4.000000e+000,5.000000e-001,5,1,0.000000e+000,0,,0,
1405604904.640,,4.500000e+001,2.980050e+002,3.327672e-005,0.000000e+000,3.612372e-003,0.000000e+000,3,9.066699e-001,1.825000e+000,,,,,,,,,,,,,,,,,,0,4.000000e+000,5.000000e-001,5,1,0.000000e+000,0,,0,
1405604922.375,,4.500000e+001,2.979968e+002,3.326841e-005,0.000000e+000,3.779864e-003,0.000000e+000,3,9.065979e-001,1.825000e+000,,,,,,,,,,,,,,,,,,0,4.000000e+000,5.000000e-001,5,1,0.000000e+000,0,,0,
1405604940.359,,4.500000e+001,2.980009e+002,3.325808e-005,0.000000e+000,3.751111e-003,0.000000e+000,3,9.063223e-001,1.825000e+000,,,,,,,,,,,,,,,,,,0,4.000000e+000,5.000000e-001,5,1,8.209229e-003,0,,0,
1405605060.125,,4.000000e+001,2.980009e+002,3.266241e-005,0.000000e+000,4.924956e-003,0.000000e+000,3,9.074180e-001,1.825000e+000,,,,,,,,,,,,,,,,,,0,4.000000e+000,5.000000e-001,5,1,8.209229e-003,0,,0,
1405605077.875,,4.000000e+001,2.980009e+002,3.265850e-005,0.000000e+000,5.112247e-003,0.000000e+000,3,9.074121e-001,1.825000e+000,,,,,,,,,,,,,,,,,,0,4.000000e+000,5.000000e-001,5,1,8.209229e-003,0,,0,
1405605096.125,,4.000000e+001,2.980050e+002,3.264468e-005,0.000000e+000,5.254304e-003,0.000000e+000,3,9.074014e-001,1.825000e+000,,,,,,,,,,,,,,,,,,0,4.000000e+000,5.000000e-001,5,1,0.000000e+000,0,,0,
1405605213.875,,3.500000e+001,2.979968e+002,3.193977e-005,0.000000e+000,6.785962e-003,0.000000e+000,3,9.082379e-001,1.825000e+000,,,,,,,,,,,,,,,,,,0,4.000000e+000,5.000000e-001,5,1,0.000000e+000,0,,0,
1405605230.625,,3.500000e+001,2.979968e+002,3.193428e-005,0.000000e+000,6.869821e-003,0.000000e+000,3,9.082402e-001,1.825000e+000,,,,,,,,,,,,,,,,,,0,4.000000e+000,5.000000e-001,5,1,0.000000e+000,0,,0,
1405605248.390,,3.500000e+001,2.980009e+002,3.193789e-005,0.000000e+000,6.662118e-003,0.000000e+000,3,9.083694e-001,1.825000e+000,,,,,,,,,,,,,,,,,,0,4.000000e+000,5.000000e-001,5,1,8.209229e-003,0,,0,
1405605367.187,,3.000000e+001,2.979926e+002,3.111767e-005,0.000000e+000,8.724964e-003,0.000000e+000,3,9.087150e-001,1.825000e+000,,,,,,,,,,,,,,,,,,0,4.000000e+000,5.000000e-001,5,1,8.300781e-003,0,,0,
1405605384.687,,3.000000e+001,2.979968e+002,3.110279e-005,0.000000e+000,8.794222e-003,0.000000e+000,3,9.086902e-001,1.825000e+000,,,,,,,,,,,,,,,,,,0,4.000000e+000,5.000000e-001,5,1,0.000000e+000,0,,0,
1405605402.484,,3.000000e+001,2.980050e+002,3.109248e-005,0.000000e+000,9.030943e-003,0.000000e+000,3,9.089563e-001,1.825000e+000,,,,,,,,,,,,,,,,,,0,4.000000e+000,5.000000e-001,5,1,0.000000e+000,0,,0,
1405605521.281,,2.500000e+001,2.979968e+002,3.007295e-005,0.000000e+000,1.146245e-002,0.000000e+000,3,9.089348e-001,1.825000e+000,,,,,,,,,,,,,,,,,,0,4.000000e+000,5.000000e-001,5,1,0.000000e+000,0,,0,
1405605539.015,,2.500000e+001,2.980009e+002,3.005696e-005,0.000000e+000,1.143574e-002,0.000000e+000,3,9.092355e-001,1.825000e+000,,,,,,,,,,,,,,,,,,0,4.000000e+000,5.000000e-001,5,1,8.209229e-003,0,,0,
1405605556.781,,2.500000e+001,2.980050e+002,3.004678e-005,0.000000e+000,1.179496e-002,0.000000e+000,3,9.090546e-001,1.825000e+000,,,,,,,,,,,,,,,,,,0,4.000000e+000,5.000000e-001,5,1,1.641846e-002,0,,0,
1405605674.859,,2.000000e+001,2.980009e+002,2.880161e-005,0.000000e+000,1.521145e-002,0.000000e+000,3,9.089136e-001,1.825000e+000,,,,,,,,,,,,,,,,,,0,4.000000e+000,5.000000e-001,5,1,8.209229e-003,0,,0,
1405605692.218,,2.000000e+001,2.980009e+002,2.878507e-005,0.000000e+000,1.514284e-002,0.000000e+000,3,9.088482e-001,1.825000e+000,,,,,,,,,,,,,,,,,,0,4.000000e+000,5.000000e-001,5,1,8.209229e-003,0,,0,
1405605709.953,,2.000000e+001,2.980050e+002,2.876315e-005,0.000000e+000,1.507081e-002,0.000000e+000,3,9.087802e-001,1.825000e+000,,,,,,,,,,,,,,,,,,0,4.000000e+000,5.000000e-001,5,1,0.000000e+000,0,,0,
1405605823.218,,1.500000e+001,2.980050e+002,2.723570e-005,0.000000e+000,1.968610e-002,0.000000e+000,3,9.082432e-001,1.825000e+000,,,,,,,,,,,,,,,,,,0,4.000000e+000,5.000000e-001,5,1,0.000000e+000,0,,0,
1405605840.734,,1.500000e+001,2.980009e+002,2.721401e-005,0.000000e+000,1.994576e-002,0.000000e+000,3,9.078473e-001,1.825000e+000,,,,,,,,,,,,,,,,,,0,4.000000e+000,5.000000e-001,5,1,8.209229e-003,0,,0,
1405605858.484,,1.500000e+001,2.980009e+002,2.718510e-005,0.000000e+000,1.983082e-002,0.000000e+000,3,9.080994e-001,1.825000e+000,,,,,,,,,,,,,,,,,,0,4.000000e+000,5.000000e-001,5,1,8.209229e-003,0,,0,
1405605976.843,,1.000000e+001,2.980009e+002,2.508502e-005,0.000000e+000,2.736031e-002,0.000000e+000,3,9.054207e-001,1.825000e+000,,,,,,,,,,,,,,,,,,0,4.000000e+000,5.000000e-001,5,1,8.209229e-003,0,,0,
1405605995.328,,1.000000e+001,2.979968e+002,2.501901e-005,0.000000e+000,2.758619e-002,0.000000e+000,3,9.058093e-001,1.825000e+000,,,,,,,,,,,,,,,,,,0,4.000000e+000,5.000000e-001,5,1,0.000000e+000,0,,0,
1405606013.843,,1.000000e+001,2.979968e+002,2.498378e-005,0.000000e+000,2.778459e-002,0.000000e+000,3,9.056252e-001,1.825000e+000,,,,,,,,,,,,,,,,,,0,4.000000e+000,5.000000e-001,5,1,0.000000e+000,0,,0,
1405606131.812,,5.000000e+000,2.979926e+002,2.169184e-005,0.000000e+000,4.150325e-002,0.000000e+000,3,8.987978e-001,1.825000e+000,,,,,,,,,,,,,,,,,,0,4.000000e+000,5.000000e-001,5,1,8.300781e-003,0,,0,
1405606149.390,,5.000000e+000,2.980009e+002,2.158159e-005,0.000000e+000,4.241278e-002,0.000000e+000,3,8.983232e-001,1.825000e+000,,,,,,,,,,,,,,,,,,0,4.000000e+000,5.000000e-001,5,1,8.209229e-003,0,,0,
1405606167.640,,5.000000e+000,2.980009e+002,2.145744e-005,0.000000e+000,4.304757e-002,0.000000e+000,3,8.979489e-001,1.825000e+000,,,,,,,,,,,,,,,,,,0,4.000000e+000,5.000000e-001,5,1,8.209229e-003,0,,0,
1405606286.906,,0.000000e+000,2.979968e+002,1.292050e-005,0.000000e+000,1.256409e-001,0.000000e+000,3,8.524309e-001,1.825000e+000,,,,,,,,,,,,,,,,,,0,4.000000e+000,5.000000e-001,5,1,0.000000e+000,0,,0,
1405606304.140,,0.000000e+000,2.979968e+002,1.235734e-005,0.000000e+000,1.347473e-001,0.000000e+000,3,8.465104e-001,1.825000e+000,,,,,,,,,,,,,,,,,,0,4.000000e+000,5.000000e-001,5,1,0.000000e+000,0,,0,
1405606321.875,,0.000000e+000,2.980009e+002,1.188738e-005,0.000000e+000,1.434295e-001,0.000000e+000,3,8.414318e-001,1.825000e+000,,,,,,,,,,,,,,,,,,0,4.000000e+000,5.000000e-001,5,1,8.209229e-003,0,,0,
1405606457.703,,-5.000000e+000,2.980009e+002,-5.177531e-006,0.000000e+000,-2.325955e-001,0.000000e+000,3,6.246698e-001,1.825000e+000,,,,,,,,,,,,,,,,,,0,4.000000e+000,5.000000e-001,5,1,8.209229e-003,0,,0,
1405606474.953,,-5.000000e+000,2.980009e+002,-5.632430e-006,0.000000e+000,-2.105507e-001,0.000000e+000,3,6.571587e-001,1.825000e+000,,,,,,,,,,,,,,,,,,0,4.000000e+000,5.000000e-001,5,1,8.209229e-003,0,,0,
1405606492.203,,-5.000000e+000,2.980009e+002,-5.992322e-006,0.000000e+000,-1.967728e-001,0.000000e+000,3,6.788064e-001,1.825000e+000,,,,,,,,,,,,,,,,,,0,4.000000e+000,5.000000e-001,5,1,8.209229e-003,0,,0,
1405606616.859,,-1.000000e+001,2.980009e+002,-1.591401e-005,0.000000e+000,-6.039535e-002,0.000000e+000,3,8.977115e-001,1.825000e+000,,,,,,,,,,,,,,,,,,0,4.000000e+000,5.000000e-001,5,1,8.209229e-003,0,,0,
1405606634.843,,-1.000000e+001,2.980009e+002,-1.642165e-005,0.000000e+000,-5.737747e-002,0.000000e+000,3,9.018289e-001,1.825000e+000,,,,,,,,,,,,,,,,,,0,4.000000e+000,5.000000e-001,5,1,8.209229e-003,0,,0,
1405606653.078,,-1.000000e+001,2.979968e+002,-1.680294e-005,0.000000e+000,-5.440206e-002,0.000000e+000,3,9.036941e-001,1.825000e+000,,,,,,,,,,,,,,,,,,0,4.000000e+000,5.000000e-001,5,1,0.000000e+000,0,,0,
1405606772.656,,-1.500000e+001,2.979968e+002,-2.083986e-005,0.000000e+000,-2.690055e-002,0.000000e+000,3,9.319906e-001,1.825000e+000,,,,,,,,,,,,,,,,,,0,4.000000e+000,5.000000e-001,5,1,0.000000e+000,0,,0,
1405606791.156,,-1.500000e+001,2.979926e+002,-2.100968e-005,0.000000e+000,-2.563961e-002,0.000000e+000,3,9.327350e-001,1.825000e+000,,,,,,,,,,,,,,,,,,0,4.000000e+000,5.000000e-001,5,1,8.300781e-003,0,,0,
1405606809.390,,-1.500000e+001,2.979926e+002,-2.114088e-005,0.000000e+000,-2.466175e-002,0.000000e+000,3,9.327447e-001,1.825000e+000,,,,,,,,,,,,,,,,,,0,4.000000e+000,5.000000e-001,5,1,8.300781e-003,0,,0,
1405606929.234,,-2.000000e+001,2.980009e+002,-2.325177e-005,0.000000e+000,-1.022215e-002,0.000000e+000,3,9.464883e-001,1.825000e+000,,,,,,,,,,,,,,,,,,0,4.000000e+000,5.000000e-001,5,1,8.209229e-003,0,,0,
1405606946.468,,-2.000000e+001,2.979968e+002,-2.340555e-005,0.000000e+000,-9.370079e-003,0.000000e+000,3,9.466599e-001,1.825000e+000,,,,,,,,,,,,,,,,,,0,4.000000e+000,5.000000e-001,5,1,0.000000e+000,0,,0,
1405606964.203,,-2.000000e+001,2.979968e+002,-2.353565e-005,0.000000e+000,-8.444745e-003,0.000000e+000,3,9.470844e-001,1.825000e+000,,,,,,,,,,,,,,,,,,0,4.000000e+000,5.000000e-001,5,1,0.000000e+000,0,,0,
1405607081.984,,-2.500000e+001,2.979968e+002,-2.580118e-005,0.000000e+000,7.139437e-003,0.000000e+000,3,9.575561e-001,1.825000e+000,,,,,,,,,,,,,,,,,,0,4.000000e+000,5.000000e-001,5,1,0.000000e+000,0,,0,
1405607099.296,,-2.500000e+001,2.979968e+002,-2.597662e-005,0.000000e+000,8.283948e-003,0.000000e+000,3,9.581420e-001,1.825000e+000,,,,,,,,,,,,,,,,,,0,4.000000e+000,5.000000e-001,5,1,0.000000e+000,0,,0,
1405607116.843,,-2.500000e+001,2.980009e+002,-2.612547e-005,0.000000e+000,9.220158e-003,0.000000e+000,3,9.581679e-001,1.825000e+000,,,,,,,,,,,,,,,,,,0,4.000000e+000,5.000000e-001,5,1,8.209229e-003,0,,0,
1405607228.609,,-3.000000e+001,2.980050e+002,-2.727314e-005,0.000000e+000,1.499609e-002,0.000000e+000,3,9.642156e-001,1.825000e+000,,,,,,,,,,,,,,,,,,0,4.000000e+000,5.000000e-001,5,1,0.000000e+000,0,,0,
1405607246.718,,-3.000000e+001,2.980009e+002,-2.729157e-005,0.000000e+000,1.489717e-002,0.000000e+000,3,9.641508e-001,1.825000e+000,,,,,,,,,,,,,,,,,,0,4.000000e+000,5.000000e-001,5,1,8.209229e-003,0,,0,
1405607264.453,,-3.000000e+001,2.980009e+002,-2.729421e-005,0.000000e+000,1.520661e-002,0.000000e+000,3,9.642695e-001,1.825000e+000,,,,,,,,,,,,,,,,,,0,4.000000e+000,5.000000e-001,5,1,8.209229e-003,0,,0,
1405607383.375,,-3.500000e+001,2.979968e+002,-2.787247e-005,0.000000e+000,1.856187e-002,0.000000e+000,3,9.692740e-001,1.825000e+000,,,,,,,,,,,,,,,,,,0,4.000000e+000,5.000000e-001,5,1,0.000000e+000,0,,0,
1405607400.875,,-3.500000e+001,2.980009e+002,-2.789547e-005,0.000000e+000,1.855952e-002,0.000000e+000,3,9.696098e-001,1.825000e+000,,,,,,,,,,,,,,,,,,0,4.000000e+000,5.000000e-001,5,1,8.209229e-003,0,,0,
1405607418.796,,-3.500000e+001,2.979926e+002,-2.789916e-005,0.000000e+000,1.869187e-002,0.000000e+000,3,9.697202e-001,1.825000e+000,,,,,,,,,,,,,,,,,,0,4.000000e+000,5.000000e-001,5,1,8.300781e-003,0,,0,
1405607538.718,,-4.000000e+001,2.980091e+002,-2.838461e-005,0.000000e+000,2.103141e-002,0.000000e+000,3,9.738539e-001,1.825000e+000,,,,,,,,,,,,,,,,,,0,4.000000e+000,5.000000e-001,5,1,8.209229e-003,0,,0,
1405607557.203,,-4.000000e+001,2.980009e+002,-2.838493e-005,0.000000e+000,2.115701e-002,0.000000e+000,3,9.738037e-001,1.825000e+000,,,,,,,,,,,,,,,,,,0,4.000000e+000,5.000000e-001,5,1,8.209229e-003,0,,0,
1405607574.500,,-4.000000e+001,2.980009e+002,-2.839315e-005,0.000000e+000,2.096642e-002,0.000000e+000,3,9.741108e-001,1.825000e+000,,,,,,,,,,,,,,,,,,0,4.000000e+000,5.000000e-001,5,1,8.209229e-003,0,,0,
1405607693.250,,-4.500000e+001,2.979968e+002,-2.877360e-005,0.000000e+000,2.186549e-002,0.000000e+000,3,9.768074e-001,1.825000e+000,,,,,,,,,,,,,,,,,,0,4.000000e+000,5.000000e-001,5,1,0.000000e+000,0,,0,
1405607711.031,,-4.500000e+001,2.980009e+002,-2.877618e-005,0.000000e+000,2.170881e-002,0.000000e+000,3,9.770721e-001,1.825000e+000,,,,,,,,,,,,,,,,,,0,4.000000e+000,5.000000e-001,5,1,8.209229e-003,0,,0,
1405607728.781,,-4.500000e+001,2.979968e+002,-2.879372e-005,0.000000e+000,2.157005e-002,0.000000e+000,3,9.770131e-001,1.825000e+000,,,,,,,,,,,,,,,,,,0,4.000000e+000,5.000000e-001,5,1,0.000000e+000,0,,0,
1405607848.531,,-5.000000e+001,2.979968e+002,-2.913319e-005,0.000000e+000,2.320132e-002,0.000000e+000,3,9.797989e-001,1.825000e+000,,,,,,,,,,,,,,,,,,0,4.000000e+000,5.000000e-001,5,1,1.651001e-002,0,,0,
1405607866.328,,-5.000000e+001,2.980009e+002,-2.913295e-005,0.000000e+000,2.305855e-002,0.000000e+000,3,9.799557e-001,1.825000e+000,,,,,,,,,,,,,,,,,,0,4.000000e+000,5.000000e-001,5,1,8.209229e-003,0,,0,
1405607884.562,,-5.000000e+001,2.979926e+002,-2.914643e-005,0.000000e+000,2.307601e-002,0.000000e+000,3,9.798265e-001,1.825000e+000,,,,,,,,,,,,,,,,,,0,4.000000e+000,5.000000e-001,5,1,8.300781e-003,0,,0,
1405608027.171,,-7.500000e+001,2.979968e+002,-3.039700e-005,0.000000e+000,2.632978e-002,0.000000e+000,3,9.833502e-001,1.825000e+000,,,,,,,,,,,,,,,,,,0,4.000000e+000,5.000000e-001,5,1,0.000000e+000,0,,0,
1405608045.406,,-7.500000e+001,2.979968e+002,-3.038909e-005,0.000000e+000,2.633334e-002,0.000000e+000,3,9.834119e-001,1.825000e+000,,,,,,,,,,,,,,,,,,0,4.000000e+000,5.000000e-001,5,1,0.000000e+000,0,,0,
1405608063.156,,-7.500000e+001,2.980009e+002,-3.040284e-005,0.000000e+000,2.653549e-002,0.000000e+000,3,9.829358e-001,1.825000e+000,,,,,,,,,,,,,,,,,,0,4.000000e+000,5.000000e-001,5,1,8.209229e-003,0,,0,
1405608194.031,,-1.000000e+002,2.980009e+002,-3.121320e-005,0.000000e+000,2.438300e-002,0.000000e+000,3,9.752728e-001,1.825000e+000,,,,,,,,,,,,,,,,,,0,4.000000e+000,5.000000e-001,5,1,8.209229e-003,0,,0,
1405608211.765,,-1.000000e+002,2.979968e+002,-3.124649e-005,0.000000e+000,2.629104e-002,0.000000e+000,3,9.734425e-001,1.825000e+000,,,,,,,,,,,,,,,,,,0,4.000000e+000,5.000000e-001,5,1,0.000000e+000,0,,0,
1405608229.250,,-1.000000e+002,2.979968e+002,-3.116126e-005,0.000000e+000,2.648016e-002,0.000000e+000,3,9.722765e-001,1.825000e+000,,,,,,,,,,,,,,,,,,0,4.000000e+000,5.000000e-001,5,1,0.000000e+000,0,,0,
1405608363.062,,-7.500000e+001,2.979968e+002,-3.067105e-005,0.000000e+000,2.673765e-002,0.000000e+000,3,9.811102e-001,1.825000e+000,,,,,,,,,,,,,,,,,,0,4.000000e+000,5.000000e-001,5,1,0.000000e+000,0,,0,
1405608380.828,,-7.500000e+001,2.979968e+002,-3.067323e-005,0.000000e+000,2.639534e-002,0.000000e+000,3,9.812682e-001,1.825000e+000,,,,,,,,,,,,,,,,,,0,4.000000e+000,5.000000e-001,5,1,0.000000e+000,0,,0,
1405608399.140,,-7.500000e+001,2.980050e+002,-3.066603e-005,0.000000e+000,2.657375e-002,0.000000e+000,3,9.812301e-001,1.825000e+000,,,,,,,,,,,,,,,,,,0,4.000000e+000,5.000000e-001,5,1,0.000000e+000,0,,0,
1405608529.953,,-5.000000e+001,2.980009e+002,-2.980786e-005,0.000000e+000,2.771829e-002,0.000000e+000,3,9.837354e-001,1.825000e+000,,,,,,,,,,,,,,,,,,0,4.000000e+000,5.000000e-001,5,1,8.209229e-003,0,,0,
1405608548.234,,-5.000000e+001,2.979968e+002,-2.978925e-005,0.000000e+000,2.762894e-002,0.000000e+000,3,9.836869e-001,1.825000e+000,,,,,,,,,,,,,,,,,,0,4.000000e+000,5.000000e-001,5,1,0.000000e+000,0,,0,
1405608566.484,,-5.000000e+001,2.979968e+002,-2.980066e-005,0.000000e+000,2.785360e-002,0.000000e+000,3,9.835483e-001,1.825000e+000,,,,,,,,,,,,,,,,,,0,4.000000e+000,5.000000e-001,5,1,0.000000e+000,0,,0,
1405608686.968,,-4.500000e+001,2.979968e+002,-2.953695e-005,0.000000e+000,2.831348e-002,0.000000e+000,3,9.832942e-001,1.825000e+000,,,,,,,,,,,,,,,,,,0,4.000000e+000,5.000000e-001,5,1,0.000000e+000,0,,0,
1405608705.750,,-4.500000e+001,2.979968e+002,-2.952593e-005,0.000000e+000,2.813581e-002,0.000000e+000,3,9.829800e-001,1.825000e+000,,,,,,,,,,,,,,,,,,0,4.000000e+000,5.000000e-001,5,1,0.000000e+000,0,,0,
1405608724.000,,-4.500000e+001,2.979968e+002,-2.953890e-005,0.000000e+000,2.822832e-002,0.000000e+000,3,9.829046e-001,1.825000e+000,,,,,,,,,,,,,,,,,,0,4.000000e+000,5.000000e-001,5,1,0.000000e+000,0,,0,
1405608843.000,,-4.000000e+001,2.979926e+002,-2.925097e-005,0.000000e+000,2.912246e-002,0.000000e+000,3,9.822003e-001,1.825000e+000,,,,,,,,,,,,,,,,,,0,4.000000e+000,5.000000e-001,5,1,8.300781e-003,0,,0,
1405608860.750,,-4.000000e+001,2.980009e+002,-2.926090e-005,0.000000e+000,2.875232e-002,0.000000e+000,3,9.822611e-001,1.825000e+000,,,,,,,,,,,,,,,,,,0,4.000000e+000,5.000000e-001,5,1,8.209229e-003,0,,0,
1405608878.234,,-4.000000e+001,2.980009e+002,-2.925249e-005,0.000000e+000,2.908079e-002,0.000000e+000,3,9.823093e-001,1.825000e+000,,,,,,,,,,,,,,,,,,0,4.000000e+000,5.000000e-001,5,1,8.209229e-003,0,,0,
1405608997.984,,-3.500000e+001,2.979968e+002,-2.893156e-005,0.000000e+000,2.941552e-002,0.000000e+000,3,9.810142e-001,1.825000e+000,,,,,,,,,,,,,,,,,,0,4.000000e+000,5.000000e-001,5,1,1.651001e-002,0,,0,
1405609015.718,,-3.500000e+001,2.980009e+002,-2.893734e-005,0.000000e+000,2.960636e-002,0.000000e+000,3,9.812021e-001,1.825000e+000,,,,,,,,,,,,,,,,,,0,4.000000e+000,5.000000e-001,5,1,8.209229e-003,0,,0,
1405609034.453,,-3.500000e+001,2.979968e+002,-2.893160e-005,0.000000e+000,2.959039e-002,0.000000e+000,3,9.810277e-001,1.825000e+000,,,,,,,,,,,,,,,,,,0,4.000000e+000,5.000000e-001,5,1,0.000000e+000,0,,0,
1405609160.234,,-3.000000e+001,2.980009e+002,-2.855842e-005,0.000000e+000,3.025550e-002,0.000000e+000,3,9.795052e-001,1.825000e+000,,,,,,,,,,,,,,,,,,0,4.000000e+000,5.000000e-001,5,1,8.209229e-003,0,,0,
1405609177.968,,-3.000000e+001,2.979968e+002,-2.855491e-005,0.000000e+000,3.055166e-002,0.000000e+000,3,9.792230e-001,1.825000e+000,,,,,,,,,,,,,,,,,,0,4.000000e+000,5.000000e-001,5,1,0.000000e+000,0,,0,
1405609195.718,,-3.000000e+001,2.979926e+002,-2.856295e-005,0.000000e+000,3.051520e-002,0.000000e+000,3,9.792889e-001,1.825000e+000,,,,,,,,,,,,,,,,,,0,4.000000e+000,5.000000e-001,5,1,8.300781e-003,0,,0,
1405609315.562,,-2.500000e+001,2.980009e+002,-2.814643e-005,0.000000e+000,3.128760e-002,0.000000e+000,3,9.775258e-001,1.825000e+000,,,,,,,,,,,,,,,,,,0,4.000000e+000,5.000000e-001,5,1,8.209229e-003,0,,0,
1405609333.343,,-2.500000e+001,2.980009e+002,-2.813011e-005,0.000000e+000,3.165272e-002,0.000000e+000,3,9.773554e-001,1.825000e+000,,,,,,,,,,,,,,,,,,0,4.000000e+000,5.000000e-001,5,1,8.209229e-003,0,,0,
1405609351.593,,-2.500000e+001,2.979968e+002,-2.814235e-005,0.000000e+000,3.105680e-002,0.000000e+000,3,9.773019e-001,1.825000e+000,,,,,,,,,,,,,,,,,,0,4.000000e+000,5.000000e-001,5,1,0.000000e+000,0,,0,
1405609469.906,,-2.000000e+001,2.979968e+002,-2.766075e-005,0.000000e+000,3.260410e-002,0.000000e+000,3,9.748541e-001,1.825000e+000,,,,,,,,,,,,,,,,,,0,4.000000e+000,5.000000e-001,5,1,0.000000e+000,0,,0,
1405609487.140,,-2.000000e+001,2.980009e+002,-2.765770e-005,0.000000e+000,3.241730e-002,0.000000e+000,3,9.747091e-001,1.825000e+000,,,,,,,,,,,,,,,,,,0,4.000000e+000,5.000000e-001,5,1,8.209229e-003,0,,0,
1405609505.375,,-2.000000e+001,2.979968e+002,-2.764182e-005,0.000000e+000,3.260570e-002,0.000000e+000,3,9.749862e-001,1.825000e+000,,,,,,,,,,,,,,,,,,0,4.000000e+000,5.000000e-001,5,1,0.000000e+000,0,,0,
1405609615.921,,-1.500000e+001,2.980050e+002,-2.709592e-005,0.000000e+000,3.392699e-002,0.000000e+000,3,9.718378e-001,1.825000e+000,,,,,,,,,,,,,,,,,,0,4.000000e+000,5.000000e-001,5,1,0.000000e+000,0,,0,
1405609633.187,,-1.500000e+001,2.980009e+002,-2.709137e-005,0.000000e+000,3.379148e-002,0.000000e+000,3,9.720226e-001,1.825000e+000,,,,,,,,,,,,,,,,,,0,4.000000e+000,5.000000e-001,5,1,8.209229e-003,0,,0,
1405609650.453,,-1.500000e+001,2.980050e+002,-2.709082e-005,0.000000e+000,3.393983e-002,0.000000e+000,3,9.716152e-001,1.825000e+000,,,,,,,,,,,,,,,,,,0,4.000000e+000,5.000000e-001,5,1,0.000000e+000,0,,0,
1405609768.203,,-1.000000e+001,2.980009e+002,-2.641650e-005,0.000000e+000,3.584208e-002,0.000000e+000,3,9.681728e-001,1.825000e+000,,,,,,,,,,,,,,,,,,0,4.000000e+000,5.000000e-001,5,1,8.209229e-003,0,,0,
1405609786.437,,-1.000000e+001,2.980009e+002,-2.641677e-005,0.000000e+000,3.585532e-002,0.000000e+000,3,9.683579e-001,1.825000e+000,,,,,,,,,,,,,,,,,,0,4.000000e+000,5.000000e-001,5,1,8.209229e-003,0,,0,
1405609804.687,,-1.000000e+001,2.979968e+002,-2.641211e-005,0.000000e+000,3.590272e-002,0.000000e+000,3,9.681389e-001,1.825000e+000,,,,,,,,,,,,,,,,,,0,4.000000e+000,5.000000e-001,5,1,0.000000e+000,0,,0,
1405609929.484,,-5.000000e+000,2.980050e+002,-2.560027e-005,0.000000e+000,3.808537e-002,0.000000e+000,3,9.643112e-001,1.825000e+000,,,,,,,,,,,,,,,,,,0,4.000000e+000,5.000000e-001,5,1,1.641846e-002,0,,0,
1405609947.750,,-5.000000e+000,2.979968e+002,-2.558795e-005,0.000000e+000,3.848492e-002,0.000000e+000,3,9.640429e-001,1.825000e+000,,,,,,,,,,,,,,,,,,0,4.000000e+000,5.000000e-001,5,1,0.000000e+000,0,,0,
1405609964.984,,-5.000000e+000,2.979968e+002,-2.558067e-005,0.000000e+000,3.838186e-002,0.000000e+000,3,9.639204e-001,1.825000e+000,,,,,,,,,,,,,,,,,,0,4.000000e+000,5.000000e-001,5,1,0.000000e+000,0,,0,
1405610084.234,,0.000000e+000,2.980050e+002,-2.463151e-005,0.000000e+000,4.125030e-002,0.000000e+000,3,9.589432e-001,1.825000e+000,,,,,,,,,,,,,,,,,,0,4.000000e+000,5.000000e-001,5,1,0.000000e+000,0,,0,
1405610101.968,,0.000000e+000,2.979968e+002,-2.462987e-005,0.000000e+000,4.154179e-002,0.000000e+000,3,9.594871e-001,1.825000e+000,,,,,,,,,,,,,,,,,,0,4.000000e+000,5.000000e-001,5,1,1.651001e-002,0,,0,
1405610120.203,,0.000000e+000,2.980009e+002,-2.461314e-005,0.000000e+000,4.151553e-002,0.000000e+000,3,9.594899e-001,1.825000e+000,,,,,,,,,,,,,,,,,,0,4.000000e+000,5.000000e-001,5,1,8.209229e-003,0,,0,
1405610239.187,,5.000000e+000,2.980009e+002,-2.337923e-005,0.000000e+000,4.604841e-002,0.000000e+000,3,9.530977e-001,1.825000e+000,,,,,,,,,,,,,,,,,,0,4.000000e+000,5.000000e-001,5,1,8.209229e-003,0,,0,
1405610257.171,,5.000000e+000,2.979968e+002,-2.335063e-005,0.000000e+000,4.686620e-002,0.000000e+000,3,9.524816e-001,1.825000e+000,,,,,,,,,,,,,,,,,,0,4.000000e+000,5.000000e-001,5,1,0.000000e+000,0,,0,
1405610275.156,,5.000000e+000,2.980050e+002,-2.334824e-005,0.000000e+000,4.682124e-002,0.000000e+000,3,9.525242e-001,1.825000e+000,,,,,,,,,,,,,,,,,,0,4.000000e+000,5.000000e-001,5,1,1.641846e-002,0,,0,
1405610395.171,,1.000000e+001,2.979968e+002,-2.189413e-005,0.000000e+000,5.284919e-002,0.000000e+000,3,9.451187e-001,1.825000e+000,,,,,,,,,,,,,,,,,,0,4.000000e+000,5.000000e-001,5,1,0.000000e+000,0,,0,
1405610412.656,,1.000000e+001,2.979968e+002,-2.187705e-005,0.000000e+000,5.312533e-002,0.000000e+000,3,9.450592e-001,1.825000e+000,,,,,,,,,,,,,,,,,,0,4.000000e+000,5.000000e-001,5,1,0.000000e+000,0,,0,
1405610429.890,,1.000000e+001,2.979968e+002,-2.186319e-005,0.000000e+000,5.315125e-002,0.000000e+000,3,9.448189e-001,1.825000e+000,,,,,,,,,,,,,,,,,,0,4.000000e+000,5.000000e-001,5,1,0.000000e+000,0,,0,
1405610548.125,,1.500000e+001,2.980009e+002,-1.986321e-005,0.000000e+000,6.326479e-002,0.000000e+000,3,9.331100e-001,1.825000e+000,,,,,,,,,,,,,,,,,,0,4.000000e+000,5.000000e-001,5,1,8.209229e-003,0,,0,
1405610565.859,,1.500000e+001,2.980050e+002,-1.982640e-005,0.000000e+000,6.338218e-002,0.000000e+000,3,9.331381e-001,1.825000e+000,,,,,,,,,,,,,,,,,,0,4.000000e+000,5.000000e-001,5,1,1.641846e-002,0,,0,
1405610583.625,,1.500000e+001,2.980091e+002,-1.980424e-005,0.000000e+000,6.390060e-002,0.000000e+000,3,9.323930e-001,1.825000e+000,,,,,,,,,,,,,,,,,,0,4.000000e+000,5.000000e-001,5,1,8.209229e-003,0,,0,
1405610702.453,,2.000000e+001,2.980009e+002,-1.679587e-005,0.000000e+000,8.409902e-002,0.000000e+000,3,9.119509e-001,1.825000e+000,,,,,,,,,,,,,,,,,,0,4.000000e+000,5.000000e-001,5,1,8.209229e-003,0,,0,
1405610719.937,,2.000000e+001,2.980009e+002,-1.673148e-005,0.000000e+000,8.453736e-002,0.000000e+000,3,9.116943e-001,1.825000e+000,,,,,,,,,,,,,,,,,,0,4.000000e+000,5.000000e-001,5,1,8.209229e-003,0,,0,
1405610738.421,,2.000000e+001,2.979968e+002,-1.665168e-005,0.000000e+000,8.531468e-002,0.000000e+000,3,9.110870e-001,1.825000e+000,,,,,,,,,,,,,,,,,,0,4.000000e+000,5.000000e-001,5,1,1.651001e-002,0,,0,
1405610857.406,,2.500000e+001,2.980009e+002,-9.453809e-006,0.000000e+000,1.873532e-001,0.000000e+000,3,8.102323e-001,1.825000e+000,,,,,,,,,,,,,,,,,,0,4.000000e+000,5.000000e-001,5,1,8.209229e-003,0,,0,
1405610875.390,,2.500000e+001,2.980009e+002,-9.128659e-006,0.000000e+000,1.966239e-001,0.000000e+000,3,8.018357e-001,1.825000e+000,,,,,,,,,,,,,,,,,,0,4.000000e+000,5.000000e-001,5,1,8.209229e-003,0,,0,
1405610893.625,,2.500000e+001,2.980050e+002,-8.831787e-006,0.000000e+000,2.043643e-001,0.000000e+000,3,7.935004e-001,1.825000e+000,,,,,,,,,,,,,,,,,,0,4.000000e+000,5.000000e-001,5,1,0.000000e+000,0,,0,
1405611024.125,,3.000000e+001,2.980009e+002,8.822110e-006,0.000000e+000,-2.777422e-001,0.000000e+000,3,8.244899e-001,1.825000e+000,,,,,,,,,,,,,,,,,,0,4.000000e+000,5.000000e-001,5,1,8.209229e-003,0,,0,
1405611042.375,,3.000000e+001,2.980009e+002,9.211562e-006,0.000000e+000,-2.613019e-001,0.000000e+000,3,8.294875e-001,1.825000e+000,,,,,,,,,,,,,,,,,,0,4.000000e+000,5.000000e-001,5,1,8.209229e-003,0,,0,
1405611060.359,,3.000000e+001,2.980009e+002,9.535864e-006,0.000000e+000,-2.491437e-001,0.000000e+000,3,8.334607e-001,1.825000e+000,,,,,,,,,,,,,,,,,,0,4.000000e+000,5.000000e-001,5,1,8.209229e-003,0,,0,
1405611178.343,,3.500000e+001,2.979926e+002,2.046795e-005,0.000000e+000,-8.786593e-002,0.000000e+000,3,9.031036e-001,1.825000e+000,,,,,,,,,,,,,,,,,,0,4.000000e+000,5.000000e-001,5,1,8.300781e-003,0,,0,
1405611196.609,,3.500000e+001,2.979926e+002,2.094360e-005,0.000000e+000,-8.491624e-002,0.000000e+000,3,9.045216e-001,1.825000e+000,,,,,,,,,,,,,,,,,,0,4.000000e+000,5.000000e-001,5,1,8.300781e-003,0,,0,
1405611213.843,,3.500000e+001,2.979968e+002,2.131648e-005,0.000000e+000,-8.264481e-002,0.000000e+000,3,9.055586e-001,1.825000e+000,,,,,,,,,,,,,,,,,,0,4.000000e+000,5.000000e-001,5,1,0.000000e+000,0,,0,
1405611332.593,,4.000000e+001,2.980009e+002,2.657551e-005,0.000000e+000,-4.674941e-002,0.000000e+000,3,9.139673e-001,1.825000e+000,,,,,,,,,,,,,,,,,,0,4.000000e+000,5.000000e-001,5,1,8.209229e-003,0,,0,
1405611350.828,,4.000000e+001,2.980009e+002,2.671376e-005,0.000000e+000,-4.586358e-002,0.000000e+000,3,9.141684e-001,1.825000e+000,,,,,,,,,,,,,,,,,,0,4.000000e+000,5.000000e-001,5,1,8.209229e-003,0,,0,
1405611368.593,,4.000000e+001,2.980009e+002,2.683106e-005,0.000000e+000,-4.543773e-002,0.000000e+000,3,9.143804e-001,1.825000e+000,,,,,,,,,,,,,,,,,,0,4.000000e+000,5.000000e-001,5,1,8.209229e-003,0,,0,
1405611486.578,,4.500000e+001,2.980009e+002,2.904326e-005,0.000000e+000,-3.174711e-002,0.000000e+000,3,9.150697e-001,1.825000e+000,,,,,,,,,,,,,,,,,,0,4.000000e+000,5.000000e-001,5,1,8.209229e-003,0,,0,
1405611505.312,,4.500000e+001,2.979926e+002,2.917150e-005,0.000000e+000,-3.084895e-002,0.000000e+000,3,9.154406e-001,1.825000e+000,,,,,,,,,,,,,,,,,,0,4.000000e+000,5.000000e-001,5,1,8.300781e-003,0,,0,
1405611522.546,,4.500000e+001,2.979926e+002,2.927950e-005,0.000000e+000,-3.006419e-002,0.000000e+000,3,9.156113e-001,1.825000e+000,,,,,,,,,,,,,,,,,,0,4.000000e+000,5.000000e-001,5,1,8.300781e-003,0,,0,
1405611642.078,,5.000000e+001,2.979968e+002,3.166244e-005,0.000000e+000,-1.482078e-002,0.000000e+000,3,9.160344e-001,1.825000e+000,,,,,,,,,,,,,,,,,,0,4.000000e+000,5.000000e-001,5,1,0.000000e+000,0,,0,
1405611660.312,,5.000000e+001,2.979968e+002,3.182638e-005,0.000000e+000,-1.383883e-002,0.000000e+000,3,9.164172e-001,1.825000e+000,,,,,,,,,,,,,,,,,,0,4.000000e+000,5.000000e-001,5,1,0.000000e+000,0,,0,
1405611677.546,,5.000000e+001,2.979926e+002,3.195106e-005,0.000000e+000,-1.275185e-002,0.000000e+000,3,9.164750e-001,1.825000e+000,,,,,,,,,,,,,,,,,,0,4.000000e+000,5.000000e-001,5,1,8.300781e-003,0,,0,
1405611803.343,,7.500000e+001,2.980009e+002,3.505434e-005,0.000000e+000,2.779264e-003,0.000000e+000,3,9.037374e-001,1.825000e+000,,,,,,,,,,,,,,,,,,0,4.000000e+000,5.000000e-001,5,1,8.209229e-003,0,,0,
1405611821.140,,7.500000e+001,2.980009e+002,3.504684e-005,0.000000e+000,2.524621e-003,0.000000e+000,3,9.040257e-001,1.825000e+000,,,,,,,,,,,,,,,,,,0,4.000000e+000,5.000000e-001,5,1,8.209229e-003,0,,0,
1405611838.625,,7.500000e+001,2.979968e+002,3.506631e-005,0.000000e+000,2.446937e-003,0.000000e+000,3,9.038370e-001,1.825000e+000,,,,,,,,,,,,,,,,,,0,4.000000e+000,5.000000e-001,5,1,0.000000e+000,0,,0,
1405611962.875,,1.000000e+002,2.980009e+002,3.642134e-005,0.000000e+000,3.672652e-003,0.000000e+000,3,8.923544e-001,1.825000e+000,,,,,,,,,,,,,,,,,,0,4.000000e+000,5.000000e-001,5,1,8.209229e-003,0,,0,
1405611980.109,,1.000000e+002,2.979926e+002,3.643063e-005,0.000000e+000,3.668492e-003,0.000000e+000,3,8.925873e-001,1.825000e+000,,,,,,,,,,,,,,,,,,0,4.000000e+000,5.000000e-001,5,1,8.300781e-003,0,,0,
1405611997.843,,1.000000e+002,2.979968e+002,3.643389e-005,0.000000e+000,3.654086e-003,0.000000e+000,3,8.923994e-001,1.825000e+000,,,,,,,,,,,,,,,,,,0,4.000000e+000,5.000000e-001,5,1,1.651001e-002,0,,0,