File: Sample Data Files/2014-07-16 EB on isolated PMN-PT no Ti spontaneous in situ/Ni-NiO_298K_SiO2_PMN-PT_5.0Tprebias_100V_Au_back.rso.raw
[Header]
TITLE,MPMS RSO Measurement
BYAPP,MPMS Measurement,2.1,Raw with ABS
FILEOPENTIME, 1405574774.875000 7/16/2014, 10:26:14 PM

INFO, APPNAME, MPMS MultiVu Application, Revision 1.58,  Build 076

INFO, NAME, EB in situ
INFO, WEIGHT, 0.000
INFO, AREA, 0.000
INFO, LENGTH, 0.000
INFO, SHAPE, 0
INFO, COMMENT,
INFO, SEQUENCE FILE: MHcurveUpTo100.seq


INFO, BACKGROUND DATA FILE:, None


STARTUPAXIS,X,8,LINEAR,AUTO,0.000000,0.000000
STARTUPAXIS,Y1,9,LINEAR,AUTO,0.000000,0.000000


STARTUPGROUP,Longitudinal
FIELDGROUP,Longitudinal,1,2,3,4,5,6,7,8,9,10,11,12,13,14,15,16,17,18,19,20,21,22
FIELDGROUP,Transverse,1,2,3,4,5,6,7,8,23,24,25,26,27,28,29,30,31,32,33,34,35,36

PLOT_APPEARANCE,ALL,HORZ_GRID_ON,VERT_GRID_ON,MARKERS_ONLY

[Data]
Time,Comment,Field (Oe),Start Temperature (K),End Temperature (K),Scan,Rejected,Position (cm),Long Voltage,Long Average Voltage,Long Detrended Voltage,Long Demeaned Voltage,Long Reg Fit,Long Detrended Fit,Long Demeaned Fit,Long Scaled Response,Long Avg. Scaled Response,Long Background Response,Long Response [w/ABS],Long Detrended Resp. [w/ABS],Long Fit [w/ABS],Long Detrended Fit [w/ABS],Trans Voltage,Trans Average Voltage,Trans Detrended Voltage,Trans Demeaned Voltage,Trans Reg Fit,Trans Detrended Fit,Trans Demeaned Fit,Trans Scaled Response,Trans Avg. Scaled Response,Trans Background Response,Trans Response [w/ABS],Trans Detrended Resp. [w/ABS],Trans Adjusted Fit,Trans Detrended Fit [w/ABS],
1405574774.875,,1.000000e+002,2.979968e+002,2.980050e+002,1,0,2.079745e+000,-5.767998e-002,-5.767998e-002,2.609406e+000,2.609406e+000,4.739500e-002,2.714480e+000,2.714480e+000,-1.256990e-006,-1.256990e-006,,,,,,,,,,,,,,,,,,,,
1405574774.875,,1.000000e+002,2.979968e+002,2.980050e+002,1,0,3.705822e+000,-3.722953e+000,-3.722953e+000,-1.209512e+000,-1.055868e+000,-3.701658e+000,-1.188217e+000,-1.034572e+000,-8.113238e-005,-8.113238e-005,,,,,,,,,,,,,,,,,,,,
1405574793.109,,1.000000e+002,2.979968e+002,2.979968e+002,1,0,4.359733e-001,-3.756981e+000,-3.756981e+000,-1.161946e+000,-1.080948e+000,-3.786281e+000,-1.191245e+000,-1.110248e+000,-8.187394e-005,-8.187394e-005,,,,,,,,,,,,,,,,,,,,
1405574810.406,,1.000000e+002,2.979968e+002,2.979968e+002,1,0,1.899852e+000,-1.147496e-001,-1.147496e-001,2.538187e+000,2.541860e+000,2.344984e-002,2.676386e+000,2.680060e+000,-2.500678e-006,-2.500678e-006,,,,,,,,,,,,,,,,,,,,
1405574810.406,,1.000000e+002,2.979968e+002,2.979968e+002,1,0,3.810039e+000,-3.728599e+000,-3.728599e+000,-1.233613e+000,-1.071989e+000,-3.622163e+000,-1.127178e+000,-9.655535e-001,-8.125542e-005,-8.125542e-005,,,,,,,,,,,,,,,,,,,,
1405574935.218,,7.500000e+001,2.979968e+002,2.979968e+002,1,0,5.563078e-001,-3.491012e+000,-3.491012e+000,-9.729753e-001,-9.002893e-001,-3.580602e+000,-1.062565e+000,-9.898794e-001,-7.607799e-005,-7.607799e-005,,,,,,,,,,,,,,,,,,,,
1405574952.984,,7.500000e+001,2.979968e+002,2.980050e+002,1,0,1.718754e+000,-4.445021e-001,-4.445021e-001,2.147483e+000,2.153911e+000,-3.884748e-001,2.203511e+000,2.209939e+000,-9.686825e-006,-9.686825e-006,,,,,,,,,,,,,,,,,,,,
1405574952.984,,7.500000e+001,2.979968e+002,2.980050e+002,1,0,3.893578e+000,-3.633076e+000,-3.633076e+000,-1.179288e+000,-1.034663e+000,-3.465825e+000,-1.012037e+000,-8.674116e-001,-7.917392e-005,-7.917392e-005,,,,,,,,,,,,,,,,,,,,
1405574970.750,,7.500000e+001,2.979968e+002,2.979968e+002,1,0,6.832266e-001,-3.262734e+000,-3.262734e+000,-7.500502e-001,-6.722291e-001,-3.396003e+000,-8.833193e-001,-8.054981e-001,-7.110323e-005,-7.110323e-005,,,,,,,,,,,,,,,,,,,,
1405575100.031,,5.000000e+001,2.979968e+002,2.980050e+002,1,0,1.538598e+000,-8.612323e-001,-8.612323e-001,1.548499e+000,1.557059e+000,-9.088831e-001,1.500848e+000,1.509408e+000,-1.876847e-005,-1.876847e-005,,,,,,,,,,,,,,,,,,,,
1405575100.031,,5.000000e+001,2.979968e+002,2.980050e+002,1,0,3.953416e+000,-3.360393e+000,-3.360393e+000,-1.073352e+000,-9.421017e-001,-3.167526e+000,-8.804851e-001,-7.492344e-001,-7.323163e-005,-7.323163e-005,,,,,,,,,,,,,,,,,,,,
1405575118.531,,5.000000e+001,2.980050e+002,2.979968e+002,1,0,8.157555e-001,-2.741783e+000,-2.741783e+000,-4.298634e-001,-3.585417e-001,-2.881942e+000,-5.700225e-001,-4.987009e-001,-5.975052e-005,-5.975052e-005,,,,,,,,,,,,,,,,,,,,
1405575136.265,,5.000000e+001,2.979968e+002,2.979968e+002,1,0,1.361113e+000,-1.320689e+000,-1.320688e+000,1.067434e+000,1.078954e+000,-1.447291e+000,9.408314e-001,9.523518e-001,-2.878121e-005,-2.878121e-005,,,,,,,,,,,,,,,,,,,,
1405575136.265,,5.000000e+001,2.979968e+002,2.979968e+002,1,0,3.987427e+000,-3.332011e+000,-3.332011e+000,-1.067733e+000,-9.323683e-001,-3.111590e+000,-8.473121e-001,-7.119477e-001,-7.261311e-005,-7.261311e-005,,,,,,,,,,,,,,,,,,,,
1405575254.515,,4.500000e+001,2.979968e+002,2.979968e+002,1,0,9.541418e-001,-2.357097e+000,-2.357097e+000,-9.452099e-002,-2.136397e-002,-2.502911e+000,-2.403352e-001,-1.671782e-001,-5.136725e-005,-5.136725e-005,,,,,,,,,,,,,,,,,,,,
1405575272.546,,4.500000e+001,2.979968e+002,2.979968e+002,1,0,1.187337e+000,-1.751610e+000,-1.751610e+000,5.576489e-001,5.716782e-001,-1.918275e+000,3.909833e-001,4.050126e-001,-3.817211e-005,-3.817211e-005,,,,,,,,,,,,,,,,,,,,
1405575272.546,,4.500000e+001,2.979968e+002,2.979968e+002,1,0,3.994459e+000,-3.230537e+000,-3.230537e+000,-1.041930e+000,-9.072490e-001,-3.008608e+000,-8.200011e-001,-6.853201e-001,-7.040177e-005,-7.040177e-005,,,,,,,,,,,,,,,,,,,,
1405575290.296,,4.500000e+001,2.979968e+002,2.980050e+002,1,0,1.098432e+000,-1.945403e+000,-1.945402e+000,2.971942e-001,3.753335e-001,-2.103048e+000,1.395487e-001,2.176881e-001,-4.239536e-005,-4.239536e-005,,,,,,,,,,,,,,,,,,,,
1405575407.093,,4.000000e+001,2.979968e+002,2.979968e+002,1,0,1.018205e+000,-2.137516e+000,-2.137516e+000,1.023261e-001,1.186872e-001,-2.319406e+000,-7.956324e-002,-6.320214e-002,-4.658204e-005,-4.658204e-005,,,,,,,,,,,,,,,,,,,,
1405575407.093,,4.000000e+001,2.979968e+002,2.979968e+002,1,0,3.974720e+000,-3.144017e+000,-3.144017e+000,-1.021429e+000,-8.878131e-001,-2.937824e+000,-8.152355e-001,-6.816199e-001,-6.851630e-005,-6.851630e-005,,,,,,,,,,,,,,,,,,,,
1405575425.343,,4.000000e+001,2.979968e+002,2.979968e+002,1,0,1.249541e+000,-1.477249e+000,-1.477248e+000,6.876419e-001,7.656679e-001,-1.615741e+000,5.491495e-001,6.271756e-001,-3.219309e-005,-3.219309e-005,,,,,,,,,,,,,,,,,,,,
1405575443.578,,4.000000e+001,2.979968e+002,2.979968e+002,1,0,8.552450e-001,-2.486648e+000,-2.486648e+000,-2.715947e-001,-2.520318e-001,-2.678962e+000,-4.639091e-001,-4.443462e-001,-5.419053e-005,-5.419053e-005,,,,,,,,,,,,,,,,,,,,
1405575443.578,,4.000000e+001,2.979968e+002,2.979968e+002,1,0,3.929997e+000,-3.129673e+000,-3.129673e+000,-1.034792e+000,-8.950570e-001,-2.949336e+000,-8.544548e-001,-7.147195e-001,-6.820372e-005,-6.820372e-005,,,,,,,,,,,,,,,,,,,,
1405575569.078,,3.500000e+001,2.980050e+002,2.980050e+002,1,0,1.407876e+000,-1.057924e+000,-1.057924e+000,1.059816e+000,1.133212e+000,-1.149140e+000,9.686002e-001,1.041996e+000,-2.305493e-005,-2.305493e-005,,,,,,,,,,,,,,,,,,,,
1405575587.109,,3.500000e+001,2.980050e+002,2.979968e+002,1,0,6.993810e-001,-2.726524e+000,-2.726524e+000,-5.794793e-001,-5.581477e-001,-2.879329e+000,-7.322851e-001,-7.109535e-001,-5.941807e-005,-5.941807e-005,,,,,,,,,,,,,,,,,,,,
1405575587.109,,3.500000e+001,2.980050e+002,2.979968e+002,1,0,3.863022e+000,-3.047578e+000,-3.047578e+000,-1.015191e+000,-8.792024e-001,-2.910327e+000,-8.779404e-001,-7.419515e-001,-6.641469e-005,-6.641469e-005,,,,,,,,,,,,,,,,,,,,
1405575605.343,,3.500000e+001,2.980050e+002,2.979968e+002,1,0,1.573228e+000,-6.237983e-001,-6.237983e-001,1.456417e+000,1.538488e+000,-6.410903e-001,1.439125e+000,1.521196e+000,-1.359419e-005,-1.359419e-005,,,,,,,,,,,,,,,,,,,,
1405575725.328,,3.000000e+001,2.979968e+002,2.979968e+002,1,0,5.522624e-001,-2.826930e+000,-2.826930e+000,-7.526390e-001,-7.303436e-001,-2.940013e+000,-8.657221e-001,-8.434267e-001,-6.160620e-005,-6.160620e-005,,,,,,,,,,,,,,,,,,,,
1405575725.328,,3.000000e+001,2.979968e+002,2.979968e+002,1,0,3.777328e+000,-2.940611e+000,-2.940611e+000,-9.728430e-001,-8.440249e-001,-2.860450e+000,-8.926817e-001,-7.638636e-001,-6.408362e-005,-6.408362e-005,,,,,,,,,,,,,,,,,,,,
1405575743.562,,3.000000e+001,2.979968e+002,2.980050e+002,1,0,1.744831e+000,-3.201391e-001,-3.201392e-001,1.702967e+000,1.782575e+000,-2.382153e-001,1.784891e+000,1.864498e+000,-6.976672e-006,-6.976672e-006,,,,,,,,,,,,,,,,,,,,
1405575760.359,,3.000000e+001,2.979968e+002,2.979968e+002,1,0,4.166670e-001,-2.916654e+000,-2.916654e+000,-8.624329e-001,-8.364425e-001,-2.974370e+000,-9.201495e-001,-8.941591e-001,-6.356154e-005,-6.356154e-005,,,,,,,,,,,,,,,,,,,,
1405575760.359,,3.000000e+001,2.979968e+002,2.979968e+002,1,0,3.676817e+000,-2.885373e+000,-2.885372e+000,-9.429104e-001,-8.051610e-001,-2.862557e+000,-9.200951e-001,-7.823458e-001,-6.287983e-005,-6.287983e-005,,,,,,,,,,,,,,,,,,,,
1405575879.093,,2.500000e+001,2.979968e+002,2.980050e+002,1,0,1.921407e+000,-1.271096e-001,-1.271096e-001,1.793134e+000,1.866230e+000,2.739720e-002,1.947641e+000,2.020737e+000,-2.770053e-006,-2.770053e-006,,,,,,,,,,,,,,,,,,,,
1405575897.343,,2.500000e+001,2.979968e+002,2.980050e+002,1,0,2.951507e-001,-2.848750e+000,-2.848750e+000,-8.624581e-001,-8.357849e-001,-2.838322e+000,-8.520301e-001,-8.253570e-001,-6.208177e-005,-6.208177e-005,,,,,,,,,,,,,,,,,,,,
1405575897.343,,2.500000e+001,2.979968e+002,2.980050e+002,1,0,3.565010e+000,-2.711112e+000,-2.711112e+000,-8.290873e-001,-6.981463e-001,-2.735840e+000,-8.538154e-001,-7.228744e-001,-5.908226e-005,-5.908226e-005,,,,,,,,,,,,,,,,,,,,
1405575914.828,,2.500000e+001,2.980050e+002,2.979968e+002,1,0,2.101077e+000,-7.446516e-002,-7.446516e-002,1.810390e+000,1.889879e+000,8.721592e-002,1.972071e+000,2.051560e+000,-1.622792e-006,-1.622792e-006,,,,,,,,,,,,,,,,,,,,
1405576034.562,,2.000000e+001,2.980050e+002,2.980050e+002,1,0,1.908567e-001,-2.619404e+000,-2.619404e+000,-8.140209e-001,-7.866834e-001,-2.547747e+000,-7.423644e-001,-7.150270e-001,-5.708373e-005,-5.708373e-005,,,,,,,,,,,,,,,,,,,,
1405576034.562,,2.000000e+001,2.980050e+002,2.980050e+002,1,0,3.444577e+000,-2.357860e+000,-2.357860e+000,-6.504365e-001,-5.251399e-001,-2.423166e+000,-7.157424e-001,-5.904459e-001,-5.138400e-005,-5.138400e-005,,,,,,,,,,,,,,,,,,,,
1405576052.046,,2.000000e+001,2.979968e+002,2.979968e+002,1,0,2.282052e+000,-2.182073e-001,-2.182073e-001,1.555084e+000,1.635797e+000,-1.314965e-001,1.641794e+000,1.722508e+000,-4.755314e-006,-4.755314e-006,,,,,,,,,,,,,,,,,,,,
1405576069.328,,2.000000e+001,2.979968e+002,2.979968e+002,1,0,1.073632e-001,-2.611469e+000,-2.611469e+000,-8.033414e-001,-7.717130e-001,-2.492361e+000,-6.842332e-001,-6.526048e-001,-5.691081e-005,-5.691081e-005,,,,,,,,,,,,,,,,,,,,
1405576069.328,,2.000000e+001,2.979968e+002,2.979968e+002,1,0,3.317760e+000,-2.172155e+000,-2.172155e+000,-4.686447e-001,-3.323991e-001,-2.268420e+000,-5.649102e-001,-4.286647e-001,-4.733699e-005,-4.733699e-005,,,,,,,,,,,,,,,,,,,,
1405576187.859,,1.500000e+001,2.980050e+002,2.979968e+002,1,0,2.462364e+000,-4.130681e-001,-4.130680e-001,1.204855e+000,1.282104e+000,-4.310296e-001,1.186894e+000,1.264143e+000,-9.001848e-006,-9.001848e-006,,,,,,,,,,,,,,,,,,,,
1405576205.843,,1.500000e+001,2.979968e+002,2.979968e+002,1,0,4.743819e-002,-2.404248e+000,-2.404248e+000,-7.317557e-001,-6.997143e-001,-2.256055e+000,-5.835626e-001,-5.515212e-001,-5.239494e-005,-5.239494e-005,,,,,,,,,,,,,,,,,,,,
1405576205.843,,1.500000e+001,2.979968e+002,2.979968e+002,1,0,3.185070e+000,-1.766564e+000,-1.766564e+000,-1.924845e-001,-6.202996e-002,-1.886256e+000,-3.121769e-001,-1.817224e-001,-3.849811e-005,-3.849811e-005,,,,,,,,,,,,,,,,,,,,
1405576222.578,,1.500000e+001,2.979968e+002,2.979968e+002,1,0,2.640161e+000,-7.060457e-001,-7.060457e-001,8.985718e-001,9.811007e-001,-8.115209e-001,7.930966e-001,8.756256e-001,-1.538661e-005,-1.538661e-005,,,,,,,,,,,,,,,,,,,,
1405576341.156,,1.000000e+001,2.980132e+002,2.979968e+002,1,0,1.354783e-002,-2.143925e+000,-2.143925e+000,-6.533761e-001,-6.223780e-001,-1.983368e+000,-4.928187e-001,-4.618206e-001,-4.672184e-005,-4.672184e-005,,,,,,,,,,,,,,,,,,,,
1405576341.156,,1.000000e+001,2.980132e+002,2.979968e+002,1,0,3.046890e+000,-1.318247e+000,-1.318247e+000,8.344087e-002,2.033002e-001,-1.443792e+000,-4.210451e-002,7.775486e-002,-2.872811e-005,-2.872811e-005,,,,,,,,,,,,,,,,,,,,
1405576359.656,,1.000000e+001,2.979968e+002,2.979968e+002,1,0,2.813879e+000,-8.952605e-001,-8.952605e-001,5.302171e-001,6.088287e-001,-1.042774e+000,3.827031e-001,4.613147e-001,-1.951011e-005,-1.951011e-005,,,,,,,,,,,,,,,,,,,,
1405576377.390,,1.000000e+001,2.979968e+002,2.980050e+002,1,0,6.585951e-003,-2.097842e+000,-2.097842e+000,-6.517548e-001,-6.193631e-001,-1.931184e+000,-4.850963e-001,-4.527045e-001,-4.571757e-005,-4.571757e-005,,,,,,,,,,,,,,,,,,,,
1405576377.390,,1.000000e+001,2.979968e+002,2.980050e+002,1,0,2.902517e+000,-1.013520e+000,-1.013520e+000,3.455152e-001,4.649597e-001,-1.143563e+000,2.154723e-001,3.349168e-001,-2.208729e-005,-2.208729e-005,,,,,,,,,,,,,,,,,,,,
1405576495.421,,5.000000e+000,2.979968e+002,2.979968e+002,1,0,2.982795e+000,-9.945983e-001,-9.945982e-001,2.337245e-001,3.024057e-001,-1.143022e+000,8.530056e-002,1.539817e-001,-2.167495e-005,-2.167495e-005,,,,,,,,,,,,,,,,,,,,
1405576513.906,,5.000000e+000,2.979968e+002,2.979968e+002,1,0,2.634209e-002,-1.781823e+000,-1.781823e+000,-5.580860e-001,-5.266004e-001,-1.627346e+000,-4.036090e-001,-3.721234e-001,-3.883069e-005,-3.883069e-005,,,,,,,,,,,,,,,,,,,,
1405576513.906,,5.000000e+000,2.979968e+002,2.979968e+002,1,0,2.751429e+000,-6.024354e-001,-6.024354e-001,5.416615e-001,6.527874e-001,-6.955139e-001,4.485829e-001,5.597089e-001,-1.312868e-005,-1.312868e-005,,,,,,,,,,,,,,,,,,,,
1405576532.640,,5.000000e+000,2.980050e+002,2.979968e+002,1,0,3.145879e+000,-1.186102e+000,-1.186102e+000,-3.596448e-003,7.090962e-002,-1.325172e+000,-1.426665e-001,-6.816041e-002,-2.584833e-005,-2.584833e-005,,,,,,,,,,,,,,,,,,,,
1405576651.875,,0.000000e+000,2.980050e+002,2.980050e+002,1,0,7.096416e-002,-1.169469e+000,-1.169469e+000,-3.809657e-001,-3.543025e-001,-1.035376e+000,-2.468726e-001,-2.202095e-001,-2.548587e-005,-2.548587e-005,,,,,,,,,,,,,,,,,,,,
1405576651.875,,0.000000e+000,2.980050e+002,2.980050e+002,1,0,2.593010e+000,-1.977599e-001,-1.977599e-001,5.270483e-001,6.174068e-001,-2.119745e-001,5.128338e-001,6.031923e-001,-4.309719e-006,-4.309719e-006,,,,,,,,,,,,,,,,,,,,
1405576669.609,,0.000000e+000,2.979968e+002,2.979968e+002,1,0,3.301717e+000,-7.382428e-001,-7.382427e-001,-5.214103e-002,6.934166e-003,-8.377170e-001,-1.516153e-001,-9.254009e-002,-1.608829e-005,-1.608829e-005,,,,,,,,,,,,,,,,,,,,
1405576687.859,,0.000000e+000,2.979968e+002,2.979968e+002,1,0,1.380408e-001,-1.070894e+000,-1.070894e+000,-3.561518e-001,-3.296412e-001,-9.635602e-001,-2.488176e-001,-2.223069e-001,-2.333766e-005,-2.333766e-005,,,,,,,,,,,,,,,,,,,,
1405576687.859,,0.000000e+000,2.979968e+002,2.979968e+002,1,0,2.427818e+000,-7.950072e-002,-7.950072e-002,5.752441e-001,6.617526e-001,-1.982864e-002,6.349162e-001,7.214247e-001,-1.732534e-006,-1.732534e-006,,,,,,,,,,,,,,,,,,,,
1405576807.609,,-5.000000e+000,2.980050e+002,2.980050e+002,1,0,3.448617e+000,1.857051e-001,1.857051e-001,1.089472e-001,2.190651e-001,8.122234e-002,4.464382e-003,1.145823e-001,4.047011e-006,4.047011e-006,,,,,,,,,,,,,,,,,,,,
1405576826.343,,-5.000000e+000,2.979968e+002,2.979968e+002,1,0,2.237659e-001,6.530961e-002,6.530961e-002,-4.944121e-004,4.861680e-002,5.844588e-002,-7.358148e-003,4.175307e-002,1.423271e-006,1.423271e-006,,,,,,,,,,,,,,,,,,,,
1405576826.343,,-5.000000e+000,2.979968e+002,2.979968e+002,1,0,2.256203e+000,1.022370e-002,1.022370e-002,-1.611694e-001,-6.469111e-003,1.828105e-001,1.141739e-002,1.661177e-001,2.228018e-007,2.228018e-007,,,,,,,,,,,,,,,,,,,,
1405576844.578,,-5.000000e+000,2.979968e+002,2.979968e+002,1,0,3.584237e+000,2.192755e-001,2.192755e-001,7.483111e-002,1.477281e-001,1.684567e-001,2.401230e-002,9.690926e-002,4.778599e-006,4.778599e-006,,,,,,,,,,,,,,,,,,,,
1405576968.062,,-1.000000e+001,2.979968e+002,2.979968e+002,1,0,3.242326e-001,1.144444e+000,1.144444e+000,3.467298e-001,3.716419e-001,1.164203e+000,3.664887e-001,3.914008e-001,2.494048e-005,2.494048e-005,,,,,,,,,,,,,,,,,,,,
1405576986.062,,-1.000000e+001,2.980050e+002,2.979968e+002,1,0,2.079674e+000,-1.831111e-002,-1.831111e-002,-8.716551e-001,-8.716551e-001,1.472561e-002,-8.386184e-001,-8.386184e-001,-3.990477e-007,-3.990477e-007,,,,,,,,,,,,,,,,,,,,
1405576986.062,,-1.000000e+001,2.980050e+002,2.979968e+002,1,0,3.705826e+000,1.261635e+000,1.261635e+000,3.594012e-001,4.082912e-001,1.269504e+000,3.672696e-001,4.161596e-001,2.749439e-005,2.749439e-005,,,,,,,,,,,,,,,,,,,,
1405577003.828,,-1.000000e+001,2.979968e+002,2.979885e+002,1,0,4.359523e-001,1.264840e+000,1.264840e+000,3.852870e-001,4.124116e-001,1.257991e+000,3.784383e-001,4.055629e-001,2.756422e-005,2.756422e-005,,,,,,,,,,,,,,,,,,,,
1405577121.828,,-1.500000e+001,2.979968e+002,2.979968e+002,1,0,1.899962e+000,-2.639851e-002,-2.639851e-002,-1.254895e+000,-1.254175e+000,-1.491772e-002,-1.243414e+000,-1.242694e+000,-5.752935e-007,-5.752935e-007,,,,,,,,,,,,,,,,,,,,
1405577121.828,,-1.500000e+001,2.979968e+002,2.979968e+002,1,0,3.810090e+000,1.737266e+000,1.737266e+000,4.777962e-001,5.094898e-001,1.766660e+000,5.071899e-001,5.388836e-001,3.785964e-005,3.785964e-005,,,,,,,,,,,,,,,,,,,,
1405577139.562,,-1.500000e+001,2.979885e+002,2.980050e+002,1,0,5.562985e-001,1.818598e+000,1.818598e+000,5.308137e-001,5.524230e-001,1.785660e+000,4.978758e-001,5.194851e-001,3.963207e-005,3.963207e-005,,,,,,,,,,,,,,,,,,,,
1405577157.796,,-1.500000e+001,2.979968e+002,2.979968e+002,1,0,1.718775e+000,1.715140e-001,1.715140e-001,-1.105952e+000,-1.103996e+000,1.654095e-001,-1.112056e+000,-1.110101e+000,3.737745e-006,3.737745e-006,,,,,,,,,,,,,,,,,,,,
1405577157.796,,-1.500000e+001,2.979968e+002,2.979968e+002,1,0,3.893614e+000,1.751457e+000,1.751457e+000,4.319476e-001,4.759470e-001,1.800340e+000,4.808303e-001,5.248297e-001,3.816890e-005,3.816890e-005,,,,,,,,,,,,,,,,,,,,
1405577282.531,,-2.000000e+001,2.979968e+002,2.979968e+002,1,0,6.832125e-001,2.003845e+000,2.003845e+000,5.498843e-001,5.597092e-001,1.948869e+000,4.949085e-001,5.047333e-001,4.366908e-005,4.366908e-005,,,,,,,,,,,,,,,,,,,,
1405577300.562,,-2.000000e+001,2.979968e+002,2.979968e+002,1,0,1.538766e+000,5.719169e-001,5.719169e-001,-9.574304e-001,-9.555750e-001,5.544514e-001,-9.748958e-001,-9.730405e-001,1.246358e-005,1.246358e-005,,,,,,,,,,,,,,,,,,,,
1405577300.562,,-2.000000e+001,2.979968e+002,2.979968e+002,1,0,3.953515e+000,2.040315e+000,2.040315e+000,4.843749e-001,5.128230e-001,2.100470e+000,5.445303e-001,5.729784e-001,4.446385e-005,4.446385e-005,,,,,,,,,,,,,,,,,,,,
1405577318.046,,-2.000000e+001,2.979885e+002,2.979968e+002,1,0,8.158861e-001,1.967528e+000,1.967528e+000,4.041865e-001,4.181583e-001,1.903499e+000,3.401568e-001,3.541286e-001,4.287764e-005,4.287764e-005,,,,,,,,,,,,,,,,,,,,
1405577437.296,,-2.500000e+001,2.979968e+002,2.979968e+002,1,0,1.361216e+000,1.047395e+000,1.047395e+000,-6.391406e-001,-6.383883e-001,1.011137e+000,-6.753988e-001,-6.746465e-001,2.282550e-005,2.282550e-005,,,,,,,,,,,,,,,,,,,,
1405577437.296,,-2.500000e+001,2.979968e+002,2.979968e+002,1,0,3.987494e+000,2.246467e+000,2.246468e+000,5.518441e-001,5.606841e-001,2.302160e+000,6.075368e-001,6.163768e-001,4.895644e-005,4.895644e-005,,,,,,,,,,,,,,,,,,,,
1405577455.531,,-2.500000e+001,2.979968e+002,2.979968e+002,1,0,9.541831e-001,1.956847e+000,1.956847e+000,2.365477e-001,2.448443e-001,1.897485e+000,1.771857e-001,1.854824e-001,4.264484e-005,4.264484e-005,,,,,,,,,,,,,,,,,,,,
1405577473.812,,-2.500000e+001,2.979968e+002,2.980050e+002,1,0,1.186900e+000,1.530351e+000,1.530351e+000,-2.306866e-001,-2.282779e-001,1.470033e+000,-2.910042e-001,-2.885956e-001,3.335037e-005,3.335037e-005,,,,,,,,,,,,,,,,,,,,
1405577473.812,,-2.500000e+001,2.979968e+002,2.980050e+002,1,0,3.994387e+000,2.337870e+000,2.337870e+000,5.561187e-001,5.792418e-001,2.394470e+000,6.127188e-001,6.358418e-001,5.094835e-005,5.094835e-005,,,,,,,,,,,,,,,,,,,,
1405577592.046,,-3.000000e+001,2.980050e+002,2.979968e+002,1,0,1.098460e+000,1.754662e+000,1.754662e+000,-5.870654e-002,-5.871034e-002,1.715423e+000,-9.794512e-002,-9.794891e-002,3.823868e-005,3.823868e-005,,,,,,,,,,,,,,,,,,,,
1405577610.281,,-3.000000e+001,2.979968e+002,2.980050e+002,1,0,1.018009e+000,1.984161e+000,1.984161e+000,1.358324e-001,1.370823e-001,1.923515e+000,7.518693e-002,7.643688e-002,4.324007e-005,4.324007e-005,,,,,,,,,,,,,,,,,,,,
1405577610.281,,-3.000000e+001,2.979968e+002,2.980050e+002,1,0,3.974681e+000,2.483902e+000,2.483902e+000,6.266150e-001,6.368229e-001,2.535932e+000,6.786451e-001,6.888530e-001,5.413072e-005,5.413072e-005,,,,,,,,,,,,,,,,,,,,
1405577628.515,,-3.000000e+001,2.979968e+002,2.980050e+002,1,0,1.249550e+000,1.423536e+000,1.423536e+000,-4.406304e-001,-4.319532e-001,1.418288e+000,-4.458784e-001,-4.372011e-001,3.102258e-005,3.102258e-005,,,,,,,,,,,,,,,,,,,,
1405577747.765,,-3.500000e+001,2.979968e+002,2.979968e+002,1,0,8.549398e-001,2.375408e+000,2.375408e+000,4.546822e-001,4.538140e-001,2.334746e+000,4.140202e-001,4.131520e-001,5.176635e-005,5.176635e-005,,,,,,,,,,,,,,,,,,,,
1405577747.765,,-3.500000e+001,2.979968e+002,2.979968e+002,1,0,3.929918e+000,2.618183e+000,2.618183e+000,7.027900e-001,6.965888e-001,2.657604e+000,7.422106e-001,7.360094e-001,5.705704e-005,5.705704e-005,,,,,,,,,,,,,,,,,,,,
1405577765.015,,-3.500000e+001,2.979968e+002,2.980050e+002,1,0,1.407858e+000,1.058687e+000,1.058687e+000,-8.811472e-001,-8.814772e-001,1.084136e+000,-8.556982e-001,-8.560282e-001,2.307156e-005,2.307156e-005,,,,,,,,,,,,,,,,,,,,
1405577783.515,,-3.500000e+001,2.980050e+002,2.979968e+002,1,0,6.992154e-001,2.666707e+000,2.666707e+000,7.004893e-001,7.007159e-001,2.627494e+000,6.612757e-001,6.615022e-001,5.811452e-005,5.811452e-005,,,,,,,,,,,,,,,,,,,,
1405577783.515,,-3.500000e+001,2.980050e+002,2.979968e+002,1,0,3.862950e+000,2.727439e+000,2.727439e+000,7.600036e-001,7.614478e-001,2.756084e+000,7.886488e-001,7.900931e-001,5.943802e-005,5.943802e-005,,,,,,,,,,,,,,,,,,,,
1405577901.750,,-4.000000e+001,2.979968e+002,2.979968e+002,1,0,1.573259e+000,6.144902e-001,6.144902e-001,-1.358739e+000,-1.362765e+000,6.619436e-001,-1.311285e+000,-1.315311e+000,1.339134e-005,1.339134e-005,,,,,,,,,,,,,,,,,,,,
1405577919.765,,-4.000000e+001,2.980050e+002,2.980050e+002,1,0,5.524911e-001,2.857601e+000,2.857601e+000,8.544466e-001,8.538377e-001,2.839353e+000,8.361993e-001,8.355904e-001,6.227455e-005,6.227455e-005,,,,,,,,,,,,,,,,,,,,
1405577919.765,,-4.000000e+001,2.980050e+002,2.980050e+002,1,0,3.777336e+000,2.852718e+000,2.852718e+000,8.524730e-001,8.489547e-001,2.861641e+000,8.613963e-001,8.578780e-001,6.216814e-005,6.216814e-005,,,,,,,,,,,,,,,,,,,,
1405577938.265,,-4.000000e+001,2.980050e+002,2.980050e+002,1,0,1.744845e+000,2.862636e-001,2.862636e-001,-1.750538e+000,-1.747478e+000,3.224443e-001,-1.714357e+000,-1.711297e+000,6.238429e-006,6.238429e-006,,,,,,,,,,,,,,,,,,,,
1405578049.812,,-4.500000e+001,2.980050e+002,2.979968e+002,1,0,4.167930e-001,2.957549e+000,2.957549e+000,9.121478e-001,9.108264e-001,2.955456e+000,9.100550e-001,9.087336e-001,6.445265e-005,6.445265e-005,,,,,,,,,,,,,,,,,,,,
1405578049.812,,-4.500000e+001,2.980050e+002,2.979968e+002,1,0,3.676836e+000,2.955107e+000,2.955107e+000,9.153880e-001,9.083848e-001,2.949733e+000,9.100141e-001,9.030108e-001,6.439944e-005,6.439944e-005,,,,,,,,,,,,,,,,,,,,
1405578067.546,,-4.500000e+001,2.979968e+002,2.979968e+002,1,0,1.921443e+000,1.785333e-002,1.785333e-002,-2.025440e+000,-2.026034e+000,1.418972e-002,-2.029104e+000,-2.029697e+000,3.890703e-007,3.890703e-007,,,,,,,,,,,,,,,,,,,,
1405578085.281,,-4.500000e+001,2.979968e+002,2.979968e+002,1,0,2.952276e-001,2.964568e+000,2.964568e+000,8.744654e-001,8.740528e-001,2.978371e+000,8.882684e-001,8.878558e-001,6.460561e-005,6.460561e-005,,,,,,,,,,,,,,,,,,,,
1405578085.281,,-4.500000e+001,2.979968e+002,2.979968e+002,1,0,3.565030e+000,2.991271e+000,2.991272e+000,9.027824e-001,9.007566e-001,2.978566e+000,8.900769e-001,8.880510e-001,6.518756e-005,6.518756e-005,,,,,,,,,,,,,,,,,,,,
1405578205.515,,-5.000000e+001,2.980050e+002,2.979885e+002,1,0,2.101200e+000,8.362071e-002,8.362072e-002,-2.061082e+000,-2.063660e+000,3.917097e-002,-2.105532e+000,-2.108110e+000,1.822311e-006,1.822311e-006,,,,,,,,,,,,,,,,,,,,
1405578224.000,,-5.000000e+001,2.979885e+002,2.979968e+002,1,0,1.908937e-001,2.958312e+000,2.958312e+000,8.227695e-001,8.215353e-001,2.983251e+000,8.477086e-001,8.464744e-001,6.446925e-005,6.446925e-005,,,,,,,,,,,,,,,,,,,,
1405578224.000,,-5.000000e+001,2.979885e+002,2.979968e+002,1,0,3.444673e+000,2.972045e+000,2.972045e+000,8.409250e-001,8.352685e-001,2.949702e+000,8.185816e-001,8.129251e-001,6.476853e-005,6.476853e-005,,,,,,,,,,,,,,,,,,,,
1405578242.000,,-5.000000e+001,2.979968e+002,2.979968e+002,1,0,2.282158e+000,3.047273e-001,3.047273e-001,-1.835480e+000,-1.833900e+000,2.744628e-001,-1.865745e+000,-1.864165e+000,6.640795e-006,6.640795e-006,,,,,,,,,,,,,,,,,,,,
1405578385.031,,-7.500000e+001,2.979885e+002,2.979968e+002,1,0,1.074148e-001,1.882077e+000,1.882077e+000,4.143127e-001,4.297894e-001,1.885933e+000,4.181690e-001,4.336457e-001,8.203042e-005,8.203042e-005,,,,,,,,,,,,,,,,,,,,
1405578385.031,,-7.500000e+001,2.979885e+002,2.979968e+002,1,0,3.317761e+000,1.870785e+000,1.870785e+000,3.518286e-001,4.184976e-001,1.865067e+000,3.461113e-001,4.127803e-001,8.153827e-005,8.153827e-005,,,,,,,,,,,,,,,,,,,,
1405578402.265,,-7.500000e+001,2.979968e+002,2.979968e+002,1,0,2.462311e+000,7.293924e-001,7.293923e-001,-7.607524e-001,-7.172647e-001,7.161574e-001,-7.739874e-001,-7.304997e-001,3.179061e-005,3.179061e-005,,,,,,,,,,,,,,,,,,,,
1405578419.750,,-7.500000e+001,2.979968e+002,2.979968e+002,1,0,4.748593e-002,1.836756e+000,1.836756e+000,3.845646e-001,4.041926e-001,1.842951e+000,3.907591e-001,4.103870e-001,8.005514e-005,8.005514e-005,,,,,,,,,,,,,,,,,,,,
1405578419.750,,-7.500000e+001,2.979968e+002,2.979968e+002,1,0,3.185081e+000,1.731163e+000,1.731162e+000,2.186848e-001,2.985985e-001,1.728479e+000,2.160012e-001,2.959149e-001,7.545282e-005,7.545282e-005,,,,,,,,,,,,,,,,,,,,
1405578551.250,,-1.000000e+002,2.979968e+002,2.980050e+002,1,0,2.640048e+000,1.394238e+000,1.394238e+000,-5.397460e-001,-4.420640e-001,1.403329e+000,-5.306547e-001,-4.329728e-001,6.076782e-005,6.076782e-005,,,,,,,,,,,,,,,,,,,,
1405578569.281,,-1.000000e+002,2.980050e+002,2.979968e+002,1,0,1.350234e-002,2.386547e+000,2.386547e+000,4.000241e-001,4.492401e-001,2.376620e+000,3.900971e-001,4.393131e-001,1.040176e-004,1.040176e-004,,,,,,,,,,,,,,,,,,,,
1405578569.281,,-1.000000e+002,2.980050e+002,2.979968e+002,1,0,3.046821e+000,2.168798e+000,2.168798e+000,4.118904e-002,2.314907e-001,2.186224e+000,5.861458e-002,2.489163e-001,9.452698e-005,9.452698e-005,,,,,,,,,,,,,,,,,,,,
1405578586.765,,-1.000000e+002,2.980050e+002,2.980050e+002,1,0,2.813902e+000,1.619617e+000,1.619617e+000,-2.868241e-001,-1.898000e-001,1.638657e+000,-2.677848e-001,-1.707608e-001,7.059096e-005,7.059096e-005,,,,,,,,,,,,,,,,,,,,
1405578712.500,,-7.500000e+001,2.979968e+002,2.980050e+002,1,0,6.612767e-003,1.503494e+000,1.503494e+000,3.747932e-001,3.693930e-001,1.504737e+000,3.760354e-001,3.706352e-001,6.552989e-005,6.552989e-005,,,,,,,,,,,,,,,,,,,,
1405578712.500,,-7.500000e+001,2.979968e+002,2.980050e+002,1,0,2.902476e+000,9.533983e-001,9.533982e-001,-1.607899e-001,-1.807032e-001,9.767684e-001,-1.374198e-001,-1.573330e-001,4.155392e-005,4.155392e-005,,,,,,,,,,,,,,,,,,,,
1405578730.250,,-7.500000e+001,2.980050e+002,2.979968e+002,1,0,2.982981e+000,1.105686e+000,1.105686e+000,-3.193927e-002,-3.869820e-002,1.109645e+000,-2.798033e-002,-3.473926e-002,4.819137e-005,4.819137e-005,,,,,,,,,,,,,,,,,,,,
1405578747.500,,-7.500000e+001,2.980050e+002,2.979968e+002,1,0,2.629067e-002,1.535386e+000,1.535386e+000,3.809993e-001,3.788357e-001,1.539897e+000,3.855102e-001,3.833466e-001,6.691990e-005,6.691990e-005,,,,,,,,,,,,,,,,,,,,
1405578747.500,,-7.500000e+001,2.980050e+002,2.979968e+002,1,0,2.751328e+000,7.649464e-001,7.649465e-001,-3.839678e-001,-3.916041e-001,7.952032e-001,-3.537110e-001,-3.613473e-001,3.334024e-005,3.334024e-005,,,,,,,,,,,,,,,,,,,,
1405578878.000,,-5.000000e+001,2.980050e+002,2.979885e+002,1,0,3.145930e+000,1.232948e+000,1.232948e+000,1.770615e-001,1.679454e-001,1.219213e+000,1.633266e-001,1.542104e-001,5.373823e-005,5.373823e-005,,,,,,,,,,,,,,,,,,,,
1405578895.734,,-5.000000e+001,2.980050e+002,2.979968e+002,1,0,7.102750e-002,1.448103e+000,1.448103e+000,3.731362e-001,3.684292e-001,1.460658e+000,3.856906e-001,3.809836e-001,6.311581e-005,6.311581e-005,,,,,,,,,,,,,,,,,,,,
1405578895.734,,-5.000000e+001,2.980050e+002,2.979968e+002,1,0,2.593030e+000,4.709006e-001,4.709006e-001,-5.928219e-001,-6.087735e-001,4.980783e-001,-5.656441e-001,-5.815958e-001,2.052428e-005,2.052428e-005,,,,,,,,,,,,,,,,,,,,
1405578913.484,,-5.000000e+001,2.979968e+002,2.980050e+002,1,0,3.301718e+000,1.399426e+000,1.399426e+000,3.303106e-001,3.203188e-001,1.386562e+000,3.174467e-001,3.074549e-001,6.099422e-005,6.099422e-005,,,,,,,,,,,,,,,,,,,,
1405579026.218,,-4.500000e+001,2.980050e+002,2.980050e+002,1,0,1.380124e-001,1.439100e+000,1.439100e+000,4.019455e-001,3.959793e-001,1.445337e+000,4.081823e-001,4.022161e-001,6.272345e-005,6.272345e-005,,,,,,,,,,,,,,,,,,,,
1405579026.218,,-4.500000e+001,2.980050e+002,2.980050e+002,1,0,2.427774e+000,2.198859e-001,2.198859e-001,-8.037663e-001,-8.232352e-001,2.383902e-001,-7.852620e-001,-8.047308e-001,9.583765e-006,9.583765e-006,,,,,,,,,,,,,,,,,,,,
1405579044.203,,-4.500000e+001,2.979968e+002,2.979968e+002,1,0,3.448635e+000,1.462447e+000,1.462447e+000,4.226832e-001,4.124888e-001,1.454234e+000,4.144708e-001,4.042764e-001,6.374102e-005,6.374102e-005,,,,,,,,,,,,,,,,,,,,
1405579062.687,,-4.500000e+001,2.979968e+002,2.979968e+002,1,0,2.236698e-001,1.494034e+000,1.494034e+000,4.418852e-001,4.369189e-001,1.491714e+000,4.395658e-001,4.345994e-001,6.511773e-005,6.511773e-005,,,,,,,,,,,,,,,,,,,,
1405579062.687,,-4.500000e+001,2.979968e+002,2.979968e+002,1,0,2.256183e+000,6.454664e-002,6.454664e-002,-9.769240e-001,-9.925681e-001,6.480619e-002,-9.766645e-001,-9.923086e-001,2.813277e-006,2.813277e-006,,,,,,,,,,,,,,,,,,,,
1405579179.437,,-4.000000e+001,2.979968e+002,2.979968e+002,1,0,3.584265e+000,1.478927e+000,1.478927e+000,4.567303e-001,4.446950e-001,1.478108e+000,4.559111e-001,4.438758e-001,6.445933e-005,6.445933e-005,,,,,,,,,,,,,,,,,,,,
1405579197.171,,-4.000000e+001,2.980050e+002,2.980050e+002,1,0,3.241036e-001,1.481369e+000,1.481368e+000,4.580139e-001,4.532731e-001,1.480192e+000,4.568372e-001,4.520963e-001,6.456574e-005,6.456574e-005,,,,,,,,,,,,,,,,,,,,
1405579214.906,,-4.000000e+001,2.979968e+002,2.979885e+002,1,0,2.079445e+000,-2.471999e-002,-2.471999e-002,-1.053452e+000,-1.053452e+000,-2.845043e-002,-1.057183e+000,-1.057183e+000,-1.077426e-006,-1.077426e-006,,,,,,,,,,,,,,,,,,,,
1405579214.906,,-4.000000e+001,2.979968e+002,2.979885e+002,1,0,3.705778e+000,1.476028e+000,1.476028e+000,4.595119e-001,4.472955e-001,1.479237e+000,4.627214e-001,4.505050e-001,6.433296e-005,6.433296e-005,,,,,,,,,,,,,,,,,,,,
1405579332.640,,-3.500000e+001,2.979968e+002,2.979968e+002,1,0,4.359419e-001,1.445662e+000,1.445662e+000,4.586681e-001,4.528126e-001,1.441601e+000,4.546070e-001,4.487514e-001,6.300949e-005,6.300949e-005,,,,,,,,,,,,,,,,,,,,
1405579350.875,,-3.500000e+001,2.979968e+002,2.980050e+002,1,0,1.899823e+000,2.792444e-002,2.792444e-002,-9.912164e-001,-9.914709e-001,2.153781e-002,-9.976031e-001,-9.978576e-001,1.217093e-006,1.217093e-006,,,,,,,,,,,,,,,,,,,,
1405579350.875,,-3.500000e+001,2.979968e+002,2.980050e+002,1,0,3.810084e+000,1.440016e+000,1.440016e+000,4.318184e-001,4.206206e-001,1.444623e+000,4.364256e-001,4.252278e-001,6.276341e-005,6.276341e-005,,,,,,,,,,,,,,,,,,,,
1405579369.109,,-3.500000e+001,2.980050e+002,2.979968e+002,1,0,5.562779e-001,1.435285e+000,1.435285e+000,4.384313e-001,4.327247e-001,1.427861e+000,4.310072e-001,4.253006e-001,6.255724e-005,6.255724e-005,,,,,,,,,,,,,,,,,,,,
1405579488.875,,-3.000000e+001,2.979968e+002,2.979968e+002,1,0,1.718950e+000,1.786859e-001,1.786859e-001,-8.162474e-001,-8.167037e-001,1.769583e-001,-8.179750e-001,-8.184313e-001,7.788067e-006,7.788067e-006,,,,,,,,,,,,,,,,,,,,
1405579488.875,,-3.000000e+001,2.979968e+002,2.979968e+002,1,0,3.893637e+000,1.383099e+000,1.383099e+000,3.979762e-001,3.877093e-001,1.388041e+000,4.029185e-001,3.926516e-001,6.028270e-005,6.028270e-005,,,,,,,,,,,,,,,,,,,,
1405579506.875,,-3.000000e+001,2.980050e+002,2.979885e+002,1,0,6.832566e-001,1.377911e+000,1.377911e+000,3.782598e-001,3.739094e-001,1.362336e+000,3.626851e-001,3.583347e-001,6.005657e-005,6.005657e-005,,,,,,,,,,,,,,,,,,,,
1405579524.859,,-3.000000e+001,2.980050e+002,2.979968e+002,1,0,1.538920e+000,4.033021e-001,4.033021e-001,-5.985015e-001,-5.990934e-001,4.064291e-001,-5.953745e-001,-5.959665e-001,1.757802e-005,1.757802e-005,,,,,,,,,,,,,,,,,,,,
1405579524.859,,-3.000000e+001,2.980050e+002,2.979968e+002,1,0,3.953566e+000,1.368450e+000,1.368450e+000,3.751307e-001,3.660544e-001,1.374253e+000,3.809341e-001,3.718579e-001,5.964422e-005,5.964422e-005,,,,,,,,,,,,,,,,,,,,
1405579643.609,,-2.500000e+001,2.979968e+002,2.979968e+002,1,0,8.158066e-001,1.233711e+000,1.233711e+000,2.786702e-001,2.737343e-001,1.214146e+000,2.591056e-001,2.541697e-001,5.377161e-005,5.377161e-005,,,,,,,,,,,,,,,,,,,,
1405579661.093,,-2.500000e+001,2.980050e+002,2.979968e+002,1,0,1.361032e+000,6.216621e-001,6.216620e-001,-3.394410e-001,-3.400846e-001,6.133105e-001,-3.477925e-001,-3.484362e-001,2.709530e-005,2.709530e-005,,,,,,,,,,,,,,,,,,,,
1405579661.093,,-2.500000e+001,2.980050e+002,2.979968e+002,1,0,3.987440e+000,1.302683e+000,1.302683e+000,3.484987e-001,3.409359e-001,1.312809e+000,3.586252e-001,3.510624e-001,5.677776e-005,5.677776e-005,,,,,,,,,,,,,,,,,,,,
1405579679.828,,-2.500000e+001,2.980050e+002,2.979968e+002,1,0,9.541395e-001,1.124454e+000,1.124454e+000,1.494929e-001,1.461223e-001,1.104551e+000,1.295897e-001,1.262192e-001,4.900964e-005,4.900964e-005,,,,,,,,,,,,,,,,,,,,
1405579798.078,,-2.000000e+001,2.980050e+002,2.979968e+002,1,0,1.186796e+000,8.243049e-001,8.243049e-001,-1.035743e-001,-1.045240e-001,8.046572e-001,-1.232220e-001,-1.241717e-001,3.592757e-005,3.592757e-005,,,,,,,,,,,,,,,,,,,,
1405579798.078,,-2.000000e+001,2.980050e+002,2.979968e+002,1,0,3.994364e+000,1.254158e+000,1.254158e+000,3.344459e-001,3.253292e-001,1.266088e+000,3.463760e-001,3.372594e-001,5.466284e-005,5.466284e-005,,,,,,,,,,,,,,,,,,,,
1405579816.812,,-2.000000e+001,2.979968e+002,2.979968e+002,1,0,1.098560e+000,9.340190e-001,9.340190e-001,-7.764830e-003,-1.104379e-002,9.188488e-001,-2.293505e-002,-2.621400e-002,4.070948e-005,4.070948e-005,,,,,,,,,,,,,,,,,,,,
1405579835.546,,-2.000000e+001,2.979968e+002,2.979968e+002,1,0,1.018226e+000,1.024506e+000,1.024506e+000,8.598654e-002,8.546472e-002,1.001969e+000,6.344931e-002,6.292748e-002,4.465340e-005,4.465340e-005,,,,,,,,,,,,,,,,,,,,
1405579835.546,,-2.000000e+001,2.979968e+002,2.979968e+002,1,0,3.974708e+000,1.274148e+000,1.274148e+000,3.393677e-001,3.351061e-001,1.288309e+000,3.535286e-001,3.492670e-001,5.553409e-005,5.553409e-005,,,,,,,,,,,,,,,,,,,,
1405579947.281,,-1.500000e+001,2.979885e+002,2.979968e+002,1,0,1.249609e+000,7.095554e-001,7.095553e-001,-1.833360e-001,-1.861546e-001,7.059530e-001,-1.869383e-001,-1.897569e-001,3.092618e-005,3.092618e-005,,,,,,,,,,,,,,,,,,,,
1405579965.265,,-1.500000e+001,2.979968e+002,2.979885e+002,1,0,8.548373e-001,1.147801e+000,1.147801e+000,2.341712e-001,2.336795e-001,1.129170e+000,2.155397e-001,2.150480e-001,5.002726e-005,5.002726e-005,,,,,,,,,,,,,,,,,,,,
1405579965.265,,-1.500000e+001,2.979968e+002,2.979885e+002,1,0,3.929925e+000,1.252174e+000,1.252174e+000,3.415651e-001,3.380529e-001,1.268565e+000,3.579554e-001,3.544432e-001,5.457640e-005,5.457640e-005,,,,,,,,,,,,,,,,,,,,
1405579982.750,,-1.500000e+001,2.979885e+002,2.979968e+002,1,0,1.407981e+000,5.261391e-001,5.261391e-001,-3.852110e-001,-3.872948e-001,5.374655e-001,-3.738845e-001,-3.759683e-001,2.293193e-005,2.293193e-005,,,,,,,,,,,,,,,,,,,,
1405580100.765,,-1.000000e+001,2.979968e+002,2.980050e+002,1,0,6.992093e-001,1.181066e+000,1.181066e+000,3.339463e-001,3.334144e-001,1.161441e+000,3.143212e-001,3.137894e-001,5.147716e-005,5.147716e-005,,,,,,,,,,,,,,,,,,,,
1405580100.765,,-1.000000e+001,2.979968e+002,2.980050e+002,1,0,3.862934e+000,1.192358e+000,1.192358e+000,3.480969e-001,3.447063e-001,1.207577e+000,3.633159e-001,3.599253e-001,5.196932e-005,5.196932e-005,,,,,,,,,,,,,,,,,,,,
1405580118.250,,-1.000000e+001,2.980050e+002,2.979885e+002,1,0,1.573238e+000,2.957244e-001,2.957244e-001,-5.696133e-001,-5.715393e-001,3.208651e-001,-5.444726e-001,-5.463985e-001,1.288924e-005,1.288924e-005,,,,,,,,,,,,,,,,,,,,
1405580136.000,,-1.000000e+001,2.980050e+002,2.979968e+002,1,0,5.523826e-001,1.254768e+000,1.254768e+000,3.861299e-001,3.859598e-001,1.241497e+000,3.728586e-001,3.726886e-001,5.468949e-005,5.468949e-005,,,,,,,,,,,,,,,,,,,,
1405580136.000,,-1.000000e+001,2.980050e+002,2.979968e+002,1,0,3.777350e+000,1.241493e+000,1.241493e+000,3.736669e-001,3.726843e-001,1.248917e+000,3.810909e-001,3.801083e-001,5.411087e-005,5.411087e-005,,,,,,,,,,,,,,,,,,,,
1405580254.750,,-5.000000e+000,2.979968e+002,2.979885e+002,1,0,1.744906e+000,1.219214e-001,1.219214e-001,-7.084647e-001,-7.085919e-001,1.466084e-001,-6.837777e-001,-6.839049e-001,5.313988e-006,5.313988e-006,,,,,,,,,,,,,,,,,,,,
1405580272.984,,-5.000000e+000,2.979885e+002,2.980050e+002,1,0,4.167984e-001,1.195105e+000,1.195105e+000,3.740994e-001,3.740748e-001,1.188903e+000,3.678975e-001,3.678730e-001,5.208906e-005,5.208906e-005,,,,,,,,,,,,,,,,,,,,
1405580272.984,,-5.000000e+000,2.979885e+002,2.980050e+002,1,0,3.676872e+000,1.188391e+000,1.188391e+000,3.674910e-001,3.673607e-001,1.188813e+000,3.679129e-001,3.677826e-001,5.179642e-005,5.179642e-005,,,,,,,,,,,,,,,,,,,,
1405580290.718,,-5.000000e+000,2.980050e+002,2.979968e+002,1,0,1.921494e+000,1.876888e-002,1.876888e-002,-8.203843e-001,-8.195638e-001,3.152293e-002,-8.076303e-001,-8.068098e-001,8.180482e-007,8.180482e-007,,,,,,,,,,,,,,,,,,,,
1405580410.468,,0.000000e+000,2.979968e+002,2.979885e+002,1,0,2.951603e-001,1.108280e+000,1.108280e+000,3.251607e-001,3.260025e-001,1.113304e+000,3.301854e-001,3.310272e-001,4.830477e-005,4.830477e-005,,,,,,,,,,,,,,,,,,,,
1405580410.468,,0.000000e+000,2.979968e+002,2.979885e+002,1,0,3.565005e+000,1.127812e+000,1.127812e+000,3.414019e-001,3.455343e-001,1.116432e+000,3.300226e-001,3.341550e-001,4.915607e-005,4.915607e-005,,,,,,,,,,,,,,,,,,,,
1405580427.703,,0.000000e+000,2.979968e+002,2.979968e+002,1,0,2.101130e+000,-1.419111e-002,-1.419111e-002,-7.888194e-001,-7.869974e-001,-1.115350e-002,-7.857819e-001,-7.839599e-001,-6.185246e-007,-6.185246e-007,,,,,,,,,,,,,,,,,,,,
1405580445.437,,0.000000e+000,2.980050e+002,2.980050e+002,1,0,1.908751e-001,1.061586e+000,1.061586e+000,2.847480e-001,2.853283e-001,1.081498e+000,3.046600e-001,3.052403e-001,4.626963e-005,4.626963e-005,,,,,,,,,,,,,,,,,,,,
1405580445.437,,0.000000e+000,2.980050e+002,2.980050e+002,1,0,3.444625e+000,1.089969e+000,1.089969e+000,3.110510e-001,3.137105e-001,1.067769e+000,2.888511e-001,2.915106e-001,4.750667e-005,4.750667e-005,,,,,,,,,,,,,,,,,,,,
1405580563.671,,5.000000e+000,2.979968e+002,2.979968e+002,1,0,2.281995e+000,5.340739e-002,5.340739e-002,-6.587441e-001,-6.572666e-001,5.132042e-002,-6.608310e-001,-6.593535e-001,2.327780e-006,2.327780e-006,,,,,,,,,,,,,,,,,,,,
1405580581.906,,5.000000e+000,2.979885e+002,2.979885e+002,1,0,1.073627e-001,9.302042e-001,9.302042e-001,2.202646e-001,2.214259e-001,9.637889e-001,2.538494e-001,2.550106e-001,4.054327e-005,4.054327e-005,,,,,,,,,,,,,,,,,,,,
1405580581.906,,5.000000e+000,2.979885e+002,2.979885e+002,1,0,3.317762e+000,9.431746e-001,9.431745e-001,2.293940e-001,2.343963e-001,9.102731e-001,1.964926e-001,2.014949e-001,4.110859e-005,4.110859e-005,,,,,,,,,,,,,,,,,,,,
1405580600.140,,5.000000e+000,2.979885e+002,2.979968e+002,1,0,2.462326e+000,1.860103e-001,1.860103e-001,-5.165720e-001,-5.136864e-001,1.757082e-001,-5.268741e-001,-5.239885e-001,8.107324e-006,8.107324e-006,,,,,,,,,,,,,,,,,,,,
1405580754.953,,1.000000e+001,2.979968e+002,2.979968e+002,1,0,4.753934e-002,8.032472e-001,8.032472e-001,1.603150e-001,1.616200e-001,8.509594e-001,2.080272e-001,2.093322e-001,3.500979e-005,3.500979e-005,,,,,,,,,,,,,,,,,,,,
1405580754.953,,1.000000e+001,2.979968e+002,2.979968e+002,1,0,3.185128e+000,7.744071e-001,7.744071e-001,1.274668e-001,1.327800e-001,7.358012e-001,8.886082e-002,9.417397e-002,3.375279e-005,3.375279e-005,,,,,,,,,,,,,,,,,,,,
1405580772.687,,1.000000e+001,2.980050e+002,2.979968e+002,1,0,2.640104e+000,3.091525e-001,3.091525e-001,-3.178689e-001,-3.135401e-001,2.895551e-001,-3.374664e-001,-3.331375e-001,1.347451e-005,1.347451e-005,,,,,,,,,,,,,,,,,,,,
1405580790.421,,1.000000e+001,2.979968e+002,2.979968e+002,1,0,1.357810e-002,7.931761e-001,7.931761e-001,1.432862e-001,1.455765e-001,8.483253e-001,1.984355e-001,2.007257e-001,3.457084e-005,3.457084e-005,,,,,,,,,,,,,,,,,,,,
1405580790.421,,1.000000e+001,2.979968e+002,2.979968e+002,1,0,3.046879e+000,6.836146e-001,6.836146e-001,2.715941e-002,3.601503e-002,6.481369e-001,-8.318344e-003,5.372763e-004,2.979556e-005,2.979556e-005,,,,,,,,,,,,,,,,,,,,
1405580908.406,,1.500000e+001,2.979968e+002,2.979968e+002,1,0,2.813856e+000,4.045229e-001,4.045228e-001,-1.417751e-001,-1.369364e-001,3.684794e-001,-1.778185e-001,-1.729798e-001,1.763125e-005,1.763125e-005,,,,,,,,,,,,,,,,,,,,
1405580926.640,,1.500000e+001,2.980050e+002,2.980050e+002,1,0,6.561244e-003,6.549272e-001,6.549272e-001,1.019222e-001,1.056331e-001,7.183159e-001,1.653109e-001,1.690218e-001,2.854520e-005,2.854520e-005,,,,,,,,,,,,,,,,,,,,
1405580926.640,,1.500000e+001,2.980050e+002,2.980050e+002,1,0,2.902428e+000,4.725791e-001,4.725791e-001,-9.039916e-002,-7.671493e-002,4.476382e-001,-1.153401e-001,-1.016559e-001,2.059750e-005,2.059750e-005,,,,,,,,,,,,,,,,,,,,
1405580944.640,,1.500000e+001,2.980050e+002,2.979968e+002,1,0,2.982844e+000,5.429243e-001,5.429243e-001,-1.394215e-002,-5.181730e-003,4.958673e-001,-6.099918e-002,-5.223876e-002,2.366352e-005,2.366352e-005,,,,,,,,,,,,,,,,,,,,
1405581064.406,,2.000000e+001,2.979968e+002,2.980050e+002,1,0,2.632652e-002,4.904324e-001,4.904324e-001,6.064976e-002,6.513298e-002,5.590392e-001,1.292565e-001,1.337398e-001,2.137564e-005,2.137564e-005,,,,,,,,,,,,,,,,,,,,
1405581064.406,,2.000000e+001,2.979968e+002,2.980050e+002,1,0,2.751338e+000,2.592547e-001,2.592547e-001,-1.818679e-001,-1.660447e-001,2.460060e-001,-1.951166e-001,-1.792935e-001,1.129969e-005,1.129969e-005,,,,,,,,,,,,,,,,,,,,
1405581082.390,,2.000000e+001,2.979968e+002,2.979968e+002,1,0,3.146065e+000,5.151525e-001,5.151525e-001,7.074896e-002,8.127484e-002,4.628245e-001,1.842099e-002,2.894688e-002,2.245306e-005,2.245306e-005,,,,,,,,,,,,,,,,,,,,
1405581099.890,,2.000000e+001,2.979968e+002,2.979968e+002,1,0,7.107223e-002,5.159154e-001,5.159154e-001,7.473053e-002,7.977009e-002,5.768234e-001,1.356385e-001,1.406780e-001,2.248632e-005,2.248632e-005,,,,,,,,,,,,,,,,,,,,
1405581099.890,,2.000000e+001,2.979968e+002,2.979968e+002,1,0,2.593059e+000,1.640370e-001,1.640370e-001,-2.891868e-001,-2.721083e-001,1.698274e-001,-2.833964e-001,-2.663179e-001,7.149599e-006,7.149599e-006,,,,,,,,,,,,,,,,,,,,
1405581235.656,,2.500000e+001,2.980050e+002,2.979968e+002,1,0,3.301807e+000,6.073183e-001,6.073183e-001,1.317219e-001,1.564703e-001,5.072379e-001,3.164145e-002,5.638984e-002,1.323506e-005,1.323506e-005,,,,,,,,,,,,,,,,,,,,
1405581253.437,,2.500000e+001,2.980050e+002,2.979968e+002,1,0,1.380807e-001,4.457228e-001,4.457228e-001,1.209816e-002,2.525070e-002,5.593863e-001,1.257617e-001,1.389142e-001,9.713473e-006,9.713473e-006,,,,,,,,,,,,,,,,,,,,
1405581253.437,,2.500000e+001,2.980050e+002,2.979968e+002,1,0,2.427773e+000,-1.022370e-002,-1.022370e-002,-4.736146e-001,-4.306958e-001,3.560078e-002,-4.277902e-001,-3.848713e-001,-2.228013e-007,-2.228013e-007,,,,,,,,,,,,,,,,,,,,
1405581271.171,,2.500000e+001,2.980050e+002,2.979968e+002,1,0,3.448680e+000,6.265450e-001,6.265450e-001,1.634034e-001,1.909488e-001,5.517967e-001,8.865507e-002,1.162005e-001,1.365406e-005,1.365406e-005,,,,,,,,,,,,,,,,,,,,
1405581389.906,,3.000000e+001,2.979968e+002,2.979968e+002,1,0,2.236762e-001,-5.589465e-001,-5.589465e-001,-2.139338e-001,-1.723001e-001,-5.141943e-001,-1.691817e-001,-1.275479e-001,-1.218091e-005,-1.218091e-005,,,,,,,,,,,,,,,,,,,,
1405581389.906,,3.000000e+001,2.979968e+002,2.979968e+002,1,0,2.256143e+000,-1.408429e-001,-1.408429e-001,1.146571e-001,2.458035e-001,-7.670544e-002,1.787946e-001,3.099410e-001,-3.069336e-006,-3.069336e-006,,,,,,,,,,,,,,,,,,,,
1405581407.203,,3.000000e+001,2.980050e+002,2.979968e+002,1,0,3.584296e+000,-4.687643e-001,-4.687643e-001,-1.506762e-001,-6.218857e-002,-4.881362e-001,-1.700481e-001,-8.156046e-002,-1.021560e-005,-1.021560e-005,,,,,,,,,,,,,,,,,,,,
1405581425.437,,3.000000e+001,2.979968e+002,2.979968e+002,1,0,3.242198e-001,-5.587939e-001,-5.587939e-001,-1.871691e-001,-1.464703e-001,-5.336798e-001,-1.620550e-001,-1.213562e-001,-1.217758e-005,-1.217758e-005,,,,,,,,,,,,,,,,,,,,
1405581544.687,,3.500000e+001,2.980050e+002,2.979968e+002,1,0,2.079381e+000,-5.722221e-002,-5.722221e-002,1.087101e+000,1.087101e+000,-3.482328e-002,1.109500e+000,1.109500e+000,-1.247021e-006,-1.247021e-006,,,,,,,,,,,,,,,,,,,,
1405581544.687,,3.500000e+001,2.980050e+002,2.979968e+002,1,0,3.705848e+000,-1.572771e+000,-1.572771e+000,-5.088992e-001,-4.284477e-001,-1.550424e+000,-4.865520e-001,-4.061005e-001,-3.427480e-005,-3.427480e-005,,,,,,,,,,,,,,,,,,,,
1405581562.921,,3.500000e+001,2.979968e+002,2.979968e+002,1,0,4.360738e-001,-1.641438e+000,-1.641438e+000,-4.749791e-001,-4.350588e-001,-1.664076e+000,-4.976173e-001,-4.576970e-001,-3.577122e-005,-3.577122e-005,,,,,,,,,,,,,,,,,,,,
1405581581.656,,3.500000e+001,2.980050e+002,2.979968e+002,1,0,1.899823e+000,-2.319407e-002,-2.319407e-002,1.179951e+000,1.181818e+000,4.203691e-002,1.245182e+000,1.247049e+000,-5.054593e-007,-5.054593e-007,,,,,,,,,,,,,,,,,,,,
1405581581.656,,3.500000e+001,2.980050e+002,2.979968e+002,1,0,3.810120e+000,-1.658223e+000,-1.658223e+000,-5.353370e-001,-4.532113e-001,-1.591504e+000,-4.686181e-001,-3.864924e-001,-3.613701e-005,-3.613701e-005,,,,,,,,,,,,,,,,,,,,
1405581699.921,,4.000000e+001,2.980050e+002,2.979968e+002,1,0,5.563110e-001,-2.205115e+000,-2.205115e+000,-5.718953e-001,-5.264328e-001,-2.265050e+000,-6.318302e-001,-5.863676e-001,-4.805519e-005,-4.805519e-005,,,,,,,,,,,,,,,,,,,,
1405581718.156,,4.000000e+001,2.979968e+002,2.979968e+002,1,0,1.718702e+000,-2.233955e-001,-2.233955e-001,1.454313e+000,1.458695e+000,-1.653600e-001,1.512349e+000,1.516730e+000,-4.868369e-006,-4.868369e-006,,,,,,,,,,,,,,,,,,,,
1405581718.156,,4.000000e+001,2.979968e+002,2.979968e+002,1,0,3.893610e+000,-2.309183e+000,-2.309183e+000,-7.256783e-001,-6.270928e-001,-2.196936e+000,-6.134313e-001,-5.148458e-001,-5.032310e-005,-5.032310e-005,,,,,,,,,,,,,,,,,,,,
1405581736.406,,4.000000e+001,2.980050e+002,2.979968e+002,1,0,6.832446e-001,-2.009339e+000,-2.009339e+000,-4.140504e-001,-3.605150e-001,-2.095815e+000,-5.005265e-001,-4.469911e-001,-4.378871e-005,-4.378871e-005,,,,,,,,,,,,,,,,,,,,
1405581853.687,,4.500000e+001,2.980050e+002,2.979968e+002,1,0,1.538595e+000,-5.801569e-001,-5.801569e-001,1.328479e+000,1.335146e+000,-5.987325e-001,1.309904e+000,1.316570e+000,-1.264312e-005,-1.264312e-005,,,,,,,,,,,,,,,,,,,,
1405581853.687,,4.500000e+001,2.980050e+002,2.979968e+002,1,0,3.953477e+000,-2.638783e+000,-2.638783e+000,-8.257038e-001,-7.234801e-001,-2.483251e+000,-6.701719e-001,-5.679482e-001,-5.750592e-005,-5.750592e-005,,,,,,,,,,,,,,,,,,,,
1405581871.437,,4.500000e+001,2.979968e+002,2.979968e+002,1,0,8.158905e-001,-2.108066e+000,-2.108066e+000,-2.749551e-001,-2.157925e-001,-2.213302e+000,-3.801907e-001,-3.210281e-001,-4.594022e-005,-4.594022e-005,,,,,,,,,,,,,,,,,,,,
1405581889.703,,4.500000e+001,2.979968e+002,2.980132e+002,1,0,1.360807e+000,-9.320353e-001,-9.320353e-001,9.621449e-001,9.716484e-001,-1.023929e+000,8.702515e-001,8.797550e-001,-2.031146e-005,-2.031146e-005,,,,,,,,,,,,,,,,,,,,
1405581889.703,,4.500000e+001,2.979968e+002,2.980132e+002,1,0,3.987422e+000,-2.620777e+000,-2.620777e+000,-8.287590e-001,-7.170932e-001,-2.442645e+000,-6.506267e-001,-5.389609e-001,-5.711352e-005,-5.711352e-005,,,,,,,,,,,,,,,,,,,,
1405582008.937,,5.000000e+001,2.980050e+002,2.980050e+002,1,0,9.541279e-001,-2.126225e+000,-2.126225e+000,-3.222373e-002,3.232217e-002,-2.252704e+000,-1.587036e-001,-9.415770e-002,-4.633592e-005,-4.633592e-005,,,,,,,,,,,,,,,,,,,,
1405582026.171,,5.000000e+001,2.979968e+002,2.980050e+002,1,0,1.186969e+000,-1.545763e+000,-1.545763e+000,5.797834e-001,5.926731e-001,-1.689832e+000,4.357139e-001,4.486035e-001,-3.368615e-005,-3.368615e-005,,,,,,,,,,,,,,,,,,,,
1405582026.171,,5.000000e+001,2.979968e+002,2.980050e+002,1,0,3.994415e+000,-2.951903e+000,-2.951903e+000,-9.372076e-001,-8.134673e-001,-2.755783e+000,-7.410874e-001,-6.173470e-001,-6.432958e-005,-6.432958e-005,,,,,,,,,,,,,,,,,,,,
1405582044.406,,5.000000e+001,2.980050e+002,2.979968e+002,1,0,1.098584e+000,-1.752831e+000,-1.752831e+000,3.389152e-001,4.090458e-001,-1.894524e+000,1.972222e-001,2.673528e-001,-3.819870e-005,-3.819870e-005,,,,,,,,,,,,,,,,,,,,
1405582163.203,,7.500000e+001,2.980050e+002,2.979968e+002,1,0,1.017981e+000,-2.359996e+000,-2.359996e+000,1.485064e-001,1.674025e-001,-2.565221e+000,-5.671815e-002,-3.782201e-002,-5.143029e-005,-5.143029e-005,,,,,,,,,,,,,,,,,,,,
1405582163.203,,7.500000e+001,2.980050e+002,2.979968e+002,1,0,3.974659e+000,-3.511155e+000,-3.511154e+000,-1.138074e+000,-9.837556e-001,-3.282430e+000,-9.093501e-001,-7.550316e-001,-7.651695e-005,-7.651695e-005,,,,,,,,,,,,,,,,,,,,
1405582180.453,,7.500000e+001,2.979968e+002,2.980050e+002,1,0,1.249672e+000,-1.632588e+000,-1.632588e+000,8.132102e-001,9.030957e-001,-1.785419e+000,6.603791e-001,7.502646e-001,-3.557822e-005,-3.557822e-005,,,,,,,,,,,,,,,,,,,,
1405582198.187,,7.500000e+001,2.979968e+002,2.979968e+002,1,0,8.549802e-001,-2.761925e+000,-2.761925e+000,-2.829441e-001,-2.604170e-001,-2.975694e+000,-4.967126e-001,-4.741855e-001,-6.018934e-005,-6.018934e-005,,,,,,,,,,,,,,,,,,,,
1405582198.187,,7.500000e+001,2.979968e+002,2.979968e+002,1,0,3.929944e+000,-3.500015e+000,-3.500015e+000,-1.159415e+000,-9.985070e-001,-3.296326e+000,-9.557260e-001,-7.948182e-001,-7.627419e-005,-7.627419e-005,,,,,,,,,,,,,,,,,,,,
1405582330.171,,1.000000e+002,2.980050e+002,2.979968e+002,1,0,1.407903e+000,-1.177404e+000,-1.177404e+000,1.365706e+000,1.473121e+000,-1.291150e+000,1.251959e+000,1.359375e+000,-2.565856e-005,-2.565856e-005,,,,,,,,,,,,,,,,,,,,
1405582347.906,,1.000000e+002,2.979968e+002,2.980050e+002,1,0,6.990708e-001,-3.308207e+000,-3.308206e+000,-6.823858e-001,-6.533291e-001,-3.516562e+000,-8.907415e-001,-8.616848e-001,-7.209403e-005,-7.209403e-005,,,,,,,,,,,,,,,,,,,,
1405582347.906,,1.000000e+002,2.979968e+002,2.980050e+002,1,0,3.862892e+000,-3.738365e+000,-3.738365e+000,-1.268724e+000,-1.083488e+000,-3.553452e+000,-1.083812e+000,-8.985751e-001,-8.146824e-005,-8.146824e-005,,,,,,,,,,,,,,,,,,,,
1405582366.140,,1.000000e+002,2.980050e+002,2.980050e+002,1,0,1.573279e+000,-6.736961e-001,-6.736961e-001,1.854085e+000,1.967051e+000,-6.891212e-001,1.838660e+000,1.951625e+000,-1.468151e-005,-1.468151e-005,,,,,,,,,,,,,,,,,,,,
1405582366.140,,1.000000e+002,2.980050e+002,2.980050e+002,1,0,2.256131e+000,-2.046266e-001,-2.046266e-001,2.198892e+000,2.436120e+000,1.165064e-002,2.415169e+000,2.652397e+000,-4.459322e-006,-4.459322e-006,,,,,,,,,,,,,,,,,,,,