File: Sample Data Files/2014-07-16 EB on isolated PMN-PT no Ti spontaneous in situ/Ni-NiO_298K_SiO2_PMN-PT_5.0Tprebias_085V_Au_back.rso.raw
[Header]
TITLE,MPMS RSO Measurement
BYAPP,MPMS Measurement,2.1,Raw with ABS
FILEOPENTIME, 1405612735.437000 7/17/2014, 8:58:55 AM

INFO, APPNAME, MPMS MultiVu Application, Revision 1.58,  Build 076

INFO, NAME, EB in situ
INFO, WEIGHT, 0.000
INFO, AREA, 0.000
INFO, LENGTH, 0.000
INFO, SHAPE, 0
INFO, COMMENT,
INFO, SEQUENCE FILE: MHcurveUpTo100.seq


INFO, BACKGROUND DATA FILE:, None


STARTUPAXIS,X,8,LINEAR,AUTO,0.000000,0.000000
STARTUPAXIS,Y1,9,LINEAR,AUTO,0.000000,0.000000


STARTUPGROUP,Longitudinal
FIELDGROUP,Longitudinal,1,2,3,4,5,6,7,8,9,10,11,12,13,14,15,16,17,18,19,20,21,22
FIELDGROUP,Transverse,1,2,3,4,5,6,7,8,23,24,25,26,27,28,29,30,31,32,33,34,35,36

PLOT_APPEARANCE,ALL,HORZ_GRID_ON,VERT_GRID_ON,MARKERS_ONLY

[Data]
Time,Comment,Field (Oe),Start Temperature (K),End Temperature (K),Scan,Rejected,Position (cm),Long Voltage,Long Average Voltage,Long Detrended Voltage,Long Demeaned Voltage,Long Reg Fit,Long Detrended Fit,Long Demeaned Fit,Long Scaled Response,Long Avg. Scaled Response,Long Background Response,Long Response [w/ABS],Long Detrended Resp. [w/ABS],Long Fit [w/ABS],Long Detrended Fit [w/ABS],Trans Voltage,Trans Average Voltage,Trans Detrended Voltage,Trans Demeaned Voltage,Trans Reg Fit,Trans Detrended Fit,Trans Demeaned Fit,Trans Scaled Response,Trans Avg. Scaled Response,Trans Background Response,Trans Response [w/ABS],Trans Detrended Resp. [w/ABS],Trans Adjusted Fit,Trans Detrended Fit [w/ABS],
1405612735.437,,1.000000e+002,2.980050e+002,2.979968e+002,1,0,2.079487e+000,-3.921628e-002,-3.921628e-002,2.650708e+000,2.650708e+000,6.891779e-002,2.758842e+000,2.758842e+000,-8.546202e-007,-8.546202e-007,,,,,,,,,,,,,,,,,,,,
1405612735.437,,1.000000e+002,2.980050e+002,2.979968e+002,1,0,3.705962e+000,-3.766900e+000,-3.766900e+000,-1.231827e+000,-1.076976e+000,-3.742561e+000,-1.207489e+000,-1.052637e+000,-8.209009e-005,-8.209009e-005,,,,,,,,,,,,,,,,,,,,
1405612753.671,,1.000000e+002,2.979968e+002,2.979968e+002,1,0,4.361428e-001,-3.808405e+000,-3.808405e+000,-1.179978e+000,-1.099338e+000,-3.838962e+000,-1.210535e+000,-1.129895e+000,-8.299459e-005,-8.299459e-005,,,,,,,,,,,,,,,,,,,,
1405612771.468,,1.000000e+002,2.980050e+002,2.979968e+002,1,0,1.899604e+000,-9.338664e-002,-9.338664e-002,2.590520e+000,2.594168e+000,4.780080e-002,2.731707e+000,2.735356e+000,-2.035126e-006,-2.035126e-006,,,,,,,,,,,,,,,,,,,,
1405612771.468,,1.000000e+002,2.980050e+002,2.979968e+002,1,0,3.810156e+000,-3.779870e+000,-3.779870e+000,-1.252854e+000,-1.092315e+000,-3.670817e+000,-1.143801e+000,-9.832621e-001,-8.237275e-005,-8.237275e-005,,,,,,,,,,,,,,,,,,,,
1405612897.218,,7.500000e+001,2.980050e+002,2.979968e+002,1,0,5.564555e-001,-3.544115e+000,-3.544115e+000,-9.952855e-001,-9.203894e-001,-3.635468e+000,-1.086639e+000,-1.011743e+000,-7.723522e-005,-7.723522e-005,,,,,,,,,,,,,,,,,,,,
1405612915.703,,7.500000e+001,2.979968e+002,2.979968e+002,1,0,1.718936e+000,-3.720206e-001,-3.720206e-001,2.222737e+000,2.229378e+000,-3.102826e-001,2.284475e+000,2.291117e+000,-8.107271e-006,-8.107271e-006,,,,,,,,,,,,,,,,,,,,
1405612915.703,,7.500000e+001,2.979968e+002,2.979968e+002,1,0,3.893738e+000,-3.656423e+000,-3.656423e+000,-1.204450e+000,-1.055023e+000,-3.487530e+000,-1.035558e+000,-8.861310e-001,-7.968270e-005,-7.968270e-005,,,,,,,,,,,,,,,,,,,,
1405612933.937,,7.500000e+001,2.979968e+002,2.979968e+002,1,0,6.833198e-001,-3.292489e+000,-3.292489e+000,-7.667891e-001,-6.864309e-001,-3.423645e+000,-8.979453e-001,-8.175871e-001,-7.175167e-005,-7.175167e-005,,,,,,,,,,,,,,,,,,,,
1405613065.265,,5.000000e+001,2.980050e+002,2.980050e+002,1,0,1.538710e+000,-8.107242e-001,-8.107242e-001,1.647251e+000,1.656150e+000,-8.532736e-001,1.604702e+000,1.613601e+000,-1.766777e-005,-1.766777e-005,,,,,,,,,,,,,,,,,,,,
1405613065.265,,5.000000e+001,2.980050e+002,2.980050e+002,1,0,3.953554e+000,-3.447523e+000,-3.447523e+000,-1.117100e+000,-9.806490e-001,-3.249617e+000,-9.191935e-001,-7.827425e-001,-7.513043e-005,-7.513043e-005,,,,,,,,,,,,,,,,,,,,
1405613083.500,,5.000000e+001,2.980050e+002,2.979968e+002,1,0,8.159040e-001,-2.843257e+000,-2.843257e+000,-4.424143e-001,-3.665805e-001,-2.983004e+000,-5.821614e-001,-5.063276e-001,-6.196190e-005,-6.196190e-005,,,,,,,,,,,,,,,,,,,,
1405613101.281,,5.000000e+001,2.979968e+002,2.979968e+002,1,0,1.361086e+000,-1.332743e+000,-1.332743e+000,1.138833e+000,1.151289e+000,-1.455784e+000,1.015792e+000,1.028248e+000,-2.904392e-005,-2.904392e-005,,,,,,,,,,,,,,,,,,,,
1405613101.281,,5.000000e+001,2.979968e+002,2.979968e+002,1,0,3.987481e+000,-3.442946e+000,-3.442946e+000,-1.105266e+000,-9.589136e-001,-3.221564e+000,-8.838843e-001,-7.375317e-001,-7.503067e-005,-7.503067e-005,,,,,,,,,,,,,,,,,,,,
1405613213.515,,4.500000e+001,2.980050e+002,2.979968e+002,1,0,9.541574e-001,-2.474441e+000,-2.474441e+000,-8.696683e-002,-1.214123e-002,-2.620345e+000,-2.328714e-001,-1.580458e-001,-5.392448e-005,-5.392448e-005,,,,,,,,,,,,,,,,,,,,
1405613232.250,,4.500000e+001,2.980050e+002,2.979885e+002,1,0,1.186858e+000,-1.797693e+000,-1.797693e+000,6.060305e-001,6.208384e-001,-1.964968e+000,4.387557e-001,4.535636e-001,-3.917638e-005,-3.917638e-005,,,,,,,,,,,,,,,,,,,,
1405613232.250,,4.500000e+001,2.980050e+002,2.979885e+002,1,0,3.994340e+000,-3.360698e+000,-3.360698e+000,-1.084323e+000,-9.421670e-001,-3.138177e+000,-8.618023e-001,-7.196462e-001,-7.323832e-005,-7.323832e-005,,,,,,,,,,,,,,,,,,,,
1405613249.984,,4.500000e+001,2.979885e+002,2.979968e+002,1,0,1.098544e+000,-2.012543e+000,-2.012543e+000,3.319142e-001,4.125984e-001,-2.171560e+000,1.728978e-001,2.535820e-001,-4.385853e-005,-4.385853e-005,,,,,,,,,,,,,,,,,,,,
1405613368.734,,4.000000e+001,2.979968e+002,2.979968e+002,1,0,1.018156e+000,-2.245399e+000,-2.245399e+000,1.178269e-001,1.349247e-001,-2.423807e+000,-6.058056e-002,-4.348278e-002,-4.893309e-005,-4.893309e-005,,,,,,,,,,,,,,,,,,,,
1405613368.734,,4.000000e+001,2.979968e+002,2.979968e+002,1,0,3.974669e+000,-3.310801e+000,-3.310801e+000,-1.070109e+000,-9.304767e-001,-3.103834e+000,-8.631421e-001,-7.235103e-001,-7.215096e-005,-7.215096e-005,,,,,,,,,,,,,,,,,,,,
1405613386.968,,4.000000e+001,2.980050e+002,2.979968e+002,1,0,1.249752e+000,-1.509293e+000,-1.509293e+000,7.558894e-001,8.384624e-001,-1.648944e+000,6.162378e-001,6.988108e-001,-3.289142e-005,-3.289142e-005,,,,,,,,,,,,,,,,,,,,
1405613405.203,,4.000000e+001,2.979968e+002,2.979968e+002,1,0,8.550766e-001,-2.636952e+000,-2.636952e+000,-2.823467e-001,-2.617059e-001,-2.830261e+000,-4.756553e-001,-4.550145e-001,-5.746604e-005,-5.746604e-005,,,,,,,,,,,,,,,,,,,,
1405613405.203,,4.000000e+001,2.979968e+002,2.979968e+002,1,0,3.929899e+000,-3.317362e+000,-3.317362e+000,-1.089551e+000,-9.421160e-001,-3.133923e+000,-9.061112e-001,-7.586765e-001,-7.229394e-005,-7.229394e-005,,,,,,,,,,,,,,,,,,,,
1405613524.187,,3.500000e+001,2.979968e+002,2.979968e+002,1,0,1.407974e+000,-1.060976e+000,-1.060976e+000,1.174334e+000,1.255088e+000,-1.155330e+000,1.079980e+000,1.160734e+000,-2.312144e-005,-2.312144e-005,,,,,,,,,,,,,,,,,,,,
1405613541.921,,3.500000e+001,2.979968e+002,2.979968e+002,1,0,6.990041e-001,-2.912229e+000,-2.912229e+000,-6.219859e-001,-5.995481e-001,-3.065198e+000,-7.749547e-001,-7.525170e-001,-6.346507e-005,-6.346507e-005,,,,,,,,,,,,,,,,,,,,
1405613541.921,,3.500000e+001,2.979968e+002,2.979968e+002,1,0,3.862853e+000,-3.250832e+000,-3.250832e+000,-1.081192e+000,-9.381509e-001,-3.110117e+000,-9.404776e-001,-7.974367e-001,-7.084411e-005,-7.084411e-005,,,,,,,,,,,,,,,,,,,,
1405613559.906,,3.500000e+001,2.979968e+002,2.980050e+002,1,0,1.573325e+000,-5.848872e-001,-5.848872e-001,1.605927e+000,1.691430e+000,-6.056437e-001,1.585170e+000,1.670673e+000,-1.274622e-005,-1.274622e-005,,,,,,,,,,,,,,,,,,,,
1405613678.937,,3.000000e+001,2.979968e+002,2.979968e+002,1,0,5.524307e-001,-3.030640e+000,-3.030641e+000,-8.224960e-001,-7.985640e-001,-3.143769e+000,-9.356239e-001,-9.116919e-001,-6.604560e-005,-6.604560e-005,,,,,,,,,,,,,,,,,,,,
1405613678.937,,3.000000e+001,2.979968e+002,2.979968e+002,1,0,3.777292e+000,-3.149663e+000,-3.149663e+000,-1.055860e+000,-9.175861e-001,-3.062560e+000,-9.687573e-001,-8.304834e-001,-6.863941e-005,-6.863941e-005,,,,,,,,,,,,,,,,,,,,
1405613697.437,,3.000000e+001,2.979968e+002,2.980050e+002,1,0,1.744920e+000,-2.598651e-001,-2.598651e-001,1.888867e+000,1.974463e+000,-1.742650e-001,1.974467e+000,2.060064e+000,-5.663142e-006,-5.663142e-006,,,,,,,,,,,,,,,,,,,,
1405613715.687,,3.000000e+001,2.980050e+002,2.980050e+002,1,0,4.167567e-001,-3.147985e+000,-3.147984e+000,-9.431859e-001,-9.155746e-001,-3.208177e+000,-1.003379e+000,-9.757676e-001,-6.860283e-005,-6.860283e-005,,,,,,,,,,,,,,,,,,,,
1405613715.687,,3.000000e+001,2.980050e+002,2.980050e+002,1,0,3.676828e+000,-3.116550e+000,-3.116550e+000,-1.030481e+000,-8.841405e-001,-3.089423e+000,-1.003354e+000,-8.570135e-001,-6.791780e-005,-6.791780e-005,,,,,,,,,,,,,,,,,,,,
1405613835.171,,2.500000e+001,2.979968e+002,2.979968e+002,1,0,1.921503e+000,-7.843257e-002,-7.843257e-002,2.007106e+000,2.089150e+000,7.778455e-002,2.163323e+000,2.245368e+000,-1.709252e-006,-1.709252e-006,,,,,,,,,,,,,,,,,,,,
1405613852.656,,2.500000e+001,2.980050e+002,2.979968e+002,1,0,2.951415e-001,-3.047884e+000,-3.047884e+000,-9.526669e-001,-9.233012e-001,-3.041605e+000,-9.463879e-001,-9.170222e-001,-6.642140e-005,-6.642140e-005,,,,,,,,,,,,,,,,,,,,
1405613852.656,,2.500000e+001,2.980050e+002,2.979968e+002,1,0,3.564997e+000,-2.909024e+000,-2.909024e+000,-9.286010e-001,-7.844419e-001,-2.929106e+000,-9.486825e-001,-8.045235e-001,-6.339530e-005,-6.339530e-005,,,,,,,,,,,,,,,,,,,,
1405613870.656,,2.500000e+001,2.979968e+002,2.979968e+002,1,0,2.101199e+000,-2.670369e-002,-2.670370e-002,2.007085e+000,2.095005e+000,1.376784e-001,2.171467e+000,2.259387e+000,-5.819438e-007,-5.819438e-007,,,,,,,,,,,,,,,,,,,,
1405613989.203,,2.000000e+001,2.980132e+002,2.979968e+002,1,0,1.909003e-001,-2.969298e+000,-2.969298e+000,-9.108939e-001,-8.814366e-001,-2.900108e+000,-8.417032e-001,-8.122458e-001,-6.470885e-005,-6.470885e-005,,,,,,,,,,,,,,,,,,,,
1405613989.203,,2.000000e+001,2.980132e+002,2.979968e+002,1,0,3.444651e+000,-2.705313e+000,-2.705313e+000,-7.524643e-001,-6.174514e-001,-2.769297e+000,-8.164480e-001,-6.814351e-001,-5.895592e-005,-5.895592e-005,,,,,,,,,,,,,,,,,,,,
1405614007.468,,2.000000e+001,2.979968e+002,2.979968e+002,1,0,2.282067e+000,-2.136296e-001,-2.136296e-001,1.728189e+000,1.814171e+000,-1.277228e-001,1.814095e+000,1.900078e+000,-4.655552e-006,-4.655552e-006,,,,,,,,,,,,,,,,,,,,
1405614025.718,,2.000000e+001,2.979968e+002,2.979885e+002,1,0,1.072912e-001,-2.859584e+000,-2.859584e+000,-8.953069e-001,-8.621647e-001,-2.743135e+000,-7.788578e-001,-7.457156e-001,-6.231789e-005,-6.231789e-005,,,,,,,,,,,,,,,,,,,,
1405614025.718,,2.000000e+001,2.979968e+002,2.979885e+002,1,0,3.317684e+000,-2.419050e+000,-2.419050e+000,-5.643966e-001,-4.216301e-001,-2.510095e+000,-6.554422e-001,-5.126758e-001,-5.271748e-005,-5.271748e-005,,,,,,,,,,,,,,,,,,,,
1405614138.968,,1.500000e+001,2.979968e+002,2.980050e+002,1,0,2.462323e+000,-5.186620e-001,-5.186621e-001,1.334757e+000,1.417796e+000,-5.391116e-001,1.314308e+000,1.397347e+000,-1.130302e-005,-1.130302e-005,,,,,,,,,,,,,,,,,,,,
1405614157.234,,1.500000e+001,2.979968e+002,2.980050e+002,1,0,4.745831e-002,-2.683187e+000,-2.683187e+000,-8.213372e-001,-7.876189e-001,-2.539122e+000,-6.772721e-001,-6.435537e-001,-5.847377e-005,-5.847377e-005,,,,,,,,,,,,,,,,,,,,
1405614157.234,,1.500000e+001,2.979968e+002,2.980050e+002,1,0,3.185071e+000,-2.028565e+000,-2.028565e+000,-2.702788e-001,-1.329970e-001,-2.142891e+000,-3.846044e-001,-2.473226e-001,-4.420782e-005,-4.420782e-005,,,,,,,,,,,,,,,,,,,,
1405614174.968,,1.500000e+001,2.980050e+002,2.979968e+002,1,0,2.640087e+000,-8.357493e-001,-8.357494e-001,9.702627e-001,1.056687e+000,-9.417524e-001,8.642597e-001,9.506839e-001,-1.821320e-005,-1.821320e-005,,,,,,,,,,,,,,,,,,,,
1405614293.234,,1.000000e+001,2.979968e+002,2.979968e+002,1,0,1.355298e-002,-2.428968e+000,-2.428968e+000,-7.376229e-001,-7.046404e-001,-2.273949e+000,-5.826036e-001,-5.496211e-001,-5.293368e-005,-5.293368e-005,,,,,,,,,,,,,,,,,,,,
1405614293.234,,1.000000e+001,2.979968e+002,2.979968e+002,1,0,3.046842e+000,-1.553392e+000,-1.553392e+000,4.340337e-002,1.709356e-001,-1.676137e+000,-7.934131e-002,4.819095e-002,-3.385255e-005,-3.385255e-005,,,,,,,,,,,,,,,,,,,,
1405614310.968,,1.000000e+001,2.979968e+002,2.979968e+002,1,0,2.813871e+000,-1.047243e+000,-1.047243e+000,5.576975e-001,6.405910e-001,-1.196379e+000,4.085607e-001,4.914542e-001,-2.282221e-005,-2.282221e-005,,,,,,,,,,,,,,,,,,,,
1405614328.718,,1.000000e+001,2.979968e+002,2.979968e+002,1,0,6.660818e-003,-2.388684e+000,-2.388684e+000,-7.401974e-001,-7.030292e-001,-2.223345e+000,-5.748584e-001,-5.376902e-001,-5.205578e-005,-5.205578e-005,,,,,,,,,,,,,,,,,,,,
1405614328.718,,1.000000e+001,2.979968e+002,2.979968e+002,1,0,2.902488e+000,-1.199072e+000,-1.199072e+000,3.495245e-001,4.865824e-001,-1.332605e+000,2.159921e-001,3.530500e-001,-2.613098e-005,-2.613098e-005,,,,,,,,,,,,,,,,,,,,
1405614448.000,,5.000000e+000,2.979968e+002,2.979968e+002,1,0,2.983019e+000,-1.188086e+000,-1.188086e+000,2.202114e-001,2.962757e-001,-1.337418e+000,7.087933e-002,1.469437e-001,-2.589156e-005,-2.589156e-005,,,,,,,,,,,,,,,,,,,,
1405614465.250,,5.000000e+000,2.979968e+002,2.979968e+002,1,0,2.637956e-002,-2.019715e+000,-2.019715e+000,-6.373479e-001,-6.019664e-001,-1.867730e+000,-4.853633e-001,-4.499818e-001,-4.401499e-005,-4.401499e-005,,,,,,,,,,,,,,,,,,,,
1405614465.250,,5.000000e+000,2.979968e+002,2.979968e+002,1,0,2.751377e+000,-6.936857e-001,-6.936857e-001,5.991871e-001,7.240630e-001,-7.971436e-001,4.957292e-001,6.206051e-001,-1.511727e-005,-1.511727e-005,,,,,,,,,,,,,,,,,,,,
1405614482.984,,5.000000e+000,2.979968e+002,2.979968e+002,1,0,3.146087e+000,-1.420026e+000,-1.420026e+000,-5.952812e-002,2.272451e-002,-1.553027e+000,-1.925285e-001,-1.102759e-001,-3.094616e-005,-3.094616e-005,,,,,,,,,,,,,,,,,,,,
1405614601.234,,0.000000e+000,2.979968e+002,2.979968e+002,1,0,7.108534e-002,-1.203955e+000,-1.203955e+000,-3.945034e-001,-3.686052e-001,-1.078369e+000,-2.689177e-001,-2.430195e-001,-2.623741e-005,-2.623741e-005,,,,,,,,,,,,,,,,,,,,
1405614601.234,,0.000000e+000,2.979968e+002,2.979968e+002,1,0,2.593047e+000,-1.681570e-001,-1.681570e-001,5.794269e-001,6.671930e-001,-1.850230e-001,5.625609e-001,6.503270e-001,-3.664592e-006,-3.664592e-006,,,,,,,,,,,,,,,,,,,,
1405614618.468,,0.000000e+000,2.980050e+002,2.979968e+002,1,0,3.301709e+000,-8.030946e-001,-8.030946e-001,-6.392211e-002,-3.547966e-003,-8.989475e-001,-1.597750e-001,-9.940088e-002,-1.750158e-005,-1.750158e-005,,,,,,,,,,,,,,,,,,,,
1405614636.703,,0.000000e+000,2.979968e+002,2.979968e+002,1,0,1.381579e-001,-1.066622e+000,-1.066622e+000,-3.640688e-001,-3.364064e-001,-9.660655e-001,-2.635123e-001,-2.358500e-001,-2.324455e-005,-2.324455e-005,,,,,,,,,,,,,,,,,,,,
1405614636.703,,0.000000e+000,2.979968e+002,2.979968e+002,1,0,2.427830e+000,-1.358074e-002,-1.358074e-002,6.263681e-001,7.166348e-001,4.414686e-002,6.840957e-001,7.743623e-001,-2.959607e-007,-2.959607e-007,,,,,,,,,,,,,,,,,,,,
1405614755.703,,-5.000000e+000,2.980050e+002,2.979968e+002,1,0,3.448643e+000,5.458235e-001,5.458235e-001,2.157835e-001,2.826950e-001,4.624463e-001,1.324062e-001,1.993178e-001,1.189495e-005,1.189495e-005,,,,,,,,,,,,,,,,,,,,
1405614774.187,,-5.000000e+000,2.979968e+002,2.980050e+002,1,0,2.237973e-001,4.748680e-001,4.748680e-001,1.019203e-001,1.373546e-001,5.221061e-001,1.491584e-001,1.845927e-001,1.034864e-005,1.034864e-005,,,,,,,,,,,,,,,,,,,,
1405614774.187,,-5.000000e+000,2.979968e+002,2.980050e+002,1,0,2.256171e+000,1.220740e-001,1.220740e-001,-3.270573e-001,-2.154393e-001,2.398140e-001,-2.093174e-001,-9.769939e-002,2.660320e-006,2.660320e-006,,,,,,,,,,,,,,,,,,,,
1405614792.171,,-5.000000e+000,2.980050e+002,2.979968e+002,1,0,3.584305e+000,6.421095e-001,6.421095e-001,1.893949e-001,2.624854e-001,6.088249e-001,1.561104e-001,2.292009e-001,1.399328e-005,1.399328e-005,,,,,,,,,,,,,,,,,,,,
1405614916.921,,-1.000000e+001,2.979968e+002,2.979968e+002,1,0,3.242368e-001,1.645863e+000,1.645863e+000,4.841604e-001,5.080626e-001,1.663374e+000,5.016717e-001,5.255738e-001,3.586774e-005,3.586774e-005,,,,,,,,,,,,,,,,,,,,
1405614934.671,,-1.000000e+001,2.979968e+002,2.980050e+002,1,0,2.079522e+000,1.403851e-002,1.403851e-002,-1.172771e+000,-1.172771e+000,4.713452e-002,-1.139675e+000,-1.139675e+000,3.059366e-007,3.059366e-007,,,,,,,,,,,,,,,,,,,,
1405614934.671,,-1.000000e+001,2.979968e+002,2.980050e+002,1,0,3.705873e+000,1.733451e+000,1.733451e+000,4.917886e-001,5.466422e-001,1.740690e+000,4.990273e-001,5.538809e-001,3.777652e-005,3.777652e-005,,,,,,,,,,,,,,,,,,,,
1405614952.406,,-1.000000e+001,2.980050e+002,2.979968e+002,1,0,4.360803e-001,1.751915e+000,1.751915e+000,5.187487e-001,5.455506e-001,1.744413e+000,5.112464e-001,5.380483e-001,3.817889e-005,3.817889e-005,,,,,,,,,,,,,,,,,,,,
1405615072.140,,-1.500000e+001,2.980050e+002,2.980050e+002,1,0,1.899612e+000,1.525925e-003,1.525925e-003,-1.508299e+000,-1.507552e+000,1.028235e-002,-1.499542e+000,-1.498795e+000,3.325396e-008,3.325396e-008,,,,,,,,,,,,,,,,,,,,
1405615072.140,,-1.500000e+001,2.980050e+002,2.980050e+002,1,0,3.810260e+000,2.123783e+000,2.123783e+000,5.818352e-001,6.147054e-001,2.152452e+000,6.105046e-001,6.433748e-001,4.628286e-005,4.628286e-005,,,,,,,,,,,,,,,,,,,,
1405615089.875,,-1.500000e+001,2.980050e+002,2.980050e+002,1,0,5.565618e-001,2.186651e+000,2.186651e+000,6.338221e-001,6.534495e-001,2.150192e+000,5.973632e-001,6.169906e-001,4.765293e-005,4.765293e-005,,,,,,,,,,,,,,,,,,,,
1405615107.109,,-1.500000e+001,2.979968e+002,2.979968e+002,1,0,1.718860e+000,2.296518e-001,2.296518e-001,-1.330296e+000,-1.328445e+000,2.236619e-001,-1.336286e+000,-1.334435e+000,5.004722e-006,5.004722e-006,,,,,,,,,,,,,,,,,,,,
1405615107.109,,-1.500000e+001,2.979968e+002,2.979968e+002,1,0,3.893819e+000,2.125004e+000,2.125004e+000,5.252490e-001,5.669073e-001,2.174684e+000,5.749295e-001,6.165878e-001,4.630947e-005,4.630947e-005,,,,,,,,,,,,,,,,,,,,
1405615226.109,,-2.000000e+001,2.979968e+002,2.980050e+002,1,0,6.834713e-001,2.333140e+000,2.333140e+000,6.091401e-001,6.249501e-001,2.279779e+000,5.557787e-001,5.715886e-001,5.084528e-005,5.084528e-005,,,,,,,,,,,,,,,,,,,,
1405615244.359,,-2.000000e+001,2.979968e+002,2.980050e+002,1,0,1.538712e+000,6.367687e-001,6.367687e-001,-1.103255e+000,-1.100970e+000,6.194937e-001,-1.120530e+000,-1.118245e+000,1.387687e-005,1.387687e-005,,,,,,,,,,,,,,,,,,,,
1405615244.359,,-2.000000e+001,2.979968e+002,2.980050e+002,1,0,3.953593e+000,2.331309e+000,2.331309e+000,5.585455e-001,5.935698e-001,2.387848e+000,6.150845e-001,6.501088e-001,5.080538e-005,5.080538e-005,,,,,,,,,,,,,,,,,,,,
1405615262.843,,-2.000000e+001,2.979968e+002,2.979968e+002,1,0,8.160456e-001,2.240059e+000,2.240059e+000,4.411606e-001,4.597590e-001,2.176755e+000,3.778571e-001,3.964555e-001,4.881679e-005,4.881679e-005,,,,,,,,,,,,,,,,,,,,
1405615383.578,,-2.500000e+001,2.979968e+002,2.979968e+002,1,0,1.360884e+000,1.194037e+000,1.194037e+000,-7.293099e-001,-7.276497e-001,1.160746e+000,-7.626011e-001,-7.609409e-001,2.602120e-005,2.602120e-005,,,,,,,,,,,,,,,,,,,,
1405615383.578,,-2.500000e+001,2.979968e+002,2.979968e+002,1,0,3.987499e+000,2.562792e+000,2.562792e+000,6.215976e-001,6.411054e-001,2.613548e+000,6.723540e-001,6.918619e-001,5.584998e-005,5.584998e-005,,,,,,,,,,,,,,,,,,,,
1405615401.312,,-2.500000e+001,2.980050e+002,2.980050e+002,1,0,9.543542e-001,2.214728e+000,2.214728e+000,2.450912e-001,2.562681e-001,2.155301e+000,1.856637e-001,1.968406e-001,4.826476e-005,4.826476e-005,,,,,,,,,,,,,,,,,,,,
1405615419.062,,-2.500000e+001,2.979968e+002,2.980050e+002,1,0,1.186868e+000,1.687674e+000,1.687674e+000,-2.783117e-001,-2.759039e-001,1.631395e+000,-3.345904e-001,-3.321826e-001,3.677885e-005,3.677885e-005,,,,,,,,,,,,,,,,,,,,
1405615419.062,,-2.500000e+001,2.979968e+002,2.980050e+002,1,0,3.994375e+000,2.612079e+000,2.612079e+000,6.253871e-001,6.485016e-001,2.663293e+000,6.766009e-001,6.997154e-001,5.692408e-005,5.692408e-005,,,,,,,,,,,,,,,,,,,,
1405615536.812,,-3.000000e+001,2.979968e+002,2.980050e+002,1,0,1.098820e+000,1.971954e+000,1.971954e+000,-8.586061e-002,-7.786381e-002,1.938232e+000,-1.195822e-001,-1.115854e-001,4.297404e-005,4.297404e-005,,,,,,,,,,,,,,,,,,,,
1405615553.546,,-3.000000e+001,2.980050e+002,2.980050e+002,1,0,1.018063e+000,2.185736e+000,2.185736e+000,1.269170e-001,1.287370e-001,2.128197e+000,6.937800e-002,7.119799e-002,4.763291e-005,4.763291e-005,,,,,,,,,,,,,,,,,,,,
1405615553.546,,-3.000000e+001,2.980050e+002,2.980050e+002,1,0,3.974677e+000,2.752922e+000,2.752922e+000,6.810601e-001,6.959233e-001,2.801506e+000,7.296439e-001,7.445071e-001,5.999339e-005,5.999339e-005,,,,,,,,,,,,,,,,,,,,
1405615570.781,,-3.000000e+001,2.980050e+002,2.979968e+002,1,0,1.249808e+000,1.593677e+000,1.593677e+000,-4.945169e-001,-4.859142e-001,1.591563e+000,-4.966301e-001,-4.880275e-001,3.473039e-005,3.473039e-005,,,,,,,,,,,,,,,,,,,,
1405615688.562,,-3.500000e+001,2.979968e+002,2.980132e+002,1,0,8.547648e-001,2.565539e+000,2.565538e+000,4.685516e-001,4.692132e-001,2.527929e+000,4.309422e-001,4.316039e-001,5.590978e-005,5.590978e-005,,,,,,,,,,,,,,,,,,,,
1405615688.562,,-3.500000e+001,2.979968e+002,2.980132e+002,1,0,3.929807e+000,2.854549e+000,2.854549e+000,7.534972e-001,7.582235e-001,2.888584e+000,7.875322e-001,7.922585e-001,6.220807e-005,6.220807e-005,,,,,,,,,,,,,,,,,,,,
1405615705.296,,-3.500000e+001,2.980050e+002,2.979968e+002,1,0,1.408087e+000,1.127964e+000,1.127964e+000,-9.629346e-001,-9.582738e-001,1.160573e+000,-9.303257e-001,-9.256649e-001,2.458128e-005,2.458128e-005,,,,,,,,,,,,,,,,,,,,
1405615723.281,,-3.500000e+001,2.979968e+002,2.979885e+002,1,0,6.990646e-001,2.844630e+000,2.844630e+000,7.365347e-001,7.381740e-001,2.806226e+000,6.981302e-001,6.997695e-001,6.199192e-005,6.199192e-005,,,,,,,,,,,,,,,,,,,,
1405615723.281,,-3.500000e+001,2.979968e+002,2.979885e+002,1,0,3.862866e+000,2.930235e+000,2.930235e+000,8.133282e-001,8.237784e-001,2.954875e+000,8.379683e-001,8.484185e-001,6.385746e-005,6.385746e-005,,,,,,,,,,,,,,,,,,,,
1405615843.281,,-4.000000e+001,2.980050e+002,2.979968e+002,1,0,1.573401e+000,7.379375e-001,7.379376e-001,-1.455816e+000,-1.452486e+000,7.896112e-001,-1.404142e+000,-1.400813e+000,1.608158e-005,1.608158e-005,,,,,,,,,,,,,,,,,,,,
1405615861.765,,-4.000000e+001,2.979968e+002,2.980050e+002,1,0,5.523434e-001,3.087100e+000,3.087100e+000,8.950405e-001,8.959608e-001,3.071036e+000,8.789768e-001,8.798971e-001,6.727593e-005,6.727593e-005,,,,,,,,,,,,,,,,,,,,
1405615861.765,,-4.000000e+001,2.979968e+002,2.980050e+002,1,0,3.777260e+000,3.096866e+000,3.096866e+000,9.004094e-001,9.057267e-001,3.104044e+000,9.075882e-001,9.129055e-001,6.748876e-005,6.748876e-005,,,,,,,,,,,,,,,,,,,,
1405615878.781,,-4.000000e+001,2.980050e+002,2.979968e+002,1,0,1.745000e+000,3.465377e-001,3.465377e-001,-1.859637e+000,-1.854190e+000,3.795637e-001,-1.826611e+000,-1.821164e+000,7.551957e-006,7.551957e-006,,,,,,,,,,,,,,,,,,,,
1405615997.062,,-4.500000e+001,2.979968e+002,2.979968e+002,1,0,4.165761e-001,3.166600e+000,3.166600e+000,9.522826e-001,9.522409e-001,3.169069e+000,9.547510e-001,9.547093e-001,6.900843e-005,6.900843e-005,,,,,,,,,,,,,,,,,,,,
1405615997.062,,-4.500000e+001,2.979968e+002,2.979968e+002,1,0,3.676721e+000,3.172399e+000,3.172399e+000,9.582605e-001,9.580395e-001,3.168833e+000,9.546949e-001,9.544740e-001,6.913480e-005,6.913480e-005,,,,,,,,,,,,,,,,,,,,
1405616015.328,,-4.500000e+001,2.979968e+002,2.979968e+002,1,0,1.921576e+000,1.030000e-001,1.030000e-001,-2.127061e+000,-2.125808e+000,9.326176e-002,-2.136799e+000,-2.135546e+000,2.244636e-006,2.244636e-006,,,,,,,,,,,,,,,,,,,,
1405616034.062,,-4.500000e+001,2.979968e+002,2.980050e+002,1,0,2.950973e-001,3.157292e+000,3.157292e+000,9.225379e-001,9.229844e-001,3.170194e+000,9.354399e-001,9.358864e-001,6.880558e-005,6.880558e-005,,,,,,,,,,,,,,,,,,,,
1405616034.062,,-4.500000e+001,2.979968e+002,2.980050e+002,1,0,3.564957e+000,3.188421e+000,3.188421e+000,9.519215e-001,9.541132e-001,3.174083e+000,9.375837e-001,9.397755e-001,6.948396e-005,6.948396e-005,,,,,,,,,,,,,,,,,,,,
1405616152.359,,-5.000000e+001,2.980050e+002,2.980050e+002,1,0,2.101274e+000,1.278726e-001,1.278726e-001,-2.148524e+000,-2.149217e+000,8.654496e-002,-2.189851e+000,-2.190545e+000,2.786673e-006,2.786673e-006,,,,,,,,,,,,,,,,,,,,
1405616170.140,,-5.000000e+001,2.980050e+002,2.979968e+002,1,0,1.908760e-001,3.173925e+000,3.173925e+000,8.684528e-001,8.697624e-001,3.194585e+000,8.891132e-001,8.904228e-001,6.916802e-005,6.916802e-005,,,,,,,,,,,,,,,,,,,,
1405616170.140,,-5.000000e+001,2.980050e+002,2.979968e+002,1,0,3.444623e+000,3.189795e+000,3.189795e+000,8.796294e-001,8.856320e-001,3.171224e+000,8.610592e-001,8.670619e-001,6.951386e-005,6.951386e-005,,,,,,,,,,,,,,,,,,,,
1405616187.875,,-5.000000e+001,2.980050e+002,2.980050e+002,1,0,2.282218e+000,3.999451e-001,3.999451e-001,-1.897753e+000,-1.893514e+000,3.667888e-001,-1.930909e+000,-1.926671e+000,8.715835e-006,8.715835e-006,,,,,,,,,,,,,,,,,,,,
1405616329.890,,-7.500000e+001,2.979968e+002,2.979968e+002,1,0,1.072225e-001,1.868191e+000,1.868191e+000,4.291032e-001,4.420791e-001,1.870764e+000,4.316764e-001,4.446522e-001,8.142520e-005,8.142520e-005,,,,,,,,,,,,,,,,,,,,
1405616329.890,,-7.500000e+001,2.979968e+002,2.979968e+002,1,0,3.317624e+000,1.846980e+000,1.846980e+000,3.649728e-001,4.208688e-001,1.842642e+000,3.606350e-001,4.165310e-001,8.050074e-005,8.050074e-005,,,,,,,,,,,,,,,,,,,,
1405616348.125,,-7.500000e+001,2.979968e+002,2.979968e+002,1,0,2.462255e+000,6.784264e-001,6.784264e-001,-7.704315e-001,-7.344845e-001,6.649294e-001,-7.839285e-001,-7.479815e-001,2.956926e-005,2.956926e-005,,,,,,,,,,,,,,,,,,,,
1405616366.375,,-7.500000e+001,2.979968e+002,2.979968e+002,1,0,4.745845e-002,1.827296e+000,1.827296e+000,4.008403e-001,4.135991e-001,1.830433e+000,4.039776e-001,4.167365e-001,7.964280e-005,7.964280e-005,,,,,,,,,,,,,,,,,,,,
1405616366.375,,-7.500000e+001,2.979968e+002,2.979968e+002,1,0,3.185026e+000,1.698660e+000,1.698660e+000,2.330168e-001,2.849636e-001,1.694899e+000,2.292560e-001,2.812028e-001,7.403621e-005,7.403621e-005,,,,,,,,,,,,,,,,,,,,
1405616527.359,,-1.000000e+002,2.979968e+002,2.979968e+002,1,0,2.640091e+000,7.522812e-001,7.522812e-001,-2.150490e-001,-1.482905e-001,7.549515e-001,-2.123787e-001,-1.456202e-001,8.197038e-005,8.197038e-005,,,,,,,,,,,,,,,,,,,,
1405616545.093,,-1.000000e+002,2.979968e+002,2.979968e+002,1,0,1.351789e-002,1.129185e+000,1.129185e+000,1.645105e-001,1.966318e-001,1.124480e+000,1.598058e-001,1.919271e-001,1.230387e-004,1.230387e-004,,,,,,,,,,,,,,,,,,,,
1405616545.093,,-1.000000e+002,2.979968e+002,2.979968e+002,1,0,3.046603e+000,1.075777e+000,1.075777e+000,1.902200e-002,1.432244e-001,1.083689e+000,2.693320e-002,1.511356e-001,1.172193e-004,1.172193e-004,,,,,,,,,,,,,,,,,,,,
1405616561.828,,-1.000000e+002,2.979968e+002,2.980050e+002,1,0,2.814207e+000,7.090976e-001,7.090976e-001,-1.132729e-001,-7.058841e-002,7.170413e-001,-1.053291e-001,-6.264466e-002,7.726498e-005,7.726498e-005,,,,,,,,,,,,,,,,,,,,
1405616688.078,,-7.500000e+001,2.979968e+002,2.980050e+002,1,0,6.677025e-003,6.331065e-001,6.331065e-001,1.547402e-001,1.537990e-001,6.335232e-001,1.551569e-001,1.542157e-001,6.898496e-005,6.898496e-005,,,,,,,,,,,,,,,,,,,,
1405616688.078,,-7.500000e+001,2.979968e+002,2.980050e+002,1,0,2.902255e+000,4.138310e-001,4.138310e-001,-6.200555e-002,-6.547651e-002,4.232700e-001,-5.256653e-002,-5.603749e-002,4.509212e-005,4.509212e-005,,,,,,,,,,,,,,,,,,,,
1405616706.343,,-7.500000e+001,2.979968e+002,2.979968e+002,1,0,2.983150e+000,4.762414e-001,4.762414e-001,-9.950616e-003,-1.136348e-002,4.783542e-001,-7.837811e-003,-9.250671e-003,5.189252e-005,5.189252e-005,,,,,,,,,,,,,,,,,,,,
1405616723.578,,-7.500000e+001,2.979968e+002,2.980050e+002,1,0,2.645577e-002,6.407361e-001,6.407361e-001,1.581776e-001,1.573349e-001,6.415679e-001,1.590095e-001,1.581668e-001,6.981631e-005,6.981631e-005,,,,,,,,,,,,,,,,,,,,
1405616723.578,,-7.500000e+001,2.979968e+002,2.980050e+002,1,0,2.751147e+000,3.267007e-001,3.267007e-001,-1.537263e-001,-1.567005e-001,3.394993e-001,-1.409276e-001,-1.439019e-001,3.559817e-005,3.559817e-005,,,,,,,,,,,,,,,,,,,,
1405616854.375,,-5.000000e+001,2.979968e+002,2.979968e+002,1,0,3.146328e+000,5.168310e-001,5.168310e-001,7.557656e-002,7.206702e-002,5.126123e-001,7.135792e-002,6.784838e-002,5.631540e-005,5.631540e-005,,,,,,,,,,,,,,,,,,,,
1405616872.359,,-5.000000e+001,2.979968e+002,2.979968e+002,1,0,7.123676e-002,6.079287e-001,6.079287e-001,1.572886e-001,1.558317e-001,6.120244e-001,1.613843e-001,1.599274e-001,6.624168e-005,6.624168e-005,,,,,,,,,,,,,,,,,,,,
1405616872.359,,-5.000000e+001,2.979968e+002,2.979968e+002,1,0,2.592845e+000,2.058474e-001,2.058474e-001,-2.413125e-001,-2.462496e-001,2.168856e-001,-2.302743e-001,-2.352114e-001,2.242972e-005,2.242972e-005,,,,,,,,,,,,,,,,,,,,
1405616890.093,,-5.000000e+001,2.979968e+002,2.979885e+002,1,0,3.302004e+000,5.888546e-001,5.888546e-001,1.389423e-001,1.359952e-001,5.843616e-001,1.344493e-001,1.315022e-001,6.416331e-005,6.416331e-005,,,,,,,,,,,,,,,,,,,,
1405617008.843,,-4.500000e+001,2.979968e+002,2.980050e+002,1,0,1.381641e-001,6.041139e-001,6.041139e-001,1.688222e-001,1.670239e-001,6.064699e-001,1.711783e-001,1.693799e-001,6.582603e-005,6.582603e-005,,,,,,,,,,,,,,,,,,,,
1405617008.843,,-4.500000e+001,2.979968e+002,2.980050e+002,1,0,2.427433e+000,1.002533e-001,1.002533e-001,-3.309684e-001,-3.368367e-001,1.084681e-001,-3.227536e-001,-3.286218e-001,1.092390e-005,1.092390e-005,,,,,,,,,,,,,,,,,,,,
1405617027.078,,-4.500000e+001,2.980050e+002,2.979968e+002,1,0,3.448903e+000,6.128117e-001,6.128117e-001,1.773101e-001,1.741786e-001,6.097493e-001,1.742477e-001,1.711163e-001,6.677377e-005,6.677377e-005,,,,,,,,,,,,,,,,,,,,
1405617044.812,,-4.500000e+001,2.979968e+002,2.979968e+002,1,0,2.239070e-001,6.274605e-001,6.274605e-001,1.846574e-001,1.833375e-001,6.267441e-001,1.839410e-001,1.826210e-001,6.836995e-005,6.836995e-005,,,,,,,,,,,,,,,,,,,,
1405617044.812,,-4.500000e+001,2.979968e+002,2.979968e+002,1,0,2.255958e+000,3.631703e-002,3.631703e-002,-4.036481e-001,-4.078060e-001,3.646692e-002,-4.034983e-001,-4.076561e-001,3.957211e-006,3.957211e-006,,,,,,,,,,,,,,,,,,,,
1405617162.546,,-4.000000e+001,2.980050e+002,2.979968e+002,1,0,3.584530e+000,6.176946e-001,6.176946e-001,1.912749e-001,1.874815e-001,6.178720e-001,1.914523e-001,1.876589e-001,6.730586e-005,6.730586e-005,,,,,,,,,,,,,,,,,,,,
1405617180.281,,-4.000000e+001,2.980050e+002,2.980050e+002,1,0,3.244340e-001,6.360058e-001,6.360058e-001,1.927154e-001,1.914539e-001,6.349043e-001,1.916139e-001,1.903524e-001,6.930110e-005,6.930110e-005,,,,,,,,,,,,,,,,,,,,
1405617197.531,,-4.000000e+001,2.980050e+002,2.979968e+002,1,0,2.079241e+000,6.408887e-003,6.408887e-003,-4.396848e-001,-4.396848e-001,4.391671e-003,-4.417021e-001,-4.417021e-001,6.983316e-007,6.983316e-007,,,,,,,,,,,,,,,,,,,,
1405617197.531,,-4.000000e+001,2.980050e+002,2.979968e+002,1,0,3.706075e+000,6.350902e-001,6.350902e-001,1.917996e-001,1.889964e-001,6.366029e-001,1.933123e-001,1.905091e-001,6.920133e-005,6.920133e-005,,,,,,,,,,,,,,,,,,,,
1405617316.765,,-3.500000e+001,2.979885e+002,2.980050e+002,1,0,4.362360e-001,6.183050e-001,6.183050e-001,1.914593e-001,1.901007e-001,6.177790e-001,1.909333e-001,1.895747e-001,6.737240e-005,6.737240e-005,,,,,,,,,,,,,,,,,,,,
1405617335.000,,-3.500000e+001,2.980050e+002,2.979968e+002,1,0,1.899688e+000,1.876888e-002,1.876888e-002,-4.181113e-001,-4.181790e-001,1.512663e-002,-4.217536e-001,-4.218212e-001,2.045115e-006,2.045115e-006,,,,,,,,,,,,,,,,,,,,
1405617335.000,,-3.500000e+001,2.980050e+002,2.979968e+002,1,0,3.810322e+000,6.154057e-001,6.154057e-001,1.814345e-001,1.784579e-001,6.165159e-001,1.825447e-001,1.795681e-001,6.705649e-005,6.705649e-005,,,,,,,,,,,,,,,,,,,,
1405617353.281,,-3.500000e+001,2.979968e+002,2.979968e+002,1,0,5.566254e-001,6.225776e-001,6.225776e-001,1.826231e-001,1.811887e-001,6.200576e-001,1.801031e-001,1.786687e-001,6.783796e-005,6.783796e-005,,,,,,,,,,,,,,,,,,,,
1405617473.062,,-3.000000e+001,2.980050e+002,2.980050e+002,1,0,1.718558e+000,7.629628e-002,7.629628e-002,-3.499805e-001,-3.501354e-001,7.584529e-002,-3.504315e-001,-3.505864e-001,8.313479e-006,8.313479e-006,,,,,,,,,,,,,,,,,,,,
1405617473.062,,-3.000000e+001,2.980050e+002,2.980050e+002,1,0,3.893777e+000,5.900754e-001,5.900754e-001,1.671279e-001,1.636437e-001,5.919867e-001,1.690392e-001,1.655551e-001,6.429644e-005,6.429644e-005,,,,,,,,,,,,,,,,,,,,
1405617490.828,,-3.000000e+001,2.979968e+002,2.979968e+002,1,0,6.836356e-001,5.850399e-001,5.850399e-001,1.565880e-001,1.553078e-001,5.792285e-001,1.507766e-001,1.494964e-001,6.374776e-005,6.374776e-005,,,,,,,,,,,,,,,,,,,,
1405617508.562,,-3.000000e+001,2.979968e+002,2.979968e+002,1,0,1.538622e+000,1.680044e-001,1.680044e-001,-2.586606e-001,-2.588119e-001,1.692627e-001,-2.574023e-001,-2.575535e-001,1.830628e-005,1.830628e-005,,,,,,,,,,,,,,,,,,,,
1405617508.562,,-3.000000e+001,2.979968e+002,2.979968e+002,1,0,3.953635e+000,5.822932e-001,5.822932e-001,1.577960e-001,1.554769e-001,5.840946e-001,1.595975e-001,1.572784e-001,6.344847e-005,6.344847e-005,,,,,,,,,,,,,,,,,,,,
1405617626.828,,-2.500000e+001,2.979968e+002,2.980050e+002,1,0,8.161705e-001,5.238502e-001,5.238502e-001,1.138781e-001,1.125218e-001,5.163620e-001,1.063899e-001,1.050335e-001,5.708037e-005,5.708037e-005,,,,,,,,,,,,,,,,,,,,
1405617644.062,,-2.500000e+001,2.979968e+002,2.979968e+002,1,0,1.360915e+000,2.653584e-001,2.653584e-001,-1.507341e-001,-1.508920e-001,2.622910e-001,-1.538016e-001,-1.539595e-001,2.891429e-005,2.891429e-005,,,,,,,,,,,,,,,,,,,,
1405617644.062,,-2.500000e+001,2.979968e+002,2.979968e+002,1,0,3.987553e+000,5.629139e-001,5.629139e-001,1.485185e-001,1.466634e-001,5.656493e-001,1.512539e-001,1.493989e-001,6.133688e-005,6.133688e-005,,,,,,,,,,,,,,,,,,,,
1405617662.109,,-2.500000e+001,2.980050e+002,2.980050e+002,1,0,9.545614e-001,4.757836e-001,4.757836e-001,5.848670e-002,5.739716e-002,4.677087e-001,5.041188e-002,4.932234e-002,5.184288e-005,5.184288e-005,,,,,,,,,,,,,,,,,,,,
1405617781.109,,-2.000000e+001,2.979968e+002,2.980050e+002,1,0,1.186428e+000,3.573717e-001,3.573717e-001,-5.140285e-002,-5.160567e-002,3.499807e-001,-5.879391e-002,-5.899674e-002,3.894037e-005,3.894037e-005,,,,,,,,,,,,,,,,,,,,
1405617781.109,,-2.000000e+001,2.979968e+002,2.980050e+002,1,0,3.994343e+000,5.497909e-001,5.497909e-001,1.427606e-001,1.408135e-001,5.541128e-001,1.470825e-001,1.451354e-001,5.990698e-005,5.990698e-005,,,,,,,,,,,,,,,,,,,,
1405617798.343,,-2.000000e+001,2.980050e+002,2.980050e+002,1,0,1.098985e+000,3.949095e-001,3.949095e-001,-1.013221e-002,-1.092118e-002,3.892697e-001,-1.577203e-002,-1.656100e-002,4.303061e-005,4.303061e-005,,,,,,,,,,,,,,,,,,,,
1405617816.578,,-2.000000e+001,2.979968e+002,2.979968e+002,1,0,1.017713e+000,4.443495e-001,4.443495e-001,3.043186e-002,3.024957e-002,4.359786e-001,2.206095e-002,2.187866e-002,4.841775e-005,4.841775e-005,,,,,,,,,,,,,,,,,,,,
1405617816.578,,-2.000000e+001,2.979968e+002,2.979968e+002,1,0,3.974593e+000,5.580310e-001,5.580310e-001,1.454197e-001,1.439310e-001,5.628541e-001,1.502428e-001,1.487541e-001,6.080484e-005,6.080484e-005,,,,,,,,,,,,,,,,,,,,
1405617928.328,,-1.500000e+001,2.980050e+002,2.979968e+002,1,0,1.250119e+000,3.100681e-001,3.100681e-001,-8.750989e-002,-8.867192e-002,3.094074e-001,-8.817055e-002,-8.933258e-002,3.378603e-005,3.378603e-005,,,,,,,,,,,,,,,,,,,,
1405617946.343,,-1.500000e+001,2.979968e+002,2.979968e+002,1,0,8.546951e-001,4.940947e-001,4.940947e-001,9.618600e-002,9.605202e-002,4.868537e-001,8.894505e-002,8.881107e-002,5.383816e-005,5.383816e-005,,,,,,,,,,,,,,,,,,,,
1405617946.343,,-1.500000e+001,2.979968e+002,2.979968e+002,1,0,3.929802e+000,5.449080e-001,5.449080e-001,1.478224e-001,1.468653e-001,5.507751e-001,1.536895e-001,1.527325e-001,5.937495e-005,5.937495e-005,,,,,,,,,,,,,,,,,,,,
1405617964.328,,-1.500000e+001,2.979968e+002,2.980050e+002,1,0,1.408330e+000,2.218696e-001,2.218696e-001,-1.758081e-001,-1.761559e-001,2.280353e-001,-1.696424e-001,-1.699901e-001,2.417563e-005,2.417563e-005,,,,,,,,,,,,,,,,,,,,
1405618089.562,,-1.000000e+001,2.979968e+002,2.979968e+002,1,0,6.990165e-001,5.259865e-001,5.259865e-001,1.419700e-001,1.418115e-001,5.186982e-001,1.346817e-001,1.345232e-001,5.731323e-005,5.731323e-005,,,,,,,,,,,,,,,,,,,,
1405618089.562,,-1.000000e+001,2.979968e+002,2.979968e+002,1,0,3.862812e+000,5.355998e-001,5.355998e-001,1.524353e-001,1.514248e-001,5.411898e-001,1.580253e-001,1.570148e-001,5.836073e-005,5.836073e-005,,,,,,,,,,,,,,,,,,,,
1405618107.812,,-1.000000e+001,2.980050e+002,2.979968e+002,1,0,1.573615e+000,1.336711e-001,1.336711e-001,-2.573701e-001,-2.575037e-001,1.444589e-001,-2.465823e-001,-2.467159e-001,1.456524e-005,1.456524e-005,,,,,,,,,,,,,,,,,,,,
1405618125.546,,-1.000000e+001,2.979968e+002,2.980050e+002,1,0,5.521086e-001,5.592517e-001,5.592517e-001,1.673046e-001,1.672649e-001,5.540945e-001,1.621474e-001,1.621077e-001,6.093791e-005,6.093791e-005,,,,,,,,,,,,,,,,,,,,
1405618125.546,,-1.000000e+001,2.979968e+002,2.980050e+002,1,0,3.777071e+000,5.552843e-001,5.552843e-001,1.635268e-001,1.632975e-001,5.581699e-001,1.664124e-001,1.661831e-001,6.050561e-005,6.050561e-005,,,,,,,,,,,,,,,,,,,,
1405618245.796,,-5.000000e+000,2.979968e+002,2.979968e+002,1,0,1.745255e+000,5.203406e-002,5.203406e-002,-3.214710e-001,-3.216626e-001,6.176262e-002,-3.117425e-001,-3.119340e-001,5.669806e-006,5.669806e-006,,,,,,,,,,,,,,,,,,,,
1405618264.062,,-5.000000e+000,2.979968e+002,2.979968e+002,1,0,4.164972e-001,5.418561e-001,5.418561e-001,1.666192e-001,1.667924e-001,5.395498e-001,1.643129e-001,1.644861e-001,5.904246e-005,5.904246e-005,,,,,,,,,,,,,,,,,,,,
1405618264.062,,-5.000000e+000,2.979968e+002,2.979968e+002,1,0,3.676560e+000,5.406354e-001,5.406354e-001,1.646537e-001,1.655717e-001,5.402930e-001,1.643113e-001,1.652293e-001,5.890945e-005,5.890945e-005,,,,,,,,,,,,,,,,,,,,
1405618282.328,,-5.000000e+000,2.979968e+002,2.979968e+002,1,0,1.921835e+000,9.308145e-003,9.308145e-003,-3.679736e-001,-3.671044e-001,1.346148e-002,-3.638202e-001,-3.629511e-001,1.014247e-006,1.014247e-006,,,,,,,,,,,,,,,,,,,,
1405618400.078,,0.000000e+000,2.979968e+002,2.979968e+002,1,0,2.949163e-001,4.960784e-001,4.960784e-001,1.494206e-001,1.494732e-001,4.980827e-001,1.514249e-001,1.514775e-001,5.405439e-005,5.405439e-005,,,,,,,,,,,,,,,,,,,,
1405618400.078,,0.000000e+000,2.979968e+002,2.979968e+002,1,0,3.564682e+000,5.026398e-001,5.026398e-001,1.557768e-001,1.560346e-001,4.984499e-001,1.515868e-001,1.518447e-001,5.476935e-005,5.476935e-005,,,,,,,,,,,,,,,,,,,,
1405618417.812,,0.000000e+000,2.980050e+002,2.979968e+002,1,0,2.101541e+000,-3.051851e-004,-3.051851e-004,-3.546133e-001,-3.538099e-001,-1.123681e-003,-3.554318e-001,-3.546284e-001,-3.325401e-008,-3.325401e-008,,,,,,,,,,,,,,,,,,,,
1405618435.546,,0.000000e+000,2.980050e+002,2.980050e+002,1,0,1.907535e-001,4.867702e-001,4.867702e-001,1.333306e-001,1.337112e-001,4.940582e-001,1.406185e-001,1.409992e-001,5.304014e-005,5.304014e-005,,,,,,,,,,,,,,,,,,,,
1405618435.546,,0.000000e+000,2.980050e+002,2.980050e+002,1,0,3.444333e+000,4.974517e-001,4.974517e-001,1.426480e-001,1.443927e-001,4.894848e-001,1.346810e-001,1.364258e-001,5.420403e-005,5.420403e-005,,,,,,,,,,,,,,,,,,,,
1405618569.031,,5.000000e+000,2.979968e+002,2.979968e+002,1,0,2.282419e+000,9.216589e-002,9.216590e-002,-7.467927e-001,-7.426186e-001,8.820520e-002,-7.507533e-001,-7.465793e-001,4.017083e-006,4.017083e-006,,,,,,,,,,,,,,,,,,,,
1405618586.765,,5.000000e+000,2.979968e+002,2.979885e+002,1,0,1.071844e-001,1.101108e+000,1.101108e+000,2.687133e-001,2.702952e-001,1.133306e+000,3.009116e-001,3.024935e-001,4.799216e-005,4.799216e-005,,,,,,,,,,,,,,,,,,,,
1405618586.765,,5.000000e+000,2.979968e+002,2.979885e+002,1,0,3.317316e+000,1.110721e+000,1.110721e+000,2.730941e-001,2.799085e-001,1.078656e+000,2.410287e-001,2.478431e-001,4.841116e-005,4.841116e-005,,,,,,,,,,,,,,,,,,,,
1405618604.000,,5.000000e+000,2.979885e+002,2.979968e+002,1,0,2.462594e+000,2.618488e-001,2.618488e-001,-5.795256e-001,-5.752779e-001,2.516992e-001,-5.896752e-001,-5.854275e-001,1.141277e-005,1.141277e-005,,,,,,,,,,,,,,,,,,,,
1405618729.500,,1.000000e+001,2.980050e+002,2.979968e+002,1,0,4.742036e-002,9.739982e-001,9.739982e-001,2.116444e-001,2.131317e-001,1.017779e+000,2.554248e-001,2.569121e-001,4.245203e-005,4.245203e-005,,,,,,,,,,,,,,,,,,,,
1405618729.500,,1.000000e+001,2.980050e+002,2.979968e+002,1,0,3.184731e+000,9.303567e-001,9.303567e-001,1.634348e-001,1.694902e-001,8.912344e-001,1.243124e-001,1.303679e-001,4.054990e-005,4.054990e-005,,,,,,,,,,,,,,,,,,,,
1405618747.734,,1.000000e+001,2.980050e+002,2.979968e+002,1,0,2.640541e+000,4.068117e-001,4.068117e-001,-3.565287e-001,-3.511105e-001,3.870800e-001,-3.762605e-001,-3.708423e-001,1.773102e-005,1.773102e-005,,,,,,,,,,,,,,,,,,,,
1405618765.984,,1.000000e+001,2.979968e+002,2.979968e+002,1,0,1.359949e-002,9.546190e-001,9.546190e-001,1.924859e-001,1.950842e-001,1.005980e+000,2.438466e-001,2.464448e-001,4.160738e-005,4.160738e-005,,,,,,,,,,,,,,,,,,,,
1405618765.984,,1.000000e+001,2.979968e+002,2.979968e+002,1,0,3.046496e+000,8.151494e-001,8.151494e-001,4.556806e-002,5.561453e-002,7.806897e-001,1.110841e-002,2.115488e-002,3.552855e-005,3.552855e-005,,,,,,,,,,,,,,,,,,,,
1405618889.468,,1.500000e+001,2.979968e+002,2.979968e+002,1,0,2.814434e+000,5.171362e-001,5.171362e-001,-1.572491e-001,-1.506459e-001,4.822937e-001,-1.920916e-001,-1.854883e-001,2.253954e-005,2.253954e-005,,,,,,,,,,,,,,,,,,,,
1405618907.265,,1.500000e+001,2.979968e+002,2.979968e+002,1,0,6.630558e-003,8.359020e-001,8.359020e-001,1.522132e-001,1.554146e-001,8.938228e-001,2.101341e-001,2.133355e-001,3.643304e-005,3.643304e-005,,,,,,,,,,,,,,,,,,,,
1405618907.265,,1.500000e+001,2.979968e+002,2.979968e+002,1,0,2.902074e+000,5.975524e-001,5.975524e-001,-9.474006e-002,-8.293492e-002,5.750058e-001,-1.172867e-001,-1.054815e-001,2.604450e-005,2.604450e-005,,,,,,,,,,,,,,,,,,,,
1405618924.796,,1.500000e+001,2.979968e+002,2.979968e+002,1,0,2.983212e+000,6.848354e-001,6.848354e-001,-3.071212e-003,5.211174e-003,6.371104e-001,-5.079623e-002,-4.251385e-002,2.984876e-005,2.984876e-005,,,,,,,,,,,,,,,,,,,,
1405619042.343,,2.000000e+001,2.980050e+002,2.980050e+002,1,0,2.644288e-002,6.613361e-001,6.613361e-001,1.065433e-001,1.102356e-001,7.264260e-001,1.716332e-001,1.753255e-001,2.882452e-005,2.882452e-005,,,,,,,,,,,,,,,,,,,,
1405619042.343,,2.000000e+001,2.980050e+002,2.980050e+002,1,0,2.751013e+000,3.537095e-001,3.537095e-001,-2.104226e-001,-1.973910e-001,3.428290e-001,-2.213030e-001,-2.082714e-001,1.541653e-005,1.541653e-005,,,,,,,,,,,,,,,,,,,,
1405619060.828,,2.000000e+001,2.980132e+002,2.979968e+002,1,0,3.146243e+000,6.530961e-001,6.530961e-001,9.807268e-002,1.081509e-001,6.001131e-001,4.508970e-002,5.516791e-002,2.846538e-005,2.846538e-005,,,,,,,,,,,,,,,,,,,,
1405619078.906,,2.000000e+001,2.979968e+002,2.979968e+002,1,0,7.118937e-002,6.860561e-001,6.860561e-001,1.240478e-001,1.290985e-001,7.418467e-001,1.798385e-001,1.848891e-001,2.990195e-005,2.990195e-005,,,,,,,,,,,,,,,,,,,,
1405619078.906,,2.000000e+001,2.979968e+002,2.979968e+002,1,0,2.592715e+000,2.322459e-001,2.322459e-001,-3.418279e-001,-3.247117e-001,2.402412e-001,-3.338326e-001,-3.167164e-001,1.012250e-005,1.012250e-005,,,,,,,,,,,,,,,,,,,,
1405619214.625,,2.500000e+001,2.980050e+002,2.979968e+002,1,0,3.302060e+000,7.640309e-001,7.640309e-001,1.562057e-001,1.831136e-001,6.673222e-001,5.949702e-002,8.640486e-002,1.665024e-005,1.665024e-005,,,,,,,,,,,,,,,,,,,,
1405619232.859,,2.500000e+001,2.979968e+002,2.980132e+002,1,0,1.382210e-001,6.138798e-001,6.138798e-001,5.300535e-002,6.601328e-002,7.222359e-001,1.613614e-001,1.743693e-001,1.337806e-005,1.337806e-005,,,,,,,,,,,,,,,,,,,,
1405619232.859,,2.500000e+001,2.979968e+002,2.980132e+002,1,0,2.427495e+000,3.616443e-002,3.616443e-002,-5.541490e-001,-5.117021e-001,7.785665e-002,-5.124568e-001,-4.700099e-001,7.881182e-007,7.881182e-007,,,,,,,,,,,,,,,,,,,,
1405619250.843,,2.500000e+001,2.980050e+002,2.980050e+002,1,0,3.448951e+000,7.486191e-001,7.486190e-001,1.958439e-001,2.232932e-001,6.752570e-001,1.224819e-001,1.499313e-001,1.631438e-005,1.631438e-005,,,,,,,,,,,,,,,,,,,,
1405619370.343,,3.000000e+001,2.980050e+002,2.980050e+002,1,0,2.238807e-001,-8.488724e-001,-8.488724e-001,-3.103465e-001,-2.724406e-001,-8.075126e-001,-2.689867e-001,-2.310808e-001,-1.849915e-005,-1.849915e-005,,,,,,,,,,,,,,,,,,,,
1405619370.343,,3.000000e+001,2.980050e+002,2.980050e+002,1,0,2.255919e+000,-1.657155e-001,-1.657155e-001,2.913127e-001,4.107163e-001,-1.092070e-001,3.478212e-001,4.672248e-001,-3.611375e-006,-3.611375e-006,,,,,,,,,,,,,,,,,,,,
1405619388.078,,3.000000e+001,2.980050e+002,2.979968e+002,1,0,3.584516e+000,-7.698294e-001,-7.698294e-001,-2.474705e-001,-1.680554e-001,-7.880701e-001,-2.657112e-001,-1.862962e-001,-1.677660e-005,-1.677660e-005,,,,,,,,,,,,,,,,,,,,
1405619405.812,,3.000000e+001,2.979968e+002,2.980050e+002,1,0,3.243814e-001,-8.481094e-001,-8.481094e-001,-2.884146e-001,-2.478049e-001,-8.297905e-001,-2.700957e-001,-2.294860e-001,-1.848253e-005,-1.848253e-005,,,,,,,,,,,,,,,,,,,,
1405619525.062,,3.500000e+001,2.980050e+002,2.980050e+002,1,0,2.079396e+000,-8.209479e-002,-8.209479e-002,1.378676e+000,1.378676e+000,-5.295369e-002,1.407817e+000,1.407817e+000,-1.789060e-006,-1.789060e-006,,,,,,,,,,,,,,,,,,,,
1405619525.062,,3.500000e+001,2.980050e+002,2.980050e+002,1,0,3.706020e+000,-2.018952e+000,-2.018952e+000,-6.404678e-001,-5.581810e-001,-1.995409e+000,-6.169247e-001,-5.346379e-001,-4.399824e-005,-4.399824e-005,,,,,,,,,,,,,,,,,,,,
1405619543.296,,3.500000e+001,2.979968e+002,2.979885e+002,1,0,4.361901e-001,-2.016510e+000,-2.016510e+000,-6.050240e-001,-5.601221e-001,-2.040859e+000,-6.293722e-001,-5.844704e-001,-4.394503e-005,-4.394503e-005,,,,,,,,,,,,,,,,,,,,
1405619561.031,,3.500000e+001,2.979885e+002,2.979968e+002,1,0,1.899434e+000,-8.697775e-003,-8.697775e-003,1.475529e+000,1.477560e+000,6.686144e-002,1.551088e+000,1.553119e+000,-1.895472e-007,-1.895472e-007,,,,,,,,,,,,,,,,,,,,
1405619561.031,,3.500000e+001,2.979885e+002,2.979968e+002,1,0,3.810181e+000,-2.054811e+000,-2.054811e+000,-6.578998e-001,-5.685537e-001,-1.988203e+000,-5.912920e-001,-5.019459e-001,-4.477970e-005,-4.477970e-005,,,,,,,,,,,,,,,,,,,,
1405619679.281,,4.000000e+001,2.979968e+002,2.979968e+002,1,0,5.565689e-001,-2.502518e+000,-2.502518e+000,-6.687567e-001,-6.190728e-001,-2.565696e+000,-7.319345e-001,-6.822506e-001,-5.453637e-005,-5.453637e-005,,,,,,,,,,,,,,,,,,,,
1405619697.062,,4.000000e+001,2.979968e+002,2.979968e+002,1,0,1.718792e+000,-1.719718e-001,-1.719718e-001,1.675589e+000,1.680029e+000,-1.066732e-001,1.740888e+000,1.745327e+000,-3.747713e-006,-3.747713e-006,,,,,,,,,,,,,,,,,,,,
1405619697.062,,4.000000e+001,2.979968e+002,2.979968e+002,1,0,3.893787e+000,-2.573473e+000,-2.573473e+000,-8.213559e-001,-7.214729e-001,-2.460341e+000,-7.082239e-001,-6.083409e-001,-5.608268e-005,-5.608268e-005,,,,,,,,,,,,,,,,,,,,
1405619715.046,,4.000000e+001,2.979968e+002,2.980050e+002,1,0,6.834516e-001,-2.293161e+000,-2.293161e+000,-4.893396e-001,-4.351661e-001,-2.381970e+000,-5.781487e-001,-5.239751e-001,-4.997394e-005,-4.997394e-005,,,,,,,,,,,,,,,,,,,,
1405619828.031,,4.500000e+001,2.979968e+002,2.979968e+002,1,0,1.538378e+000,-6.256294e-001,-6.256294e-001,1.477048e+000,1.483942e+000,-6.412514e-001,1.461426e+000,1.468320e+000,-1.363409e-005,-1.363409e-005,,,,,,,,,,,,,,,,,,,,
1405619828.031,,4.500000e+001,2.979968e+002,2.979968e+002,1,0,3.953563e+000,-2.901395e+000,-2.901395e+000,-8.975272e-001,-7.918234e-001,-2.745011e+000,-7.411435e-001,-6.354396e-001,-6.322891e-005,-6.322891e-005,,,,,,,,,,,,,,,,,,,,
1405619846.265,,4.500000e+001,2.979968e+002,2.979968e+002,1,0,8.161630e-001,-2.329936e+000,-2.329936e+000,-3.068414e-001,-2.464943e-001,-2.438682e+000,-4.155882e-001,-3.552411e-001,-5.077533e-005,-5.077533e-005,,,,,,,,,,,,,,,,,,,,
1405619863.500,,4.500000e+001,2.980050e+002,2.980050e+002,1,0,1.360976e+000,-1.017182e+000,-1.017182e+000,1.063115e+000,1.072898e+000,-1.107264e+000,9.730324e-001,9.828157e-001,-2.216703e-005,-2.216703e-005,,,,,,,,,,,,,,,,,,,,
1405619863.500,,4.500000e+001,2.980050e+002,2.980050e+002,1,0,3.987519e+000,-2.872402e+000,-2.872402e+000,-8.972766e-001,-7.823222e-001,-2.694091e+000,-7.189655e-001,-6.040111e-001,-6.259709e-005,-6.259709e-005,,,,,,,,,,,,,,,,,,,,
1405619982.250,,5.000000e+001,2.979968e+002,2.979885e+002,1,0,9.543487e-001,-2.294229e+000,-2.294229e+000,-3.031169e-002,3.271317e-002,-2.425184e+000,-1.612667e-001,-9.824181e-002,-4.999717e-005,-4.999717e-005,,,,,,,,,,,,,,,,,,,,
1405619999.531,,5.000000e+001,2.980050e+002,2.979968e+002,1,0,1.187084e+000,-1.665700e+000,-1.665700e+000,6.262722e-001,6.389079e-001,-1.806974e+000,4.849987e-001,4.976344e-001,-3.629991e-005,-3.629991e-005,,,,,,,,,,,,,,,,,,,,
1405619999.531,,5.000000e+001,2.980050e+002,2.979968e+002,1,0,3.994412e+000,-3.176214e+000,-3.176214e+000,-9.929087e-001,-8.716059e-001,-2.982983e+000,-7.996774e-001,-6.783745e-001,-6.921789e-005,-6.921789e-005,,,,,,,,,,,,,,,,,,,,
1405620017.796,,5.000000e+001,2.980050e+002,2.980050e+002,1,0,1.098751e+000,-1.875362e+000,-1.875362e+000,3.708498e-001,4.395442e-001,-2.019618e+000,2.265939e-001,2.952883e-001,-4.086898e-005,-4.086898e-005,,,,,,,,,,,,,,,,,,,,
1405620143.031,,7.500000e+001,2.979968e+002,2.979885e+002,1,0,1.017619e+000,-2.397992e+000,-2.397992e+000,1.604024e-001,1.795728e-001,-2.602098e+000,-4.370327e-002,-2.453279e-002,-5.225831e-005,-5.225831e-005,,,,,,,,,,,,,,,,,,,,
1405620143.031,,7.500000e+001,2.979968e+002,2.979885e+002,1,0,3.974633e+000,-3.588977e+000,-3.588977e+000,-1.167971e+000,-1.011412e+000,-3.355647e+000,-9.346412e-001,-7.780824e-001,-7.821288e-005,-7.821288e-005,,,,,,,,,,,,,,,,,,,,
1405620161.328,,7.500000e+001,2.979885e+002,2.979968e+002,1,0,1.249845e+000,-1.623432e+000,-1.623432e+000,8.535368e-001,9.449501e-001,-1.776248e+000,7.007206e-001,7.921339e-001,-3.537869e-005,-3.537869e-005,,,,,,,,,,,,,,,,,,,,
1405620179.078,,7.500000e+001,2.980050e+002,2.979968e+002,1,0,8.547568e-001,-2.852718e+000,-2.852718e+000,-2.843754e-001,-2.614546e-001,-3.069881e+000,-5.015392e-001,-4.786184e-001,-6.216794e-005,-6.216794e-005,,,,,,,,,,,,,,,,,,,,
1405620179.078,,7.500000e+001,2.980050e+002,2.979968e+002,1,0,3.929829e+000,-3.614612e+000,-3.614612e+000,-1.187069e+000,-1.023349e+000,-3.410838e+000,-9.832945e-001,-8.195746e-001,-7.877155e-005,-7.877155e-005,,,,,,,,,,,,,,,,,,,,
1405620311.078,,1.000000e+002,2.980050e+002,2.980050e+002,1,0,1.408107e+000,-1.201208e+000,-1.201209e+000,1.413652e+000,1.516730e+000,-1.316752e+000,1.298108e+000,1.401187e+000,-2.617731e-005,-2.617731e-005,,,,,,,,,,,,,,,,,,,,
1405620329.312,,1.000000e+002,2.980050e+002,2.979968e+002,1,0,6.989640e-001,-3.356426e+000,-3.356426e+000,-6.903216e-001,-6.610529e-001,-3.562895e+000,-8.967906e-001,-8.675220e-001,-7.314485e-005,-7.314485e-005,,,,,,,,,,,,,,,,,,,,
1405620329.312,,1.000000e+002,2.980050e+002,2.979968e+002,1,0,3.862835e+000,-3.794672e+000,-3.794672e+000,-1.285886e+000,-1.099299e+000,-3.608288e+000,-1.099503e+000,-9.129155e-001,-8.269531e-005,-8.269531e-005,,,,,,,,,,,,,,,,,,,,
1405620347.609,,1.000000e+002,2.979968e+002,2.979968e+002,1,0,1.573432e+000,-6.811731e-001,-6.811731e-001,1.909686e+000,2.020674e+000,-6.967617e-001,1.894097e+000,2.005086e+000,-1.484445e-005,-1.484445e-005,,,,,,,,,,,,,,,,,,,,
1405620347.609,,1.000000e+002,2.979968e+002,2.979968e+002,1,0,2.255887e+000,-2.305673e-001,-2.305673e-001,2.238204e+000,2.471280e+000,-2.038250e-002,2.448389e+000,2.681465e+000,-5.024634e-006,-5.024634e-006,,,,,,,,,,,,,,,,,,,,