File: Sample Data Files/2014-07-31 EB on isolated PMN-PT no Ti spontaneous in situ repeat/Ni-NiO_298K_SiO2_PMN-PT_5.0Tprebias_125V_Au_back.rso.raw
[Header]
TITLE,MPMS RSO Measurement
BYAPP,MPMS Measurement,2.1,Raw with ABS
FILEOPENTIME, 1406858067.546000 7/31/2014, 6:54:27 PM

INFO, APPNAME, MPMS MultiVu Application, Revision 1.58,  Build 076

INFO, NAME, EB in situ 2
INFO, WEIGHT, 0.000
INFO, AREA, 0.000
INFO, LENGTH, 0.000
INFO, SHAPE, 0
INFO, COMMENT,
INFO, SEQUENCE FILE: MHcurveUpTo100.seq


INFO, BACKGROUND DATA FILE:, None


STARTUPAXIS,X,8,LINEAR,AUTO,0.000000,0.000000
STARTUPAXIS,Y1,9,LINEAR,AUTO,0.000000,0.000000


STARTUPGROUP,Longitudinal
FIELDGROUP,Longitudinal,1,2,3,4,5,6,7,8,9,10,11,12,13,14,15,16,17,18,19,20,21,22
FIELDGROUP,Transverse,1,2,3,4,5,6,7,8,23,24,25,26,27,28,29,30,31,32,33,34,35,36

PLOT_APPEARANCE,ALL,HORZ_GRID_ON,VERT_GRID_ON,MARKERS_ONLY

[Data]
Time,Comment,Field (Oe),Start Temperature (K),End Temperature (K),Scan,Rejected,Position (cm),Long Voltage,Long Average Voltage,Long Detrended Voltage,Long Demeaned Voltage,Long Reg Fit,Long Detrended Fit,Long Demeaned Fit,Long Scaled Response,Long Avg. Scaled Response,Long Background Response,Long Response [w/ABS],Long Detrended Resp. [w/ABS],Long Fit [w/ABS],Long Detrended Fit [w/ABS],Trans Voltage,Trans Average Voltage,Trans Detrended Voltage,Trans Demeaned Voltage,Trans Reg Fit,Trans Detrended Fit,Trans Demeaned Fit,Trans Scaled Response,Trans Avg. Scaled Response,Trans Background Response,Trans Response [w/ABS],Trans Detrended Resp. [w/ABS],Trans Adjusted Fit,Trans Detrended Fit [w/ABS],
1406858067.531,,1.000000e+002,2.980050e+002,2.979968e+002,1,0,2.079996e+000,-1.434370e-002,-1.434370e-002,1.333059e+000,1.333059e+000,3.774364e-002,1.385146e+000,1.385146e+000,-6.251696e-007,-6.251696e-007,,,,,,,,,,,,,,,,,,,,
1406858067.531,,1.000000e+002,2.980050e+002,2.979968e+002,1,0,3.706144e+000,-1.872463e+000,-1.872463e+000,-6.118004e-001,-5.250605e-001,-1.866971e+000,-6.063080e-001,-5.195681e-001,-8.161124e-005,-8.161124e-005,,,,,,,,,,,,,,,,,,,,
1406858085.015,,1.000000e+002,2.980050e+002,2.979968e+002,1,0,4.365807e-001,-1.888943e+000,-1.888943e+000,-5.935805e-001,-5.495555e-001,-1.903094e+000,-6.077311e-001,-5.637062e-001,-8.232952e-005,-8.232952e-005,,,,,,,,,,,,,,,,,,,,
1406858103.500,,1.000000e+002,2.979968e+002,2.979885e+002,1,0,1.900351e+000,-2.380444e-002,-2.380444e-002,1.302105e+000,1.304099e+000,3.541465e-002,1.361324e+000,1.363318e+000,-1.037516e-006,-1.037516e-006,,,,,,,,,,,,,,,,,,,,
1406858103.500,,1.000000e+002,2.979968e+002,2.979885e+002,1,0,3.810447e+000,-1.874905e+000,-1.874905e+000,-6.347244e-001,-5.470012e-001,-1.816872e+000,-5.766917e-001,-4.889685e-001,-8.171765e-005,-8.171765e-005,,,,,,,,,,,,,,,,,,,,
1406858226.515,,7.500000e+001,2.979968e+002,2.979968e+002,1,0,5.568657e-001,-1.823481e+000,-1.823481e+000,-5.070280e-001,-4.694241e-001,-1.864775e+000,-5.483221e-001,-5.107182e-001,-7.947653e-005,-7.947653e-005,,,,,,,,,,,,,,,,,,,,
1406858244.750,,7.500000e+001,2.979968e+002,2.979885e+002,1,0,1.719428e+000,-2.237007e-001,-2.237007e-001,1.114487e+000,1.117867e+000,-2.085349e-001,1.129653e+000,1.133032e+000,-9.750008e-006,-9.750008e-006,,,,,,,,,,,,,,,,,,,,
1406858244.750,,7.500000e+001,2.979968e+002,2.979885e+002,1,0,3.894073e+000,-1.879177e+000,-1.879177e+000,-6.136445e-001,-5.376101e-001,-1.787954e+000,-5.224215e-001,-4.463871e-001,-8.190406e-005,-8.190406e-005,,,,,,,,,,,,,,,,,,,,
1406858262.984,,7.500000e+001,2.979968e+002,2.979968e+002,1,0,6.837345e-001,-1.699118e+000,-1.699118e+000,-4.021101e-001,-3.615030e-001,-1.754496e+000,-4.574882e-001,-4.168811e-001,-7.405617e-005,-7.405617e-005,,,,,,,,,,,,,,,,,,,,
1406858393.218,,5.000000e+001,2.979968e+002,2.980050e+002,1,0,1.539332e+000,-4.539628e-001,-4.539628e-001,8.222374e-001,8.267219e-001,-4.890088e-001,7.871914e-001,7.916759e-001,-1.978604e-005,-1.978604e-005,,,,,,,,,,,,,,,,,,,,
1406858393.218,,5.000000e+001,2.979968e+002,2.980050e+002,1,0,3.953985e+000,-1.782128e+000,-1.782128e+000,-5.702063e-001,-5.014436e-001,-1.673679e+000,-4.617571e-001,-3.929944e-001,-7.767435e-005,-7.767435e-005,,,,,,,,,,,,,,,,,,,,
1406858410.953,,5.000000e+001,2.980050e+002,2.980050e+002,1,0,8.162675e-001,-1.467177e+000,-1.467177e+000,-2.395273e-001,-2.016314e-001,-1.526494e+000,-2.988437e-001,-2.609478e-001,-6.394716e-005,-6.394716e-005,,,,,,,,,,,,,,,,,,,,
1406858429.203,,5.000000e+001,2.979968e+002,2.980050e+002,1,0,1.361726e+000,-6.746116e-001,-6.746116e-001,5.644192e-001,5.705424e-001,-7.459725e-001,4.930583e-001,4.991815e-001,-2.940306e-005,-2.940306e-005,,,,,,,,,,,,,,,,,,,,
1406858429.203,,5.000000e+001,2.979968e+002,2.980050e+002,1,0,3.987966e+000,-1.740165e+000,-1.740165e+000,-5.669596e-001,-4.950113e-001,-1.617512e+000,-4.443067e-001,-3.723584e-001,-7.584539e-005,-7.584539e-005,,,,,,,,,,,,,,,,,,,,
1406858541.187,,4.500000e+001,2.979968e+002,2.979968e+002,1,0,9.545235e-001,-1.273690e+000,-1.273690e+000,-5.583748e-002,-1.888037e-002,-1.343502e+000,-1.256497e-001,-8.869255e-002,-5.551401e-005,-5.551401e-005,,,,,,,,,,,,,,,,,,,,
1406858559.171,,4.500000e+001,2.979968e+002,2.979968e+002,1,0,1.187695e+000,-9.292886e-001,-9.292886e-001,2.954332e-001,3.026894e-001,-1.016966e+000,2.077562e-001,2.150124e-001,-4.050321e-005,-4.050321e-005,,,,,,,,,,,,,,,,,,,,
1406858559.171,,4.500000e+001,2.979968e+002,2.979968e+002,1,0,3.994900e+000,-1.716971e+000,-1.716971e+000,-5.546533e-001,-4.849933e-001,-1.594569e+000,-4.322508e-001,-3.625908e-001,-7.483450e-005,-7.483450e-005,,,,,,,,,,,,,,,,,,,,
1406858577.406,,4.500000e+001,2.979968e+002,2.979968e+002,1,0,1.098753e+000,-1.031526e+000,-1.031526e+000,1.518529e-001,1.925309e-001,-1.108241e+000,7.513741e-002,1.158154e-001,-4.495923e-005,-4.495923e-005,,,,,,,,,,,,,,,,,,,,
1406858694.703,,4.000000e+001,2.979968e+002,2.979968e+002,1,0,1.018433e+000,-1.156194e+000,-1.156194e+000,4.628114e-002,5.461371e-002,-1.242907e+000,-4.043217e-002,-3.209960e-002,-5.039294e-005,-5.039294e-005,,,,,,,,,,,,,,,,,,,,
1406858694.703,,4.000000e+001,2.979968e+002,2.979968e+002,1,0,3.975082e+000,-1.687216e+000,-1.687216e+000,-5.444577e-001,-4.764084e-001,-1.574755e+000,-4.319967e-001,-3.639474e-001,-7.353764e-005,-7.353764e-005,,,,,,,,,,,,,,,,,,,,
1406858712.937,,4.000000e+001,2.979968e+002,2.980050e+002,1,0,1.249878e+000,-8.098087e-001,-8.098087e-001,3.669116e-001,4.036466e-001,-8.817869e-001,2.949333e-001,3.316684e-001,-3.529567e-005,-3.529567e-005,,,,,,,,,,,,,,,,,,,,
1406858730.218,,4.000000e+001,2.980050e+002,2.979968e+002,1,0,8.556263e-001,-1.349529e+000,-1.349528e+000,-1.618818e-001,-1.519022e-001,-1.431747e+000,-2.441004e-001,-2.341208e-001,-5.881947e-005,-5.881947e-005,,,,,,,,,,,,,,,,,,,,
1406858730.218,,4.000000e+001,2.980050e+002,2.979968e+002,1,0,3.930310e+000,-1.678671e+000,-1.678671e+000,-5.523271e-001,-4.810444e-001,-1.579319e+000,-4.529756e-001,-3.816929e-001,-7.316520e-005,-7.316520e-005,,,,,,,,,,,,,,,,,,,,
1406858848.203,,3.500000e+001,2.980050e+002,2.979968e+002,1,0,1.408234e+000,-5.580309e-001,-5.580310e-001,5.810682e-001,6.206074e-001,-6.153385e-001,5.237606e-001,5.632998e-001,-2.432190e-005,-2.432190e-005,,,,,,,,,,,,,,,,,,,,
1406858866.437,,3.500000e+001,2.979968e+002,2.980050e+002,1,0,6.999142e-001,-1.469314e+000,-1.469314e+000,-3.163036e-001,-3.052099e-001,-1.541763e+000,-3.887526e-001,-3.776590e-001,-6.404036e-005,-6.404036e-005,,,,,,,,,,,,,,,,,,,,
1406858866.437,,3.500000e+001,2.979968e+002,2.980050e+002,1,0,3.863285e+000,-1.637471e+000,-1.637471e+000,-5.440891e-001,-4.733669e-001,-1.561755e+000,-4.683731e-001,-3.976510e-001,-7.136952e-005,-7.136952e-005,,,,,,,,,,,,,,,,,,,,
1406858884.734,,3.500000e+001,2.979968e+002,2.979968e+002,1,0,1.573527e+000,-3.225806e-001,-3.225806e-001,7.948655e-001,8.376350e-001,-3.426437e-001,7.748024e-001,8.175719e-001,-1.405975e-005,-1.405975e-005,,,,,,,,,,,,,,,,,,,,
1406859002.968,,3.000000e+001,2.979968e+002,2.979968e+002,1,0,5.528750e-001,-1.516923e+000,-1.516922e+000,-4.075629e-001,-3.954418e-001,-1.572828e+000,-4.634682e-001,-4.513471e-001,-6.611543e-005,-6.611543e-005,,,,,,,,,,,,,,,,,,,,
1406859002.968,,3.000000e+001,2.979968e+002,2.979968e+002,1,0,3.777544e+000,-1.575976e+000,-1.575976e+000,-5.245281e-001,-4.544951e-001,-1.530351e+000,-4.789033e-001,-4.088702e-001,-6.868929e-005,-6.868929e-005,,,,,,,,,,,,,,,,,,,,
1406859021.203,,3.000000e+001,2.979968e+002,2.980050e+002,1,0,1.745195e+000,-1.477096e-001,-1.477096e-001,9.295491e-001,9.715061e-001,-1.115108e-001,9.657480e-001,1.007705e+000,-6.437958e-006,-6.437958e-006,,,,,,,,,,,,,,,,,,,,
1406859039.453,,3.000000e+001,2.980050e+002,2.979968e+002,1,0,4.172981e-001,-1.549577e+000,-1.549577e+000,-4.651337e-001,-4.513731e-001,-1.579309e+000,-4.948654e-001,-4.811049e-001,-6.753871e-005,-6.753871e-005,,,,,,,,,,,,,,,,,,,,
1406859039.453,,3.000000e+001,2.980050e+002,2.979968e+002,1,0,3.677063e+000,-1.530351e+000,-1.530351e+000,-5.050774e-001,-4.321464e-001,-1.520135e+000,-4.948613e-001,-4.219303e-001,-6.670070e-005,-6.670070e-005,,,,,,,,,,,,,,,,,,,,
1406859157.500,,2.500000e+001,2.979968e+002,2.979968e+002,1,0,1.921807e+000,-4.852443e-002,-4.852443e-002,9.812602e-001,1.022896e+000,2.717495e-002,1.056960e+000,1.098595e+000,-2.114950e-006,-2.114950e-006,,,,,,,,,,,,,,,,,,,,
1406859176.234,,2.500000e+001,2.979968e+002,2.980132e+002,1,0,2.955402e-001,-1.518296e+000,-1.518296e+000,-4.666416e-001,-4.525393e-001,-1.513699e+000,-4.620445e-001,-4.479423e-001,-6.617532e-005,-6.617532e-005,,,,,,,,,,,,,,,,,,,,
1406859176.234,,2.500000e+001,2.979968e+002,2.980132e+002,1,0,3.565121e+000,-1.435285e+000,-1.435285e+000,-4.387583e-001,-3.695289e-001,-1.459577e+000,-4.630495e-001,-3.938202e-001,-6.255729e-005,-6.255729e-005,,,,,,,,,,,,,,,,,,,,
1406859193.500,,2.500000e+001,2.979968e+002,2.979968e+002,1,0,2.101557e+000,-3.051851e-002,-3.051851e-002,9.776216e-001,1.022603e+000,5.673456e-002,1.064875e+000,1.109856e+000,-1.330157e-006,-1.330157e-006,,,,,,,,,,,,,,,,,,,,
1406859310.046,,2.000000e+001,2.979968e+002,2.979968e+002,1,0,1.913359e-001,-1.440626e+000,-1.440626e+000,-4.426638e-001,-4.281744e-001,-1.404625e+000,-4.066622e-001,-3.921728e-001,-6.279010e-005,-6.279010e-005,,,,,,,,,,,,,,,,,,,,
1406859310.046,,2.000000e+001,2.979968e+002,2.979968e+002,1,0,3.444911e+000,-1.291696e+000,-1.291696e+000,-3.456537e-001,-2.792441e-001,-1.339497e+000,-3.934552e-001,-3.270456e-001,-5.629893e-005,-5.629893e-005,,,,,,,,,,,,,,,,,,,,
1406859328.296,,2.000000e+001,2.980050e+002,2.979885e+002,1,0,2.282632e+000,-1.292459e-001,-1.292459e-001,8.331066e-001,8.750391e-001,-7.721017e-002,8.851423e-001,9.270748e-001,-5.633219e-006,-5.633219e-006,,,,,,,,,,,,,,,,,,,,
1406859347.109,,2.000000e+001,2.979968e+002,2.980050e+002,1,0,1.077097e-001,-1.402478e+000,-1.402478e+000,-4.388122e-001,-4.216949e-001,-1.338994e+000,-3.753282e-001,-3.582108e-001,-6.112741e-005,-6.112741e-005,,,,,,,,,,,,,,,,,,,,
1406859347.109,,2.000000e+001,2.979968e+002,2.980050e+002,1,0,3.317963e+000,-1.156194e+000,-1.156194e+000,-2.491468e-001,-1.754105e-001,-1.220421e+000,-3.133741e-001,-2.396379e-001,-5.039303e-005,-5.039303e-005,,,,,,,,,,,,,,,,,,,,
1406859457.093,,1.500000e+001,2.980050e+002,2.979968e+002,1,0,2.462573e+000,-2.587970e-001,-2.587970e-001,6.355075e-001,6.775130e-001,-2.585650e-001,6.357394e-001,6.777449e-001,-1.127974e-005,-1.127974e-005,,,,,,,,,,,,,,,,,,,,
1406859475.328,,1.500000e+001,2.979968e+002,2.979968e+002,1,0,4.779058e-002,-1.300394e+000,-1.300394e+000,-4.014224e-001,-3.852018e-001,-1.221073e+000,-3.221012e-001,-3.058807e-001,-5.667805e-005,-5.667805e-005,,,,,,,,,,,,,,,,,,,,
1406859475.328,,1.500000e+001,2.979968e+002,2.979968e+002,1,0,3.185423e+000,-9.537035e-001,-9.537034e-001,-1.045522e-001,-3.851151e-002,-1.028586e+000,-1.794350e-001,-1.133943e-001,-4.156745e-005,-4.156745e-005,,,,,,,,,,,,,,,,,,,,
1406859493.062,,1.500000e+001,2.979968e+002,2.980050e+002,1,0,2.640247e+000,-4.014710e-001,-4.014710e-001,4.683692e-001,5.130767e-001,-4.499534e-001,4.198868e-001,4.645942e-001,-1.749823e-005,-1.749823e-005,,,,,,,,,,,,,,,,,,,,
1406859609.562,,1.000000e+001,2.979968e+002,2.979968e+002,1,0,1.384097e-002,-1.167791e+000,-1.167791e+000,-3.590560e-001,-3.416584e-001,-1.081130e+000,-2.723954e-001,-2.549977e-001,-5.089854e-005,-5.089854e-005,,,,,,,,,,,,,,,,,,,,
1406859609.562,,1.000000e+001,2.979968e+002,2.979968e+002,1,0,3.047364e+000,-7.177953e-001,-7.177954e-001,4.106601e-002,1.083370e-001,-7.920457e-001,-3.318428e-002,3.408676e-002,-3.128534e-005,-3.128534e-005,,,,,,,,,,,,,,,,,,,,
1406859627.296,,1.000000e+001,2.980050e+002,2.979968e+002,1,0,2.813985e+000,-4.846339e-001,-4.846339e-001,2.729380e-001,3.163180e-001,-5.605606e-001,1.970112e-001,2.403913e-001,-2.112293e-005,-2.112293e-005,,,,,,,,,,,,,,,,,,,,
1406859645.296,,1.000000e+001,2.980050e+002,2.979968e+002,1,0,6.953729e-003,-1.124760e+000,-1.124760e+000,-3.571065e-001,-3.376537e-001,-1.035964e+000,-2.683104e-001,-2.488576e-001,-4.902302e-005,-4.902302e-005,,,,,,,,,,,,,,,,,,,,
1406859645.296,,1.000000e+001,2.980050e+002,2.979968e+002,1,0,2.903090e+000,-5.407880e-001,-5.407880e-001,1.745857e-001,2.463180e-001,-6.093667e-001,1.060069e-001,1.777393e-001,-2.357042e-005,-2.357042e-005,,,,,,,,,,,,,,,,,,,,
1406859763.031,,5.000000e+000,2.979968e+002,2.980050e+002,1,0,2.983075e+000,-5.178991e-001,-5.178991e-001,1.178564e-001,1.589506e-001,-5.994442e-001,3.631131e-002,7.740557e-002,-2.257281e-005,-2.257281e-005,,,,,,,,,,,,,,,,,,,,
1406859780.765,,5.000000e+000,2.980050e+002,2.980050e+002,1,0,2.666482e-002,-9.521775e-001,-9.521775e-001,-3.036536e-001,-2.855950e-001,-8.703167e-001,-2.217928e-001,-2.037342e-001,-4.150099e-005,-4.150099e-005,,,,,,,,,,,,,,,,,,,,
1406859780.765,,5.000000e+000,2.980050e+002,2.980050e+002,1,0,2.751921e+000,-3.238014e-001,-3.238014e-001,2.790450e-001,3.427811e-001,-3.710151e-001,2.318313e-001,2.955675e-001,-1.411299e-005,-1.411299e-005,,,,,,,,,,,,,,,,,,,,
1406859798.500,,5.000000e+000,2.980050e+002,2.979968e+002,1,0,3.146174e+000,-5.887021e-001,-5.887020e-001,-2.457209e-003,4.150361e-002,-6.711195e-001,-8.487470e-002,-4.091388e-002,-2.565878e-005,-2.565878e-005,,,,,,,,,,,,,,,,,,,,
1406859915.234,,0.000000e+000,2.979968e+002,2.979968e+002,1,0,7.151778e-002,-5.955687e-001,-5.955687e-001,-2.036390e-001,-1.879909e-001,-5.274972e-001,-1.355675e-001,-1.199194e-001,-2.595808e-005,-2.595808e-005,,,,,,,,,,,,,,,,,,,,
1406859915.234,,0.000000e+000,2.979968e+002,2.979968e+002,1,0,2.593713e+000,-8.056886e-002,-8.056886e-002,2.739792e-001,3.270090e-001,-8.678110e-002,2.677670e-001,3.207967e-001,-3.511623e-006,-3.511623e-006,,,,,,,,,,,,,,,,,,,,
1406859933.484,,0.000000e+000,2.979968e+002,2.979968e+002,1,0,3.301924e+000,-3.570666e-001,-3.570666e-001,-2.373606e-002,1.097798e-002,-4.198032e-001,-8.647267e-002,-5.175862e-002,-1.556287e-005,-1.556287e-005,,,,,,,,,,,,,,,,,,,,
1406859951.218,,0.000000e+000,2.979968e+002,2.979968e+002,1,0,1.384762e-001,-5.156102e-001,-5.156102e-001,-1.919115e-001,-1.749819e-001,-4.587619e-001,-1.350631e-001,-1.181335e-001,-2.247306e-005,-2.247306e-005,,,,,,,,,,,,,,,,,,,,
1406859951.218,,0.000000e+000,2.979968e+002,2.979968e+002,1,0,2.428305e+000,1.297037e-002,1.297037e-002,2.983547e-001,3.535987e-001,4.796746e-002,3.333518e-001,3.885958e-001,5.653181e-007,5.653181e-007,,,,,,,,,,,,,,,,,,,,
1406860084.000,,-5.000000e+000,2.979968e+002,2.979968e+002,1,0,3.448640e+000,5.647450e-001,5.647450e-001,2.068626e-001,2.872835e-001,4.630258e-001,1.051433e-001,1.855642e-001,1.230730e-005,1.230730e-005,,,,,,,,,,,,,,,,,,,,
1406860101.734,,-5.000000e+000,2.980050e+002,2.979968e+002,1,0,2.240708e-001,4.347362e-001,4.347362e-001,6.096318e-002,1.034294e-001,4.945222e-001,1.207492e-001,1.632154e-001,9.474063e-006,9.474063e-006,,,,,,,,,,,,,,,,,,,,
1406860101.734,,-5.000000e+000,2.980050e+002,2.979968e+002,1,0,2.256750e+000,1.782281e-001,1.782281e-001,-2.868473e-001,-1.530786e-001,3.037160e-001,-1.613594e-001,-2.759069e-002,3.884066e-006,3.884066e-006,,,,,,,,,,,,,,,,,,,,
1406860119.968,,-5.000000e+000,2.979968e+002,2.979968e+002,1,0,3.584404e+000,6.173894e-001,6.173894e-001,1.742789e-001,2.615143e-001,5.717521e-001,1.286416e-001,2.158770e-001,1.345457e-005,1.345457e-005,,,,,,,,,,,,,,,,,,,,
1406860243.218,,-1.000000e+001,2.980050e+002,2.979968e+002,1,0,3.245898e-001,1.550645e+000,1.550645e+000,4.182568e-001,4.536902e-001,1.578974e+000,4.465850e-001,4.820184e-001,3.379269e-005,3.379269e-005,,,,,,,,,,,,,,,,,,,,
1406860261.015,,-1.000000e+001,2.979968e+002,2.980050e+002,1,0,2.080279e+000,8.301035e-002,8.301035e-002,-1.058453e+000,-1.058453e+000,1.256705e-001,-1.015793e+000,-1.015793e+000,1.809016e-006,1.809016e-006,,,,,,,,,,,,,,,,,,,,
1406860261.015,,-1.000000e+001,2.979968e+002,2.980050e+002,1,0,3.706065e+000,1.652883e+000,1.652882e+000,4.395051e-001,5.114187e-001,1.658275e+000,4.448975e-001,5.168111e-001,3.602071e-005,3.602071e-005,,,,,,,,,,,,,,,,,,,,
1406860279.000,,-1.000000e+001,2.980050e+002,2.979968e+002,1,0,4.364111e-001,1.686605e+000,1.686605e+000,4.673319e-001,5.051907e-001,1.675202e+000,4.559284e-001,4.937873e-001,3.675562e-005,3.675562e-005,,,,,,,,,,,,,,,,,,,,
1406860389.812,,-1.500000e+001,2.979968e+002,2.979968e+002,1,0,1.900353e+000,9.857479e-002,9.857479e-002,-1.420421e+000,-1.418951e+000,1.367586e-001,-1.382237e+000,-1.380767e+000,2.148206e-006,2.148206e-006,,,,,,,,,,,,,,,,,,,,
1406860389.812,,-1.500000e+001,2.979968e+002,2.979968e+002,1,0,3.810384e+000,2.101199e+000,2.101199e+000,5.190098e-001,5.836737e-001,2.144646e+000,5.624561e-001,6.271200e-001,4.579070e-005,4.579070e-005,,,,,,,,,,,,,,,,,,,,
1406860408.796,,-1.500000e+001,2.980050e+002,2.979968e+002,1,0,5.567757e-001,2.188330e+000,2.188330e+000,5.945883e-001,6.297952e-001,2.145646e+000,5.519042e-001,5.871111e-001,4.768951e-005,4.768951e-005,,,,,,,,,,,,,,,,,,,,
1406860426.031,,-1.500000e+001,2.979968e+002,2.979968e+002,1,0,1.719346e+000,3.448592e-001,3.448592e-001,-1.252445e+000,-1.249280e+000,3.604223e-001,-1.236882e+000,-1.233717e+000,7.515395e-006,7.515395e-006,,,,,,,,,,,,,,,,,,,,
1406860426.031,,-1.500000e+001,2.979968e+002,2.979968e+002,1,0,3.893978e+000,2.124851e+000,2.124851e+000,4.595020e-001,5.307122e-001,2.197433e+000,5.320833e-001,6.032935e-001,4.630614e-005,4.630614e-005,,,,,,,,,,,,,,,,,,,,
1406860543.531,,-2.000000e+001,2.979885e+002,2.980050e+002,1,0,6.835181e-001,2.409284e+000,2.409284e+000,5.925770e-001,6.290585e-001,2.343319e+000,5.266123e-001,5.630938e-001,5.250466e-005,5.250466e-005,,,,,,,,,,,,,,,,,,,,
1406860561.515,,-2.000000e+001,2.980050e+002,2.979968e+002,1,0,1.539534e+000,7.702872e-001,7.702872e-001,-1.041530e+000,-1.036925e+000,7.569375e-001,-1.054880e+000,-1.050275e+000,1.678659e-005,1.678659e-005,,,,,,,,,,,,,,,,,,,,
1406860561.515,,-2.000000e+001,2.980050e+002,2.979968e+002,1,0,3.953994e+000,2.375561e+000,2.375561e+000,4.977398e-001,5.683483e-001,2.457786e+000,5.799651e-001,6.505736e-001,5.176974e-005,5.176974e-005,,,,,,,,,,,,,,,,,,,,
1406860579.578,,-2.000000e+001,2.979968e+002,2.979968e+002,1,0,8.161939e-001,2.318491e+000,2.318491e+000,4.444050e-001,4.799984e-001,2.230420e+000,3.563334e-001,3.919268e-001,5.052605e-005,5.052605e-005,,,,,,,,,,,,,,,,,,,,
1406860697.562,,-2.500000e+001,2.980050e+002,2.979968e+002,1,0,1.361753e+000,1.407819e+000,1.407819e+000,-6.681512e-001,-6.616189e-001,1.358517e+000,-7.174533e-001,-7.109210e-001,3.068008e-005,3.068008e-005,,,,,,,,,,,,,,,,,,,,
1406860697.562,,-2.500000e+001,2.980050e+002,2.979968e+002,1,0,3.987927e+000,2.707602e+000,2.707602e+000,5.614103e-001,6.381645e-001,2.781128e+000,6.349362e-001,7.116904e-001,5.900578e-005,5.900578e-005,,,,,,,,,,,,,,,,,,,,
1406860715.796,,-2.500000e+001,2.979968e+002,2.980050e+002,1,0,9.543568e-001,2.400586e+000,2.400586e+000,2.676406e-001,3.077095e-001,2.311699e+000,1.787539e-001,2.188227e-001,5.231508e-005,5.231508e-005,,,,,,,,,,,,,,,,,,,,
1406860734.078,,-2.500000e+001,2.979968e+002,2.980050e+002,1,0,1.187551e+000,1.921293e+000,1.921293e+000,-2.304947e-001,-2.229595e-001,1.837665e+000,-3.141224e-001,-3.065872e-001,4.187003e-005,4.187003e-005,,,,,,,,,,,,,,,,,,,,
1406860734.078,,-2.500000e+001,2.979968e+002,2.980050e+002,1,0,3.994808e+000,2.781762e+000,2.781762e+000,5.651723e-001,6.375098e-001,2.856941e+000,6.403506e-001,7.126882e-001,6.062192e-005,6.062192e-005,,,,,,,,,,,,,,,,,,,,
1406860845.359,,-3.000000e+001,2.979968e+002,2.979968e+002,1,0,1.098760e+000,2.367321e+000,2.367321e+000,-2.552594e-002,2.237773e-002,2.296092e+000,-9.675492e-002,-4.885125e-002,5.159013e-005,5.159013e-005,,,,,,,,,,,,,,,,,,,,
1406860862.609,,-3.000000e+001,2.979968e+002,2.979968e+002,1,0,1.018775e+000,2.537156e+000,2.537156e+000,1.753732e-001,1.856911e-001,2.449105e+000,8.732164e-002,9.763956e-002,5.529129e-005,5.529129e-005,,,,,,,,,,,,,,,,,,,,
1406860862.609,,-3.000000e+001,2.979968e+002,2.979968e+002,1,0,3.975134e+000,3.098697e+000,3.098697e+000,6.629687e-001,7.472317e-001,3.159993e+000,7.242652e-001,8.085282e-001,6.752873e-005,6.752873e-005,,,,,,,,,,,,,,,,,,,,
1406860880.093,,-3.000000e+001,2.979968e+002,2.979968e+002,1,0,1.249865e+000,1.990722e+000,1.990722e+000,-4.298767e-001,-3.809276e-001,1.956344e+000,-4.642556e-001,-4.153064e-001,4.338306e-005,4.338306e-005,,,,,,,,,,,,,,,,,,,,
1406860996.515,,-3.500000e+001,2.979968e+002,2.980050e+002,1,0,8.558574e-001,3.079012e+000,3.079012e+000,5.172758e-001,5.329072e-001,3.002002e+000,4.402654e-001,4.558969e-001,6.709972e-005,6.709972e-005,,,,,,,,,,,,,,,,,,,,
1406860996.515,,-3.500000e+001,2.979968e+002,2.980050e+002,1,0,3.930348e+000,3.394727e+000,3.394727e+000,7.369683e-001,8.486214e-001,3.440700e+000,7.829421e-001,8.945951e-001,7.397995e-005,7.397995e-005,,,,,,,,,,,,,,,,,,,,
1406861014.375,,-3.500000e+001,2.980050e+002,2.980050e+002,1,0,1.408097e+000,1.744133e+000,1.744133e+000,-9.125681e-001,-8.467371e-001,1.765092e+000,-8.916085e-001,-8.257775e-001,3.800921e-005,3.800921e-005,,,,,,,,,,,,,,,,,,,,
1406861032.859,,-3.500000e+001,2.979968e+002,2.979968e+002,1,0,7.001035e-001,3.371837e+000,3.371838e+000,7.528250e-001,7.706876e-001,3.318772e+000,6.997589e-001,7.176216e-001,7.348114e-005,7.348114e-005,,,,,,,,,,,,,,,,,,,,
1406861032.859,,-3.500000e+001,2.979968e+002,2.979968e+002,1,0,3.863338e+000,3.513138e+000,3.513138e+000,7.981141e-001,9.119883e-001,3.547110e+000,8.320861e-001,9.459603e-001,7.656046e-005,7.656046e-005,,,,,,,,,,,,,,,,,,,,
1406861150.359,,-4.000000e+001,2.979968e+002,2.979968e+002,1,0,1.573429e+000,1.400494e+000,1.400494e+000,-1.423663e+000,-1.333139e+000,1.465069e+000,-1.359089e+000,-1.268565e+000,3.052042e-005,3.052042e-005,,,,,,,,,,,,,,,,,,,,
1406861167.640,,-4.000000e+001,2.979968e+002,2.979968e+002,1,0,5.530671e-001,3.667867e+000,3.667867e+000,8.920286e-001,9.186537e-001,3.649708e+000,8.738694e-001,9.004946e-001,7.993236e-005,7.993236e-005,,,,,,,,,,,,,,,,,,,,
1406861167.640,,-4.000000e+001,2.979968e+002,2.979968e+002,1,0,3.777631e+000,3.789483e+000,3.789483e+000,8.864358e-001,1.040270e+000,3.802654e+000,8.996060e-001,1.053440e+000,8.258269e-005,8.258269e-005,,,,,,,,,,,,,,,,,,,,
1406861186.125,,-4.000000e+001,2.980050e+002,2.979968e+002,1,0,1.745060e+000,9.869686e-001,9.869686e-001,-1.844714e+000,-1.753264e+000,1.049952e+000,-1.781730e+000,-1.690280e+000,2.150861e-005,2.150861e-005,,,,,,,,,,,,,,,,,,,,
1406861320.609,,-4.500000e+001,2.979968e+002,2.979968e+002,1,0,4.173110e-001,1.978515e+000,1.978515e+000,4.695329e-001,4.885663e-001,1.980283e+000,4.713009e-001,4.903343e-001,8.623394e-005,8.623394e-005,,,,,,,,,,,,,,,,,,,,
1406861320.609,,-4.500000e+001,2.979968e+002,2.979968e+002,1,0,3.677086e+000,2.058168e+000,2.058168e+000,4.673425e-001,5.682195e-001,2.062115e+000,4.712895e-001,5.721666e-001,8.970564e-005,8.970564e-005,,,,,,,,,,,,,,,,,,,,
1406861337.843,,-4.500000e+001,2.979968e+002,2.980050e+002,1,0,1.921705e+000,4.826503e-001,4.826502e-001,-1.059198e+000,-9.994684e-001,4.926086e-001,-1.049240e+000,-9.895100e-001,2.103640e-005,2.103640e-005,,,,,,,,,,,,,,,,,,,,
1406861355.578,,-4.500000e+001,2.980050e+002,2.979968e+002,1,0,2.956547e-001,1.958068e+000,1.958068e+000,4.520826e-001,4.722599e-001,1.965508e+000,4.595226e-001,4.796999e-001,8.534273e-005,8.534273e-005,,,,,,,,,,,,,,,,,,,,
1406861355.578,,-4.500000e+001,2.980050e+002,2.979968e+002,1,0,3.565268e+000,2.048555e+000,2.048555e+000,4.636951e-001,5.627472e-001,2.045238e+000,4.603787e-001,5.594308e-001,8.928664e-005,8.928664e-005,,,,,,,,,,,,,,,,,,,,
1406861471.828,,-5.000000e+001,2.979968e+002,2.979968e+002,1,0,2.101435e+000,6.761376e-001,6.761376e-001,-1.071802e+000,-9.855294e-001,6.628964e-001,-1.085043e+000,-9.987706e-001,2.946957e-005,2.946957e-005,,,,,,,,,,,,,,,,,,,,
1406861489.812,,-5.000000e+001,2.979968e+002,2.980050e+002,1,0,1.913620e-001,2.109287e+000,2.109287e+000,4.209745e-001,4.517136e-001,2.123771e+000,4.354585e-001,4.661975e-001,9.193360e-005,9.193360e-005,,,,,,,,,,,,,,,,,,,,
1406861489.812,,-5.000000e+001,2.979968e+002,2.980050e+002,1,0,3.445029e+000,2.226936e+000,2.226936e+000,4.284752e-001,5.693624e-001,2.218193e+000,4.197324e-001,5.606196e-001,9.706135e-005,9.706135e-005,,,,,,,,,,,,,,,,,,,,
1406861508.296,,-5.000000e+001,2.979968e+002,2.979968e+002,1,0,2.282369e+000,7.985168e-001,7.985168e-001,-9.429225e-001,-8.577570e-001,7.765034e-001,-9.649359e-001,-8.797704e-001,3.480348e-005,3.480348e-005,,,,,,,,,,,,,,,,,,,,
1406861660.515,,-7.500000e+001,2.979968e+002,2.979968e+002,1,0,1.077015e-001,1.762291e+000,1.762291e+000,1.655218e-001,2.327524e-001,1.765556e+000,1.687866e-001,2.360172e-001,1.920239e-004,1.920239e-004,,,,,,,,,,,,,,,,,,,,
1406861660.515,,-7.500000e+001,2.979968e+002,2.979968e+002,1,0,3.318112e+000,1.958373e+000,1.958373e+000,1.392248e-001,4.288338e-001,1.957933e+000,1.387854e-001,4.283944e-001,2.133895e-004,2.133895e-004,,,,,,,,,,,,,,,,,,,,
1406861678.250,,-7.500000e+001,2.979968e+002,2.979968e+002,1,0,2.462561e+000,1.324656e+000,1.324656e+000,-3.083633e-001,-1.387478e-001,1.316331e+000,-3.166887e-001,-1.470731e-001,1.443380e-004,1.443380e-004,,,,,,,,,,,,,,,,,,,,
1406861695.984,,-7.500000e+001,2.979968e+002,2.980050e+002,1,0,4.779626e-002,1.666311e+000,1.666311e+000,1.541597e-001,2.215326e-001,1.669846e+000,1.576954e-001,2.250682e-001,1.815656e-004,1.815656e-004,,,,,,,,,,,,,,,,,,,,
1406861695.984,,-7.500000e+001,2.979968e+002,2.980050e+002,1,0,3.185531e+000,1.804559e+000,1.804559e+000,8.547762e-002,3.597814e-001,1.804828e+000,8.574644e-002,3.600502e-001,1.966296e-004,1.966296e-004,,,,,,,,,,,,,,,,,,,,
1406861848.640,,-1.000000e+002,2.980132e+002,2.979968e+002,1,0,2.640281e+000,1.254463e+000,1.254463e+000,-5.464744e-002,7.721484e-002,1.254726e+000,-5.438494e-002,7.747734e-002,5.467574e-004,5.467574e-004,,,,,,,,,,,,,,,,,,,,
1406861866.125,,-1.000000e+002,2.980050e+002,2.979968e+002,1,0,1.388039e-002,1.010620e+000,1.010620e+000,3.955258e-002,8.776510e-002,1.009985e+000,3.891732e-002,8.712983e-002,4.404785e-004,4.404785e-004,,,,,,,,,,,,,,,,,,,,
1406861866.125,,-1.000000e+002,2.980050e+002,2.979968e+002,1,0,3.047417e+000,1.112095e+000,1.112095e+000,2.817433e-003,1.892391e-001,1.114321e+000,5.044144e-003,1.914659e-001,4.847060e-004,4.847060e-004,,,,,,,,,,,,,,,,,,,,
1406861883.921,,-1.000000e+002,2.979968e+002,2.980050e+002,1,0,2.813942e+000,5.313272e-001,5.313272e-001,-2.953254e-002,7.553110e-002,5.328886e-001,-2.797120e-002,7.709244e-002,2.315788e-004,2.315788e-004,,,,,,,,,,,,,,,,,,,,
1406862022.953,,-7.500000e+001,2.979968e+002,2.979968e+002,1,0,6.876035e-003,2.090976e+000,2.090976e+000,3.751971e-001,4.086015e-001,2.094255e+000,3.784761e-001,4.118805e-001,9.113531e-005,9.113531e-005,,,,,,,,,,,,,,,,,,,,
1406862022.953,,-7.500000e+001,2.979968e+002,2.979968e+002,1,0,2.903050e+000,1.644185e+000,1.644185e+000,-1.613683e-001,-3.818953e-002,1.660215e+000,-1.453378e-001,-2.215898e-002,7.166189e-005,7.166189e-005,,,,,,,,,,,,,,,,,,,,
1406862041.203,,-7.500000e+001,2.979968e+002,2.980050e+002,1,0,2.982998e+000,1.738487e+000,1.738487e+000,-4.152638e-002,4.085648e-002,1.744992e+000,-3.502161e-002,4.736125e-002,7.577206e-005,7.577206e-005,,,,,,,,,,,,,,,,,,,,
1406862059.437,,-7.500000e+001,2.979968e+002,2.979968e+002,1,0,2.671667e-002,2.105319e+000,2.105319e+000,3.847775e-001,4.200392e-001,2.108717e+000,3.881750e-001,4.234366e-001,9.176048e-005,9.176048e-005,,,,,,,,,,,,,,,,,,,,
1406862059.437,,-7.500000e+001,2.979968e+002,2.979968e+002,1,0,2.752006e+000,1.423231e+000,1.423231e+000,-3.865025e-001,-2.620494e-001,1.445204e+000,-3.645295e-001,-2.400764e-001,6.203160e-005,6.203160e-005,,,,,,,,,,,,,,,,,,,,
1406862184.234,,-5.000000e+001,2.979968e+002,2.980050e+002,1,0,3.146114e+000,1.463515e+000,1.463515e+000,1.705490e-001,1.851392e-001,1.457210e+000,1.642442e-001,1.788343e-001,6.378754e-005,6.378754e-005,,,,,,,,,,,,,,,,,,,,
1406862201.500,,-5.000000e+001,2.979968e+002,2.979968e+002,1,0,7.150203e-002,1.668752e+000,1.668752e+000,3.823072e-001,3.883039e-001,1.681037e+000,3.945919e-001,4.005886e-001,7.273283e-005,7.273283e-005,,,,,,,,,,,,,,,,,,,,
1406862201.500,,-5.000000e+001,2.979968e+002,2.979968e+002,1,0,2.593787e+000,7.029939e-001,7.029939e-001,-5.977765e-001,-5.774543e-001,7.161938e-001,-5.845766e-001,-5.642544e-001,3.064010e-005,3.064010e-005,,,,,,,,,,,,,,,,,,,,
1406862219.937,,-5.000000e+001,2.979968e+002,2.980050e+002,1,0,3.301735e+000,1.625111e+000,1.625111e+000,3.297451e-001,3.449991e-001,1.618663e+000,3.232975e-001,3.385514e-001,7.083071e-005,7.083071e-005,,,,,,,,,,,,,,,,,,,,
1406862336.312,,-4.500000e+001,2.979968e+002,2.979968e+002,1,0,1.384516e-001,1.650136e+000,1.650136e+000,4.120056e-001,4.179465e-001,1.657465e+000,4.193347e-001,4.252756e-001,7.192147e-005,7.192147e-005,,,,,,,,,,,,,,,,,,,,
1406862336.312,,-4.500000e+001,2.979968e+002,2.979968e+002,1,0,2.428353e+000,4.348888e-001,4.348888e-001,-8.166866e-001,-7.973006e-001,4.401242e-001,-8.114511e-001,-7.920650e-001,1.895470e-005,1.895470e-005,,,,,,,,,,,,,,,,,,,,
1406862354.046,,-4.500000e+001,2.980050e+002,2.980050e+002,1,0,3.448710e+000,1.672872e+000,1.672872e+000,4.256541e-001,4.374881e-001,1.672963e+000,4.257454e-001,4.375794e-001,7.291244e-005,7.291244e-005,,,,,,,,,,,,,,,,,,,,
1406862372.031,,-4.500000e+001,2.979968e+002,2.980132e+002,1,0,2.240939e-001,1.706595e+000,1.706595e+000,4.488647e-001,4.550551e-001,1.709817e+000,4.520862e-001,4.582766e-001,7.438225e-005,7.438225e-005,,,,,,,,,,,,,,,,,,,,
1406862372.031,,-4.500000e+001,2.979968e+002,2.980132e+002,1,0,2.256739e+000,2.702414e-001,2.702414e-001,-1.000798e+000,-9.812986e-001,2.631977e-001,-1.007842e+000,-9.883423e-001,1.177852e-005,1.177852e-005,,,,,,,,,,,,,,,,,,,,
1406862489.265,,-4.000000e+001,2.980132e+002,2.979885e+002,1,0,3.584432e+000,1.676534e+000,1.676534e+000,4.683713e-001,4.805501e-001,1.679754e+000,4.715908e-001,4.837695e-001,7.307209e-005,7.307209e-005,,,,,,,,,,,,,,,,,,,,
1406862506.046,,-4.000000e+001,2.979968e+002,2.979968e+002,1,0,3.246684e-001,1.680502e+000,1.680502e+000,4.724146e-001,4.778748e-001,1.680552e+000,4.724647e-001,4.779248e-001,7.324501e-005,7.324501e-005,,,,,,,,,,,,,,,,,,,,
1406862523.578,,-4.000000e+001,2.979968e+002,2.980050e+002,1,0,2.080271e+000,1.036103e-001,1.036103e-001,-1.100537e+000,-1.100537e+000,1.095884e-001,-1.094559e+000,-1.094559e+000,4.515878e-006,4.515878e-006,,,,,,,,,,,,,,,,,,,,
1406862523.578,,-4.000000e+001,2.979968e+002,2.980050e+002,1,0,3.706050e+000,1.689505e+000,1.689505e+000,4.737273e-001,4.853575e-001,1.694899e+000,4.791220e-001,4.907522e-001,7.363740e-005,7.363740e-005,,,,,,,,,,,,,,,,,,,,
1406862639.328,,-3.500000e+001,2.980050e+002,2.979968e+002,1,0,4.364273e-001,1.645100e+000,1.645100e+000,4.782171e-001,4.825488e-001,1.640033e+000,4.731497e-001,4.774815e-001,7.170206e-005,7.170206e-005,,,,,,,,,,,,,,,,,,,,
1406862657.562,,-3.500000e+001,2.979968e+002,2.979968e+002,1,0,1.900284e+000,1.249733e-001,1.249733e-001,-1.049426e+000,-1.049255e+000,1.361207e-001,-1.038278e+000,-1.038107e+000,5.446989e-006,5.446989e-006,,,,,,,,,,,,,,,,,,,,
1406862657.562,,-3.500000e+001,2.979968e+002,2.979968e+002,1,0,3.810334e+000,1.627857e+000,1.627857e+000,4.461136e-001,4.536293e-001,1.636283e+000,4.545394e-001,4.620550e-001,7.095052e-005,7.095052e-005,,,,,,,,,,,,,,,,,,,,
1406862674.843,,-3.500000e+001,2.979968e+002,2.980050e+002,1,0,5.567569e-001,1.647389e+000,1.647389e+000,4.616950e-001,4.662355e-001,1.634795e+000,4.491006e-001,4.536412e-001,7.180182e-005,7.180182e-005,,,,,,,,,,,,,,,,,,,,
1406862791.578,,-3.000000e+001,2.979968e+002,2.979968e+002,1,0,1.719450e+000,2.624592e-001,2.624592e-001,-8.719865e-001,-8.717895e-001,2.772402e-001,-8.572055e-001,-8.570085e-001,1.143935e-005,1.143935e-005,,,,,,,,,,,,,,,,,,,,
1406862791.578,,-3.000000e+001,2.979968e+002,2.979968e+002,1,0,3.894015e+000,1.547899e+000,1.547899e+000,4.092157e-001,4.136502e-001,1.560302e+000,4.216186e-001,4.260530e-001,6.746555e-005,6.746555e-005,,,,,,,,,,,,,,,,,,,,
1406862809.859,,-3.000000e+001,2.979968e+002,2.979968e+002,1,0,6.835614e-001,1.578722e+000,1.578722e+000,4.024664e-001,4.058976e-001,1.555643e+000,3.793873e-001,3.828186e-001,6.880900e-005,6.880900e-005,,,,,,,,,,,,,,,,,,,,
1406862828.093,,-3.000000e+001,2.980050e+002,2.979968e+002,1,0,1.539437e+000,5.336161e-001,5.336161e-001,-6.332433e-001,-6.327304e-001,5.427333e-001,-6.241261e-001,-6.236133e-001,2.325779e-005,2.325779e-005,,,,,,,,,,,,,,,,,,,,
1406862828.093,,-3.000000e+001,2.980050e+002,2.979968e+002,1,0,3.953936e+000,1.558580e+000,1.558580e+000,3.843701e-001,3.922337e-001,1.572879e+000,3.986692e-001,4.065329e-001,6.793110e-005,6.793110e-005,,,,,,,,,,,,,,,,,,,,
1406862945.843,,-2.500000e+001,2.979968e+002,2.979968e+002,1,0,8.161590e-001,1.429182e+000,1.429182e+000,3.049345e-001,3.070414e-001,1.396008e+000,2.717609e-001,2.738677e-001,6.229126e-005,6.229126e-005,,,,,,,,,,,,,,,,,,,,
1406862964.078,,-2.500000e+001,2.979968e+002,2.979968e+002,1,0,1.361486e+000,7.649464e-001,7.649465e-001,-3.559617e-001,-3.552519e-001,7.521960e-001,-3.687122e-001,-3.680024e-001,3.334039e-005,3.334039e-005,,,,,,,,,,,,,,,,,,,,
1406862964.078,,-2.500000e+001,2.979968e+002,2.979968e+002,1,0,3.987875e+000,1.490829e+000,1.490829e+000,3.622912e-001,3.706309e-001,1.506475e+000,3.779368e-001,3.862765e-001,6.497818e-005,6.497818e-005,,,,,,,,,,,,,,,,,,,,
1406862982.375,,-2.500000e+001,2.979968e+002,2.980050e+002,1,0,9.544099e-001,1.311686e+000,1.311686e+000,1.717105e-001,1.758091e-001,1.275066e+000,1.350906e-001,1.391892e-001,5.717016e-005,5.717016e-005,,,,,,,,,,,,,,,,,,,,
1406863100.140,,-2.000000e+001,2.979885e+002,2.980050e+002,1,0,1.187446e+000,9.739982e-001,9.739982e-001,-1.042116e-001,-1.037330e-001,9.423773e-001,-1.358326e-001,-1.353540e-001,4.245199e-005,4.245199e-005,,,,,,,,,,,,,,,,,,,,
1406863100.140,,-2.000000e+001,2.979885e+002,2.980050e+002,1,0,3.994812e+000,1.429334e+000,1.429334e+000,3.470086e-001,3.516032e-001,1.449339e+000,3.670133e-001,3.716079e-001,6.229794e-005,6.229794e-005,,,,,,,,,,,,,,,,,,,,
1406863118.671,,-2.000000e+001,2.979968e+002,2.979968e+002,1,0,1.098785e+000,1.099124e+000,1.099124e+000,3.292526e-003,5.515337e-003,1.067271e+000,-2.856020e-002,-2.633739e-002,4.790564e-005,4.790564e-005,,,,,,,,,,,,,,,,,,,,
1406863136.921,,-2.000000e+001,2.980050e+002,2.980050e+002,1,0,1.018893e+000,1.196326e+000,1.196326e+000,9.957192e-002,1.003009e-001,1.160119e+000,6.336544e-002,6.409442e-002,5.214219e-005,5.214219e-005,,,,,,,,,,,,,,,,,,,,
1406863136.921,,-2.000000e+001,2.980050e+002,2.980050e+002,1,0,3.975141e+000,1.456801e+000,1.456801e+000,3.548230e-001,3.607764e-001,1.476912e+000,3.749340e-001,3.808874e-001,6.349508e-005,6.349508e-005,,,,,,,,,,,,,,,,,,,,
1406863248.921,,-1.500000e+001,2.979968e+002,2.979968e+002,1,0,1.249851e+000,8.502457e-001,8.502457e-001,-1.888149e-001,-1.873530e-001,8.328062e-001,-2.062543e-001,-2.047924e-001,3.705822e-005,3.705822e-005,,,,,,,,,,,,,,,,,,,,
1406863266.656,,-1.500000e+001,2.979968e+002,2.979968e+002,1,0,8.557174e-001,1.335337e+000,1.335337e+000,2.623154e-001,2.631643e-001,1.299527e+000,2.265048e-001,2.273537e-001,5.820108e-005,5.820108e-005,,,,,,,,,,,,,,,,,,,,
1406863266.656,,-1.500000e+001,2.979968e+002,2.979968e+002,1,0,3.930293e+000,1.439558e+000,1.439558e+000,3.613214e-001,3.673850e-001,1.460792e+000,3.825557e-001,3.886193e-001,6.274357e-005,6.274357e-005,,,,,,,,,,,,,,,,,,,,
1406863283.921,,-1.500000e+001,2.979968e+002,2.980050e+002,1,0,1.408092e+000,6.370739e-001,6.370739e-001,-4.161996e-001,-4.132725e-001,6.453962e-001,-4.078772e-001,-4.049501e-001,2.776706e-005,2.776706e-005,,,,,,,,,,,,,,,,,,,,
1406863401.218,,-1.000000e+001,2.980050e+002,2.980050e+002,1,0,6.998519e-001,1.357005e+000,1.357005e+000,3.628552e-001,3.633509e-001,1.330753e+000,3.366029e-001,3.370986e-001,5.914552e-005,5.914552e-005,,,,,,,,,,,,,,,,,,,,
1406863401.218,,-1.000000e+001,2.980050e+002,2.980050e+002,1,0,3.863270e+000,1.371502e+000,1.371502e+000,3.746871e-001,3.778472e-001,1.389008e+000,3.921930e-001,3.953531e-001,5.977735e-005,5.977735e-005,,,,,,,,,,,,,,,,,,,,
1406863418.953,,-1.000000e+001,2.979968e+002,2.980050e+002,1,0,1.573404e+000,3.883480e-001,3.883480e-001,-6.303366e-001,-6.271114e-001,4.197999e-001,-5.988848e-001,-5.956595e-001,1.692627e-005,1.692627e-005,,,,,,,,,,,,,,,,,,,,
1406863437.203,,-1.000000e+001,2.979968e+002,2.979968e+002,1,0,5.529463e-001,1.436201e+000,1.436201e+000,4.151213e-001,4.161247e-001,1.423141e+000,4.020610e-001,4.030644e-001,6.259729e-005,6.259729e-005,,,,,,,,,,,,,,,,,,,,
1406863437.203,,-1.000000e+001,2.979968e+002,2.979968e+002,1,0,3.777597e+000,1.428419e+000,1.428419e+000,4.025452e-001,4.083425e-001,1.437727e+000,4.118530e-001,4.176502e-001,6.225810e-005,6.225810e-005,,,,,,,,,,,,,,,,,,,,
1406863560.968,,-5.000000e+000,2.980050e+002,2.979968e+002,1,0,1.745067e+000,1.661733e-001,1.661733e-001,-7.931055e-001,-7.897173e-001,2.013586e-001,-7.579201e-001,-7.545320e-001,7.242720e-006,7.242720e-006,,,,,,,,,,,,,,,,,,,,
1406863579.265,,-5.000000e+000,2.979885e+002,2.980050e+002,1,0,4.174228e-001,1.384777e+000,1.384777e+000,4.061822e-001,4.073851e-001,1.381968e+000,4.033729e-001,4.045758e-001,6.035600e-005,6.035600e-005,,,,,,,,,,,,,,,,,,,,
1406863579.265,,-5.000000e+000,2.979885e+002,2.980050e+002,1,0,3.677158e+000,1.384167e+000,1.384167e+000,4.003995e-001,4.067746e-001,1.387143e+000,4.033759e-001,4.097510e-001,6.032940e-005,6.032940e-005,,,,,,,,,,,,,,,,,,,,
1406863597.500,,-5.000000e+000,2.979968e+002,2.980050e+002,1,0,1.921682e+000,7.217627e-002,7.217628e-002,-9.130082e-001,-9.095108e-001,9.540459e-002,-8.897799e-001,-8.862825e-001,3.145828e-006,3.145828e-006,,,,,,,,,,,,,,,,,,,,
1406863714.734,,0.000000e+000,2.979968e+002,2.979885e+002,1,0,2.957395e-001,1.275979e+000,1.275979e+000,3.616315e-001,3.630319e-001,1.283734e+000,3.693868e-001,3.707871e-001,5.561400e-005,5.561400e-005,,,,,,,,,,,,,,,,,,,,
1406863714.734,,0.000000e+000,2.979968e+002,2.979885e+002,1,0,3.565328e+000,1.297037e+000,1.297037e+000,3.772151e-001,3.840896e-001,1.289403e+000,3.695815e-001,3.764560e-001,5.653181e-005,5.653181e-005,,,,,,,,,,,,,,,,,,,,
1406863732.484,,0.000000e+000,2.980050e+002,2.980050e+002,1,0,2.101374e+000,3.814813e-002,3.814814e-002,-8.769783e-001,-8.716169e-001,4.450838e-002,-8.706181e-001,-8.652567e-001,1.662700e-006,1.662700e-006,,,,,,,,,,,,,,,,,,,,
1406863749.968,,0.000000e+000,2.980050e+002,2.980050e+002,1,0,1.913483e-001,1.239204e+000,1.239204e+000,3.205145e-001,3.223732e-001,1.260975e+000,3.422853e-001,3.441440e-001,5.401116e-005,5.401116e-005,,,,,,,,,,,,,,,,,,,,
1406863749.968,,0.000000e+000,2.980050e+002,2.980050e+002,1,0,3.444984e+000,1.272164e+000,1.272164e+000,3.468143e-001,3.553332e-001,1.252181e+000,3.268312e-001,3.353500e-001,5.544773e-005,5.544773e-005,,,,,,,,,,,,,,,,,,,,
1406863868.468,,5.000000e+000,2.980050e+002,2.979968e+002,1,0,2.282407e+000,1.315348e-001,1.315348e-001,-7.270766e-001,-7.214029e-001,1.247346e-001,-7.338768e-001,-7.282031e-001,5.732988e-006,5.732988e-006,,,,,,,,,,,,,,,,,,,,
1406863885.765,,5.000000e+000,2.979968e+002,2.980050e+002,1,0,1.077481e-001,1.108890e+000,1.108890e+000,2.538917e-001,2.563431e-001,1.145880e+000,2.908820e-001,2.933334e-001,4.833135e-005,4.833135e-005,,,,,,,,,,,,,,,,,,,,
1406863885.765,,5.000000e+000,2.979968e+002,2.980050e+002,1,0,3.318179e+000,1.125217e+000,1.125217e+000,2.621106e-001,2.726705e-001,1.094404e+000,2.312971e-001,2.418571e-001,4.904299e-005,4.904299e-005,,,,,,,,,,,,,,,,,,,,
1406863903.531,,5.000000e+000,2.980050e+002,2.980050e+002,1,0,2.462344e+000,2.989288e-001,2.989288e-001,-5.637568e-001,-5.572515e-001,2.835253e-001,-5.791604e-001,-5.726550e-001,1.302891e-005,1.302891e-005,,,,,,,,,,,,,,,,,,,,
1406864028.265,,1.000000e+001,2.979968e+002,2.980050e+002,1,0,4.787726e-002,9.744560e-001,9.744560e-001,1.960399e-001,1.983168e-001,1.022487e+000,2.440707e-001,2.463475e-001,4.247198e-005,4.247198e-005,,,,,,,,,,,,,,,,,,,,
1406864028.265,,1.000000e+001,2.979968e+002,2.980050e+002,1,0,3.185595e+000,9.405804e-001,9.405805e-001,1.551713e-001,1.644412e-001,9.021365e-001,1.167274e-001,1.259972e-001,4.099550e-005,4.099550e-005,,,,,,,,,,,,,,,,,,,,
1406864046.031,,1.000000e+001,2.980050e+002,2.979968e+002,1,0,2.640280e+000,4.423658e-001,4.423658e-001,-3.423263e-001,-3.343995e-001,4.186390e-001,-3.660530e-001,-3.581263e-001,1.928066e-005,1.928066e-005,,,,,,,,,,,,,,,,,,,,
1406864064.515,,1.000000e+001,2.979968e+002,2.979968e+002,1,0,1.385041e-002,9.599597e-001,9.599597e-001,1.806533e-001,1.838537e-001,1.012240e+000,2.329334e-001,2.361339e-001,4.184015e-005,4.184015e-005,,,,,,,,,,,,,,,,,,,,
1406864064.515,,1.000000e+001,2.979968e+002,2.979968e+002,1,0,3.047386e+000,8.328501e-001,8.328501e-001,4.436902e-002,5.674416e-002,7.961511e-001,7.670018e-003,2.004516e-002,3.630004e-005,3.630004e-005,,,,,,,,,,,,,,,,,,,,
1406864175.031,,1.500000e+001,2.980050e+002,2.979885e+002,1,0,2.814148e+000,5.371258e-001,5.371258e-001,-1.464320e-001,-1.373379e-001,4.976812e-001,-1.858765e-001,-1.767825e-001,2.341079e-005,2.341079e-005,,,,,,,,,,,,,,,,,,,,
1406864192.765,,1.500000e+001,2.980050e+002,2.979885e+002,1,0,6.930329e-003,8.253731e-001,8.253731e-001,1.398772e-001,1.434606e-001,8.851784e-001,1.996826e-001,2.032660e-001,3.597414e-005,3.597414e-005,,,,,,,,,,,,,,,,,,,,
1406864192.765,,1.500000e+001,2.980050e+002,2.979885e+002,1,0,2.903043e+000,6.102176e-001,6.102176e-001,-8.490873e-002,-7.169491e-002,5.820699e-001,-1.130564e-001,-9.984255e-002,2.659652e-005,2.659652e-005,,,,,,,,,,,,,,,,,,,,
1406864211.000,,1.500000e+001,2.979885e+002,2.979885e+002,1,0,2.983049e+000,6.970428e-001,6.970428e-001,-2.629939e-003,8.500397e-003,6.492364e-001,-5.043626e-002,-3.930593e-002,3.038082e-005,3.038082e-005,,,,,,,,,,,,,,,,,,,,
1406864329.484,,2.000000e+001,2.979968e+002,2.979968e+002,1,0,2.665077e-002,6.544694e-001,6.544694e-001,9.392513e-002,9.869635e-002,7.193378e-001,1.587935e-001,1.635647e-001,2.852524e-005,2.852524e-005,,,,,,,,,,,,,,,,,,,,
1406864329.484,,2.000000e+001,2.979968e+002,2.979968e+002,1,0,2.751952e+000,3.816340e-001,3.816340e-001,-1.909787e-001,-1.741391e-001,3.662223e-001,-2.063904e-001,-1.895508e-001,1.663362e-005,1.663362e-005,,,,,,,,,,,,,,,,,,,,
1406864348.218,,2.000000e+001,2.980050e+002,2.979968e+002,1,0,3.146018e+000,6.315806e-001,6.315805e-001,9.371695e-002,1.046125e-001,5.777489e-001,3.988531e-002,5.078089e-002,2.752762e-005,2.752762e-005,,,,,,,,,,,,,,,,,,,,
1406864365.953,,2.000000e+001,2.980050e+002,2.979968e+002,1,0,7.149789e-002,6.607258e-001,6.607257e-001,1.088505e-001,1.140708e-001,7.180237e-001,1.661485e-001,1.713688e-001,2.879792e-005,2.879792e-005,,,,,,,,,,,,,,,,,,,,
1406864365.953,,2.000000e+001,2.980050e+002,2.979968e+002,1,0,2.593736e+000,2.516251e-001,2.516251e-001,-3.127209e-001,-2.950298e-001,2.531656e-001,-3.111804e-001,-2.934893e-001,1.096715e-005,1.096715e-005,,,,,,,,,,,,,,,,,,,,
1406864500.953,,2.500000e+001,2.979968e+002,2.980050e+002,1,0,3.301927e+000,8.455153e-001,8.455153e-001,1.879805e-001,2.174661e-001,7.408133e-001,8.327842e-002,1.127640e-001,1.842600e-005,1.842600e-005,,,,,,,,,,,,,,,,,,,,
1406864517.968,,2.500000e+001,2.980050e+002,2.979968e+002,1,0,1.384466e-001,6.984161e-001,6.984161e-001,6.563254e-002,7.950294e-002,8.071438e-001,1.743602e-001,1.882306e-001,1.522032e-005,1.522032e-005,,,,,,,,,,,,,,,,,,,,
1406864517.968,,2.500000e+001,2.980050e+002,2.979968e+002,1,0,2.428335e+000,1.197852e-001,1.197852e-001,-5.443893e-001,-4.991280e-001,1.602156e-001,-5.039589e-001,-4.586976e-001,2.610434e-006,2.610434e-006,,,,,,,,,,,,,,,,,,,,
1406864535.703,,2.500000e+001,2.979968e+002,2.979968e+002,1,0,3.448727e+000,8.748130e-001,8.748131e-001,2.222933e-001,2.537093e-001,7.995859e-001,1.470661e-001,1.784821e-001,1.906448e-005,1.906448e-005,,,,,,,,,,,,,,,,,,,,
1406864647.437,,3.000000e+001,2.979968e+002,2.979968e+002,1,0,2.241808e-001,-5.902280e-001,-5.902280e-001,-2.411379e-001,-1.962022e-001,-5.434189e-001,-1.943288e-001,-1.493931e-001,-1.286261e-005,-1.286261e-005,,,,,,,,,,,,,,,,,,,,
1406864647.437,,3.000000e+001,2.979968e+002,2.979968e+002,1,0,2.256743e+000,-1.048311e-001,-1.048311e-001,1.476472e-001,2.891947e-001,-3.978390e-002,2.126944e-001,3.542419e-001,-2.284544e-006,-2.284544e-006,,,,,,,,,,,,,,,,,,,,
1406864666.218,,3.000000e+001,2.980050e+002,2.979968e+002,1,0,3.584466e+000,-5.333109e-001,-5.333109e-001,-1.830201e-001,-9.126455e-002,-5.542746e-001,-2.039837e-001,-1.122282e-001,-1.162224e-005,-1.162224e-005,,,,,,,,,,,,,,,,,,,,
1406864683.968,,3.000000e+001,2.979968e+002,2.980050e+002,1,0,3.247118e-001,-6.874294e-001,-6.874294e-001,-2.307148e-001,-1.838964e-001,-6.645679e-001,-2.078533e-001,-1.610348e-001,-1.498089e-005,-1.498089e-005,,,,,,,,,,,,,,,,,,,,
1406864803.734,,3.500000e+001,2.979968e+002,2.980050e+002,1,0,2.080155e+000,-3.479110e-002,-3.479110e-002,1.333119e+000,1.333119e+000,-1.334326e-004,1.367777e+000,1.367777e+000,-7.581889e-007,-7.581889e-007,,,,,,,,,,,,,,,,,,,,
1406864803.734,,3.500000e+001,2.979968e+002,2.980050e+002,1,0,3.706127e+000,-1.904355e+000,-1.904355e+000,-6.202645e-001,-5.364448e-001,-1.883706e+000,-5.996153e-001,-5.157956e-001,-4.150087e-005,-4.150087e-005,,,,,,,,,,,,,,,,,,,,
1406864821.968,,3.500000e+001,2.979968e+002,2.979968e+002,1,0,4.365074e-001,-1.942045e+000,-1.942045e+000,-5.913238e-001,-5.450972e-001,-1.963549e+000,-6.128274e-001,-5.666008e-001,-4.232224e-005,-4.232224e-005,,,,,,,,,,,,,,,,,,,,
1406864840.203,,3.500000e+001,2.980050e+002,2.979968e+002,1,0,1.900279e+000,3.845332e-002,3.845332e-002,1.435452e+000,1.437605e+000,1.102267e-001,1.507225e+000,1.509379e+000,8.379983e-007,8.379983e-007,,,,,,,,,,,,,,,,,,,,
1406864840.203,,3.500000e+001,2.980050e+002,2.979968e+002,1,0,3.810415e+000,-1.955931e+000,-1.955931e+000,-6.515363e-001,-5.567794e-001,-1.879734e+000,-5.753387e-001,-4.805818e-001,-4.262485e-005,-4.262485e-005,,,,,,,,,,,,,,,,,,,,
1406864958.437,,4.000000e+001,2.979968e+002,2.979885e+002,1,0,5.568556e-001,-2.468184e+000,-2.468184e+000,-6.673219e-001,-6.166719e-001,-2.523076e+000,-7.222130e-001,-6.715630e-001,-5.378816e-005,-5.378816e-005,,,,,,,,,,,,,,,,,,,,
1406864977.171,,4.000000e+001,2.980050e+002,2.980050e+002,1,0,1.719395e+000,-1.454207e-001,-1.454207e-001,1.659280e+000,1.663859e+000,-9.487344e-002,1.709827e+000,1.714406e+000,-3.169095e-006,-3.169095e-006,,,,,,,,,,,,,,,,,,,,
1406864977.171,,4.000000e+001,2.980050e+002,2.980050e+002,1,0,3.894045e+000,-2.539140e+000,-2.539140e+000,-8.328946e-001,-7.298602e-001,-2.405801e+000,-6.995552e-001,-5.965208e-001,-5.533447e-005,-5.533447e-005,,,,,,,,,,,,,,,,,,,,
1406864994.406,,4.000000e+001,2.979968e+002,2.980050e+002,1,0,6.836584e-001,-2.304147e+000,-2.304147e+000,-5.026560e-001,-4.453663e-001,-2.374732e+000,-5.732401e-001,-5.159503e-001,-5.021337e-005,-5.021337e-005,,,,,,,,,,,,,,,,,,,,
1406865110.906,,4.500000e+001,2.979968e+002,2.980050e+002,1,0,1.539100e+000,-6.155583e-001,-6.155583e-001,1.473508e+000,1.480745e+000,-6.499360e-001,1.439131e+000,1.446368e+000,-1.341461e-005,-1.341461e-005,,,,,,,,,,,,,,,,,,,,
1406865110.906,,4.500000e+001,2.979968e+002,2.980050e+002,1,0,3.953901e+000,-2.896054e+000,-2.896054e+000,-9.107172e-001,-7.997506e-001,-2.721948e+000,-7.366108e-001,-6.256442e-001,-6.311251e-005,-6.311251e-005,,,,,,,,,,,,,,,,,,,,
1406865129.171,,4.500000e+001,2.979968e+002,2.979968e+002,1,0,8.162836e-001,-2.368389e+000,-2.368389e+000,-3.290206e-001,-2.680695e-001,-2.458097e+000,-4.187282e-001,-3.577771e-001,-5.161333e-005,-5.161333e-005,,,,,,,,,,,,,,,,,,,,
1406865147.406,,4.500000e+001,2.979968e+002,2.980050e+002,1,0,1.361531e+000,-1.029389e+000,-1.029389e+000,1.059745e+000,1.069788e+000,-1.133906e+000,9.552281e-001,9.652708e-001,-2.243306e-005,-2.243306e-005,,,,,,,,,,,,,,,,,,,,
1406865147.406,,4.500000e+001,2.979968e+002,2.980050e+002,1,0,3.987900e+000,-2.890103e+000,-2.890103e+000,-9.089276e-001,-7.909260e-001,-2.695165e+000,-7.139901e-001,-5.959885e-001,-6.298283e-005,-6.298283e-005,,,,,,,,,,,,,,,,,,,,
1406865266.390,,5.000000e+001,2.979968e+002,2.979968e+002,1,0,9.543819e-001,-2.255318e+000,-2.255318e+000,-4.560747e-002,2.351952e-002,-2.378673e+000,-1.689622e-001,-9.983516e-002,-4.914920e-005,-4.914920e-005,,,,,,,,,,,,,,,,,,,,
1406865284.125,,5.000000e+001,2.979968e+002,2.980050e+002,1,0,1.187850e+000,-1.674093e+000,-1.674093e+000,6.211975e-001,6.344825e-001,-1.826374e+000,4.689164e-001,4.822013e-001,-3.648280e-005,-3.648280e-005,,,,,,,,,,,,,,,,,,,,
1406865284.125,,5.000000e+001,2.979968e+002,2.980050e+002,1,0,3.994912e+000,-3.189642e+000,-3.189642e+000,-1.008602e+000,-8.810666e-001,-2.974835e+000,-7.937955e-001,-6.662598e-001,-6.951053e-005,-6.951053e-005,,,,,,,,,,,,,,,,,,,,
1406865301.859,,5.000000e+001,2.980132e+002,2.979968e+002,1,0,1.098728e+000,-1.859798e+000,-1.859798e+000,3.494650e-001,4.210324e-001,-1.997705e+000,2.115582e-001,2.831256e-001,-4.052980e-005,-4.052980e-005,,,,,,,,,,,,,,,,,,,,
1406865426.375,,7.500000e+001,2.979968e+002,2.979968e+002,1,0,1.018748e+000,-2.489853e+000,-2.489853e+000,1.227404e-001,1.438124e-001,-2.686719e+000,-7.412633e-002,-5.305433e-002,-5.426019e-005,-5.426019e-005,,,,,,,,,,,,,,,,,,,,
1406865426.375,,7.500000e+001,2.979968e+002,2.979968e+002,1,0,3.975123e+000,-3.660848e+000,-3.660848e+000,-1.199271e+000,-1.027183e+000,-3.413251e+000,-9.516740e-001,-7.795861e-001,-7.977914e-005,-7.977914e-005,,,,,,,,,,,,,,,,,,,,
1406865443.421,,7.500000e+001,2.979885e+002,2.979968e+002,1,0,1.249837e+000,-1.685385e+000,-1.685385e+000,8.222718e-001,9.222955e-001,-1.840171e+000,6.674858e-001,7.675095e-001,-3.672880e-005,-3.672880e-005,,,,,,,,,,,,,,,,,,,,
1406865461.171,,7.500000e+001,2.979968e+002,2.979968e+002,1,0,8.555833e-001,-2.957091e+000,-2.957091e+000,-3.461413e-001,-3.214941e-001,-3.141347e+000,-5.303977e-001,-5.057504e-001,-6.444249e-005,-6.444249e-005,,,,,,,,,,,,,,,,,,,,
1406865461.171,,7.500000e+001,2.979968e+002,2.979968e+002,1,0,3.930310e+000,-3.679617e+000,-3.679617e+000,-1.220071e+000,-1.044020e+000,-3.459643e+000,-1.000098e+000,-8.240464e-001,-8.018816e-005,-8.018816e-005,,,,,,,,,,,,,,,,,,,,
1406865584.656,,1.000000e+002,2.980050e+002,2.979885e+002,1,0,1.408089e+000,-1.189306e+000,-1.189306e+000,1.397282e+000,1.513463e+000,-1.325314e+000,1.261275e+000,1.377456e+000,-2.591794e-005,-2.591794e-005,,,,,,,,,,,,,,,,,,,,
1406865603.140,,1.000000e+002,2.979885e+002,2.979885e+002,1,0,7.000531e-001,-3.436079e+000,-3.436079e+000,-7.270795e-001,-6.941278e-001,-3.631407e+000,-9.224075e-001,-8.894558e-001,-7.488069e-005,-7.488069e-005,,,,,,,,,,,,,,,,,,,,
1406865603.140,,1.000000e+002,2.979885e+002,2.979885e+002,1,0,3.863350e+000,-3.839381e+000,-3.839381e+000,-1.307497e+000,-1.097430e+000,-3.647675e+000,-1.115791e+000,-9.057238e-001,-8.366964e-005,-8.366964e-005,,,,,,,,,,,,,,,,,,,,
1406865621.390,,1.000000e+002,2.979885e+002,2.979885e+002,1,0,1.573466e+000,-6.965849e-001,-6.965850e-001,1.902160e+000,2.022730e+000,-7.352201e-001,1.863525e+000,1.984095e+000,-1.518032e-005,-1.518032e-005,,,,,,,,,,,,,,,,,,,,
1406865621.390,,1.000000e+002,2.979885e+002,2.979885e+002,1,0,2.256731e+000,-2.240059e-001,-2.240059e-001,2.242111e+000,2.495309e+000,2.359471e-002,2.489712e+000,2.742910e+000,-4.881644e-006,-4.881644e-006,,,,,,,,,,,,,,,,,,,,