File: Sample Data Files/2014-07-31 EB on isolated PMN-PT no Ti spontaneous in situ repeat/Ni-NiO_298K_SiO2_PMN-PT_5.0Tprebias_040V_Au_back.rso.raw
[Header]
TITLE,MPMS RSO Measurement
BYAPP,MPMS Measurement,2.1,Raw with ABS
FILEOPENTIME, 1406848290.484000 7/31/2014, 4:11:30 PM

INFO, APPNAME, MPMS MultiVu Application, Revision 1.58,  Build 076

INFO, NAME, EB in situ 2
INFO, WEIGHT, 0.000
INFO, AREA, 0.000
INFO, LENGTH, 0.000
INFO, SHAPE, 0
INFO, COMMENT,
INFO, SEQUENCE FILE: MHcurveUpTo100.seq


INFO, BACKGROUND DATA FILE:, None


STARTUPAXIS,X,8,LINEAR,AUTO,0.000000,0.000000
STARTUPAXIS,Y1,9,LINEAR,AUTO,0.000000,0.000000


STARTUPGROUP,Longitudinal
FIELDGROUP,Longitudinal,1,2,3,4,5,6,7,8,9,10,11,12,13,14,15,16,17,18,19,20,21,22
FIELDGROUP,Transverse,1,2,3,4,5,6,7,8,23,24,25,26,27,28,29,30,31,32,33,34,35,36

PLOT_APPEARANCE,ALL,HORZ_GRID_ON,VERT_GRID_ON,MARKERS_ONLY

[Data]
Time,Comment,Field (Oe),Start Temperature (K),End Temperature (K),Scan,Rejected,Position (cm),Long Voltage,Long Average Voltage,Long Detrended Voltage,Long Demeaned Voltage,Long Reg Fit,Long Detrended Fit,Long Demeaned Fit,Long Scaled Response,Long Avg. Scaled Response,Long Background Response,Long Response [w/ABS],Long Detrended Resp. [w/ABS],Long Fit [w/ABS],Long Detrended Fit [w/ABS],Trans Voltage,Trans Average Voltage,Trans Detrended Voltage,Trans Demeaned Voltage,Trans Reg Fit,Trans Detrended Fit,Trans Demeaned Fit,Trans Scaled Response,Trans Avg. Scaled Response,Trans Background Response,Trans Response [w/ABS],Trans Detrended Resp. [w/ABS],Trans Adjusted Fit,Trans Detrended Fit [w/ABS],
1406848290.468,,1.000000e+002,2.980050e+002,2.980050e+002,1,0,2.080208e+000,-6.637776e-002,-6.637776e-002,1.395099e+000,1.395099e+000,-1.325254e-002,1.448224e+000,1.448224e+000,-2.893072e-006,-2.893072e-006,,,,,,,,,,,,,,,,,,,,
1406848290.468,,1.000000e+002,2.980050e+002,2.980050e+002,1,0,3.706024e+000,-2.025666e+000,-2.025666e+000,-6.411690e-001,-5.641893e-001,-2.018481e+000,-6.339840e-001,-5.570043e-001,-8.828858e-005,-8.828858e-005,,,,,,,,,,,,,,,,,,,,
1406848308.203,,1.000000e+002,2.979968e+002,2.980050e+002,1,0,4.364521e-001,-2.029634e+000,-2.029634e+000,-6.203514e-001,-5.805697e-001,-2.044834e+000,-6.355522e-001,-5.957706e-001,-8.846150e-005,-8.846150e-005,,,,,,,,,,,,,,,,,,,,
1406848326.187,,1.000000e+002,2.980050e+002,2.980050e+002,1,0,1.900530e+000,-9.048738e-002,-9.048738e-002,1.367911e+000,1.369712e+000,-3.030629e-002,1.428092e+000,1.429893e+000,-3.943889e-006,-3.943889e-006,,,,,,,,,,,,,,,,,,,,
1406848326.187,,1.000000e+002,2.980050e+002,2.980050e+002,1,0,3.810359e+000,-2.041383e+000,-2.041383e+000,-6.604317e-001,-5.811832e-001,-1.982744e+000,-6.017927e-001,-5.225441e-001,-8.897360e-005,-8.897360e-005,,,,,,,,,,,,,,,,,,,,
1406848450.421,,7.500000e+001,2.979968e+002,2.979885e+002,1,0,5.567176e-001,-2.010559e+000,-2.010559e+000,-5.429941e-001,-5.098764e-001,-2.051244e+000,-5.836790e-001,-5.505613e-001,-8.763035e-005,-8.763035e-005,,,,,,,,,,,,,,,,,,,,
1406848468.156,,7.500000e+001,2.979968e+002,2.979968e+002,1,0,1.719421e+000,-2.967925e-001,-2.967925e-001,1.199219e+000,1.202129e+000,-2.790114e-001,1.217000e+000,1.219911e+000,-1.293572e-005,-1.293572e-005,,,,,,,,,,,,,,,,,,,,
1406848468.156,,7.500000e+001,2.979968e+002,2.979968e+002,1,0,3.893972e+000,-2.085940e+000,-2.085940e+000,-6.524970e-001,-5.870183e-001,-1.989709e+000,-5.562662e-001,-4.907875e-001,-9.091583e-005,-9.091583e-005,,,,,,,,,,,,,,,,,,,,
1406848485.906,,7.500000e+001,2.979968e+002,2.979968e+002,1,0,6.836644e-001,-1.877651e+000,-1.877651e+000,-4.271865e-001,-3.912364e-001,-1.934845e+000,-4.843803e-001,-4.484302e-001,-8.183755e-005,-8.183755e-005,,,,,,,,,,,,,,,,,,,,
1406848614.921,,5.000000e+001,2.980132e+002,2.979968e+002,1,0,1.539572e+000,-5.569628e-001,-5.569628e-001,9.331299e-001,9.366733e-001,-5.923369e-001,8.977558e-001,9.012992e-001,-2.427531e-005,-2.427531e-005,,,,,,,,,,,,,,,,,,,,
1406848614.921,,5.000000e+001,2.980132e+002,2.979968e+002,1,0,3.953968e+000,-2.064730e+000,-2.064730e+000,-6.254263e-001,-5.710936e-001,-1.953056e+000,-5.137523e-001,-4.594196e-001,-8.999158e-005,-8.999158e-005,,,,,,,,,,,,,,,,,,,,
1406848632.656,,5.000000e+001,2.979968e+002,2.979968e+002,1,0,8.161071e-001,-1.735435e+000,-1.735435e+000,-2.659664e-001,-2.355729e-001,-1.795401e+000,-3.259320e-001,-2.955385e-001,-7.563922e-005,-7.563922e-005,,,,,,,,,,,,,,,,,,,,
1406848651.203,,5.000000e+001,2.979968e+002,2.980050e+002,1,0,1.361463e+000,-8.076724e-001,-8.076724e-001,6.404181e-001,6.453872e-001,-8.803794e-001,5.677111e-001,5.726801e-001,-3.520253e-005,-3.520253e-005,,,,,,,,,,,,,,,,,,,,
1406848651.203,,5.000000e+001,2.979968e+002,2.980050e+002,1,0,3.987827e+000,-2.014527e+000,-2.014527e+000,-6.198537e-001,-5.614673e-001,-1.888939e+000,-4.942659e-001,-4.358795e-001,-8.780348e-005,-8.780348e-005,,,,,,,,,,,,,,,,,,,,
1406848762.437,,4.500000e+001,2.980050e+002,2.979968e+002,1,0,9.543266e-001,-1.522874e+000,-1.522874e+000,-6.092954e-002,-3.189182e-002,-1.592463e+000,-1.305187e-001,-1.014810e-001,-6.637472e-005,-6.637472e-005,,,,,,,,,,,,,,,,,,,,
1406848779.921,,4.500000e+001,2.979968e+002,2.980132e+002,1,0,1.187994e+000,-1.136662e+000,-1.136662e+000,3.407841e-001,3.466208e-001,-1.224883e+000,2.525632e-001,2.584000e-001,-4.954161e-005,-4.954161e-005,,,,,,,,,,,,,,,,,,,,
1406848779.921,,4.500000e+001,2.979968e+002,2.980132e+002,1,0,3.994924e+000,-2.041078e+000,-2.041078e+000,-6.138276e-001,-5.577952e-001,-1.915089e+000,-4.878393e-001,-4.318068e-001,-8.896075e-005,-8.896075e-005,,,,,,,,,,,,,,,,,,,,
1406848798.203,,4.500000e+001,2.980132e+002,2.979968e+002,1,0,1.098620e+000,-1.274453e+000,-1.274453e+000,1.776873e-001,2.084864e-001,-1.352456e+000,9.968411e-002,1.304833e-001,-5.554726e-005,-5.554726e-005,,,,,,,,,,,,,,,,,,,,
1406848916.453,,4.000000e+001,2.979968e+002,2.980050e+002,1,0,1.018853e+000,-1.436201e+000,-1.436201e+000,5.741095e-002,6.364095e-002,-1.523890e+000,-3.027761e-002,-2.404761e-002,-6.259712e-005,-6.259712e-005,,,,,,,,,,,,,,,,,,,,
1406848916.453,,4.000000e+001,2.979968e+002,2.980050e+002,1,0,3.975137e+000,-2.062288e+000,-2.062288e+000,-6.133246e-001,-5.624462e-001,-1.945361e+000,-4.963972e-001,-4.455189e-001,-8.988525e-005,-8.988525e-005,,,,,,,,,,,,,,,,,,,,
1406848934.187,,4.000000e+001,2.980050e+002,2.980050e+002,1,0,1.249739e+000,-1.005432e+000,-1.005432e+000,4.355171e-001,4.670479e-001,-1.081032e+000,3.599176e-001,3.914484e-001,-4.382197e-005,-4.382197e-005,,,,,,,,,,,,,,,,,,,,
1406848952.421,,4.000000e+001,2.980050e+002,2.979968e+002,1,0,8.556206e-001,-1.652577e+000,-1.652577e+000,-1.897775e-001,-1.816947e-001,-1.733311e+000,-2.705111e-001,-2.624283e-001,-7.202791e-005,-7.202791e-005,,,,,,,,,,,,,,,,,,,,
1406848952.421,,4.000000e+001,2.980050e+002,2.979968e+002,1,0,3.930317e+000,-2.037263e+000,-2.037263e+000,-6.241148e-001,-5.663806e-001,-1.934567e+000,-5.214186e-001,-4.636844e-001,-8.879452e-005,-8.879452e-005,,,,,,,,,,,,,,,,,,,,
1406849076.468,,3.500000e+001,2.980050e+002,2.979968e+002,1,0,1.408025e+000,-7.406843e-001,-7.406842e-001,7.068571e-001,7.353656e-001,-8.032728e-001,6.442685e-001,6.727770e-001,-3.228289e-005,-3.228289e-005,,,,,,,,,,,,,,,,,,,,
1406849094.453,,3.500000e+001,2.979968e+002,2.979968e+002,1,0,7.000772e-001,-1.843776e+000,-1.843776e+000,-3.761768e-001,-3.678606e-001,-1.919356e+000,-4.517575e-001,-4.434413e-001,-8.036137e-005,-8.036137e-005,,,,,,,,,,,,,,,,,,,,
1406849094.453,,3.500000e+001,2.979968e+002,2.979968e+002,1,0,3.863360e+000,-2.056032e+000,-2.056032e+000,-6.331328e-001,-5.801167e-001,-1.975295e+000,-5.523959e-001,-4.993799e-001,-8.961261e-005,-8.961261e-005,,,,,,,,,,,,,,,,,,,,
1406849112.687,,3.500000e+001,2.980050e+002,2.979968e+002,1,0,1.573400e+000,-4.686117e-001,-4.686117e-001,9.662377e-001,9.986784e-001,-4.921159e-001,9.427335e-001,9.751743e-001,-2.042455e-005,-2.042455e-005,,,,,,,,,,,,,,,,,,,,
1406849231.687,,3.000000e+001,2.979968e+002,2.979885e+002,1,0,5.530544e-001,-1.980499e+000,-1.980499e+000,-5.051895e-001,-4.973837e-001,-2.037333e+000,-5.620241e-001,-5.542183e-001,-8.632051e-005,-8.632051e-005,,,,,,,,,,,,,,,,,,,,
1406849231.687,,3.000000e+001,2.979968e+002,2.979885e+002,1,0,3.777664e+000,-2.070833e+000,-2.070833e+000,-6.328189e-001,-5.877185e-001,-2.021621e+000,-5.836064e-001,-5.385060e-001,-9.025778e-005,-9.025778e-005,,,,,,,,,,,,,,,,,,,,
1406849250.421,,3.000000e+001,2.979968e+002,2.979968e+002,1,0,1.745012e+000,-2.662740e-001,-2.662740e-001,1.167998e+000,1.196810e+000,-2.300314e-001,1.204241e+000,1.233052e+000,-1.160562e-005,-1.160562e-005,,,,,,,,,,,,,,,,,,,,
1406849268.656,,3.000000e+001,2.979968e+002,2.980050e+002,1,0,4.173248e-001,-2.026429e+000,-2.026429e+000,-5.739775e-001,-5.641162e-001,-2.059038e+000,-6.065862e-001,-5.967250e-001,-8.832240e-005,-8.832240e-005,,,,,,,,,,,,,,,,,,,,
1406849268.656,,3.000000e+001,2.979968e+002,2.980050e+002,1,0,3.677162e+000,-2.029328e+000,-2.029328e+000,-6.192802e-001,-5.670156e-001,-2.016677e+000,-6.066292e-001,-5.543647e-001,-8.844877e-005,-8.844877e-005,,,,,,,,,,,,,,,,,,,,
1406849387.406,,2.500000e+001,2.979968e+002,2.979968e+002,1,0,1.921633e+000,-1.884518e-001,-1.884518e-001,1.275477e+000,1.300855e+000,-1.054693e-001,1.358460e+000,1.383838e+000,-8.213721e-006,-8.213721e-006,,,,,,,,,,,,,,,,,,,,
1406849405.640,,2.500000e+001,2.979968e+002,2.980050e+002,1,0,2.957333e-001,-2.060305e+000,-2.060305e+000,-5.941254e-001,-5.848364e-001,-2.060878e+000,-5.946983e-001,-5.854093e-001,-8.979892e-005,-8.979892e-005,,,,,,,,,,,,,,,,,,,,
1406849405.640,,2.500000e+001,2.979968e+002,2.980050e+002,1,0,3.565350e+000,-2.002319e+000,-2.002319e+000,-5.724517e-001,-5.268511e-001,-2.026010e+000,-5.961421e-001,-5.505415e-001,-8.727162e-005,-8.727162e-005,,,,,,,,,,,,,,,,,,,,
1406849423.890,,2.500000e+001,2.980050e+002,2.979968e+002,1,0,2.101368e+000,-1.646474e-001,-1.646474e-001,1.259740e+000,1.290645e+000,-6.960741e-002,1.354780e+000,1.385685e+000,-7.176198e-006,-7.176198e-006,,,,,,,,,,,,,,,,,,,,
1406849535.203,,2.000000e+001,2.980050e+002,2.979968e+002,1,0,1.914542e-001,-2.070376e+000,-2.070376e+000,-5.889414e-001,-5.812467e-001,-2.037529e+000,-5.560949e-001,-5.484003e-001,-9.023791e-005,-9.023791e-005,,,,,,,,,,,,,,,,,,,,
1406849535.203,,2.000000e+001,2.980050e+002,2.979968e+002,1,0,3.445120e+000,-1.948759e+000,-1.948759e+000,-4.948976e-001,-4.596305e-001,-1.996243e+000,-5.423813e-001,-5.071142e-001,-8.493723e-005,-8.493723e-005,,,,,,,,,,,,,,,,,,,,
1406849553.484,,2.000000e+001,2.979968e+002,2.980050e+002,1,0,2.282298e+000,-3.404340e-001,-3.404340e-001,1.108468e+000,1.134078e+000,-2.811881e-001,1.167714e+000,1.193324e+000,-1.483791e-005,-1.483791e-005,,,,,,,,,,,,,,,,,,,,
1406849571.750,,2.000000e+001,2.979968e+002,2.979968e+002,1,0,1.078098e-001,-2.031770e+000,-2.031770e+000,-5.791557e-001,-5.686964e-001,-1.969874e+000,-5.172598e-001,-5.068004e-001,-8.855526e-005,-8.855526e-005,,,,,,,,,,,,,,,,,,,,
1406849571.750,,2.000000e+001,2.979968e+002,2.979968e+002,1,0,3.318209e+000,-1.796472e+000,-1.796472e+000,-3.784544e-001,-3.333987e-001,-1.861390e+000,-4.433727e-001,-3.983170e-001,-7.829974e-005,-7.829974e-005,,,,,,,,,,,,,,,,,,,,
1406849689.484,,1.500000e+001,2.980050e+002,2.979968e+002,1,0,2.462312e+000,-6.134220e-001,-6.134220e-001,8.729464e-001,8.914849e-001,-6.111871e-001,8.751813e-001,8.937198e-001,-2.673619e-005,-2.673619e-005,,,,,,,,,,,,,,,,,,,,
1406849707.718,,1.500000e+001,2.979968e+002,2.979968e+002,1,0,4.785421e-002,-2.033143e+000,-2.033143e+000,-5.595142e-001,-5.508287e-001,-1.953386e+000,-4.797570e-001,-4.710715e-001,-8.861516e-005,-8.861516e-005,,,,,,,,,,,,,,,,,,,,
1406849707.718,,1.500000e+001,2.979968e+002,2.979968e+002,1,0,3.185633e+000,-1.660665e+000,-1.660665e+000,-2.137128e-001,-1.783503e-001,-1.738892e+000,-2.919400e-001,-2.565775e-001,-7.238057e-005,-7.238057e-005,,,,,,,,,,,,,,,,,,,,
1406849726.031,,1.500000e+001,2.979968e+002,2.979968e+002,1,0,2.640023e+000,-8.389539e-001,-8.389539e-001,6.144552e-001,6.391697e-001,-8.900752e-001,5.633338e-001,5.880483e-001,-3.656606e-005,-3.656606e-005,,,,,,,,,,,,,,,,,,,,
1406849843.015,,1.000000e+001,2.979968e+002,2.980050e+002,1,0,1.384418e-002,-2.028108e+000,-2.028108e+000,-5.405255e-001,-5.343060e-001,-1.942070e+000,-4.544874e-001,-4.482679e-001,-8.839573e-005,-8.839573e-005,,,,,,,,,,,,,,,,,,,,
1406849843.015,,1.000000e+001,2.979968e+002,2.980050e+002,1,0,3.047423e+000,-1.494186e+000,-1.494186e+000,-2.443329e-002,-3.846884e-004,-1.573380e+000,-1.036270e-001,-7.957840e-002,-6.512459e-005,-6.512459e-005,,,,,,,,,,,,,,,,,,,,
1406849861.000,,1.000000e+001,2.980050e+002,2.979968e+002,1,0,2.814146e+000,-1.113926e+000,-1.113926e+000,3.375705e-001,3.554111e-001,-1.193138e+000,2.583583e-001,2.761989e-001,-4.855081e-005,-4.855081e-005,,,,,,,,,,,,,,,,,,,,
1406849879.031,,1.000000e+001,2.979968e+002,2.980050e+002,1,0,6.930448e-003,-1.988128e+000,-1.988128e+000,-5.392898e-001,-5.301436e-001,-1.899240e+000,-4.504018e-001,-4.412557e-001,-8.665321e-005,-8.665321e-005,,,,,,,,,,,,,,,,,,,,
1406849879.031,,1.000000e+001,2.979968e+002,2.980050e+002,1,0,2.903112e+000,-1.233405e+000,-1.233406e+000,1.908526e-001,2.245791e-001,-1.309795e+000,1.144627e-001,1.481892e-001,-5.375838e-005,-5.375838e-005,,,,,,,,,,,,,,,,,,,,
1406849995.015,,5.000000e+000,2.979968e+002,2.980050e+002,1,0,2.983000e+000,-1.392865e+000,-1.392865e+000,7.924267e-002,9.003294e-002,-1.480593e+000,-8.485232e-003,2.305031e-003,-6.070849e-005,-6.070849e-005,,,,,,,,,,,,,,,,,,,,
1406850013.515,,5.000000e+000,2.980050e+002,2.979968e+002,1,0,2.665350e-002,-1.968139e+000,-1.968139e+000,-5.304599e-001,-5.248276e-001,-1.888830e+000,-4.511508e-001,-4.455185e-001,-8.578201e-005,-8.578201e-005,,,,,,,,,,,,,,,,,,,,
1406850013.515,,5.000000e+000,2.980050e+002,2.979968e+002,1,0,2.751991e+000,-1.007263e+000,-1.007263e+000,4.161688e-001,4.360477e-001,-1.069452e+000,3.539806e-001,3.738594e-001,-4.390192e-005,-4.390192e-005,,,,,,,,,,,,,,,,,,,,
1406850031.015,,5.000000e+000,2.979968e+002,2.979968e+002,1,0,3.146148e+000,-1.576891e+000,-1.576891e+000,-1.446170e-001,-1.273707e-001,-1.665307e+000,-2.330328e-001,-2.157866e-001,-6.872935e-005,-6.872935e-005,,,,,,,,,,,,,,,,,,,,
1406850147.296,,0.000000e+000,2.979968e+002,2.979968e+002,1,0,7.140516e-002,-1.994079e+000,-1.994079e+000,-5.223224e-001,-5.223087e-001,-1.927171e+000,-4.554145e-001,-4.554008e-001,-8.691267e-005,-8.691267e-005,,,,,,,,,,,,,,,,,,,,
1406850147.296,,0.000000e+000,2.979968e+002,2.979968e+002,1,0,2.593723e+000,-8.430738e-001,-8.430738e-001,6.286504e-001,6.286968e-001,-8.748705e-001,5.968538e-001,5.969002e-001,-3.674568e-005,-3.674568e-005,,,,,,,,,,,,,,,,,,,,
1406850165.031,,0.000000e+000,2.979968e+002,2.980050e+002,1,0,3.301776e+000,-1.745659e+000,-1.745659e+000,-3.154343e-001,-3.090296e-001,-1.819988e+000,-3.897638e-001,-3.833591e-001,-7.608517e-005,-7.608517e-005,,,,,,,,,,,,,,,,,,,,
1406850183.265,,0.000000e+000,2.980050e+002,2.979968e+002,1,0,1.385047e-001,-1.949980e+000,-1.949980e+000,-5.382199e-001,-5.339593e-001,-1.896431e+000,-4.846710e-001,-4.804103e-001,-8.499059e-005,-8.499059e-005,,,,,,,,,,,,,,,,,,,,
1406850183.265,,0.000000e+000,2.980050e+002,2.979968e+002,1,0,2.428438e+000,-5.574206e-001,-5.574206e-001,8.446971e-001,8.586003e-001,-5.435628e-001,8.585549e-001,8.724581e-001,-2.429538e-005,-2.429538e-005,,,,,,,,,,,,,,,,,,,,
1406850301.796,,-5.000000e+000,2.979968e+002,2.979968e+002,1,0,3.448691e+000,-1.664479e+000,-1.664479e+000,-3.566843e-001,-3.680130e-001,-1.714577e+000,-4.067816e-001,-4.181104e-001,-7.254691e-005,-7.254691e-005,,,,,,,,,,,,,,,,,,,,
1406850319.531,,-5.000000e+000,2.979968e+002,2.979968e+002,1,0,2.241046e-001,-1.677145e+000,-1.677145e+000,-4.467348e-001,-4.489856e-001,-1.644896e+000,-4.144864e-001,-4.167372e-001,-7.309893e-005,-7.309893e-005,,,,,,,,,,,,,,,,,,,,
1406850319.531,,-5.000000e+000,2.979968e+002,2.979968e+002,1,0,2.256694e+000,-4.110843e-001,-4.110843e-001,8.241647e-001,8.170748e-001,-3.426079e-001,8.926412e-001,8.855512e-001,-1.791725e-005,-1.791725e-005,,,,,,,,,,,,,,,,,,,,
1406850338.562,,-5.000000e+000,2.979968e+002,2.979968e+002,1,0,3.584446e+000,-1.597797e+000,-1.597797e+000,-3.997240e-001,-4.020885e-001,-1.620683e+000,-4.226101e-001,-4.249746e-001,-6.964051e-005,-6.964051e-005,,,,,,,,,,,,,,,,,,,,
1406850479.031,,-1.000000e+001,2.979968e+002,2.980050e+002,1,0,3.245564e-001,9.567553e-002,9.567553e-002,1.949310e-001,1.732485e-001,1.144308e-001,2.136863e-001,1.920038e-001,2.085024e-006,2.085024e-006,,,,,,,,,,,,,,,,,,,,
1406850497.781,,-1.000000e+001,2.980050e+002,2.980050e+002,1,0,2.080253e+000,-4.860072e-001,-4.860073e-001,-6.119995e-001,-6.119995e-001,-4.455180e-001,-5.715102e-001,-5.715102e-001,-1.059139e-005,-1.059139e-005,,,,,,,,,,,,,,,,,,,,
1406850497.781,,-1.000000e+001,2.980050e+002,2.980050e+002,1,0,3.706087e+000,3.294473e-001,3.294473e-001,2.399663e-001,2.034551e-001,3.414938e-001,2.520128e-001,2.155016e-001,7.179534e-006,7.179534e-006,,,,,,,,,,,,,,,,,,,,
1406850516.515,,-1.000000e+001,2.980050e+002,2.979968e+002,1,0,4.364583e-001,5.336161e-001,5.336161e-001,3.068746e-001,2.874765e-001,5.189165e-001,2.921750e-001,2.727769e-001,1.162892e-005,1.162892e-005,,,,,,,,,,,,,,,,,,,,
1406850633.515,,-1.500000e+001,2.979968e+002,2.980050e+002,1,0,1.900551e+000,-6.582842e-001,-6.582842e-001,-1.718982e+000,-1.721404e+000,-6.220302e-001,-1.682728e+000,-1.685150e+000,-1.434576e-005,-1.434576e-005,,,,,,,,,,,,,,,,,,,,
1406850633.515,,-1.500000e+001,2.979968e+002,2.980050e+002,1,0,3.810462e+000,1.588031e+000,1.588031e+000,6.314951e-001,5.249106e-001,1.631179e+000,6.746430e-001,5.680585e-001,3.460740e-005,3.460740e-005,,,,,,,,,,,,,,,,,,,,
1406850651.312,,-1.500000e+001,2.979968e+002,2.979885e+002,1,0,5.568220e-001,1.822413e+000,1.822413e+000,7.129132e-001,6.622748e-001,1.778458e+000,6.689587e-001,6.183203e-001,3.971521e-005,3.971521e-005,,,,,,,,,,,,,,,,,,,,
1406850668.625,,-1.500000e+001,2.979968e+002,2.979968e+002,1,0,1.719364e+000,-3.163244e-001,-3.163244e-001,-1.566214e+000,-1.569888e+000,-3.013295e-001,-1.551220e+000,-1.554894e+000,-6.893546e-006,-6.893546e-006,,,,,,,,,,,,,,,,,,,,
1406850668.625,,-1.500000e+001,2.979968e+002,2.979968e+002,1,0,3.894003e+000,1.750542e+000,1.750542e+000,5.796421e-001,4.969776e-001,1.823916e+000,6.530163e-001,5.703518e-001,3.814894e-005,3.814894e-005,,,,,,,,,,,,,,,,,,,,
1406850793.375,,-2.000000e+001,2.980050e+002,2.979968e+002,1,0,6.835808e-001,1.894284e+000,1.894284e+000,7.000303e-001,6.251520e-001,1.824875e+000,6.306211e-001,5.557429e-001,4.128145e-005,4.128145e-005,,,,,,,,,,,,,,,,,,,,
1406850811.671,,-2.000000e+001,2.979968e+002,2.979968e+002,1,0,1.539336e+000,6.897183e-002,6.897184e-002,-1.285310e+000,-1.293882e+000,5.745606e-002,-1.296826e+000,-1.305398e+000,1.503078e-006,1.503078e-006,,,,,,,,,,,,,,,,,,,,
1406850811.671,,-2.000000e+001,2.979968e+002,2.979968e+002,1,0,3.953963e+000,1.849727e+000,1.849727e+000,6.183117e-001,4.868729e-001,1.930470e+000,6.990544e-001,5.676156e-001,4.031043e-005,4.031043e-005,,,,,,,,,,,,,,,,,,,,
1406850829.906,,-2.000000e+001,2.980050e+002,2.979968e+002,1,0,8.162252e-001,1.814631e+000,1.814631e+000,5.070015e-001,4.434865e-001,1.728385e+000,4.207557e-001,3.572407e-001,3.954559e-005,3.954559e-005,,,,,,,,,,,,,,,,,,,,
1406850947.156,,-2.500000e+001,2.979968e+002,2.980050e+002,1,0,1.361832e+000,4.550310e-001,4.550310e-001,-7.998771e-001,-8.156471e-001,4.063607e-001,-8.485474e-001,-8.643174e-001,9.916323e-006,9.916323e-006,,,,,,,,,,,,,,,,,,,,
1406850947.156,,-2.500000e+001,2.979968e+002,2.980050e+002,1,0,3.987971e+000,1.728721e+000,1.728721e+000,6.433398e-001,4.580430e-001,1.803702e+000,7.183208e-001,5.330241e-001,3.767338e-005,3.767338e-005,,,,,,,,,,,,,,,,,,,,
1406850965.390,,-2.500000e+001,2.980050e+002,2.979968e+002,1,0,9.544427e-001,1.567888e+000,1.567888e+000,2.712117e-001,1.780423e-001,1.478245e+000,1.815680e-001,8.839858e-002,3.416841e-005,3.416841e-005,,,,,,,,,,,,,,,,,,,,
1406850983.125,,-2.500000e+001,2.979968e+002,2.979968e+002,1,0,1.187856e+000,1.028169e+000,1.028169e+000,-3.039772e-001,-3.216027e-001,9.471336e-001,-3.850122e-001,-4.026377e-001,2.240650e-005,2.240650e-005,,,,,,,,,,,,,,,,,,,,
1406850983.125,,-2.500000e+001,2.979968e+002,2.979968e+002,1,0,3.994917e+000,1.828669e+000,1.828669e+000,6.481025e-001,4.788978e-001,1.901030e+000,7.204632e-001,5.512584e-001,3.985151e-005,3.985151e-005,,,,,,,,,,,,,,,,,,,,
1406851099.625,,-3.000000e+001,2.979968e+002,2.980050e+002,1,0,1.098711e+000,1.110416e+000,1.110416e+000,-6.774354e-002,-1.957029e-001,1.040934e+000,-1.372257e-001,-2.651851e-001,2.419887e-005,2.419887e-005,,,,,,,,,,,,,,,,,,,,
1406851118.109,,-3.000000e+001,2.979968e+002,2.979968e+002,1,0,1.018636e+000,1.533250e+000,1.533250e+000,1.597565e-001,1.322956e-001,1.443979e+000,7.048508e-002,4.302418e-002,3.341353e-005,3.341353e-005,,,,,,,,,,,,,,,,,,,,
1406851118.109,,-3.000000e+001,2.979968e+002,2.979968e+002,1,0,3.975082e+000,1.914731e+000,1.914731e+000,7.380409e-001,5.137769e-001,1.977581e+000,8.008901e-001,5.766262e-001,4.172701e-005,4.172701e-005,,,,,,,,,,,,,,,,,,,,
1406851135.593,,-3.000000e+001,2.979885e+002,2.979968e+002,1,0,1.249835e+000,7.722709e-001,7.722709e-001,-5.187618e-001,-6.399141e-001,7.416528e-001,-5.493799e-001,-6.705322e-001,1.682981e-005,1.682981e-005,,,,,,,,,,,,,,,,,,,,
1406851251.859,,-3.500000e+001,2.979968e+002,2.979968e+002,1,0,8.559015e-001,1.747032e+000,1.747032e+000,5.586092e-001,5.179664e-001,1.671212e+000,4.827895e-001,4.421467e-001,3.807239e-005,3.807239e-005,,,,,,,,,,,,,,,,,,,,
1406851251.859,,-3.500000e+001,2.979968e+002,2.979968e+002,1,0,3.930350e+000,1.766106e+000,1.766106e+000,8.273467e-001,5.370405e-001,1.811877e+000,8.731176e-001,5.828114e-001,3.848807e-005,3.848807e-005,,,,,,,,,,,,,,,,,,,,
1406851269.843,,-3.500000e+001,2.980050e+002,2.979968e+002,1,0,1.408092e+000,6.347850e-002,6.347850e-002,-1.037096e+000,-1.198608e+000,8.898836e-002,-1.011586e+000,-1.173098e+000,1.383362e-006,1.383362e-006,,,,,,,,,,,,,,,,,,,,
1406851288.578,,-3.500000e+001,2.980050e+002,2.980050e+002,1,0,6.999924e-001,2.104709e+000,2.104709e+000,8.271921e-001,7.861046e-001,2.053544e+000,7.760273e-001,7.349397e-001,4.586711e-005,4.586711e-005,,,,,,,,,,,,,,,,,,,,
1406851288.578,,-3.500000e+001,2.980050e+002,2.980050e+002,1,0,3.863307e+000,1.954863e+000,1.954863e+000,8.981919e-001,6.362587e-001,1.984776e+000,9.281054e-001,6.661721e-001,4.260157e-005,4.260157e-005,,,,,,,,,,,,,,,,,,,,
1406851407.062,,-4.000000e+001,2.979968e+002,2.979968e+002,1,0,1.573379e+000,-7.510605e-001,-7.510605e-001,-1.586049e+000,-1.794943e+000,-6.819535e-001,-1.516942e+000,-1.725836e+000,-1.636756e-005,-1.636756e-005,,,,,,,,,,,,,,,,,,,,
1406851425.046,,-4.000000e+001,2.979968e+002,2.979968e+002,1,0,5.530549e-001,1.982482e+000,1.982482e+000,9.754940e-001,9.156154e-001,1.965950e+000,9.589620e-001,8.990835e-001,4.320345e-005,4.320345e-005,,,,,,,,,,,,,,,,,,,,
1406851425.046,,-4.000000e+001,2.979968e+002,2.979968e+002,1,0,3.777620e+000,1.696371e+000,1.696371e+000,9.754692e-001,6.295043e-001,1.710108e+000,9.892060e-001,6.432412e-001,3.696834e-005,3.696834e-005,,,,,,,,,,,,,,,,,,,,
1406851443.281,,-4.000000e+001,2.979968e+002,2.979968e+002,1,0,1.744998e+000,-1.098971e+000,-1.098971e+000,-2.044091e+000,-2.243990e+000,-1.033274e+000,-1.978395e+000,-2.178293e+000,-2.394945e-005,-2.394945e-005,,,,,,,,,,,,,,,,,,,,
1406851560.328,,-4.500000e+001,2.979968e+002,2.980050e+002,1,0,4.173294e-001,1.637928e+000,1.637928e+000,1.021264e+000,9.338890e-001,1.643433e+000,1.026769e+000,9.393939e-001,3.569470e-005,3.569470e-005,,,,,,,,,,,,,,,,,,,,
1406851560.328,,-4.500000e+001,2.979968e+002,2.980050e+002,1,0,3.677111e+000,1.263161e+000,1.263161e+000,1.022209e+000,5.591217e-001,1.267695e+000,1.026744e+000,5.636560e-001,2.752755e-005,2.752755e-005,,,,,,,,,,,,,,,,,,,,
1406851578.812,,-4.500000e+001,2.980132e+002,2.980050e+002,1,0,1.921607e+000,-1.803491e+000,-1.803491e+000,-2.312939e+000,-2.584801e+000,-1.784167e+000,-2.293614e+000,-2.565476e+000,-3.930275e-005,-3.930275e-005,,,,,,,,,,,,,,,,,,,,
1406851596.343,,-4.500000e+001,2.980050e+002,2.979968e+002,1,0,2.957061e-001,1.708121e+000,1.708121e+000,9.842708e-001,8.951086e-001,1.728328e+000,1.004478e+000,9.153156e-001,3.722438e-005,3.722438e-005,,,,,,,,,,,,,,,,,,,,
1406851596.343,,-4.500000e+001,2.980050e+002,2.979968e+002,1,0,3.565309e+000,1.391491e+000,1.391491e+000,1.016184e+000,5.784791e-001,1.381876e+000,1.006568e+000,5.688635e-001,3.032420e-005,3.032420e-005,,,,,,,,,,,,,,,,,,,,
1406851714.609,,-5.000000e+001,2.979968e+002,2.980050e+002,1,0,2.101335e+000,-2.295145e+000,-2.295145e+000,-2.308170e+000,-2.654946e+000,-2.324201e+000,-2.337227e+000,-2.684002e+000,-5.001712e-005,-5.001712e-005,,,,,,,,,,,,,,,,,,,,
1406851732.093,,-5.000000e+001,2.979968e+002,2.980050e+002,1,0,1.913944e-001,1.228217e+000,1.228217e+000,9.138573e-001,7.921491e-001,1.259691e+000,9.453307e-001,8.236225e-001,2.676603e-005,2.676603e-005,,,,,,,,,,,,,,,,,,,,
1406851732.093,,-5.000000e+001,2.979968e+002,2.980050e+002,1,0,3.444992e+000,8.099613e-001,8.099613e-001,9.317225e-001,3.738929e-001,7.922830e-001,9.140442e-001,3.562147e-001,1.765115e-005,1.765115e-005,,,,,,,,,,,,,,,,,,,,
1406851749.578,,-5.000000e+001,2.980050e+002,2.979968e+002,1,0,2.282376e+000,-1.791742e+000,-1.791742e+000,-2.016323e+000,-2.344695e+000,-1.841670e+000,-2.066252e+000,-2.394624e+000,-3.904667e-005,-3.904667e-005,,,,,,,,,,,,,,,,,,,,
1406851898.812,,-7.500000e+001,2.979968e+002,2.980050e+002,1,0,1.077658e-001,-5.458235e-001,-5.458235e-001,8.723789e-002,3.252125e-002,-5.441036e-001,8.895778e-002,3.424114e-002,-1.189488e-004,-1.189488e-004,,,,,,,,,,,,,,,,,,,,
1406851898.812,,-7.500000e+001,2.979968e+002,2.980050e+002,1,0,3.318107e+000,-7.400739e-001,-7.400739e-001,7.397334e-002,-1.617291e-001,-7.404720e-001,7.357518e-002,-1.621273e-001,-1.612808e-004,-1.612808e-004,,,,,,,,,,,,,,,,,,,,
1406851915.546,,-7.500000e+001,2.980050e+002,2.980050e+002,1,0,2.462504e+000,-8.230842e-001,-8.230842e-001,-1.606657e-001,-2.986665e-001,-8.271393e-001,-1.647208e-001,-3.027217e-001,-1.793709e-004,-1.793709e-004,,,,,,,,,,,,,,,,,,,,
1406851933.531,,-7.500000e+001,2.980050e+002,2.979968e+002,1,0,4.783098e-002,-4.455702e-001,-4.455702e-001,8.152375e-002,2.964115e-002,-4.439570e-001,8.313698e-002,3.125438e-002,-9.710103e-005,-9.710103e-005,,,,,,,,,,,,,,,,,,,,
1406851933.531,,-7.500000e+001,2.980050e+002,2.979968e+002,1,0,3.185539e+000,-6.404309e-001,-6.404309e-001,4.601675e-002,-1.652195e-001,-6.404883e-001,4.595935e-002,-1.652769e-001,-1.395661e-004,-1.395661e-004,,,,,,,,,,,,,,,,,,,,
1406852064.765,,-1.000000e+002,2.979968e+002,2.979968e+002,1,0,2.640254e+000,-2.737815e+000,-2.737815e+000,-1.134790e-001,-5.588460e-001,-2.735714e+000,-1.113778e-001,-5.567448e-001,-5.966379e-004,-5.966379e-004,,,,,,,,,,,,,,,,,,,,
1406852083.000,,-1.000000e+002,2.980050e+002,2.979968e+002,1,0,1.388165e-002,-1.944334e+000,-1.944334e+000,8.274769e-002,-7.907879e-002,-1.946106e+000,8.097600e-002,-8.085048e-002,-4.237187e-004,-4.237187e-004,,,,,,,,,,,,,,,,,,,,
1406852083.000,,-1.000000e+002,2.980050e+002,2.979968e+002,1,0,3.047356e+000,-2.483444e+000,-2.483444e+000,7.540813e-003,-6.181883e-001,-2.479743e+000,1.124202e-002,-6.144871e-001,-5.412040e-004,-5.412040e-004,,,,,,,,,,,,,,,,,,,,
1406852100.734,,-1.000000e+002,2.980050e+002,2.979968e+002,1,0,2.814179e+000,-1.990417e+000,-1.990417e+000,-5.956769e-002,-4.041103e-001,-1.987295e+000,-5.644512e-002,-4.009877e-001,-4.337613e-004,-4.337613e-004,,,,,,,,,,,,,,,,,,,,
1406852243.468,,-7.500000e+001,2.979968e+002,2.979968e+002,1,0,6.921424e-003,1.550188e+000,1.550188e+000,7.927876e-001,6.517811e-001,1.555460e+000,7.980598e-001,6.570532e-001,3.378251e-005,3.378251e-005,,,,,,,,,,,,,,,,,,,,
1406852243.468,,-7.500000e+001,2.979968e+002,2.979968e+002,1,0,2.903009e+000,5.066073e-002,5.066073e-002,-3.277843e-001,-8.477459e-001,8.571709e-002,-2.927279e-001,-8.126895e-001,1.104025e-006,1.104025e-006,,,,,,,,,,,,,,,,,,,,
1406852261.468,,-7.500000e+001,2.979968e+002,2.979968e+002,1,0,2.983145e+000,6.212043e-001,6.212043e-001,-7.104159e-002,-3.831842e-001,6.298845e-001,-6.236131e-002,-3.745039e-001,1.353761e-005,1.353761e-005,,,,,,,,,,,,,,,,,,,,
1406852280.203,,-7.500000e+001,2.980050e+002,2.980050e+002,1,0,2.670703e-002,1.671346e+000,1.671346e+000,8.119853e-001,6.697081e-001,1.677118e+000,8.177570e-001,6.754798e-001,3.642286e-005,3.642286e-005,,,,,,,,,,,,,,,,,,,,
1406852280.203,,-7.500000e+001,2.980050e+002,2.980050e+002,1,0,2.751938e+000,-2.957244e-001,-2.957244e-001,-7.952076e-001,-1.297362e+000,-2.530088e-001,-7.524920e-001,-1.254647e+000,-6.444582e-006,-6.444582e-006,,,,,,,,,,,,,,,,,,,,
1406852409.687,,-5.000000e+001,2.980132e+002,2.979968e+002,1,0,3.146197e+000,2.169866e+000,2.169866e+000,3.813506e-001,2.491356e-001,2.155886e+000,3.673705e-001,2.351555e-001,4.728698e-005,4.728698e-005,,,,,,,,,,,,,,,,,,,,
1406852427.187,,-5.000000e+001,2.980050e+002,2.979968e+002,1,0,7.152486e-002,2.740104e+000,2.740104e+000,8.297526e-001,7.714634e-001,2.764384e+000,8.540317e-001,7.957425e-001,5.971394e-005,5.971394e-005,,,,,,,,,,,,,,,,,,,,
1406852427.187,,-5.000000e+001,2.980050e+002,2.979968e+002,1,0,2.593692e+000,5.034028e-001,5.034028e-001,-1.267703e+000,-1.465238e+000,5.334843e-001,-1.237621e+000,-1.435157e+000,1.097045e-005,1.097045e-005,,,,,,,,,,,,,,,,,,,,
1406852444.671,,-5.000000e+001,2.979968e+002,2.980050e+002,1,0,3.301895e+000,2.561571e+000,2.561571e+000,7.176381e-001,5.951871e-001,2.549645e+000,7.057122e-001,5.832611e-001,5.582324e-005,5.582324e-005,,,,,,,,,,,,,,,,,,,,
1406852553.406,,-4.500000e+001,2.979968e+002,2.979968e+002,1,0,1.385441e-001,2.812281e+000,2.812281e+000,8.954023e-001,8.385539e-001,2.830600e+000,9.137214e-001,8.568730e-001,6.128688e-005,6.128688e-005,,,,,,,,,,,,,,,,,,,,
1406852553.406,,-4.500000e+001,2.979968e+002,2.979968e+002,1,0,2.428354e+000,3.265480e-002,3.265481e-002,-1.755567e+000,-1.941072e+000,4.940119e-002,-1.738820e+000,-1.924326e+000,7.116328e-007,7.116328e-007,,,,,,,,,,,,,,,,,,,,
1406852571.953,,-4.500000e+001,2.980050e+002,2.979968e+002,1,0,3.448728e+000,2.834864e+000,2.834864e+000,9.272853e-001,8.142905e-001,2.836867e+000,9.292876e-001,8.162928e-001,6.177904e-005,6.177904e-005,,,,,,,,,,,,,,,,,,,,
1406852590.437,,-4.500000e+001,2.979968e+002,2.979968e+002,1,0,2.242054e-001,3.009735e+000,3.009735e+000,9.768433e-001,9.245205e-001,3.015953e+000,9.830608e-001,9.307380e-001,6.558993e-005,6.558993e-005,,,,,,,,,,,,,,,,,,,,
1406852590.437,,-4.500000e+001,2.979968e+002,2.979968e+002,1,0,2.256665e+000,-2.331614e-001,-2.331614e-001,-2.153559e+000,-2.318376e+000,-2.477022e-001,-2.168100e+000,-2.332917e+000,-5.081191e-006,-5.081191e-006,,,,,,,,,,,,,,,,,,,,
1406852707.421,,-4.000000e+001,2.979968e+002,2.979968e+002,1,0,3.584444e+000,2.955413e+000,2.955412e+000,1.024263e+000,9.182522e-001,2.963806e+000,1.032657e+000,9.266462e-001,6.440612e-005,6.440612e-005,,,,,,,,,,,,,,,,,,,,
1406852725.203,,-4.000000e+001,2.980050e+002,2.979968e+002,1,0,3.246891e-001,3.059023e+000,3.059023e+000,1.030827e+000,9.789152e-001,3.062572e+000,1.034376e+000,9.824641e-001,6.666406e-005,6.666406e-005,,,,,,,,,,,,,,,,,,,,
1406852743.203,,-4.000000e+001,2.980050e+002,2.979968e+002,1,0,2.080131e+000,-2.494888e-001,-2.494888e-001,-2.395033e+000,-2.395033e+000,-2.420230e-001,-2.387568e+000,-2.387568e+000,-5.437010e-006,-5.437010e-006,,,,,,,,,,,,,,,,,,,,
1406852743.203,,-4.000000e+001,2.980050e+002,2.979968e+002,1,0,3.706146e+000,3.085421e+000,3.085421e+000,1.035173e+000,9.398768e-001,3.095342e+000,1.045094e+000,9.497979e-001,6.723936e-005,6.723936e-005,,,,,,,,,,,,,,,,,,,,
1406852866.937,,-3.500000e+001,2.979968e+002,2.979968e+002,1,0,4.365320e-001,3.080539e+000,3.080538e+000,1.049874e+000,1.000450e+000,3.072788e+000,1.042125e+000,9.927001e-001,6.713298e-005,6.713298e-005,,,,,,,,,,,,,,,,,,,,
1406852884.671,,-3.500000e+001,2.980050e+002,2.979968e+002,1,0,1.900244e+000,-2.386547e-001,-2.386547e-001,-2.316861e+000,-2.318940e+000,-2.204665e-001,-2.298673e+000,-2.300752e+000,-5.200910e-006,-5.200910e-006,,,,,,,,,,,,,,,,,,,,
1406852884.671,,-3.500000e+001,2.980050e+002,2.979968e+002,1,0,3.810438e+000,2.967925e+000,2.967925e+000,9.791143e-001,8.876398e-001,2.985839e+000,9.970279e-001,9.055533e-001,6.467884e-005,6.467884e-005,,,,,,,,,,,,,,,,,,,,
1406852902.906,,-3.500000e+001,2.979968e+002,2.980050e+002,1,0,5.568686e-001,3.123875e+000,3.123875e+000,1.007848e+000,9.649534e-001,3.099714e+000,9.836873e-001,9.407923e-001,6.807738e-005,6.807738e-005,,,,,,,,,,,,,,,,,,,,
1406853019.453,,-3.000000e+001,2.979968e+002,2.980050e+002,1,0,1.719358e+000,1.420637e-001,1.420637e-001,-1.961359e+000,-1.965480e+000,1.708291e-001,-1.932593e+000,-1.936714e+000,3.095940e-006,3.095940e-006,,,,,,,,,,,,,,,,,,,,
1406853019.453,,-3.000000e+001,2.979968e+002,2.980050e+002,1,0,3.894074e+000,2.927030e+000,2.927030e+000,9.122040e-001,8.194871e-001,2.948410e+000,9.335837e-001,8.408668e-001,6.378766e-005,6.378766e-005,,,,,,,,,,,,,,,,,,,,
1406853037.218,,-3.000000e+001,2.979968e+002,2.980050e+002,1,0,6.837456e-001,2.996918e+000,2.996918e+000,8.794804e-001,8.357539e-001,2.950764e+000,8.333271e-001,7.896006e-001,6.531069e-005,6.531069e-005,,,,,,,,,,,,,,,,,,,,
1406853055.453,,-3.000000e+001,2.979885e+002,2.979968e+002,1,0,1.539264e+000,7.260354e-001,7.260354e-001,-1.437523e+000,-1.442463e+000,7.444417e-001,-1.419116e+000,-1.424057e+000,1.582221e-005,1.582221e-005,,,,,,,,,,,,,,,,,,,,
1406853055.453,,-3.000000e+001,2.979885e+002,2.979968e+002,1,0,3.953980e+000,2.949461e+000,2.949461e+000,8.567204e-001,7.809627e-001,2.974078e+000,8.813371e-001,8.055794e-001,6.427649e-005,6.427649e-005,,,,,,,,,,,,,,,,,,,,
1406853172.687,,-2.500000e+001,2.979885e+002,2.979968e+002,1,0,8.163171e-001,2.713401e+000,2.713401e+000,6.606739e-001,6.190193e-001,2.647030e+000,5.943037e-001,5.526490e-001,5.913214e-005,5.913214e-005,,,,,,,,,,,,,,,,,,,,
1406853190.453,,-2.500000e+001,2.980050e+002,2.979968e+002,1,0,1.361716e+000,1.297494e+000,1.297494e+000,-8.421407e-001,-8.487711e-001,1.275095e+000,-8.645399e-001,-8.711703e-001,2.827582e-005,2.827582e-005,,,,,,,,,,,,,,,,,,,,
1406853190.453,,-2.500000e+001,2.980050e+002,2.979968e+002,1,0,3.987986e+000,2.884610e+000,2.884609e+000,8.162518e-001,7.383440e-001,2.913845e+000,8.454874e-001,7.675796e-001,6.286323e-005,6.286323e-005,,,,,,,,,,,,,,,,,,,,
1406853208.187,,-2.500000e+001,2.979968e+002,2.979885e+002,1,0,9.545485e-001,2.484207e+000,2.484207e+000,3.553673e-001,3.164599e-001,2.409826e+000,2.809867e-001,2.420793e-001,5.413740e-005,5.413740e-005,,,,,,,,,,,,,,,,,,,,
1406853325.687,,-2.000000e+001,2.980050e+002,2.979968e+002,1,0,1.187369e+000,1.825312e+000,1.825312e+000,-2.799672e-001,-2.882365e-001,1.762261e+000,-3.430185e-001,-3.512877e-001,3.977837e-005,3.977837e-005,,,,,,,,,,,,,,,,,,,,
1406853325.687,,-2.000000e+001,2.980050e+002,2.979968e+002,1,0,3.994845e+000,2.835322e+000,2.835322e+000,8.011583e-001,7.217736e-001,2.867825e+000,8.336612e-001,7.542765e-001,6.178916e-005,6.178916e-005,,,,,,,,,,,,,,,,,,,,
1406853343.203,,-2.000000e+001,2.979968e+002,2.980050e+002,1,0,1.098829e+000,2.056185e+000,2.056185e+000,-3.427248e-002,-7.658243e-002,1.995656e+000,-9.480111e-002,-1.371111e-001,4.480969e-005,4.480969e-005,,,,,,,,,,,,,,,,,,,,
1406853360.937,,-2.000000e+001,2.979885e+002,2.979968e+002,1,0,1.018685e+000,2.351146e+000,2.351146e+000,1.912290e-001,1.832156e-001,2.277670e+000,1.177534e-001,1.097400e-001,5.123768e-005,5.123768e-005,,,,,,,,,,,,,,,,,,,,
1406853360.937,,-2.000000e+001,2.979885e+002,2.979968e+002,1,0,3.975128e+000,2.918943e+000,2.918943e+000,8.164554e-001,7.510126e-001,2.954683e+000,8.521958e-001,7.867529e-001,6.361148e-005,6.361148e-005,,,,,,,,,,,,,,,,,,,,
1406853472.921,,-1.500000e+001,2.980050e+002,2.980050e+002,1,0,1.249968e+000,1.675161e+000,1.675161e+000,-4.972218e-001,-5.296379e-001,1.649656e+000,-5.227271e-001,-5.551432e-001,3.650620e-005,3.650620e-005,,,,,,,,,,,,,,,,,,,,
1406853491.218,,-1.500000e+001,2.980050e+002,2.979968e+002,1,0,8.555375e-001,2.760552e+000,2.760552e+000,5.769460e-001,5.681355e-001,2.688285e+000,5.046797e-001,4.958692e-001,6.015974e-005,6.015974e-005,,,,,,,,,,,,,,,,,,,,
1406853491.218,,-1.500000e+001,2.980050e+002,2.979968e+002,1,0,3.930299e+000,2.979217e+000,2.979217e+000,8.497331e-001,7.868006e-001,3.016640e+000,8.871565e-001,8.242240e-001,6.492504e-005,6.492504e-005,,,,,,,,,,,,,,,,,,,,
1406853509.453,,-1.500000e+001,2.979968e+002,2.979968e+002,1,0,1.408194e+000,1.147191e+000,1.147191e+000,-1.025390e+000,-1.059988e+000,1.175727e+000,-9.968544e-001,-1.031452e+000,2.500033e-005,2.500033e-005,,,,,,,,,,,,,,,,,,,,
1406853626.703,,-1.000000e+001,2.979968e+002,2.979968e+002,1,0,6.999273e-001,3.009583e+000,3.009583e+000,8.417314e-001,8.326993e-001,2.956163e+000,7.883115e-001,7.792795e-001,6.558682e-005,6.558682e-005,,,,,,,,,,,,,,,,,,,,
1406853626.703,,-1.000000e+001,2.979968e+002,2.979968e+002,1,0,3.863299e+000,3.022401e+000,3.022401e+000,9.030967e-001,8.455172e-001,3.053169e+000,9.338656e-001,8.762860e-001,6.586615e-005,6.586615e-005,,,,,,,,,,,,,,,,,,,,
1406853643.937,,-1.000000e+001,2.979968e+002,2.980050e+002,1,0,1.573503e+000,5.560473e-001,5.560473e-001,-1.562412e+000,-1.596357e+000,6.312582e-001,-1.487201e+000,-1.521146e+000,1.211775e-005,1.211775e-005,,,,,,,,,,,,,,,,,,,,
1406853662.171,,-1.000000e+001,2.980050e+002,2.979885e+002,1,0,5.530524e-001,3.159887e+000,3.159886e+000,9.802186e-001,9.714913e-001,3.138644e+000,9.589762e-001,9.502490e-001,6.886234e-005,6.886234e-005,,,,,,,,,,,,,,,,,,,,
1406853662.171,,-1.000000e+001,2.980050e+002,2.979885e+002,1,0,3.777614e+000,3.108157e+000,3.108158e+000,9.701868e-001,9.197626e-001,3.124774e+000,9.868032e-001,9.363790e-001,6.773503e-005,6.773503e-005,,,,,,,,,,,,,,,,,,,,
1406853780.437,,-5.000000e+000,2.979968e+002,2.979968e+002,1,0,1.745075e+000,1.194800e-001,1.194800e-001,-2.011832e+000,-2.041916e+000,1.971382e-001,-1.934173e+000,-1.964258e+000,2.603788e-006,2.603788e-006,,,,,,,,,,,,,,,,,,,,
1406853798.718,,-5.000000e+000,2.980050e+002,2.980050e+002,1,0,4.172215e-001,3.157445e+000,3.157445e+000,1.006563e+000,9.972098e-001,3.157466e+000,1.006584e+000,9.972310e-001,6.880916e-005,6.880916e-005,,,,,,,,,,,,,,,,,,,,
1406853798.718,,-5.000000e+000,2.980050e+002,2.980050e+002,1,0,3.677027e+000,3.116550e+000,3.116550e+000,1.005887e+000,9.563150e-001,3.117221e+000,1.006557e+000,9.569857e-001,6.791796e-005,6.791796e-005,,,,,,,,,,,,,,,,,,,,
1406853816.468,,-5.000000e+000,2.980050e+002,2.980050e+002,1,0,1.921691e+000,-9.552293e-002,-9.552293e-002,-2.276816e+000,-2.303921e+000,-6.133093e-002,-2.242624e+000,-2.269729e+000,-2.081700e-006,-2.081700e-006,,,,,,,,,,,,,,,,,,,,
1406853934.218,,0.000000e+000,2.980050e+002,2.979968e+002,1,0,2.956266e-001,3.092593e+000,3.092593e+000,9.545164e-001,9.457386e-001,3.110494e+000,9.724174e-001,9.636395e-001,6.739589e-005,6.739589e-005,,,,,,,,,,,,,,,,,,,,
1406853934.218,,0.000000e+000,2.980050e+002,2.979968e+002,1,0,3.565270e+000,3.095492e+000,3.095492e+000,9.917291e-001,9.486377e-001,3.078034e+000,9.742704e-001,9.311790e-001,6.745908e-005,6.745908e-005,,,,,,,,,,,,,,,,,,,,
1406853950.984,,0.000000e+000,2.979968e+002,2.979968e+002,1,0,2.101410e+000,-1.123081e-001,-1.123081e-001,-2.250922e+000,-2.279452e+000,-1.180340e-001,-2.256648e+000,-2.285178e+000,-2.447495e-006,-2.447495e-006,,,,,,,,,,,,,,,,,,,,
1406853969.046,,0.000000e+000,2.979968e+002,2.980050e+002,1,0,1.913684e-001,3.068789e+000,3.068789e+000,8.665287e-001,8.579044e-001,3.111355e+000,9.090946e-001,9.004703e-001,6.687713e-005,6.687713e-005,,,,,,,,,,,,,,,,,,,,
1406853969.046,,0.000000e+000,2.979968e+002,2.980050e+002,1,0,3.444983e+000,3.085421e+000,3.085421e+000,9.140650e-001,8.745370e-001,3.048929e+000,8.775731e-001,8.380451e-001,6.723960e-005,6.723960e-005,,,,,,,,,,,,,,,,,,,,
1406854086.328,,5.000000e+000,2.979968e+002,2.980050e+002,1,0,2.282413e+000,1.387066e-001,1.387066e-001,-1.953778e+000,-1.976759e+000,1.146602e-001,-1.977825e+000,-2.000805e+000,3.022788e-006,3.022788e-006,,,,,,,,,,,,,,,,,,,,
1406854104.093,,5.000000e+000,2.980050e+002,2.979968e+002,1,0,1.077364e-001,2.883847e+000,2.883847e+000,7.599081e-001,7.504139e-001,2.954898e+000,8.309597e-001,8.214655e-001,6.284672e-005,6.284672e-005,,,,,,,,,,,,,,,,,,,,
1406854104.093,,5.000000e+000,2.980050e+002,2.979968e+002,1,0,3.318111e+000,2.842341e+000,2.842341e+000,7.498067e-001,7.089088e-001,2.782114e+000,6.895788e-001,6.486809e-001,6.194221e-005,6.194221e-005,,,,,,,,,,,,,,,,,,,,
1406854121.859,,5.000000e+000,2.980050e+002,2.979968e+002,1,0,2.462401e+000,6.801050e-001,6.801050e-001,-1.489451e+000,-1.510934e+000,6.407551e-001,-1.528800e+000,-1.550284e+000,1.482130e-005,1.482130e-005,,,,,,,,,,,,,,,,,,,,
1406854244.609,,1.000000e+001,2.980050e+002,2.979968e+002,1,0,4.785569e-002,2.750481e+000,2.750481e+000,6.733077e-001,6.640213e-001,2.843896e+000,7.667232e-001,7.574368e-001,5.994030e-005,5.994030e-005,,,,,,,,,,,,,,,,,,,,
1406854244.609,,1.000000e+001,2.980050e+002,2.979968e+002,1,0,3.185811e+000,2.553941e+000,2.553941e+000,5.052910e-001,4.674821e-001,2.477040e+000,4.283893e-001,3.905804e-001,5.565718e-005,5.565718e-005,,,,,,,,,,,,,,,,,,,,
1406854263.593,,1.000000e+001,2.979968e+002,2.980050e+002,1,0,2.639859e+000,1.140629e+000,1.140629e+000,-9.493952e-001,-9.684005e-001,1.089502e+000,-1.000523e+000,-1.019528e+000,2.485735e-005,2.485735e-005,,,,,,,,,,,,,,,,,,,,
1406854281.828,,1.000000e+001,2.979968e+002,2.979968e+002,1,0,1.384044e-002,2.792138e+000,2.792138e+000,6.368787e-001,6.299112e-001,2.891097e+000,7.358370e-001,7.288694e-001,6.084813e-005,6.084813e-005,,,,,,,,,,,,,,,,,,,,
1406854281.828,,1.000000e+001,2.979968e+002,2.979968e+002,1,0,3.047486e+000,2.319559e+000,2.319559e+000,1.842734e-001,1.573322e-001,2.247334e+000,1.120483e-001,8.510709e-002,5.054937e-005,5.054937e-005,,,,,,,,,,,,,,,,,,,,
1406854398.562,,1.500000e+001,2.979968e+002,2.979968e+002,1,0,2.813890e+000,1.655171e+000,1.655171e+000,-4.128682e-001,-4.267228e-001,1.574483e+000,-4.935569e-001,-5.074115e-001,3.607057e-005,3.607057e-005,,,,,,,,,,,,,,,,,,,,
1406854415.593,,1.500000e+001,2.980050e+002,2.980050e+002,1,0,6.968851e-003,2.658925e+000,2.658925e+000,6.047933e-001,5.974305e-001,2.772166e+000,7.180342e-001,7.106714e-001,5.794503e-005,5.794503e-005,,,,,,,,,,,,,,,,,,,,
1406854415.593,,1.500000e+001,2.980050e+002,2.980050e+002,1,0,2.903164e+000,1.832179e+000,1.832179e+000,-2.021657e-001,-2.293159e-001,1.781295e+000,-2.530495e-001,-2.801996e-001,3.992803e-005,3.992803e-005,,,,,,,,,,,,,,,,,,,,
1406854433.328,,1.500000e+001,2.980050e+002,2.979968e+002,1,0,2.982923e+000,2.167730e+000,2.167730e+000,5.323014e-002,4.129791e-002,2.066157e+000,-4.834285e-002,-6.027508e-002,4.724058e-005,4.724058e-005,,,,,,,,,,,,,,,,,,,,
1406854551.093,,2.000000e+001,2.979968e+002,2.979885e+002,1,0,2.671297e-002,2.619861e+000,2.619861e+000,5.994161e-001,5.936768e-001,2.739671e+000,7.192257e-001,7.134864e-001,5.709370e-005,5.709370e-005,,,,,,,,,,,,,,,,,,,,
1406854551.093,,2.000000e+001,2.979968e+002,2.979885e+002,1,0,2.752098e+000,1.370434e+000,1.370434e+000,-6.354946e-001,-6.557509e-001,1.356472e+000,-6.494559e-001,-6.697122e-001,2.986537e-005,2.986537e-005,,,,,,,,,,,,,,,,,,,,
1406854569.359,,2.000000e+001,2.980050e+002,2.979968e+002,1,0,3.145893e+000,2.464980e+000,2.464980e+000,4.415075e-001,4.294095e-001,2.353674e+000,3.302011e-001,3.181031e-001,5.371842e-005,5.371842e-005,,,,,,,,,,,,,,,,,,,,
1406854587.593,,2.000000e+001,2.980050e+002,2.979968e+002,1,0,7.141288e-002,2.759636e+000,2.759636e+000,6.528897e-001,6.503296e-001,2.864779e+000,7.580321e-001,7.554719e-001,6.013976e-005,6.013976e-005,,,,,,,,,,,,,,,,,,,,
1406854587.593,,2.000000e+001,2.980050e+002,2.979968e+002,1,0,2.593741e+000,9.895627e-001,9.895627e-001,-1.111068e+000,-1.119744e+000,1.012212e+000,-1.088419e+000,-1.097095e+000,2.156519e-005,2.156519e-005,,,,,,,,,,,,,,,,,,,,
1406854705.140,,2.500000e+001,2.979968e+002,2.979885e+002,1,0,3.301728e+000,2.649617e+000,2.649617e+000,7.095654e-001,7.063892e-001,2.547001e+000,6.069498e-001,6.037736e-001,5.774213e-005,5.774213e-005,,,,,,,,,,,,,,,,,,,,
1406854723.125,,2.500000e+001,2.979968e+002,2.979968e+002,1,0,1.384121e-001,2.673421e+000,2.673421e+000,6.960359e-001,6.950984e-001,2.760056e+000,7.826706e-001,7.817330e-001,5.826089e-005,5.826089e-005,,,,,,,,,,,,,,,,,,,,
1406854723.125,,2.500000e+001,2.979968e+002,2.979968e+002,1,0,2.428411e+000,4.429762e-001,4.429762e-001,-1.532288e+000,-1.535347e+000,5.004064e-001,-1.474857e+000,-1.477917e+000,9.653616e-006,9.653616e-006,,,,,,,,,,,,,,,,,,,,
1406854741.359,,2.500000e+001,2.980050e+002,2.979968e+002,1,0,3.448683e+000,2.884152e+000,2.884152e+000,8.608603e-001,8.630013e-001,2.819017e+000,7.957258e-001,7.978668e-001,6.285326e-005,6.285326e-005,,,,,,,,,,,,,,,,,,,,
1406854851.109,,3.000000e+001,2.979968e+002,2.979968e+002,1,0,2.241048e-001,2.441175e+000,2.441175e+000,6.900691e-001,6.904274e-001,2.501843e+000,7.507367e-001,7.510949e-001,5.319962e-005,5.319962e-005,,,,,,,,,,,,,,,,,,,,
1406854851.109,,3.000000e+001,2.979968e+002,2.979968e+002,1,0,2.256799e+000,9.155553e-003,9.155553e-003,-1.742721e+000,-1.741593e+000,9.134679e-002,-1.660530e+000,-1.659401e+000,1.995235e-007,1.995235e-007,,,,,,,,,,,,,,,,,,,,
1406854868.171,,3.000000e+001,2.980050e+002,2.980050e+002,1,0,3.584370e+000,2.585833e+000,2.585833e+000,8.117566e-001,8.173752e-001,2.557132e+000,7.830557e-001,7.886744e-001,5.635208e-005,5.635208e-005,,,,,,,,,,,,,,,,,,,,
1406854886.953,,3.000000e+001,2.979968e+002,2.980050e+002,1,0,3.245751e-001,2.518845e+000,2.518845e+000,7.460669e-001,7.506688e-001,2.548833e+000,7.760544e-001,7.806563e-001,5.489224e-005,5.489224e-005,,,,,,,,,,,,,,,,,,,,
1406855005.953,,3.500000e+001,2.980050e+002,2.979968e+002,1,0,2.080141e+000,-6.424146e-002,-6.424146e-002,-1.886703e-001,-1.886703e-001,1.223502e-001,-2.078637e-003,-2.078637e-003,-1.399989e-006,-1.399989e-006,,,,,,,,,,,,,,,,,,,,
1406855005.953,,3.500000e+001,2.980050e+002,2.979968e+002,1,0,3.706049e+000,6.714072e-002,6.714072e-002,3.387345e-002,-5.728812e-002,3.417723e-002,9.099555e-004,-9.025161e-002,1.463172e-006,1.463172e-006,,,,,,,,,,,,,,,,,,,,
1406855023.937,,3.500000e+001,2.979968e+002,2.979968e+002,1,0,4.364792e-001,-1.910459e-001,-1.910459e-001,5.882652e-003,6.483318e-002,-1.589188e-001,3.800976e-002,9.696029e-002,-4.163388e-006,-4.163388e-006,,,,,,,,,,,,,,,,,,,,
1406855042.171,,3.500000e+001,2.979968e+002,2.979968e+002,1,0,1.900294e+000,2.868740e-002,2.868740e-002,3.760570e-001,3.783788e-001,-5.648513e-003,3.417211e-001,3.440429e-001,6.251733e-007,6.251733e-007,,,,,,,,,,,,,,,,,,,,
1406855042.171,,3.500000e+001,2.979968e+002,2.979968e+002,1,0,3.810335e+000,-3.993347e-001,-3.993347e-001,-1.518060e-001,-4.964325e-002,-3.505976e-001,-1.030688e-001,-9.061098e-004,-8.702546e-006,-8.702546e-006,,,,,,,,,,,,,,,,,,,,
1406855160.421,,4.000000e+001,2.979968e+002,2.979968e+002,1,0,5.567105e-001,-2.910092e+000,-2.910092e+000,-7.492245e-001,-7.081835e-001,-2.963928e+000,-8.030599e-001,-7.620189e-001,-6.341848e-005,-6.341848e-005,,,,,,,,,,,,,,,,,,,,
1406855178.656,,4.000000e+001,2.979968e+002,2.979968e+002,1,0,1.719632e+000,-2.897733e-001,-2.897733e-001,1.927607e+000,1.931326e+000,-2.368606e-001,1.980520e+000,1.984238e+000,-6.314913e-006,-6.314913e-006,,,,,,,,,,,,,,,,,,,,
1406855178.656,,4.000000e+001,2.979968e+002,2.979968e+002,1,0,3.894032e+000,-3.064821e+000,-3.064821e+000,-9.273925e-001,-8.437223e-001,-2.932631e+000,-7.952027e-001,-7.115326e-001,-6.679042e-005,-6.679042e-005,,,,,,,,,,,,,,,,,,,,
1406855196.906,,4.000000e+001,2.979968e+002,2.979968e+002,1,0,6.836209e-001,-2.765435e+000,-2.765435e+000,-5.825216e-001,-5.343170e-001,-2.835987e+000,-6.530742e-001,-6.048696e-001,-6.026601e-005,-6.026601e-005,,,,,,,,,,,,,,,,,,,,
1406855307.921,,4.500000e+001,2.980050e+002,2.980050e+002,1,0,1.539093e+000,-8.264413e-001,-8.264412e-001,1.710475e+000,1.716415e+000,-8.609021e-001,1.676014e+000,1.681954e+000,-1.801030e-005,-1.801030e-005,,,,,,,,,,,,,,,,,,,,
1406855307.921,,4.500000e+001,2.980050e+002,2.980050e+002,1,0,3.953883e+000,-3.485519e+000,-3.485519e+000,-1.033743e+000,-9.426627e-001,-3.307491e+000,-8.557142e-001,-7.646344e-001,-7.595849e-005,-7.595849e-005,,,,,,,,,,,,,,,,,,,,
1406855325.703,,4.500000e+001,2.980050e+002,2.980050e+002,1,0,8.162024e-001,-2.881863e+000,-2.881863e+000,-3.938488e-001,-3.421454e-001,-2.972375e+000,-4.843611e-001,-4.326577e-001,-6.280326e-005,-6.280326e-005,,,,,,,,,,,,,,,,,,,,
1406855343.953,,4.500000e+001,2.979968e+002,2.980050e+002,1,0,1.361795e+000,-1.231422e+000,-1.231422e+000,1.217789e+000,1.226774e+000,-1.336976e+000,1.112235e+000,1.121220e+000,-2.683587e-005,-2.683587e-005,,,,,,,,,,,,,,,,,,,,
1406855343.953,,4.500000e+001,2.979968e+002,2.980050e+002,1,0,3.987917e+000,-3.380535e+000,-3.380535e+000,-1.027915e+000,-9.223392e-001,-3.181271e+000,-8.286514e-001,-7.230752e-001,-7.367062e-005,-7.367062e-005,,,,,,,,,,,,,,,,,,,,
1406855462.203,,5.000000e+001,2.979968e+002,2.979968e+002,1,0,9.543601e-001,-2.642903e+000,-2.642903e+000,-5.243374e-002,7.561445e-003,-2.763021e+000,-1.725521e-001,-1.125569e-001,-5.759567e-005,-5.759567e-005,,,,,,,,,,,,,,,,,,,,
1406855480.437,,5.000000e+001,2.979968e+002,2.979968e+002,1,0,1.187707e+000,-1.938078e+000,-1.938078e+000,6.915041e-001,7.031863e-001,-2.087820e+000,5.417620e-001,5.534441e-001,-4.223572e-005,-4.223572e-005,,,,,,,,,,,,,,,,,,,,
1406855480.437,,5.000000e+001,2.979968e+002,2.979968e+002,1,0,3.994881e+000,-3.622395e+000,-3.622395e+000,-1.093279e+000,-9.811304e-001,-3.407592e+000,-8.784769e-001,-7.663281e-001,-7.894132e-005,-7.894132e-005,,,,,,,,,,,,,,,,,,,,
1406855498.187,,5.000000e+001,2.979968e+002,2.980132e+002,1,0,1.098660e+000,-2.148808e+000,-2.148808e+000,3.960251e-001,4.622736e-001,-2.289701e+000,2.551329e-001,3.213813e-001,-4.682808e-005,-4.682808e-005,,,,,,,,,,,,,,,,,,,,
1406855632.156,,7.500000e+001,2.979968e+002,2.980050e+002,1,0,1.018818e+000,-1.340220e+000,-1.340220e+000,6.470057e-002,7.435012e-002,-1.438257e+000,-3.333656e-002,-2.368701e-002,-5.841359e-005,-5.841359e-005,,,,,,,,,,,,,,,,,,,,
1406855632.156,,7.500000e+001,2.979968e+002,2.980050e+002,1,0,3.975121e+000,-1.966155e+000,-1.966155e+000,-6.303892e-001,-5.515845e-001,-1.840750e+000,-5.049837e-001,-4.261791e-001,-8.569498e-005,-8.569498e-005,,,,,,,,,,,,,,,,,,,,
1406855650.390,,7.500000e+001,2.980050e+002,2.979968e+002,1,0,1.249838e+000,-9.216590e-001,-9.216590e-001,4.410502e-001,4.880320e-001,-9.995646e-001,3.631446e-001,4.101264e-001,-4.017057e-005,-4.017057e-005,,,,,,,,,,,,,,,,,,,,
1406855668.625,,7.500000e+001,2.979968e+002,2.979968e+002,1,0,8.558902e-001,-1.586505e+000,-1.586505e+000,-1.837360e-001,-1.720443e-001,-1.679259e+000,-2.764904e-001,-2.647986e-001,-6.914791e-005,-6.914791e-005,,,,,,,,,,,,,,,,,,,,
1406855668.625,,7.500000e+001,2.979968e+002,2.979968e+002,1,0,3.930348e+000,-1.972564e+000,-1.972564e+000,-6.416160e-001,-5.581034e-001,-1.861409e+000,-5.304613e-001,-4.469486e-001,-8.597432e-005,-8.597432e-005,,,,,,,,,,,,,,,,,,,,
1406855798.875,,1.000000e+002,2.980050e+002,2.979968e+002,1,0,1.408132e+000,-6.584368e-001,-6.584368e-001,7.311392e-001,7.878470e-001,-7.279025e-001,6.616735e-001,7.183813e-001,-2.869794e-005,-2.869794e-005,,,,,,,,,,,,,,,,,,,,
1406855816.609,,1.000000e+002,2.979968e+002,2.979968e+002,1,0,7.000319e-001,-1.796014e+000,-1.796014e+000,-3.782210e-001,-3.626248e-001,-1.895590e+000,-4.777967e-001,-4.622004e-001,-7.827922e-005,-7.827922e-005,,,,,,,,,,,,,,,,,,,,
1406855816.609,,1.000000e+002,2.979968e+002,2.979968e+002,1,0,3.863297e+000,-2.011933e+000,-2.011933e+000,-6.779695e-001,-5.785433e-001,-1.913912e+000,-5.799482e-001,-4.805220e-001,-8.769002e-005,-8.769002e-005,,,,,,,,,,,,,,,,,,,,
1406855834.593,,1.000000e+002,2.979968e+002,2.979968e+002,1,0,1.573459e+000,-3.666799e-001,-3.666799e-001,9.943553e-001,1.053832e+000,-3.865121e-001,9.745231e-001,1.034000e+000,-1.598173e-005,-1.598173e-005,,,,,,,,,,,,,,,,,,,,
1406855834.593,,1.000000e+002,2.979968e+002,2.979968e+002,1,0,2.256717e+000,-1.261940e-001,-1.261940e-001,1.169417e+000,1.294318e+000,-2.242014e-003,1.293369e+000,1.418270e+000,-5.500162e-006,-5.500162e-006,,,,,,,,,,,,,,,,,,,,