File: Sample Data Files/2014-07-31 EB on isolated PMN-PT no Ti spontaneous in situ repeat/Ni-NiO_298K_SiO2_PMN-PT_5.0Tprebias_250V_Au_back.rso.raw
[Header]
TITLE,MPMS RSO Measurement
BYAPP,MPMS Measurement,2.1,Raw with ABS
FILEOPENTIME, 1406886186.953000 8/1/2014, 2:43:06 AM

INFO, APPNAME, MPMS MultiVu Application, Revision 1.58,  Build 076

INFO, NAME, EB in situ 2
INFO, WEIGHT, 0.000
INFO, AREA, 0.000
INFO, LENGTH, 0.000
INFO, SHAPE, 0
INFO, COMMENT,
INFO, SEQUENCE FILE: MHcurveUpTo100.seq


INFO, BACKGROUND DATA FILE:, None


STARTUPAXIS,X,8,LINEAR,AUTO,0.000000,0.000000
STARTUPAXIS,Y1,9,LINEAR,AUTO,0.000000,0.000000


STARTUPGROUP,Longitudinal
FIELDGROUP,Longitudinal,1,2,3,4,5,6,7,8,9,10,11,12,13,14,15,16,17,18,19,20,21,22
FIELDGROUP,Transverse,1,2,3,4,5,6,7,8,23,24,25,26,27,28,29,30,31,32,33,34,35,36

PLOT_APPEARANCE,ALL,HORZ_GRID_ON,VERT_GRID_ON,MARKERS_ONLY

[Data]
Time,Comment,Field (Oe),Start Temperature (K),End Temperature (K),Scan,Rejected,Position (cm),Long Voltage,Long Average Voltage,Long Detrended Voltage,Long Demeaned Voltage,Long Reg Fit,Long Detrended Fit,Long Demeaned Fit,Long Scaled Response,Long Avg. Scaled Response,Long Background Response,Long Response [w/ABS],Long Detrended Resp. [w/ABS],Long Fit [w/ABS],Long Detrended Fit [w/ABS],Trans Voltage,Trans Average Voltage,Trans Detrended Voltage,Trans Demeaned Voltage,Trans Reg Fit,Trans Detrended Fit,Trans Demeaned Fit,Trans Scaled Response,Trans Avg. Scaled Response,Trans Background Response,Trans Response [w/ABS],Trans Detrended Resp. [w/ABS],Trans Adjusted Fit,Trans Detrended Fit [w/ABS],
1406886186.937,,1.000000e+002,2.979968e+002,2.979968e+002,1,0,2.079891e+000,-3.265480e-002,-3.265481e-002,1.176697e+000,1.176697e+000,5.466964e-002,1.264021e+000,1.264021e+000,-7.116292e-007,-7.116292e-007,,,,,,,,,,,,,,,,,,,,
1406886186.937,,1.000000e+002,2.979968e+002,2.979968e+002,1,0,3.706206e+000,-1.617176e+000,-1.617176e+000,-5.628453e-001,-4.078243e-001,-1.607596e+000,-5.532655e-001,-3.982444e-001,-3.524228e-005,-3.524228e-005,,,,,,,,,,,,,,,,,,,,
1406886203.734,,1.000000e+002,2.979968e+002,2.979968e+002,1,0,4.366554e-001,-1.659444e+000,-1.659444e+000,-5.375736e-001,-4.574245e-001,-1.677197e+000,-5.553267e-001,-4.751776e-001,-3.616340e-005,-3.616340e-005,,,,,,,,,,,,,,,,,,,,
1406886221.718,,1.000000e+002,2.980050e+002,2.979968e+002,1,0,1.900285e+000,-3.204443e-003,-3.204443e-003,1.157749e+000,1.161394e+000,9.406967e-002,1.255024e+000,1.258668e+000,-6.983277e-008,-6.983277e-008,,,,,,,,,,,,,,,,,,,,
1406886221.718,,1.000000e+002,2.980050e+002,2.979968e+002,1,0,3.810517e+000,-1.635792e+000,-1.635792e+000,-6.315442e-001,-4.711939e-001,-1.528524e+000,-5.242757e-001,-3.639255e-001,-3.564797e-005,-3.564797e-005,,,,,,,,,,,,,,,,,,,,
1406886343.703,,7.500000e+001,2.980050e+002,2.979968e+002,1,0,5.569123e-001,-1.384320e+000,-1.384320e+000,-3.758050e-001,-3.020189e-001,-1.455827e+000,-4.473125e-001,-3.735265e-001,-3.016783e-005,-3.016783e-005,,,,,,,,,,,,,,,,,,,,
1406886361.953,,7.500000e+001,2.980050e+002,2.980050e+002,1,0,1.719337e+000,-1.396222e-001,-1.396222e-001,9.376861e-001,9.440827e-001,-1.163530e-001,9.609552e-001,9.673519e-001,-3.042721e-006,-3.042721e-006,,,,,,,,,,,,,,,,,,,,
1406886361.953,,7.500000e+001,2.980050e+002,2.980050e+002,1,0,3.894087e+000,-1.537065e+000,-1.537065e+000,-5.972856e-001,-4.533597e-001,-1.365754e+000,-4.259754e-001,-2.820495e-001,-3.349653e-005,-3.349653e-005,,,,,,,,,,,,,,,,,,,,
1406886380.187,,7.500000e+001,2.980050e+002,2.979968e+002,1,0,6.837046e-001,-1.232643e+000,-1.232643e+000,-2.574030e-001,-1.791705e-001,-1.341010e+000,-3.657707e-001,-2.875382e-001,-2.686240e-005,-2.686240e-005,,,,,,,,,,,,,,,,,,,,
1406886510.703,,5.000000e+001,2.980050e+002,2.979968e+002,1,0,1.539286e+000,-2.076785e-001,-2.076785e-001,6.264204e-001,6.347305e-001,-2.714544e-001,5.626444e-001,5.709544e-001,-4.525849e-006,-4.525849e-006,,,,,,,,,,,,,,,,,,,,
1406886510.703,,5.000000e+001,2.980050e+002,2.979968e+002,1,0,3.953990e+000,-1.221198e+000,-1.221198e+000,-5.062101e-001,-3.787893e-001,-1.022185e+000,-3.071968e-001,-1.797760e-001,-2.661306e-005,-2.661306e-005,,,,,,,,,,,,,,,,,,,,
1406886527.953,,5.000000e+001,2.979968e+002,2.979968e+002,1,0,8.162747e-001,-8.194220e-001,-8.194220e-001,-6.792497e-002,2.652764e-003,-9.375031e-001,-1.860061e-001,-1.154283e-001,-1.785732e-005,-1.785732e-005,,,,,,,,,,,,,,,,,,,,
1406886545.953,,5.000000e+001,2.979968e+002,2.979968e+002,1,0,1.361430e+000,-3.270058e-001,-3.270058e-001,4.935123e-001,5.050763e-001,-4.591297e-001,3.613884e-001,3.729524e-001,-7.126301e-006,-7.126301e-006,,,,,,,,,,,,,,,,,,,,
1406886545.953,,5.000000e+001,2.979968e+002,2.979968e+002,1,0,3.987890e+000,-1.214942e+000,-1.214942e+000,-5.187365e-001,-3.828598e-001,-9.909172e-001,-2.947119e-001,-1.588351e-001,-2.647672e-005,-2.647672e-005,,,,,,,,,,,,,,,,,,,,
1406886663.953,,4.500000e+001,2.980050e+002,2.979968e+002,1,0,9.544607e-001,-6.413465e-001,-6.413465e-001,7.433090e-002,1.455014e-001,-7.760957e-001,-6.041839e-002,1.075214e-002,-1.397660e-005,-1.397660e-005,,,,,,,,,,,,,,,,,,,,
1406886682.000,,4.500000e+001,2.979968e+002,2.979968e+002,1,0,1.187710e+000,-3.889584e-001,-3.889584e-001,3.303589e-001,3.441772e-001,-5.588290e-001,1.604882e-001,1.743066e-001,-8.476411e-006,-8.476411e-006,,,,,,,,,,,,,,,,,,,,
1406886682.000,,4.500000e+001,2.979968e+002,2.979968e+002,1,0,3.994861e+000,-1.095462e+000,-1.095462e+000,-4.949822e-001,-3.623263e-001,-8.748247e-001,-2.743451e-001,-1.416891e-001,-2.387295e-005,-2.387295e-005,,,,,,,,,,,,,,,,,,,,
1406886699.484,,4.500000e+001,2.979968e+002,2.980050e+002,1,0,1.098747e+000,-4.855495e-001,-4.855495e-001,2.065622e-001,2.825675e-001,-6.189176e-001,7.319406e-002,1.491994e-001,-1.058138e-005,-1.058138e-005,,,,,,,,,,,,,,,,,,,,
1406886817.046,,4.000000e+001,2.979968e+002,2.980050e+002,1,0,1.018597e+000,-5.339214e-001,-5.339213e-001,1.728720e-001,1.886975e-001,-7.095780e-001,-2.784687e-003,1.304084e-002,-1.163553e-005,-1.163553e-005,,,,,,,,,,,,,,,,,,,,
1406886817.046,,4.000000e+001,2.979968e+002,2.980050e+002,1,0,3.975064e+000,-1.066317e+000,-1.066317e+000,-4.729397e-001,-3.436979e-001,-8.562744e-001,-2.628974e-001,-1.336556e-001,-2.323782e-005,-2.323782e-005,,,,,,,,,,,,,,,,,,,,
1406886834.312,,4.000000e+001,2.979968e+002,2.980050e+002,1,0,1.249850e+000,-3.160192e-001,-3.160192e-001,3.168127e-001,3.911950e-001,-4.232582e-001,2.095737e-001,2.839560e-001,-6.886879e-006,-6.886879e-006,,,,,,,,,,,,,,,,,,,,
1406886852.062,,4.000000e+001,2.980050e+002,2.979968e+002,1,0,8.554632e-001,-6.680502e-001,-6.680502e-001,3.191060e-002,5.104679e-002,-8.341836e-001,-1.342228e-001,-1.150866e-001,-1.455855e-005,-1.455855e-005,,,,,,,,,,,,,,,,,,,,
1406886852.062,,4.000000e+001,2.980050e+002,2.979968e+002,1,0,3.930202e+000,-1.043886e+000,-1.043886e+000,-4.614757e-001,-3.247886e-001,-8.588374e-001,-2.764275e-001,-1.397405e-001,-2.274898e-005,-2.274898e-005,,,,,,,,,,,,,,,,,,,,
1406886969.312,,3.500000e+001,2.979968e+002,2.979968e+002,1,0,1.408174e+000,-2.179022e-001,-2.179022e-001,4.017477e-001,4.749348e-001,-2.795095e-001,3.401403e-001,4.133274e-001,-4.748657e-006,-4.748657e-006,,,,,,,,,,,,,,,,,,,,
1406886987.046,,3.500000e+001,2.979968e+002,2.979968e+002,1,0,6.998237e-001,-7.029939e-001,-7.029939e-001,-7.584272e-002,-5.506784e-002,-8.455901e-001,-2.184389e-001,-1.976640e-001,-1.532007e-005,-1.532007e-005,,,,,,,,,,,,,,,,,,,,
1406886987.046,,3.500000e+001,2.979968e+002,2.979968e+002,1,0,3.863226e+000,-9.263894e-001,-9.263893e-001,-4.109032e-001,-2.784633e-001,-7.893876e-001,-2.739015e-001,-1.414616e-001,-2.018844e-005,-2.018844e-005,,,,,,,,,,,,,,,,,,,,
1406887005.046,,3.500000e+001,2.979968e+002,2.980050e+002,1,0,1.573495e+000,-1.162755e-001,-1.162755e-001,4.769455e-001,5.564055e-001,-1.017077e-001,4.915133e-001,5.709734e-001,-2.533947e-006,-2.533947e-006,,,,,,,,,,,,,,,,,,,,
1406887123.531,,3.000000e+001,2.980050e+002,2.979885e+002,1,0,5.530598e-001,-8.024842e-001,-8.024842e-001,-1.589725e-001,-1.372734e-001,-9.014765e-001,-2.579648e-001,-2.362657e-001,-1.748823e-005,-1.748823e-005,,,,,,,,,,,,,,,,,,,,
1406887123.531,,3.000000e+001,2.980050e+002,2.979885e+002,1,0,3.777588e+000,-8.879361e-001,-8.879361e-001,-3.480978e-001,-2.227253e-001,-8.101154e-001,-2.702771e-001,-1.449046e-001,-1.935045e-005,-1.935045e-005,,,,,,,,,,,,,,,,,,,,
1406887141.281,,3.000000e+001,2.979885e+002,2.979968e+002,1,0,1.745119e+000,-6.469924e-002,-6.469924e-002,4.814370e-001,5.584854e-001,3.117836e-002,5.773146e-001,6.543630e-001,-1.409966e-006,-1.409966e-006,,,,,,,,,,,,,,,,,,,,
1406887159.515,,3.000000e+001,2.980050e+002,2.979968e+002,1,0,4.172389e-001,-8.215583e-001,-8.215583e-001,-2.369521e-001,-2.114825e-001,-8.677057e-001,-2.830995e-001,-2.576299e-001,-1.790391e-005,-1.790391e-005,,,,,,,,,,,,,,,,,,,,
1406887159.515,,3.000000e+001,2.980050e+002,2.979968e+002,1,0,3.677038e+000,-7.748650e-001,-7.748650e-001,-2.997781e-001,-1.647892e-001,-7.583234e-001,-2.832365e-001,-1.482477e-001,-1.688634e-005,-1.688634e-005,,,,,,,,,,,,,,,,,,,,
1406887277.265,,2.500000e+001,2.979968e+002,2.979968e+002,1,0,1.921727e+000,-5.523850e-002,-5.523850e-002,4.508157e-001,5.253392e-001,8.436678e-002,5.904210e-001,6.649445e-001,-1.203792e-006,-1.203792e-006,,,,,,,,,,,,,,,,,,,,
1406887295.000,,2.500000e+001,2.979968e+002,2.980050e+002,1,0,2.957169e-001,-8.209479e-001,-8.209479e-001,-2.706289e-001,-2.442887e-001,-8.085806e-001,-2.582616e-001,-2.319214e-001,-1.789062e-005,-1.789062e-005,,,,,,,,,,,,,,,,,,,,
1406887295.000,,2.500000e+001,2.979968e+002,2.980050e+002,1,0,3.565309e+000,-6.602680e-001,-6.602679e-001,-2.129153e-001,-8.360875e-002,-7.061703e-001,-2.588177e-001,-1.295111e-001,-1.438898e-005,-1.438898e-005,,,,,,,,,,,,,,,,,,,,
1406887311.984,,2.500000e+001,2.979968e+002,2.980050e+002,1,0,2.101443e+000,-4.303110e-002,-4.303110e-002,4.416095e-001,5.224204e-001,9.410314e-002,5.787437e-001,6.595547e-001,-9.377609e-007,-9.377609e-007,,,,,,,,,,,,,,,,,,,,
1406887428.968,,2.000000e+001,2.980050e+002,2.979968e+002,1,0,1.913814e-001,-7.969909e-001,-7.969909e-001,-2.889344e-001,-2.615098e-001,-7.307349e-001,-2.226784e-001,-1.952538e-001,-1.736854e-005,-1.736854e-005,,,,,,,,,,,,,,,,,,,,
1406887428.968,,2.000000e+001,2.980050e+002,2.979968e+002,1,0,3.444983e+000,-5.415509e-001,-5.415509e-001,-1.317656e-001,-6.069899e-003,-6.288462e-001,-2.190609e-001,-9.336519e-002,-1.180183e-005,-1.180183e-005,,,,,,,,,,,,,,,,,,,,
1406887447.203,,2.000000e+001,2.980050e+002,2.980050e+002,1,0,2.282425e+000,-8.270516e-002,-8.270516e-002,3.749854e-001,4.549287e-001,-1.535743e-002,4.423331e-001,5.222764e-001,-1.802364e-006,-1.802364e-006,,,,,,,,,,,,,,,,,,,,
1406887465.937,,2.000000e+001,2.979968e+002,2.979885e+002,1,0,1.077461e-001,-8.258308e-001,-8.258309e-001,-3.267242e-001,-2.958440e-001,-7.071750e-001,-2.080683e-001,-1.771881e-001,-1.799704e-005,-1.799704e-005,,,,,,,,,,,,,,,,,,,,
1406887465.937,,2.000000e+001,2.979968e+002,2.979885e+002,1,0,3.318138e+000,-4.565569e-001,-4.565569e-001,-5.959241e-002,7.343000e-002,-5.803764e-001,-1.834119e-001,-5.038953e-002,-9.949581e-006,-9.949581e-006,,,,,,,,,,,,,,,,,,,,
1406887574.687,,1.500000e+001,2.980050e+002,2.979968e+002,1,0,2.462449e+000,-5.752739e-002,-5.752739e-002,3.154615e-001,3.905463e-001,-8.610033e-002,2.868886e-001,3.619733e-001,-1.253674e-006,-1.253674e-006,,,,,,,,,,,,,,,,,,,,
1406887593.437,,1.500000e+001,2.980050e+002,2.979968e+002,1,0,4.780286e-002,-7.287821e-001,-7.287820e-001,-3.204944e-001,-2.893900e-001,-5.842933e-001,-1.760057e-001,-1.449013e-001,-1.588209e-005,-1.588209e-005,,,,,,,,,,,,,,,,,,,,
1406887593.437,,1.500000e+001,2.980050e+002,2.979968e+002,1,0,3.185528e+000,-2.826014e-001,-2.826014e-001,3.015133e-002,1.567906e-001,-4.311236e-001,-1.183708e-001,8.268476e-003,-6.158634e-006,-6.158634e-006,,,,,,,,,,,,,,,,,,,,
1406887611.687,,1.500000e+001,2.979968e+002,2.980050e+002,1,0,2.640142e+000,-3.433332e-002,-3.433332e-002,2.896557e-001,3.712561e-001,-1.474628e-001,1.765262e-001,2.581266e-001,-7.482142e-007,-7.482142e-007,,,,,,,,,,,,,,,,,,,,
1406887728.734,,1.000000e+001,2.979968e+002,2.980050e+002,1,0,1.379217e-002,-6.875820e-001,-6.875820e-001,-3.010156e-001,-2.691827e-001,-5.357375e-001,-1.491710e-001,-1.173382e-001,-1.498424e-005,-1.498424e-005,,,,,,,,,,,,,,,,,,,,
1406887728.734,,1.000000e+001,2.979968e+002,2.980050e+002,1,0,3.047299e+000,-1.950133e-001,-1.950133e-001,1.002991e-001,2.233860e-001,-3.500386e-001,-5.472628e-002,6.836069e-002,-4.249858e-006,-4.249858e-006,,,,,,,,,,,,,,,,,,,,
1406887747.218,,1.000000e+001,2.979968e+002,2.979968e+002,1,0,2.814100e+000,-1.355022e-001,-1.355022e-001,2.185619e-001,2.989780e-001,-3.007431e-001,5.332095e-002,1.337371e-001,-2.952953e-006,-2.952953e-006,,,,,,,,,,,,,,,,,,,,
1406887765.453,,1.000000e+001,2.979968e+002,2.979968e+002,1,0,6.948184e-003,-6.720176e-001,-6.720176e-001,-3.038742e-001,-2.684205e-001,-5.159372e-001,-1.477938e-001,-1.123401e-001,-1.464505e-005,-1.464505e-005,,,,,,,,,,,,,,,,,,,,
1406887765.453,,1.000000e+001,2.979968e+002,2.979968e+002,1,0,2.903056e+000,-1.236000e-001,-1.236000e-001,1.492615e-001,2.799971e-001,-2.622533e-001,1.060823e-002,1.413438e-001,-2.693572e-006,-2.693572e-006,,,,,,,,,,,,,,,,,,,,
1406887882.953,,5.000000e+000,2.980050e+002,2.979968e+002,1,0,2.983127e+000,-1.264992e-001,-1.264992e-001,1.520148e-001,2.314533e-001,-3.108135e-001,-3.229953e-002,4.713893e-002,-2.756756e-006,-2.756756e-006,,,,,,,,,,,,,,,,,,,,
1406887900.687,,5.000000e+000,2.980050e+002,2.980050e+002,1,0,2.664159e-002,-5.963317e-001,-5.963317e-001,-2.745554e-001,-2.382519e-001,-4.521407e-001,-1.303645e-001,-9.406099e-002,-1.299566e-005,-1.299566e-005,,,,,,,,,,,,,,,,,,,,
1406887900.687,,5.000000e+000,2.980050e+002,2.980050e+002,1,0,2.751877e+000,-7.019257e-002,-7.019258e-002,1.597571e-001,2.878872e-001,-1.708659e-001,5.908378e-002,1.872139e-001,-1.529684e-006,-1.529684e-006,,,,,,,,,,,,,,,,,,,,
1406887918.671,,5.000000e+000,2.979968e+002,2.979968e+002,1,0,3.146104e+000,-1.573229e-001,-1.573229e-001,9.238475e-002,1.772653e-001,-3.361490e-001,-8.644135e-002,-1.560807e-003,-3.428487e-006,-3.428487e-006,,,,,,,,,,,,,,,,,,,,
1406888036.656,,0.000000e+000,2.979968e+002,2.979968e+002,1,0,7.150049e-002,-4.617450e-001,-4.617451e-001,-2.261958e-001,-1.857851e-001,-3.516245e-001,-1.160752e-001,-7.566452e-002,-1.006266e-005,-1.006266e-005,,,,,,,,,,,,,,,,,,,,
1406888036.656,,0.000000e+000,2.979968e+002,2.979968e+002,1,0,2.593635e+000,-1.632740e-002,-1.632740e-002,1.226853e-001,2.596325e-001,-6.321115e-002,7.580158e-002,2.127488e-001,-3.558179e-007,-3.558179e-007,,,,,,,,,,,,,,,,,,,,
1406888054.921,,0.000000e+000,2.979885e+002,2.979968e+002,1,0,3.301931e+000,-1.451155e-001,-1.451155e-001,3.606481e-002,1.259893e-001,-2.934716e-001,-1.122913e-001,-2.236685e-002,-3.162456e-006,-3.162456e-006,,,,,,,,,,,,,,,,,,,,
1406888073.218,,0.000000e+000,2.979968e+002,2.979968e+002,1,0,1.385161e-001,-4.805139e-001,-4.805139e-001,-2.036078e-001,-1.594849e-001,-3.965210e-001,-1.196149e-001,-7.549194e-002,-1.047169e-005,-1.047169e-005,,,,,,,,,,,,,,,,,,,,
1406888073.218,,0.000000e+000,2.979968e+002,2.979968e+002,1,0,2.428299e+000,-7.644887e-002,-7.644887e-002,1.006000e-001,2.445802e-001,-4.448869e-002,1.325602e-001,2.765404e-001,-1.666026e-006,-1.666026e-006,,,,,,,,,,,,,,,,,,,,
1406888189.968,,-5.000000e+000,2.979968e+002,2.979968e+002,1,0,3.448789e+000,-1.568651e-001,-1.568651e-001,-2.549359e-003,1.071623e-001,-2.365156e-001,-8.219986e-002,2.751181e-002,-3.418510e-006,-3.418510e-006,,,,,,,,,,,,,,,,,,,,
1406888208.468,,-5.000000e+000,2.980050e+002,2.980050e+002,1,0,2.241771e-001,-3.413495e-001,-3.413495e-001,-1.244742e-001,-6.923690e-002,-2.896125e-001,-7.273711e-002,-1.749983e-002,-7.438918e-006,-7.438918e-006,,,,,,,,,,,,,,,,,,,,
1406888208.468,,-5.000000e+000,2.980050e+002,2.980050e+002,1,0,2.256619e+000,-9.277627e-002,-9.277627e-002,5.338974e-003,1.793364e-001,-2.669587e-002,7.141937e-002,2.454168e-001,-2.021843e-006,-2.021843e-006,,,,,,,,,,,,,,,,,,,,
1406888226.015,,-5.000000e+000,2.980050e+002,2.980050e+002,1,0,3.584456e+000,-1.632740e-001,-1.632740e-001,-5.319016e-002,6.580928e-002,-1.790259e-001,-6.894206e-002,5.005738e-002,-3.558177e-006,-3.558177e-006,,,,,,,,,,,,,,,,,,,,
1406888349.750,,-1.000000e+001,2.979968e+002,2.979968e+002,1,0,3.246972e-001,-1.846370e-001,-1.846370e-001,-4.485076e-002,8.593440e-003,-1.256652e-001,1.412104e-002,6.756525e-002,-4.023731e-006,-4.023731e-006,,,,,,,,,,,,,,,,,,,,
1406888367.984,,-1.000000e+001,2.980050e+002,2.979968e+002,1,0,2.079949e+000,-6.302072e-002,-6.302072e-002,1.230514e-001,1.230514e-001,-1.683722e-001,1.769991e-002,1.769991e-002,-1.373389e-006,-1.373389e-006,,,,,,,,,,,,,,,,,,,,
1406888367.984,,-1.000000e+001,2.980050e+002,2.979968e+002,1,0,3.706127e+000,-1.309244e-001,-1.309244e-001,-5.915470e-002,5.514768e-002,-9.595358e-002,-2.418387e-002,9.011851e-002,-2.853191e-006,-2.853191e-006,,,,,,,,,,,,,,,,,,,,
1406888386.484,,-1.000000e+001,2.980050e+002,2.980050e+002,1,0,4.364997e-001,-1.258889e-001,-1.258889e-001,-1.964037e-003,5.781230e-002,-8.797374e-002,3.595108e-002,9.572742e-002,-2.743453e-006,-2.743453e-006,,,,,,,,,,,,,,,,,,,,
1406888504.718,,-1.500000e+001,2.979968e+002,2.979968e+002,1,0,1.900401e+000,-6.942961e-002,-6.942961e-002,-2.697300e-002,-2.676218e-002,-9.132580e-003,3.332403e-002,3.353485e-002,-1.513055e-006,-1.513055e-006,,,,,,,,,,,,,,,,,,,,
1406888504.718,,-1.500000e+001,2.979968e+002,2.979968e+002,1,0,3.810462e+000,-8.255257e-002,-8.255257e-002,-4.916113e-002,-3.988514e-002,-4.729114e-002,-1.389971e-002,-4.623715e-003,-1.799039e-006,-1.799039e-006,,,,,,,,,,,,,,,,,,,,
1406888522.453,,-1.500000e+001,2.979968e+002,2.979885e+002,1,0,5.568573e-001,2.685629e-002,2.685629e-002,4.435769e-002,5.064072e-002,-2.991664e-002,-1.241524e-002,-6.132202e-003,5.852697e-007,5.852697e-007,,,,,,,,,,,,,,,,,,,,
1406888540.687,,-1.500000e+001,2.979885e+002,2.979968e+002,1,0,1.719250e+000,-4.272591e-003,-4.272591e-003,1.340757e-002,1.406181e-002,7.754460e-003,2.543462e-002,2.608886e-002,-9.311110e-008,-9.311110e-008,,,,,,,,,,,,,,,,,,,,
1406888540.687,,-1.500000e+001,2.979885e+002,2.979968e+002,1,0,3.894019e+000,-7.919554e-002,-7.919553e-002,-7.558138e-002,-6.086113e-002,-1.502999e-002,-1.141584e-002,3.304410e-003,-1.725881e-006,-1.725881e-006,,,,,,,,,,,,,,,,,,,,
1406888657.937,,-2.000000e+001,2.979968e+002,2.979968e+002,1,0,6.836334e-001,1.715140e-001,1.715140e-001,1.118267e-001,1.048579e-001,5.770496e-002,-1.982377e-003,-8.951180e-003,3.737744e-006,3.737744e-006,,,,,,,,,,,,,,,,,,,,
1406888676.171,,-2.000000e+001,2.979968e+002,2.979885e+002,1,0,1.539119e+000,8.041628e-002,8.041627e-002,1.419614e-002,1.474539e-002,7.343764e-002,7.217511e-003,7.766761e-003,1.752483e-006,1.752483e-006,,,,,,,,,,,,,,,,,,,,
1406888676.171,,-2.000000e+001,2.979968e+002,2.979885e+002,1,0,3.953982e+000,2.914518e-002,2.914518e-002,-4.494754e-002,-3.652570e-002,7.522883e-002,1.136109e-003,9.557948e-003,6.351504e-007,6.351504e-007,,,,,,,,,,,,,,,,,,,,
1406888693.906,,-2.000000e+001,2.980050e+002,2.979968e+002,1,0,8.162255e-001,2.320933e-001,2.320933e-001,1.353061e-001,1.520429e-001,1.135518e-001,1.676469e-002,3.350147e-002,5.057925e-006,5.057925e-006,,,,,,,,,,,,,,,,,,,,
1406888812.156,,-2.500000e+001,2.979968e+002,2.979968e+002,1,0,1.361475e+000,2.272103e-001,2.272103e-001,5.436195e-002,5.512035e-002,1.555224e-001,-1.732597e-002,-1.656757e-002,4.951510e-006,4.951510e-006,,,,,,,,,,,,,,,,,,,,
1406888812.156,,-2.500000e+001,2.979968e+002,2.979968e+002,1,0,3.987897e+000,1.844844e-001,1.844844e-001,3.483247e-003,1.239444e-002,2.786523e-001,9.765111e-002,1.065623e-001,4.020400e-006,4.020400e-006,,,,,,,,,,,,,,,,,,,,
1406888830.390,,-2.500000e+001,2.979968e+002,2.979968e+002,1,0,9.543781e-001,3.691214e-001,3.691214e-001,1.771761e-001,1.838793e-001,2.672223e-001,7.527701e-002,8.198023e-002,8.044126e-006,8.044126e-006,,,,,,,,,,,,,,,,,,,,
1406888848.875,,-2.500000e+001,2.979968e+002,2.979968e+002,1,0,1.187827e+000,3.428755e-001,3.428755e-001,1.236549e-001,1.252670e-001,2.459367e-001,2.671615e-002,2.832824e-002,7.472158e-006,7.472158e-006,,,,,,,,,,,,,,,,,,,,
1406888848.875,,-2.500000e+001,2.979968e+002,2.979968e+002,1,0,3.994904e+000,2.388073e-001,2.388073e-001,5.722788e-003,2.119887e-002,3.344936e-001,1.014090e-001,1.168851e-001,5.204240e-006,5.204240e-006,,,,,,,,,,,,,,,,,,,,
1406888959.359,,-3.000000e+001,2.979968e+002,2.979968e+002,1,0,1.098703e+000,4.249702e-001,4.249702e-001,1.525253e-001,1.528330e-001,3.270193e-001,5.457439e-002,5.488205e-002,9.261215e-006,9.261215e-006,,,,,,,,,,,,,,,,,,,,
1406888977.593,,-3.000000e+001,2.979968e+002,2.979968e+002,1,0,1.018585e+000,4.608295e-001,4.608295e-001,1.718778e-001,1.726377e-001,3.682262e-001,7.927455e-002,8.003443e-002,1.004268e-005,1.004268e-005,,,,,,,,,,,,,,,,,,,,
1406888977.593,,-3.000000e+001,2.979968e+002,2.979968e+002,1,0,3.975085e+000,3.512681e-001,3.512681e-001,5.687054e-002,6.307629e-002,4.354343e-001,1.410368e-001,1.472425e-001,7.655051e-006,7.655051e-006,,,,,,,,,,,,,,,,,,,,
1406888995.843,,-3.000000e+001,2.979968e+002,2.979968e+002,1,0,1.249909e+000,3.915525e-001,3.915525e-001,8.340787e-002,8.825919e-002,3.083901e-001,2.455012e-004,5.096823e-003,8.532955e-006,8.532955e-006,,,,,,,,,,,,,,,,,,,,
1406889107.343,,-3.500000e+001,2.979968e+002,2.979968e+002,1,0,8.558242e-001,5.838191e-001,5.838191e-001,2.178542e-001,2.173927e-001,5.084128e-001,1.424479e-001,1.419865e-001,1.272294e-005,1.272294e-005,,,,,,,,,,,,,,,,,,,,
1406889107.343,,-3.500000e+001,2.979968e+002,2.979968e+002,1,0,3.930340e+000,4.741051e-001,4.741050e-001,1.109749e-001,1.076787e-001,5.395986e-001,1.764685e-001,1.731723e-001,1.033199e-005,1.033199e-005,,,,,,,,,,,,,,,,,,,,
1406889124.828,,-3.500000e+001,2.979968e+002,2.980050e+002,1,0,1.408174e+000,3.085421e-001,3.085421e-001,-4.480805e-002,-4.489273e-002,2.627062e-001,-9.064396e-002,-9.072864e-002,6.723938e-006,6.723938e-006,,,,,,,,,,,,,,,,,,,,
1406889142.875,,-3.500000e+001,2.980050e+002,2.979968e+002,1,0,6.999052e-001,6.337169e-001,6.337168e-001,2.358584e-001,2.367436e-001,5.725358e-001,1.746774e-001,1.755626e-001,1.381035e-005,1.381035e-005,,,,,,,,,,,,,,,,,,,,
1406889142.875,,-3.500000e+001,2.980050e+002,2.979968e+002,1,0,3.863269e+000,5.348369e-001,5.348369e-001,1.322203e-001,1.378637e-001,5.848573e-001,1.822407e-001,1.878841e-001,1.165549e-005,1.165549e-005,,,,,,,,,,,,,,,,,,,,
1406889260.656,,-4.000000e+001,2.980050e+002,2.979968e+002,1,0,1.573582e+000,2.139348e-001,2.139347e-001,-2.260974e-001,-2.286328e-001,2.198651e-001,-2.201670e-001,-2.227025e-001,4.662194e-006,4.662194e-006,,,,,,,,,,,,,,,,,,,,
1406889279.140,,-4.000000e+001,2.980050e+002,2.979968e+002,1,0,5.528306e-001,7.110813e-001,7.110813e-001,2.491920e-001,2.484341e-001,6.769047e-001,2.150155e-001,2.142575e-001,1.549631e-005,1.549631e-005,,,,,,,,,,,,,,,,,,,,
1406889279.140,,-4.000000e+001,2.980050e+002,2.979968e+002,1,0,3.777532e+000,6.419569e-001,6.419569e-001,1.836887e-001,1.793097e-001,6.727173e-001,2.144492e-001,2.100701e-001,1.398991e-005,1.398991e-005,,,,,,,,,,,,,,,,,,,,
1406889297.375,,-4.000000e+001,2.980050e+002,2.979968e+002,1,0,1.745208e+000,9.628590e-002,9.628589e-002,-3.738312e-001,-3.744593e-001,1.395456e-001,-3.305715e-001,-3.311996e-001,2.098320e-006,2.098320e-006,,,,,,,,,,,,,,,,,,,,
1406889408.625,,-4.500000e+001,2.980050e+002,2.980050e+002,1,0,4.171940e-001,8.009583e-001,8.009583e-001,2.484168e-001,2.466373e-001,7.882062e-001,2.356647e-001,2.338852e-001,1.745496e-005,1.745496e-005,,,,,,,,,,,,,,,,,,,,
1406889408.625,,-4.500000e+001,2.980050e+002,2.980050e+002,1,0,3.677020e+000,7.692190e-001,7.692190e-001,2.243297e-001,2.148980e-001,7.794949e-001,2.346056e-001,2.251740e-001,1.676328e-005,1.676328e-005,,,,,,,,,,,,,,,,,,,,
1406889426.859,,-4.500000e+001,2.979968e+002,2.980050e+002,1,0,1.921802e+000,3.311258e-002,3.311258e-002,-5.411396e-001,-5.448517e-001,8.328805e-002,-4.909641e-001,-4.946763e-001,7.216090e-007,7.216090e-007,,,,,,,,,,,,,,,,,,,,
1406889444.359,,-4.500000e+001,2.979968e+002,2.979885e+002,1,0,2.956394e-001,7.568590e-001,7.568591e-001,2.087568e-001,2.076119e-001,7.646585e-001,2.165562e-001,2.154113e-001,1.649392e-005,1.649392e-005,,,,,,,,,,,,,,,,,,,,
1406889444.359,,-4.500000e+001,2.979968e+002,2.979885e+002,1,0,3.565236e+000,7.663198e-001,7.663198e-001,2.226932e-001,2.170726e-001,7.543639e-001,2.107373e-001,2.051167e-001,1.670009e-005,1.670009e-005,,,,,,,,,,,,,,,,,,,,
1406889560.125,,-5.000000e+001,2.979885e+002,2.980050e+002,1,0,2.101560e+000,-7.019257e-003,-7.019257e-003,-6.407207e-001,-6.451770e-001,1.249195e-002,-6.212094e-001,-6.256658e-001,-1.529677e-007,-1.529677e-007,,,,,,,,,,,,,,,,,,,,
1406889577.859,,-5.000000e+001,2.979968e+002,2.980050e+002,1,0,1.913244e-001,8.378857e-001,8.378857e-001,1.933515e-001,1.925895e-001,8.649839e-001,2.204497e-001,2.196878e-001,1.825969e-005,1.825969e-005,,,,,,,,,,,,,,,,,,,,
1406889577.859,,-5.000000e+001,2.979968e+002,2.980050e+002,1,0,3.444920e+000,8.574175e-001,8.574175e-001,2.156138e-001,2.121214e-001,8.338197e-001,1.920160e-001,1.885236e-001,1.868534e-005,1.868534e-005,,,,,,,,,,,,,,,,,,,,
1406889596.625,,-5.000000e+001,2.980050e+002,2.979968e+002,1,0,2.282537e+000,7.217627e-002,7.217628e-002,-6.004625e-001,-6.015071e-001,6.596706e-002,-6.066717e-001,-6.077163e-001,1.572907e-006,1.572907e-006,,,,,,,,,,,,,,,,,,,,
1406889719.625,,-7.500000e+001,2.980050e+002,2.979968e+002,1,0,1.077504e-001,1.873074e+000,1.873074e+000,2.886794e-001,3.221302e-001,1.889480e+000,3.050857e-001,3.385365e-001,4.081901e-005,4.081901e-005,,,,,,,,,,,,,,,,,,,,
1406889719.625,,-7.500000e+001,2.980050e+002,2.979968e+002,1,0,3.318137e+000,1.917631e+000,1.917631e+000,2.225915e-001,3.666872e-001,1.910501e+000,2.154616e-001,3.595573e-001,4.179002e-005,4.179002e-005,,,,,,,,,,,,,,,,,,,,
1406889737.859,,-7.500000e+001,2.979968e+002,2.979968e+002,1,0,2.462630e+000,9.465316e-001,9.465316e-001,-6.826311e-001,-5.961080e-001,9.150129e-001,-7.141498e-001,-6.276267e-001,2.062732e-005,2.062732e-005,,,,,,,,,,,,,,,,,,,,
1406889755.593,,-7.500000e+001,2.980050e+002,2.979968e+002,1,0,4.777879e-002,1.759545e+000,1.759545e+000,2.602431e-001,2.899537e-001,1.782108e+000,2.828068e-001,3.125174e-001,3.834493e-005,3.834493e-005,,,,,,,,,,,,,,,,,,,,
1406889755.593,,-7.500000e+001,2.980050e+002,2.979968e+002,1,0,3.185527e+000,1.692404e+000,1.692404e+000,1.018482e-001,2.228130e-001,1.687838e+000,9.728271e-002,2.182475e-001,3.688176e-005,3.688176e-005,,,,,,,,,,,,,,,,,,,,
1406889885.078,,-1.000000e+002,2.979968e+002,2.979885e+002,1,0,2.640361e+000,2.483139e+000,2.483139e+000,-6.318015e-001,-3.767807e-001,2.483577e+000,-6.313633e-001,-3.763425e-001,5.411375e-005,5.411375e-005,,,,,,,,,,,,,,,,,,,,
1406889903.140,,-1.000000e+002,2.980050e+002,2.980050e+002,1,0,1.384746e-002,3.438826e+000,3.438826e+000,3.857520e-001,4.971635e-001,3.423851e+000,3.707779e-001,4.821894e-001,7.494054e-005,7.494054e-005,,,,,,,,,,,,,,,,,,,,
1406889903.140,,-1.000000e+002,2.980050e+002,2.980050e+002,1,0,3.047303e+000,3.323160e+000,3.323160e+000,-4.929286e-002,3.814983e-001,3.356813e+000,-1.564008e-002,4.151511e-001,7.241991e-005,7.241991e-005,,,,,,,,,,,,,,,,,,,,
1406889921.375,,-1.000000e+002,2.979968e+002,2.979968e+002,1,0,2.814306e+000,2.587359e+000,2.587359e+000,-3.864017e-001,-1.534207e-001,2.614783e+000,-3.589776e-001,-1.259966e-001,5.638498e-005,5.638498e-005,,,,,,,,,,,,,,,,,,,,
1406890052.375,,-7.500000e+001,2.979968e+002,2.979885e+002,1,0,6.867221e-003,1.138493e+000,1.138493e+000,2.694025e-001,2.527951e-001,1.153866e+000,2.847751e-001,2.681677e-001,2.481064e-005,2.481064e-005,,,,,,,,,,,,,,,,,,,,
1406890052.375,,-7.500000e+001,2.979968e+002,2.979885e+002,1,0,2.902897e+000,5.984680e-001,5.984679e-001,-2.259902e-001,-2.872299e-001,6.118215e-001,-2.126366e-001,-2.738763e-001,1.304213e-005,1.304213e-005,,,,,,,,,,,,,,,,,,,,
1406890070.109,,-7.500000e+001,2.980050e+002,2.979968e+002,1,0,2.983254e+000,7.087923e-001,7.087924e-001,-1.371152e-001,-1.746936e-001,7.287527e-001,-1.171549e-001,-1.547332e-001,1.544638e-005,1.544638e-005,,,,,,,,,,,,,,,,,,,,
1406890087.843,,-7.500000e+001,2.979968e+002,2.979885e+002,1,0,2.670815e-002,1.205329e+000,1.205329e+000,2.808014e-001,2.650232e-001,1.217395e+000,2.928674e-001,2.770892e-001,2.626716e-005,2.626716e-005,,,,,,,,,,,,,,,,,,,,
1406890087.843,,-7.500000e+001,2.979968e+002,2.979885e+002,1,0,2.751814e+000,4.739524e-001,4.739524e-001,-4.106653e-001,-4.663530e-001,4.828599e-001,-4.017578e-001,-4.574455e-001,1.032862e-005,1.032862e-005,,,,,,,,,,,,,,,,,,,,
1406890211.828,,-5.000000e+001,2.980050e+002,2.980050e+002,1,0,3.146148e+000,6.973479e-001,6.973479e-001,3.129980e-002,5.389035e-003,6.819575e-001,1.590941e-002,-1.000136e-002,1.519701e-005,1.519701e-005,,,,,,,,,,,,,,,,,,,,
1406890230.078,,-5.000000e+001,2.980050e+002,2.980050e+002,1,0,7.147779e-002,8.590961e-001,8.590961e-001,1.851074e-001,1.737758e-001,8.954647e-001,2.214760e-001,2.101444e-001,1.872192e-005,1.872192e-005,,,,,,,,,,,,,,,,,,,,
1406890230.078,,-5.000000e+001,2.980050e+002,2.980050e+002,1,0,2.593488e+000,1.676992e-001,1.676992e-001,-4.792197e-001,-5.176210e-001,1.579075e-001,-4.890113e-001,-5.274128e-001,3.654598e-006,3.654598e-006,,,,,,,,,,,,,,,,,,,,
1406890248.828,,-5.000000e+001,2.980050e+002,2.979968e+002,1,0,3.302031e+000,8.575701e-001,8.575701e-001,1.546365e-001,1.331155e-001,8.382872e-001,1.353536e-001,1.138325e-001,1.868867e-005,1.868867e-005,,,,,,,,,,,,,,,,,,,,
1406890366.828,,-4.500000e+001,2.979968e+002,2.979968e+002,1,0,1.385975e-001,7.895139e-001,7.895138e-001,1.954278e-001,1.835353e-001,8.159286e-001,2.218425e-001,2.099500e-001,1.720555e-005,1.720555e-005,,,,,,,,,,,,,,,,,,,,
1406890366.828,,-4.500000e+001,2.979968e+002,2.979968e+002,1,0,2.428236e+000,-1.236000e-002,-1.236000e-002,-5.795314e-001,-6.183385e-001,-2.344839e-002,-5.906198e-001,-6.294270e-001,-2.693563e-007,-2.693563e-007,,,,,,,,,,,,,,,,,,,,
1406890385.062,,-4.500000e+001,2.979968e+002,2.979885e+002,1,0,3.448836e+000,8.192694e-001,8.192694e-001,2.210853e-001,1.982079e-001,8.037885e-001,2.056045e-001,1.827271e-001,1.785400e-005,1.785400e-005,,,,,,,,,,,,,,,,,,,,
1406890403.046,,-4.500000e+001,2.979968e+002,2.979885e+002,1,0,2.243060e-001,8.616901e-001,8.616901e-001,2.368036e-001,2.271007e-001,8.707036e-001,2.458171e-001,2.361142e-001,1.877846e-005,1.877846e-005,,,,,,,,,,,,,,,,,,,,
1406890403.046,,-4.500000e+001,2.979968e+002,2.979885e+002,1,0,2.256582e+000,-6.485183e-002,-6.485184e-002,-6.688771e-001,-6.994413e-001,-6.527899e-002,-6.693042e-001,-6.998684e-001,-1.413289e-006,-1.413289e-006,,,,,,,,,,,,,,,,,,,,
1406890519.531,,-4.000000e+001,2.979968e+002,2.979968e+002,1,0,3.584594e+000,7.786798e-001,7.786798e-001,2.420657e-001,2.202798e-001,7.764891e-001,2.398750e-001,2.180891e-001,1.696946e-005,1.696946e-005,,,,,,,,,,,,,,,,,,,,
1406890538.031,,-4.000000e+001,2.979968e+002,2.979968e+002,1,0,3.248724e-001,8.171331e-001,8.171331e-001,2.535784e-001,2.425233e-001,8.121789e-001,2.486242e-001,2.375691e-001,1.780746e-005,1.780746e-005,,,,,,,,,,,,,,,,,,,,
1406890555.281,,-4.000000e+001,2.979968e+002,2.979968e+002,1,0,2.079955e+000,-7.751701e-002,-7.751702e-002,-6.550754e-001,-6.550754e-001,-4.010515e-002,-6.176635e-001,-6.176635e-001,-1.689297e-006,-1.689297e-006,,,,,,,,,,,,,,,,,,,,
1406890555.281,,-4.000000e+001,2.979968e+002,2.979968e+002,1,0,3.706243e+000,8.149968e-001,8.149968e-001,2.560934e-001,2.374384e-001,8.276171e-001,2.687137e-001,2.500588e-001,1.776090e-005,1.776090e-005,,,,,,,,,,,,,,,,,,,,
1406890673.578,,-3.500000e+001,2.980050e+002,2.979968e+002,1,0,4.366271e-001,7.806635e-001,7.806635e-001,2.685448e-001,2.591269e-001,7.571422e-001,2.450235e-001,2.356057e-001,1.701270e-005,1.701270e-005,,,,,,,,,,,,,,,,,,,,
1406890691.515,,-3.500000e+001,2.979968e+002,2.980050e+002,1,0,1.900050e+000,1.678518e-003,1.678518e-003,-5.353015e-001,-5.356593e-001,5.414926e-002,-4.828308e-001,-4.831886e-001,3.657929e-008,3.657929e-008,,,,,,,,,,,,,,,,,,,,
1406890691.515,,-3.500000e+001,2.979968e+002,2.980050e+002,1,0,3.810523e+000,7.460250e-001,7.460250e-001,2.244300e-001,2.086871e-001,7.754934e-001,2.538984e-001,2.381555e-001,1.625783e-005,1.625783e-005,,,,,,,,,,,,,,,,,,,,
1406890709.078,,-3.500000e+001,2.980050e+002,2.980050e+002,1,0,5.569670e-001,8.555865e-001,8.555864e-001,2.943052e-001,2.855649e-001,8.152710e-001,2.539898e-001,2.452495e-001,1.864546e-005,1.864546e-005,,,,,,,,,,,,,,,,,,,,
1406890834.828,,-3.000000e+001,2.980050e+002,2.979968e+002,1,0,1.719219e+000,1.234474e-001,1.234474e-001,-3.528346e-001,-3.536034e-001,1.588184e-001,-3.174635e-001,-3.182324e-001,2.690242e-006,2.690242e-006,,,,,,,,,,,,,,,,,,,,
1406890834.828,,-3.000000e+001,2.980050e+002,2.979968e+002,1,0,3.894113e+000,6.445509e-001,6.445509e-001,1.847983e-001,1.675001e-001,6.909038e-001,2.311512e-001,2.138531e-001,1.404645e-005,1.404645e-005,,,,,,,,,,,,,,,,,,,,
1406890853.328,,-3.000000e+001,2.979968e+002,2.979968e+002,1,0,6.838511e-001,7.515183e-001,7.515183e-001,2.844128e-001,2.775530e-001,6.934850e-001,2.263794e-001,2.195197e-001,1.637755e-005,1.637755e-005,,,,,,,,,,,,,,,,,,,,
1406890871.312,,-3.000000e+001,2.980050e+002,2.979968e+002,1,0,1.538990e+000,2.986236e-001,2.986236e-001,-1.853684e-001,-1.860039e-001,2.916196e-001,-1.923724e-001,-1.930079e-001,6.507791e-006,6.507791e-006,,,,,,,,,,,,,,,,,,,,
1406890871.312,,-3.000000e+001,2.980050e+002,2.979968e+002,1,0,3.954008e+000,6.451613e-001,6.451613e-001,1.702780e-001,1.605338e-001,7.012844e-001,2.264011e-001,2.166569e-001,1.405976e-005,1.405976e-005,,,,,,,,,,,,,,,,,,,,
1406890988.796,,-2.500000e+001,2.980050e+002,2.979968e+002,1,0,8.162842e-001,7.025361e-001,7.025361e-001,2.593509e-001,2.520139e-001,6.308915e-001,1.877063e-001,1.803693e-001,1.531011e-005,1.531011e-005,,,,,,,,,,,,,,,,,,,,
1406891006.531,,-2.500000e+001,2.979968e+002,2.979968e+002,1,0,1.361353e+000,4.425184e-001,4.425184e-001,-7.226021e-003,-8.214891e-003,3.944684e-001,-5.527601e-002,-5.626488e-002,9.643640e-006,9.643640e-006,,,,,,,,,,,,,,,,,,,,
1406891006.531,,-2.500000e+001,2.979968e+002,2.979968e+002,1,0,3.987874e+000,5.778680e-001,5.778680e-001,1.387539e-001,1.271347e-001,6.435322e-001,2.044182e-001,1.927989e-001,1.259326e-005,1.259326e-005,,,,,,,,,,,,,,,,,,,,
1406891024.765,,-2.500000e+001,2.979968e+002,2.979968e+002,1,0,9.545261e-001,6.854457e-001,6.854457e-001,2.292506e-001,2.249202e-001,6.016474e-001,1.454524e-001,1.411219e-001,1.493767e-005,1.493767e-005,,,,,,,,,,,,,,,,,,,,
1406891142.015,,-2.000000e+001,2.980050e+002,2.979968e+002,1,0,1.187780e+000,5.133213e-001,5.133213e-001,1.276527e-001,1.262933e-001,4.338270e-001,4.815833e-002,4.679888e-002,1.118663e-005,1.118663e-005,,,,,,,,,,,,,,,,,,,,
1406891142.015,,-2.000000e+001,2.980050e+002,2.979968e+002,1,0,3.994893e+000,4.872280e-001,4.872280e-001,1.132507e-001,1.001999e-001,5.589089e-001,1.849316e-001,1.718809e-001,1.061799e-005,1.061799e-005,,,,,,,,,,,,,,,,,,,,
1406891159.765,,-2.000000e+001,2.979968e+002,2.979968e+002,1,0,1.098870e+000,5.325480e-001,5.325480e-001,1.790921e-001,1.748733e-001,4.395086e-001,8.605274e-002,8.183390e-002,1.160563e-005,1.160563e-005,,,,,,,,,,,,,,,,,,,,
1406891177.500,,-2.000000e+001,2.979968e+002,2.979968e+002,1,0,1.018627e+000,6.099124e-001,6.099124e-001,1.978142e-001,1.971049e-001,5.294232e-001,1.173250e-001,1.166157e-001,1.329160e-005,1.329160e-005,,,,,,,,,,,,,,,,,,,,
1406891177.500,,-2.000000e+001,2.979968e+002,2.979968e+002,1,0,3.975076e+000,5.255287e-001,5.255287e-001,1.185135e-001,1.127213e-001,5.930664e-001,1.860512e-001,1.802589e-001,1.145266e-005,1.145266e-005,,,,,,,,,,,,,,,,,,,,
1406891294.734,,-1.500000e+001,2.979968e+002,2.979968e+002,1,0,1.249998e+000,4.286325e-001,4.286325e-001,1.160397e-001,1.131367e-001,3.431896e-001,3.059682e-002,2.769378e-002,9.341038e-006,9.341038e-006,,,,,,,,,,,,,,,,,,,,
1406891312.218,,-1.500000e+001,2.980050e+002,2.979885e+002,1,0,8.557101e-001,5.697806e-001,5.697806e-001,2.315620e-001,2.312058e-001,4.902557e-001,1.520371e-001,1.516810e-001,1.241703e-005,1.241703e-005,,,,,,,,,,,,,,,,,,,,
1406891312.218,,-1.500000e+001,2.980050e+002,2.979885e+002,1,0,3.930295e+000,4.387036e-001,4.387036e-001,1.026727e-001,1.001288e-001,5.038641e-001,1.678332e-001,1.652893e-001,9.560515e-006,9.560515e-006,,,,,,,,,,,,,,,,,,,,
1406891330.453,,-1.500000e+001,2.980050e+002,2.979885e+002,1,0,1.408226e+000,3.592028e-001,3.592029e-001,1.999665e-002,2.031708e-002,3.013418e-001,-3.786444e-002,-3.754401e-002,7.827983e-006,7.827983e-006,,,,,,,,,,,,,,,,,,,,
1406891449.218,,-1.000000e+001,2.979968e+002,2.979968e+002,1,0,6.998833e-001,5.276650e-001,5.276650e-001,2.209207e-001,2.208845e-001,4.535778e-001,1.468336e-001,1.467973e-001,1.149923e-005,1.149923e-005,,,,,,,,,,,,,,,,,,,,
1406891449.218,,-1.000000e+001,2.979968e+002,2.979968e+002,1,0,3.863254e+000,3.956725e-001,3.956725e-001,8.912299e-002,8.889195e-002,4.496824e-001,1.431330e-001,1.429019e-001,8.622756e-006,8.622756e-006,,,,,,,,,,,,,,,,,,,,
1406891467.500,,-1.000000e+001,2.979968e+002,2.979968e+002,1,0,1.573542e+000,2.298044e-001,2.298044e-001,-7.091305e-002,-6.894200e-002,2.165285e-001,-8.418893e-002,-8.221787e-002,5.008049e-006,5.008049e-006,,,,,,,,,,,,,,,,,,,,
1406891485.734,,-1.000000e+001,2.979968e+002,2.979968e+002,1,0,5.530659e-001,4.927213e-001,4.927213e-001,1.897017e-001,1.909180e-001,4.428521e-001,1.398325e-001,1.410488e-001,1.073771e-005,1.073771e-005,,,,,,,,,,,,,,,,,,,,
1406891485.734,,-1.000000e+001,2.979968e+002,2.979968e+002,1,0,3.777601e+000,4.086429e-001,4.086428e-001,9.981235e-002,1.068394e-001,4.428763e-001,1.340458e-001,1.410729e-001,8.905416e-006,8.905416e-006,,,,,,,,,,,,,,,,,,,,
1406891609.734,,-5.000000e+000,2.979968e+002,2.979968e+002,1,0,1.745193e+000,1.011689e-001,1.011689e-001,-1.546230e-001,-1.528479e-001,1.434092e-001,-1.123827e-001,-1.106076e-001,2.204740e-006,2.204740e-006,,,,,,,,,,,,,,,,,,,,
1406891626.968,,-5.000000e+000,2.980050e+002,2.980050e+002,1,0,4.173287e-001,3.437910e-001,3.437910e-001,1.227366e-001,1.251454e-001,3.203436e-001,9.928915e-002,1.016980e-001,7.492125e-006,7.492125e-006,,,,,,,,,,,,,,,,,,,,
1406891626.968,,-5.000000e+000,2.980050e+002,2.980050e+002,1,0,3.677087e+000,3.166296e-001,3.166295e-001,8.521706e-002,9.798394e-002,3.178187e-001,8.640623e-002,9.917311e-002,6.900204e-006,6.900204e-006,,,,,,,,,,,,,,,,,,,,
1406891645.265,,-5.000000e+000,2.979968e+002,2.980050e+002,1,0,1.921783e+000,6.561480e-003,6.561480e-003,-2.542585e-001,-2.452348e-001,8.448972e-002,-1.763303e-001,-1.673066e-001,1.429922e-007,1.429922e-007,,,,,,,,,,,,,,,,,,,,
1406891763.062,,0.000000e+000,2.979968e+002,2.979885e+002,1,0,2.956263e-001,2.406384e-001,2.406384e-001,4.446531e-002,4.848655e-002,2.578825e-001,6.170934e-002,6.573057e-002,5.244157e-006,5.244157e-006,,,,,,,,,,,,,,,,,,,,
1406891763.062,,0.000000e+000,2.979968e+002,2.979885e+002,1,0,3.565200e+000,2.693258e-001,2.693259e-001,5.743336e-002,7.717395e-002,2.369775e-001,2.508497e-002,4.482555e-002,5.869332e-006,5.869332e-006,,,,,,,,,,,,,,,,,,,,
1406891781.546,,0.000000e+000,2.979968e+002,2.979968e+002,1,0,2.101522e+000,-5.172887e-002,-5.172887e-002,-2.670955e-001,-2.520179e-001,4.230379e-002,-1.730628e-001,-1.579853e-001,-1.127311e-006,-1.127311e-006,,,,,,,,,,,,,,,,,,,,
1406891800.281,,0.000000e+000,2.979885e+002,2.980050e+002,1,0,1.912441e-001,2.111881e-001,2.111881e-001,-8.693829e-003,-2.195239e-003,2.718539e-001,5.197194e-002,5.847053e-002,4.602355e-006,4.602355e-006,,,,,,,,,,,,,,,,,,,,
1406891800.281,,0.000000e+000,2.979885e+002,2.980050e+002,1,0,3.444892e+000,2.894681e-001,2.894681e-001,4.629951e-002,7.608472e-002,2.346707e-001,-8.497868e-003,2.128734e-002,6.308285e-006,6.308285e-006,,,,,,,,,,,,,,,,,,,,
1406891917.812,,5.000000e+000,2.979968e+002,2.979968e+002,1,0,2.282525e+000,-1.338237e-001,-1.338237e-001,-2.292411e-001,-2.015367e-001,-3.593040e-002,-1.313478e-001,-1.036434e-001,-2.916375e-006,-2.916375e-006,,,,,,,,,,,,,,,,,,,,
1406891936.296,,5.000000e+000,2.979968e+002,2.979968e+002,1,0,1.076329e-001,3.631702e-002,3.631703e-002,-8.090223e-002,-6.976608e-002,1.427445e-001,2.552525e-002,3.666140e-002,7.914450e-007,7.914450e-007,,,,,,,,,,,,,,,,,,,,
1406891936.296,,5.000000e+000,2.979968e+002,2.979968e+002,1,0,3.318031e+000,1.469466e-001,1.469466e-001,-7.107592e-003,4.086351e-002,6.273746e-002,-9.131676e-002,-4.334565e-002,3.202359e-006,3.202359e-006,,,,,,,,,,,,,,,,,,,,
1406891954.031,,5.000000e+000,2.979968e+002,2.980050e+002,1,0,2.462481e+000,7.629627e-004,7.629627e-004,-2.064145e-001,-1.744855e-001,3.534436e-002,-1.718331e-001,-1.399041e-001,1.662700e-008,1.662700e-008,,,,,,,,,,,,,,,,,,,,
1406892078.796,,1.000000e+001,2.979968e+002,2.980050e+002,1,0,4.781982e-002,-7.873775e-002,-7.873776e-002,-1.479164e-001,-1.434199e-001,7.814615e-002,8.967537e-003,1.346398e-002,-1.715905e-006,-1.715905e-006,,,,,,,,,,,,,,,,,,,,
1406892078.796,,1.000000e+001,2.979968e+002,2.980050e+002,1,0,3.185532e+000,6.210517e-002,6.210517e-002,-2.088395e-002,-2.577003e-003,-3.140437e-002,-1.143935e-001,-9.608655e-002,1.353437e-006,1.353437e-006,,,,,,,,,,,,,,,,,,,,
1406892096.281,,1.000000e+001,2.980050e+002,2.979885e+002,1,0,2.640204e+000,-5.294961e-002,-5.294961e-002,-1.309171e-001,-1.198386e-001,-1.368343e-002,-9.165097e-002,-8.057237e-002,-1.153913e-006,-1.153913e-006,,,,,,,,,,,,,,,,,,,,
1406892114.765,,1.000000e+001,2.979885e+002,2.979968e+002,1,0,1.386851e-002,-7.614368e-002,-7.614368e-002,-1.618033e-001,-1.557947e-001,9.401425e-002,8.354615e-003,1.436325e-002,-1.659374e-006,-1.659374e-006,,,,,,,,,,,,,,,,,,,,
1406892114.765,,1.000000e+001,2.979885e+002,2.979968e+002,1,0,3.047335e+000,5.737480e-002,5.737480e-002,-4.550959e-002,-2.227620e-002,-1.783758e-002,-1.207220e-001,-9.748857e-002,1.250350e-006,1.250350e-006,,,,,,,,,,,,,,,,,,,,
1406892232.500,,1.500000e+001,2.980050e+002,2.980050e+002,1,0,2.814072e+000,-6.118961e-002,-6.118961e-002,-4.438210e-002,-1.089292e-001,-1.342134e-002,3.386174e-003,-6.116094e-002,-1.333484e-006,-1.333484e-006,,,,,,,,,,,,,,,,,,,,
1406892250.250,,1.500000e+001,2.979968e+002,2.980050e+002,1,0,6.959210e-003,-1.803644e-001,-1.803644e-001,-2.101627e-001,-2.365172e-001,2.278348e-002,-7.014873e-003,-3.336935e-002,-3.930618e-006,-3.930618e-006,,,,,,,,,,,,,,,,,,,,
1406892250.250,,1.500000e+001,2.979968e+002,2.980050e+002,1,0,2.902958e+000,-3.448591e-002,-3.448592e-002,6.543388e-003,-9.063874e-002,-3.943086e-002,1.598445e-003,-9.558369e-002,-7.515396e-007,-7.515396e-007,,,,,,,,,,,,,,,,,,,,
1406892268.984,,1.500000e+001,2.979968e+002,2.980050e+002,1,0,2.983049e+000,2.655110e-002,2.655110e-002,-2.044657e-002,-8.098523e-002,4.670443e-002,-2.932416e-004,-6.083190e-002,5.786189e-007,5.786189e-007,,,,,,,,,,,,,,,,,,,,
1406892386.781,,2.000000e+001,2.979968e+002,2.979968e+002,1,0,2.671291e-002,-2.459792e-001,-2.459792e-001,-2.324106e-001,-2.570861e-001,-4.504423e-002,-3.147558e-002,-5.615118e-002,-5.360536e-006,-5.360536e-006,,,,,,,,,,,,,,,,,,,,
1406892386.781,,2.000000e+001,2.979968e+002,2.979968e+002,1,0,2.751865e+000,-6.668294e-002,-6.668294e-002,9.300442e-003,-7.778990e-002,-5.228679e-002,2.369660e-002,-6.339374e-002,-1.453197e-006,-1.453197e-006,,,,,,,,,,,,,,,,,,,,
1406892404.015,,2.000000e+001,2.979968e+002,2.979885e+002,1,0,3.146227e+000,-5.813776e-002,-5.813776e-002,2.315288e-003,-5.330774e-002,-7.730356e-002,-1.685051e-002,-7.247354e-002,-1.266975e-006,-1.266975e-006,,,,,,,,,,,,,,,,,,,,
1406892421.750,,2.000000e+001,2.979885e+002,2.979968e+002,1,0,7.153213e-002,-2.221747e-001,-2.221747e-001,-2.151101e-001,-2.401428e-001,-4.047257e-002,-3.340795e-002,-5.844064e-002,-4.841775e-006,-4.841775e-006,,,,,,,,,,,,,,,,,,,,
1406892421.750,,2.000000e+001,2.979885e+002,2.979968e+002,1,0,2.593562e+000,-7.370220e-002,-7.370220e-002,-6.837266e-003,-9.167027e-002,-2.433316e-002,4.253177e-002,-4.230124e-002,-1.606166e-006,-1.606166e-006,,,,,,,,,,,,,,,,,,,,
1406892539.015,,2.500000e+001,2.979968e+002,2.979968e+002,1,0,3.301880e+000,-1.385540e-001,-1.385540e-001,-9.766027e-003,8.492012e-002,-2.436118e-001,-1.148238e-001,-2.013767e-002,-3.019457e-006,-3.019457e-006,,,,,,,,,,,,,,,,,,,,
1406892556.500,,2.500000e+001,2.979968e+002,2.979968e+002,1,0,1.385197e-001,-3.140354e-001,-3.140355e-001,-1.513005e-001,-1.058667e-001,-2.434775e-001,-8.074250e-002,-3.530876e-002,-6.843659e-006,-6.843659e-006,,,,,,,,,,,,,,,,,,,,
1406892556.500,,2.500000e+001,2.979968e+002,2.979968e+002,1,0,2.428242e+000,-1.187170e-001,-1.187170e-001,-5.880570e-002,8.945176e-002,-9.517264e-002,-3.526134e-002,1.129961e-001,-2.587156e-006,-2.587156e-006,,,,,,,,,,,,,,,,,,,,
1406892575.234,,2.500000e+001,2.980050e+002,2.980050e+002,1,0,3.448777e+000,-1.237526e-001,-1.237526e-001,-2.965757e-002,7.123802e-002,-1.901896e-001,-9.609459e-002,4.801005e-003,-2.696894e-006,-2.696894e-006,,,,,,,,,,,,,,,,,,,,
1406892692.734,,3.000000e+001,2.979968e+002,2.979885e+002,1,0,2.242005e-001,-3.942991e-001,-3.942991e-001,-1.517937e-001,-1.024963e-001,-3.419960e-001,-9.949051e-002,-5.019313e-002,-8.592812e-006,-8.592812e-006,,,,,,,,,,,,,,,,,,,,
1406892692.734,,3.000000e+001,2.979968e+002,2.979885e+002,1,0,2.256584e+000,-1.260414e-001,-1.260414e-001,1.047466e-002,1.657614e-001,-5.578514e-002,8.073097e-002,2.360177e-001,-2.746773e-006,-2.746773e-006,,,,,,,,,,,,,,,,,,,,
1406892710.515,,3.000000e+001,2.979968e+002,2.980050e+002,1,0,3.584499e+000,-2.626118e-001,-2.626118e-001,-8.270083e-002,2.229118e-002,-2.842121e-001,-1.043011e-001,6.908774e-004,-5.722999e-006,-5.722999e-006,,,,,,,,,,,,,,,,,,,,
1406892728.750,,3.000000e+001,2.980050e+002,2.979968e+002,1,0,3.247660e-001,-3.216651e-001,-3.216651e-001,-1.090614e-001,-5.580777e-002,-2.806862e-001,-6.808249e-002,-1.482889e-002,-7.009925e-006,-7.009925e-006,,,,,,,,,,,,,,,,,,,,
1406892846.734,,3.500000e+001,2.980050e+002,2.980050e+002,1,0,2.079916e+000,-5.981628e-002,-5.981628e-002,2.862042e-001,2.862042e-001,-1.042381e-001,2.417823e-001,2.417823e-001,-1.303553e-006,-1.303553e-006,,,,,,,,,,,,,,,,,,,,
1406892846.734,,3.500000e+001,2.980050e+002,2.980050e+002,1,0,3.706132e+000,-3.807184e-001,-3.807184e-001,-1.414755e-001,-3.469795e-002,-3.559086e-001,-1.166657e-001,-9.888172e-003,-8.296848e-006,-8.296848e-006,,,,,,,,,,,,,,,,,,,,
1406892864.218,,3.500000e+001,2.980050e+002,2.979968e+002,1,0,4.365271e-001,-3.935362e-001,-3.935362e-001,-8.457720e-002,-2.937096e-002,-3.866461e-001,-7.768711e-002,-2.248088e-002,-8.576181e-006,-8.576181e-006,,,,,,,,,,,,,,,,,,,,
1406892881.968,,3.500000e+001,2.979968e+002,2.979968e+002,1,0,1.900137e+000,-1.068148e-003,-1.068148e-003,3.415700e-001,3.441449e-001,-1.133211e-002,3.313060e-001,3.338809e-001,-2.327773e-008,-2.327773e-008,,,,,,,,,,,,,,,,,,,,
1406892881.968,,3.500000e+001,2.979968e+002,2.979968e+002,1,0,3.810460e+000,-4.078799e-001,-4.078799e-001,-1.759625e-001,-6.266689e-002,-3.326135e-001,-1.006961e-001,1.259953e-002,-8.888767e-006,-8.888767e-006,,,,,,,,,,,,,,,,,,,,
1406892999.468,,4.000000e+001,2.979968e+002,2.980050e+002,1,0,5.568618e-001,-4.461806e-001,-4.461806e-001,-6.068455e-002,-1.429170e-003,-4.747052e-001,-8.920909e-002,-2.995372e-002,-9.723436e-006,-9.723436e-006,,,,,,,,,,,,,,,,,,,,
1406893017.703,,4.000000e+001,2.979968e+002,2.979968e+002,1,0,1.719397e+000,2.563555e-002,2.563555e-002,4.452437e-001,4.504262e-001,4.863804e-002,4.682462e-001,4.734287e-001,5.586652e-007,5.586652e-007,,,,,,,,,,,,,,,,,,,,
1406893017.703,,4.000000e+001,2.979968e+002,2.979968e+002,1,0,3.894119e+000,-5.598621e-001,-5.598621e-001,-2.516779e-001,-1.350715e-001,-4.315432e-001,-1.233591e-001,-6.752610e-003,-1.220085e-005,-1.220085e-005,,,,,,,,,,,,,,,,,,,,
1406893035.437,,4.000000e+001,2.979968e+002,2.979968e+002,1,0,6.837702e-001,-3.317362e-001,-3.317362e-001,9.219190e-003,7.218069e-002,-3.727524e-001,-3.179697e-002,3.116453e-002,-7.229395e-006,-7.229395e-006,,,,,,,,,,,,,,,,,,,,
1406893147.421,,4.500000e+001,2.980050e+002,2.980050e+002,1,0,1.539293e+000,-5.432295e-002,-5.432295e-002,4.950937e-001,5.025626e-001,-7.039883e-002,4.790178e-001,4.864867e-001,-1.183838e-006,-1.183838e-006,,,,,,,,,,,,,,,,,,,,
1406893147.421,,4.500000e+001,2.980050e+002,2.980050e+002,1,0,3.954005e+000,-7.695242e-001,-7.695242e-001,-3.271621e-001,-2.126387e-001,-5.989487e-001,-1.565866e-001,-4.206312e-002,-1.676993e-005,-1.676993e-005,,,,,,,,,,,,,,,,,,,,
1406893165.234,,4.500000e+001,2.979968e+002,2.980050e+002,1,0,8.162851e-001,-4.091006e-001,-4.091006e-001,5.166176e-002,1.149323e-001,-4.783564e-001,-1.759398e-002,4.567653e-002,-8.915363e-006,-8.915363e-006,,,,,,,,,,,,,,,,,,,,
1406893182.968,,4.500000e+001,2.979968e+002,2.979968e+002,1,0,1.361369e+000,-8.255257e-002,-8.255257e-002,4.377139e-001,4.481685e-001,-1.552102e-001,3.650563e-001,3.755108e-001,-1.799034e-006,-1.799034e-006,,,,,,,,,,,,,,,,,,,,
1406893182.968,,4.500000e+001,2.979968e+002,2.979968e+002,1,0,3.987880e+000,-7.481613e-001,-7.481613e-001,-3.402813e-001,-2.174402e-001,-5.603686e-001,-1.524887e-001,-2.964759e-002,-1.630437e-005,-1.630437e-005,,,,,,,,,,,,,,,,,,,,
1406893299.218,,5.000000e+001,2.980050e+002,2.980050e+002,1,0,9.544411e-001,-4.785302e-001,-4.785302e-001,1.251242e-001,1.912226e-001,-5.830986e-001,2.055583e-002,8.665425e-002,-1.042841e-005,-1.042841e-005,,,,,,,,,,,,,,,,,,,,
1406893317.453,,5.000000e+001,2.980050e+002,2.980050e+002,1,0,1.187700e+000,-2.639851e-001,-2.639851e-001,3.568774e-001,3.697864e-001,-4.050190e-001,2.158436e-001,2.287526e-001,-5.752917e-006,-5.752917e-006,,,,,,,,,,,,,,,,,,,,
1406893317.453,,5.000000e+001,2.980050e+002,2.980050e+002,1,0,3.994859e+000,-9.199805e-001,-9.199805e-001,-4.101353e-001,-2.862089e-001,-7.160744e-001,-2.062292e-001,-8.230287e-002,-2.004875e-005,-2.004875e-005,,,,,,,,,,,,,,,,,,,,
1406893334.687,,5.000000e+001,2.980050e+002,2.980050e+002,1,0,1.098850e+000,-3.331095e-001,-3.331095e-001,2.399611e-001,3.104348e-001,-4.365215e-001,1.365491e-001,2.070228e-001,-7.259316e-006,-7.259316e-006,,,,,,,,,,,,,,,,,,,,
1406893458.187,,7.500000e+001,2.980050e+002,2.980050e+002,1,0,1.018830e+000,-5.229347e-001,-5.229347e-001,1.620171e-001,1.786860e-001,-7.287835e-001,-4.383171e-002,-2.716285e-002,-1.139607e-005,-1.139607e-005,,,,,,,,,,,,,,,,,,,,
1406893458.187,,7.500000e+001,2.980050e+002,2.980050e+002,1,0,3.975096e+000,-1.063417e+000,-1.063417e+000,-4.979258e-001,-3.617968e-001,-8.444423e-001,-2.789507e-001,-1.428217e-001,-2.317456e-005,-2.317456e-005,,,,,,,,,,,,,,,,,,,,
1406893476.421,,7.500000e+001,2.979968e+002,2.980050e+002,1,0,1.249929e+000,-3.257851e-001,-3.257851e-001,2.898915e-001,3.668566e-001,-4.540502e-001,1.616264e-001,2.385915e-001,-7.099682e-006,-7.099682e-006,,,,,,,,,,,,,,,,,,,,
1406893494.671,,7.500000e+001,2.979968e+002,2.980050e+002,1,0,8.556916e-001,-6.036561e-001,-6.036561e-001,2.397645e-002,4.402953e-002,-7.951905e-001,-1.675580e-001,-1.475049e-001,-1.315519e-005,-1.315519e-005,,,,,,,,,,,,,,,,,,,,
1406893494.671,,7.500000e+001,2.979968e+002,2.980050e+002,1,0,3.930253e+000,-9.810175e-001,-9.810175e-001,-4.765682e-001,-3.333318e-001,-7.916393e-001,-2.871900e-001,-1.439536e-001,-2.137885e-005,-2.137885e-005,,,,,,,,,,,,,,,,,,,,
1406893623.921,,1.000000e+002,2.979968e+002,2.979968e+002,1,0,1.408217e+000,-3.010651e-001,-3.010651e-001,4.519589e-001,5.444610e-001,-3.936207e-001,3.594032e-001,4.519054e-001,-6.560956e-006,-6.560956e-006,,,,,,,,,,,,,,,,,,,,
1406893641.656,,1.000000e+002,2.980050e+002,2.980050e+002,1,0,6.996560e-001,-8.809168e-001,-8.809168e-001,-1.075549e-001,-8.120209e-002,-1.075849e+000,-3.024874e-001,-2.761346e-001,-1.919736e-005,-1.919736e-005,,,,,,,,,,,,,,,,,,,,
1406893641.656,,1.000000e+002,2.980050e+002,2.980050e+002,1,0,3.863178e+000,-1.149022e+000,-1.149022e+000,-5.173064e-001,-3.493072e-001,-9.815196e-001,-3.498042e-001,-1.818050e-001,-2.504004e-005,-2.504004e-005,,,,,,,,,,,,,,,,,,,,
1406893659.156,,1.000000e+002,2.979968e+002,2.980050e+002,1,0,1.573534e+000,-1.434370e-001,-1.434370e-001,4.936934e-001,5.911831e-001,-1.419410e-001,4.951894e-001,5.926790e-001,-3.125848e-006,-3.125848e-006,,,,,,,,,,,,,,,,,,,,
1406893659.156,,1.000000e+002,2.979968e+002,2.980050e+002,1,0,2.256592e+000,-7.019257e-003,-7.019257e-003,5.228725e-001,7.276008e-001,2.310225e-001,7.609143e-001,9.656425e-001,-1.529670e-007,-1.529670e-007,,,,,,,,,,,,,,,,,,,,