File: Sample Data Files/2014-07-31 EB on isolated PMN-PT no Ti spontaneous in situ repeat/Ni-NiO_298K_SiO2_PMN-PT_5.0Tprebias_170V_Au_back.rso.raw
[Header]
TITLE,MPMS RSO Measurement
BYAPP,MPMS Measurement,2.1,Raw with ABS
FILEOPENTIME, 1406868190.546000 7/31/2014, 9:43:10 PM

INFO, APPNAME, MPMS MultiVu Application, Revision 1.58,  Build 076

INFO, NAME, EB in situ 2
INFO, WEIGHT, 0.000
INFO, AREA, 0.000
INFO, LENGTH, 0.000
INFO, SHAPE, 0
INFO, COMMENT,
INFO, SEQUENCE FILE: MHcurveUpTo100.seq


INFO, BACKGROUND DATA FILE:, None


STARTUPAXIS,X,8,LINEAR,AUTO,0.000000,0.000000
STARTUPAXIS,Y1,9,LINEAR,AUTO,0.000000,0.000000


STARTUPGROUP,Longitudinal
FIELDGROUP,Longitudinal,1,2,3,4,5,6,7,8,9,10,11,12,13,14,15,16,17,18,19,20,21,22
FIELDGROUP,Transverse,1,2,3,4,5,6,7,8,23,24,25,26,27,28,29,30,31,32,33,34,35,36

PLOT_APPEARANCE,ALL,HORZ_GRID_ON,VERT_GRID_ON,MARKERS_ONLY

[Data]
Time,Comment,Field (Oe),Start Temperature (K),End Temperature (K),Scan,Rejected,Position (cm),Long Voltage,Long Average Voltage,Long Detrended Voltage,Long Demeaned Voltage,Long Reg Fit,Long Detrended Fit,Long Demeaned Fit,Long Scaled Response,Long Avg. Scaled Response,Long Background Response,Long Response [w/ABS],Long Detrended Resp. [w/ABS],Long Fit [w/ABS],Long Detrended Fit [w/ABS],Trans Voltage,Trans Average Voltage,Trans Detrended Voltage,Trans Demeaned Voltage,Trans Reg Fit,Trans Detrended Fit,Trans Demeaned Fit,Trans Scaled Response,Trans Avg. Scaled Response,Trans Background Response,Trans Response [w/ABS],Trans Detrended Resp. [w/ABS],Trans Adjusted Fit,Trans Detrended Fit [w/ABS],
1406868190.531,,1.000000e+002,2.980050e+002,2.979968e+002,1,0,2.080263e+000,-5.157628e-002,-5.157628e-002,2.111614e+000,2.111614e+000,5.183526e-002,2.215026e+000,2.215026e+000,-1.123975e-006,-1.123975e-006,,,,,,,,,,,,,,,,,,,,
1406868190.531,,1.000000e+002,2.980050e+002,2.979968e+002,1,0,3.706075e+000,-2.982116e+000,-2.982116e+000,-9.782636e-001,-8.189254e-001,-2.973478e+000,-9.696257e-001,-8.102875e-001,-6.498771e-005,-6.498771e-005,,,,,,,,,,,,,,,,,,,,
1406868208.765,,1.000000e+002,2.979968e+002,2.980050e+002,1,0,4.364608e-001,-3.008667e+000,-3.008667e+000,-9.524778e-001,-8.689241e-001,-3.028294e+000,-9.721049e-001,-8.885512e-001,-6.556632e-005,-6.556632e-005,,,,,,,,,,,,,,,,,,,,
1406868227.250,,1.000000e+002,2.980050e+002,2.979968e+002,1,0,1.900333e+000,-7.583849e-002,-7.583850e-002,2.043644e+000,2.047400e+000,3.683219e-002,2.156315e+000,2.160071e+000,-1.652709e-006,-1.652709e-006,,,,,,,,,,,,,,,,,,,,
1406868227.250,,1.000000e+002,2.980050e+002,2.979968e+002,1,0,3.810388e+000,-2.992798e+000,-2.992798e+000,-1.034852e+000,-8.695586e-001,-2.886136e+000,-9.281898e-001,-7.628968e-001,-6.522048e-005,-6.522048e-005,,,,,,,,,,,,,,,,,,,,
1406868353.015,,7.500000e+001,2.980050e+002,2.979968e+002,1,0,5.567725e-001,-2.527085e+000,-2.527085e+000,-7.141722e-001,-6.411096e-001,-2.608920e+000,-7.960075e-001,-7.229449e-001,-5.507158e-005,-5.507158e-005,,,,,,,,,,,,,,,,,,,,
1406868371.250,,7.500000e+001,2.979968e+002,2.979968e+002,1,0,1.719469e+000,-2.864162e-001,-2.864162e-001,1.539958e+000,1.546381e+000,-2.636193e-001,1.562755e+000,1.569178e+000,-6.241734e-006,-6.241734e-006,,,,,,,,,,,,,,,,,,,,
1406868371.250,,7.500000e+001,2.979968e+002,2.979968e+002,1,0,3.894055e+000,-2.616962e+000,-2.616962e+000,-9.286871e-001,-7.841651e-001,-2.446758e+000,-7.584825e-001,-6.139605e-001,-5.703023e-005,-5.703023e-005,,,,,,,,,,,,,,,,,,,,
1406868388.281,,7.500000e+001,2.979968e+002,2.979885e+002,1,0,6.836250e-001,-2.343211e+000,-2.343211e+000,-5.637442e-001,-4.853854e-001,-2.458223e+000,-6.787562e-001,-6.003973e-001,-5.106450e-005,-5.106450e-005,,,,,,,,,,,,,,,,,,,,
1406868519.359,,5.000000e+001,2.979968e+002,2.980050e+002,1,0,1.539216e+000,-4.779199e-001,-4.779198e-001,9.628053e-001,9.711801e-001,-5.542710e-001,8.864542e-001,8.948289e-001,-1.041511e-005,-1.041511e-005,,,,,,,,,,,,,,,,,,,,
1406868519.359,,5.000000e+001,2.979968e+002,2.980050e+002,1,0,3.953945e+000,-2.094485e+000,-2.094485e+000,-7.737977e-001,-6.453854e-001,-1.902894e+000,-5.822064e-001,-4.537941e-001,-4.564424e-005,-4.564424e-005,,,,,,,,,,,,,,,,,,,,
1406868537.156,,5.000000e+001,2.980050e+002,2.980050e+002,1,0,8.162133e-001,-1.626789e+000,-1.626789e+000,-2.826549e-001,-2.099067e-001,-1.753717e+000,-4.095832e-001,-3.368350e-001,-3.545193e-005,-3.545193e-005,,,,,,,,,,,,,,,,,,,,
1406868555.406,,5.000000e+001,2.980050e+002,2.980050e+002,1,0,1.361786e+000,-7.539598e-001,-7.539598e-001,6.727926e-001,6.842196e-001,-8.974263e-001,5.293261e-001,5.407531e-001,-1.643073e-005,-1.643073e-005,,,,,,,,,,,,,,,,,,,,
1406868555.406,,5.000000e+001,2.980050e+002,2.980050e+002,1,0,3.987933e+000,-2.087924e+000,-2.087924e+000,-7.840116e-001,-6.497444e-001,-1.865216e+000,-5.613042e-001,-4.270370e-001,-4.550125e-005,-4.550125e-005,,,,,,,,,,,,,,,,,,,,
1406868673.156,,4.500000e+001,2.980050e+002,2.979968e+002,1,0,9.543701e-001,-1.333506e+000,-1.333506e+000,-6.146620e-002,7.863522e-003,-1.477767e+000,-2.057266e-001,-1.363969e-001,-2.906056e-005,-2.906056e-005,,,,,,,,,,,,,,,,,,,,
1406868690.890,,4.500000e+001,2.979968e+002,2.979968e+002,1,0,1.187611e+000,-9.732353e-001,-9.732352e-001,3.522644e-001,3.661338e-001,-1.150842e+000,1.746577e-001,1.885271e-001,-2.120932e-005,-2.120932e-005,,,,,,,,,,,,,,,,,,,,
1406868690.890,,4.500000e+001,2.979968e+002,2.979968e+002,1,0,3.994854e+000,-1.954253e+000,-1.954253e+000,-7.480299e-001,-6.148837e-001,-1.734531e+000,-5.283079e-001,-3.951616e-001,-4.258823e-005,-4.258823e-005,,,,,,,,,,,,,,,,,,,,
1406868709.125,,4.500000e+001,2.979968e+002,2.980050e+002,1,0,1.098760e+000,-1.095920e+000,-1.095920e+000,1.691331e-001,2.453192e-001,-1.242819e+000,2.223358e-002,9.841979e-002,-2.388293e-005,-2.388293e-005,,,,,,,,,,,,,,,,,,,,
1406868825.859,,4.000000e+001,2.980050e+002,2.979968e+002,1,0,1.018784e+000,-1.190985e+000,-1.190985e+000,7.150725e-002,8.725119e-002,-1.369964e+000,-1.074723e-001,-9.172833e-002,-2.595466e-005,-2.595466e-005,,,,,,,,,,,,,,,,,,,,
1406868825.859,,4.000000e+001,2.980050e+002,2.979968e+002,1,0,3.975129e+000,-1.862697e+000,-1.862697e+000,-7.130367e-001,-5.844612e-001,-1.659862e+000,-5.102015e-001,-3.816260e-001,-4.059302e-005,-4.059302e-005,,,,,,,,,,,,,,,,,,,,
1406868844.093,,4.000000e+001,2.979968e+002,2.979968e+002,1,0,1.249791e+000,-8.122501e-001,-8.122501e-001,3.921659e-001,4.706709e-001,-9.438252e-001,2.605908e-001,3.390958e-001,-1.770104e-005,-1.770104e-005,,,,,,,,,,,,,,,,,,,,
1406868861.625,,4.000000e+001,2.980050e+002,2.979968e+002,1,0,8.556011e-001,-1.431318e+000,-1.431318e+000,-1.591166e-001,-1.399242e-001,-1.600323e+000,-3.281215e-001,-3.089291e-001,-3.119214e-005,-3.119214e-005,,,,,,,,,,,,,,,,,,,,
1406868861.625,,4.000000e+001,2.980050e+002,2.979968e+002,1,0,3.930300e+000,-1.866359e+000,-1.866359e+000,-7.120543e-001,-5.749656e-001,-1.686493e+000,-5.321881e-001,-3.950994e-001,-4.067282e-005,-4.067282e-005,,,,,,,,,,,,,,,,,,,,
1406868985.875,,3.500000e+001,2.979968e+002,2.979968e+002,1,0,1.408163e+000,-5.235450e-001,-5.235450e-001,5.852822e-001,6.601475e-001,-6.170422e-001,4.917850e-001,5.666504e-001,-1.140941e-005,-1.140941e-005,,,,,,,,,,,,,,,,,,,,
1406869003.109,,3.500000e+001,2.979968e+002,2.979968e+002,1,0,6.998131e-001,-1.449629e+000,-1.449629e+000,-3.166509e-001,-2.954662e-001,-1.592607e+000,-4.596287e-001,-4.384440e-001,-3.159120e-005,-3.159120e-005,,,,,,,,,,,,,,,,,,,,
1406869003.109,,3.500000e+001,2.979968e+002,2.979968e+002,1,0,3.863291e+000,-1.674398e+000,-1.674398e+000,-6.552875e-001,-5.202351e-001,-1.545348e+000,-5.262374e-001,-3.911849e-001,-3.648951e-005,-3.648951e-005,,,,,,,,,,,,,,,,,,,,
1406869020.890,,3.500000e+001,2.979968e+002,2.979968e+002,1,0,1.573421e+000,-3.018281e-001,-3.018281e-001,7.889761e-001,8.683138e-001,-3.245168e-001,7.662874e-001,8.456250e-001,-6.577622e-006,-6.577622e-006,,,,,,,,,,,,,,,,,,,,
1406869139.125,,3.000000e+001,2.980050e+002,2.980050e+002,1,0,5.529292e-001,-1.454970e+000,-1.454970e+000,-4.065142e-001,-3.836762e-001,-1.551785e+000,-5.033298e-001,-4.804918e-001,-3.170761e-005,-3.170761e-005,,,,,,,,,,,,,,,,,,,,
1406869139.125,,3.000000e+001,2.980050e+002,2.980050e+002,1,0,3.777590e+000,-1.521653e+000,-1.521653e+000,-5.823122e-001,-4.503592e-001,-1.451765e+000,-5.124243e-001,-3.804713e-001,-3.316081e-005,-3.316081e-005,,,,,,,,,,,,,,,,,,,,
1406869156.687,,3.000000e+001,2.980050e+002,2.979968e+002,1,0,1.745112e+000,-1.121555e-001,-1.121555e-001,8.822044e-001,9.638209e-001,-4.574179e-002,9.486181e-001,1.030235e+000,-2.444163e-006,-2.444163e-006,,,,,,,,,,,,,,,,,,,,
1406869174.921,,3.000000e+001,2.980050e+002,2.980050e+002,1,0,4.174249e-001,-1.549883e+000,-1.549883e+000,-4.742319e-001,-4.482136e-001,-1.593402e+000,-5.177516e-001,-4.917333e-001,-3.377600e-005,-3.377600e-005,,,,,,,,,,,,,,,,,,,,
1406869174.921,,3.000000e+001,2.980050e+002,2.980050e+002,1,0,3.677117e+000,-1.490371e+000,-1.490371e+000,-5.265996e-001,-3.887025e-001,-1.481527e+000,-5.177552e-001,-3.798581e-001,-3.247910e-005,-3.247910e-005,,,,,,,,,,,,,,,,,,,,
1406869290.421,,2.500000e+001,2.980050e+002,2.979968e+002,1,0,1.921710e+000,1.922666e-002,1.922666e-002,9.044328e-001,9.816062e-001,1.475576e-001,1.032764e+000,1.109937e+000,4.189995e-007,4.189995e-007,,,,,,,,,,,,,,,,,,,,
1406869308.406,,2.500000e+001,2.979968e+002,2.979968e+002,1,0,2.957214e-001,-1.408582e+000,-1.408582e+000,-4.735881e-001,-4.454715e-001,-1.386934e+000,-4.519401e-001,-4.238234e-001,-3.069670e-005,-3.069670e-005,,,,,,,,,,,,,,,,,,,,
1406869308.406,,2.500000e+001,2.979968e+002,2.979968e+002,1,0,3.565288e+000,-1.226997e+000,-1.226997e+000,-4.019134e-001,-2.638863e-001,-1.276023e+000,-4.509401e-001,-3.129130e-001,-2.673949e-005,-2.673949e-005,,,,,,,,,,,,,,,,,,,,
1406869326.140,,2.500000e+001,2.979968e+002,2.979968e+002,1,0,2.101460e+000,7.858516e-002,7.858516e-002,9.391147e-001,1.024452e+000,2.245931e-001,1.085123e+000,1.170460e+000,1.712578e-006,1.712578e-006,,,,,,,,,,,,,,,,,,,,
1406869443.125,,2.000000e+001,2.980050e+002,2.979885e+002,1,0,1.913527e-001,-1.282998e+000,-1.282998e+000,-4.570744e-001,-4.284598e-001,-1.199894e+000,-3.739699e-001,-3.453553e-001,-2.795992e-005,-2.795992e-005,,,,,,,,,,,,,,,,,,,,
1406869443.125,,2.000000e+001,2.980050e+002,2.979885e+002,1,0,3.444994e+000,-9.822383e-001,-9.822382e-001,-2.588505e-001,-1.276999e-001,-1.073086e+000,-3.496985e-001,-2.185479e-001,-2.140557e-005,-2.140557e-005,,,,,,,,,,,,,,,,,,,,
1406869460.859,,2.000000e+001,2.979968e+002,2.979968e+002,1,0,2.282432e+000,6.408887e-002,6.408887e-002,8.135126e-001,9.011019e-001,1.576795e-001,9.071033e-001,9.946926e-001,1.396666e-006,1.396666e-006,,,,,,,,,,,,,,,,,,,,
1406869478.609,,2.000000e+001,2.979968e+002,2.979968e+002,1,0,1.077816e-001,-1.284066e+000,-1.284066e+000,-4.769169e-001,-4.440781e-001,-1.147855e+000,-3.407058e-001,-3.078669e-001,-2.798320e-005,-2.798320e-005,,,,,,,,,,,,,,,,,,,,
1406869478.609,,2.000000e+001,2.979968e+002,2.979968e+002,1,0,3.318174e+000,-8.368176e-001,-8.368175e-001,-1.382888e-001,3.170729e-003,-9.561360e-001,-2.576073e-001,-1.161478e-001,-1.823646e-005,-1.823646e-005,,,,,,,,,,,,,,,,,,,,
1406869596.609,,1.500000e+001,2.980050e+002,2.980050e+002,1,0,2.462430e+000,3.067110e-002,3.067110e-002,6.614966e-001,7.439794e-001,3.454214e-002,6.653676e-001,7.478504e-001,6.684047e-007,6.684047e-007,,,,,,,,,,,,,,,,,,,,
1406869614.593,,1.500000e+001,2.979968e+002,2.979968e+002,1,0,4.787052e-002,-1.100650e+000,-1.100650e+000,-4.386736e-001,-4.046566e-001,-9.395444e-001,-2.775680e-001,-2.435510e-001,-2.398608e-005,-2.398608e-005,,,,,,,,,,,,,,,,,,,,
1406869614.593,,1.500000e+001,2.979968e+002,2.979968e+002,1,0,3.185609e+000,-5.299539e-001,-5.299539e-001,2.754154e-002,1.660396e-001,-6.680557e-001,-1.105603e-001,2.793777e-002,-1.154910e-005,-1.154910e-005,,,,,,,,,,,,,,,,,,,,
1406869632.828,,1.500000e+001,2.979885e+002,2.979968e+002,1,0,2.640268e+000,-4.623554e-002,-4.623554e-002,5.508434e-001,6.393439e-001,-1.273543e-001,4.697247e-001,5.582252e-001,-1.007595e-006,-1.007595e-006,,,,,,,,,,,,,,,,,,,,
1406869749.312,,1.000000e+001,2.979968e+002,2.980050e+002,1,0,1.383402e-002,-9.462264e-001,-9.462264e-001,-3.995582e-001,-3.638148e-001,-7.706773e-001,-2.240091e-001,-1.882657e-001,-2.062079e-005,-2.062079e-005,,,,,,,,,,,,,,,,,,,,
1406869749.312,,1.000000e+001,2.979968e+002,2.980050e+002,1,0,3.047335e+000,-2.710043e-001,-2.710044e-001,1.731994e-001,3.114072e-001,-4.084690e-001,3.573484e-002,1.739426e-001,-5.905907e-006,-5.905907e-006,,,,,,,,,,,,,,,,,,,,
1406869767.046,,1.000000e+001,2.979968e+002,2.980050e+002,1,0,2.814096e+000,-6.225776e-002,-6.225776e-002,3.867526e-001,4.751087e-001,-1.957544e-001,2.532560e-001,3.416121e-001,-1.356762e-006,-1.356762e-006,,,,,,,,,,,,,,,,,,,,
1406869785.281,,1.000000e+001,2.980050e+002,2.979968e+002,1,0,6.944508e-003,-9.355449e-001,-9.355449e-001,-4.015902e-001,-3.636457e-001,-7.541870e-001,-2.202323e-001,-1.822878e-001,-2.038801e-005,-2.038801e-005,,,,,,,,,,,,,,,,,,,,
1406869785.281,,1.000000e+001,2.980050e+002,2.979968e+002,1,0,2.903027e+000,-1.458785e-001,-1.458785e-001,2.861004e-001,4.260207e-001,-2.637980e-001,1.681809e-001,3.081013e-001,-3.179080e-006,-3.179080e-006,,,,,,,,,,,,,,,,,,,,
1406869904.343,,5.000000e+000,2.979968e+002,2.979968e+002,1,0,2.983062e+000,-8.850367e-002,-8.850368e-002,2.496840e-001,3.367982e-001,-2.397404e-001,9.844730e-002,1.855615e-001,-1.928732e-006,-1.928732e-006,,,,,,,,,,,,,,,,,,,,
1406869922.828,,5.000000e+000,2.979968e+002,2.980050e+002,1,0,2.670910e-002,-6.938383e-001,-6.938383e-001,-3.488265e-001,-3.091843e-001,-5.241605e-001,-1.791487e-001,-1.395065e-001,-1.512059e-005,-1.512059e-005,,,,,,,,,,,,,,,,,,,,
1406869922.828,,5.000000e+000,2.979968e+002,2.980050e+002,1,0,2.751916e+000,1.052889e-001,1.052889e-001,3.500292e-001,4.899428e-001,3.806851e-002,2.828089e-001,4.227225e-001,2.294526e-006,2.294526e-006,,,,,,,,,,,,,,,,,,,,
1406869940.328,,5.000000e+000,2.980050e+002,2.979968e+002,1,0,3.146244e+000,-1.915036e-001,-1.915036e-001,1.303466e-001,2.210447e-001,-3.420220e-001,-2.017173e-002,7.052633e-002,-4.173376e-006,-4.173376e-006,,,,,,,,,,,,,,,,,,,,
1406870057.562,,0.000000e+000,2.979968e+002,2.979885e+002,1,0,7.146427e-002,-4.199347e-001,-4.199347e-001,-2.825652e-001,-2.449140e-001,-2.708619e-001,-1.334924e-001,-9.584121e-002,-9.151503e-006,-9.151503e-006,,,,,,,,,,,,,,,,,,,,
1406870057.562,,0.000000e+000,2.979968e+002,2.979885e+002,1,0,2.593618e+000,2.969451e-001,2.969451e-001,3.443700e-001,4.719658e-001,2.978491e-001,3.452740e-001,4.728698e-001,6.471230e-006,6.471230e-006,,,,,,,,,,,,,,,,,,,,
1406870075.796,,0.000000e+000,2.979885e+002,2.980050e+002,1,0,3.301965e+000,-1.953185e-002,-1.953185e-002,5.274703e-002,1.429446e-001,-1.353969e-001,-6.311804e-002,2.707955e-002,-4.256513e-007,-4.256513e-007,,,,,,,,,,,,,,,,,,,,
1406870094.062,,0.000000e+000,2.980050e+002,2.979968e+002,1,0,1.384260e-001,-4.248177e-001,-4.248177e-001,-2.645143e-001,-2.238301e-001,-3.039431e-001,-1.436398e-001,-1.029556e-001,-9.257916e-006,-9.257916e-006,,,,,,,,,,,,,,,,,,,,
1406870094.062,,0.000000e+000,2.980050e+002,2.979968e+002,1,0,2.428234e+000,2.812281e-001,2.812281e-001,3.494567e-001,4.822156e-001,3.509858e-001,4.192145e-001,5.519733e-001,6.128713e-006,6.128713e-006,,,,,,,,,,,,,,,,,,,,
1406870212.312,,-5.000000e+000,2.979968e+002,2.979968e+002,1,0,3.448793e+000,1.458785e-001,1.458785e-001,3.898996e-002,8.369014e-002,1.030176e-001,-3.870938e-003,4.082923e-002,3.179082e-006,3.179082e-006,,,,,,,,,,,,,,,,,,,,
1406870230.046,,-5.000000e+000,2.979968e+002,2.980050e+002,1,0,2.241960e-001,-5.325480e-002,-5.325480e-002,-1.657846e-001,-1.440324e-001,4.336886e-002,-6.916097e-002,-4.740876e-002,-1.160564e-006,-1.160564e-006,,,,,,,,,,,,,,,,,,,,
1406870230.046,,-5.000000e+000,2.979968e+002,2.980050e+002,1,0,2.256720e+000,3.695792e-001,3.695791e-001,2.102821e-001,2.788015e-001,4.249716e-001,2.656745e-001,3.341939e-001,8.054118e-006,8.054118e-006,,,,,,,,,,,,,,,,,,,,
1406870248.093,,-5.000000e+000,2.979968e+002,2.979968e+002,1,0,3.584490e+000,1.225318e-001,1.225318e-001,-2.447006e-002,1.532002e-002,1.100616e-001,-3.694025e-002,2.849825e-003,2.670296e-006,2.670296e-006,,,,,,,,,,,,,,,,,,,,
1406870371.390,,-1.000000e+001,2.980050e+002,2.979968e+002,1,0,3.246437e-001,2.821436e-001,2.821436e-001,-3.382222e-002,4.156335e-002,2.926829e-001,-2.328289e-002,5.210267e-002,6.148660e-006,6.148660e-006,,,,,,,,,,,,,,,,,,,,
1406870389.125,,-1.000000e+001,2.980050e+002,2.979968e+002,1,0,2.079894e+000,3.103732e-001,3.103732e-001,-4.843849e-002,-4.843849e-002,3.659339e-001,7.122159e-003,7.122159e-003,6.763859e-006,6.763859e-006,,,,,,,,,,,,,,,,,,,,
1406870389.125,,-1.000000e+001,2.980050e+002,2.979968e+002,1,0,3.706100e+000,4.042177e-001,4.042177e-001,2.362635e-002,4.540592e-002,4.440553e-001,6.346404e-002,8.524361e-002,8.808979e-006,8.808979e-006,,,,,,,,,,,,,,,,,,,,
1406870407.890,,-1.000000e+001,2.979968e+002,2.979968e+002,1,0,4.364801e-001,3.422651e-001,3.422651e-001,-4.565858e-003,5.489528e-003,3.216857e-001,-2.514523e-002,-1.508984e-002,7.458867e-006,7.458867e-006,,,,,,,,,,,,,,,,,,,,
1406870525.140,,-1.500000e+001,2.980050e+002,2.979885e+002,1,0,1.900409e+000,3.408917e-001,3.408917e-001,-1.990974e-001,-1.962281e-001,3.987780e-001,-1.412111e-001,-1.383418e-001,7.428935e-006,7.428935e-006,,,,,,,,,,,,,,,,,,,,
1406870525.140,,-1.500000e+001,2.980050e+002,2.979885e+002,1,0,3.810503e+000,6.678976e-001,6.678976e-001,4.526217e-003,1.307778e-001,7.155073e-001,5.213596e-002,1.783875e-001,1.455526e-005,1.455526e-005,,,,,,,,,,,,,,,,,,,,
1406870543.375,,-1.500000e+001,2.979968e+002,2.980050e+002,1,0,5.568333e-001,7.234412e-001,7.234412e-001,1.020503e-001,1.720898e-001,6.724647e-001,5.107376e-002,1.211132e-001,1.576570e-005,1.576570e-005,,,,,,,,,,,,,,,,,,,,
1406870561.109,,-1.500000e+001,2.979968e+002,2.980050e+002,1,0,1.719382e+000,3.608814e-001,3.608814e-001,-1.670176e-001,-1.612607e-001,3.856452e-001,-1.422537e-001,-1.364968e-001,7.864562e-006,7.864562e-006,,,,,,,,,,,,,,,,,,,,
1406870561.109,,-1.500000e+001,2.979968e+002,2.980050e+002,1,0,3.894104e+000,6.221198e-001,6.221198e-001,-2.955247e-002,9.997779e-002,7.042544e-001,5.258207e-002,1.821123e-001,1.355764e-005,1.355764e-005,,,,,,,,,,,,,,,,,,,,
1406870678.593,,-2.000000e+001,2.980050e+002,2.979968e+002,1,0,6.837679e-001,1.118961e+000,1.118961e+000,1.868169e-001,2.627842e-001,1.050771e+000,1.186268e-001,1.945941e-001,2.438512e-005,2.438512e-005,,,,,,,,,,,,,,,,,,,,
1406870696.328,,-2.000000e+001,2.979968e+002,2.979968e+002,1,0,1.539259e+000,6.553850e-001,6.553850e-001,-2.085416e-001,-1.988486e-001,6.409950e-001,-2.229316e-001,-2.132386e-001,1.428257e-005,1.428257e-005,,,,,,,,,,,,,,,,,,,,
1406870696.328,,-2.000000e+001,2.979968e+002,2.979968e+002,1,0,3.953988e+000,1.042512e+000,1.042512e+000,3.965276e-002,1.882787e-001,1.134397e+000,1.315374e-001,2.801633e-001,2.271910e-005,2.271910e-005,,,,,,,,,,,,,,,,,,,,
1406870714.812,,-2.000000e+001,2.980050e+002,2.980050e+002,1,0,8.163292e-001,1.105075e+000,1.105075e+000,1.720470e-001,2.493284e-001,1.021912e+000,8.888325e-002,1.661646e-001,2.408251e-005,2.408251e-005,,,,,,,,,,,,,,,,,,,,
1406870833.062,,-2.500000e+001,2.979968e+002,2.979968e+002,1,0,1.361367e+000,1.075014e+000,1.075014e+000,-1.407976e-001,-1.275882e-001,1.016699e+000,-1.991134e-001,-1.859040e-001,2.342739e-005,2.342739e-005,,,,,,,,,,,,,,,,,,,,
1406870833.062,,-2.500000e+001,2.979968e+002,2.979968e+002,1,0,3.987928e+000,1.493423e+000,1.493423e+000,1.356101e-001,2.908206e-001,1.581224e+000,2.234113e-001,3.786218e-001,3.254562e-005,3.254562e-005,,,,,,,,,,,,,,,,,,,,
1406870850.796,,-2.500000e+001,2.979885e+002,2.980050e+002,1,0,9.545332e-001,1.506394e+000,1.506394e+000,1.877434e-001,2.752367e-001,1.412417e+000,9.376631e-002,1.812596e-001,3.282828e-005,3.282828e-005,,,,,,,,,,,,,,,,,,,,
1406870868.546,,-2.500000e+001,2.979968e+002,2.979968e+002,1,0,1.187739e+000,1.196631e+000,1.196631e+000,2.018126e-002,3.634501e-002,1.109190e+000,-6.725983e-002,-5.109608e-002,2.607773e-005,2.607773e-005,,,,,,,,,,,,,,,,,,,,
1406870868.546,,-2.500000e+001,2.979968e+002,2.979968e+002,1,0,3.994924e+000,1.459243e+000,1.459243e+000,1.437850e-001,2.989569e-001,1.548675e+000,2.332177e-001,3.883896e-001,3.180073e-005,3.180073e-005,,,,,,,,,,,,,,,,,,,,
1406870986.078,,-3.000000e+001,2.980050e+002,2.980050e+002,1,0,1.098834e+000,1.716819e+000,1.716819e+000,8.752561e-002,1.916826e-001,1.635230e+000,5.937097e-003,1.100941e-001,3.741398e-005,3.741398e-005,,,,,,,,,,,,,,,,,,,,
1406871004.078,,-3.000000e+001,2.980050e+002,2.979968e+002,1,0,1.018485e+000,1.771142e+000,1.771142e+000,1.639472e-001,1.867502e-001,1.685181e+000,7.798618e-002,1.007892e-001,3.859782e-005,3.859782e-005,,,,,,,,,,,,,,,,,,,,
1406871004.078,,-3.000000e+001,2.980050e+002,2.979968e+002,1,0,3.975092e+000,2.004914e+000,2.004914e+000,2.342975e-001,4.205221e-001,2.080022e+000,3.094056e-001,4.956301e-001,4.369232e-005,4.369232e-005,,,,,,,,,,,,,,,,,,,,
1406871022.875,,-3.000000e+001,2.980050e+002,2.979968e+002,1,0,1.249952e+000,1.542863e+000,1.542863e+000,-8.179706e-002,2.218044e-002,1.483502e+000,-1.411584e-001,-3.718090e-002,3.362303e-005,3.362303e-005,,,,,,,,,,,,,,,,,,,,
1406871139.406,,-3.500000e+001,2.980050e+002,2.979968e+002,1,0,8.553905e-001,2.185888e+000,2.185888e+000,3.161440e-001,3.476777e-001,2.109108e+000,2.393639e-001,2.708976e-001,4.763621e-005,4.763621e-005,,,,,,,,,,,,,,,,,,,,
1406871139.406,,-3.500000e+001,2.980050e+002,2.979968e+002,1,0,3.930259e+000,2.379833e+000,2.379833e+000,3.163818e-001,5.416229e-001,2.437543e+000,3.740915e-001,5.993326e-001,5.186278e-005,5.186278e-005,,,,,,,,,,,,,,,,,,,,
1406871157.671,,-3.500000e+001,2.979968e+002,2.979968e+002,1,0,1.408253e+000,1.629383e+000,1.629383e+000,-3.398149e-001,-2.093543e-001,1.612487e+000,-3.567115e-001,-2.262509e-001,3.550851e-005,3.550851e-005,,,,,,,,,,,,,,,,,,,,
1406871175.406,,-3.500000e+001,2.980050e+002,2.979968e+002,1,0,6.996562e-001,2.221442e+000,2.221442e+000,4.030007e-001,4.378411e-001,2.167308e+000,3.488663e-001,3.837067e-001,4.841103e-005,4.841103e-005,,,,,,,,,,,,,,,,,,,,
1406871175.406,,-3.500000e+001,2.980050e+002,2.979968e+002,1,0,3.863233e+000,2.355266e+000,2.355266e+000,3.495576e-001,5.716647e-001,2.401776e+000,3.960676e-001,6.181747e-001,5.132740e-005,5.132740e-005,,,,,,,,,,,,,,,,,,,,
1406871291.156,,-4.000000e+001,2.979968e+002,2.979885e+002,1,0,1.573603e+000,1.655171e+000,1.655171e+000,-6.734372e-001,-5.109215e-001,1.689413e+000,-6.391954e-001,-4.766797e-001,3.607049e-005,3.607049e-005,,,,,,,,,,,,,,,,,,,,
1406871309.890,,-4.000000e+001,2.980050e+002,2.980050e+002,1,0,5.530380e-001,2.675252e+000,2.675252e+000,4.851339e-001,5.332427e-001,2.649980e+000,4.598613e-001,5.079701e-001,5.830071e-005,5.830071e-005,,,,,,,,,,,,,,,,,,,,
1406871309.890,,-4.000000e+001,2.980050e+002,2.980050e+002,1,0,3.777621e+000,2.862636e+000,2.862636e+000,4.426647e-001,7.206264e-001,2.888105e+000,4.681333e-001,7.460949e-001,6.238429e-005,6.238429e-005,,,,,,,,,,,,,,,,,,,,
1406871327.625,,-4.000000e+001,2.980050e+002,2.979968e+002,1,0,1.745211e+000,1.322672e+000,1.322672e+000,-9.225219e-001,-7.648405e-001,1.377624e+000,-8.675703e-001,-7.098889e-001,2.882447e-005,2.882447e-005,,,,,,,,,,,,,,,,,,,,
1406871438.375,,-4.500000e+001,2.979968e+002,2.979968e+002,1,0,4.172136e-001,3.191168e+000,3.191168e+000,5.295134e-001,5.960584e-001,3.185982e+000,5.243273e-001,5.908723e-001,6.954381e-005,6.954381e-005,,,,,,,,,,,,,,,,,,,,
1406871438.375,,-4.500000e+001,2.979968e+002,2.979968e+002,1,0,3.677026e+000,3.464461e+000,3.464461e+000,5.166632e-001,8.693516e-001,3.472137e+000,5.243388e-001,8.770273e-001,7.549959e-005,7.549959e-005,,,,,,,,,,,,,,,,,,,,
1406871456.359,,-4.500000e+001,2.979968e+002,2.979968e+002,1,0,1.921800e+000,1.635487e+000,1.635487e+000,-1.183083e+000,-9.735872e-001,1.670095e+000,-1.148476e+000,-9.389795e-001,3.564150e-005,3.564150e-005,,,,,,,,,,,,,,,,,,,,
1406871474.343,,-4.500000e+001,2.980050e+002,2.979968e+002,1,0,2.956692e-001,3.053682e+000,3.053682e+000,4.962747e-001,5.649002e-001,3.061613e+000,5.042056e-001,5.728312e-001,6.654764e-005,6.654764e-005,,,,,,,,,,,,,,,,,,,,
1406871474.343,,-4.500000e+001,2.980050e+002,2.979968e+002,1,0,3.565220e+000,3.337199e+000,3.337199e+000,5.115283e-001,8.484170e-001,3.329302e+000,5.036314e-001,8.405201e-001,7.272621e-005,7.272621e-005,,,,,,,,,,,,,,,,,,,,
1406871625.218,,-5.000000e+001,2.979885e+002,2.979968e+002,1,0,2.101592e+000,9.591967e-001,9.591967e-001,-6.587282e-001,-5.295524e-001,9.573879e-001,-6.605370e-001,-5.313612e-001,4.180674e-005,4.180674e-005,,,,,,,,,,,,,,,,,,,,
1406871643.000,,-5.000000e+001,2.979968e+002,2.980050e+002,1,0,1.913164e-001,1.753594e+000,1.753594e+000,2.440318e-001,2.899259e-001,1.765618e+000,2.560560e-001,3.019502e-001,7.643066e-005,7.643066e-005,,,,,,,,,,,,,,,,,,,,
1406871643.000,,-5.000000e+001,2.979968e+002,2.980050e+002,1,0,3.444901e+000,1.926786e+000,1.926786e+000,2.527701e-001,4.631184e-001,1.916288e+000,2.422717e-001,4.526200e-001,8.397928e-005,8.397928e-005,,,,,,,,,,,,,,,,,,,,
1406871660.984,,-5.000000e+001,2.979968e+002,2.980050e+002,1,0,2.282412e+000,9.700308e-001,9.700308e-001,-5.892599e-001,-4.649580e-001,9.554654e-001,-6.038253e-001,-4.795234e-001,4.227895e-005,4.227895e-005,,,,,,,,,,,,,,,,,,,,
1406871810.968,,-7.500000e+001,2.979968e+002,2.980050e+002,1,0,1.077361e-001,9.968871e-001,9.968871e-001,6.219709e-002,1.074331e-001,9.983088e-001,6.361885e-002,1.088549e-001,2.172469e-004,2.172469e-004,,,,,,,,,,,,,,,,,,,,
1406871810.968,,-7.500000e+001,2.979968e+002,2.980050e+002,1,0,3.318061e+000,1.135136e+000,1.135136e+000,5.081909e-002,2.456821e-001,1.134939e+000,5.062216e-002,2.454851e-001,2.473748e-004,2.473748e-004,,,,,,,,,,,,,,,,,,,,
1406871828.953,,-7.500000e+001,2.980050e+002,2.979968e+002,1,0,2.462550e+000,8.331553e-001,8.331553e-001,-1.228229e-001,-9.220898e-003,8.293547e-001,-1.266235e-001,-1.302153e-002,1.815656e-004,1.815656e-004,,,,,,,,,,,,,,,,,,,,
1406871846.687,,-7.500000e+001,2.980050e+002,2.979968e+002,1,0,4.778993e-002,8.995331e-001,8.995331e-001,5.746942e-002,1.000560e-001,9.013851e-001,5.932146e-002,1.019080e-001,1.960310e-004,1.960310e-004,,,,,,,,,,,,,,,,,,,,
1406871846.687,,-7.500000e+001,2.980050e+002,2.979968e+002,1,0,3.185451e+000,1.002380e+000,1.002380e+000,2.951522e-002,2.029034e-001,1.002325e+000,2.946015e-002,2.028483e-001,2.184441e-004,2.184441e-004,,,,,,,,,,,,,,,,,,,,
1406871975.937,,-1.000000e+002,2.980050e+002,2.979968e+002,1,0,2.640289e+000,2.843562e+000,2.843562e+000,-9.883888e-002,3.136611e-001,2.844415e+000,-9.798558e-002,3.145144e-001,6.196827e-004,6.196827e-004,,,,,,,,,,,,,,,,,,,,
1406871993.703,,-1.000000e+002,2.979968e+002,2.979968e+002,1,0,1.383373e-002,2.582324e+000,2.582324e+000,6.813151e-002,2.254257e-001,2.580251e+000,6.605823e-002,2.233524e-001,5.627524e-004,5.627524e-004,,,,,,,,,,,,,,,,,,,,
1406871993.703,,-1.000000e+002,2.979968e+002,2.979968e+002,1,0,3.047304e+000,2.967010e+000,2.967010e+000,1.907203e-003,6.101115e-001,2.970678e+000,5.575750e-003,6.137800e-001,6.465850e-004,6.465850e-004,,,,,,,,,,,,,,,,,,,,
1406872011.968,,-1.000000e+002,2.980050e+002,2.979968e+002,1,0,2.814132e+000,2.442244e+000,2.442244e+000,-5.414719e-002,3.015893e-001,2.444427e+000,-5.196375e-002,3.037727e-001,5.322255e-004,5.322255e-004,,,,,,,,,,,,,,,,,,,,
1406872158.703,,-7.500000e+001,2.979968e+002,2.979968e+002,1,0,6.889226e-003,7.699820e-001,7.699820e-001,1.147108e-001,1.333846e-001,7.718457e-001,1.165746e-001,1.352483e-001,8.389928e-005,8.389928e-005,,,,,,,,,,,,,,,,,,,,
1406872158.703,,-7.500000e+001,2.979968e+002,2.979968e+002,1,0,2.902973e+000,6.442457e-001,6.442457e-001,-6.121110e-002,7.648349e-003,6.492454e-001,-5.621140e-002,1.264805e-002,7.019872e-005,7.019872e-005,,,,,,,,,,,,,,,,,,,,
1406872176.437,,-7.500000e+001,2.980050e+002,2.980050e+002,1,0,2.983190e+000,6.488235e-001,6.488235e-001,-2.416741e-002,1.891130e-002,6.520782e-001,-2.091270e-002,2.216601e-002,7.069753e-005,7.069753e-005,,,,,,,,,,,,,,,,,,,,
1406872194.171,,-7.500000e+001,2.980050e+002,2.980050e+002,1,0,2.664570e-002,7.556383e-001,7.556383e-001,1.177908e-001,1.363090e-001,7.573971e-001,1.195496e-001,1.380678e-001,8.233635e-005,8.233635e-005,,,,,,,,,,,,,,,,,,,,
1406872194.171,,-7.500000e+001,2.980050e+002,2.980050e+002,1,0,2.751861e+000,5.520799e-001,5.520799e-001,-1.326078e-001,-6.724942e-002,5.583141e-001,-1.263736e-001,-6.101519e-002,6.015608e-005,6.015608e-005,,,,,,,,,,,,,,,,,,,,
1406872324.968,,-5.000000e+001,2.979968e+002,2.979968e+002,1,0,3.146201e+000,4.193243e-001,4.193243e-001,3.591313e-002,4.339388e-002,4.167991e-001,3.338792e-002,4.086867e-002,4.569079e-005,4.569079e-005,,,,,,,,,,,,,,,,,,,,
1406872342.718,,-5.000000e+001,2.979968e+002,2.979968e+002,1,0,7.142713e-002,4.832606e-001,4.832606e-001,9.932347e-002,1.032721e-001,4.881018e-001,1.041647e-001,1.081133e-001,5.265748e-005,5.265748e-005,,,,,,,,,,,,,,,,,,,,
1406872342.718,,-5.000000e+001,2.979968e+002,2.979968e+002,1,0,2.593559e+000,2.143925e-001,2.143925e-001,-1.789774e-001,-1.655960e-001,2.164794e-001,-1.768905e-001,-1.635091e-001,2.336083e-005,2.336083e-005,,,,,,,,,,,,,,,,,,,,
1406872361.468,,-5.000000e+001,2.979968e+002,2.980050e+002,1,0,3.301882e+000,4.651021e-001,4.651021e-001,8.227415e-002,9.106889e-002,4.623848e-001,7.955684e-002,8.835158e-002,5.067887e-005,5.067887e-005,,,,,,,,,,,,,,,,,,,,
1406872497.687,,-4.500000e+001,2.979968e+002,2.980132e+002,1,0,1.385259e-001,1.134678e+000,1.134678e+000,2.575379e-001,2.646006e-001,1.143786e+000,2.666461e-001,2.737088e-001,4.945515e-005,4.945515e-005,,,,,,,,,,,,,,,,,,,,
1406872497.687,,-4.500000e+001,2.979968e+002,2.980132e+002,1,0,2.428274e+000,3.175451e-001,3.175451e-001,-5.755792e-001,-5.525324e-001,3.175784e-001,-5.755458e-001,-5.524991e-001,1.384026e-005,1.384026e-005,,,,,,,,,,,,,,,,,,,,
1406872515.671,,-4.500000e+001,2.979968e+002,2.980050e+002,1,0,3.448851e+000,1.147649e+000,1.147649e+000,2.692973e-001,2.837529e-001,1.144028e+000,2.656765e-001,2.801321e-001,5.002047e-005,5.002047e-005,,,,,,,,,,,,,,,,,,,,
1406872532.953,,-4.500000e+001,2.979968e+002,2.979968e+002,1,0,2.242075e-001,1.164434e+000,1.164434e+000,2.890952e-001,2.956749e-001,1.165509e+000,2.901707e-001,2.967504e-001,5.075206e-005,5.075206e-005,,,,,,,,,,,,,,,,,,,,
1406872532.953,,-4.500000e+001,2.979968e+002,2.979968e+002,1,0,2.256643e+000,2.000488e-001,2.000488e-001,-6.894359e-001,-6.687100e-001,1.965527e-001,-6.929321e-001,-6.722062e-001,8.719165e-006,8.719165e-006,,,,,,,,,,,,,,,,,,,,
1406872650.703,,-4.000000e+001,2.980050e+002,2.979968e+002,1,0,3.584535e+000,1.081118e+000,1.081118e+000,2.910994e-001,2.995840e-001,1.083179e+000,2.931606e-001,3.016452e-001,4.712075e-005,4.712075e-005,,,,,,,,,,,,,,,,,,,,
1406872668.187,,-4.000000e+001,2.979968e+002,2.979968e+002,1,0,3.247625e-001,1.094394e+000,1.094394e+000,2.962247e-001,3.022557e-001,1.093231e+000,2.950624e-001,3.010935e-001,4.769937e-005,4.769937e-005,,,,,,,,,,,,,,,,,,,,
1406872686.171,,-4.000000e+001,2.979968e+002,2.980050e+002,1,0,2.080056e+000,7.736442e-002,7.736442e-002,-7.090560e-001,-7.090560e-001,8.587929e-002,-7.005412e-001,-7.005412e-001,3.371944e-006,3.371944e-006,,,,,,,,,,,,,,,,,,,,
1406872686.171,,-4.000000e+001,2.979968e+002,2.980050e+002,1,0,3.706159e+000,1.097598e+000,1.097598e+000,3.007713e-001,3.111777e-001,1.103304e+000,3.064769e-001,3.168833e-001,4.783904e-005,4.783904e-005,,,,,,,,,,,,,,,,,,,,
1406872803.171,,-3.500000e+001,2.979968e+002,2.979968e+002,1,0,4.365562e-001,1.028779e+000,1.028779e+000,2.967572e-001,2.990893e-001,1.020970e+000,2.889486e-001,2.912807e-001,4.483956e-005,4.483956e-005,,,,,,,,,,,,,,,,,,,,
1406872820.968,,-3.500000e+001,2.979968e+002,2.980050e+002,1,0,1.900250e+000,1.083407e-001,1.083407e-001,-6.296608e-001,-6.294632e-001,1.269195e-001,-6.110820e-001,-6.108844e-001,4.722054e-006,4.722054e-006,,,,,,,,,,,,,,,,,,,,
1406872820.968,,-3.500000e+001,2.979968e+002,2.980050e+002,1,0,3.810452e+000,1.020081e+000,1.020081e+000,2.735806e-001,2.822773e-001,1.031171e+000,2.846706e-001,2.933673e-001,4.446046e-005,4.446046e-005,,,,,,,,,,,,,,,,,,,,
1406872838.968,,-3.500000e+001,2.979968e+002,2.980050e+002,1,0,5.568307e-001,1.031983e+000,1.031983e+000,3.006218e-001,3.049464e-001,1.014728e+000,2.833663e-001,2.876909e-001,4.497922e-005,4.497922e-005,,,,,,,,,,,,,,,,,,,,
1406872961.703,,-3.000000e+001,2.980050e+002,2.979968e+002,1,0,1.719397e+000,2.079836e-001,2.079836e-001,-4.735380e-001,-4.733872e-001,2.243395e-001,-4.571820e-001,-4.570313e-001,9.065017e-006,9.065017e-006,,,,,,,,,,,,,,,,,,,,
1406872961.703,,-3.000000e+001,2.980050e+002,2.979968e+002,1,0,3.894069e+000,9.241005e-001,9.241005e-001,2.393383e-001,2.427296e-001,9.417333e-001,2.569711e-001,2.603624e-001,4.027714e-005,4.027714e-005,,,,,,,,,,,,,,,,,,,,
1406872979.203,,-3.000000e+001,2.979968e+002,2.979885e+002,1,0,6.837503e-001,9.651479e-001,9.651479e-001,2.644061e-001,2.683253e-001,9.415317e-001,2.407898e-001,2.447091e-001,4.206620e-005,4.206620e-005,,,,,,,,,,,,,,,,,,,,
1406872997.187,,-3.000000e+001,2.980050e+002,2.979968e+002,1,0,1.539125e+000,3.447066e-001,3.447066e-001,-3.184470e-001,-3.180726e-001,3.487915e-001,-3.143620e-001,-3.139877e-001,1.502412e-005,1.502412e-005,,,,,,,,,,,,,,,,,,,,
1406872997.187,,-3.000000e+001,2.980050e+002,2.979968e+002,1,0,3.953970e+000,8.919035e-001,8.919035e-001,2.233842e-001,2.291242e-001,9.139599e-001,2.454406e-001,2.511807e-001,3.887383e-005,3.887383e-005,,,,,,,,,,,,,,,,,,,,
1406873115.437,,-2.500000e+001,2.979968e+002,2.980050e+002,1,0,8.162657e-001,8.279672e-001,8.279672e-001,2.141149e-001,2.153887e-001,7.951720e-001,1.813197e-001,1.825935e-001,3.608717e-005,3.608717e-005,,,,,,,,,,,,,,,,,,,,
1406873133.421,,-2.500000e+001,2.979968e+002,2.979968e+002,1,0,1.361544e+000,4.892117e-001,4.892117e-001,-1.373015e-001,-1.367104e-001,4.716737e-001,-1.548396e-001,-1.542484e-001,2.132242e-005,2.132242e-005,,,,,,,,,,,,,,,,,,,,
1406873133.421,,-2.500000e+001,2.979968e+002,2.979968e+002,1,0,3.987950e+000,8.313242e-001,8.313242e-001,1.984561e-001,2.054021e-001,8.568555e-001,2.239873e-001,2.309334e-001,3.623348e-005,3.623348e-005,,,,,,,,,,,,,,,,,,,,
1406873151.921,,-2.500000e+001,2.980050e+002,2.979968e+002,1,0,9.544560e-001,7.780694e-001,7.780694e-001,1.518828e-001,1.550715e-001,7.396062e-001,1.134197e-001,1.166083e-001,3.391236e-005,3.391236e-005,,,,,,,,,,,,,,,,,,,,
1406873269.406,,-2.000000e+001,2.979968e+002,2.980050e+002,1,0,1.187654e+000,5.673391e-001,5.673391e-001,1.011439e-002,1.045346e-002,5.337383e-001,-2.348642e-002,-2.314734e-002,2.472763e-005,2.472763e-005,,,,,,,,,,,,,,,,,,,,
1406873269.406,,-2.000000e+001,2.979968e+002,2.980050e+002,1,0,3.994890e+000,7.403790e-001,7.403790e-001,1.802383e-001,1.834934e-001,7.679296e-001,2.077889e-001,2.110440e-001,3.226963e-005,3.226963e-005,,,,,,,,,,,,,,,,,,,,
1406873287.390,,-2.000000e+001,2.980050e+002,2.980050e+002,1,0,1.098788e+000,6.430250e-001,6.430250e-001,6.950008e-002,7.245958e-002,6.038585e-001,3.033357e-002,3.329307e-002,2.802643e-005,2.802643e-005,,,,,,,,,,,,,,,,,,,,
1406873305.125,,-2.000000e+001,2.980050e+002,2.980050e+002,1,0,1.018676e+000,6.755272e-001,6.755272e-001,1.124170e-001,1.130341e-001,6.388850e-001,7.577480e-002,7.639194e-002,2.944304e-005,2.944304e-005,,,,,,,,,,,,,,,,,,,,
1406873305.125,,-2.000000e+001,2.980050e+002,2.980050e+002,1,0,3.975148e+000,7.518235e-001,7.518235e-001,1.842904e-001,1.893304e-001,7.787753e-001,2.112423e-001,2.162822e-001,3.276844e-005,3.276844e-005,,,,,,,,,,,,,,,,,,,,
1406873420.859,,-1.500000e+001,2.979968e+002,2.980050e+002,1,0,1.249922e+000,5.076754e-001,5.076754e-001,-1.926244e-002,-1.720840e-002,4.758039e-001,-5.113397e-002,-4.907992e-002,2.212719e-005,2.212719e-005,,,,,,,,,,,,,,,,,,,,
1406873439.093,,-1.500000e+001,2.980050e+002,2.979968e+002,1,0,8.557689e-001,7.177953e-001,7.177954e-001,1.817790e-001,1.827126e-001,6.825244e-001,1.465081e-001,1.474416e-001,3.128533e-005,3.128533e-005,,,,,,,,,,,,,,,,,,,,
1406873439.093,,-1.500000e+001,2.980050e+002,2.979968e+002,1,0,3.930353e+000,7.165746e-001,7.165746e-001,1.748234e-001,1.814918e-001,7.439329e-001,2.021817e-001,2.088501e-001,3.123212e-005,3.123212e-005,,,,,,,,,,,,,,,,,,,,
1406873456.328,,-1.500000e+001,2.979968e+002,2.979968e+002,1,0,1.408204e+000,3.843806e-001,3.843806e-001,-1.342611e-001,-1.313902e-001,3.712569e-001,-1.473849e-001,-1.445140e-001,1.675335e-005,1.675335e-005,,,,,,,,,,,,,,,,,,,,
1406873581.078,,-1.000000e+001,2.979968e+002,2.979968e+002,1,0,6.996865e-001,6.666768e-001,6.666768e-001,2.074277e-001,2.082378e-001,6.368329e-001,1.775838e-001,1.783938e-001,2.905733e-005,2.905733e-005,,,,,,,,,,,,,,,,,,,,
1406873581.078,,-1.000000e+001,2.979968e+002,2.979968e+002,1,0,3.863259e+000,6.308177e-001,6.308176e-001,1.672146e-001,1.723785e-001,6.545241e-001,1.909212e-001,1.960851e-001,2.749439e-005,2.749439e-005,,,,,,,,,,,,,,,,,,,,
1406873599.562,,-1.000000e+001,2.979968e+002,2.979885e+002,1,0,1.573526e+000,2.520829e-001,2.520829e-001,-2.328974e-001,-2.286848e-001,2.635809e-001,-2.213993e-001,-2.171867e-001,1.098711e-005,1.098711e-005,,,,,,,,,,,,,,,,,,,,
1406873616.562,,-1.000000e+001,2.979968e+002,2.980050e+002,1,0,5.530954e-001,6.813257e-001,6.813257e-001,2.115447e-001,2.126154e-001,6.633399e-001,1.935589e-001,1.946296e-001,2.969580e-005,2.969580e-005,,,,,,,,,,,,,,,,,,,,
1406873616.562,,-1.000000e+001,2.979968e+002,2.980050e+002,1,0,3.777648e+000,6.535539e-001,6.535539e-001,1.786575e-001,1.848436e-001,6.691503e-001,1.942539e-001,2.004400e-001,2.848536e-005,2.848536e-005,,,,,,,,,,,,,,,,,,,,
1406873726.796,,-5.000000e+000,2.979885e+002,2.979968e+002,1,0,1.745187e+000,9.063997e-002,9.063997e-002,-3.066467e-001,-3.035902e-001,1.201307e-001,-2.771559e-001,-2.740995e-001,3.950574e-006,3.950574e-006,,,,,,,,,,,,,,,,,,,,
1406873744.562,,-5.000000e+000,2.980050e+002,2.979968e+002,1,0,4.173189e-001,5.986206e-001,5.986205e-001,1.777505e-001,1.793401e-001,5.900873e-001,1.692173e-001,1.708069e-001,2.609108e-005,2.609108e-005,,,,,,,,,,,,,,,,,,,,
1406873744.562,,-5.000000e+000,2.980050e+002,2.979968e+002,1,0,3.677117e+000,5.932798e-001,5.932798e-001,1.655745e-001,1.739994e-001,5.962616e-001,1.685562e-001,1.769812e-001,2.585831e-005,2.585831e-005,,,,,,,,,,,,,,,,,,,,
1406873763.296,,-5.000000e+000,2.979968e+002,2.980050e+002,1,0,1.921803e+000,3.311258e-002,3.311258e-002,-3.842216e-001,-3.800079e-001,6.515089e-002,-3.521833e-001,-3.479696e-001,1.443223e-006,1.443223e-006,,,,,,,,,,,,,,,,,,,,
1406873879.531,,0.000000e+000,2.980050e+002,2.980050e+002,1,0,2.956133e-001,4.696799e-001,4.696799e-001,1.274069e-001,1.285879e-001,4.758922e-001,1.336192e-001,1.348002e-001,2.047117e-005,2.047117e-005,,,,,,,,,,,,,,,,,,,,
1406873879.531,,0.000000e+000,2.980050e+002,2.980050e+002,1,0,3.565228e+000,4.879910e-001,4.879910e-001,1.411016e-001,1.468990e-001,4.759426e-001,1.290532e-001,1.348506e-001,2.126926e-005,2.126926e-005,,,,,,,,,,,,,,,,,,,,
1406873897.531,,0.000000e+000,2.980050e+002,2.980050e+002,1,0,2.101540e+000,-2.288888e-003,-2.288888e-003,-3.687581e-001,-3.627302e-001,2.332716e-002,-3.431420e-001,-3.371142e-001,-9.976202e-008,-9.976202e-008,,,,,,,,,,,,,,,,,,,,
1406873915.515,,0.000000e+000,2.980050e+002,2.979968e+002,1,0,1.913456e-001,4.515213e-001,4.515213e-001,9.439160e-002,9.630755e-002,4.759769e-001,1.188471e-001,1.207631e-001,1.967972e-005,1.967972e-005,,,,,,,,,,,,,,,,,,,,
1406873915.515,,0.000000e+000,2.980050e+002,2.979968e+002,1,0,3.444944e+000,4.857021e-001,4.857021e-001,1.217068e-001,1.304883e-001,4.640920e-001,1.000968e-001,1.088782e-001,2.116950e-005,2.116950e-005,,,,,,,,,,,,,,,,,,,,
1406874051.000,,5.000000e+000,2.979968e+002,2.979968e+002,1,0,2.282451e+000,-5.798517e-003,-5.798517e-003,-6.059524e-001,-5.921150e-001,1.814225e-002,-5.820116e-001,-5.681743e-001,-1.263652e-007,-1.263652e-007,,,,,,,,,,,,,,,,,,,,
1406874068.562,,5.000000e+000,2.980132e+002,2.979968e+002,1,0,1.077225e-001,7.060457e-001,7.060457e-001,8.549397e-002,9.090590e-002,7.936107e-001,1.730590e-001,1.784709e-001,1.538662e-005,1.538662e-005,,,,,,,,,,,,,,,,,,,,
1406874068.562,,5.000000e+000,2.980132e+002,2.979968e+002,1,0,3.318056e+000,7.881405e-001,7.881405e-001,1.496878e-001,1.730008e-001,7.241687e-001,8.571590e-002,1.090289e-001,1.717569e-005,1.717569e-005,,,,,,,,,,,,,,,,,,,,
1406874085.812,,5.000000e+000,2.979968e+002,2.979968e+002,1,0,2.462667e+000,1.356548e-001,1.356548e-001,-4.983202e-001,-4.849068e-001,1.202876e-001,-5.136874e-001,-5.002739e-001,2.956280e-006,2.956280e-006,,,,,,,,,,,,,,,,,,,,
1406874209.046,,1.000000e+001,2.979968e+002,2.979968e+002,1,0,4.778885e-002,4.853969e-001,4.853969e-001,5.355731e-004,4.388332e-003,6.068516e-001,1.219903e-001,1.258430e-001,1.057809e-005,1.057809e-005,,,,,,,,,,,,,,,,,,,,
1406874209.046,,1.000000e+001,2.979968e+002,2.979968e+002,1,0,3.185485e+000,5.494857e-001,5.494857e-001,5.279095e-002,6.847718e-002,4.746311e-001,-2.206366e-002,-6.377429e-003,1.197476e-005,1.197476e-005,,,,,,,,,,,,,,,,,,,,
1406874227.031,,1.000000e+001,2.980050e+002,2.980050e+002,1,0,2.640171e+000,1.994385e-001,1.994385e-001,-3.086769e-001,-2.928936e-001,1.554266e-001,-3.526887e-001,-3.369055e-001,4.346295e-006,4.346295e-006,,,,,,,,,,,,,,,,,,,,
1406874245.265,,1.000000e+001,2.979968e+002,2.979968e+002,1,0,1.388339e-002,4.692221e-001,4.692221e-001,-1.842571e-002,-1.169193e-002,6.023363e-001,1.146886e-001,1.214224e-001,1.022560e-005,1.022560e-005,,,,,,,,,,,,,,,,,,,,
1406874245.265,,1.000000e+001,2.979968e+002,2.979968e+002,1,0,3.047304e+000,4.802088e-001,4.802088e-001,-2.674254e-002,-7.052422e-004,4.038887e-001,-1.030626e-001,-7.702526e-002,1.046503e-005,1.046503e-005,,,,,,,,,,,,,,,,,,,,
1406874356.265,,1.500000e+001,2.979885e+002,2.979968e+002,1,0,2.814319e+000,1.959288e-001,1.959288e-001,-1.533767e-001,-1.395475e-001,1.226132e-001,-2.266923e-001,-2.128631e-001,4.269809e-006,4.269809e-006,,,,,,,,,,,,,,,,,,,,
1406874373.500,,1.500000e+001,2.979968e+002,2.979968e+002,1,0,6.945526e-003,3.035066e-001,3.035066e-001,-7.276230e-002,-6.322247e-002,4.545626e-001,7.829369e-002,8.783352e-002,6.614213e-006,6.614213e-006,,,,,,,,,,,,,,,,,,,,
1406874373.500,,1.500000e+001,2.979968e+002,2.979968e+002,1,0,2.902948e+000,2.893155e-001,2.893155e-001,-1.125917e-001,-7.741359e-002,2.172973e-001,-1.846099e-001,-1.494317e-001,6.304951e-006,6.304951e-006,,,,,,,,,,,,,,,,,,,,
1406874392.281,,1.500000e+001,2.980050e+002,2.979968e+002,1,0,2.983201e+000,3.361614e-001,3.361614e-001,-5.871309e-002,-3.729421e-002,2.497901e-001,-1.450844e-001,-1.236655e-001,7.325848e-006,7.325848e-006,,,,,,,,,,,,,,,,,,,,
1406874510.515,,2.000000e+001,2.979968e+002,2.979968e+002,1,0,2.669866e-002,7.126072e-002,7.126072e-002,-1.224039e-001,-1.084996e-001,2.332799e-001,3.961529e-002,5.351958e-002,1.552959e-006,1.552959e-006,,,,,,,,,,,,,,,,,,,,
1406874510.515,,2.000000e+001,2.979968e+002,2.979968e+002,1,0,2.751825e+000,5.203406e-002,5.203406e-002,-1.768002e-001,-1.277263e-001,-5.456456e-003,-2.342907e-001,-1.852168e-001,1.133960e-006,1.133960e-006,,,,,,,,,,,,,,,,,,,,
1406874528.750,,2.000000e+001,2.979885e+002,2.979968e+002,1,0,3.146235e+000,2.610858e-001,2.610858e-001,-2.705000e-004,3.879917e-002,1.435584e-001,-1.177980e-001,-7.872832e-002,5.689750e-006,5.689750e-006,,,,,,,,,,,,,,,,,,,,
1406874546.984,,2.000000e+001,2.979968e+002,2.979968e+002,1,0,7.151877e-002,1.042207e-001,1.042207e-001,-1.046521e-001,-8.680660e-002,2.501478e-001,4.127495e-002,5.912045e-002,2.271245e-006,2.271245e-006,,,,,,,,,,,,,,,,,,,,
1406874546.984,,2.000000e+001,2.979968e+002,2.979968e+002,1,0,2.593584e+000,2.136296e-003,2.136296e-003,-2.493674e-001,-1.888910e-001,-1.786984e-003,-2.532907e-001,-1.928143e-001,4.655552e-008,4.655552e-008,,,,,,,,,,,,,,,,,,,,
1406874665.234,,2.500000e+001,2.979968e+002,2.980050e+002,1,0,3.302001e+000,5.264443e-002,5.264443e-002,3.673823e-002,-3.364351e-002,1.792650e-002,2.020299e-003,-6.836145e-002,1.147261e-006,1.147261e-006,,,,,,,,,,,,,,,,,,,,
1406874683.484,,2.500000e+001,2.979968e+002,2.980050e+002,1,0,1.385280e-001,-9.170812e-002,-9.170812e-002,-1.605368e-001,-1.922568e-001,7.003904e-002,1.210421e-003,-3.050967e-002,-1.998561e-006,-1.998561e-006,,,,,,,,,,,,,,,,,,,,
1406874683.484,,2.500000e+001,2.979968e+002,2.980050e+002,1,0,2.428205e+000,-9.933775e-002,-9.933775e-002,-9.637880e-002,-1.998865e-001,-5.059934e-003,-2.100989e-003,-1.056086e-001,-2.164831e-006,-2.164831e-006,,,,,,,,,,,,,,,,,,,,
1406874701.218,,2.500000e+001,2.979968e+002,2.979968e+002,1,0,3.448925e+000,7.171850e-002,7.171850e-002,4.224539e-002,-2.386037e-002,2.923987e-002,-2.332423e-004,-6.633899e-002,1.562935e-006,1.562935e-006,,,,,,,,,,,,,,,,,,,,
1406874811.703,,3.000000e+001,2.979968e+002,2.979968e+002,1,0,2.242576e-001,-3.527940e-001,-3.527940e-001,-1.318034e-001,-8.375931e-002,-2.940484e-001,-7.305785e-002,-2.501374e-002,-7.688305e-006,-7.688305e-006,,,,,,,,,,,,,,,,,,,,
1406874811.703,,3.000000e+001,2.979968e+002,2.979968e+002,1,0,2.256542e+000,-1.561022e-001,-1.561022e-001,-3.840647e-002,1.129325e-001,-7.268719e-002,4.500851e-002,1.963475e-001,-3.401876e-006,-3.401876e-006,,,,,,,,,,,,,,,,,,,,
1406874829.187,,3.000000e+001,2.979968e+002,2.980050e+002,1,0,3.584546e+000,-1.782281e-001,-1.782281e-001,-6.294669e-002,4.518767e-002,-2.077730e-001,-9.249158e-002,1.564278e-002,-3.884057e-006,-3.884057e-006,,,,,,,,,,,,,,,,,,,,
1406874847.437,,3.000000e+001,2.980050e+002,2.979968e+002,1,0,3.248788e-001,-2.673422e-001,-2.673422e-001,-8.849175e-002,-3.451224e-002,-2.244958e-001,-4.564536e-002,8.334160e-003,-5.826086e-006,-5.826086e-006,,,,,,,,,,,,,,,,,,,,
1406874963.937,,3.500000e+001,2.980050e+002,2.980050e+002,1,0,2.079870e+000,-6.256294e-002,-6.256294e-002,3.763676e-001,3.763676e-001,-8.731540e-002,3.516151e-001,3.516151e-001,-1.363410e-006,-1.363410e-006,,,,,,,,,,,,,,,,,,,,
1406874963.937,,3.500000e+001,2.980050e+002,2.980050e+002,1,0,3.706199e+000,-5.360576e-001,-5.360576e-001,-1.867254e-001,-9.712708e-002,-5.100009e-001,-1.606687e-001,-7.107037e-002,-1.168209e-005,-1.168209e-005,,,,,,,,,,,,,,,,,,,,
1406874981.671,,3.500000e+001,2.979968e+002,2.979968e+002,1,0,4.366286e-001,-5.003510e-001,-5.003510e-001,-1.394685e-001,-8.962214e-002,-4.989609e-001,-1.380785e-001,-8.823210e-002,-1.090395e-005,-1.090395e-005,,,,,,,,,,,,,,,,,,,,
1406874999.156,,3.500000e+001,2.979968e+002,2.979968e+002,1,0,1.900118e+000,-1.556444e-002,-1.556444e-002,4.411479e-001,4.434143e-001,-4.711990e-003,4.520003e-001,4.542668e-001,-3.391898e-007,-3.391898e-007,,,,,,,,,,,,,,,,,,,,
1406874999.156,,3.500000e+001,2.979968e+002,2.979968e+002,1,0,3.810477e+000,-5.737480e-001,-5.737480e-001,-2.144917e-001,-1.147692e-001,-5.026852e-001,-1.434290e-001,-4.370648e-002,-1.250347e-005,-1.250347e-005,,,,,,,,,,,,,,,,,,,,
1406875116.890,,4.000000e+001,2.980050e+002,2.979968e+002,1,0,5.569279e-001,-7.133701e-001,-7.133701e-001,-1.650800e-001,-1.152050e-001,-7.517300e-001,-2.034398e-001,-1.535648e-001,-1.554619e-005,-1.554619e-005,,,,,,,,,,,,,,,,,,,,
1406875134.625,,4.000000e+001,2.979968e+002,2.979968e+002,1,0,1.719176e+000,3.769036e-002,3.769036e-002,6.156552e-001,6.201189e-001,7.515708e-002,6.531219e-001,6.575856e-001,8.213710e-007,8.213710e-007,,,,,,,,,,,,,,,,,,,,
1406875134.625,,4.000000e+001,2.979968e+002,2.979968e+002,1,0,3.894082e+000,-8.201849e-001,-8.201849e-001,-3.381894e-001,-2.377564e-001,-6.963452e-001,-2.143497e-001,-1.139166e-001,-1.787396e-005,-1.787396e-005,,,,,,,,,,,,,,,,,,,,
1406875152.359,,4.000000e+001,2.980050e+002,2.979968e+002,1,0,6.837953e-001,-6.112857e-001,-6.112857e-001,-7.996108e-002,-2.376616e-002,-6.682968e-001,-1.369721e-001,-8.077717e-002,-1.332151e-005,-1.332151e-005,,,,,,,,,,,,,,,,,,,,
1406875263.687,,4.500000e+001,2.979968e+002,2.979885e+002,1,0,1.539089e+000,-1.812799e-001,-1.812799e-001,6.782045e-001,6.846337e-001,-2.092966e-001,6.501880e-001,6.566172e-001,-3.950560e-006,-3.950560e-006,,,,,,,,,,,,,,,,,,,,
1406875263.687,,4.500000e+001,2.979968e+002,2.979885e+002,1,0,3.954043e+000,-1.212043e+000,-1.212043e+000,-4.447097e-001,-3.461289e-001,-1.049899e+000,-2.825656e-001,-1.839848e-001,-2.641355e-005,-2.641355e-005,,,,,,,,,,,,,,,,,,,,
1406875281.953,,4.500000e+001,2.979968e+002,2.979968e+002,1,0,8.163823e-001,-8.206427e-001,-8.206427e-001,-4.155500e-002,1.416177e-002,-9.054123e-001,-1.263246e-001,-7.060784e-002,-1.788393e-005,-1.788393e-005,,,,,,,,,,,,,,,,,,,,
1406875300.234,,4.500000e+001,2.979968e+002,2.979968e+002,1,0,1.361582e+000,-3.218177e-001,-3.218177e-001,5.465519e-001,5.554430e-001,-4.123574e-001,4.560122e-001,4.649033e-001,-7.013241e-006,-7.013241e-006,,,,,,,,,,,,,,,,,,,,
1406875300.234,,4.500000e+001,2.979968e+002,2.979968e+002,1,0,3.987980e+000,-1.232643e+000,-1.232643e+000,-4.598527e-001,-3.553819e-001,-1.051181e+000,-2.783915e-001,-1.739207e-001,-2.686248e-005,-2.686248e-005,,,,,,,,,,,,,,,,,,,,
1406875417.031,,5.000000e+001,2.979968e+002,2.979968e+002,1,0,9.547185e-001,-1.036714e+000,-1.036714e+000,4.727723e-002,1.043111e-001,-1.154886e+000,-7.089505e-002,-1.386118e-002,-2.259267e-005,-2.259267e-005,,,,,,,,,,,,,,,,,,,,
1406875435.218,,5.000000e+001,2.979968e+002,2.979968e+002,1,0,1.187454e+000,-7.168798e-001,-7.168798e-001,3.924432e-001,4.039661e-001,-8.690104e-001,2.403126e-001,2.518355e-001,-1.562266e-005,-1.562266e-005,,,,,,,,,,,,,,,,,,,,
1406875435.218,,5.000000e+001,2.979968e+002,2.979968e+002,1,0,3.994895e+000,-1.595508e+000,-1.595508e+000,-5.852816e-001,-4.746617e-001,-1.395055e+000,-3.848290e-001,-2.742091e-001,-3.477023e-005,-3.477023e-005,,,,,,,,,,,,,,,,,,,,
1406875453.015,,5.000000e+001,2.979968e+002,2.980050e+002,1,0,1.098920e+000,-8.134708e-001,-8.134708e-001,2.387818e-001,3.009305e-001,-9.380205e-001,1.142321e-001,1.763809e-001,-1.772763e-005,-1.772763e-005,,,,,,,,,,,,,,,,,,,,
1406875576.015,,7.500000e+001,2.980050e+002,2.980050e+002,1,0,1.018727e+000,-1.612751e+000,-1.612751e+000,1.464454e-001,1.648945e-001,-1.809763e+000,-5.056734e-002,-3.211832e-002,-3.514592e-005,-3.514592e-005,,,,,,,,,,,,,,,,,,,,
1406875576.015,,7.500000e+001,2.980050e+002,2.980050e+002,1,0,3.975125e+000,-2.506638e+000,-2.506638e+000,-8.796597e-001,-7.289927e-001,-2.270289e+000,-6.433111e-001,-4.926441e-001,-5.462598e-005,-5.462598e-005,,,,,,,,,,,,,,,,,,,,
1406875594.250,,7.500000e+001,2.979968e+002,2.980050e+002,1,0,1.249891e+000,-1.054262e+000,-1.054262e+000,5.901334e-001,6.802472e-001,-1.192707e+000,4.516879e-001,5.418017e-001,-2.297503e-005,-2.297503e-005,,,,,,,,,,,,,,,,,,,,
1406875613.000,,7.500000e+001,2.979968e+002,2.979968e+002,1,0,8.556650e-001,-1.910917e+000,-1.910916e+000,-1.744334e-001,-1.522627e-001,-2.096365e+000,-3.598819e-001,-3.377112e-001,-4.164371e-005,-4.164371e-005,,,,,,,,,,,,,,,,,,,,
1406875613.000,,7.500000e+001,2.979968e+002,2.979968e+002,1,0,3.930325e+000,-2.486648e+000,-2.486648e+000,-8.863564e-001,-7.279943e-001,-2.278012e+000,-6.777198e-001,-5.193578e-001,-5.419036e-005,-5.419036e-005,,,,,,,,,,,,,,,,,,,,
1406875743.265,,1.000000e+002,2.979968e+002,2.980050e+002,1,0,1.408224e+000,-1.017334e+000,-1.017334e+000,1.133475e+000,1.243443e+000,-1.137138e+000,1.013671e+000,1.123640e+000,-2.217024e-005,-2.217024e-005,,,,,,,,,,,,,,,,,,,,
1406875761.250,,1.000000e+002,2.980050e+002,2.979968e+002,1,0,6.997665e-001,-2.751854e+000,-2.751854e+000,-5.695910e-001,-5.395195e-001,-2.945434e+000,-7.631709e-001,-7.330995e-001,-5.996973e-005,-5.996973e-005,,,,,,,,,,,,,,,,,,,,
1406875761.250,,1.000000e+002,2.980050e+002,2.979968e+002,1,0,3.863240e+000,-3.120975e+000,-3.120975e+000,-1.100346e+000,-9.086409e-001,-2.936585e+000,-9.159557e-001,-7.242503e-001,-6.801380e-005,-6.801380e-005,,,,,,,,,,,,,,,,,,,,
1406875779.500,,1.000000e+002,2.979968e+002,2.979968e+002,1,0,1.573545e+000,-5.465865e-001,-5.465865e-001,1.531172e+000,1.643700e+000,-5.732018e-001,1.504556e+000,1.617085e+000,-1.191148e-005,-1.191148e-005,,,,,,,,,,,,,,,,,,,,
1406875779.500,,1.000000e+002,2.979968e+002,2.979968e+002,1,0,2.256532e+000,-1.525925e-001,-1.525926e-001,1.801385e+000,2.037694e+000,9.319589e-002,2.047173e+000,2.283482e+000,-3.325370e-006,-3.325370e-006,,,,,,,,,,,,,,,,,,,,