File: Sample Data Files/2014-07-31 EB on isolated PMN-PT no Ti spontaneous in situ repeat/Ni-NiO_298K_SiO2_PMN-PT_5.0Tprebias_000V_Au_back.rso.raw
[Header]
TITLE,MPMS RSO Measurement
BYAPP,MPMS Measurement,2.1,Raw with ABS
FILEOPENTIME, 1406837160.890000 7/31/2014, 1:06:00 PM

INFO, APPNAME, MPMS MultiVu Application, Revision 1.58,  Build 076

INFO, NAME, EB in situ 2
INFO, WEIGHT, 0.000
INFO, AREA, 0.000
INFO, LENGTH, 0.000
INFO, SHAPE, 0
INFO, COMMENT,
INFO, SEQUENCE FILE: MHcurveUpTo100.seq


INFO, BACKGROUND DATA FILE:, None


STARTUPAXIS,X,8,LINEAR,AUTO,0.000000,0.000000
STARTUPAXIS,Y1,9,LINEAR,AUTO,0.000000,0.000000


STARTUPGROUP,Longitudinal
FIELDGROUP,Longitudinal,1,2,3,4,5,6,7,8,9,10,11,12,13,14,15,16,17,18,19,20,21,22
FIELDGROUP,Transverse,1,2,3,4,5,6,7,8,23,24,25,26,27,28,29,30,31,32,33,34,35,36

PLOT_APPEARANCE,ALL,HORZ_GRID_ON,VERT_GRID_ON,MARKERS_ONLY

[Data]
Time,Comment,Field (Oe),Start Temperature (K),End Temperature (K),Scan,Rejected,Position (cm),Long Voltage,Long Average Voltage,Long Detrended Voltage,Long Demeaned Voltage,Long Reg Fit,Long Detrended Fit,Long Demeaned Fit,Long Scaled Response,Long Avg. Scaled Response,Long Background Response,Long Response [w/ABS],Long Detrended Resp. [w/ABS],Long Fit [w/ABS],Long Detrended Fit [w/ABS],Trans Voltage,Trans Average Voltage,Trans Detrended Voltage,Trans Demeaned Voltage,Trans Reg Fit,Trans Detrended Fit,Trans Demeaned Fit,Trans Scaled Response,Trans Avg. Scaled Response,Trans Background Response,Trans Response [w/ABS],Trans Detrended Resp. [w/ABS],Trans Adjusted Fit,Trans Detrended Fit [w/ABS],
1406837160.890,,1.000000e+002,2.980050e+002,2.979968e+002,1,0,2.080135e+000,-7.827998e-002,-7.827998e-002,1.393662e+000,1.393662e+000,-2.270144e-002,1.449240e+000,1.449240e+000,-3.411830e-006,-3.411830e-006,,,,,,,,,,,,,,,,,,,,
1406837160.890,,1.000000e+002,2.980050e+002,2.979968e+002,1,0,3.706020e+000,-2.044282e+000,-2.044282e+000,-6.433777e-001,-5.723407e-001,-2.035324e+000,-6.344188e-001,-5.633819e-001,-8.909997e-005,-8.909997e-005,,,,,,,,,,,,,,,,,,,,
1406837178.625,,1.000000e+002,2.979968e+002,2.979968e+002,1,0,4.364187e-001,-2.046113e+000,-2.046113e+000,-6.191049e-001,-5.824708e-001,-2.062788e+000,-6.357794e-001,-5.991453e-001,-8.917978e-005,-8.917978e-005,,,,,,,,,,,,,,,,,,,,
1406837196.359,,1.000000e+002,2.979968e+002,2.980050e+002,1,0,1.900540e+000,-1.126133e-001,-1.126133e-001,1.369600e+000,1.371234e+000,-5.035320e-002,1.431860e+000,1.433494e+000,-4.908246e-006,-4.908246e-006,,,,,,,,,,,,,,,,,,,,
1406837196.359,,1.000000e+002,2.979968e+002,2.980050e+002,1,0,3.810409e+000,-2.073580e+000,-2.073580e+000,-6.616497e-001,-5.897324e-001,-2.013455e+000,-6.015244e-001,-5.296071e-001,-9.037691e-005,-9.037691e-005,,,,,,,,,,,,,,,,,,,,
1406837321.093,,7.500000e+001,2.980050e+002,2.979968e+002,1,0,5.567318e-001,-2.028871e+000,-2.028871e+000,-5.402104e-001,-5.122330e-001,-2.071792e+000,-5.831321e-001,-5.551548e-001,-8.842845e-005,-8.842845e-005,,,,,,,,,,,,,,,,,,,,
1406837339.328,,7.500000e+001,2.979968e+002,2.979968e+002,1,0,1.719407e+000,-3.071688e-001,-3.071688e-001,1.201570e+000,1.204068e+000,-2.866963e-001,1.222042e+000,1.224540e+000,-1.338797e-005,-1.338797e-005,,,,,,,,,,,,,,,,,,,,
1406837339.328,,7.500000e+001,2.979968e+002,2.979968e+002,1,0,3.893950e+000,-2.108066e+000,-2.108066e+000,-6.530366e-001,-5.968297e-001,-2.010879e+000,-5.558496e-001,-4.996426e-001,-9.188019e-005,-9.188019e-005,,,,,,,,,,,,,,,,,,,,
1406837357.578,,7.500000e+001,2.979968e+002,2.980050e+002,1,0,6.835876e-001,-1.917478e+000,-1.917478e+000,-4.254548e-001,-3.947744e-001,-1.974963e+000,-4.829403e-001,-4.522599e-001,-8.357340e-005,-8.357340e-005,,,,,,,,,,,,,,,,,,,,
1406837488.578,,5.000000e+001,2.980050e+002,2.980050e+002,1,0,1.539219e+000,-5.577257e-001,-5.577258e-001,9.381953e-001,9.414829e-001,-5.932146e-001,9.027066e-001,9.059941e-001,-2.430857e-005,-2.430857e-005,,,,,,,,,,,,,,,,,,,,
1406837488.578,,5.000000e+001,2.980050e+002,2.980050e+002,1,0,3.953883e+000,-2.075564e+000,-2.075564e+000,-6.267648e-001,-5.763552e-001,-1.961876e+000,-5.130764e-001,-4.626669e-001,-9.046379e-005,-9.046379e-005,,,,,,,,,,,,,,,,,,,,
1406837506.312,,5.000000e+001,2.979968e+002,2.980050e+002,1,0,8.160876e-001,-1.717734e+000,-1.717734e+000,-2.628525e-001,-2.346033e-001,-1.778178e+000,-3.232967e-001,-2.950474e-001,-7.486773e-005,-7.486773e-005,,,,,,,,,,,,,,,,,,,,
1406837524.078,,5.000000e+001,2.979885e+002,2.980050e+002,1,0,1.361750e+000,-8.873257e-001,-8.873256e-001,6.446035e-001,6.485981e-001,-9.578312e-001,5.740979e-001,5.780925e-001,-3.867423e-005,-3.867423e-005,,,,,,,,,,,,,,,,,,,,
1406837524.078,,5.000000e+001,2.979885e+002,2.980050e+002,1,0,3.987934e+000,-2.109287e+000,-2.109287e+000,-6.202995e-001,-5.733631e-001,-1.981966e+000,-4.929792e-001,-4.460428e-001,-9.193360e-005,-9.193360e-005,,,,,,,,,,,,,,,,,,,,
1406837642.312,,4.500000e+001,2.980050e+002,2.979968e+002,1,0,9.543293e-001,-1.533860e+000,-1.533860e+000,-5.605221e-002,-2.942157e-002,-1.605214e+000,-1.274056e-001,-1.007750e-001,-6.685358e-005,-6.685358e-005,,,,,,,,,,,,,,,,,,,,
1406837660.296,,4.500000e+001,2.979968e+002,2.979968e+002,1,0,1.187633e+000,-1.134678e+000,-1.134678e+000,3.454525e-001,3.508025e-001,-1.224252e+000,2.558782e-001,2.612282e-001,-4.945515e-005,-4.945515e-005,,,,,,,,,,,,,,,,,,,,
1406837660.296,,4.500000e+001,2.979968e+002,2.979968e+002,1,0,3.994852e+000,-2.050844e+000,-2.050844e+000,-6.167238e-001,-5.653633e-001,-1.921366e+000,-4.872458e-001,-4.358853e-001,-8.938640e-005,-8.938640e-005,,,,,,,,,,,,,,,,,,,,
1406837678.531,,4.500000e+001,2.979968e+002,2.979968e+002,1,0,1.098544e+000,-1.288034e+000,-1.288034e+000,1.839930e-001,2.135222e-001,-1.368829e+000,1.031981e-001,1.327273e-001,-5.613918e-005,-5.613918e-005,,,,,,,,,,,,,,,,,,,,
1406837794.531,,4.000000e+001,2.980050e+002,2.979968e+002,1,0,1.018920e+000,-1.439558e+000,-1.439558e+000,6.047097e-002,6.624532e-002,-1.527251e+000,-2.722153e-002,-2.144718e-002,-6.274343e-005,-6.274343e-005,,,,,,,,,,,,,,,,,,,,
1406837794.531,,4.000000e+001,2.980050e+002,2.979968e+002,1,0,3.975156e+000,-2.072664e+000,-2.072664e+000,-6.140182e-001,-5.668610e-001,-1.954506e+000,-4.958597e-001,-4.487026e-001,-9.033750e-005,-9.033750e-005,,,,,,,,,,,,,,,,,,,,
1406837812.593,,4.000000e+001,2.979968e+002,2.979885e+002,1,0,1.249623e+000,-1.019318e+000,-1.019318e+000,4.406720e-001,4.699697e-001,-1.096281e+000,3.637095e-001,3.930073e-001,-4.442719e-005,-4.442719e-005,,,,,,,,,,,,,,,,,,,,
1406837831.578,,4.000000e+001,2.980050e+002,2.979968e+002,1,0,8.557181e-001,-1.659902e+000,-1.659902e+000,-1.845336e-001,-1.772038e-001,-1.743741e+000,-2.683730e-001,-2.610432e-001,-7.234715e-005,-7.234715e-005,,,,,,,,,,,,,,,,,,,,
1406837831.578,,4.000000e+001,2.980050e+002,2.979968e+002,1,0,3.930355e+000,-2.056642e+000,-2.056642e+000,-6.263002e-001,-5.739443e-001,-1.951502e+000,-5.211597e-001,-4.688039e-001,-8.963917e-005,-8.963917e-005,,,,,,,,,,,,,,,,,,,,
1406837954.812,,3.500000e+001,2.979885e+002,2.980050e+002,1,0,1.407965e+000,-7.556383e-001,-7.556383e-001,7.113124e-001,7.381595e-001,-8.185892e-001,6.483615e-001,6.752086e-001,-3.293466e-005,-3.293466e-005,,,,,,,,,,,,,,,,,,,,
1406837973.046,,3.500000e+001,2.980050e+002,2.980050e+002,1,0,7.000747e-001,-1.835994e+000,-1.835994e+000,-3.734824e-001,-3.654195e-001,-1.912957e+000,-4.504456e-001,-4.423827e-001,-8.002218e-005,-8.002218e-005,,,,,,,,,,,,,,,,,,,,
1406837973.046,,3.500000e+001,2.980050e+002,2.980050e+002,1,0,3.863396e+000,-2.052370e+000,-2.052370e+000,-6.331967e-001,-5.817958e-001,-1.971407e+000,-5.522341e-001,-5.008333e-001,-8.945299e-005,-8.945299e-005,,,,,,,,,,,,,,,,,,,,
1406837990.781,,3.500000e+001,2.979968e+002,2.979968e+002,1,0,1.573346e+000,-4.814295e-001,-4.814295e-001,9.706137e-001,1.000840e+000,-5.043051e-001,9.477381e-001,9.779640e-001,-2.098321e-005,-2.098321e-005,,,,,,,,,,,,,,,,,,,,
1406838106.093,,3.000000e+001,2.979968e+002,2.979968e+002,1,0,5.532572e-001,-1.961882e+000,-1.961882e+000,-5.020030e-001,-4.935882e-001,-2.021533e+000,-5.616537e-001,-5.532389e-001,-8.550912e-005,-8.550912e-005,,,,,,,,,,,,,,,,,,,,
1406838106.093,,3.000000e+001,2.979968e+002,2.979968e+002,1,0,3.777736e+000,-2.053133e+000,-2.053133e+000,-6.334576e-001,-5.848386e-001,-2.003482e+000,-5.838065e-001,-5.351875e-001,-8.948629e-005,-8.948629e-005,,,,,,,,,,,,,,,,,,,,
1406838124.156,,3.000000e+001,2.979968e+002,2.979968e+002,1,0,1.744966e+000,-2.580340e-001,-2.580340e-001,1.171144e+000,1.200918e+000,-2.211266e-001,1.208051e+000,1.237826e+000,-1.124647e-005,-1.124647e-005,,,,,,,,,,,,,,,,,,,,
1406838141.890,,3.000000e+001,2.979968e+002,2.979968e+002,1,0,4.174187e-001,-2.024750e+000,-2.024750e+000,-5.728820e-001,-5.627823e-001,-2.059253e+000,-6.073847e-001,-5.972850e-001,-8.824924e-005,-8.824924e-005,,,,,,,,,,,,,,,,,,,,
1406838141.890,,3.000000e+001,2.979968e+002,2.979968e+002,1,0,3.677168e+000,-2.028871e+000,-2.028871e+000,-6.204309e-001,-5.669024e-001,-2.015890e+000,-6.074505e-001,-5.539219e-001,-8.842881e-005,-8.842881e-005,,,,,,,,,,,,,,,,,,,,
1406838259.437,,2.500000e+001,2.979968e+002,2.979968e+002,1,0,1.921524e+000,-1.525925e-001,-1.525926e-001,1.278198e+000,1.307320e+000,-6.913429e-002,1.361656e+000,1.390778e+000,-6.650786e-006,-6.650786e-006,,,,,,,,,,,,,,,,,,,,
1406838277.171,,2.500000e+001,2.979968e+002,2.979885e+002,1,0,2.957505e-001,-2.043825e+000,-2.043825e+000,-5.956411e-001,-5.852599e-001,-2.044384e+000,-5.962002e-001,-5.858190e-001,-8.908063e-005,-8.908063e-005,,,,,,,,,,,,,,,,,,,,
1406838277.171,,2.500000e+001,2.979968e+002,2.979885e+002,1,0,3.565380e+000,-1.981567e+000,-1.981567e+000,-5.739641e-001,-5.230020e-001,-2.005255e+000,-5.976521e-001,-5.466900e-001,-8.636711e-005,-8.636711e-005,,,,,,,,,,,,,,,,,,,,
1406838294.656,,2.500000e+001,2.979968e+002,2.979968e+002,1,0,2.101254e+000,-1.612903e-001,-1.612903e-001,1.258955e+000,1.290717e+000,-6.378024e-002,1.356465e+000,1.388227e+000,-7.029881e-006,-7.029881e-006,,,,,,,,,,,,,,,,,,,,
1406838407.406,,2.000000e+001,2.979968e+002,2.980050e+002,1,0,1.914572e-001,-2.039247e+000,-2.039247e+000,-5.921211e-001,-5.816014e-001,-2.005137e+000,-5.580110e-001,-5.474913e-001,-8.888115e-005,-8.888115e-005,,,,,,,,,,,,,,,,,,,,
1406838407.406,,2.000000e+001,2.979968e+002,2.980050e+002,1,0,3.445085e+000,-1.904050e+000,-1.904050e+000,-4.946196e-001,-4.464043e-001,-1.953987e+000,-5.445571e-001,-4.963418e-001,-8.298855e-005,-8.298855e-005,,,,,,,,,,,,,,,,,,,,
1406838424.640,,2.000000e+001,2.979968e+002,2.980050e+002,1,0,2.282162e+000,-3.074740e-001,-3.074740e-001,1.108183e+000,1.138319e+000,-2.483451e-001,1.167312e+000,1.197448e+000,-1.340134e-005,-1.340134e-005,,,,,,,,,,,,,,,,,,,,
1406838442.875,,2.000000e+001,2.980050e+002,2.980050e+002,1,0,1.077497e-001,-2.022767e+000,-2.022767e+000,-5.817093e-001,-5.697160e-001,-1.959813e+000,-5.187556e-001,-5.067623e-001,-8.816287e-005,-8.816287e-005,,,,,,,,,,,,,,,,,,,,
1406838442.875,,2.000000e+001,2.980050e+002,2.980050e+002,1,0,3.318194e+000,-1.779687e+000,-1.779687e+000,-3.782996e-001,-3.266361e-001,-1.846792e+000,-4.454050e-001,-3.937415e-001,-7.756815e-005,-7.756815e-005,,,,,,,,,,,,,,,,,,,,
1406838559.859,,1.500000e+001,2.979968e+002,2.980050e+002,1,0,2.462348e+000,-5.298013e-001,-5.298013e-001,8.749534e-001,9.040408e-001,-5.310457e-001,8.737091e-001,9.027964e-001,-2.309155e-005,-2.309155e-005,,,,,,,,,,,,,,,,,,,,
1406838578.125,,1.500000e+001,2.980050e+002,2.980050e+002,1,0,4.789715e-002,-1.969054e+000,-1.969054e+000,-5.622742e-001,-5.502676e-001,-1.888363e+000,-4.815834e-001,-4.695768e-001,-8.582183e-005,-8.582183e-005,,,,,,,,,,,,,,,,,,,,
1406838578.125,,1.500000e+001,2.980050e+002,2.980050e+002,1,0,3.185743e+000,-1.586200e+000,-1.586200e+000,-2.162967e-001,-1.674129e-001,-1.664521e+000,-2.946177e-001,-2.457339e-001,-6.913499e-005,-6.913499e-005,,,,,,,,,,,,,,,,,,,,
1406838595.859,,1.500000e+001,2.979968e+002,2.979968e+002,1,0,2.640182e+000,-7.896665e-001,-7.896664e-001,6.147472e-001,6.453570e-001,-8.431382e-001,5.612755e-001,5.918853e-001,-3.441785e-005,-3.441785e-005,,,,,,,,,,,,,,,,,,,,
1406838712.359,,1.000000e+001,2.979968e+002,2.979968e+002,1,0,1.387517e-002,-1.976989e+000,-1.976989e+000,-5.436196e-001,-5.333691e-001,-1.889634e+000,-4.562650e-001,-4.460145e-001,-8.616771e-005,-8.616771e-005,,,,,,,,,,,,,,,,,,,,
1406838712.359,,1.000000e+001,2.979968e+002,2.979968e+002,1,0,3.047508e+000,-1.429487e+000,-1.429487e+000,-2.550232e-002,1.413298e-002,-1.509548e+000,-1.055630e-001,-6.592774e-002,-6.230465e-005,-6.230465e-005,,,,,,,,,,,,,,,,,,,,
1406838730.593,,1.000000e+001,2.979968e+002,2.980050e+002,1,0,2.813904e+000,-1.044801e+000,-1.044801e+000,3.374894e-001,3.672132e-001,-1.125187e+000,2.571037e-001,2.868276e-001,-4.553800e-005,-4.553800e-005,,,,,,,,,,,,,,,,,,,,
1406838748.078,,1.000000e+001,2.980050e+002,2.979968e+002,1,0,6.927983e-003,-1.953185e+000,-1.953185e+000,-5.412308e-001,-5.290674e-001,-1.864237e+000,-4.522834e-001,-4.401200e-001,-8.513018e-005,-8.513018e-005,,,,,,,,,,,,,,,,,,,,
1406838748.078,,1.000000e+001,2.980050e+002,2.979968e+002,1,0,2.903195e+000,-1.187170e+000,-1.187170e+000,1.920947e-001,2.369472e-001,-1.266599e+000,1.126657e-001,1.575181e-001,-5.174319e-005,-5.174319e-005,,,,,,,,,,,,,,,,,,,,
1406838864.343,,5.000000e+000,2.980050e+002,2.980050e+002,1,0,2.982886e+000,-1.343425e+000,-1.343425e+000,7.710383e-002,9.547234e-002,-1.431642e+000,-1.111366e-002,7.254839e-003,-5.855363e-005,-5.855363e-005,,,,,,,,,,,,,,,,,,,,
1406838882.328,,5.000000e+000,2.979968e+002,2.979968e+002,1,0,2.663186e-002,-1.949980e+000,-1.949980e+000,-5.354478e-001,-5.259366e-001,-1.868091e+000,-4.535585e-001,-4.440472e-001,-8.499056e-005,-8.499056e-005,,,,,,,,,,,,,,,,,,,,
1406838882.328,,5.000000e+000,2.979968e+002,2.979968e+002,1,0,2.752087e+000,-9.739982e-001,-9.739982e-001,4.164762e-001,4.500453e-001,-1.038152e+000,3.523229e-001,3.858920e-001,-4.245205e-005,-4.245205e-005,,,,,,,,,,,,,,,,,,,,
1406838900.562,,5.000000e+000,2.979968e+002,2.980050e+002,1,0,3.145869e+000,-1.549577e+000,-1.549577e+000,-1.451501e-001,-1.230274e-001,-1.640165e+000,-2.357373e-001,-2.136147e-001,-6.753886e-005,-6.753886e-005,,,,,,,,,,,,,,,,,,,,
1406839017.062,,0.000000e+000,2.979968e+002,2.979968e+002,1,0,7.142000e-002,-1.976074e+000,-1.976074e+000,-5.289901e-001,-5.258524e-001,-1.907158e+000,-4.600749e-001,-4.569372e-001,-8.612787e-005,-8.612787e-005,,,,,,,,,,,,,,,,,,,,
1406839017.062,,0.000000e+000,2.979968e+002,2.979968e+002,1,0,2.593814e+000,-8.081301e-001,-8.081301e-001,6.314576e-001,6.420909e-001,-8.414920e-001,5.980958e-001,6.087291e-001,-3.522265e-005,-3.522265e-005,,,,,,,,,,,,,,,,,,,,
1406839035.296,,0.000000e+000,2.979968e+002,2.979968e+002,1,0,3.301725e+000,-1.720176e+000,-1.720176e+000,-3.186767e-001,-3.079761e-001,-1.796079e+000,-3.945800e-001,-3.838794e-001,-7.497449e-005,-7.497449e-005,,,,,,,,,,,,,,,,,,,,
1406839054.031,,0.000000e+000,2.979968e+002,2.979968e+002,1,0,1.384659e-001,-1.937620e+000,-1.937620e+000,-5.431998e-001,-5.366410e-001,-1.883834e+000,-4.894141e-001,-4.828553e-001,-8.445187e-005,-8.445187e-005,,,,,,,,,,,,,,,,,,,,
1406839054.031,,0.000000e+000,2.979968e+002,2.979968e+002,1,0,2.428501e+000,-5.333109e-001,-5.333109e-001,8.462658e-001,8.676682e-001,-5.169499e-001,8.626269e-001,8.840293e-001,-2.324455e-005,-2.324455e-005,,,,,,,,,,,,,,,,,,,,
1406839170.593,,-5.000000e+000,2.979968e+002,2.979968e+002,1,0,3.448606e+000,-1.770684e+000,-1.770684e+000,-3.922860e-001,-4.026877e-001,-1.820273e+000,-4.418749e-001,-4.522766e-001,-7.717587e-005,-7.717587e-005,,,,,,,,,,,,,,,,,,,,
1406839188.828,,-5.000000e+000,2.979968e+002,2.979968e+002,1,0,2.240994e-001,-1.830653e+000,-1.830653e+000,-4.868768e-001,-4.909725e-001,-1.798299e+000,-4.545228e-001,-4.586185e-001,-7.978964e-005,-7.978964e-005,,,,,,,,,,,,,,,,,,,,
1406839188.828,,-5.000000e+000,2.979968e+002,2.979968e+002,1,0,2.256861e+000,-4.538102e-001,-4.538102e-001,8.987715e-001,8.858701e-001,-3.853688e-001,9.672130e-001,9.543115e-001,-1.977948e-005,-1.977948e-005,,,,,,,,,,,,,,,,,,,,
1406839206.562,,-5.000000e+000,2.980050e+002,2.980050e+002,1,0,3.584311e+000,-1.748711e+000,-1.748711e+000,-4.460793e-001,-4.519914e-001,-1.771480e+000,-4.688486e-001,-4.747608e-001,-7.621815e-005,-7.621815e-005,,,,,,,,,,,,,,,,,,,,
1406839329.328,,-1.000000e+001,2.980050e+002,2.980050e+002,1,0,3.245807e-001,-7.712027e-001,-7.712027e-001,-1.099111e-001,-1.436139e-001,-7.518758e-001,-9.058420e-002,-1.242869e-001,-3.361312e-005,-3.361312e-005,,,,,,,,,,,,,,,,,,,,
1406839347.062,,-1.000000e+001,2.979968e+002,2.979968e+002,1,0,2.080303e+000,-3.846858e-001,-3.846858e-001,1.154456e-001,1.154456e-001,-3.715897e-001,1.285417e-001,1.285417e-001,-1.676665e-005,-1.676665e-005,,,,,,,,,,,,,,,,,,,,
1406839347.062,,-1.000000e+001,2.979968e+002,2.979968e+002,1,0,3.705993e+000,-6.372265e-001,-6.372265e-001,-5.177255e-002,-1.370950e-001,-6.269622e-001,-4.150828e-002,-1.268308e-001,-2.777372e-005,-2.777372e-005,,,,,,,,,,,,,,,,,,,,
1406839364.796,,-1.000000e+001,2.979968e+002,2.979968e+002,1,0,4.364478e-001,-4.481643e-001,-4.481643e-001,-2.427452e-002,-7.284790e-002,-4.585764e-001,-3.468659e-002,-8.325997e-002,-1.953339e-005,-1.953339e-005,,,,,,,,,,,,,,,,,,,,
1406839480.781,,-1.500000e+001,2.979968e+002,2.980050e+002,1,0,1.900523e+000,-5.406354e-001,-5.406354e-001,-7.442283e-001,-7.463033e-001,-5.208035e-001,-7.243964e-001,-7.264714e-001,-2.356376e-005,-2.356376e-005,,,,,,,,,,,,,,,,,,,,
1406839480.781,,-1.500000e+001,2.979968e+002,2.980050e+002,1,0,3.810333e+000,3.758354e-001,3.758354e-001,2.614671e-001,1.701675e-001,3.988320e-001,2.844636e-001,1.931641e-001,1.638090e-005,1.638090e-005,,,,,,,,,,,,,,,,,,,,
1406839499.296,,-1.500000e+001,2.980050e+002,2.980050e+002,1,0,5.567312e-001,5.543687e-001,5.543687e-001,3.084374e-001,2.657258e-001,5.332314e-001,2.873001e-001,2.445884e-001,2.416233e-005,2.416233e-005,,,,,,,,,,,,,,,,,,,,
1406839516.812,,-1.500000e+001,2.979968e+002,2.980050e+002,1,0,1.719684e+000,-3.494369e-001,-3.494369e-001,-7.127128e-001,-7.161429e-001,-3.405157e-001,-7.037915e-001,-7.072216e-001,-1.523031e-005,-1.523031e-005,,,,,,,,,,,,,,,,,,,,
1406839516.812,,-1.500000e+001,2.979968e+002,2.980050e+002,1,0,3.894016e+000,5.368206e-001,5.368206e-001,2.472925e-001,1.701146e-001,5.763723e-001,2.868442e-001,2.096663e-001,2.339749e-005,2.339749e-005,,,,,,,,,,,,,,,,,,,,
1406839635.046,,-2.000000e+001,2.979968e+002,2.980050e+002,1,0,6.835025e-001,5.511643e-001,5.511643e-001,3.350005e-001,2.605230e-001,5.165735e-001,3.004098e-001,2.259322e-001,2.402265e-005,2.402265e-005,,,,,,,,,,,,,,,,,,,,
1406839652.093,,-2.000000e+001,2.980050e+002,2.979968e+002,1,0,1.539583e+000,-3.187658e-001,-3.187658e-001,-6.281648e-001,-6.367871e-001,-3.254619e-001,-6.348609e-001,-6.434831e-001,-1.389350e-005,-1.389350e-005,,,,,,,,,,,,,,,,,,,,
1406839652.093,,-2.000000e+001,2.980050e+002,2.979968e+002,1,0,3.953958e+000,4.791406e-001,4.791406e-001,2.933269e-001,1.611194e-001,5.216235e-001,3.358097e-001,2.036023e-001,2.088348e-005,2.088348e-005,,,,,,,,,,,,,,,,,,,,
1406839670.578,,-2.000000e+001,2.979968e+002,2.979968e+002,1,0,8.160608e-001,5.652028e-001,5.652028e-001,2.448079e-001,1.793734e-001,5.193872e-001,1.989924e-001,1.335579e-001,2.463452e-005,2.463452e-005,,,,,,,,,,,,,,,,,,,,
1406839788.312,,-2.500000e+001,2.979968e+002,2.979968e+002,1,0,1.361788e+000,-2.613910e-001,-2.613910e-001,-3.974526e-001,-4.139542e-001,-2.874381e-001,-4.234996e-001,-4.400012e-001,-1.139280e-005,-1.139280e-005,,,,,,,,,,,,,,,,,,,,
1406839788.312,,-2.500000e+001,2.979968e+002,2.979968e+002,1,0,3.987891e+000,2.638325e-001,2.638325e-001,3.051633e-001,1.112694e-001,3.033290e-001,3.446598e-001,1.507659e-001,1.149921e-005,1.149921e-005,,,,,,,,,,,,,,,,,,,,
1406839806.046,,-2.500000e+001,2.979968e+002,2.980050e+002,1,0,9.543290e-001,2.693258e-001,2.693259e-001,1.228659e-001,2.377951e-002,2.242807e-001,7.782067e-002,-2.126569e-002,1.173864e-005,1.173864e-005,,,,,,,,,,,,,,,,,,,,
1406839824.562,,-2.500000e+001,2.980050e+002,2.979968e+002,1,0,1.187948e+000,1.058992e-001,1.058992e-001,-1.542657e-001,-1.722070e-001,6.160005e-002,-1.985649e-001,-2.165062e-001,4.615646e-006,4.615646e-006,,,,,,,,,,,,,,,,,,,,
1406839824.562,,-2.500000e+001,2.980050e+002,2.979968e+002,1,0,3.994895e+000,4.104739e-001,4.104739e-001,3.046045e-001,1.323677e-001,4.505365e-001,3.446671e-001,1.724303e-001,1.789062e-005,1.789062e-005,,,,,,,,,,,,,,,,,,,,
1406839941.312,,-3.000000e+001,2.979968e+002,2.979968e+002,1,0,1.098560e+000,-2.038636e-001,-2.038637e-001,-3.810120e-002,-1.854050e-001,-2.393646e-001,-7.360216e-002,-2.209060e-001,-8.885447e-006,-8.885447e-006,,,,,,,,,,,,,,,,,,,,
1406839959.578,,-3.000000e+001,2.979968e+002,2.979885e+002,1,0,1.019065e+000,1.376385e-001,1.376385e-001,7.237423e-002,4.274964e-002,9.183116e-002,2.656691e-002,-3.057681e-003,5.999007e-006,5.999007e-006,,,,,,,,,,,,,,,,,,,,
1406839959.578,,-3.000000e+001,2.979968e+002,2.979885e+002,1,0,3.975186e+000,2.035585e-001,2.035585e-001,3.506038e-001,1.086696e-001,2.357133e-001,3.827586e-001,1.408245e-001,8.872144e-006,8.872144e-006,,,,,,,,,,,,,,,,,,,,
1406839978.062,,-3.000000e+001,2.979885e+002,2.980050e+002,1,0,1.249698e+000,-1.849422e-001,-1.849422e-001,-2.564330e-001,-3.844197e-001,-2.011600e-001,-2.726509e-001,-4.006375e-001,-8.060749e-006,-8.060749e-006,,,,,,,,,,,,,,,,,,,,
1406840088.562,,-3.500000e+001,2.979968e+002,2.979968e+002,1,0,8.559448e-001,2.578814e-002,2.578814e-002,2.756349e-001,2.274520e-001,-1.448085e-002,2.353659e-001,1.871830e-001,1.123982e-006,1.123982e-006,,,,,,,,,,,,,,,,,,,,
1406840088.562,,-3.500000e+001,2.979968e+002,2.979968e+002,1,0,3.930351e+000,-1.402325e-001,-1.402325e-001,4.055954e-001,6.143126e-002,-1.155483e-001,4.302796e-001,8.611548e-002,-6.112067e-006,-6.112067e-006,,,,,,,,,,,,,,,,,,,,
1406840106.796,,-3.500000e+001,2.980050e+002,2.979968e+002,1,0,1.408026e+000,-7.669301e-001,-7.669302e-001,-5.188383e-001,-7.008426e-001,-7.539616e-001,-5.058698e-001,-6.878741e-001,-3.342682e-005,-3.342682e-005,,,,,,,,,,,,,,,,,,,,
1406840124.546,,-3.500000e+001,2.979968e+002,2.979968e+002,1,0,7.001150e-001,3.932310e-001,3.932310e-001,4.119358e-001,3.658443e-001,3.654948e-001,3.841996e-001,3.381081e-001,1.713906e-005,1.713906e-005,,,,,,,,,,,,,,,,,,,,
1406840124.546,,-3.500000e+001,2.979968e+002,2.979968e+002,1,0,3.863336e+000,1.767022e-001,1.767022e-001,4.431489e-001,1.493155e-001,1.941073e-001,4.605541e-001,1.667206e-001,7.701603e-006,7.701603e-006,,,,,,,,,,,,,,,,,,,,
1406840241.531,,-4.000000e+001,2.980050e+002,2.979968e+002,1,0,1.573250e+000,-1.398816e+000,-1.398816e+000,-7.921662e-001,-1.027677e+000,-1.362882e+000,-7.562326e-001,-9.917430e-001,-6.096767e-005,-6.096767e-005,,,,,,,,,,,,,,,,,,,,
1406840260.078,,-4.000000e+001,2.979968e+002,2.979968e+002,1,0,5.531110e-001,1.722770e-001,1.722770e-001,4.865681e-001,4.215510e-001,1.627921e-001,4.770832e-001,4.120662e-001,7.508727e-006,7.508727e-006,,,,,,,,,,,,,,,,,,,,
1406840260.078,,-4.000000e+001,2.979968e+002,2.979968e+002,1,0,3.777684e+000,-1.400800e-001,-1.400800e-001,4.848481e-001,1.091941e-001,-1.326286e-001,4.922994e-001,1.166454e-001,-6.105413e-006,-6.105413e-006,,,,,,,,,,,,,,,,,,,,
1406840278.312,,-4.000000e+001,2.979968e+002,2.979968e+002,1,0,1.744891e+000,-1.348308e+000,-1.348308e+000,-1.018732e+000,-1.223802e+000,-1.315711e+000,-9.861351e-001,-1.191205e+000,-5.876627e-005,-5.876627e-005,,,,,,,,,,,,,,,,,,,,
1406840396.593,,-4.500000e+001,2.980050e+002,2.979968e+002,1,0,4.174300e-001,-1.281777e-001,-1.281777e-001,5.097522e-001,4.216133e-001,-1.262323e-001,5.116976e-001,4.235588e-001,-5.586650e-006,-5.586650e-006,,,,,,,,,,,,,,,,,,,,
1406840396.593,,-4.500000e+001,2.980050e+002,2.979968e+002,1,0,3.677182e+000,-5.063021e-001,-5.063021e-001,5.106248e-001,4.348904e-002,-5.052401e-001,5.116868e-001,4.455101e-002,-2.206727e-005,-2.206727e-005,,,,,,,,,,,,,,,,,,,,
1406840414.843,,-4.500000e+001,2.979968e+002,2.979968e+002,1,0,1.921618e+000,-1.781518e+000,-1.781518e+000,-1.154926e+000,-1.411855e+000,-1.769942e+000,-1.143351e+000,-1.400279e+000,-7.764778e-005,-7.764778e-005,,,,,,,,,,,,,,,,,,,,
1406840432.578,,-4.500000e+001,2.980050e+002,2.980050e+002,1,0,2.957714e-001,1.730400e-001,1.730399e-001,4.925596e-001,4.119215e-001,1.811824e-001,5.007020e-001,4.200639e-001,7.541978e-006,7.541978e-006,,,,,,,,,,,,,,,,,,,,
1406840432.578,,-4.500000e+001,2.980050e+002,2.980050e+002,1,0,3.565309e+000,-1.284829e-001,-1.284829e-001,5.062581e-001,1.103987e-001,-1.329981e-001,5.017429e-001,1.058834e-001,-5.599952e-006,-5.599952e-006,,,,,,,,,,,,,,,,,,,,
1406840550.812,,-5.000000e+001,2.980050e+002,2.979968e+002,1,0,2.101320e+000,-2.172002e+000,-2.172002e+000,-1.150407e+000,-1.468438e+000,-2.186495e+000,-1.164900e+000,-1.482931e+000,-9.466707e-005,-9.466707e-005,,,,,,,,,,,,,,,,,,,,
1406840569.046,,-5.000000e+001,2.979968e+002,2.979968e+002,1,0,1.914253e-001,-1.794488e-001,-1.794488e-001,4.557340e-001,3.495421e-001,-1.638299e-001,4.713529e-001,3.651611e-001,-7.821306e-006,-7.821306e-006,,,,,,,,,,,,,,,,,,,,
1406840569.046,,-5.000000e+001,2.979968e+002,2.979968e+002,1,0,3.445011e+000,-5.499436e-001,-5.499436e-001,4.657600e-001,-2.095258e-002,-5.598885e-001,4.558150e-001,-3.089756e-002,-2.396938e-005,-2.396938e-005,,,,,,,,,,,,,,,,,,,,
1406840586.781,,-5.000000e+001,2.979968e+002,2.980050e+002,1,0,2.282270e+000,-1.673025e+000,-1.673025e+000,-1.007509e+000,-1.283859e+000,-1.695138e+000,-1.029622e+000,-1.305973e+000,-7.291905e-005,-7.291905e-005,,,,,,,,,,,,,,,,,,,,
1406840767.500,,-7.500000e+001,2.979968e+002,2.979968e+002,1,0,1.077562e-001,-6.630146e-001,-6.630146e-001,1.741751e-001,9.038037e-002,-6.596055e-001,1.775842e-001,9.378946e-002,-7.224383e-005,-7.224383e-005,,,,,,,,,,,,,,,,,,,,
1406840767.500,,-7.500000e+001,2.979968e+002,2.979968e+002,1,0,3.318078e+000,-9.669790e-001,-9.669790e-001,1.473781e-001,-2.135840e-001,-9.673374e-001,1.470197e-001,-2.139424e-001,-1.053646e-004,-1.053646e-004,,,,,,,,,,,,,,,,,,,,
1406840785.734,,-7.500000e+001,2.979968e+002,2.980050e+002,1,0,2.462379e+000,-1.196936e+000,-1.196936e+000,-3.203602e-001,-5.299371e-001,-1.205145e+000,-3.285691e-001,-5.381460e-001,-1.304213e-004,-1.304213e-004,,,,,,,,,,,,,,,,,,,,
1406840804.046,,-7.500000e+001,2.979968e+002,2.979968e+002,1,0,4.779514e-002,-5.531480e-001,-5.531480e-001,1.623909e-001,8.129704e-002,-5.495462e-001,1.659926e-001,8.489883e-002,-6.027247e-005,-6.027247e-005,,,,,,,,,,,,,,,,,,,,
1406840804.046,,-7.500000e+001,2.979968e+002,2.979968e+002,1,0,3.185546e+000,-8.719138e-001,-8.719138e-001,9.269889e-002,-2.374688e-001,-8.725721e-001,9.204055e-002,-2.381271e-001,-9.500604e-005,-9.500604e-005,,,,,,,,,,,,,,,,,,,,
1406840933.781,,-1.000000e+002,2.980050e+002,2.979885e+002,1,0,2.640100e+000,-2.129124e+000,-2.129124e+000,-2.228252e-001,-5.952572e-001,-2.128527e+000,-2.222280e-001,-5.946599e-001,-2.319944e-004,-2.319944e-004,,,,,,,,,,,,,,,,,,,,
1406840951.765,,-1.000000e+002,2.979968e+002,2.980050e+002,1,0,1.380337e-002,-1.101871e+000,-1.101871e+000,1.629867e-001,4.011726e-002,-1.103535e+000,1.613227e-001,3.845322e-002,-1.200625e-004,-1.200625e-004,,,,,,,,,,,,,,,,,,,,
1406840951.765,,-1.000000e+002,2.979968e+002,2.980050e+002,1,0,3.047372e+000,-1.602222e+000,-1.602222e+000,1.486153e-002,-4.602337e-001,-1.595385e+000,2.169866e-002,-4.533966e-001,-1.745819e-004,-1.745819e-004,,,,,,,,,,,,,,,,,,,,
1406840970.000,,-1.000000e+002,2.979968e+002,2.979968e+002,1,0,2.814181e+000,-1.376080e+000,-1.376080e+000,-1.190379e-001,-3.755817e-001,-1.370403e+000,-1.133614e-001,-3.699052e-001,-1.499409e-004,-1.499409e-004,,,,,,,,,,,,,,,,,,,,
1406841093.265,,-7.500000e+001,2.979968e+002,2.979968e+002,1,0,6.851120e-003,4.777673e-001,4.777673e-001,1.591911e-001,1.432749e-001,4.780713e-001,1.594951e-001,1.435789e-001,5.205879e-005,5.205879e-005,,,,,,,,,,,,,,,,,,,,
1406841093.265,,-7.500000e+001,2.979968e+002,2.979968e+002,1,0,2.903047e+000,2.110355e-001,2.110355e-001,-6.476580e-002,-1.234569e-001,2.177682e-001,-5.803311e-002,-1.167242e-001,2.299499e-005,2.299499e-005,,,,,,,,,,,,,,,,,,,,
1406841111.046,,-7.500000e+001,2.980050e+002,2.980050e+002,1,0,2.983087e+000,2.855006e-001,2.855006e-001,-1.513752e-002,-5.141297e-002,2.884976e-001,-1.214060e-002,-4.841605e-002,3.110891e-005,3.110891e-005,,,,,,,,,,,,,,,,,,,,
1406841129.312,,-7.500000e+001,2.980050e+002,2.979968e+002,1,0,2.665089e-002,4.916532e-001,4.916532e-001,1.623996e-001,1.461345e-001,4.927773e-001,1.635238e-001,1.472587e-001,5.357184e-005,5.357184e-005,,,,,,,,,,,,,,,,,,,,
1406841129.312,,-7.500000e+001,2.980050e+002,2.979968e+002,1,0,2.751970e+000,1.293985e-001,1.293985e-001,-1.587140e-001,-2.161202e-001,1.382043e-001,-1.499081e-001,-2.073143e-001,1.409960e-005,1.409960e-005,,,,,,,,,,,,,,,,,,,,
1406841260.312,,-5.000000e+001,2.979968e+002,2.980050e+002,1,0,3.145993e+000,4.683065e-001,4.683065e-001,7.652511e-002,5.677438e-002,4.653756e-001,7.359418e-002,5.384344e-002,5.102804e-005,5.102804e-005,,,,,,,,,,,,,,,,,,,,
1406841278.046,,-5.000000e+001,2.979968e+002,2.980050e+002,1,0,7.142889e-002,5.754265e-001,5.754265e-001,1.657186e-001,1.568283e-001,5.802980e-001,1.705901e-001,1.616997e-001,6.270014e-005,6.270014e-005,,,,,,,,,,,,,,,,,,,,
1406841278.046,,-5.000000e+001,2.979968e+002,2.980050e+002,1,0,2.593621e+000,1.356548e-001,1.356548e-001,-2.528151e-001,-2.829435e-001,1.418023e-001,-2.466675e-001,-2.767959e-001,1.478134e-005,1.478134e-005,,,,,,,,,,,,,,,,,,,,
1406841295.781,,-5.000000e+001,2.980050e+002,2.979968e+002,1,0,3.301824e+000,5.363628e-001,5.363628e-001,1.431565e-001,1.227234e-001,5.343435e-001,1.411372e-001,1.207041e-001,5.844365e-005,5.844365e-005,,,,,,,,,,,,,,,,,,,,
1406841414.281,,-4.500000e+001,2.980050e+002,2.979968e+002,1,0,1.384408e-001,5.842769e-001,5.842769e-001,1.786537e-001,1.693093e-001,5.882215e-001,1.825983e-001,1.732539e-001,6.366453e-005,6.366453e-005,,,,,,,,,,,,,,,,,,,,
1406841414.281,,-4.500000e+001,2.980050e+002,2.979968e+002,1,0,2.428303e+000,3.479110e-002,3.479110e-002,-3.496841e-001,-3.801765e-001,3.765353e-002,-3.468217e-001,-3.773141e-001,3.790941e-006,3.790941e-006,,,,,,,,,,,,,,,,,,,,
1406841432.765,,-4.500000e+001,2.980132e+002,2.979968e+002,1,0,3.448759e+000,5.879391e-001,5.879391e-001,1.857186e-001,1.660835e-001,5.879276e-001,1.857071e-001,1.660720e-001,6.406358e-005,6.406358e-005,,,,,,,,,,,,,,,,,,,,
1406841451.000,,-4.500000e+001,2.979968e+002,2.979968e+002,1,0,2.241402e-001,6.047243e-001,6.047243e-001,1.948515e-001,1.854043e-001,6.063000e-001,1.964272e-001,1.869800e-001,6.589254e-005,6.589254e-005,,,,,,,,,,,,,,,,,,,,
1406841451.000,,-4.500000e+001,2.979968e+002,2.979968e+002,1,0,2.256670e+000,-4.013184e-002,-4.013184e-002,-4.296930e-001,-4.594519e-001,-4.348293e-002,-4.330441e-001,-4.628029e-001,-4.372884e-006,-4.372884e-006,,,,,,,,,,,,,,,,,,,,
1406841568.234,,-4.000000e+001,2.979968e+002,2.979968e+002,1,0,3.584443e+000,6.059450e-001,6.059450e-001,2.051982e-001,1.863670e-001,6.070930e-001,2.063463e-001,1.875151e-001,6.602559e-005,6.602559e-005,,,,,,,,,,,,,,,,,,,,
1406841586.468,,-4.000000e+001,2.979968e+002,2.980050e+002,1,0,3.246818e-001,6.237983e-001,6.237983e-001,2.061547e-001,1.969342e-001,6.242123e-001,2.065688e-001,1.973482e-001,6.797094e-005,6.797094e-005,,,,,,,,,,,,,,,,,,,,
1406841604.703,,-4.000000e+001,2.979968e+002,2.979968e+002,1,0,2.080069e+000,-6.088443e-002,-6.088443e-002,-4.782792e-001,-4.782792e-001,-5.936427e-002,-4.767590e-001,-4.767590e-001,-6.634150e-006,-6.634150e-006,,,,,,,,,,,,,,,,,,,,
1406841604.703,,-4.000000e+001,2.979968e+002,2.979968e+002,1,0,3.706075e+000,6.056398e-001,6.056398e-001,2.073085e-001,1.882450e-001,6.070207e-001,2.086893e-001,1.896259e-001,6.599233e-005,6.599233e-005,,,,,,,,,,,,,,,,,,,,
1406841721.640,,-3.500000e+001,2.979968e+002,2.979968e+002,1,0,4.365471e-001,6.141850e-001,6.141850e-001,2.097359e-001,1.999559e-001,6.125551e-001,2.081061e-001,1.983261e-001,6.692347e-005,6.692347e-005,,,,,,,,,,,,,,,,,,,,
1406841739.250,,-3.500000e+001,2.980050e+002,2.979968e+002,1,0,1.900370e+000,-4.119999e-002,-4.119999e-002,-4.628870e-001,-4.633079e-001,-3.796389e-002,-4.596509e-001,-4.600718e-001,-4.489276e-006,-4.489276e-006,,,,,,,,,,,,,,,,,,,,
1406841739.250,,-3.500000e+001,2.980050e+002,2.979968e+002,1,0,3.810404e+000,5.998413e-001,5.998413e-001,1.962538e-001,1.777334e-001,6.027880e-001,1.992005e-001,1.806801e-001,6.536054e-005,6.536054e-005,,,,,,,,,,,,,,,,,,,,
1406841756.484,,-3.500000e+001,2.980050e+002,2.980050e+002,1,0,5.568175e-001,6.157109e-001,6.157109e-001,2.016260e-001,1.926100e-001,6.104764e-001,1.963915e-001,1.873755e-001,6.708974e-005,6.708974e-005,,,,,,,,,,,,,,,,,,,,
1406841873.718,,-3.000000e+001,2.979968e+002,2.979968e+002,1,0,1.719481e+000,2.777184e-002,2.777184e-002,-3.915795e-001,-3.924188e-001,3.308408e-002,-3.862672e-001,-3.871065e-001,3.026106e-006,3.026106e-006,,,,,,,,,,,,,,,,,,,,
1406841873.718,,-3.000000e+001,2.979968e+002,2.979968e+002,1,0,3.894041e+000,5.829035e-001,5.829035e-001,1.815965e-001,1.627129e-001,5.876143e-001,1.863073e-001,1.674237e-001,6.351498e-005,6.351498e-005,,,,,,,,,,,,,,,,,,,,
1406841890.484,,-3.000000e+001,2.979968e+002,2.979968e+002,1,0,6.837298e-001,5.865657e-001,5.865657e-001,1.749276e-001,1.657875e-001,5.779481e-001,1.663100e-001,1.571699e-001,6.391403e-005,6.391403e-005,,,,,,,,,,,,,,,,,,,,
1406841908.218,,-3.000000e+001,2.979968e+002,2.979968e+002,1,0,1.539210e+000,1.306192e-001,1.306192e-001,-2.875673e-001,-2.887185e-001,1.346407e-001,-2.835458e-001,-2.846970e-001,1.423268e-005,1.423268e-005,,,,,,,,,,,,,,,,,,,,
1406841908.218,,-3.000000e+001,2.979968e+002,2.979968e+002,1,0,3.953952e+000,5.726798e-001,5.726798e-001,1.709937e-001,1.533421e-001,5.775818e-001,1.758957e-001,1.582441e-001,6.240097e-005,6.240097e-005,,,,,,,,,,,,,,,,,,,,
1406842024.468,,-2.500000e+001,2.979968e+002,2.979968e+002,1,0,8.161971e-001,5.352947e-001,5.352947e-001,1.319106e-001,1.220456e-001,5.219921e-001,1.186081e-001,1.087431e-001,5.832739e-005,5.832739e-005,,,,,,,,,,,,,,,,,,,,
1406842041.703,,-2.500000e+001,2.979968e+002,2.980050e+002,1,0,1.361652e+000,2.505570e-001,2.505570e-001,-1.680598e-001,-1.695026e-001,2.458250e-001,-1.727918e-001,-1.742345e-001,2.730148e-005,2.730148e-005,,,,,,,,,,,,,,,,,,,,
1406842041.703,,-2.500000e+001,2.979968e+002,2.980050e+002,1,0,3.987934e+000,5.658132e-001,5.658132e-001,1.627057e-001,1.457537e-001,5.717373e-001,1.686298e-001,1.516778e-001,6.165279e-005,6.165279e-005,,,,,,,,,,,,,,,,,,,,
1406842059.437,,-2.500000e+001,2.980050e+002,2.979968e+002,1,0,9.544637e-001,4.815821e-001,4.815821e-001,7.039205e-002,6.109846e-002,4.670693e-001,5.587930e-002,4.658571e-002,5.247470e-005,5.247470e-005,,,,,,,,,,,,,,,,,,,,
1406842174.921,,-2.000000e+001,2.979968e+002,2.979968e+002,1,0,1.187479e+000,3.608814e-001,3.608814e-001,-5.660470e-002,-5.844864e-002,3.486485e-001,-6.883760e-002,-7.068154e-002,3.932279e-005,3.932279e-005,,,,,,,,,,,,,,,,,,,,
1406842174.921,,-2.000000e+001,2.979968e+002,2.979968e+002,1,0,3.994833e+000,5.612354e-001,5.612354e-001,1.596072e-001,1.419053e-001,5.680798e-001,1.664516e-001,1.487497e-001,6.115401e-005,6.115401e-005,,,,,,,,,,,,,,,,,,,,
1406842192.656,,-2.000000e+001,2.979968e+002,2.979968e+002,1,0,1.098803e+000,4.109317e-001,4.109317e-001,-7.302455e-003,-1.593655e-002,3.989730e-001,-1.926117e-002,-2.789527e-002,4.477644e-005,4.477644e-005,,,,,,,,,,,,,,,,,,,,
1406842231.906,,-2.000000e+001,2.979968e+002,2.980050e+002,1,0,1.018875e+000,4.524369e-001,4.524369e-001,3.794538e-002,3.590563e-002,4.377310e-001,2.323951e-002,2.119976e-002,4.929897e-005,4.929897e-005,,,,,,,,,,,,,,,,,,,,
1406842231.906,,-2.000000e+001,2.979968e+002,2.980050e+002,1,0,3.975143e+000,5.626087e-001,5.626087e-001,1.627354e-001,1.460775e-001,5.700267e-001,1.701534e-001,1.534954e-001,6.130365e-005,6.130365e-005,,,,,,,,,,,,,,,,,,,,
1406842349.171,,-1.500000e+001,2.979968e+002,2.979968e+002,1,0,1.249851e+000,3.143407e-001,3.143407e-001,-9.948770e-002,-1.087806e-001,3.093340e-001,-1.044944e-001,-1.137873e-001,3.425158e-005,3.425158e-005,,,,,,,,,,,,,,,,,,,,
1406842366.906,,-1.500000e+001,2.979968e+002,2.979968e+002,1,0,8.555278e-001,5.362102e-001,5.362102e-001,1.149270e-001,1.126828e-001,5.218250e-001,1.005418e-001,9.829754e-002,5.842721e-005,5.842721e-005,,,,,,,,,,,,,,,,,,,,
1406842366.906,,-1.500000e+001,2.979968e+002,2.979968e+002,1,0,3.930272e+000,5.774102e-001,5.774102e-001,1.699128e-001,1.538827e-001,5.845681e-001,1.770708e-001,1.610407e-001,6.291649e-005,6.291649e-005,,,,,,,,,,,,,,,,,,,,
1406842385.140,,-1.500000e+001,2.979968e+002,2.979968e+002,1,0,1.408076e+000,2.072207e-001,2.072207e-001,-2.050544e-001,-2.139841e-001,2.131448e-001,-1.991302e-001,-2.080600e-001,2.257944e-005,2.257944e-005,,,,,,,,,,,,,,,,,,,,
1406842508.875,,-1.000000e+001,2.979885e+002,2.979968e+002,1,0,7.000570e-001,5.757317e-001,5.757317e-001,1.670499e-001,1.639018e-001,5.659221e-001,1.572404e-001,1.540923e-001,6.273363e-005,6.273363e-005,,,,,,,,,,,,,,,,,,,,
1406842508.875,,-1.000000e+001,2.979885e+002,2.979968e+002,1,0,3.863328e+000,5.714591e-001,5.714591e-001,1.796985e-001,1.596292e-001,5.781758e-001,1.864151e-001,1.663459e-001,6.226807e-005,6.226807e-005,,,,,,,,,,,,,,,,,,,,
1406842526.687,,-1.000000e+001,2.979968e+002,2.979968e+002,1,0,1.573481e+000,1.036103e-001,1.036103e-001,-3.128476e-001,-3.212042e-001,1.191836e-001,-2.972743e-001,-3.056309e-001,1.128973e-005,1.128973e-005,,,,,,,,,,,,,,,,,,,,
1406842545.000,,-1.000000e+001,2.980050e+002,2.980050e+002,1,0,5.529084e-001,6.154057e-001,6.154057e-001,1.954112e-001,1.927620e-001,6.114107e-001,1.914161e-001,1.887669e-001,6.705664e-005,6.705664e-005,,,,,,,,,,,,,,,,,,,,
1406842545.000,,-1.000000e+001,2.980050e+002,2.980050e+002,1,0,3.777547e+000,6.012146e-001,6.012146e-001,1.938777e-001,1.785709e-001,6.043265e-001,1.969896e-001,1.816828e-001,6.551034e-005,6.551034e-005,,,,,,,,,,,,,,,,,,,,
1406842662.234,,-5.000000e+000,2.980050e+002,2.979968e+002,1,0,1.745106e+000,2.136296e-003,2.136296e-003,-4.021515e-001,-4.111261e-001,1.770037e-002,-3.865874e-001,-3.955621e-001,2.327779e-007,2.327779e-007,,,,,,,,,,,,,,,,,,,,
1406842679.968,,-5.000000e+000,2.980050e+002,2.979885e+002,1,0,4.173018e-001,6.170843e-001,6.170843e-001,2.014887e-001,1.987620e-001,6.166387e-001,2.010431e-001,1.983164e-001,6.723958e-005,6.723958e-005,,,,,,,,,,,,,,,,,,,,
1406842679.968,,-5.000000e+000,2.980050e+002,2.979885e+002,1,0,3.677035e+000,6.042665e-001,6.042665e-001,2.003955e-001,1.859442e-001,6.049097e-001,2.010387e-001,1.865874e-001,6.584291e-005,6.584291e-005,,,,,,,,,,,,,,,,,,,,
1406842698.703,,-5.000000e+000,2.979968e+002,2.979968e+002,1,0,1.921692e+000,-4.028443e-002,-4.028443e-002,-4.549342e-001,-4.627594e-001,-3.326995e-002,-4.479197e-001,-4.557449e-001,-4.389527e-006,-4.389527e-006,,,,,,,,,,,,,,,,,,,,
1406842816.453,,0.000000e+000,2.979968e+002,2.979968e+002,1,0,2.957132e-001,5.945005e-001,5.945005e-001,1.903780e-001,1.874024e-001,5.983465e-001,1.942240e-001,1.912484e-001,6.477880e-005,6.477880e-005,,,,,,,,,,,,,,,,,,,,
1406842816.453,,0.000000e+000,2.979968e+002,2.979968e+002,1,0,3.565275e+000,5.902280e-001,5.902280e-001,1.977376e-001,1.831298e-001,5.870792e-001,1.945888e-001,1.799810e-001,6.431325e-005,6.431325e-005,,,,,,,,,,,,,,,,,,,,
1406842834.000,,0.000000e+000,2.980050e+002,2.980050e+002,1,0,2.101365e+000,-3.982665e-002,-3.982665e-002,-4.502014e-001,-4.583833e-001,-4.037455e-002,-4.507493e-001,-4.589311e-001,-4.339648e-006,-4.339648e-006,,,,,,,,,,,,,,,,,,,,
1406842851.484,,0.000000e+000,2.980050e+002,2.979968e+002,1,0,1.914074e-001,5.917539e-001,5.917539e-001,1.726209e-001,1.698937e-001,6.007390e-001,1.816060e-001,1.788788e-001,6.447952e-005,6.447952e-005,,,,,,,,,,,,,,,,,,,,
1406842851.484,,0.000000e+000,2.980050e+002,2.979968e+002,1,0,3.444991e+000,5.925168e-001,5.925168e-001,1.831566e-001,1.706566e-001,5.846947e-001,1.753345e-001,1.628345e-001,6.456265e-005,6.456265e-005,,,,,,,,,,,,,,,,,,,,
1406842967.718,,5.000000e+000,2.980050e+002,2.979968e+002,1,0,2.282405e+000,1.251259e-002,1.251259e-002,-3.898208e-001,-3.978555e-001,7.138757e-003,-3.951946e-001,-4.032293e-001,1.363414e-006,1.363414e-006,,,,,,,,,,,,,,,,,,,,
1406842985.953,,5.000000e+000,2.979968e+002,2.980050e+002,1,0,1.077429e-001,5.607776e-001,5.607776e-001,1.523372e-001,1.493588e-001,5.745725e-001,1.661321e-001,1.631537e-001,6.110421e-005,6.110421e-005,,,,,,,,,,,,,,,,,,,,
1406842985.953,,5.000000e+000,2.979968e+002,2.980050e+002,1,0,3.318092e+000,5.488754e-001,5.488754e-001,1.502865e-001,1.374566e-001,5.365046e-001,1.379156e-001,1.250858e-001,5.980731e-005,5.980731e-005,,,,,,,,,,,,,,,,,,,,
1406843003.187,,5.000000e+000,2.979968e+002,2.979968e+002,1,0,2.462461e+000,1.058992e-001,1.058992e-001,-2.976793e-001,-3.052020e-001,9.810436e-002,-3.054742e-001,-3.129969e-001,1.153914e-005,1.153914e-005,,,,,,,,,,,,,,,,,,,,
1406843125.937,,1.000000e+001,2.979968e+002,2.980050e+002,1,0,4.784382e-002,5.400250e-001,5.400250e-001,1.348961e-001,1.318358e-001,5.585268e-001,1.533979e-001,1.503376e-001,5.884291e-005,5.884291e-005,,,,,,,,,,,,,,,,,,,,
1406843125.937,,1.000000e+001,2.979968e+002,2.980050e+002,1,0,3.185601e+000,4.971465e-001,4.971465e-001,1.014173e-001,8.895728e-002,4.815753e-001,8.584604e-002,7.338604e-002,5.417073e-005,5.417073e-005,,,,,,,,,,,,,,,,,,,,
1406843144.171,,1.000000e+001,2.980050e+002,2.979885e+002,1,0,2.640278e+000,2.143925e-001,2.143925e-001,-1.898603e-001,-1.969276e-001,2.046573e-001,-1.995956e-001,-2.066628e-001,2.336092e-005,2.336092e-005,,,,,,,,,,,,,,,,,,,,
1406843162.406,,1.000000e+001,2.979968e+002,2.979968e+002,1,0,1.383461e-002,5.320902e-001,5.320902e-001,1.270783e-001,1.243725e-001,5.520959e-001,1.470840e-001,1.443782e-001,5.797831e-005,5.797831e-005,,,,,,,,,,,,,,,,,,,,
1406843162.406,,1.000000e+001,2.979968e+002,2.979968e+002,1,0,3.047421e+000,4.344310e-001,4.344310e-001,3.717580e-002,2.671325e-002,4.197421e-001,2.248695e-002,1.202440e-002,4.733704e-005,4.733704e-005,,,,,,,,,,,,,,,,,,,,
1406843280.640,,1.500000e+001,2.980050e+002,2.979968e+002,1,0,2.814054e+000,3.082370e-001,3.082370e-001,-8.168649e-002,-8.935532e-002,2.915762e-001,-9.834727e-002,-1.060161e-001,3.358650e-005,3.358650e-005,,,,,,,,,,,,,,,,,,,,
1406843298.875,,1.500000e+001,2.979968e+002,2.979968e+002,1,0,6.855616e-003,5.185094e-001,5.185094e-001,1.209635e-001,1.182714e-001,5.410157e-001,1.434698e-001,1.407777e-001,5.649848e-005,5.649848e-005,,,,,,,,,,,,,,,,,,,,
1406843298.875,,1.500000e+001,2.979968e+002,2.979968e+002,1,0,2.903063e+000,3.500473e-001,3.500473e-001,-4.026349e-002,-5.019078e-002,3.397610e-001,-5.054979e-002,-6.047708e-002,3.814229e-005,3.814229e-005,,,,,,,,,,,,,,,,,,,,
1406843316.640,,1.500000e+001,2.979968e+002,2.980050e+002,1,0,2.982959e+000,4.020814e-001,4.020814e-001,1.051576e-002,4.053354e-003,3.821815e-001,-9.384148e-003,-1.584655e-002,4.381210e-005,4.381210e-005,,,,,,,,,,,,,,,,,,,,
1406843439.968,,2.000000e+001,2.979968e+002,2.980050e+002,1,0,2.659726e-002,5.075228e-001,5.075228e-001,1.203959e-001,1.176334e-001,5.310358e-001,1.439089e-001,1.411465e-001,5.530131e-005,5.530131e-005,,,,,,,,,,,,,,,,,,,,
1406843439.968,,2.000000e+001,2.979968e+002,2.980050e+002,1,0,2.751930e+000,2.533036e-001,2.533036e-001,-1.268359e-001,-1.365858e-001,2.504873e-001,-1.296523e-001,-1.394021e-001,2.760078e-005,2.760078e-005,,,,,,,,,,,,,,,,,,,,
1406843458.453,,2.000000e+001,2.979968e+002,2.980050e+002,1,0,3.145971e+000,4.794458e-001,4.794458e-001,8.797629e-002,8.228511e-002,4.576569e-001,6.618743e-002,6.049624e-002,5.224195e-005,5.224195e-005,,,,,,,,,,,,,,,,,,,,
1406843475.687,,2.000000e+001,2.979968e+002,2.979968e+002,1,0,7.149410e-002,5.214087e-001,5.214087e-001,1.303473e-001,1.279460e-001,5.427498e-001,1.516884e-001,1.492870e-001,5.681437e-005,5.681437e-005,,,,,,,,,,,,,,,,,,,,
1406843475.687,,2.000000e+001,2.979968e+002,2.979968e+002,1,0,2.593732e+000,1.629688e-001,1.629688e-001,-2.223560e-001,-2.304939e-001,1.678008e-001,-2.175241e-001,-2.256620e-001,1.775761e-005,1.775761e-005,,,,,,,,,,,,,,,,,,,,
1406843593.171,,2.500000e+001,2.979968e+002,2.980050e+002,1,0,3.301841e+000,5.224769e-001,5.224769e-001,1.421797e-001,1.374865e-001,5.021179e-001,1.218207e-001,1.171275e-001,5.693073e-005,5.693073e-005,,,,,,,,,,,,,,,,,,,,
1406843610.937,,2.500000e+001,2.980050e+002,2.979968e+002,1,0,1.384803e-001,5.149999e-001,5.149999e-001,1.402030e-001,1.381323e-001,5.321095e-001,1.573126e-001,1.552419e-001,5.611601e-005,5.611601e-005,,,,,,,,,,,,,,,,,,,,
1406843610.937,,2.500000e+001,2.980050e+002,2.979968e+002,1,0,2.428463e+000,6.164739e-002,6.164739e-002,-3.084631e-001,-3.152202e-001,7.349553e-002,-2.966150e-001,-3.033720e-001,6.717294e-006,6.717294e-006,,,,,,,,,,,,,,,,,,,,
1406843629.171,,2.500000e+001,2.979968e+002,2.979968e+002,1,0,3.448706e+000,5.510117e-001,5.510117e-001,1.725488e-001,1.677313e-001,5.383657e-001,1.599027e-001,1.550852e-001,6.003997e-005,6.003997e-005,,,,,,,,,,,,,,,,,,,,
1406843746.421,,3.000000e+001,2.979968e+002,2.980050e+002,1,0,2.241416e-001,4.893643e-001,4.893643e-001,1.422095e-001,1.408544e-001,5.020285e-001,1.548737e-001,1.535186e-001,5.332265e-005,5.332265e-005,,,,,,,,,,,,,,,,,,,,
1406843746.421,,3.000000e+001,2.979968e+002,2.980050e+002,1,0,2.256781e+000,-1.342814e-002,-1.342814e-002,-3.576694e-001,-3.619380e-001,3.059997e-003,-3.411812e-001,-3.454499e-001,-1.463172e-006,-1.463172e-006,,,,,,,,,,,,,,,,,,,,
1406843764.406,,3.000000e+001,2.979968e+002,2.979968e+002,1,0,3.584366e+000,5.162206e-001,5.162206e-001,1.681509e-001,1.656371e-001,5.103326e-001,1.622629e-001,1.597491e-001,5.624900e-005,5.624900e-005,,,,,,,,,,,,,,,,,,,,
1406843824.656,,3.000000e+001,2.980050e+002,2.980050e+002,1,0,3.246748e-001,4.974517e-001,4.974517e-001,1.535986e-001,1.527704e-001,5.033298e-001,1.594767e-001,1.586484e-001,5.420388e-005,5.420388e-005,,,,,,,,,,,,,,,,,,,,
1406843960.625,,3.500000e+001,2.979968e+002,2.980050e+002,1,0,2.080054e+000,-1.745659e-001,-1.745659e-001,-6.525178e-001,-6.525178e-001,-9.279866e-002,-5.707505e-001,-5.707505e-001,-3.804246e-006,-3.804246e-006,,,,,,,,,,,,,,,,,,,,
1406843960.625,,3.500000e+001,2.979968e+002,2.980050e+002,1,0,3.705983e+000,7.235939e-001,7.235938e-001,2.443957e-001,2.456419e-001,7.273290e-001,2.481309e-001,2.493771e-001,1.576900e-005,1.576900e-005,,,,,,,,,,,,,,,,,,,,
1406843978.359,,3.500000e+001,2.979968e+002,2.980050e+002,1,0,4.363974e-001,5.755791e-001,5.755791e-001,2.125646e-001,2.129591e-001,5.550240e-001,1.920096e-001,1.924040e-001,1.254337e-005,1.254337e-005,,,,,,,,,,,,,,,,,,,,
1406843996.156,,3.500000e+001,2.979968e+002,2.980050e+002,1,0,1.900353e+000,-1.066622e-001,-1.066622e-001,-3.261034e-001,-3.259926e-001,-3.126796e-002,-2.507092e-001,-2.505984e-001,-2.324448e-006,-2.324448e-006,,,,,,,,,,,,,,,,,,,,
1406843996.156,,3.500000e+001,2.979968e+002,2.980050e+002,1,0,3.810319e+000,3.234962e-001,3.234962e-001,9.928879e-002,1.041658e-001,3.765646e-001,1.523572e-001,1.572342e-001,7.049827e-006,7.049827e-006,,,,,,,,,,,,,,,,,,,,
1406844113.906,,4.000000e+001,2.979968e+002,2.980050e+002,1,0,5.566934e-001,-2.684408e+000,-2.684408e+000,-6.636835e-001,-6.341763e-001,-2.740048e+000,-7.193230e-001,-6.898158e-001,-5.850023e-005,-5.850023e-005,,,,,,,,,,,,,,,,,,,,
1406844131.640,,4.000000e+001,2.980050e+002,2.979968e+002,1,0,1.719542e+000,-3.318888e-001,-3.318888e-001,1.811522e+000,1.814231e+000,-2.786865e-001,1.864724e+000,1.867433e+000,-7.232720e-006,-7.232720e-006,,,,,,,,,,,,,,,,,,,,
1406844131.640,,4.000000e+001,2.980050e+002,2.979968e+002,1,0,3.894009e+000,-2.947020e+000,-2.947020e+000,-8.618531e-001,-8.009000e-001,-2.817673e+000,-7.325062e-001,-6.715531e-001,-6.422323e-005,-6.422323e-005,,,,,,,,,,,,,,,,,,,,
1406844149.875,,4.000000e+001,2.980050e+002,2.980050e+002,1,0,6.836286e-001,-2.721030e+000,-2.721030e+000,-5.326622e-001,-4.994783e-001,-2.790607e+000,-6.022387e-001,-5.690548e-001,-5.929833e-005,-5.929833e-005,,,,,,,,,,,,,,,,,,,,
1406844263.109,,4.500000e+001,2.979968e+002,2.979885e+002,1,0,1.539225e+000,-8.812220e-001,-8.812220e-001,1.705765e+000,1.710506e+000,-9.180657e-001,1.668921e+000,1.673662e+000,-1.920411e-005,-1.920411e-005,,,,,,,,,,,,,,,,,,,,
1406844263.109,,4.500000e+001,2.979968e+002,2.979885e+002,1,0,3.953949e+000,-3.546709e+000,-3.546709e+000,-1.027671e+000,-9.549809e-001,-3.366083e+000,-8.470451e-001,-7.743554e-001,-7.729197e-005,-7.729197e-005,,,,,,,,,,,,,,,,,,,,
1406844280.843,,4.500000e+001,2.979968e+002,2.980050e+002,1,0,8.161843e-001,-2.885983e+000,-2.885983e+000,-3.862237e-001,-3.444757e-001,-2.975657e+000,-4.758975e-001,-4.341495e-001,-6.289304e-005,-6.289304e-005,,,,,,,,,,,,,,,,,,,,
1406844299.625,,4.500000e+001,2.979968e+002,2.980050e+002,1,0,1.361734e+000,-1.338389e+000,-1.338389e+000,1.214170e+000,1.220934e+000,-1.443035e+000,1.109525e+000,1.116289e+000,-2.916697e-005,-2.916697e-005,,,,,,,,,,,,,,,,,,,,
1406844299.625,,4.500000e+001,2.979968e+002,2.980050e+002,1,0,3.987963e+000,-3.500015e+000,-3.500015e+000,-1.020174e+000,-9.406917e-001,-3.300282e+000,-8.204411e-001,-7.409587e-001,-7.627440e-005,-7.627440e-005,,,,,,,,,,,,,,,,,,,,
1406844416.875,,5.000000e+001,2.979968e+002,2.979968e+002,1,0,9.543557e-001,-2.748039e+000,-2.748039e+000,-4.640689e-002,-3.058195e-003,-2.869812e+000,-1.681794e-001,-1.248307e-001,-5.988686e-005,-5.988686e-005,,,,,,,,,,,,,,,,,,,,
1406844435.109,,5.000000e+001,2.979968e+002,2.980050e+002,1,0,1.187804e+000,-2.026582e+000,-2.026582e+000,6.924219e-001,7.017448e-001,-2.178618e+000,5.403852e-001,5.497081e-001,-4.416444e-005,-4.416444e-005,,,,,,,,,,,,,,,,,,,,
1406844435.109,,5.000000e+001,2.979968e+002,2.980050e+002,1,0,3.994872e+000,-3.727378e+000,-3.727378e+000,-1.088552e+000,-9.990518e-001,-3.509247e+000,-8.704212e-001,-7.809210e-001,-8.122919e-005,-8.122919e-005,,,,,,,,,,,,,,,,,,,,
1406844453.343,,5.000000e+001,2.979968e+002,2.979968e+002,1,0,1.098713e+000,-2.284158e+000,-2.284158e+000,3.952816e-001,4.468758e-001,-2.423255e+000,2.561844e-001,3.077786e-001,-4.977769e-005,-4.977769e-005,,,,,,,,,,,,,,,,,,,,
1406844588.312,,7.500000e+001,2.980050e+002,2.979968e+002,1,0,1.018861e+000,-1.390728e+000,-1.390728e+000,6.383566e-002,7.286942e-002,-1.488380e+000,-3.381630e-002,-2.478254e-002,-6.061499e-005,-6.061499e-005,,,,,,,,,,,,,,,,,,,,
1406844588.312,,7.500000e+001,2.980050e+002,2.979968e+002,1,0,3.975147e+000,-2.020936e+000,-2.020936e+000,-6.311136e-001,-5.573379e-001,-1.895355e+000,-5.055332e-001,-4.317575e-001,-8.808260e-005,-8.808260e-005,,,,,,,,,,,,,,,,,,,,
1406844605.546,,7.500000e+001,2.980050e+002,2.979968e+002,1,0,1.249817e+000,-9.668264e-001,-9.668264e-001,4.431904e-001,4.856327e-001,-1.047445e+000,3.625714e-001,4.050138e-001,-4.213919e-005,-4.213919e-005,,,,,,,,,,,,,,,,,,,,
1406844623.796,,7.500000e+001,2.980050e+002,2.980050e+002,1,0,8.558163e-001,-1.627094e+000,-1.627094e+000,-1.844036e-001,-1.739371e-001,-1.720032e+000,-2.773417e-001,-2.668751e-001,-7.091701e-005,-7.091701e-005,,,,,,,,,,,,,,,,,,,,
1406844623.796,,7.500000e+001,2.980050e+002,2.980050e+002,1,0,3.930348e+000,-2.020478e+000,-2.020478e+000,-6.420815e-001,-5.673207e-001,-1.909360e+000,-5.309639e-001,-4.562031e-001,-8.806265e-005,-8.806265e-005,,,,,,,,,,,,,,,,,,,,
1406844754.046,,1.000000e+002,2.979968e+002,2.979968e+002,1,0,1.408065e+000,-6.761376e-001,-6.761376e-001,7.325008e-001,7.847354e-001,-7.464164e-001,6.622219e-001,7.144566e-001,-2.946943e-005,-2.946943e-005,,,,,,,,,,,,,,,,,,,,
1406844771.796,,1.000000e+002,2.979968e+002,2.979968e+002,1,0,7.000062e-001,-1.828517e+000,-1.828516e+000,-3.784375e-001,-3.639001e-001,-1.927933e+000,-4.778541e-001,-4.633167e-001,-7.969583e-005,-7.969583e-005,,,,,,,,,,,,,,,,,,,,
1406844771.796,,1.000000e+002,2.979968e+002,2.979968e+002,1,0,3.863323e+000,-2.051759e+000,-2.051759e+000,-6.798192e-001,-5.871431e-001,-1.952012e+000,-5.800716e-001,-4.873954e-001,-8.942586e-005,-8.942586e-005,,,,,,,,,,,,,,,,,,,,
1406844789.531,,1.000000e+002,2.979968e+002,2.980050e+002,1,0,1.573367e+000,-4.071169e-001,-4.071169e-001,9.947925e-001,1.049570e+000,-4.261314e-001,9.757780e-001,1.030555e+000,-1.774418e-005,-1.774418e-005,,,,,,,,,,,,,,,,,,,,
1406844789.531,,1.000000e+002,2.979968e+002,2.980050e+002,1,0,2.256685e+000,-1.739555e-001,-1.739555e-001,1.167699e+000,1.282732e+000,-4.779141e-002,1.293863e+000,1.408896e+000,-7.581844e-006,-7.581844e-006,,,,,,,,,,,,,,,,,,,,