File: Sample Data Files/2014-07-31 EB on isolated PMN-PT no Ti spontaneous in situ repeat/Ni-NiO_298K_SiO2_PMN-PT_5.0Tprebias_200V_Au_back.rso.dat
[Header]
TITLE,MPMS RSO Measurement
BYAPP,MPMS Measurement,1.1,Summary
FILEOPENTIME, 1406898598.046000 8/1/2014, 6:09:58 AM

INFO, APPNAME, MPMS MultiVu Application, Revision 1.58,  Build 076

INFO, NAME, EB in situ 2
INFO, WEIGHT, 0.000
INFO, AREA, 0.000
INFO, LENGTH, 0.000
INFO, SHAPE, 0
INFO, COMMENT,
INFO, SEQUENCE FILE: MHcurveUpTo100.seq


INFO, BACKGROUND DATA FILE:, None


STARTUPAXIS,X,4,LINEAR,AUTO,0.000000,0.000000
STARTUPAXIS,Y1,5,LINEAR,AUTO,0.000000,0.000000


STARTUPGROUP,Longitudinal
FIELDGROUP,Longitudinal,1,2,3,4,5,6,7,8,9,10,11,19,20,21,22,23,35
FIELDGROUP,Transverse,1,2,3,4,12,13,14,15,16,17,18,24,25,26,27,28,35

PLOT_APPEARANCE,ALL,HORZ_GRID_ON,VERT_GRID_ON,MARKERS_AND_LINES

[Data]
Time,Comment,Field (Oe),Temperature (K),Long Moment (emu),Long Scan Std Dev,Long Offset (cm),Long Offset Std Dev,Long Algorithm,Long Reg Fit,Long Reg Factor,Trans Moment (emu),Trans Scan Std Dev,Trans Offset (cm),Trans Offset Std Dev,Trans Algorithm,Trans Reg Fit,Trans Reg Factor,Long Moment [w/o ABS] (emu),Long Scan Std Dev [w/o ABS],Long Offset [w/o ABS] (cm),Long Offset Std Dev [w/o ABS],Long Reg Fit [w/o ABS],Trans Moment [w/o ABS] (emu),Trans Scan Std Dev [w/o ABS],Trans Offset [w/o ABS] (cm),Trans Offset Std Dev [w/o ABS],Trans Reg Fit [w/o ABS],RSO Position (deg),Amplitude (cm),Frequency,Cycles to Average,Scans per Measurement,Delta Temp (K),Error,EC Comp. Running,Using ABS,
1406898598.046,,1.000000e+002,2.980009e+002,1.092870e-005,0.000000e+000,3.828438e-002,0.000000e+000,3,6.462886e-001,1.825000e+000,,,,,,,,,,,,,,,,,,0,4.000000e+000,5.000000e-001,5,1,8.209229e-003,0,,0,
1406898616.531,,1.000000e+002,2.980009e+002,1.093280e-005,0.000000e+000,3.736156e-002,0.000000e+000,3,6.466529e-001,1.825000e+000,,,,,,,,,,,,,,,,,,0,4.000000e+000,5.000000e-001,5,1,8.209229e-003,0,,0,
1406898634.265,,1.000000e+002,2.980009e+002,1.094041e-005,0.000000e+000,3.814706e-002,0.000000e+000,3,6.465639e-001,1.825000e+000,,,,,,,,,,,,,,,,,,0,4.000000e+000,5.000000e-001,5,1,8.209229e-003,0,,0,
1406898756.796,,7.500000e+001,2.980009e+002,9.444650e-006,0.000000e+000,4.714974e-002,0.000000e+000,3,6.279823e-001,1.825000e+000,,,,,,,,,,,,,,,,,,0,4.000000e+000,5.000000e-001,5,1,8.209229e-003,0,,0,
1406898774.781,,7.500000e+001,2.979968e+002,9.449786e-006,0.000000e+000,4.722274e-002,0.000000e+000,3,6.279458e-001,1.825000e+000,,,,,,,,,,,,,,,,,,0,4.000000e+000,5.000000e-001,5,1,0.000000e+000,0,,0,
1406898792.781,,7.500000e+001,2.979968e+002,9.454959e-006,0.000000e+000,4.641036e-002,0.000000e+000,3,6.289838e-001,1.825000e+000,,,,,,,,,,,,,,,,,,0,4.000000e+000,5.000000e-001,5,1,0.000000e+000,0,,0,
1406898922.781,,5.000000e+001,2.979968e+002,7.797857e-006,0.000000e+000,6.412744e-002,0.000000e+000,3,6.005283e-001,1.825000e+000,,,,,,,,,,,,,,,,,,0,4.000000e+000,5.000000e-001,5,1,0.000000e+000,0,,0,
1406898940.015,,5.000000e+001,2.980009e+002,7.792989e-006,0.000000e+000,6.341996e-002,0.000000e+000,3,6.002604e-001,1.825000e+000,,,,,,,,,,,,,,,,,,0,4.000000e+000,5.000000e-001,5,1,8.209229e-003,0,,0,
1406898958.250,,5.000000e+001,2.980009e+002,7.782925e-006,0.000000e+000,6.318083e-002,0.000000e+000,3,5.989570e-001,1.825000e+000,,,,,,,,,,,,,,,,,,0,4.000000e+000,5.000000e-001,5,1,8.209229e-003,0,,0,
1406899070.312,,4.500000e+001,2.980050e+002,7.452943e-006,0.000000e+000,6.693949e-002,0.000000e+000,3,5.927137e-001,1.825000e+000,,,,,,,,,,,,,,,,,,0,4.000000e+000,5.000000e-001,5,1,0.000000e+000,0,,0,
1406899088.562,,4.500000e+001,2.980009e+002,7.450091e-006,0.000000e+000,6.715207e-002,0.000000e+000,3,5.926423e-001,1.825000e+000,,,,,,,,,,,,,,,,,,0,4.000000e+000,5.000000e-001,5,1,8.209229e-003,0,,0,
1406899106.812,,4.500000e+001,2.979968e+002,7.442570e-006,0.000000e+000,6.738394e-002,0.000000e+000,3,5.921011e-001,1.825000e+000,,,,,,,,,,,,,,,,,,0,4.000000e+000,5.000000e-001,5,1,1.651001e-002,0,,0,
1406899223.796,,4.000000e+001,2.980009e+002,7.096438e-006,0.000000e+000,7.099910e-002,0.000000e+000,3,5.841209e-001,1.825000e+000,,,,,,,,,,,,,,,,,,0,4.000000e+000,5.000000e-001,5,1,8.209229e-003,0,,0,
1406899241.031,,4.000000e+001,2.979968e+002,7.092248e-006,0.000000e+000,7.251863e-002,0.000000e+000,3,5.845592e-001,1.825000e+000,,,,,,,,,,,,,,,,,,0,4.000000e+000,5.000000e-001,5,1,0.000000e+000,0,,0,
1406899258.828,,4.000000e+001,2.980009e+002,7.094377e-006,0.000000e+000,7.281737e-002,0.000000e+000,3,5.837131e-001,1.825000e+000,,,,,,,,,,,,,,,,,,0,4.000000e+000,5.000000e-001,5,1,8.209229e-003,0,,0,
1406899376.843,,3.500000e+001,2.980050e+002,6.728728e-006,0.000000e+000,7.795975e-002,0.000000e+000,3,5.757560e-001,1.825000e+000,,,,,,,,,,,,,,,,,,0,4.000000e+000,5.000000e-001,5,1,0.000000e+000,0,,0,
1406899395.093,,3.500000e+001,2.979968e+002,6.722476e-006,0.000000e+000,7.598656e-002,0.000000e+000,3,5.743562e-001,1.825000e+000,,,,,,,,,,,,,,,,,,0,4.000000e+000,5.000000e-001,5,1,0.000000e+000,0,,0,
1406899412.875,,3.500000e+001,2.980009e+002,6.714627e-006,0.000000e+000,7.808486e-002,0.000000e+000,3,5.742926e-001,1.825000e+000,,,,,,,,,,,,,,,,,,0,4.000000e+000,5.000000e-001,5,1,8.209229e-003,0,,0,
1406899529.359,,3.000000e+001,2.979968e+002,6.368565e-006,0.000000e+000,8.181424e-002,0.000000e+000,3,5.646082e-001,1.825000e+000,,,,,,,,,,,,,,,,,,0,4.000000e+000,5.000000e-001,5,1,0.000000e+000,0,,0,
1406899547.593,,3.000000e+001,2.979968e+002,6.365523e-006,0.000000e+000,8.296635e-002,0.000000e+000,3,5.648617e-001,1.825000e+000,,,,,,,,,,,,,,,,,,0,4.000000e+000,5.000000e-001,5,1,0.000000e+000,0,,0,
1406899565.875,,3.000000e+001,2.980009e+002,6.359290e-006,0.000000e+000,8.270316e-002,0.000000e+000,3,5.645261e-001,1.825000e+000,,,,,,,,,,,,,,,,,,0,4.000000e+000,5.000000e-001,5,1,8.209229e-003,0,,0,
1406899683.109,,2.500000e+001,2.979968e+002,5.967411e-006,0.000000e+000,8.775105e-002,0.000000e+000,3,5.511830e-001,1.825000e+000,,,,,,,,,,,,,,,,,,0,4.000000e+000,5.000000e-001,5,1,0.000000e+000,0,,0,
1406899700.343,,2.500000e+001,2.980009e+002,5.986918e-006,0.000000e+000,8.799221e-002,0.000000e+000,3,5.540200e-001,1.825000e+000,,,,,,,,,,,,,,,,,,0,4.000000e+000,5.000000e-001,5,1,8.209229e-003,0,,0,
1406899718.578,,2.500000e+001,2.979968e+002,5.979873e-006,0.000000e+000,8.978956e-002,0.000000e+000,3,5.535159e-001,1.825000e+000,,,,,,,,,,,,,,,,,,0,4.000000e+000,5.000000e-001,5,1,0.000000e+000,0,,0,
1406899835.312,,2.000000e+001,2.979968e+002,5.588735e-006,0.000000e+000,9.920949e-002,0.000000e+000,3,5.384766e-001,1.825000e+000,,,,,,,,,,,,,,,,,,0,4.000000e+000,5.000000e-001,5,1,0.000000e+000,0,,0,
1406899853.046,,2.000000e+001,2.980009e+002,5.576967e-006,0.000000e+000,9.634096e-002,0.000000e+000,3,5.379889e-001,1.825000e+000,,,,,,,,,,,,,,,,,,0,4.000000e+000,5.000000e-001,5,1,8.209229e-003,0,,0,
1406899871.546,,2.000000e+001,2.980009e+002,5.567247e-006,0.000000e+000,9.589662e-002,0.000000e+000,3,5.367147e-001,1.825000e+000,,,,,,,,,,,,,,,,,,0,4.000000e+000,5.000000e-001,5,1,8.209229e-003,0,,0,
1406899982.031,,1.500000e+001,2.980009e+002,5.167871e-006,0.000000e+000,1.016542e-001,0.000000e+000,3,5.201252e-001,1.825000e+000,,,,,,,,,,,,,,,,,,0,4.000000e+000,5.000000e-001,5,1,8.209229e-003,0,,0,
1406899999.765,,1.500000e+001,2.980009e+002,5.169032e-006,0.000000e+000,1.022307e-001,0.000000e+000,3,5.212726e-001,1.825000e+000,,,,,,,,,,,,,,,,,,0,4.000000e+000,5.000000e-001,5,1,8.209229e-003,0,,0,
1406900017.531,,1.500000e+001,2.979968e+002,5.151505e-006,0.000000e+000,1.005255e-001,0.000000e+000,3,5.201826e-001,1.825000e+000,,,,,,,,,,,,,,,,,,0,4.000000e+000,5.000000e-001,5,1,0.000000e+000,0,,0,
1406900135.765,,1.000000e+001,2.980009e+002,4.745144e-006,0.000000e+000,1.126917e-001,0.000000e+000,3,4.997727e-001,1.825000e+000,,,,,,,,,,,,,,,,,,0,4.000000e+000,5.000000e-001,5,1,8.209229e-003,0,,0,
1406900154.515,,1.000000e+001,2.979926e+002,4.742941e-006,0.000000e+000,1.133142e-001,0.000000e+000,3,4.995722e-001,1.825000e+000,,,,,,,,,,,,,,,,,,0,4.000000e+000,5.000000e-001,5,1,8.300781e-003,0,,0,
1406900172.781,,1.000000e+001,2.979926e+002,4.740978e-006,0.000000e+000,1.152436e-001,0.000000e+000,3,4.992164e-001,1.825000e+000,,,,,,,,,,,,,,,,,,0,4.000000e+000,5.000000e-001,5,1,8.300781e-003,0,,0,
1406900290.765,,5.000000e+000,2.979968e+002,4.302609e-006,0.000000e+000,1.194295e-001,0.000000e+000,3,4.741805e-001,1.825000e+000,,,,,,,,,,,,,,,,,,0,4.000000e+000,5.000000e-001,5,1,0.000000e+000,0,,0,
1406900308.500,,5.000000e+000,2.980009e+002,4.299952e-006,0.000000e+000,1.180006e-001,0.000000e+000,3,4.753950e-001,1.825000e+000,,,,,,,,,,,,,,,,,,0,4.000000e+000,5.000000e-001,5,1,8.209229e-003,0,,0,
1406900326.234,,5.000000e+000,2.980009e+002,4.286039e-006,0.000000e+000,1.202418e-001,0.000000e+000,3,4.718874e-001,1.825000e+000,,,,,,,,,,,,,,,,,,0,4.000000e+000,5.000000e-001,5,1,8.209229e-003,0,,0,
1406900444.468,,0.000000e+000,2.980009e+002,3.817511e-006,0.000000e+000,1.199619e-001,0.000000e+000,3,4.399034e-001,1.825000e+000,,,,,,,,,,,,,,,,,,0,4.000000e+000,5.000000e-001,5,1,8.209229e-003,0,,0,
1406900462.796,,0.000000e+000,2.979968e+002,3.819914e-006,0.000000e+000,1.176620e-001,0.000000e+000,3,4.393810e-001,1.825000e+000,,,,,,,,,,,,,,,,,,0,4.000000e+000,5.000000e-001,5,1,0.000000e+000,0,,0,
1406900481.546,,0.000000e+000,2.979926e+002,3.811718e-006,0.000000e+000,1.222014e-001,0.000000e+000,3,4.382199e-001,1.825000e+000,,,,,,,,,,,,,,,,,,0,4.000000e+000,5.000000e-001,5,1,8.300781e-003,0,,0,
1406900598.781,,-5.000000e+000,2.980050e+002,3.303056e-006,0.000000e+000,1.022249e-001,0.000000e+000,3,3.900028e-001,1.825000e+000,,,,,,,,,,,,,,,,,,0,4.000000e+000,5.000000e-001,5,1,0.000000e+000,0,,0,
1406900616.515,,-5.000000e+000,2.979968e+002,3.300504e-006,0.000000e+000,9.780529e-002,0.000000e+000,3,3.879260e-001,1.825000e+000,,,,,,,,,,,,,,,,,,0,4.000000e+000,5.000000e-001,5,1,0.000000e+000,0,,0,
1406900634.750,,-5.000000e+000,2.980009e+002,3.293497e-006,0.000000e+000,1.019220e-001,0.000000e+000,3,3.902884e-001,1.825000e+000,,,,,,,,,,,,,,,,,,0,4.000000e+000,5.000000e-001,5,1,8.209229e-003,0,,0,
1406900758.734,,-1.000000e+001,2.979968e+002,2.764442e-006,0.000000e+000,3.980979e-002,0.000000e+000,3,3.234950e-001,1.825000e+000,,,,,,,,,,,,,,,,,,0,4.000000e+000,5.000000e-001,5,1,0.000000e+000,0,,0,
1406900777.015,,-1.000000e+001,2.980009e+002,2.763848e-006,0.000000e+000,3.983647e-002,0.000000e+000,3,3.215787e-001,1.825000e+000,,,,,,,,,,,,,,,,,,0,4.000000e+000,5.000000e-001,5,1,8.209229e-003,0,,0,
1406900795.250,,-1.000000e+001,2.979968e+002,2.757270e-006,0.000000e+000,4.953807e-002,0.000000e+000,3,3.184400e-001,1.825000e+000,,,,,,,,,,,,,,,,,,0,4.000000e+000,5.000000e-001,5,1,0.000000e+000,0,,0,
1406900913.296,,-1.500000e+001,2.980009e+002,2.280516e-006,0.000000e+000,-8.171777e-002,0.000000e+000,3,2.236112e-001,1.825000e+000,,,,,,,,,,,,,,,,,,0,4.000000e+000,5.000000e-001,5,1,8.209229e-003,0,,0,
1406900931.281,,-1.500000e+001,2.980009e+002,2.267103e-006,0.000000e+000,-7.871124e-002,0.000000e+000,3,2.180268e-001,1.825000e+000,,,,,,,,,,,,,,,,,,0,4.000000e+000,5.000000e-001,5,1,8.209229e-003,0,,0,
1406900949.515,,-1.500000e+001,2.980009e+002,2.264620e-006,0.000000e+000,-7.655139e-002,0.000000e+000,3,2.208124e-001,1.825000e+000,,,,,,,,,,,,,,,,,,0,4.000000e+000,5.000000e-001,5,1,8.209229e-003,0,,0,
1406901066.515,,-2.000000e+001,2.980009e+002,1.794670e-006,0.000000e+000,-5.937800e-001,0.000000e+000,3,9.280128e-003,1.825000e+000,,,,,,,,,,,,,,,,,,0,4.000000e+000,5.000000e-001,5,1,8.209229e-003,0,,0,
1406901084.750,,-2.000000e+001,2.980050e+002,1.786736e-006,0.000000e+000,-5.984831e-001,0.000000e+000,3,1.093102e-002,1.825000e+000,,,,,,,,,,,,,,,,,,0,4.000000e+000,5.000000e-001,5,1,0.000000e+000,0,,0,
1406901101.984,,-2.000000e+001,2.979968e+002,1.785916e-006,0.000000e+000,-6.017982e-001,0.000000e+000,3,4.417648e-003,1.825000e+000,,,,,,,,,,,,,,,,,,0,4.000000e+000,5.000000e-001,5,1,0.000000e+000,0,,0,
1406901219.218,,-2.500000e+001,2.980009e+002,1.404622e-006,0.000000e+000,-8.184199e-001,0.000000e+000,3,0.000000e+000,1.825000e+000,,,,,,,,,,,,,,,,,,0,4.000000e+000,5.000000e-001,5,1,8.209229e-003,0,,0,
1406901236.953,,-2.500000e+001,2.980009e+002,1.419758e-006,0.000000e+000,-8.175943e-001,0.000000e+000,3,0.000000e+000,1.825000e+000,,,,,,,,,,,,,,,,,,0,4.000000e+000,5.000000e-001,5,1,8.209229e-003,0,,0,
1406901254.734,,-2.500000e+001,2.979968e+002,1.414072e-006,0.000000e+000,-8.189785e-001,0.000000e+000,3,0.000000e+000,1.825000e+000,,,,,,,,,,,,,,,,,,0,4.000000e+000,5.000000e-001,5,1,0.000000e+000,0,,0,
1406901371.484,,-3.000000e+001,2.979968e+002,1.352709e-006,0.000000e+000,-8.874718e-001,0.000000e+000,3,1.100554e-001,1.825000e+000,,,,,,,,,,,,,,,,,,0,4.000000e+000,5.000000e-001,5,1,0.000000e+000,0,,0,
1406901389.218,,-3.000000e+001,2.980009e+002,1.353865e-006,0.000000e+000,-8.917868e-001,0.000000e+000,3,1.082977e-001,1.825000e+000,,,,,,,,,,,,,,,,,,0,4.000000e+000,5.000000e-001,5,1,8.209229e-003,0,,0,
1406901407.453,,-3.000000e+001,2.979968e+002,6.239473e-007,0.000000e+000,0.000000e+000,0.000000e+000,3,0.000000e+000,1.825000e+000,,,,,,,,,,,,,,,,,,0,4.000000e+000,5.000000e-001,5,1,0.000000e+000,0,,0,
1406901525.453,,-3.500000e+001,2.980009e+002,2.768295e-007,0.000000e+000,1.166071e+000,0.000000e+000,3,0.000000e+000,1.825000e+000,,,,,,,,,,,,,,,,,,0,4.000000e+000,5.000000e-001,5,1,8.209229e-003,0,,0,
1406901542.687,,-3.500000e+001,2.979968e+002,2.812750e-007,0.000000e+000,1.166118e+000,0.000000e+000,3,0.000000e+000,1.825000e+000,,,,,,,,,,,,,,,,,,0,4.000000e+000,5.000000e-001,5,1,0.000000e+000,0,,0,
1406901561.437,,-3.500000e+001,2.980009e+002,2.768577e-007,0.000000e+000,1.166619e+000,0.000000e+000,3,0.000000e+000,1.825000e+000,,,,,,,,,,,,,,,,,,0,4.000000e+000,5.000000e-001,5,1,8.209229e-003,0,,0,
1406901678.187,,-4.000000e+001,2.980009e+002,3.962933e-007,0.000000e+000,1.191628e+000,0.000000e+000,3,0.000000e+000,1.825000e+000,,,,,,,,,,,,,,,,,,0,4.000000e+000,5.000000e-001,5,1,8.209229e-003,0,,0,
1406901696.421,,-4.000000e+001,2.980050e+002,4.098584e-007,0.000000e+000,1.190600e+000,0.000000e+000,3,0.000000e+000,1.825000e+000,,,,,,,,,,,,,,,,,,0,4.000000e+000,5.000000e-001,5,1,0.000000e+000,0,,0,
1406901714.671,,-4.000000e+001,2.980009e+002,3.973207e-007,0.000000e+000,1.188902e+000,0.000000e+000,3,0.000000e+000,1.825000e+000,,,,,,,,,,,,,,,,,,0,4.000000e+000,5.000000e-001,5,1,8.209229e-003,0,,0,
1406901832.406,,-4.500000e+001,2.980009e+002,-9.455760e-007,0.000000e+000,4.542780e-001,0.000000e+000,3,0.000000e+000,1.825000e+000,,,,,,,,,,,,,,,,,,0,4.000000e+000,5.000000e-001,5,1,8.209229e-003,0,,0,
1406901850.640,,-4.500000e+001,2.980050e+002,-9.628097e-007,0.000000e+000,4.506038e-001,0.000000e+000,3,0.000000e+000,1.825000e+000,,,,,,,,,,,,,,,,,,0,4.000000e+000,5.000000e-001,5,1,0.000000e+000,0,,0,
1406901869.125,,-4.500000e+001,2.980009e+002,-9.716553e-007,0.000000e+000,4.330765e-001,0.000000e+000,3,0.000000e+000,1.825000e+000,,,,,,,,,,,,,,,,,,0,4.000000e+000,5.000000e-001,5,1,8.209229e-003,0,,0,
1406901988.656,,-5.000000e+001,2.980009e+002,-1.468152e-006,0.000000e+000,2.484526e-001,0.000000e+000,3,3.764328e-001,1.825000e+000,,,,,,,,,,,,,,,,,,0,4.000000e+000,5.000000e-001,5,1,8.209229e-003,0,,0,
1406902007.140,,-5.000000e+001,2.980009e+002,-1.468242e-006,0.000000e+000,2.561975e-001,0.000000e+000,3,3.764279e-001,1.825000e+000,,,,,,,,,,,,,,,,,,0,4.000000e+000,5.000000e-001,5,1,8.209229e-003,0,,0,
1406902025.375,,-5.000000e+001,2.979968e+002,-1.470183e-006,0.000000e+000,2.510481e-001,0.000000e+000,3,3.770619e-001,1.825000e+000,,,,,,,,,,,,,,,,,,0,4.000000e+000,5.000000e-001,5,1,0.000000e+000,0,,0,
1406902148.609,,-7.500000e+001,2.979968e+002,-3.641443e-006,0.000000e+000,1.528577e-001,0.000000e+000,3,8.579078e-001,1.825000e+000,,,,,,,,,,,,,,,,,,0,4.000000e+000,5.000000e-001,5,1,0.000000e+000,0,,0,
1406902166.843,,-7.500000e+001,2.979968e+002,-3.656996e-006,0.000000e+000,1.524737e-001,0.000000e+000,3,8.567945e-001,1.825000e+000,,,,,,,,,,,,,,,,,,0,4.000000e+000,5.000000e-001,5,1,0.000000e+000,0,,0,
1406902185.078,,-7.500000e+001,2.979968e+002,-3.658687e-006,0.000000e+000,1.511753e-001,0.000000e+000,3,8.585932e-001,1.825000e+000,,,,,,,,,,,,,,,,,,0,4.000000e+000,5.000000e-001,5,1,0.000000e+000,0,,0,
1406902340.937,,-1.000000e+002,2.980009e+002,-5.716041e-006,0.000000e+000,1.140392e-001,0.000000e+000,3,9.258879e-001,1.825000e+000,,,,,,,,,,,,,,,,,,0,4.000000e+000,5.000000e-001,5,1,8.209229e-003,0,,0,
1406902357.687,,-1.000000e+002,2.980009e+002,-5.767684e-006,0.000000e+000,1.131484e-001,0.000000e+000,3,9.251091e-001,1.825000e+000,,,,,,,,,,,,,,,,,,0,4.000000e+000,5.000000e-001,5,1,8.209229e-003,0,,0,
1406902375.921,,-1.000000e+002,2.980009e+002,-5.745933e-006,0.000000e+000,1.169900e-001,0.000000e+000,3,9.115164e-001,1.825000e+000,,,,,,,,,,,,,,,,,,0,4.000000e+000,5.000000e-001,5,1,8.209229e-003,0,,0,
1406902523.656,,-7.500000e+001,2.980009e+002,-4.264137e-006,0.000000e+000,1.488055e-001,0.000000e+000,3,8.928298e-001,1.825000e+000,,,,,,,,,,,,,,,,,,0,4.000000e+000,5.000000e-001,5,1,8.209229e-003,0,,0,
1406902540.890,,-7.500000e+001,2.980009e+002,-4.274767e-006,0.000000e+000,1.495615e-001,0.000000e+000,3,8.927407e-001,1.825000e+000,,,,,,,,,,,,,,,,,,0,4.000000e+000,5.000000e-001,5,1,8.209229e-003,0,,0,
1406902559.156,,-7.500000e+001,2.980009e+002,-4.274551e-006,0.000000e+000,1.504173e-001,0.000000e+000,3,8.890945e-001,1.825000e+000,,,,,,,,,,,,,,,,,,0,4.000000e+000,5.000000e-001,5,1,8.209229e-003,0,,0,
1406902683.921,,-5.000000e+001,2.980009e+002,-2.687595e-006,0.000000e+000,2.268263e-001,0.000000e+000,3,7.351150e-001,1.825000e+000,,,,,,,,,,,,,,,,,,0,4.000000e+000,5.000000e-001,5,1,8.209229e-003,0,,0,
1406902701.687,,-5.000000e+001,2.979926e+002,-2.693289e-006,0.000000e+000,2.262456e-001,0.000000e+000,3,7.387644e-001,1.825000e+000,,,,,,,,,,,,,,,,,,0,4.000000e+000,5.000000e-001,5,1,8.300781e-003,0,,0,
1406902719.921,,-5.000000e+001,2.979968e+002,-2.682149e-006,0.000000e+000,2.259455e-001,0.000000e+000,3,7.333438e-001,1.825000e+000,,,,,,,,,,,,,,,,,,0,4.000000e+000,5.000000e-001,5,1,0.000000e+000,0,,0,
1406902836.703,,-4.500000e+001,2.979968e+002,-2.357716e-006,0.000000e+000,2.554330e-001,0.000000e+000,3,6.717482e-001,1.825000e+000,,,,,,,,,,,,,,,,,,0,4.000000e+000,5.000000e-001,5,1,0.000000e+000,0,,0,
1406902854.437,,-4.500000e+001,2.980050e+002,-2.370586e-006,0.000000e+000,2.522915e-001,0.000000e+000,3,6.699103e-001,1.825000e+000,,,,,,,,,,,,,,,,,,0,4.000000e+000,5.000000e-001,5,1,0.000000e+000,0,,0,
1406902872.687,,-4.500000e+001,2.979968e+002,-2.365838e-006,0.000000e+000,2.511752e-001,0.000000e+000,3,6.740974e-001,1.825000e+000,,,,,,,,,,,,,,,,,,0,4.000000e+000,5.000000e-001,5,1,0.000000e+000,0,,0,
1406902991.671,,-4.000000e+001,2.979968e+002,-2.055749e-006,0.000000e+000,2.925030e-001,0.000000e+000,3,5.847176e-001,1.825000e+000,,,,,,,,,,,,,,,,,,0,4.000000e+000,5.000000e-001,5,1,0.000000e+000,0,,0,
1406903009.406,,-4.000000e+001,2.980009e+002,-2.049156e-006,0.000000e+000,2.965085e-001,0.000000e+000,3,5.793737e-001,1.825000e+000,,,,,,,,,,,,,,,,,,0,4.000000e+000,5.000000e-001,5,1,8.209229e-003,0,,0,
1406903027.140,,-4.000000e+001,2.979926e+002,-2.047666e-006,0.000000e+000,2.948835e-001,0.000000e+000,3,5.840365e-001,1.825000e+000,,,,,,,,,,,,,,,,,,0,4.000000e+000,5.000000e-001,5,1,8.300781e-003,0,,0,
1406903144.625,,-3.500000e+001,2.980050e+002,-1.734275e-006,0.000000e+000,3.658478e-001,0.000000e+000,3,4.593977e-001,1.825000e+000,,,,,,,,,,,,,,,,,,0,4.000000e+000,5.000000e-001,5,1,0.000000e+000,0,,0,
1406903162.375,,-3.500000e+001,2.980009e+002,-1.736670e-006,0.000000e+000,3.629860e-001,0.000000e+000,3,4.512963e-001,1.825000e+000,,,,,,,,,,,,,,,,,,0,4.000000e+000,5.000000e-001,5,1,8.209229e-003,0,,0,
1406903180.656,,-3.500000e+001,2.979968e+002,-1.731822e-006,0.000000e+000,3.624981e-001,0.000000e+000,3,4.542415e-001,1.825000e+000,,,,,,,,,,,,,,,,,,0,4.000000e+000,5.000000e-001,5,1,0.000000e+000,0,,0,
1406903304.437,,-3.000000e+001,2.980009e+002,-1.439090e-006,0.000000e+000,5.118415e-001,0.000000e+000,3,2.613964e-001,1.825000e+000,,,,,,,,,,,,,,,,,,0,4.000000e+000,5.000000e-001,5,1,8.209229e-003,0,,0,
1406903323.171,,-3.000000e+001,2.980009e+002,-1.433867e-006,0.000000e+000,5.086128e-001,0.000000e+000,3,2.571838e-001,1.825000e+000,,,,,,,,,,,,,,,,,,0,4.000000e+000,5.000000e-001,5,1,8.209229e-003,0,,0,
1406903340.906,,-3.000000e+001,2.979968e+002,-1.442575e-006,0.000000e+000,4.985088e-001,0.000000e+000,3,2.669994e-001,1.825000e+000,,,,,,,,,,,,,,,,,,0,4.000000e+000,5.000000e-001,5,1,0.000000e+000,0,,0,
1406903458.671,,-2.500000e+001,2.979968e+002,-1.005054e-006,0.000000e+000,8.264892e-001,0.000000e+000,3,0.000000e+000,1.825000e+000,,,,,,,,,,,,,,,,,,0,4.000000e+000,5.000000e-001,5,1,0.000000e+000,0,,0,
1406903476.437,,-2.500000e+001,2.979926e+002,-1.018866e-006,0.000000e+000,8.270086e-001,0.000000e+000,3,0.000000e+000,1.825000e+000,,,,,,,,,,,,,,,,,,0,4.000000e+000,5.000000e-001,5,1,8.300781e-003,0,,0,
1406903494.671,,-2.500000e+001,2.979968e+002,-1.012691e-006,0.000000e+000,8.284784e-001,0.000000e+000,3,0.000000e+000,1.825000e+000,,,,,,,,,,,,,,,,,,0,4.000000e+000,5.000000e-001,5,1,0.000000e+000,0,,0,
1406903612.906,,-2.000000e+001,2.979968e+002,-2.498990e-007,0.000000e+000,1.117595e+000,0.000000e+000,3,0.000000e+000,1.825000e+000,,,,,,,,,,,,,,,,,,0,4.000000e+000,5.000000e-001,5,1,0.000000e+000,0,,0,
1406903630.156,,-2.000000e+001,2.979968e+002,-2.535436e-007,0.000000e+000,1.121358e+000,0.000000e+000,3,0.000000e+000,1.825000e+000,,,,,,,,,,,,,,,,,,0,4.000000e+000,5.000000e-001,5,1,0.000000e+000,0,,0,
1406903648.390,,-2.000000e+001,2.979968e+002,-2.287718e-007,0.000000e+000,1.124042e+000,0.000000e+000,3,0.000000e+000,1.825000e+000,,,,,,,,,,,,,,,,,,0,4.000000e+000,5.000000e-001,5,1,0.000000e+000,0,,0,
1406903764.640,,-1.500000e+001,2.980009e+002,4.618696e-009,0.000000e+000,0.000000e+000,0.000000e+000,3,0.000000e+000,1.825000e+000,,,,,,,,,,,,,,,,,,0,4.000000e+000,5.000000e-001,5,1,8.209229e-003,0,,0,
1406903782.875,,-1.500000e+001,2.980009e+002,7.734853e-009,0.000000e+000,0.000000e+000,0.000000e+000,3,0.000000e+000,1.825000e+000,,,,,,,,,,,,,,,,,,0,4.000000e+000,5.000000e-001,5,1,8.209229e-003,0,,0,
1406903800.609,,-1.500000e+001,2.979968e+002,-5.336556e-009,0.000000e+000,0.000000e+000,0.000000e+000,3,0.000000e+000,1.825000e+000,,,,,,,,,,,,,,,,,,0,4.000000e+000,5.000000e-001,5,1,0.000000e+000,0,,0,
1406903917.843,,-1.000000e+001,2.980009e+002,3.781626e-007,0.000000e+000,0.000000e+000,0.000000e+000,3,0.000000e+000,1.825000e+000,,,,,,,,,,,,,,,,,,0,4.000000e+000,5.000000e-001,5,1,8.209229e-003,0,,0,
1406903935.078,,-1.000000e+001,2.980009e+002,3.810682e-007,0.000000e+000,0.000000e+000,0.000000e+000,3,0.000000e+000,1.825000e+000,,,,,,,,,,,,,,,,,,0,4.000000e+000,5.000000e-001,5,1,8.209229e-003,0,,0,
1406903953.312,,-1.000000e+001,2.979968e+002,3.836082e-007,0.000000e+000,0.000000e+000,0.000000e+000,3,0.000000e+000,1.825000e+000,,,,,,,,,,,,,,,,,,0,4.000000e+000,5.000000e-001,5,1,0.000000e+000,0,,0,
1406904069.593,,-5.000000e+000,2.980050e+002,2.137754e-006,0.000000e+000,-8.030191e-001,0.000000e+000,3,5.228305e-001,1.825000e+000,,,,,,,,,,,,,,,,,,0,4.000000e+000,5.000000e-001,5,1,1.641846e-002,0,,0,
1406904087.328,,-5.000000e+000,2.979968e+002,2.161713e-006,0.000000e+000,-8.005424e-001,0.000000e+000,3,5.325117e-001,1.825000e+000,,,,,,,,,,,,,,,,,,0,4.000000e+000,5.000000e-001,5,1,0.000000e+000,0,,0,
1406904105.593,,-5.000000e+000,2.980009e+002,2.148173e-006,0.000000e+000,-8.041297e-001,0.000000e+000,3,5.265549e-001,1.825000e+000,,,,,,,,,,,,,,,,,,0,4.000000e+000,5.000000e-001,5,1,8.209229e-003,0,,0,
1406904223.328,,0.000000e+000,2.980050e+002,2.310366e-006,0.000000e+000,-7.250021e-001,0.000000e+000,3,4.954948e-001,1.825000e+000,,,,,,,,,,,,,,,,,,0,4.000000e+000,5.000000e-001,5,1,0.000000e+000,0,,0,
1406904241.593,,0.000000e+000,2.979968e+002,2.307107e-006,0.000000e+000,-7.249448e-001,0.000000e+000,3,4.909743e-001,1.825000e+000,,,,,,,,,,,,,,,,,,0,4.000000e+000,5.000000e-001,5,1,0.000000e+000,0,,0,
1406904259.828,,0.000000e+000,2.979968e+002,2.305386e-006,0.000000e+000,-7.224274e-001,0.000000e+000,3,4.911094e-001,1.825000e+000,,,,,,,,,,,,,,,,,,0,4.000000e+000,5.000000e-001,5,1,0.000000e+000,0,,0,
1406904376.578,,5.000000e+000,2.979968e+002,2.543462e-006,0.000000e+000,-6.466218e-001,0.000000e+000,3,4.761587e-001,1.825000e+000,,,,,,,,,,,,,,,,,,0,4.000000e+000,5.000000e-001,5,1,0.000000e+000,0,,0,
1406904394.312,,5.000000e+000,2.979968e+002,2.536761e-006,0.000000e+000,-6.456099e-001,0.000000e+000,3,4.715305e-001,1.825000e+000,,,,,,,,,,,,,,,,,,0,4.000000e+000,5.000000e-001,5,1,0.000000e+000,0,,0,
1406904411.843,,5.000000e+000,2.980009e+002,2.539410e-006,0.000000e+000,-6.430113e-001,0.000000e+000,3,4.801355e-001,1.825000e+000,,,,,,,,,,,,,,,,,,0,4.000000e+000,5.000000e-001,5,1,8.209229e-003,0,,0,
1406904535.578,,1.000000e+001,2.980050e+002,2.821349e-006,0.000000e+000,-5.644782e-001,0.000000e+000,3,4.792610e-001,1.825000e+000,,,,,,,,,,,,,,,,,,0,4.000000e+000,5.000000e-001,5,1,0.000000e+000,0,,0,
1406904554.062,,1.000000e+001,2.980009e+002,2.812579e-006,0.000000e+000,-5.649530e-001,0.000000e+000,3,4.742966e-001,1.825000e+000,,,,,,,,,,,,,,,,,,0,4.000000e+000,5.000000e-001,5,1,8.209229e-003,0,,0,
1406904572.125,,1.000000e+001,2.980050e+002,2.819447e-006,0.000000e+000,-5.637340e-001,0.000000e+000,3,4.773447e-001,1.825000e+000,,,,,,,,,,,,,,,,,,0,4.000000e+000,5.000000e-001,5,1,0.000000e+000,0,,0,
1406904683.906,,1.500000e+001,2.980009e+002,3.089800e-006,0.000000e+000,-4.860473e-001,0.000000e+000,3,4.805869e-001,1.825000e+000,,,,,,,,,,,,,,,,,,0,4.000000e+000,5.000000e-001,5,1,8.209229e-003,0,,0,
1406904701.640,,1.500000e+001,2.979926e+002,3.102217e-006,0.000000e+000,-4.842927e-001,0.000000e+000,3,4.868259e-001,1.825000e+000,,,,,,,,,,,,,,,,,,0,4.000000e+000,5.000000e-001,5,1,8.300781e-003,0,,0,
1406904719.375,,1.500000e+001,2.979968e+002,3.103043e-006,0.000000e+000,-4.839972e-001,0.000000e+000,3,4.845972e-001,1.825000e+000,,,,,,,,,,,,,,,,,,0,4.000000e+000,5.000000e-001,5,1,1.651001e-002,0,,0,
1406904837.109,,2.000000e+001,2.980009e+002,3.421804e-006,0.000000e+000,-4.042769e-001,0.000000e+000,3,4.906927e-001,1.825000e+000,,,,,,,,,,,,,,,,,,0,4.000000e+000,5.000000e-001,5,1,8.209229e-003,0,,0,
1406904855.843,,2.000000e+001,2.979968e+002,3.425075e-006,0.000000e+000,-4.021608e-001,0.000000e+000,3,4.926965e-001,1.825000e+000,,,,,,,,,,,,,,,,,,0,4.000000e+000,5.000000e-001,5,1,0.000000e+000,0,,0,
1406904873.578,,2.000000e+001,2.980050e+002,3.438529e-006,0.000000e+000,-4.055436e-001,0.000000e+000,3,4.928060e-001,1.825000e+000,,,,,,,,,,,,,,,,,,0,4.000000e+000,5.000000e-001,5,1,0.000000e+000,0,,0,
1406904991.828,,2.500000e+001,2.980009e+002,3.779663e-006,0.000000e+000,-3.167233e-001,0.000000e+000,3,4.955157e-001,1.825000e+000,,,,,,,,,,,,,,,,,,0,4.000000e+000,5.000000e-001,5,1,8.209229e-003,0,,0,
1406905010.843,,2.500000e+001,2.980050e+002,3.772951e-006,0.000000e+000,-3.108683e-001,0.000000e+000,3,4.961444e-001,1.825000e+000,,,,,,,,,,,,,,,,,,0,4.000000e+000,5.000000e-001,5,1,0.000000e+000,0,,0,
1406905028.875,,2.500000e+001,2.979968e+002,3.779508e-006,0.000000e+000,-3.148372e-001,0.000000e+000,3,4.968299e-001,1.825000e+000,,,,,,,,,,,,,,,,,,0,4.000000e+000,5.000000e-001,5,1,0.000000e+000,0,,0,
1406905140.359,,3.000000e+001,2.980009e+002,4.175583e-006,0.000000e+000,-2.546278e-001,0.000000e+000,3,5.133260e-001,1.825000e+000,,,,,,,,,,,,,,,,,,0,4.000000e+000,5.000000e-001,5,1,8.209229e-003,0,,0,
1406905158.093,,3.000000e+001,2.979968e+002,4.187887e-006,0.000000e+000,-2.579732e-001,0.000000e+000,3,5.150905e-001,1.825000e+000,,,,,,,,,,,,,,,,,,0,4.000000e+000,5.000000e-001,5,1,0.000000e+000,0,,0,
1406905176.078,,3.000000e+001,2.979968e+002,4.184134e-006,0.000000e+000,-2.539366e-001,0.000000e+000,3,5.134646e-001,1.825000e+000,,,,,,,,,,,,,,,,,,0,4.000000e+000,5.000000e-001,5,1,0.000000e+000,0,,0,
1406905293.328,,3.500000e+001,2.979968e+002,4.618274e-006,0.000000e+000,-2.002725e-001,0.000000e+000,3,5.301862e-001,1.825000e+000,,,,,,,,,,,,,,,,,,0,4.000000e+000,5.000000e-001,5,1,0.000000e+000,0,,0,
1406905312.062,,3.500000e+001,2.979926e+002,4.617455e-006,0.000000e+000,-2.006120e-001,0.000000e+000,3,5.302131e-001,1.825000e+000,,,,,,,,,,,,,,,,,,0,4.000000e+000,5.000000e-001,5,1,8.300781e-003,0,,0,
1406905329.562,,3.500000e+001,2.979968e+002,4.629190e-006,0.000000e+000,-2.038272e-001,0.000000e+000,3,5.330867e-001,1.825000e+000,,,,,,,,,,,,,,,,,,0,4.000000e+000,5.000000e-001,5,1,0.000000e+000,0,,0,
1406905445.796,,4.000000e+001,2.980009e+002,5.104723e-006,0.000000e+000,-1.421528e-001,0.000000e+000,3,5.429963e-001,1.825000e+000,,,,,,,,,,,,,,,,,,0,4.000000e+000,5.000000e-001,5,1,8.209229e-003,0,,0,
1406905463.781,,4.000000e+001,2.979968e+002,5.097188e-006,0.000000e+000,-1.434342e-001,0.000000e+000,3,5.400884e-001,1.825000e+000,,,,,,,,,,,,,,,,,,0,4.000000e+000,5.000000e-001,5,1,0.000000e+000,0,,0,
1406905482.015,,4.000000e+001,2.979968e+002,5.115974e-006,0.000000e+000,-1.430094e-001,0.000000e+000,3,5.439278e-001,1.825000e+000,,,,,,,,,,,,,,,,,,0,4.000000e+000,5.000000e-001,5,1,0.000000e+000,0,,0,
1406905592.515,,4.500000e+001,2.979968e+002,5.582242e-006,0.000000e+000,-1.069653e-001,0.000000e+000,3,5.534787e-001,1.825000e+000,,,,,,,,,,,,,,,,,,0,4.000000e+000,5.000000e-001,5,1,0.000000e+000,0,,0,
1406905610.250,,4.500000e+001,2.979968e+002,5.587924e-006,0.000000e+000,-1.051397e-001,0.000000e+000,3,5.540507e-001,1.825000e+000,,,,,,,,,,,,,,,,,,0,4.000000e+000,5.000000e-001,5,1,0.000000e+000,0,,0,
1406905628.500,,4.500000e+001,2.979968e+002,5.592415e-006,0.000000e+000,-1.057249e-001,0.000000e+000,3,5.537833e-001,1.825000e+000,,,,,,,,,,,,,,,,,,0,4.000000e+000,5.000000e-001,5,1,0.000000e+000,0,,0,
1406905746.734,,5.000000e+001,2.980009e+002,6.108541e-006,0.000000e+000,-7.076772e-002,0.000000e+000,3,5.651239e-001,1.825000e+000,,,,,,,,,,,,,,,,,,0,4.000000e+000,5.000000e-001,5,1,8.209229e-003,0,,0,
1406905764.968,,5.000000e+001,2.979968e+002,6.115150e-006,0.000000e+000,-6.718396e-002,0.000000e+000,3,5.653182e-001,1.825000e+000,,,,,,,,,,,,,,,,,,0,4.000000e+000,5.000000e-001,5,1,1.651001e-002,0,,0,
1406905783.203,,5.000000e+001,2.980009e+002,6.125824e-006,0.000000e+000,-7.055092e-002,0.000000e+000,3,5.663002e-001,1.825000e+000,,,,,,,,,,,,,,,,,,0,4.000000e+000,5.000000e-001,5,1,8.209229e-003,0,,0,
1406905906.203,,7.500000e+001,2.980009e+002,8.644241e-006,0.000000e+000,3.942727e-003,0.000000e+000,3,6.146412e-001,1.825000e+000,,,,,,,,,,,,,,,,,,0,4.000000e+000,5.000000e-001,5,1,8.209229e-003,0,,0,
1406905924.453,,7.500000e+001,2.980009e+002,8.661056e-006,0.000000e+000,4.833924e-003,0.000000e+000,3,6.149556e-001,1.825000e+000,,,,,,,,,,,,,,,,,,0,4.000000e+000,5.000000e-001,5,1,8.209229e-003,0,,0,
1406905942.187,,7.500000e+001,2.979968e+002,8.656977e-006,0.000000e+000,3.230074e-003,0.000000e+000,3,6.146888e-001,1.825000e+000,,,,,,,,,,,,,,,,,,0,4.000000e+000,5.000000e-001,5,1,0.000000e+000,0,,0,
1406906066.421,,1.000000e+002,2.980050e+002,1.098466e-005,0.000000e+000,2.017825e-002,0.000000e+000,3,6.450484e-001,1.825000e+000,,,,,,,,,,,,,,,,,,0,4.000000e+000,5.000000e-001,5,1,0.000000e+000,0,,0,
1406906084.406,,1.000000e+002,2.979968e+002,1.100348e-005,0.000000e+000,2.006383e-002,0.000000e+000,3,6.459563e-001,1.825000e+000,,,,,,,,,,,,,,,,,,0,4.000000e+000,5.000000e-001,5,1,0.000000e+000,0,,0,
1406906102.921,,1.000000e+002,2.979968e+002,1.101111e-005,0.000000e+000,2.056811e-002,0.000000e+000,3,6.459016e-001,1.825000e+000,,,,,,,,,,,,,,,,,,0,4.000000e+000,5.000000e-001,5,1,0.000000e+000,0,,0,