File: Sample Data Files/2014-07-31 EB on isolated PMN-PT no Ti spontaneous in situ repeat/Ni-NiO_298K_SiO2_PMN-PT_5.0Tprebias_170V_Au_back.rso.dat
[Header]
TITLE,MPMS RSO Measurement
BYAPP,MPMS Measurement,1.1,Summary
FILEOPENTIME, 1406868190.531000 7/31/2014, 9:43:10 PM

INFO, APPNAME, MPMS MultiVu Application, Revision 1.58,  Build 076

INFO, NAME, EB in situ 2
INFO, WEIGHT, 0.000
INFO, AREA, 0.000
INFO, LENGTH, 0.000
INFO, SHAPE, 0
INFO, COMMENT,
INFO, SEQUENCE FILE: MHcurveUpTo100.seq


INFO, BACKGROUND DATA FILE:, None


STARTUPAXIS,X,4,LINEAR,AUTO,0.000000,0.000000
STARTUPAXIS,Y1,5,LINEAR,AUTO,0.000000,0.000000


STARTUPGROUP,Longitudinal
FIELDGROUP,Longitudinal,1,2,3,4,5,6,7,8,9,10,11,19,20,21,22,23,35
FIELDGROUP,Transverse,1,2,3,4,12,13,14,15,16,17,18,24,25,26,27,28,35

PLOT_APPEARANCE,ALL,HORZ_GRID_ON,VERT_GRID_ON,MARKERS_AND_LINES

[Data]
Time,Comment,Field (Oe),Temperature (K),Long Moment (emu),Long Scan Std Dev,Long Offset (cm),Long Offset Std Dev,Long Algorithm,Long Reg Fit,Long Reg Factor,Trans Moment (emu),Trans Scan Std Dev,Trans Offset (cm),Trans Offset Std Dev,Trans Algorithm,Trans Reg Fit,Trans Reg Factor,Long Moment [w/o ABS] (emu),Long Scan Std Dev [w/o ABS],Long Offset [w/o ABS] (cm),Long Offset Std Dev [w/o ABS],Long Reg Fit [w/o ABS],Trans Moment [w/o ABS] (emu),Trans Scan Std Dev [w/o ABS],Trans Offset [w/o ABS] (cm),Trans Offset Std Dev [w/o ABS],Trans Reg Fit [w/o ABS],RSO Position (deg),Amplitude (cm),Frequency,Cycles to Average,Scans per Measurement,Delta Temp (K),Error,EC Comp. Running,Using ABS,
1406868190.531,,1.000000e+002,2.980009e+002,2.876608e-005,0.000000e+000,2.758088e-002,0.000000e+000,3,8.603744e-001,1.825000e+000,,,,,,,,,,,,,,,,,,0,4.000000e+000,5.000000e-001,5,1,8.209229e-003,0,,0,
1406868208.765,,1.000000e+002,2.980009e+002,2.878619e-005,0.000000e+000,2.748861e-002,0.000000e+000,3,8.605265e-001,1.825000e+000,,,,,,,,,,,,,,,,,,0,4.000000e+000,5.000000e-001,5,1,8.209229e-003,0,,0,
1406868227.250,,1.000000e+002,2.980009e+002,2.880100e-005,0.000000e+000,2.734435e-002,0.000000e+000,3,8.602844e-001,1.825000e+000,,,,,,,,,,,,,,,,,,0,4.000000e+000,5.000000e-001,5,1,8.209229e-003,0,,0,
1406868353.015,,7.500000e+001,2.980009e+002,2.489477e-005,0.000000e+000,3.614763e-002,0.000000e+000,3,8.535549e-001,1.825000e+000,,,,,,,,,,,,,,,,,,0,4.000000e+000,5.000000e-001,5,1,8.209229e-003,0,,0,
1406868371.250,,7.500000e+001,2.979968e+002,2.489205e-005,0.000000e+000,3.623502e-002,0.000000e+000,3,8.536519e-001,1.825000e+000,,,,,,,,,,,,,,,,,,0,4.000000e+000,5.000000e-001,5,1,0.000000e+000,0,,0,
1406868388.281,,7.500000e+001,2.979926e+002,2.489744e-005,0.000000e+000,3.609452e-002,0.000000e+000,3,8.536981e-001,1.825000e+000,,,,,,,,,,,,,,,,,,0,4.000000e+000,5.000000e-001,5,1,8.300781e-003,0,,0,
1406868519.359,,5.000000e+001,2.980009e+002,1.992580e-005,0.000000e+000,5.107554e-002,0.000000e+000,3,8.384259e-001,1.825000e+000,,,,,,,,,,,,,,,,,,0,4.000000e+000,5.000000e-001,5,1,8.209229e-003,0,,0,
1406868537.156,,5.000000e+001,2.980050e+002,1.991320e-005,0.000000e+000,5.053911e-002,0.000000e+000,3,8.383809e-001,1.825000e+000,,,,,,,,,,,,,,,,,,0,4.000000e+000,5.000000e-001,5,1,0.000000e+000,0,,0,
1406868555.406,,5.000000e+001,2.980050e+002,1.990284e-005,0.000000e+000,5.093811e-002,0.000000e+000,3,8.382040e-001,1.825000e+000,,,,,,,,,,,,,,,,,,0,4.000000e+000,5.000000e-001,5,1,0.000000e+000,0,,0,
1406868673.156,,4.500000e+001,2.980009e+002,1.879948e-005,0.000000e+000,5.531397e-002,0.000000e+000,3,8.333877e-001,1.825000e+000,,,,,,,,,,,,,,,,,,0,4.000000e+000,5.000000e-001,5,1,8.209229e-003,0,,0,
1406868690.890,,4.500000e+001,2.979968e+002,1.878673e-005,0.000000e+000,5.520844e-002,0.000000e+000,3,8.337606e-001,1.825000e+000,,,,,,,,,,,,,,,,,,0,4.000000e+000,5.000000e-001,5,1,0.000000e+000,0,,0,
1406868709.125,,4.500000e+001,2.980009e+002,1.879119e-005,0.000000e+000,5.541588e-002,0.000000e+000,3,8.335499e-001,1.825000e+000,,,,,,,,,,,,,,,,,,0,4.000000e+000,5.000000e-001,5,1,8.209229e-003,0,,0,
1406868825.859,,4.000000e+001,2.980009e+002,1.768401e-005,0.000000e+000,5.972079e-002,0.000000e+000,3,8.286384e-001,1.825000e+000,,,,,,,,,,,,,,,,,,0,4.000000e+000,5.000000e-001,5,1,8.209229e-003,0,,0,
1406868844.093,,4.000000e+001,2.979968e+002,1.767553e-005,0.000000e+000,5.982472e-002,0.000000e+000,3,8.284418e-001,1.825000e+000,,,,,,,,,,,,,,,,,,0,4.000000e+000,5.000000e-001,5,1,0.000000e+000,0,,0,
1406868861.625,,4.000000e+001,2.980009e+002,1.765813e-005,0.000000e+000,6.008982e-002,0.000000e+000,3,8.280252e-001,1.825000e+000,,,,,,,,,,,,,,,,,,0,4.000000e+000,5.000000e-001,5,1,8.209229e-003,0,,0,
1406868985.875,,3.500000e+001,2.979968e+002,1.649351e-005,0.000000e+000,6.520194e-002,0.000000e+000,3,8.219028e-001,1.825000e+000,,,,,,,,,,,,,,,,,,0,4.000000e+000,5.000000e-001,5,1,0.000000e+000,0,,0,
1406869003.109,,3.500000e+001,2.979968e+002,1.648682e-005,0.000000e+000,6.546097e-002,0.000000e+000,3,8.224995e-001,1.825000e+000,,,,,,,,,,,,,,,,,,0,4.000000e+000,5.000000e-001,5,1,0.000000e+000,0,,0,
1406869020.890,,3.500000e+001,2.979968e+002,1.648943e-005,0.000000e+000,6.543263e-002,0.000000e+000,3,8.215285e-001,1.825000e+000,,,,,,,,,,,,,,,,,,0,4.000000e+000,5.000000e-001,5,1,0.000000e+000,0,,0,
1406869139.125,,3.000000e+001,2.980050e+002,1.531931e-005,0.000000e+000,7.146380e-002,0.000000e+000,3,8.149605e-001,1.825000e+000,,,,,,,,,,,,,,,,,,0,4.000000e+000,5.000000e-001,5,1,0.000000e+000,0,,0,
1406869156.687,,3.000000e+001,2.980009e+002,1.529703e-005,0.000000e+000,7.103730e-002,0.000000e+000,3,8.140725e-001,1.825000e+000,,,,,,,,,,,,,,,,,,0,4.000000e+000,5.000000e-001,5,1,8.209229e-003,0,,0,
1406869174.921,,3.000000e+001,2.980050e+002,1.529782e-005,0.000000e+000,7.128695e-002,0.000000e+000,3,8.146068e-001,1.825000e+000,,,,,,,,,,,,,,,,,,0,4.000000e+000,5.000000e-001,5,1,0.000000e+000,0,,0,
1406869290.421,,2.500000e+001,2.980009e+002,1.404000e-005,0.000000e+000,7.838590e-002,0.000000e+000,3,8.058585e-001,1.825000e+000,,,,,,,,,,,,,,,,,,0,4.000000e+000,5.000000e-001,5,1,8.209229e-003,0,,0,
1406869308.406,,2.500000e+001,2.979968e+002,1.402329e-005,0.000000e+000,7.874741e-002,0.000000e+000,3,8.051355e-001,1.825000e+000,,,,,,,,,,,,,,,,,,0,4.000000e+000,5.000000e-001,5,1,0.000000e+000,0,,0,
1406869326.140,,2.500000e+001,2.979968e+002,1.402629e-005,0.000000e+000,7.814274e-002,0.000000e+000,3,8.048919e-001,1.825000e+000,,,,,,,,,,,,,,,,,,0,4.000000e+000,5.000000e-001,5,1,0.000000e+000,0,,0,
1406869443.125,,2.000000e+001,2.979968e+002,1.271251e-005,0.000000e+000,8.733197e-002,0.000000e+000,3,7.933242e-001,1.825000e+000,,,,,,,,,,,,,,,,,,0,4.000000e+000,5.000000e-001,5,1,1.651001e-002,0,,0,
1406869460.859,,2.000000e+001,2.979968e+002,1.269132e-005,0.000000e+000,8.680221e-002,0.000000e+000,3,7.936399e-001,1.825000e+000,,,,,,,,,,,,,,,,,,0,4.000000e+000,5.000000e-001,5,1,0.000000e+000,0,,0,
1406869478.609,,2.000000e+001,2.979968e+002,1.268328e-005,0.000000e+000,8.781020e-002,0.000000e+000,3,7.928237e-001,1.825000e+000,,,,,,,,,,,,,,,,,,0,4.000000e+000,5.000000e-001,5,1,0.000000e+000,0,,0,
1406869596.609,,1.500000e+001,2.980050e+002,1.132337e-005,0.000000e+000,9.917395e-002,0.000000e+000,3,7.781180e-001,1.825000e+000,,,,,,,,,,,,,,,,,,0,4.000000e+000,5.000000e-001,5,1,0.000000e+000,0,,0,
1406869614.593,,1.500000e+001,2.979968e+002,1.129828e-005,0.000000e+000,9.926508e-002,0.000000e+000,3,7.776820e-001,1.825000e+000,,,,,,,,,,,,,,,,,,0,4.000000e+000,5.000000e-001,5,1,0.000000e+000,0,,0,
1406869632.828,,1.500000e+001,2.979926e+002,1.128821e-005,0.000000e+000,9.983744e-002,0.000000e+000,3,7.772564e-001,1.825000e+000,,,,,,,,,,,,,,,,,,0,4.000000e+000,5.000000e-001,5,1,8.300781e-003,0,,0,
1406869749.312,,1.000000e+001,2.980009e+002,9.800710e-006,0.000000e+000,1.181984e-001,0.000000e+000,3,7.548094e-001,1.825000e+000,,,,,,,,,,,,,,,,,,0,4.000000e+000,5.000000e-001,5,1,8.209229e-003,0,,0,
1406869767.046,,1.000000e+001,2.980009e+002,9.758042e-006,0.000000e+000,1.185165e-001,0.000000e+000,3,7.543084e-001,1.825000e+000,,,,,,,,,,,,,,,,,,0,4.000000e+000,5.000000e-001,5,1,8.209229e-003,0,,0,
1406869785.281,,1.000000e+001,2.980009e+002,9.742441e-006,0.000000e+000,1.191400e-001,0.000000e+000,3,7.538671e-001,1.825000e+000,,,,,,,,,,,,,,,,,,0,4.000000e+000,5.000000e-001,5,1,8.209229e-003,0,,0,
1406869904.343,,5.000000e+000,2.979968e+002,8.081944e-006,0.000000e+000,1.461416e-001,0.000000e+000,3,7.185762e-001,1.825000e+000,,,,,,,,,,,,,,,,,,0,4.000000e+000,5.000000e-001,5,1,0.000000e+000,0,,0,
1406869922.828,,5.000000e+000,2.980009e+002,8.031430e-006,0.000000e+000,1.482827e-001,0.000000e+000,3,7.184156e-001,1.825000e+000,,,,,,,,,,,,,,,,,,0,4.000000e+000,5.000000e-001,5,1,8.209229e-003,0,,0,
1406869940.328,,5.000000e+000,2.980009e+002,8.008792e-006,0.000000e+000,1.472719e-001,0.000000e+000,3,7.166291e-001,1.825000e+000,,,,,,,,,,,,,,,,,,0,4.000000e+000,5.000000e-001,5,1,8.209229e-003,0,,0,
1406870057.562,,0.000000e+000,2.979926e+002,6.101429e-006,0.000000e+000,2.064818e-001,0.000000e+000,3,6.516786e-001,1.825000e+000,,,,,,,,,,,,,,,,,,0,4.000000e+000,5.000000e-001,5,1,8.300781e-003,0,,0,
1406870075.796,,0.000000e+000,2.979968e+002,6.037234e-006,0.000000e+000,2.072083e-001,0.000000e+000,3,6.475887e-001,1.825000e+000,,,,,,,,,,,,,,,,,,0,4.000000e+000,5.000000e-001,5,1,1.651001e-002,0,,0,
1406870094.062,,0.000000e+000,2.980009e+002,5.991421e-006,0.000000e+000,2.081289e-001,0.000000e+000,3,6.463197e-001,1.825000e+000,,,,,,,,,,,,,,,,,,0,4.000000e+000,5.000000e-001,5,1,8.209229e-003,0,,0,
1406870212.312,,-5.000000e+000,2.979968e+002,3.885197e-006,0.000000e+000,4.673729e-001,0.000000e+000,3,4.973222e-001,1.825000e+000,,,,,,,,,,,,,,,,,,0,4.000000e+000,5.000000e-001,5,1,0.000000e+000,0,,0,
1406870230.046,,-5.000000e+000,2.980009e+002,3.826043e-006,0.000000e+000,4.849484e-001,0.000000e+000,3,4.893817e-001,1.825000e+000,,,,,,,,,,,,,,,,,,0,4.000000e+000,5.000000e-001,5,1,8.209229e-003,0,,0,
1406870248.093,,-5.000000e+000,2.979968e+002,3.790088e-006,0.000000e+000,4.986337e-001,0.000000e+000,3,4.849798e-001,1.825000e+000,,,,,,,,,,,,,,,,,,0,4.000000e+000,5.000000e-001,5,1,0.000000e+000,0,,0,
1406870371.390,,-1.000000e+001,2.980009e+002,6.902843e-007,0.000000e+000,0.000000e+000,0.000000e+000,3,0.000000e+000,1.825000e+000,,,,,,,,,,,,,,,,,,0,4.000000e+000,5.000000e-001,5,1,8.209229e-003,0,,0,
1406870389.125,,-1.000000e+001,2.980009e+002,2.390834e-006,0.000000e+000,1.016440e+000,0.000000e+000,3,3.301289e-001,1.825000e+000,,,,,,,,,,,,,,,,,,0,4.000000e+000,5.000000e-001,5,1,8.209229e-003,0,,0,
1406870407.890,,-1.000000e+001,2.979968e+002,2.391144e-006,0.000000e+000,1.024248e+000,0.000000e+000,3,3.357846e-001,1.825000e+000,,,,,,,,,,,,,,,,,,0,4.000000e+000,5.000000e-001,5,1,0.000000e+000,0,,0,
1406870525.140,,-1.500000e+001,2.979968e+002,-1.823992e-006,0.000000e+000,-1.138807e-001,0.000000e+000,3,5.148946e-002,1.825000e+000,,,,,,,,,,,,,,,,,,0,4.000000e+000,5.000000e-001,5,1,1.651001e-002,0,,0,
1406870543.375,,-1.500000e+001,2.980009e+002,-1.912686e-006,0.000000e+000,-1.021671e-001,0.000000e+000,3,1.047167e-001,1.825000e+000,,,,,,,,,,,,,,,,,,0,4.000000e+000,5.000000e-001,5,1,8.209229e-003,0,,0,
1406870561.109,,-1.500000e+001,2.980009e+002,-1.976112e-006,0.000000e+000,-9.391394e-002,0.000000e+000,3,1.291257e-001,1.825000e+000,,,,,,,,,,,,,,,,,,0,4.000000e+000,5.000000e-001,5,1,8.209229e-003,0,,0,
1406870678.593,,-2.000000e+001,2.980009e+002,-4.542364e-006,0.000000e+000,1.316113e-002,0.000000e+000,3,6.582702e-001,1.825000e+000,,,,,,,,,,,,,,,,,,0,4.000000e+000,5.000000e-001,5,1,8.209229e-003,0,,0,
1406870696.328,,-2.000000e+001,2.979968e+002,-4.661032e-006,0.000000e+000,1.760063e-002,0.000000e+000,3,6.671388e-001,1.825000e+000,,,,,,,,,,,,,,,,,,0,4.000000e+000,5.000000e-001,5,1,0.000000e+000,0,,0,
1406870714.812,,-2.000000e+001,2.980050e+002,-4.780457e-006,0.000000e+000,2.098168e-002,0.000000e+000,3,6.768909e-001,1.825000e+000,,,,,,,,,,,,,,,,,,0,4.000000e+000,5.000000e-001,5,1,0.000000e+000,0,,0,
1406870833.062,,-2.500000e+001,2.979968e+002,-7.827742e-006,0.000000e+000,6.212879e-002,0.000000e+000,3,8.238281e-001,1.825000e+000,,,,,,,,,,,,,,,,,,0,4.000000e+000,5.000000e-001,5,1,0.000000e+000,0,,0,
1406870850.796,,-2.500000e+001,2.979968e+002,-8.026914e-006,0.000000e+000,6.490984e-002,0.000000e+000,3,8.287057e-001,1.825000e+000,,,,,,,,,,,,,,,,,,0,4.000000e+000,5.000000e-001,5,1,1.651001e-002,0,,0,
1406870868.546,,-2.500000e+001,2.979968e+002,-8.189782e-006,0.000000e+000,6.698774e-002,0.000000e+000,3,8.323929e-001,1.825000e+000,,,,,,,,,,,,,,,,,,0,4.000000e+000,5.000000e-001,5,1,0.000000e+000,0,,0,
1406870986.078,,-3.000000e+001,2.980050e+002,-1.049819e-005,0.000000e+000,7.532617e-002,0.000000e+000,3,8.831317e-001,1.825000e+000,,,,,,,,,,,,,,,,,,0,4.000000e+000,5.000000e-001,5,1,0.000000e+000,0,,0,
1406871004.078,,-3.000000e+001,2.980009e+002,-1.055778e-005,0.000000e+000,7.523602e-002,0.000000e+000,3,8.840180e-001,1.825000e+000,,,,,,,,,,,,,,,,,,0,4.000000e+000,5.000000e-001,5,1,8.209229e-003,0,,0,
1406871022.875,,-3.000000e+001,2.980009e+002,-1.059709e-005,0.000000e+000,7.487557e-002,0.000000e+000,3,8.839780e-001,1.825000e+000,,,,,,,,,,,,,,,,,,0,4.000000e+000,5.000000e-001,5,1,8.209229e-003,0,,0,
1406871139.406,,-3.500000e+001,2.980009e+002,-1.226310e-005,0.000000e+000,7.375545e-002,0.000000e+000,3,9.094340e-001,1.825000e+000,,,,,,,,,,,,,,,,,,0,4.000000e+000,5.000000e-001,5,1,8.209229e-003,0,,0,
1406871157.671,,-3.500000e+001,2.979968e+002,-1.230668e-005,0.000000e+000,7.356125e-002,0.000000e+000,3,9.099190e-001,1.825000e+000,,,,,,,,,,,,,,,,,,0,4.000000e+000,5.000000e-001,5,1,0.000000e+000,0,,0,
1406871175.406,,-3.500000e+001,2.980009e+002,-1.233662e-005,0.000000e+000,7.420364e-002,0.000000e+000,3,9.107323e-001,1.825000e+000,,,,,,,,,,,,,,,,,,0,4.000000e+000,5.000000e-001,5,1,8.209229e-003,0,,0,
1406871291.156,,-4.000000e+001,2.979926e+002,-1.393167e-005,0.000000e+000,7.153933e-002,0.000000e+000,3,9.298716e-001,1.825000e+000,,,,,,,,,,,,,,,,,,0,4.000000e+000,5.000000e-001,5,1,8.300781e-003,0,,0,
1406871309.890,,-4.000000e+001,2.980050e+002,-1.399281e-005,0.000000e+000,7.200491e-002,0.000000e+000,3,9.301829e-001,1.825000e+000,,,,,,,,,,,,,,,,,,0,4.000000e+000,5.000000e-001,5,1,0.000000e+000,0,,0,
1406871327.625,,-4.000000e+001,2.980009e+002,-1.400398e-005,0.000000e+000,7.186446e-002,0.000000e+000,3,9.302573e-001,1.825000e+000,,,,,,,,,,,,,,,,,,0,4.000000e+000,5.000000e-001,5,1,8.209229e-003,0,,0,
1406871438.375,,-4.500000e+001,2.979968e+002,-1.549067e-005,0.000000e+000,7.024135e-002,0.000000e+000,3,9.435579e-001,1.825000e+000,,,,,,,,,,,,,,,,,,0,4.000000e+000,5.000000e-001,5,1,0.000000e+000,0,,0,
1406871456.359,,-4.500000e+001,2.979968e+002,-1.553429e-005,0.000000e+000,7.058281e-002,0.000000e+000,3,9.434423e-001,1.825000e+000,,,,,,,,,,,,,,,,,,0,4.000000e+000,5.000000e-001,5,1,0.000000e+000,0,,0,
1406871474.343,,-4.500000e+001,2.980009e+002,-1.556690e-005,0.000000e+000,7.050631e-002,0.000000e+000,3,9.442979e-001,1.825000e+000,,,,,,,,,,,,,,,,,,0,4.000000e+000,5.000000e-001,5,1,8.209229e-003,0,,0,
1406871625.218,,-5.000000e+001,2.979926e+002,-1.709306e-005,0.000000e+000,6.975720e-002,0.000000e+000,3,9.557331e-001,1.825000e+000,,,,,,,,,,,,,,,,,,0,4.000000e+000,5.000000e-001,5,1,8.300781e-003,0,,0,
1406871643.000,,-5.000000e+001,2.980009e+002,-1.712329e-005,0.000000e+000,6.993763e-002,0.000000e+000,3,9.557775e-001,1.825000e+000,,,,,,,,,,,,,,,,,,0,4.000000e+000,5.000000e-001,5,1,8.209229e-003,0,,0,
1406871660.984,,-5.000000e+001,2.980009e+002,-1.714618e-005,0.000000e+000,6.959587e-002,0.000000e+000,3,9.557809e-001,1.825000e+000,,,,,,,,,,,,,,,,,,0,4.000000e+000,5.000000e-001,5,1,8.209229e-003,0,,0,
1406871810.968,,-7.500000e+001,2.980009e+002,-2.294124e-005,0.000000e+000,6.006134e-002,0.000000e+000,3,9.796922e-001,1.825000e+000,,,,,,,,,,,,,,,,,,0,4.000000e+000,5.000000e-001,5,1,8.209229e-003,0,,0,
1406871828.953,,-7.500000e+001,2.980009e+002,-2.295059e-005,0.000000e+000,6.017623e-002,0.000000e+000,3,9.792505e-001,1.825000e+000,,,,,,,,,,,,,,,,,,0,4.000000e+000,5.000000e-001,5,1,8.209229e-003,0,,0,
1406871846.687,,-7.500000e+001,2.980009e+002,-2.296967e-005,0.000000e+000,6.025398e-002,0.000000e+000,3,9.794006e-001,1.825000e+000,,,,,,,,,,,,,,,,,,0,4.000000e+000,5.000000e-001,5,1,8.209229e-003,0,,0,
1406871975.937,,-1.000000e+002,2.980009e+002,-2.645587e-005,0.000000e+000,5.465717e-002,0.000000e+000,3,9.761748e-001,1.825000e+000,,,,,,,,,,,,,,,,,,0,4.000000e+000,5.000000e-001,5,1,8.209229e-003,0,,0,
1406871993.703,,-1.000000e+002,2.979968e+002,-2.646540e-005,0.000000e+000,5.310225e-002,0.000000e+000,3,9.751700e-001,1.825000e+000,,,,,,,,,,,,,,,,,,0,4.000000e+000,5.000000e-001,5,1,0.000000e+000,0,,0,
1406872011.968,,-1.000000e+002,2.980009e+002,-2.642346e-005,0.000000e+000,5.492986e-002,0.000000e+000,3,9.757682e-001,1.825000e+000,,,,,,,,,,,,,,,,,,0,4.000000e+000,5.000000e-001,5,1,8.209229e-003,0,,0,
1406872158.703,,-7.500000e+001,2.979968e+002,-2.383954e-005,0.000000e+000,6.191280e-002,0.000000e+000,3,9.806311e-001,1.825000e+000,,,,,,,,,,,,,,,,,,0,4.000000e+000,5.000000e-001,5,1,0.000000e+000,0,,0,
1406872176.437,,-7.500000e+001,2.980050e+002,-2.383464e-005,0.000000e+000,6.224253e-002,0.000000e+000,3,9.807233e-001,1.825000e+000,,,,,,,,,,,,,,,,,,0,4.000000e+000,5.000000e-001,5,1,0.000000e+000,0,,0,
1406872194.171,,-7.500000e+001,2.980050e+002,-2.382575e-005,0.000000e+000,6.195653e-002,0.000000e+000,3,9.804028e-001,1.825000e+000,,,,,,,,,,,,,,,,,,0,4.000000e+000,5.000000e-001,5,1,0.000000e+000,0,,0,
1406872324.968,,-5.000000e+001,2.979968e+002,-2.004411e-005,0.000000e+000,7.792976e-002,0.000000e+000,3,9.724620e-001,1.825000e+000,,,,,,,,,,,,,,,,,,0,4.000000e+000,5.000000e-001,5,1,0.000000e+000,0,,0,
1406872342.718,,-5.000000e+001,2.979968e+002,-2.002977e-005,0.000000e+000,7.840211e-002,0.000000e+000,3,9.727881e-001,1.825000e+000,,,,,,,,,,,,,,,,,,0,4.000000e+000,5.000000e-001,5,1,0.000000e+000,0,,0,
1406872361.468,,-5.000000e+001,2.980009e+002,-2.002012e-005,0.000000e+000,7.824329e-002,0.000000e+000,3,9.729188e-001,1.825000e+000,,,,,,,,,,,,,,,,,,0,4.000000e+000,5.000000e-001,5,1,8.209229e-003,0,,0,
1406872497.687,,-4.500000e+001,2.980050e+002,-1.906819e-005,0.000000e+000,8.318636e-002,0.000000e+000,3,9.684135e-001,1.825000e+000,,,,,,,,,,,,,,,,,,0,4.000000e+000,5.000000e-001,5,1,1.641846e-002,0,,0,
1406872515.671,,-4.500000e+001,2.980009e+002,-1.905663e-005,0.000000e+000,8.310961e-002,0.000000e+000,3,9.682915e-001,1.825000e+000,,,,,,,,,,,,,,,,,,0,4.000000e+000,5.000000e-001,5,1,8.209229e-003,0,,0,
1406872532.953,,-4.500000e+001,2.979968e+002,-1.906241e-005,0.000000e+000,8.302852e-002,0.000000e+000,3,9.684239e-001,1.825000e+000,,,,,,,,,,,,,,,,,,0,4.000000e+000,5.000000e-001,5,1,0.000000e+000,0,,0,
1406872650.703,,-4.000000e+001,2.980009e+002,-1.810513e-005,0.000000e+000,8.845735e-002,0.000000e+000,3,9.638063e-001,1.825000e+000,,,,,,,,,,,,,,,,,,0,4.000000e+000,5.000000e-001,5,1,8.209229e-003,0,,0,
1406872668.187,,-4.000000e+001,2.979968e+002,-1.810689e-005,0.000000e+000,8.885397e-002,0.000000e+000,3,9.639660e-001,1.825000e+000,,,,,,,,,,,,,,,,,,0,4.000000e+000,5.000000e-001,5,1,0.000000e+000,0,,0,
1406872686.171,,-4.000000e+001,2.980009e+002,-1.809243e-005,0.000000e+000,8.862664e-002,0.000000e+000,3,9.634461e-001,1.825000e+000,,,,,,,,,,,,,,,,,,0,4.000000e+000,5.000000e-001,5,1,8.209229e-003,0,,0,
1406872803.171,,-3.500000e+001,2.979968e+002,-1.708475e-005,0.000000e+000,9.515291e-002,0.000000e+000,3,9.570305e-001,1.825000e+000,,,,,,,,,,,,,,,,,,0,4.000000e+000,5.000000e-001,5,1,0.000000e+000,0,,0,
1406872820.968,,-3.500000e+001,2.980009e+002,-1.708022e-005,0.000000e+000,9.451006e-002,0.000000e+000,3,9.571349e-001,1.825000e+000,,,,,,,,,,,,,,,,,,0,4.000000e+000,5.000000e-001,5,1,8.209229e-003,0,,0,
1406872838.968,,-3.500000e+001,2.980009e+002,-1.707612e-005,0.000000e+000,9.461957e-002,0.000000e+000,3,9.569418e-001,1.825000e+000,,,,,,,,,,,,,,,,,,0,4.000000e+000,5.000000e-001,5,1,8.209229e-003,0,,0,
1406872961.703,,-3.000000e+001,2.980009e+002,-1.603985e-005,0.000000e+000,1.020045e-001,0.000000e+000,3,9.496807e-001,1.825000e+000,,,,,,,,,,,,,,,,,,0,4.000000e+000,5.000000e-001,5,1,8.209229e-003,0,,0,
1406872979.203,,-3.000000e+001,2.979926e+002,-1.602021e-005,0.000000e+000,1.022338e-001,0.000000e+000,3,9.490077e-001,1.825000e+000,,,,,,,,,,,,,,,,,,0,4.000000e+000,5.000000e-001,5,1,8.300781e-003,0,,0,
1406872997.187,,-3.000000e+001,2.980009e+002,-1.601722e-005,0.000000e+000,1.028844e-001,0.000000e+000,3,9.493452e-001,1.825000e+000,,,,,,,,,,,,,,,,,,0,4.000000e+000,5.000000e-001,5,1,8.209229e-003,0,,0,
1406873115.437,,-2.500000e+001,2.980009e+002,-1.498843e-005,0.000000e+000,1.101807e-001,0.000000e+000,3,9.405776e-001,1.825000e+000,,,,,,,,,,,,,,,,,,0,4.000000e+000,5.000000e-001,5,1,8.209229e-003,0,,0,
1406873133.421,,-2.500000e+001,2.979968e+002,-1.496579e-005,0.000000e+000,1.102661e-001,0.000000e+000,3,9.404086e-001,1.825000e+000,,,,,,,,,,,,,,,,,,0,4.000000e+000,5.000000e-001,5,1,0.000000e+000,0,,0,
1406873151.921,,-2.500000e+001,2.980009e+002,-1.496164e-005,0.000000e+000,1.107716e-001,0.000000e+000,3,9.405951e-001,1.825000e+000,,,,,,,,,,,,,,,,,,0,4.000000e+000,5.000000e-001,5,1,8.209229e-003,0,,0,
1406873269.406,,-2.000000e+001,2.980009e+002,-1.385264e-005,0.000000e+000,1.196214e-001,0.000000e+000,3,9.296976e-001,1.825000e+000,,,,,,,,,,,,,,,,,,0,4.000000e+000,5.000000e-001,5,1,8.209229e-003,0,,0,
1406873287.390,,-2.000000e+001,2.980050e+002,-1.383723e-005,0.000000e+000,1.195854e-001,0.000000e+000,3,9.290333e-001,1.825000e+000,,,,,,,,,,,,,,,,,,0,4.000000e+000,5.000000e-001,5,1,0.000000e+000,0,,0,
1406873305.125,,-2.000000e+001,2.980050e+002,-1.383637e-005,0.000000e+000,1.197449e-001,0.000000e+000,3,9.293543e-001,1.825000e+000,,,,,,,,,,,,,,,,,,0,4.000000e+000,5.000000e-001,5,1,0.000000e+000,0,,0,
1406873420.859,,-1.500000e+001,2.980009e+002,-1.268928e-005,0.000000e+000,1.308240e-001,0.000000e+000,3,9.161465e-001,1.825000e+000,,,,,,,,,,,,,,,,,,0,4.000000e+000,5.000000e-001,5,1,8.209229e-003,0,,0,
1406873439.093,,-1.500000e+001,2.980009e+002,-1.268247e-005,0.000000e+000,1.309094e-001,0.000000e+000,3,9.158017e-001,1.825000e+000,,,,,,,,,,,,,,,,,,0,4.000000e+000,5.000000e-001,5,1,8.209229e-003,0,,0,
1406873456.328,,-1.500000e+001,2.979968e+002,-1.265825e-005,0.000000e+000,1.306123e-001,0.000000e+000,3,9.148804e-001,1.825000e+000,,,,,,,,,,,,,,,,,,0,4.000000e+000,5.000000e-001,5,1,0.000000e+000,0,,0,
1406873581.078,,-1.000000e+001,2.979968e+002,-1.146698e-005,0.000000e+000,1.446293e-001,0.000000e+000,3,8.975185e-001,1.825000e+000,,,,,,,,,,,,,,,,,,0,4.000000e+000,5.000000e-001,5,1,0.000000e+000,0,,0,
1406873599.562,,-1.000000e+001,2.979926e+002,-1.147609e-005,0.000000e+000,1.438857e-001,0.000000e+000,3,8.975721e-001,1.825000e+000,,,,,,,,,,,,,,,,,,0,4.000000e+000,5.000000e-001,5,1,8.300781e-003,0,,0,
1406873616.562,,-1.000000e+001,2.980009e+002,-1.146402e-005,0.000000e+000,1.438889e-001,0.000000e+000,3,8.978396e-001,1.825000e+000,,,,,,,,,,,,,,,,,,0,4.000000e+000,5.000000e-001,5,1,8.209229e-003,0,,0,
1406873726.796,,-5.000000e+000,2.979926e+002,-1.027572e-005,0.000000e+000,1.605801e-001,0.000000e+000,3,8.755237e-001,1.825000e+000,,,,,,,,,,,,,,,,,,0,4.000000e+000,5.000000e-001,5,1,8.300781e-003,0,,0,
1406873744.562,,-5.000000e+000,2.980009e+002,-1.027312e-005,0.000000e+000,1.607109e-001,0.000000e+000,3,8.758737e-001,1.825000e+000,,,,,,,,,,,,,,,,,,0,4.000000e+000,5.000000e-001,5,1,8.209229e-003,0,,0,
1406873763.296,,-5.000000e+000,2.980009e+002,-1.025176e-005,0.000000e+000,1.608785e-001,0.000000e+000,3,8.752968e-001,1.825000e+000,,,,,,,,,,,,,,,,,,0,4.000000e+000,5.000000e-001,5,1,8.209229e-003,0,,0,
1406873879.531,,0.000000e+000,2.980050e+002,-8.990581e-006,0.000000e+000,1.807876e-001,0.000000e+000,3,8.444582e-001,1.825000e+000,,,,,,,,,,,,,,,,,,0,4.000000e+000,5.000000e-001,5,1,0.000000e+000,0,,0,
1406873897.531,,0.000000e+000,2.980050e+002,-8.981400e-006,0.000000e+000,1.816913e-001,0.000000e+000,3,8.446367e-001,1.825000e+000,,,,,,,,,,,,,,,,,,0,4.000000e+000,5.000000e-001,5,1,0.000000e+000,0,,0,
1406873915.515,,0.000000e+000,2.980009e+002,-8.970451e-006,0.000000e+000,1.828570e-001,0.000000e+000,3,8.448472e-001,1.825000e+000,,,,,,,,,,,,,,,,,,0,4.000000e+000,5.000000e-001,5,1,8.209229e-003,0,,0,
1406874051.000,,5.000000e+000,2.979968e+002,-7.594004e-006,0.000000e+000,2.117377e-001,0.000000e+000,3,7.989605e-001,1.825000e+000,,,,,,,,,,,,,,,,,,0,4.000000e+000,5.000000e-001,5,1,0.000000e+000,0,,0,
1406874068.562,,5.000000e+000,2.980050e+002,-7.574427e-006,0.000000e+000,2.123550e-001,0.000000e+000,3,7.986379e-001,1.825000e+000,,,,,,,,,,,,,,,,,,0,4.000000e+000,5.000000e-001,5,1,1.641846e-002,0,,0,
1406874085.812,,5.000000e+000,2.979968e+002,-7.566113e-006,0.000000e+000,2.119485e-001,0.000000e+000,3,7.981606e-001,1.825000e+000,,,,,,,,,,,,,,,,,,0,4.000000e+000,5.000000e-001,5,1,0.000000e+000,0,,0,
1406874209.046,,1.000000e+001,2.979968e+002,-6.212120e-006,0.000000e+000,2.553017e-001,0.000000e+000,3,7.313711e-001,1.825000e+000,,,,,,,,,,,,,,,,,,0,4.000000e+000,5.000000e-001,5,1,0.000000e+000,0,,0,
1406874227.031,,1.000000e+001,2.980050e+002,-6.204466e-006,0.000000e+000,2.558069e-001,0.000000e+000,3,7.305931e-001,1.825000e+000,,,,,,,,,,,,,,,,,,0,4.000000e+000,5.000000e-001,5,1,0.000000e+000,0,,0,
1406874245.265,,1.000000e+001,2.979968e+002,-6.175837e-006,0.000000e+000,2.574776e-001,0.000000e+000,3,7.302394e-001,1.825000e+000,,,,,,,,,,,,,,,,,,0,4.000000e+000,5.000000e-001,5,1,0.000000e+000,0,,0,
1406874356.265,,1.500000e+001,2.979926e+002,-4.814167e-006,0.000000e+000,3.285128e-001,0.000000e+000,3,6.216698e-001,1.825000e+000,,,,,,,,,,,,,,,,,,0,4.000000e+000,5.000000e-001,5,1,8.300781e-003,0,,0,
1406874373.500,,1.500000e+001,2.979968e+002,-4.797721e-006,0.000000e+000,3.315431e-001,0.000000e+000,3,6.180707e-001,1.825000e+000,,,,,,,,,,,,,,,,,,0,4.000000e+000,5.000000e-001,5,1,0.000000e+000,0,,0,
1406874392.281,,1.500000e+001,2.980009e+002,-4.765924e-006,0.000000e+000,3.323706e-001,0.000000e+000,3,6.147426e-001,1.825000e+000,,,,,,,,,,,,,,,,,,0,4.000000e+000,5.000000e-001,5,1,8.209229e-003,0,,0,
1406874510.515,,2.000000e+001,2.979968e+002,-3.322916e-006,0.000000e+000,5.402102e-001,0.000000e+000,3,3.651228e-001,1.825000e+000,,,,,,,,,,,,,,,,,,0,4.000000e+000,5.000000e-001,5,1,0.000000e+000,0,,0,
1406874528.750,,2.000000e+001,2.979926e+002,-3.298861e-006,0.000000e+000,5.474953e-001,0.000000e+000,3,3.584647e-001,1.825000e+000,,,,,,,,,,,,,,,,,,0,4.000000e+000,5.000000e-001,5,1,8.300781e-003,0,,0,
1406874546.984,,2.000000e+001,2.979968e+002,-3.281529e-006,0.000000e+000,5.532208e-001,0.000000e+000,3,3.528755e-001,1.825000e+000,,,,,,,,,,,,,,,,,,0,4.000000e+000,5.000000e-001,5,1,0.000000e+000,0,,0,
1406874665.234,,2.500000e+001,2.980009e+002,-8.196321e-008,0.000000e+000,0.000000e+000,0.000000e+000,3,0.000000e+000,1.825000e+000,,,,,,,,,,,,,,,,,,0,4.000000e+000,5.000000e-001,5,1,8.209229e-003,0,,0,
1406874683.484,,2.500000e+001,2.980009e+002,-3.985081e-008,0.000000e+000,0.000000e+000,0.000000e+000,3,0.000000e+000,1.825000e+000,,,,,,,,,,,,,,,,,,0,4.000000e+000,5.000000e-001,5,1,8.209229e-003,0,,0,
1406874701.218,,2.500000e+001,2.979968e+002,7.499813e-009,0.000000e+000,0.000000e+000,0.000000e+000,3,0.000000e+000,1.825000e+000,,,,,,,,,,,,,,,,,,0,4.000000e+000,5.000000e-001,5,1,0.000000e+000,0,,0,
1406874811.703,,3.000000e+001,2.979968e+002,4.456485e-006,0.000000e+000,-6.024721e-001,0.000000e+000,3,6.624896e-001,1.825000e+000,,,,,,,,,,,,,,,,,,0,4.000000e+000,5.000000e-001,5,1,0.000000e+000,0,,0,
1406874829.187,,3.000000e+001,2.980009e+002,4.493899e-006,0.000000e+000,-5.919683e-001,0.000000e+000,3,6.649012e-001,1.825000e+000,,,,,,,,,,,,,,,,,,0,4.000000e+000,5.000000e-001,5,1,8.209229e-003,0,,0,
1406874847.437,,3.000000e+001,2.980009e+002,4.512997e-006,0.000000e+000,-5.846552e-001,0.000000e+000,3,6.637814e-001,1.825000e+000,,,,,,,,,,,,,,,,,,0,4.000000e+000,5.000000e-001,5,1,8.209229e-003,0,,0,
1406874963.937,,3.500000e+001,2.980050e+002,6.279233e-006,0.000000e+000,-3.136687e-001,0.000000e+000,3,7.018613e-001,1.825000e+000,,,,,,,,,,,,,,,,,,0,4.000000e+000,5.000000e-001,5,1,0.000000e+000,0,,0,
1406874981.671,,3.500000e+001,2.979968e+002,6.332075e-006,0.000000e+000,-3.095610e-001,0.000000e+000,3,7.026031e-001,1.825000e+000,,,,,,,,,,,,,,,,,,0,4.000000e+000,5.000000e-001,5,1,0.000000e+000,0,,0,
1406874999.156,,3.500000e+001,2.979968e+002,6.374466e-006,0.000000e+000,-3.050011e-001,0.000000e+000,3,7.046335e-001,1.825000e+000,,,,,,,,,,,,,,,,,,0,4.000000e+000,5.000000e-001,5,1,0.000000e+000,0,,0,
1406875116.890,,4.000000e+001,2.980009e+002,8.632411e-006,0.000000e+000,-1.600667e-001,0.000000e+000,3,7.462540e-001,1.825000e+000,,,,,,,,,,,,,,,,,,0,4.000000e+000,5.000000e-001,5,1,8.209229e-003,0,,0,
1406875134.625,,4.000000e+001,2.979968e+002,8.712439e-006,0.000000e+000,-1.562205e-001,0.000000e+000,3,7.468298e-001,1.825000e+000,,,,,,,,,,,,,,,,,,0,4.000000e+000,5.000000e-001,5,1,0.000000e+000,0,,0,
1406875152.359,,4.000000e+001,2.980009e+002,8.770512e-006,0.000000e+000,-1.536629e-001,0.000000e+000,3,7.487176e-001,1.825000e+000,,,,,,,,,,,,,,,,,,0,4.000000e+000,5.000000e-001,5,1,8.209229e-003,0,,0,
1406875263.687,,4.500000e+001,2.979926e+002,1.130254e-005,0.000000e+000,-8.398893e-002,0.000000e+000,3,7.865239e-001,1.825000e+000,,,,,,,,,,,,,,,,,,0,4.000000e+000,5.000000e-001,5,1,8.300781e-003,0,,0,
1406875281.953,,4.500000e+001,2.979968e+002,1.142465e-005,0.000000e+000,-8.122382e-002,0.000000e+000,3,7.882243e-001,1.825000e+000,,,,,,,,,,,,,,,,,,0,4.000000e+000,5.000000e-001,5,1,0.000000e+000,0,,0,
1406875300.234,,4.500000e+001,2.979968e+002,1.154157e-005,0.000000e+000,-7.720049e-002,0.000000e+000,3,7.903183e-001,1.825000e+000,,,,,,,,,,,,,,,,,,0,4.000000e+000,5.000000e-001,5,1,0.000000e+000,0,,0,
1406875417.031,,5.000000e+001,2.979968e+002,1.475028e-005,0.000000e+000,-1.949515e-002,0.000000e+000,3,8.177739e-001,1.825000e+000,,,,,,,,,,,,,,,,,,0,4.000000e+000,5.000000e-001,5,1,0.000000e+000,0,,0,
1406875435.218,,5.000000e+001,2.979968e+002,1.489076e-005,0.000000e+000,-1.702535e-002,0.000000e+000,3,8.192396e-001,1.825000e+000,,,,,,,,,,,,,,,,,,0,4.000000e+000,5.000000e-001,5,1,0.000000e+000,0,,0,
1406875453.015,,5.000000e+001,2.980009e+002,1.498492e-005,0.000000e+000,-1.546603e-002,0.000000e+000,3,8.205504e-001,1.825000e+000,,,,,,,,,,,,,,,,,,0,4.000000e+000,5.000000e-001,5,1,8.209229e-003,0,,0,
1406875576.015,,7.500000e+001,2.980050e+002,2.344241e-005,0.000000e+000,1.350937e-002,0.000000e+000,3,8.543894e-001,1.825000e+000,,,,,,,,,,,,,,,,,,0,4.000000e+000,5.000000e-001,5,1,0.000000e+000,0,,0,
1406875594.250,,7.500000e+001,2.980009e+002,2.348338e-005,0.000000e+000,1.350786e-002,0.000000e+000,3,8.548871e-001,1.825000e+000,,,,,,,,,,,,,,,,,,0,4.000000e+000,5.000000e-001,5,1,8.209229e-003,0,,0,
1406875613.000,,7.500000e+001,2.979968e+002,2.351398e-005,0.000000e+000,1.393536e-002,0.000000e+000,3,8.547283e-001,1.825000e+000,,,,,,,,,,,,,,,,,,0,4.000000e+000,5.000000e-001,5,1,0.000000e+000,0,,0,
1406875743.265,,1.000000e+002,2.980009e+002,2.962572e-005,0.000000e+000,2.170370e-002,0.000000e+000,3,8.640581e-001,1.825000e+000,,,,,,,,,,,,,,,,,,0,4.000000e+000,5.000000e-001,5,1,8.209229e-003,0,,0,
1406875761.250,,1.000000e+002,2.980009e+002,2.964183e-005,0.000000e+000,2.205786e-002,0.000000e+000,3,8.642423e-001,1.825000e+000,,,,,,,,,,,,,,,,,,0,4.000000e+000,5.000000e-001,5,1,8.209229e-003,0,,0,
1406875779.500,,1.000000e+002,2.979968e+002,2.965379e-005,0.000000e+000,2.227721e-002,0.000000e+000,3,8.642936e-001,1.825000e+000,,,,,,,,,,,,,,,,,,0,4.000000e+000,5.000000e-001,5,1,0.000000e+000,0,,0,