File: Sample Data Files/2014-07-31 EB on isolated PMN-PT no Ti spontaneous in situ repeat/Ni-NiO_298K_SiO2_PMN-PT_5.0Tprebias_125V_Au_back.rso.dat
[Header]
TITLE,MPMS RSO Measurement
BYAPP,MPMS Measurement,1.1,Summary
FILEOPENTIME, 1406858067.531000 7/31/2014, 6:54:27 PM

INFO, APPNAME, MPMS MultiVu Application, Revision 1.58,  Build 076

INFO, NAME, EB in situ 2
INFO, WEIGHT, 0.000
INFO, AREA, 0.000
INFO, LENGTH, 0.000
INFO, SHAPE, 0
INFO, COMMENT,
INFO, SEQUENCE FILE: MHcurveUpTo100.seq


INFO, BACKGROUND DATA FILE:, None


STARTUPAXIS,X,4,LINEAR,AUTO,0.000000,0.000000
STARTUPAXIS,Y1,5,LINEAR,AUTO,0.000000,0.000000


STARTUPGROUP,Longitudinal
FIELDGROUP,Longitudinal,1,2,3,4,5,6,7,8,9,10,11,19,20,21,22,23,35
FIELDGROUP,Transverse,1,2,3,4,12,13,14,15,16,17,18,24,25,26,27,28,35

PLOT_APPEARANCE,ALL,HORZ_GRID_ON,VERT_GRID_ON,MARKERS_AND_LINES

[Data]
Time,Comment,Field (Oe),Temperature (K),Long Moment (emu),Long Scan Std Dev,Long Offset (cm),Long Offset Std Dev,Long Algorithm,Long Reg Fit,Long Reg Factor,Trans Moment (emu),Trans Scan Std Dev,Trans Offset (cm),Trans Offset Std Dev,Trans Algorithm,Trans Reg Fit,Trans Reg Factor,Long Moment [w/o ABS] (emu),Long Scan Std Dev [w/o ABS],Long Offset [w/o ABS] (cm),Long Offset Std Dev [w/o ABS],Long Reg Fit [w/o ABS],Trans Moment [w/o ABS] (emu),Trans Scan Std Dev [w/o ABS],Trans Offset [w/o ABS] (cm),Trans Offset Std Dev [w/o ABS],Trans Reg Fit [w/o ABS],RSO Position (deg),Amplitude (cm),Frequency,Cycles to Average,Scans per Measurement,Delta Temp (K),Error,EC Comp. Running,Using ABS,
1406858067.531,,1.000000e+002,2.980009e+002,3.609869e-005,0.000000e+000,1.383561e-002,0.000000e+000,3,8.861071e-001,1.825000e+000,,,,,,,,,,,,,,,,,,0,4.000000e+000,5.000000e-001,5,1,8.209229e-003,0,,0,
1406858085.015,,1.000000e+002,2.980009e+002,3.610491e-005,0.000000e+000,1.363343e-002,0.000000e+000,3,8.861898e-001,1.825000e+000,,,,,,,,,,,,,,,,,,0,4.000000e+000,5.000000e-001,5,1,8.209229e-003,0,,0,
1406858103.500,,1.000000e+002,2.979926e+002,3.611251e-005,0.000000e+000,1.353327e-002,0.000000e+000,3,8.860871e-001,1.825000e+000,,,,,,,,,,,,,,,,,,0,4.000000e+000,5.000000e-001,5,1,8.300781e-003,0,,0,
1406858226.515,,7.500000e+001,2.979968e+002,3.497247e-005,0.000000e+000,1.417633e-002,0.000000e+000,3,8.922192e-001,1.825000e+000,,,,,,,,,,,,,,,,,,0,4.000000e+000,5.000000e-001,5,1,0.000000e+000,0,,0,
1406858244.750,,7.500000e+001,2.979926e+002,3.498226e-005,0.000000e+000,1.402521e-002,0.000000e+000,3,8.924119e-001,1.825000e+000,,,,,,,,,,,,,,,,,,0,4.000000e+000,5.000000e-001,5,1,8.300781e-003,0,,0,
1406858262.984,,7.500000e+001,2.979968e+002,3.497790e-005,0.000000e+000,1.396230e-002,0.000000e+000,3,8.923957e-001,1.825000e+000,,,,,,,,,,,,,,,,,,0,4.000000e+000,5.000000e-001,5,1,0.000000e+000,0,,0,
1406858393.218,,5.000000e+001,2.980009e+002,3.278883e-005,0.000000e+000,1.578563e-002,0.000000e+000,3,8.971065e-001,1.825000e+000,,,,,,,,,,,,,,,,,,0,4.000000e+000,5.000000e-001,5,1,8.209229e-003,0,,0,
1406858410.953,,5.000000e+001,2.980050e+002,3.279069e-005,0.000000e+000,1.559095e-002,0.000000e+000,3,8.970454e-001,1.825000e+000,,,,,,,,,,,,,,,,,,0,4.000000e+000,5.000000e-001,5,1,0.000000e+000,0,,0,
1406858429.203,,5.000000e+001,2.980009e+002,3.276848e-005,0.000000e+000,1.601799e-002,0.000000e+000,3,8.970004e-001,1.825000e+000,,,,,,,,,,,,,,,,,,0,4.000000e+000,5.000000e-001,5,1,8.209229e-003,0,,0,
1406858541.187,,4.500000e+001,2.979968e+002,3.212805e-005,0.000000e+000,1.658160e-002,0.000000e+000,3,8.976904e-001,1.825000e+000,,,,,,,,,,,,,,,,,,0,4.000000e+000,5.000000e-001,5,1,0.000000e+000,0,,0,
1406858559.171,,4.500000e+001,2.979968e+002,3.211542e-005,0.000000e+000,1.663785e-002,0.000000e+000,3,8.975069e-001,1.825000e+000,,,,,,,,,,,,,,,,,,0,4.000000e+000,5.000000e-001,5,1,0.000000e+000,0,,0,
1406858577.406,,4.500000e+001,2.979968e+002,3.210350e-005,0.000000e+000,1.646238e-002,0.000000e+000,3,8.972332e-001,1.825000e+000,,,,,,,,,,,,,,,,,,0,4.000000e+000,5.000000e-001,5,1,0.000000e+000,0,,0,
1406858694.703,,4.000000e+001,2.979968e+002,3.131797e-005,0.000000e+000,1.813996e-002,0.000000e+000,3,8.978837e-001,1.825000e+000,,,,,,,,,,,,,,,,,,0,4.000000e+000,5.000000e-001,5,1,0.000000e+000,0,,0,
1406858712.937,,4.000000e+001,2.980009e+002,3.131336e-005,0.000000e+000,1.756175e-002,0.000000e+000,3,8.977799e-001,1.825000e+000,,,,,,,,,,,,,,,,,,0,4.000000e+000,5.000000e-001,5,1,8.209229e-003,0,,0,
1406858730.218,,4.000000e+001,2.980009e+002,3.130646e-005,0.000000e+000,1.785149e-002,0.000000e+000,3,8.978834e-001,1.825000e+000,,,,,,,,,,,,,,,,,,0,4.000000e+000,5.000000e-001,5,1,8.209229e-003,0,,0,
1406858848.203,,3.500000e+001,2.980009e+002,3.039845e-005,0.000000e+000,1.930389e-002,0.000000e+000,3,8.978400e-001,1.825000e+000,,,,,,,,,,,,,,,,,,0,4.000000e+000,5.000000e-001,5,1,8.209229e-003,0,,0,
1406858866.437,,3.500000e+001,2.980009e+002,3.038793e-005,0.000000e+000,1.916960e-002,0.000000e+000,3,8.979405e-001,1.825000e+000,,,,,,,,,,,,,,,,,,0,4.000000e+000,5.000000e-001,5,1,8.209229e-003,0,,0,
1406858884.734,,3.500000e+001,2.979968e+002,3.037858e-005,0.000000e+000,1.945683e-002,0.000000e+000,3,8.975355e-001,1.825000e+000,,,,,,,,,,,,,,,,,,0,4.000000e+000,5.000000e-001,5,1,0.000000e+000,0,,0,
1406859002.968,,3.000000e+001,2.979968e+002,2.926835e-005,0.000000e+000,2.098248e-002,0.000000e+000,3,8.972178e-001,1.825000e+000,,,,,,,,,,,,,,,,,,0,4.000000e+000,5.000000e-001,5,1,0.000000e+000,0,,0,
1406859021.203,,3.000000e+001,2.980009e+002,2.925009e-005,0.000000e+000,2.116065e-002,0.000000e+000,3,8.971965e-001,1.825000e+000,,,,,,,,,,,,,,,,,,0,4.000000e+000,5.000000e-001,5,1,8.209229e-003,0,,0,
1406859039.453,,3.000000e+001,2.980009e+002,2.925025e-005,0.000000e+000,2.105496e-002,0.000000e+000,3,8.973733e-001,1.825000e+000,,,,,,,,,,,,,,,,,,0,4.000000e+000,5.000000e-001,5,1,8.209229e-003,0,,0,
1406859157.500,,2.500000e+001,2.979968e+002,2.789426e-005,0.000000e+000,2.355630e-002,0.000000e+000,3,8.960806e-001,1.825000e+000,,,,,,,,,,,,,,,,,,0,4.000000e+000,5.000000e-001,5,1,0.000000e+000,0,,0,
1406859176.234,,2.500000e+001,2.980050e+002,2.786355e-005,0.000000e+000,2.416872e-002,0.000000e+000,3,8.958208e-001,1.825000e+000,,,,,,,,,,,,,,,,,,0,4.000000e+000,5.000000e-001,5,1,1.641846e-002,0,,0,
1406859193.500,,2.500000e+001,2.979968e+002,2.785076e-005,0.000000e+000,2.369663e-002,0.000000e+000,3,8.957437e-001,1.825000e+000,,,,,,,,,,,,,,,,,,0,4.000000e+000,5.000000e-001,5,1,0.000000e+000,0,,0,
1406859310.046,,2.000000e+001,2.979968e+002,2.621821e-005,0.000000e+000,2.769682e-002,0.000000e+000,3,8.935505e-001,1.825000e+000,,,,,,,,,,,,,,,,,,0,4.000000e+000,5.000000e-001,5,1,0.000000e+000,0,,0,
1406859328.296,,2.000000e+001,2.979968e+002,2.618477e-005,0.000000e+000,2.791681e-002,0.000000e+000,3,8.932855e-001,1.825000e+000,,,,,,,,,,,,,,,,,,0,4.000000e+000,5.000000e-001,5,1,1.651001e-002,0,,0,
1406859347.109,,2.000000e+001,2.980009e+002,2.615135e-005,0.000000e+000,2.805231e-002,0.000000e+000,3,8.932015e-001,1.825000e+000,,,,,,,,,,,,,,,,,,0,4.000000e+000,5.000000e-001,5,1,8.209229e-003,0,,0,
1406859457.093,,1.500000e+001,2.980009e+002,2.418776e-005,0.000000e+000,3.275995e-002,0.000000e+000,3,8.894425e-001,1.825000e+000,,,,,,,,,,,,,,,,,,0,4.000000e+000,5.000000e-001,5,1,8.209229e-003,0,,0,
1406859475.328,,1.500000e+001,2.979968e+002,2.412982e-005,0.000000e+000,3.302560e-002,0.000000e+000,3,8.890066e-001,1.825000e+000,,,,,,,,,,,,,,,,,,0,4.000000e+000,5.000000e-001,5,1,0.000000e+000,0,,0,
1406859493.062,,1.500000e+001,2.980009e+002,2.408950e-005,0.000000e+000,3.313632e-002,0.000000e+000,3,8.889068e-001,1.825000e+000,,,,,,,,,,,,,,,,,,0,4.000000e+000,5.000000e-001,5,1,8.209229e-003,0,,0,
1406859609.562,,1.000000e+001,2.979968e+002,2.151121e-005,0.000000e+000,4.180183e-002,0.000000e+000,3,8.821365e-001,1.825000e+000,,,,,,,,,,,,,,,,,,0,4.000000e+000,5.000000e-001,5,1,0.000000e+000,0,,0,
1406859627.296,,1.000000e+001,2.980009e+002,2.143470e-005,0.000000e+000,4.162988e-002,0.000000e+000,3,8.813330e-001,1.825000e+000,,,,,,,,,,,,,,,,,,0,4.000000e+000,5.000000e-001,5,1,8.209229e-003,0,,0,
1406859645.296,,1.000000e+001,2.980009e+002,2.138479e-005,0.000000e+000,4.209736e-002,0.000000e+000,3,8.812959e-001,1.825000e+000,,,,,,,,,,,,,,,,,,0,4.000000e+000,5.000000e-001,5,1,8.209229e-003,0,,0,
1406859763.031,,5.000000e+000,2.980009e+002,1.776639e-005,0.000000e+000,5.882314e-002,0.000000e+000,3,8.660136e-001,1.825000e+000,,,,,,,,,,,,,,,,,,0,4.000000e+000,5.000000e-001,5,1,8.209229e-003,0,,0,
1406859780.765,,5.000000e+000,2.980050e+002,1.763134e-005,0.000000e+000,5.978861e-002,0.000000e+000,3,8.646562e-001,1.825000e+000,,,,,,,,,,,,,,,,,,0,4.000000e+000,5.000000e-001,5,1,0.000000e+000,0,,0,
1406859798.500,,5.000000e+000,2.980009e+002,1.751185e-005,0.000000e+000,6.098271e-002,0.000000e+000,3,8.639407e-001,1.825000e+000,,,,,,,,,,,,,,,,,,0,4.000000e+000,5.000000e-001,5,1,8.209229e-003,0,,0,
1406859915.234,,0.000000e+000,2.979968e+002,1.103200e-005,0.000000e+000,1.226062e-001,0.000000e+000,3,8.061187e-001,1.825000e+000,,,,,,,,,,,,,,,,,,0,4.000000e+000,5.000000e-001,5,1,0.000000e+000,0,,0,
1406859933.484,,0.000000e+000,2.979968e+002,1.061457e-005,0.000000e+000,1.300500e-001,0.000000e+000,3,7.992731e-001,1.825000e+000,,,,,,,,,,,,,,,,,,0,4.000000e+000,5.000000e-001,5,1,0.000000e+000,0,,0,
1406859951.218,,0.000000e+000,2.979968e+002,1.028146e-005,0.000000e+000,1.370076e-001,0.000000e+000,3,7.926331e-001,1.825000e+000,,,,,,,,,,,,,,,,,,0,4.000000e+000,5.000000e-001,5,1,0.000000e+000,0,,0,
1406860084.000,,-5.000000e+000,2.979968e+002,-3.220398e-006,0.000000e+000,-3.122252e-001,0.000000e+000,3,3.282405e-001,1.825000e+000,,,,,,,,,,,,,,,,,,0,4.000000e+000,5.000000e-001,5,1,0.000000e+000,0,,0,
1406860101.734,,-5.000000e+000,2.980009e+002,-3.685430e-006,0.000000e+000,-2.621277e-001,0.000000e+000,3,4.201509e-001,1.825000e+000,,,,,,,,,,,,,,,,,,0,4.000000e+000,5.000000e-001,5,1,8.209229e-003,0,,0,
1406860119.968,,-5.000000e+000,2.979968e+002,-4.081170e-006,0.000000e+000,-2.311844e-001,0.000000e+000,3,4.800864e-001,1.825000e+000,,,,,,,,,,,,,,,,,,0,4.000000e+000,5.000000e-001,5,1,0.000000e+000,0,,0,
1406860243.218,,-1.000000e+001,2.980009e+002,-1.317890e-005,0.000000e+000,-5.310072e-002,0.000000e+000,3,8.589526e-001,1.825000e+000,,,,,,,,,,,,,,,,,,0,4.000000e+000,5.000000e-001,5,1,8.209229e-003,0,,0,
1406860261.015,,-1.000000e+001,2.980009e+002,-1.358814e-005,0.000000e+000,-4.953281e-002,0.000000e+000,3,8.632344e-001,1.825000e+000,,,,,,,,,,,,,,,,,,0,4.000000e+000,5.000000e-001,5,1,8.209229e-003,0,,0,
1406860279.000,,-1.000000e+001,2.980009e+002,-1.389369e-005,0.000000e+000,-4.715735e-002,0.000000e+000,3,8.667417e-001,1.825000e+000,,,,,,,,,,,,,,,,,,0,4.000000e+000,5.000000e-001,5,1,8.209229e-003,0,,0,
1406860389.812,,-1.500000e+001,2.979968e+002,-1.807419e-005,0.000000e+000,-2.201462e-002,0.000000e+000,3,9.069762e-001,1.825000e+000,,,,,,,,,,,,,,,,,,0,4.000000e+000,5.000000e-001,5,1,0.000000e+000,0,,0,
1406860408.796,,-1.500000e+001,2.980009e+002,-1.827519e-005,0.000000e+000,-2.093128e-002,0.000000e+000,3,9.081022e-001,1.825000e+000,,,,,,,,,,,,,,,,,,0,4.000000e+000,5.000000e-001,5,1,8.209229e-003,0,,0,
1406860426.031,,-1.500000e+001,2.979968e+002,-1.841399e-005,0.000000e+000,-1.991961e-002,0.000000e+000,3,9.095978e-001,1.825000e+000,,,,,,,,,,,,,,,,,,0,4.000000e+000,5.000000e-001,5,1,0.000000e+000,0,,0,
1406860543.531,,-2.000000e+001,2.979968e+002,-2.095080e-005,0.000000e+000,-5.619074e-003,0.000000e+000,3,9.287300e-001,1.825000e+000,,,,,,,,,,,,,,,,,,0,4.000000e+000,5.000000e-001,5,1,1.651001e-002,0,,0,
1406860561.515,,-2.000000e+001,2.980009e+002,-2.106861e-005,0.000000e+000,-4.884538e-003,0.000000e+000,3,9.286776e-001,1.825000e+000,,,,,,,,,,,,,,,,,,0,4.000000e+000,5.000000e-001,5,1,8.209229e-003,0,,0,
1406860579.578,,-2.000000e+001,2.979968e+002,-2.117858e-005,0.000000e+000,-4.497258e-003,0.000000e+000,3,9.291956e-001,1.825000e+000,,,,,,,,,,,,,,,,,,0,4.000000e+000,5.000000e-001,5,1,0.000000e+000,0,,0,
1406860697.562,,-2.500000e+001,2.980009e+002,-2.352270e-005,0.000000e+000,1.200391e-002,0.000000e+000,3,9.439929e-001,1.825000e+000,,,,,,,,,,,,,,,,,,0,4.000000e+000,5.000000e-001,5,1,8.209229e-003,0,,0,
1406860715.796,,-2.500000e+001,2.980009e+002,-2.371659e-005,0.000000e+000,1.294011e-002,0.000000e+000,3,9.447808e-001,1.825000e+000,,,,,,,,,,,,,,,,,,0,4.000000e+000,5.000000e-001,5,1,8.209229e-003,0,,0,
1406860734.078,,-2.500000e+001,2.980009e+002,-2.385740e-005,0.000000e+000,1.409062e-002,0.000000e+000,3,9.454312e-001,1.825000e+000,,,,,,,,,,,,,,,,,,0,4.000000e+000,5.000000e-001,5,1,8.209229e-003,0,,0,
1406860845.359,,-3.000000e+001,2.979968e+002,-2.586911e-005,0.000000e+000,2.685594e-002,0.000000e+000,3,9.557215e-001,1.825000e+000,,,,,,,,,,,,,,,,,,0,4.000000e+000,5.000000e-001,5,1,0.000000e+000,0,,0,
1406860862.609,,-3.000000e+001,2.979968e+002,-2.597999e-005,0.000000e+000,2.755673e-002,0.000000e+000,3,9.556747e-001,1.825000e+000,,,,,,,,,,,,,,,,,,0,4.000000e+000,5.000000e-001,5,1,0.000000e+000,0,,0,
1406860880.093,,-3.000000e+001,2.979968e+002,-2.601890e-005,0.000000e+000,2.776988e-002,0.000000e+000,3,9.557355e-001,1.825000e+000,,,,,,,,,,,,,,,,,,0,4.000000e+000,5.000000e-001,5,1,0.000000e+000,0,,0,
1406860996.515,,-3.500000e+001,2.980009e+002,-2.672191e-005,0.000000e+000,3.027392e-002,0.000000e+000,3,9.613293e-001,1.825000e+000,,,,,,,,,,,,,,,,,,0,4.000000e+000,5.000000e-001,5,1,8.209229e-003,0,,0,
1406861014.375,,-3.500000e+001,2.980050e+002,-2.673781e-005,0.000000e+000,3.016642e-002,0.000000e+000,3,9.616162e-001,1.825000e+000,,,,,,,,,,,,,,,,,,0,4.000000e+000,5.000000e-001,5,1,0.000000e+000,0,,0,
1406861032.859,,-3.500000e+001,2.979968e+002,-2.675190e-005,0.000000e+000,3.030705e-002,0.000000e+000,3,9.614523e-001,1.825000e+000,,,,,,,,,,,,,,,,,,0,4.000000e+000,5.000000e-001,5,1,0.000000e+000,0,,0,
1406861150.359,,-4.000000e+001,2.979968e+002,-2.731953e-005,0.000000e+000,3.229007e-002,0.000000e+000,3,9.660998e-001,1.825000e+000,,,,,,,,,,,,,,,,,,0,4.000000e+000,5.000000e-001,5,1,0.000000e+000,0,,0,
1406861167.640,,-4.000000e+001,2.979968e+002,-2.733276e-005,0.000000e+000,3.231628e-002,0.000000e+000,3,9.661331e-001,1.825000e+000,,,,,,,,,,,,,,,,,,0,4.000000e+000,5.000000e-001,5,1,0.000000e+000,0,,0,
1406861186.125,,-4.000000e+001,2.980009e+002,-2.734317e-005,0.000000e+000,3.232954e-002,0.000000e+000,3,9.663002e-001,1.825000e+000,,,,,,,,,,,,,,,,,,0,4.000000e+000,5.000000e-001,5,1,8.209229e-003,0,,0,
1406861320.609,,-4.500000e+001,2.979968e+002,-2.782456e-005,0.000000e+000,3.365696e-002,0.000000e+000,3,9.700350e-001,1.825000e+000,,,,,,,,,,,,,,,,,,0,4.000000e+000,5.000000e-001,5,1,0.000000e+000,0,,0,
1406861337.843,,-4.500000e+001,2.980009e+002,-2.781896e-005,0.000000e+000,3.375734e-002,0.000000e+000,3,9.701601e-001,1.825000e+000,,,,,,,,,,,,,,,,,,0,4.000000e+000,5.000000e-001,5,1,8.209229e-003,0,,0,
1406861355.578,,-4.500000e+001,2.980009e+002,-2.782673e-005,0.000000e+000,3.366507e-002,0.000000e+000,3,9.702080e-001,1.825000e+000,,,,,,,,,,,,,,,,,,0,4.000000e+000,5.000000e-001,5,1,8.209229e-003,0,,0,
1406861471.828,,-5.000000e+001,2.979968e+002,-2.826873e-005,0.000000e+000,3.642984e-002,0.000000e+000,3,9.741381e-001,1.825000e+000,,,,,,,,,,,,,,,,,,0,4.000000e+000,5.000000e-001,5,1,0.000000e+000,0,,0,
1406861489.812,,-5.000000e+001,2.980009e+002,-2.827301e-005,0.000000e+000,3.635972e-002,0.000000e+000,3,9.742597e-001,1.825000e+000,,,,,,,,,,,,,,,,,,0,4.000000e+000,5.000000e-001,5,1,8.209229e-003,0,,0,
1406861508.296,,-5.000000e+001,2.979968e+002,-2.827993e-005,0.000000e+000,3.658434e-002,0.000000e+000,3,9.738260e-001,1.825000e+000,,,,,,,,,,,,,,,,,,0,4.000000e+000,5.000000e-001,5,1,0.000000e+000,0,,0,
1406861660.515,,-7.500000e+001,2.979968e+002,-2.974864e-005,0.000000e+000,3.921429e-002,0.000000e+000,3,9.821424e-001,1.825000e+000,,,,,,,,,,,,,,,,,,0,4.000000e+000,5.000000e-001,5,1,0.000000e+000,0,,0,
1406861678.250,,-7.500000e+001,2.979968e+002,-2.974881e-005,0.000000e+000,3.963645e-002,0.000000e+000,3,9.825714e-001,1.825000e+000,,,,,,,,,,,,,,,,,,0,4.000000e+000,5.000000e-001,5,1,0.000000e+000,0,,0,
1406861695.984,,-7.500000e+001,2.980009e+002,-2.976034e-005,0.000000e+000,3.941565e-002,0.000000e+000,3,9.825540e-001,1.825000e+000,,,,,,,,,,,,,,,,,,0,4.000000e+000,5.000000e-001,5,1,8.209229e-003,0,,0,
1406861848.640,,-1.000000e+002,2.980050e+002,-3.075621e-005,0.000000e+000,3.814851e-002,0.000000e+000,3,9.757699e-001,1.825000e+000,,,,,,,,,,,,,,,,,,0,4.000000e+000,5.000000e-001,5,1,1.641846e-002,0,,0,
1406861866.125,,-1.000000e+002,2.980009e+002,-3.063894e-005,0.000000e+000,3.943542e-002,0.000000e+000,3,9.766663e-001,1.825000e+000,,,,,,,,,,,,,,,,,,0,4.000000e+000,5.000000e-001,5,1,8.209229e-003,0,,0,
1406861883.921,,-1.000000e+002,2.980009e+002,-3.070133e-005,0.000000e+000,3.993032e-002,0.000000e+000,3,9.777045e-001,1.825000e+000,,,,,,,,,,,,,,,,,,0,4.000000e+000,5.000000e-001,5,1,8.209229e-003,0,,0,
1406862022.953,,-7.500000e+001,2.979968e+002,-3.006458e-005,0.000000e+000,3.942949e-002,0.000000e+000,3,9.822356e-001,1.825000e+000,,,,,,,,,,,,,,,,,,0,4.000000e+000,5.000000e-001,5,1,0.000000e+000,0,,0,
1406862041.203,,-7.500000e+001,2.980009e+002,-3.006965e-005,0.000000e+000,3.920664e-002,0.000000e+000,3,9.822337e-001,1.825000e+000,,,,,,,,,,,,,,,,,,0,4.000000e+000,5.000000e-001,5,1,8.209229e-003,0,,0,
1406862059.437,,-7.500000e+001,2.979968e+002,-3.006532e-005,0.000000e+000,3.930218e-002,0.000000e+000,3,9.820804e-001,1.825000e+000,,,,,,,,,,,,,,,,,,0,4.000000e+000,5.000000e-001,5,1,0.000000e+000,0,,0,
1406862184.234,,-5.000000e+001,2.980009e+002,-2.899532e-005,0.000000e+000,4.025320e-002,0.000000e+000,3,9.807711e-001,1.825000e+000,,,,,,,,,,,,,,,,,,0,4.000000e+000,5.000000e-001,5,1,8.209229e-003,0,,0,
1406862201.500,,-5.000000e+001,2.979968e+002,-2.900242e-005,0.000000e+000,4.049383e-002,0.000000e+000,3,9.804361e-001,1.825000e+000,,,,,,,,,,,,,,,,,,0,4.000000e+000,5.000000e-001,5,1,0.000000e+000,0,,0,
1406862219.937,,-5.000000e+001,2.980009e+002,-2.900301e-005,0.000000e+000,4.002422e-002,0.000000e+000,3,9.807285e-001,1.825000e+000,,,,,,,,,,,,,,,,,,0,4.000000e+000,5.000000e-001,5,1,8.209229e-003,0,,0,
1406862336.312,,-4.500000e+001,2.979968e+002,-2.869203e-005,0.000000e+000,4.093037e-002,0.000000e+000,3,9.792811e-001,1.825000e+000,,,,,,,,,,,,,,,,,,0,4.000000e+000,5.000000e-001,5,1,0.000000e+000,0,,0,
1406862354.046,,-4.500000e+001,2.980050e+002,-2.870408e-005,0.000000e+000,4.073834e-002,0.000000e+000,3,9.792187e-001,1.825000e+000,,,,,,,,,,,,,,,,,,0,4.000000e+000,5.000000e-001,5,1,0.000000e+000,0,,0,
1406862372.031,,-4.500000e+001,2.980050e+002,-2.870417e-005,0.000000e+000,4.059515e-002,0.000000e+000,3,9.791197e-001,1.825000e+000,,,,,,,,,,,,,,,,,,0,4.000000e+000,5.000000e-001,5,1,1.641846e-002,0,,0,
1406862489.265,,-4.000000e+001,2.980009e+002,-2.835217e-005,0.000000e+000,4.148069e-002,0.000000e+000,3,9.772642e-001,1.825000e+000,,,,,,,,,,,,,,,,,,0,4.000000e+000,5.000000e-001,5,1,2.471924e-002,0,,0,
1406862506.046,,-4.000000e+001,2.979968e+002,-2.835464e-005,0.000000e+000,4.124810e-002,0.000000e+000,3,9.773214e-001,1.825000e+000,,,,,,,,,,,,,,,,,,0,4.000000e+000,5.000000e-001,5,1,0.000000e+000,0,,0,
1406862523.578,,-4.000000e+001,2.980009e+002,-2.835429e-005,0.000000e+000,4.137716e-002,0.000000e+000,3,9.773067e-001,1.825000e+000,,,,,,,,,,,,,,,,,,0,4.000000e+000,5.000000e-001,5,1,8.209229e-003,0,,0,
1406862639.328,,-3.500000e+001,2.980009e+002,-2.796070e-005,0.000000e+000,4.196676e-002,0.000000e+000,3,9.752058e-001,1.825000e+000,,,,,,,,,,,,,,,,,,0,4.000000e+000,5.000000e-001,5,1,8.209229e-003,0,,0,
1406862657.562,,-3.500000e+001,2.979968e+002,-2.796359e-005,0.000000e+000,4.180387e-002,0.000000e+000,3,9.752408e-001,1.825000e+000,,,,,,,,,,,,,,,,,,0,4.000000e+000,5.000000e-001,5,1,0.000000e+000,0,,0,
1406862674.843,,-3.500000e+001,2.980009e+002,-2.796649e-005,0.000000e+000,4.170889e-002,0.000000e+000,3,9.754651e-001,1.825000e+000,,,,,,,,,,,,,,,,,,0,4.000000e+000,5.000000e-001,5,1,8.209229e-003,0,,0,
1406862791.578,,-3.000000e+001,2.979968e+002,-2.752978e-005,0.000000e+000,4.227193e-002,0.000000e+000,3,9.729993e-001,1.825000e+000,,,,,,,,,,,,,,,,,,0,4.000000e+000,5.000000e-001,5,1,0.000000e+000,0,,0,
1406862809.859,,-3.000000e+001,2.979968e+002,-2.752435e-005,0.000000e+000,4.248371e-002,0.000000e+000,3,9.728928e-001,1.825000e+000,,,,,,,,,,,,,,,,,,0,4.000000e+000,5.000000e-001,5,1,0.000000e+000,0,,0,
1406862828.093,,-3.000000e+001,2.980009e+002,-2.752112e-005,0.000000e+000,4.262367e-002,0.000000e+000,3,9.727668e-001,1.825000e+000,,,,,,,,,,,,,,,,,,0,4.000000e+000,5.000000e-001,5,1,8.209229e-003,0,,0,
1406862945.843,,-2.500000e+001,2.979968e+002,-2.701756e-005,0.000000e+000,4.356641e-002,0.000000e+000,3,9.701331e-001,1.825000e+000,,,,,,,,,,,,,,,,,,0,4.000000e+000,5.000000e-001,5,1,0.000000e+000,0,,0,
1406862964.078,,-2.500000e+001,2.979968e+002,-2.701465e-005,0.000000e+000,4.362274e-002,0.000000e+000,3,9.700952e-001,1.825000e+000,,,,,,,,,,,,,,,,,,0,4.000000e+000,5.000000e-001,5,1,0.000000e+000,0,,0,
1406862982.375,,-2.500000e+001,2.980009e+002,-2.701594e-005,0.000000e+000,4.345158e-002,0.000000e+000,3,9.698889e-001,1.825000e+000,,,,,,,,,,,,,,,,,,0,4.000000e+000,5.000000e-001,5,1,8.209229e-003,0,,0,
1406863100.140,,-2.000000e+001,2.979968e+002,-2.641099e-005,0.000000e+000,4.447109e-002,0.000000e+000,3,9.665813e-001,1.825000e+000,,,,,,,,,,,,,,,,,,0,4.000000e+000,5.000000e-001,5,1,1.651001e-002,0,,0,
1406863118.671,,-2.000000e+001,2.979968e+002,-2.641106e-005,0.000000e+000,4.444047e-002,0.000000e+000,3,9.665829e-001,1.825000e+000,,,,,,,,,,,,,,,,,,0,4.000000e+000,5.000000e-001,5,1,0.000000e+000,0,,0,
1406863136.921,,-2.000000e+001,2.980050e+002,-2.640571e-005,0.000000e+000,4.459658e-002,0.000000e+000,3,9.667350e-001,1.825000e+000,,,,,,,,,,,,,,,,,,0,4.000000e+000,5.000000e-001,5,1,0.000000e+000,0,,0,
1406863248.921,,-1.500000e+001,2.979968e+002,-2.571142e-005,0.000000e+000,4.635205e-002,0.000000e+000,3,9.633158e-001,1.825000e+000,,,,,,,,,,,,,,,,,,0,4.000000e+000,5.000000e-001,5,1,0.000000e+000,0,,0,
1406863266.656,,-1.500000e+001,2.979968e+002,-2.571225e-005,0.000000e+000,4.627166e-002,0.000000e+000,3,9.630296e-001,1.825000e+000,,,,,,,,,,,,,,,,,,0,4.000000e+000,5.000000e-001,5,1,0.000000e+000,0,,0,
1406863283.921,,-1.500000e+001,2.980009e+002,-2.571182e-005,0.000000e+000,4.618511e-002,0.000000e+000,3,9.631917e-001,1.825000e+000,,,,,,,,,,,,,,,,,,0,4.000000e+000,5.000000e-001,5,1,8.209229e-003,0,,0,
1406863401.218,,-1.000000e+001,2.980050e+002,-2.487529e-005,0.000000e+000,4.819741e-002,0.000000e+000,3,9.587497e-001,1.825000e+000,,,,,,,,,,,,,,,,,,0,4.000000e+000,5.000000e-001,5,1,0.000000e+000,0,,0,
1406863418.953,,-1.000000e+001,2.980009e+002,-2.485767e-005,0.000000e+000,4.814366e-002,0.000000e+000,3,9.588429e-001,1.825000e+000,,,,,,,,,,,,,,,,,,0,4.000000e+000,5.000000e-001,5,1,8.209229e-003,0,,0,
1406863437.203,,-1.000000e+001,2.979968e+002,-2.484432e-005,0.000000e+000,4.825650e-002,0.000000e+000,3,9.584190e-001,1.825000e+000,,,,,,,,,,,,,,,,,,0,4.000000e+000,5.000000e-001,5,1,0.000000e+000,0,,0,
1406863560.968,,-5.000000e+000,2.980009e+002,-2.380651e-005,0.000000e+000,5.098411e-002,0.000000e+000,3,9.532673e-001,1.825000e+000,,,,,,,,,,,,,,,,,,0,4.000000e+000,5.000000e-001,5,1,8.209229e-003,0,,0,
1406863579.265,,-5.000000e+000,2.979968e+002,-2.380520e-005,0.000000e+000,5.088379e-002,0.000000e+000,3,9.531701e-001,1.825000e+000,,,,,,,,,,,,,,,,,,0,4.000000e+000,5.000000e-001,5,1,1.651001e-002,0,,0,
1406863597.500,,-5.000000e+000,2.980009e+002,-2.379711e-005,0.000000e+000,5.088698e-002,0.000000e+000,3,9.530410e-001,1.825000e+000,,,,,,,,,,,,,,,,,,0,4.000000e+000,5.000000e-001,5,1,8.209229e-003,0,,0,
1406863714.734,,0.000000e+000,2.979926e+002,-2.260373e-005,0.000000e+000,5.465661e-002,0.000000e+000,3,9.467923e-001,1.825000e+000,,,,,,,,,,,,,,,,,,0,4.000000e+000,5.000000e-001,5,1,8.300781e-003,0,,0,
1406863732.484,,0.000000e+000,2.980050e+002,-2.258526e-005,0.000000e+000,5.461380e-002,0.000000e+000,3,9.460884e-001,1.825000e+000,,,,,,,,,,,,,,,,,,0,4.000000e+000,5.000000e-001,5,1,0.000000e+000,0,,0,
1406863749.968,,0.000000e+000,2.980050e+002,-2.257587e-005,0.000000e+000,5.471463e-002,0.000000e+000,3,9.466148e-001,1.825000e+000,,,,,,,,,,,,,,,,,,0,4.000000e+000,5.000000e-001,5,1,0.000000e+000,0,,0,
1406863868.468,,5.000000e+000,2.980009e+002,-2.102193e-005,0.000000e+000,5.999736e-002,0.000000e+000,3,9.378316e-001,1.825000e+000,,,,,,,,,,,,,,,,,,0,4.000000e+000,5.000000e-001,5,1,8.209229e-003,0,,0,
1406863885.765,,5.000000e+000,2.980009e+002,-2.099262e-005,0.000000e+000,6.066191e-002,0.000000e+000,3,9.374827e-001,1.825000e+000,,,,,,,,,,,,,,,,,,0,4.000000e+000,5.000000e-001,5,1,8.209229e-003,0,,0,
1406863903.531,,5.000000e+000,2.980050e+002,-2.098256e-005,0.000000e+000,6.031229e-002,0.000000e+000,3,9.376308e-001,1.825000e+000,,,,,,,,,,,,,,,,,,0,4.000000e+000,5.000000e-001,5,1,0.000000e+000,0,,0,
1406864028.265,,1.000000e+001,2.980009e+002,-1.908677e-005,0.000000e+000,6.812897e-002,0.000000e+000,3,9.254355e-001,1.825000e+000,,,,,,,,,,,,,,,,,,0,4.000000e+000,5.000000e-001,5,1,8.209229e-003,0,,0,
1406864046.031,,1.000000e+001,2.980009e+002,-1.905404e-005,0.000000e+000,6.832205e-002,0.000000e+000,3,9.253237e-001,1.825000e+000,,,,,,,,,,,,,,,,,,0,4.000000e+000,5.000000e-001,5,1,8.209229e-003,0,,0,
1406864064.515,,1.000000e+001,2.979968e+002,-1.903578e-005,0.000000e+000,6.814714e-002,0.000000e+000,3,9.254510e-001,1.825000e+000,,,,,,,,,,,,,,,,,,0,4.000000e+000,5.000000e-001,5,1,0.000000e+000,0,,0,
1406864175.031,,1.500000e+001,2.979968e+002,-1.679232e-005,0.000000e+000,8.011906e-002,0.000000e+000,3,9.086171e-001,1.825000e+000,,,,,,,,,,,,,,,,,,0,4.000000e+000,5.000000e-001,5,1,1.651001e-002,0,,0,
1406864192.765,,1.500000e+001,2.979968e+002,-1.673660e-005,0.000000e+000,8.010978e-002,0.000000e+000,3,9.081509e-001,1.825000e+000,,,,,,,,,,,,,,,,,,0,4.000000e+000,5.000000e-001,5,1,1.651001e-002,0,,0,
1406864211.000,,1.500000e+001,2.979885e+002,-1.668978e-005,0.000000e+000,8.027901e-002,0.000000e+000,3,9.080341e-001,1.825000e+000,,,,,,,,,,,,,,,,,,0,4.000000e+000,5.000000e-001,5,1,0.000000e+000,0,,0,
1406864329.484,,2.000000e+001,2.979968e+002,-1.339872e-005,0.000000e+000,1.047469e-001,0.000000e+000,3,8.743097e-001,1.825000e+000,,,,,,,,,,,,,,,,,,0,4.000000e+000,5.000000e-001,5,1,0.000000e+000,0,,0,
1406864348.218,,2.000000e+001,2.980009e+002,-1.331820e-005,0.000000e+000,1.061333e-001,0.000000e+000,3,8.729429e-001,1.825000e+000,,,,,,,,,,,,,,,,,,0,4.000000e+000,5.000000e-001,5,1,8.209229e-003,0,,0,
1406864365.953,,2.000000e+001,2.980009e+002,-1.324629e-005,0.000000e+000,1.068751e-001,0.000000e+000,3,8.724516e-001,1.825000e+000,,,,,,,,,,,,,,,,,,0,4.000000e+000,5.000000e-001,5,1,8.209229e-003,0,,0,
1406864500.953,,2.500000e+001,2.980009e+002,-7.426289e-006,0.000000e+000,1.975343e-001,0.000000e+000,3,7.354589e-001,1.825000e+000,,,,,,,,,,,,,,,,,,0,4.000000e+000,5.000000e-001,5,1,8.209229e-003,0,,0,
1406864517.968,,2.500000e+001,2.980009e+002,-7.231487e-006,0.000000e+000,2.039188e-001,0.000000e+000,3,7.268472e-001,1.825000e+000,,,,,,,,,,,,,,,,,,0,4.000000e+000,5.000000e-001,5,1,8.209229e-003,0,,0,
1406864535.703,,2.500000e+001,2.979968e+002,-7.048467e-006,0.000000e+000,2.098008e-001,0.000000e+000,3,7.185889e-001,1.825000e+000,,,,,,,,,,,,,,,,,,0,4.000000e+000,5.000000e-001,5,1,0.000000e+000,0,,0,
1406864647.437,,3.000000e+001,2.979968e+002,6.646442e-006,0.000000e+000,-3.786325e-001,0.000000e+000,3,7.517918e-001,1.825000e+000,,,,,,,,,,,,,,,,,,0,4.000000e+000,5.000000e-001,5,1,0.000000e+000,0,,0,
1406864666.218,,3.000000e+001,2.980009e+002,7.140314e-006,0.000000e+000,-3.404371e-001,0.000000e+000,3,7.644789e-001,1.825000e+000,,,,,,,,,,,,,,,,,,0,4.000000e+000,5.000000e-001,5,1,8.209229e-003,0,,0,
1406864683.968,,3.000000e+001,2.980009e+002,7.535252e-006,0.000000e+000,-3.160082e-001,0.000000e+000,3,7.720606e-001,1.825000e+000,,,,,,,,,,,,,,,,,,0,4.000000e+000,5.000000e-001,5,1,8.209229e-003,0,,0,
1406864803.734,,3.500000e+001,2.980009e+002,1.872147e-005,0.000000e+000,-8.657209e-002,0.000000e+000,3,8.860800e-001,1.825000e+000,,,,,,,,,,,,,,,,,,0,4.000000e+000,5.000000e-001,5,1,8.209229e-003,0,,0,
1406864821.968,,3.500000e+001,2.979968e+002,1.914940e-005,0.000000e+000,-8.305006e-002,0.000000e+000,3,8.887565e-001,1.825000e+000,,,,,,,,,,,,,,,,,,0,4.000000e+000,5.000000e-001,5,1,0.000000e+000,0,,0,
1406864840.203,,3.500000e+001,2.980009e+002,1.947421e-005,0.000000e+000,-8.115077e-002,0.000000e+000,3,8.901631e-001,1.825000e+000,,,,,,,,,,,,,,,,,,0,4.000000e+000,5.000000e-001,5,1,8.209229e-003,0,,0,
1406864958.437,,4.000000e+001,2.979926e+002,2.465658e-005,0.000000e+000,-4.464813e-002,0.000000e+000,3,9.031516e-001,1.825000e+000,,,,,,,,,,,,,,,,,,0,4.000000e+000,5.000000e-001,5,1,8.300781e-003,0,,0,
1406864977.171,,4.000000e+001,2.980050e+002,2.482875e-005,0.000000e+000,-4.383592e-002,0.000000e+000,3,9.035949e-001,1.825000e+000,,,,,,,,,,,,,,,,,,0,4.000000e+000,5.000000e-001,5,1,0.000000e+000,0,,0,
1406864994.406,,4.000000e+001,2.980009e+002,2.495122e-005,0.000000e+000,-4.337802e-002,0.000000e+000,3,9.040098e-001,1.825000e+000,,,,,,,,,,,,,,,,,,0,4.000000e+000,5.000000e-001,5,1,8.209229e-003,0,,0,
1406865110.906,,4.500000e+001,2.980009e+002,2.750182e-005,0.000000e+000,-2.860579e-002,0.000000e+000,3,9.062172e-001,1.825000e+000,,,,,,,,,,,,,,,,,,0,4.000000e+000,5.000000e-001,5,1,8.209229e-003,0,,0,
1406865129.171,,4.500000e+001,2.979968e+002,2.763906e-005,0.000000e+000,-2.755790e-002,0.000000e+000,3,9.064406e-001,1.825000e+000,,,,,,,,,,,,,,,,,,0,4.000000e+000,5.000000e-001,5,1,0.000000e+000,0,,0,
1406865147.406,,4.500000e+001,2.980009e+002,2.773709e-005,0.000000e+000,-2.719065e-002,0.000000e+000,3,9.065917e-001,1.825000e+000,,,,,,,,,,,,,,,,,,0,4.000000e+000,5.000000e-001,5,1,8.209229e-003,0,,0,
1406865266.390,,5.000000e+001,2.979968e+002,3.025826e-005,0.000000e+000,-1.058510e-002,0.000000e+000,3,9.077396e-001,1.825000e+000,,,,,,,,,,,,,,,,,,0,4.000000e+000,5.000000e-001,5,1,0.000000e+000,0,,0,
1406865284.125,,5.000000e+001,2.980009e+002,3.041742e-005,0.000000e+000,-9.127056e-003,0.000000e+000,3,9.077377e-001,1.825000e+000,,,,,,,,,,,,,,,,,,0,4.000000e+000,5.000000e-001,5,1,8.209229e-003,0,,0,
1406865301.859,,5.000000e+001,2.980050e+002,3.054888e-005,0.000000e+000,-8.095319e-003,0.000000e+000,3,9.080234e-001,1.825000e+000,,,,,,,,,,,,,,,,,,0,4.000000e+000,5.000000e-001,5,1,1.641846e-002,0,,0,
1406865426.375,,7.500000e+001,2.979968e+002,3.468750e-005,0.000000e+000,1.329830e-002,0.000000e+000,3,8.977371e-001,1.825000e+000,,,,,,,,,,,,,,,,,,0,4.000000e+000,5.000000e-001,5,1,0.000000e+000,0,,0,
1406865443.421,,7.500000e+001,2.979926e+002,3.470731e-005,0.000000e+000,1.347958e-002,0.000000e+000,3,8.975919e-001,1.825000e+000,,,,,,,,,,,,,,,,,,0,4.000000e+000,5.000000e-001,5,1,8.300781e-003,0,,0,
1406865461.171,,7.500000e+001,2.979968e+002,3.471419e-005,0.000000e+000,1.349866e-002,0.000000e+000,3,8.977933e-001,1.825000e+000,,,,,,,,,,,,,,,,,,0,4.000000e+000,5.000000e-001,5,1,0.000000e+000,0,,0,
1406865584.656,,1.000000e+002,2.979968e+002,3.628641e-005,0.000000e+000,1.620673e-002,0.000000e+000,3,8.865905e-001,1.825000e+000,,,,,,,,,,,,,,,,,,0,4.000000e+000,5.000000e-001,5,1,1.651001e-002,0,,0,
1406865603.140,,1.000000e+002,2.979885e+002,3.628813e-005,0.000000e+000,1.617005e-002,0.000000e+000,3,8.867875e-001,1.825000e+000,,,,,,,,,,,,,,,,,,0,4.000000e+000,5.000000e-001,5,1,0.000000e+000,0,,0,
1406865621.390,,1.000000e+002,2.979885e+002,3.629707e-005,0.000000e+000,1.598712e-002,0.000000e+000,3,8.867568e-001,1.825000e+000,,,,,,,,,,,,,,,,,,0,4.000000e+000,5.000000e-001,5,1,0.000000e+000,0,,0,