File: Sample Data Files/2014-07-31 EB on isolated PMN-PT no Ti spontaneous in situ repeat/Ni-NiO_298K_SiO2_PMN-PT_5.0Tprebias_200V_Au_back.rso.raw
[Header]
TITLE,MPMS RSO Measurement
BYAPP,MPMS Measurement,2.1,Raw with ABS
FILEOPENTIME, 1406898598.062000 8/1/2014, 6:09:58 AM

INFO, APPNAME, MPMS MultiVu Application, Revision 1.58,  Build 076

INFO, NAME, EB in situ 2
INFO, WEIGHT, 0.000
INFO, AREA, 0.000
INFO, LENGTH, 0.000
INFO, SHAPE, 0
INFO, COMMENT,
INFO, SEQUENCE FILE: MHcurveUpTo100.seq


INFO, BACKGROUND DATA FILE:, None


STARTUPAXIS,X,8,LINEAR,AUTO,0.000000,0.000000
STARTUPAXIS,Y1,9,LINEAR,AUTO,0.000000,0.000000


STARTUPGROUP,Longitudinal
FIELDGROUP,Longitudinal,1,2,3,4,5,6,7,8,9,10,11,12,13,14,15,16,17,18,19,20,21,22
FIELDGROUP,Transverse,1,2,3,4,5,6,7,8,23,24,25,26,27,28,29,30,31,32,33,34,35,36

PLOT_APPEARANCE,ALL,HORZ_GRID_ON,VERT_GRID_ON,MARKERS_ONLY

[Data]
Time,Comment,Field (Oe),Start Temperature (K),End Temperature (K),Scan,Rejected,Position (cm),Long Voltage,Long Average Voltage,Long Detrended Voltage,Long Demeaned Voltage,Long Reg Fit,Long Detrended Fit,Long Demeaned Fit,Long Scaled Response,Long Avg. Scaled Response,Long Background Response,Long Response [w/ABS],Long Detrended Resp. [w/ABS],Long Fit [w/ABS],Long Detrended Fit [w/ABS],Trans Voltage,Trans Average Voltage,Trans Detrended Voltage,Trans Demeaned Voltage,Trans Reg Fit,Trans Detrended Fit,Trans Demeaned Fit,Trans Scaled Response,Trans Avg. Scaled Response,Trans Background Response,Trans Response [w/ABS],Trans Detrended Resp. [w/ABS],Trans Adjusted Fit,Trans Detrended Fit [w/ABS],
1406898598.046,,1.000000e+002,2.980050e+002,2.979968e+002,1,0,2.080261e+000,-1.297037e-002,-1.297037e-002,7.461863e-001,7.461863e-001,8.416464e-002,8.433213e-001,8.433213e-001,-2.826565e-007,-2.826565e-007,,,,,,,,,,,,,,,,,,,,
1406898598.046,,1.000000e+002,2.980050e+002,2.979968e+002,1,0,3.706037e+000,-9.978027e-001,-9.978027e-001,-3.761754e-001,-2.386460e-001,-9.907801e-001,-3.691528e-001,-2.316234e-001,-2.174460e-005,-2.174460e-005,,,,,,,,,,,,,,,,,,,,
1406898616.531,,1.000000e+002,2.980050e+002,2.979968e+002,1,0,4.363681e-001,-1.018403e+000,-1.018403e+000,-3.517191e-001,-2.791442e-001,-1.036482e+000,-3.697980e-001,-2.972232e-001,-2.219352e-005,-2.219352e-005,,,,,,,,,,,,,,,,,,,,
1406898634.265,,1.000000e+002,2.979968e+002,2.980050e+002,1,0,1.900562e+000,2.090518e-002,2.090518e-002,7.166775e-001,7.199959e-001,1.185339e-001,8.143063e-001,8.176247e-001,4.555757e-007,4.555757e-007,,,,,,,,,,,,,,,,,,,,
1406898634.265,,1.000000e+002,2.979968e+002,2.980050e+002,1,0,3.810359e+000,-1.008942e+000,-1.008942e+000,-4.558574e-001,-3.098512e-001,-9.079927e-001,-3.549081e-001,-2.089019e-001,-2.198735e-005,-2.198735e-005,,,,,,,,,,,,,,,,,,,,
1406898756.796,,7.500000e+001,2.979968e+002,2.980050e+002,1,0,5.566424e-001,-8.589435e-001,-8.589435e-001,-2.269293e-001,-1.634596e-001,-9.366359e-001,-3.046217e-001,-2.411520e-001,-1.871855e-005,-1.871855e-005,,,,,,,,,,,,,,,,,,,,
1406898774.781,,7.500000e+001,2.979968e+002,2.979968e+002,1,0,1.719344e+000,-6.714072e-002,-6.714072e-002,5.714728e-001,5.771401e-001,-5.416267e-002,5.844508e-001,5.901181e-001,-1.463166e-006,-1.463166e-006,,,,,,,,,,,,,,,,,,,,
1406898774.781,,7.500000e+001,2.979968e+002,2.979968e+002,1,0,3.894002e+000,-9.688101e-001,-9.688101e-001,-4.520427e-001,-3.245293e-001,-8.074268e-001,-2.906594e-001,-1.631460e-001,-2.111282e-005,-2.111282e-005,,,,,,,,,,,,,,,,,,,,
1406898792.781,,7.500000e+001,2.979968e+002,2.979968e+002,1,0,6.835808e-001,-7.223731e-001,-7.223731e-001,-1.456650e-001,-7.657546e-002,-8.390753e-001,-2.623672e-001,-1.932777e-001,-1.574234e-005,-1.574234e-005,,,,,,,,,,,,,,,,,,,,
1406898922.781,,5.000000e+001,2.979968e+002,2.979968e+002,1,0,1.539171e+000,-8.499406e-002,-8.499405e-002,4.065520e-001,4.133506e-001,-1.548973e-001,3.366487e-001,3.434473e-001,-1.852240e-006,-1.852240e-006,,,,,,,,,,,,,,,,,,,,
1406898922.781,,5.000000e+001,2.979968e+002,2.979968e+002,1,0,3.953910e+000,-8.105716e-001,-8.105716e-001,-4.164721e-001,-3.122270e-001,-6.248717e-001,-2.307722e-001,-1.265270e-001,-1.766445e-005,-1.766445e-005,,,,,,,,,,,,,,,,,,,,
1406898940.015,,5.000000e+001,2.979968e+002,2.980050e+002,1,0,8.161420e-001,-5.027924e-001,-5.027924e-001,-3.202206e-002,2.687043e-002,-6.375143e-001,-1.667439e-001,-1.078514e-001,-1.095714e-005,-1.095714e-005,,,,,,,,,,,,,,,,,,,,
1406898958.250,,5.000000e+001,2.979968e+002,2.980050e+002,1,0,1.361535e+000,-1.423689e-001,-1.423689e-001,3.386804e-001,3.484941e-001,-2.837605e-001,1.972888e-001,2.071025e-001,-3.102585e-006,-3.102585e-006,,,,,,,,,,,,,,,,,,,,
1406898958.250,,5.000000e+001,2.979968e+002,2.980050e+002,1,0,3.987858e+000,-8.059938e-001,-8.059939e-001,-4.304419e-001,-3.151309e-001,-5.979468e-001,-2.223949e-001,-1.070838e-001,-1.756469e-005,-1.756469e-005,,,,,,,,,,,,,,,,,,,,
1406899070.312,,4.500000e+001,2.980050e+002,2.980050e+002,1,0,9.543524e-001,-3.891110e-001,-3.891110e-001,6.140719e-002,1.191739e-001,-5.388609e-001,-8.834274e-002,-3.057605e-002,-8.479737e-006,-8.479737e-006,,,,,,,,,,,,,,,,,,,,
1406899088.562,,4.500000e+001,2.980050e+002,2.979968e+002,1,0,1.187647e+000,-2.270577e-001,-2.270577e-001,2.410460e-001,2.527783e-001,-4.070956e-001,6.100814e-002,7.274041e-002,-4.948176e-006,-4.948176e-006,,,,,,,,,,,,,,,,,,,,
1406899088.562,,4.500000e+001,2.980050e+002,2.979968e+002,1,0,3.994802e+000,-7.869197e-001,-7.869198e-001,-4.197135e-001,-3.070838e-001,-5.794248e-001,-2.122185e-001,-9.958881e-002,-1.714902e-005,-1.714902e-005,,,,,,,,,,,,,,,,,,,,
1406899106.812,,4.500000e+001,2.980050e+002,2.979885e+002,1,0,1.098646e+000,-2.462844e-001,-2.462844e-001,1.520115e-001,2.157389e-001,-3.974374e-001,8.584203e-004,6.458586e-002,-5.367174e-006,-5.367174e-006,,,,,,,,,,,,,,,,,,,,
1406899223.796,,4.000000e+001,2.979968e+002,2.980050e+002,1,0,1.018902e+000,-3.729362e-001,-3.729362e-001,1.383480e-001,1.512838e-001,-5.609820e-001,-4.969775e-002,-3.676200e-002,-8.127249e-006,-8.127249e-006,,,,,,,,,,,,,,,,,,,,
1406899223.796,,4.000000e+001,2.979968e+002,2.980050e+002,1,0,3.975094e+000,-8.188117e-001,-8.188116e-001,-4.002336e-001,-2.945916e-001,-6.256741e-001,-2.070961e-001,-1.014541e-001,-1.784404e-005,-1.784404e-005,,,,,,,,,,,,,,,,,,,,
1406899241.031,,4.000000e+001,2.979968e+002,2.979968e+002,1,0,1.249770e+000,-2.145451e-001,-2.145451e-001,2.183027e-001,2.795818e-001,-3.369061e-001,9.594169e-002,1.572208e-001,-4.675496e-006,-4.675496e-006,,,,,,,,,,,,,,,,,,,,
1406899258.828,,4.000000e+001,2.979968e+002,2.980050e+002,1,0,8.557661e-001,-4.272591e-001,-4.272591e-001,3.690772e-002,5.269137e-002,-6.020198e-001,-1.378529e-001,-1.220693e-001,-9.311088e-006,-9.311088e-006,,,,,,,,,,,,,,,,,,,,
1406899258.828,,4.000000e+001,2.979968e+002,2.980050e+002,1,0,3.930283e+000,-7.487717e-001,-7.487716e-001,-3.815615e-001,-2.688211e-001,-5.834476e-001,-2.162374e-001,-1.034971e-001,-1.631768e-005,-1.631768e-005,,,,,,,,,,,,,,,,,,,,
1406899376.843,,3.500000e+001,2.980050e+002,2.980050e+002,1,0,1.408105e+000,-1.539659e-001,-1.539659e-001,2.698242e-001,3.274251e-001,-2.318292e-001,1.919609e-001,2.495617e-001,-3.355319e-006,-3.355319e-006,,,,,,,,,,,,,,,,,,,,
1406899395.093,,3.500000e+001,2.979968e+002,2.979968e+002,1,0,6.999980e-001,-4.858547e-001,-4.858547e-001,-4.466540e-002,-2.784523e-002,-6.317213e-001,-1.905320e-001,-1.737119e-001,-1.058804e-005,-1.058804e-005,,,,,,,,,,,,,,,,,,,,
1406899395.093,,3.500000e+001,2.979968e+002,2.979968e+002,1,0,3.863265e+000,-6.857509e-001,-6.857509e-001,-3.349700e-001,-2.277415e-001,-5.668495e-001,-2.160686e-001,-1.088401e-001,-1.494430e-005,-1.494430e-005,,,,,,,,,,,,,,,,,,,,
1406899412.875,,3.500000e+001,2.980050e+002,2.979968e+002,1,0,1.573417e+000,-7.110813e-002,-7.110813e-002,3.081126e-001,3.723711e-001,-7.566527e-002,3.035554e-001,3.678139e-001,-1.549632e-006,-1.549632e-006,,,,,,,,,,,,,,,,,,,,
1406899529.359,,3.000000e+001,2.979968e+002,2.979968e+002,1,0,5.529635e-001,-5.667287e-001,-5.667287e-001,-1.165618e-001,-9.943175e-002,-6.605993e-001,-2.104324e-001,-1.933023e-001,-1.235050e-005,-1.235050e-005,,,,,,,,,,,,,,,,,,,,
1406899529.359,,3.000000e+001,2.979968e+002,2.979968e+002,1,0,3.777544e+000,-6.466872e-001,-6.466872e-001,-2.783641e-001,-1.793903e-001,-5.820442e-001,-2.137211e-001,-1.147473e-001,-1.409301e-005,-1.409301e-005,,,,,,,,,,,,,,,,,,,,
1406899547.593,,3.000000e+001,2.979968e+002,2.979968e+002,1,0,1.745044e+000,-4.867702e-002,-4.867702e-002,3.153556e-001,3.775297e-001,2.419234e-002,3.882250e-001,4.503990e-001,-1.060800e-006,-1.060800e-006,,,,,,,,,,,,,,,,,,,,
1406899565.875,,3.000000e+001,2.979968e+002,2.980050e+002,1,0,4.173152e-001,-5.853450e-001,-5.853450e-001,-1.811106e-001,-1.605051e-001,-6.191242e-001,-2.148898e-001,-1.942842e-001,-1.275620e-005,-1.275620e-005,,,,,,,,,,,,,,,,,,,,
1406899565.875,,3.000000e+001,2.979968e+002,2.980050e+002,1,0,3.677087e+000,-5.377361e-001,-5.377361e-001,-2.221055e-001,-1.128962e-001,-5.305106e-001,-2.148800e-001,-1.056707e-001,-1.171868e-005,-1.171868e-005,,,,,,,,,,,,,,,,,,,,
1406899683.109,,2.500000e+001,2.979968e+002,2.979968e+002,1,0,1.921689e+000,-8.041628e-002,-8.041627e-002,3.115002e-001,3.697567e-001,4.425992e-002,4.361764e-001,4.944329e-001,-1.752482e-006,-1.752482e-006,,,,,,,,,,,,,,,,,,,,
1406899700.343,,2.500000e+001,2.979968e+002,2.980050e+002,1,0,2.956520e-001,-6.265450e-001,-6.265450e-001,-2.180222e-001,-1.970490e-001,-6.003183e-001,-1.917955e-001,-1.708222e-001,-1.365406e-005,-1.365406e-005,,,,,,,,,,,,,,,,,,,,
1406899700.343,,2.500000e+001,2.979968e+002,2.980050e+002,1,0,3.565264e+000,-4.698325e-001,-4.698325e-001,-1.432960e-001,-4.033643e-002,-5.176367e-001,-1.911002e-001,-8.814064e-002,-1.023889e-005,-1.023889e-005,,,,,,,,,,,,,,,,,,,,
1406899718.578,,2.500000e+001,2.979968e+002,2.979968e+002,1,0,2.101374e+000,-1.205481e-002,-1.205481e-002,3.242597e-001,3.881406e-001,1.267083e-001,4.630229e-001,5.269037e-001,-2.627061e-007,-2.627061e-007,,,,,,,,,,,,,,,,,,,,
1406899835.312,,2.000000e+001,2.979968e+002,2.979968e+002,1,0,1.912859e-001,-6.703391e-001,-6.703390e-001,-2.485380e-001,-2.292155e-001,-5.842729e-001,-1.624718e-001,-1.431493e-001,-1.460846e-005,-1.460846e-005,,,,,,,,,,,,,,,,,,,,
1406899835.312,,2.000000e+001,2.979968e+002,2.979968e+002,1,0,3.444997e+000,-4.171880e-001,-4.171880e-001,-6.462607e-002,2.393553e-002,-5.031150e-001,-1.505530e-001,-6.199145e-002,-9.091629e-006,-9.091629e-006,,,,,,,,,,,,,,,,,,,,
1406899853.046,,2.000000e+001,2.979968e+002,2.980050e+002,1,0,2.282309e+000,-3.204443e-002,-3.204444e-002,3.165712e-001,3.768286e-001,5.308227e-002,4.016979e-001,4.619553e-001,-6.983329e-007,-6.983329e-007,,,,,,,,,,,,,,,,,,,,
1406899871.546,,2.000000e+001,2.980050e+002,2.979968e+002,1,0,1.077257e-001,-6.157109e-001,-6.157109e-001,-2.848414e-001,-2.618030e-001,-4.789804e-001,-1.481109e-001,-1.250724e-001,-1.341797e-005,-1.341797e-005,,,,,,,,,,,,,,,,,,,,
1406899871.546,,2.000000e+001,2.980050e+002,2.979968e+002,1,0,3.318144e+000,-2.473525e-001,-2.473525e-001,7.312931e-003,1.065554e-001,-3.647694e-001,-1.101040e-001,-1.086152e-002,-5.390465e-006,-5.390465e-006,,,,,,,,,,,,,,,,,,,,
1406899982.031,,1.500000e+001,2.979968e+002,2.980050e+002,1,0,2.462378e+000,-4.226813e-002,-4.226813e-002,3.037823e-001,3.584633e-001,-4.121350e-002,3.048370e-001,3.595180e-001,-9.211348e-007,-9.211348e-007,,,,,,,,,,,,,,,,,,,,
1406899999.765,,1.500000e+001,2.979968e+002,2.980050e+002,1,0,4.781424e-002,-6.448561e-001,-6.448561e-001,-2.926337e-001,-2.695063e-001,-4.787053e-001,-1.264829e-001,-1.033556e-001,-1.405312e-005,-1.405312e-005,,,,,,,,,,,,,,,,,,,,
1406899999.765,,1.500000e+001,2.979968e+002,2.980050e+002,1,0,3.185617e+000,-1.977599e-001,-1.977599e-001,8.342838e-002,1.775898e-001,-3.305468e-001,-4.935851e-002,4.480293e-002,-4.309713e-006,-4.309713e-006,,,,,,,,,,,,,,,,,,,,
1406900017.531,,1.500000e+001,2.979968e+002,2.979968e+002,1,0,2.640242e+000,7.171850e-003,7.171850e-003,2.958864e-001,3.592994e-001,-7.397877e-002,2.147358e-001,2.781488e-001,1.562936e-007,1.562936e-007,,,,,,,,,,,,,,,,,,,,
1406900135.765,,1.000000e+001,2.980050e+002,2.979968e+002,1,0,1.384676e-002,-6.434828e-001,-6.434827e-001,-2.833948e-001,-2.622616e-001,-4.693863e-001,-1.092983e-001,-8.816513e-002,-1.402320e-005,-1.402320e-005,,,,,,,,,,,,,,,,,,,,
1406900135.765,,1.000000e+001,2.980050e+002,2.979968e+002,1,0,3.047410e+000,-1.486251e-001,-1.486251e-001,1.508811e-001,2.325960e-001,-2.845910e-001,1.491528e-002,9.663019e-002,-3.238938e-006,-3.238938e-006,,,,,,,,,,,,,,,,,,,,
1406900154.515,,1.000000e+001,2.979968e+002,2.979885e+002,1,0,2.813916e+000,-2.929777e-002,-2.929777e-002,2.558173e-001,3.123283e-001,-1.643939e-001,1.207211e-001,1.772322e-001,-6.384764e-007,-6.384764e-007,,,,,,,,,,,,,,,,,,,,
1406900172.781,,1.000000e+001,2.979885e+002,2.979968e+002,1,0,6.897166e-003,-5.847346e-001,-5.847346e-001,-2.851484e-001,-2.607187e-001,-4.073425e-001,-1.077563e-001,-8.332652e-002,-1.274292e-005,-1.274292e-005,,,,,,,,,,,,,,,,,,,,
1406900172.781,,1.000000e+001,2.979885e+002,2.979968e+002,1,0,2.903050e+000,-3.479110e-002,-3.479110e-002,1.991401e-001,2.892248e-001,-1.538878e-001,8.004335e-002,1.701281e-001,-7.581907e-007,-7.581907e-007,,,,,,,,,,,,,,,,,,,,
1406900290.765,,5.000000e+000,2.979968e+002,2.979968e+002,1,0,2.983115e+000,-9.277627e-002,-9.277627e-002,1.925622e-001,2.397035e-001,-2.437659e-001,4.157262e-002,8.871388e-002,-2.021843e-006,-2.021843e-006,,,,,,,,,,,,,,,,,,,,
1406900308.500,,5.000000e+000,2.979968e+002,2.980050e+002,1,0,2.661361e-002,-5.233924e-001,-5.233924e-001,-2.646967e-001,-2.413509e-001,-3.587719e-001,-1.000761e-001,-7.673040e-002,-1.140612e-005,-1.140612e-005,,,,,,,,,,,,,,,,,,,,
1406900308.500,,5.000000e+000,2.979968e+002,2.980050e+002,1,0,2.751917e+000,9.155553e-003,9.155553e-003,2.088004e-001,2.911971e-001,-6.140738e-002,1.382374e-001,2.206341e-001,1.995240e-007,1.995240e-007,,,,,,,,,,,,,,,,,,,,
1406900326.234,,5.000000e+000,2.980050e+002,2.979968e+002,1,0,3.145989e+000,-9.186071e-002,-9.186071e-002,1.297805e-001,1.858878e-001,-2.422271e-001,-2.058588e-002,3.552136e-002,-2.001890e-006,-2.001890e-006,,,,,,,,,,,,,,,,,,,,
1406900444.468,,0.000000e+000,2.980050e+002,2.979968e+002,1,0,7.145298e-002,-4.879910e-001,-4.879910e-001,-2.337718e-001,-2.132581e-001,-3.483618e-001,-9.414260e-002,-7.362887e-002,-1.063463e-005,-1.063463e-005,,,,,,,,,,,,,,,,,,,,
1406900444.468,,0.000000e+000,2.980050e+002,2.979968e+002,1,0,2.593699e+000,-1.083407e-002,-1.083407e-002,1.943801e-001,2.638988e-001,-2.088923e-002,1.843249e-001,2.538437e-001,-2.361034e-007,-2.361034e-007,,,,,,,,,,,,,,,,,,,,
1406900462.796,,0.000000e+000,2.979968e+002,2.979968e+002,1,0,3.301758e+000,-1.637318e-001,-1.637318e-001,5.949906e-002,1.094021e-001,-2.887979e-001,-6.556706e-002,-1.566404e-002,-3.568155e-006,-3.568155e-006,,,,,,,,,,,,,,,,,,,,
1406900481.546,,0.000000e+000,2.979968e+002,2.979885e+002,1,0,1.384606e-001,-4.385510e-001,-4.385510e-001,-2.162047e-001,-1.921863e-001,-3.242899e-001,-1.019436e-001,-7.792515e-002,-9.557201e-006,-9.557201e-006,,,,,,,,,,,,,,,,,,,,
1406900481.546,,0.000000e+000,2.979968e+002,2.979885e+002,1,0,2.428282e+000,1.129185e-002,1.129185e-002,1.792805e-001,2.576566e-001,7.466549e-002,2.426542e-001,3.210302e-001,2.460797e-007,2.460797e-007,,,,,,,,,,,,,,,,,,,,
1406900598.781,,-5.000000e+000,2.980050e+002,2.980050e+002,1,0,3.448702e+000,-2.557451e-001,-2.557451e-001,-6.081420e-003,3.630471e-002,-3.387548e-001,-8.909111e-002,-4.670498e-002,-5.573369e-006,-5.573369e-006,,,,,,,,,,,,,,,,,,,,
1406900616.515,,-5.000000e+000,2.979968e+002,2.979968e+002,1,0,2.241826e-001,-4.135258e-001,-4.135258e-001,-1.686623e-001,-1.446780e-001,-3.440274e-001,-9.916390e-002,-7.517958e-002,-9.011832e-006,-9.011832e-006,,,,,,,,,,,,,,,,,,,,
1406900616.515,,-5.000000e+000,2.979968e+002,2.979968e+002,1,0,2.256716e+000,-6.851405e-002,-6.851406e-002,1.247831e-001,2.003337e-001,4.912432e-002,2.424215e-001,3.179721e-001,-1.493104e-006,-1.493104e-006,,,,,,,,,,,,,,,,,,,,
1406900634.750,,-5.000000e+000,2.979968e+002,2.980050e+002,1,0,3.584405e+000,-2.635273e-001,-2.635273e-001,-6.829447e-002,-1.859902e-002,-3.008048e-001,-1.055719e-001,-5.587648e-002,-5.742965e-006,-5.742965e-006,,,,,,,,,,,,,,,,,,,,
1406900758.734,,-1.000000e+001,2.979968e+002,2.979968e+002,1,0,3.246373e-001,-3.038118e-001,-3.038118e-001,-1.119965e-001,-9.031439e-002,-2.839896e-001,-9.217434e-002,-7.049227e-002,-6.620867e-006,-6.620867e-006,,,,,,,,,,,,,,,,,,,,
1406900777.015,,-1.000000e+001,2.979968e+002,2.980050e+002,1,0,2.079992e+000,-7.660146e-002,-7.660146e-002,1.595437e-001,1.595437e-001,-2.280530e-002,2.133399e-001,2.133399e-001,-1.669350e-006,-1.669350e-006,,,,,,,,,,,,,,,,,,,,
1406900777.015,,-1.000000e+001,2.979968e+002,2.980050e+002,1,0,3.706077e+000,-2.876369e-001,-2.876370e-001,-1.038870e-001,-5.149180e-002,-2.771312e-001,-9.338123e-002,-4.098603e-002,-6.268375e-006,-6.268375e-006,,,,,,,,,,,,,,,,,,,,
1406900795.250,,-1.000000e+001,2.979968e+002,2.979968e+002,1,0,4.364233e-001,-2.386547e-001,-2.386547e-001,-7.515869e-002,-4.825447e-002,-2.568813e-001,-9.338524e-002,-6.648102e-002,-5.200922e-006,-5.200922e-006,,,,,,,,,,,,,,,,,,,,
1406900913.296,,-1.500000e+001,2.980050e+002,2.979968e+002,1,0,1.900167e+000,-6.851405e-002,-6.851406e-002,1.258460e-001,1.271614e-001,-1.785144e-002,1.765086e-001,1.778240e-001,-1.493103e-006,-1.493103e-006,,,,,,,,,,,,,,,,,,,,
1406900913.296,,-1.500000e+001,2.980050e+002,2.979968e+002,1,0,3.810349e+000,-2.674947e-001,-2.674947e-001,-1.296983e-001,-7.181928e-002,-2.051384e-001,-6.734204e-002,-9.462968e-003,-5.829419e-006,-5.829419e-006,,,,,,,,,,,,,,,,,,,,
1406900931.281,,-1.500000e+001,2.980050e+002,2.979968e+002,1,0,5.566576e-001,-1.399274e-001,-1.399274e-001,-1.886764e-002,1.357539e-002,-1.841576e-001,-6.309786e-002,-3.065483e-002,-3.049388e-006,-3.049388e-006,,,,,,,,,,,,,,,,,,,,
1406900949.515,,-1.500000e+001,2.979968e+002,2.980050e+002,1,0,1.719441e+000,0.000000e+000,0.000000e+000,1.271128e-001,1.300414e-001,3.361950e-002,1.607323e-001,1.636609e-001,0.000000e+000,0.000000e+000,,,,,,,,,,,,,,,,,,,,
1406900949.515,,-1.500000e+001,2.979968e+002,2.980050e+002,1,0,3.894016e+000,-2.243111e-001,-2.243110e-001,-1.601641e-001,-9.426963e-002,-1.256570e-001,-6.151007e-002,4.384413e-003,-4.888333e-006,-4.888333e-006,,,,,,,,,,,,,,,,,,,,
1406901066.515,,-2.000000e+001,2.979968e+002,2.980050e+002,1,0,6.835617e-001,-1.176489e-001,-1.176489e-001,3.860278e-002,8.955906e-002,-1.145039e-001,4.174768e-002,9.270397e-002,-2.563879e-006,-2.563879e-006,,,,,,,,,,,,,,,,,,,,
1406901084.750,,-2.000000e+001,2.980050e+002,2.980050e+002,1,0,1.539203e+000,-3.280740e-002,-3.280740e-002,1.500181e-001,1.567388e-001,-4.984558e-002,1.329799e-001,1.397006e-001,-7.149599e-007,-7.149599e-007,,,,,,,,,,,,,,,,,,,,
1406901084.750,,-2.000000e+001,2.980050e+002,2.980050e+002,1,0,3.953865e+000,-2.471999e-001,-2.471999e-001,-1.607035e-001,-5.765377e-002,-1.064455e-001,-1.994908e-002,8.310066e-002,-5.387139e-006,-5.387139e-006,,,,,,,,,,,,,,,,,,,,
1406901101.984,,-2.000000e+001,2.979968e+002,2.979968e+002,1,0,8.160459e-001,-4.257332e-002,-4.257332e-002,7.091656e-002,1.282370e-001,-4.671573e-002,6.677415e-002,1.240946e-001,-9.277851e-007,-9.277851e-007,,,,,,,,,,,,,,,,,,,,
1406901219.218,,-2.500000e+001,2.980050e+002,2.979968e+002,1,0,1.361384e+000,1.052889e-002,1.052889e-002,1.471757e-001,1.541150e-001,-3.499581e-002,1.016510e-001,1.085903e-001,2.294521e-007,2.294521e-007,,,,,,,,,,,,,,,,,,,,
1406901219.218,,-2.500000e+001,2.980050e+002,2.979968e+002,1,0,3.987785e+000,-2.006592e-001,-2.006592e-001,-1.386104e-001,-5.707307e-002,-7.227691e-002,-1.022808e-002,7.130922e-002,-4.372892e-006,-4.372892e-006,,,,,,,,,,,,,,,,,,,,
1406901236.953,,-2.500000e+001,2.980050e+002,2.979968e+002,1,0,9.543306e-001,3.234962e-002,3.234962e-002,1.090263e-001,1.577022e-001,2.192375e-002,9.860043e-002,1.472763e-001,7.049833e-007,7.049833e-007,,,,,,,,,,,,,,,,,,,,
1406901254.734,,-2.500000e+001,2.979968e+002,2.979968e+002,1,0,1.187935e+000,3.341777e-002,3.341777e-002,1.529454e-001,1.625987e-001,-1.001581e-002,1.095119e-001,1.191652e-001,7.282611e-007,7.282611e-007,,,,,,,,,,,,,,,,,,,,
1406901254.734,,-2.500000e+001,2.979968e+002,2.979968e+002,1,0,3.994853e+000,-1.747185e-001,-1.747185e-001,-1.382091e-001,-4.553750e-002,-4.667633e-002,-1.016699e-002,8.250464e-002,-3.807575e-006,-3.807575e-006,,,,,,,,,,,,,,,,,,,,
1406901371.484,,-3.000000e+001,2.979968e+002,2.979968e+002,1,0,1.098705e+000,8.270516e-002,8.270516e-002,1.244329e-001,1.648223e-001,6.300032e-002,1.047281e-001,1.451175e-001,1.802362e-006,1.802362e-006,,,,,,,,,,,,,,,,,,,,
1406901389.218,,-3.000000e+001,2.979968e+002,2.980050e+002,1,0,1.018965e+000,6.775109e-002,6.775109e-002,1.392166e-001,1.489321e-001,3.165114e-002,1.031167e-001,1.128321e-001,1.476474e-006,1.476474e-006,,,,,,,,,,,,,,,,,,,,
1406901389.218,,-3.000000e+001,2.979968e+002,2.980050e+002,1,0,3.975102e+000,-1.109348e-001,-1.109348e-001,-1.090964e-001,-2.975380e-002,-1.075290e-002,-8.914564e-003,7.042808e-002,-2.417560e-006,-2.417560e-006,,,,,,,,,,,,,,,,,,,,
1406901407.453,,-3.000000e+001,2.979968e+002,2.979968e+002,1,0,1.249771e+000,9.628590e-002,9.628589e-002,1.030106e-001,1.093512e-001,6.094004e-003,1.281872e-002,1.915930e-002,2.098322e-006,2.098322e-006,,,,,,,,,,,,,,,,,,,,
1406901525.453,,-3.500000e+001,2.980050e+002,2.979968e+002,1,0,8.559097e-001,9.506516e-002,9.506515e-002,6.739676e-002,6.321394e-002,2.304402e-002,-4.624371e-003,-8.807190e-003,2.071718e-006,2.071718e-006,,,,,,,,,,,,,,,,,,,,
1406901525.453,,-3.500000e+001,2.980050e+002,2.979968e+002,1,0,3.930331e+000,-4.715110e-002,-4.715110e-002,-4.912503e-002,-7.900231e-002,7.281161e-003,5.307228e-003,-2.457005e-002,-1.027546e-006,-1.027546e-006,,,,,,,,,,,,,,,,,,,,
1406901542.687,,-3.500000e+001,2.979968e+002,2.979968e+002,1,0,1.408038e+000,9.842220e-002,9.842219e-002,7.212090e-002,5.811783e-002,1.710401e-002,-9.197278e-003,-2.320036e-002,2.144877e-006,2.144877e-006,,,,,,,,,,,,,,,,,,,,
1406901561.437,,-3.500000e+001,2.979968e+002,2.980050e+002,1,0,7.000927e-001,9.964294e-002,9.964293e-002,5.609974e-002,5.258665e-002,3.997096e-002,-3.572236e-003,-7.085320e-003,2.171480e-006,2.171480e-006,,,,,,,,,,,,,,,,,,,,
1406901561.437,,-3.500000e+001,2.979968e+002,2.980050e+002,1,0,3.863296e+000,-9.613330e-003,-9.613330e-003,-3.427370e-002,-5.666961e-002,3.181552e-002,7.155148e-003,-1.524076e-002,-2.094996e-007,-2.094996e-007,,,,,,,,,,,,,,,,,,,,
1406901678.187,,-4.000000e+001,2.980050e+002,2.979968e+002,1,0,1.573316e+000,6.195257e-002,6.195258e-002,8.638162e-003,-1.285399e-002,3.988781e-002,-1.342660e-002,-3.491876e-002,1.350108e-006,1.350108e-006,,,,,,,,,,,,,,,,,,,,
1406901696.421,,-4.000000e+001,2.980050e+002,2.980050e+002,1,0,5.530537e-001,1.118503e-001,1.118503e-001,3.983920e-002,3.395974e-002,6.804902e-002,-3.962114e-003,-9.841576e-003,2.437510e-006,2.437510e-006,,,,,,,,,,,,,,,,,,,,
1406901696.421,,-4.000000e+001,2.980050e+002,2.980050e+002,1,0,3.777648e+000,5.081332e-002,5.081332e-002,6.892950e-003,-2.707728e-002,5.904151e-002,1.512114e-002,-1.884909e-002,1.107354e-006,1.107354e-006,,,,,,,,,,,,,,,,,,,,
1406901714.671,,-4.000000e+001,2.979968e+002,2.980050e+002,1,0,1.745016e+000,4.333628e-002,4.333628e-002,-4.011920e-002,-5.769306e-002,7.116275e-002,-1.229273e-002,-2.986659e-002,9.444103e-007,9.444103e-007,,,,,,,,,,,,,,,,,,,,
1406901832.406,,-4.500000e+001,2.979968e+002,2.980050e+002,1,0,4.172724e-001,1.647999e-001,1.648000e-001,5.050058e-002,5.525852e-002,1.379704e-001,2.367098e-002,2.842892e-002,3.591418e-006,3.591418e-006,,,,,,,,,,,,,,,,,,,,
1406901832.406,,-4.500000e+001,2.979968e+002,2.980050e+002,1,0,3.677035e+000,1.474044e-001,1.474044e-001,1.264587e-002,3.786296e-002,1.534913e-001,1.873275e-002,4.394984e-002,3.212324e-006,3.212324e-006,,,,,,,,,,,,,,,,,,,,
1406901850.640,,-4.500000e+001,2.980050e+002,2.980050e+002,1,0,1.921823e+000,5.996887e-002,5.996887e-002,-1.041973e-001,-8.714399e-002,1.229705e-001,-4.119563e-002,-2.414235e-002,1.306877e-006,1.306877e-006,,,,,,,,,,,,,,,,,,,,
1406901869.125,,-4.500000e+001,2.980050e+002,2.979968e+002,1,0,2.955410e-001,1.480148e-001,1.480148e-001,2.361603e-002,2.948636e-002,1.455801e-001,2.118141e-002,2.705173e-002,3.225625e-006,3.225625e-006,,,,,,,,,,,,,,,,,,,,
1406901869.125,,-4.500000e+001,2.980050e+002,2.979968e+002,1,0,3.565201e+000,1.753288e-001,1.753288e-001,2.798248e-002,5.680043e-002,1.603215e-001,1.297513e-002,4.179308e-002,3.820870e-006,3.820870e-006,,,,,,,,,,,,,,,,,,,,
1406901988.656,,-5.000000e+001,2.979968e+002,2.980050e+002,1,0,2.101588e+000,1.365703e-001,1.365703e-001,-1.362407e-001,-1.209126e-001,1.641390e-001,-1.086721e-001,-9.334393e-002,2.976220e-006,2.976220e-006,,,,,,,,,,,,,,,,,,,,
1406902007.140,,-5.000000e+001,2.980050e+002,2.979968e+002,1,0,1.913149e-001,3.118992e-001,3.118992e-001,1.075636e-002,1.727220e-002,3.365721e-001,3.542928e-002,4.194513e-002,6.797088e-006,6.797088e-006,,,,,,,,,,,,,,,,,,,,
1406902007.140,,-5.000000e+001,2.980050e+002,2.979968e+002,1,0,3.444984e+000,3.770562e-001,3.770562e-001,5.256493e-002,8.242923e-002,3.501777e-001,2.568648e-002,5.555078e-002,8.217027e-006,8.217027e-006,,,,,,,,,,,,,,,,,,,,
1406902025.375,,-5.000000e+001,2.979968e+002,2.979968e+002,1,0,2.282512e+000,1.104770e-001,1.104770e-001,-1.169435e-001,-9.960852e-002,1.137887e-001,-1.136319e-001,-9.629687e-002,2.407579e-006,2.407579e-006,,,,,,,,,,,,,,,,,,,,
1406902148.609,,-7.500000e+001,2.979968e+002,2.979968e+002,1,0,1.076435e-001,1.547594e+000,1.547594e+000,7.155260e-002,1.372346e-001,1.566231e+000,9.018990e-002,1.558719e-001,3.372598e-005,3.372598e-005,,,,,,,,,,,,,,,,,,,,
1406902148.609,,-7.500000e+001,2.979968e+002,2.979968e+002,1,0,3.318080e+000,1.760765e+000,1.760765e+000,6.746873e-002,3.504064e-001,1.750877e+000,5.758008e-002,3.405178e-001,3.837153e-005,3.837153e-005,,,,,,,,,,,,,,,,,,,,
1406902166.843,,-7.500000e+001,2.979968e+002,2.979968e+002,1,0,2.462500e+000,1.263161e+000,1.263161e+000,-2.036803e-001,-4.743350e-002,1.235215e+000,-2.316268e-001,-7.537997e-002,2.752748e-005,2.752748e-005,,,,,,,,,,,,,,,,,,,,
1406902185.078,,-7.500000e+001,2.979968e+002,2.979968e+002,1,0,4.779184e-002,1.286966e+000,1.286965e+000,5.745696e-002,1.136986e-001,1.313249e+000,8.374023e-002,1.399819e-001,2.804624e-005,2.804624e-005,,,,,,,,,,,,,,,,,,,,
1406902185.078,,-7.500000e+001,2.979968e+002,2.979968e+002,1,0,3.185538e+000,1.429487e+000,1.429487e+000,2.723629e-002,2.562201e-001,1.422475e+000,2.022475e-002,2.492086e-001,3.115214e-005,3.115214e-005,,,,,,,,,,,,,,,,,,,,
1406902340.937,,-1.000000e+002,2.979968e+002,2.980050e+002,1,0,2.640339e+000,8.415479e-001,8.415479e-001,-1.228952e-001,-1.001072e-002,8.414426e-001,-1.230005e-001,-1.011598e-002,3.667883e-005,3.667883e-005,,,,,,,,,,,,,,,,,,,,
1406902357.687,,-1.000000e+002,2.979968e+002,2.980050e+002,1,0,1.383455e-002,9.364605e-001,9.364604e-001,6.788950e-002,1.091345e-001,9.349536e-001,6.638269e-002,1.076277e-001,4.081559e-005,4.081559e-005,,,,,,,,,,,,,,,,,,,,
1406902357.687,,-1.000000e+002,2.979968e+002,2.980050e+002,1,0,3.047289e+000,9.630116e-001,9.630116e-001,-2.379504e-002,1.356856e-001,9.775919e-001,-9.214729e-003,1.502659e-001,4.197282e-005,4.197282e-005,,,,,,,,,,,,,,,,,,,,
1406902375.921,,-1.000000e+002,2.980050e+002,2.979968e+002,1,0,2.814019e+000,6.701865e-001,6.701865e-001,-8.390363e-002,-6.606162e-003,6.799409e-001,-7.414915e-002,3.148317e-003,2.921005e-005,2.921005e-005,,,,,,,,,,,,,,,,,,,,
1406902523.656,,-7.500000e+001,2.980050e+002,2.979968e+002,1,0,6.864435e-003,2.954192e-001,2.954192e-001,7.350823e-002,6.116624e-002,3.142733e-001,9.236231e-002,8.002032e-002,6.437931e-006,6.437931e-006,,,,,,,,,,,,,,,,,,,,
1406902523.656,,-7.500000e+001,2.980050e+002,2.979968e+002,1,0,2.902903e+000,9.521775e-002,9.521775e-002,-9.352414e-002,-1.390352e-001,1.027537e-001,-8.598819e-002,-1.314992e-001,2.075036e-006,2.075036e-006,,,,,,,,,,,,,,,,,,,,
1406902540.890,,-7.500000e+001,2.980050e+002,2.979968e+002,1,0,2.983104e+000,1.870785e-001,1.870785e-001,-6.479889e-002,-9.643058e-002,1.984369e-001,-5.344044e-002,-8.507213e-002,4.076913e-006,4.076913e-006,,,,,,,,,,,,,,,,,,,,
1406902559.156,,-7.500000e+001,2.979968e+002,2.980050e+002,1,0,2.670726e-002,3.282266e-001,3.282266e-001,8.069457e-002,6.403464e-002,3.425896e-001,9.505762e-002,7.839769e-002,7.152888e-006,7.152888e-006,,,,,,,,,,,,,,,,,,,,
1406902559.156,,-7.500000e+001,2.979968e+002,2.980050e+002,1,0,2.751832e+000,5.066073e-002,5.066073e-002,-1.547314e-001,-2.135312e-001,5.391155e-002,-1.514806e-001,-2.102804e-001,1.104025e-006,1.104025e-006,,,,,,,,,,,,,,,,,,,,
1406902683.921,,-5.000000e+001,2.979968e+002,2.980050e+002,1,0,3.146038e+000,1.333659e-001,1.333659e-001,5.999286e-003,-1.273270e-002,1.151526e-001,-1.221401e-002,-3.094599e-002,2.906387e-006,2.906387e-006,,,,,,,,,,,,,,,,,,,,
1406902701.687,,-5.000000e+001,2.979885e+002,2.979968e+002,1,0,7.147735e-002,1.971496e-001,1.971496e-001,2.116426e-002,1.277770e-002,2.332371e-001,5.725179e-002,4.886523e-002,4.296398e-006,4.296398e-006,,,,,,,,,,,,,,,,,,,,
1406902701.687,,-5.000000e+001,2.979885e+002,2.979968e+002,1,0,2.593537e+000,1.678518e-002,1.678518e-002,-1.391656e-001,-1.675867e-001,-1.332873e-003,-1.572836e-001,-1.857048e-001,3.657924e-007,3.657924e-007,,,,,,,,,,,,,,,,,,,,
1406902719.921,,-5.000000e+001,2.979968e+002,2.979968e+002,1,0,3.301848e+000,2.182073e-001,2.182073e-001,4.913964e-002,3.388704e-002,1.930648e-001,2.399708e-002,8.744478e-003,4.755301e-006,4.755301e-006,,,,,,,,,,,,,,,,,,,,
1406902836.703,,-4.500000e+001,2.979968e+002,2.979968e+002,1,0,1.385166e-001,1.699881e-001,1.699881e-001,2.420384e-002,1.577570e-002,1.987258e-001,5.294159e-002,4.451345e-002,3.704481e-006,3.704481e-006,,,,,,,,,,,,,,,,,,,,
1406902836.703,,-4.500000e+001,2.979968e+002,2.979968e+002,1,0,2.428198e+000,-3.143406e-002,-3.143407e-002,-1.581441e-001,-1.856465e-001,-4.480489e-002,-1.715149e-001,-1.990173e-001,-6.850297e-007,-6.850297e-007,,,,,,,,,,,,,,,,,,,,
1406902854.437,,-4.500000e+001,2.980050e+002,2.980050e+002,1,0,3.448807e+000,2.055422e-001,2.055422e-001,5.931722e-002,4.482159e-002,1.889746e-001,4.274962e-002,2.825399e-002,4.479296e-006,4.479296e-006,,,,,,,,,,,,,,,,,,,,
1406902872.687,,-4.500000e+001,2.979968e+002,2.979968e+002,1,0,2.241856e-001,1.925718e-001,1.925718e-001,4.799384e-002,4.085077e-002,2.045694e-001,5.999142e-002,5.284835e-002,4.196638e-006,4.196638e-006,,,,,,,,,,,,,,,,,,,,
1406902872.687,,-4.500000e+001,2.979968e+002,2.979968e+002,1,0,2.256552e+000,-6.149480e-002,-6.149480e-002,-1.907151e-001,-2.132158e-001,-5.400798e-002,-1.832283e-001,-2.057290e-001,-1.340131e-006,-1.340131e-006,,,,,,,,,,,,,,,,,,,,
1406902991.671,,-4.000000e+001,2.979968e+002,2.979968e+002,1,0,3.584477e+000,1.887570e-001,1.887570e-001,5.145429e-002,3.834701e-002,1.868138e-001,4.951110e-002,3.640382e-002,4.113505e-006,4.113505e-006,,,,,,,,,,,,,,,,,,,,
1406903009.406,,-4.000000e+001,2.980050e+002,2.979968e+002,1,0,3.247428e-001,2.362133e-001,2.362133e-001,6.368021e-002,5.828916e-002,2.281137e-001,5.558060e-002,5.018955e-002,5.147701e-006,5.147701e-006,,,,,,,,,,,,,,,,,,,,
1406903027.140,,-4.000000e+001,2.979968e+002,2.979885e+002,1,0,2.080098e+000,-2.594073e-003,-2.594073e-003,-1.897662e-001,-1.897662e-001,4.320361e-002,-1.439686e-001,-1.439686e-001,-5.653160e-008,-5.653160e-008,,,,,,,,,,,,,,,,,,,,
1406903027.140,,-4.000000e+001,2.979968e+002,2.979885e+002,1,0,3.706142e+000,2.249214e-001,2.249214e-001,4.731447e-002,3.774925e-002,2.386078e-001,6.100082e-002,5.143560e-002,4.901623e-006,4.901623e-006,,,,,,,,,,,,,,,,,,,,
1406903144.625,,-3.500000e+001,2.980050e+002,2.980050e+002,1,0,4.365265e-001,1.577807e-001,1.577807e-001,7.715811e-002,7.296406e-002,1.299366e-001,4.931399e-002,4.511994e-002,3.438453e-006,3.438453e-006,,,,,,,,,,,,,,,,,,,,
1406903162.375,,-3.500000e+001,2.980050e+002,2.979968e+002,1,0,1.900169e+000,-1.770074e-002,-1.770074e-002,-1.470786e-001,-1.472425e-001,4.365614e-002,-8.572170e-002,-8.588567e-002,-3.857452e-007,-3.857452e-007,,,,,,,,,,,,,,,,,,,,
1406903162.375,,-3.500000e+001,2.980050e+002,2.979968e+002,1,0,3.810442e+000,1.435896e-001,1.435896e-001,2.126242e-002,1.404777e-002,1.762566e-001,5.392946e-002,4.671481e-002,3.129192e-006,3.129192e-006,,,,,,,,,,,,,,,,,,,,
1406903180.656,,-3.500000e+001,2.979968e+002,2.979968e+002,1,0,5.567985e-001,1.899777e-001,1.899777e-001,9.956630e-002,9.545964e-002,1.453896e-001,5.497821e-002,5.087155e-002,4.140110e-006,4.140110e-006,,,,,,,,,,,,,,,,,,,,
1406903304.437,,-3.000000e+001,2.979968e+002,2.980050e+002,1,0,1.719518e+000,2.639851e-002,2.639851e-002,-6.449690e-002,-6.442513e-002,6.722695e-002,-2.366847e-002,-2.359669e-002,5.752927e-007,5.752927e-007,,,,,,,,,,,,,,,,,,,,
1406903304.437,,-3.000000e+001,2.979968e+002,2.980050e+002,1,0,3.894095e+000,8.239997e-002,8.239998e-002,-1.003873e-002,-8.423656e-003,1.336183e-001,4.117957e-002,4.279464e-002,1.795711e-006,1.795711e-006,,,,,,,,,,,,,,,,,,,,
1406903323.171,,-3.000000e+001,2.979968e+002,2.980050e+002,1,0,6.835699e-001,2.003540e-001,2.003540e-001,1.070464e-001,1.098093e-001,1.381846e-001,4.487699e-002,4.763991e-002,4.366239e-006,4.366239e-006,,,,,,,,,,,,,,,,,,,,
1406903340.906,,-3.000000e+001,2.979968e+002,2.979968e+002,1,0,1.539439e+000,1.124607e-001,1.124607e-001,-2.781917e-003,-2.435021e-003,1.138446e-001,-1.398069e-003,-1.051173e-003,2.450814e-006,2.450814e-006,,,,,,,,,,,,,,,,,,,,
1406903340.906,,-3.000000e+001,2.979968e+002,2.979968e+002,1,0,3.954004e+000,1.016266e-001,1.016266e-001,-1.858817e-002,-1.326910e-002,1.653711e-001,4.515627e-002,5.047534e-002,2.214711e-006,2.214711e-006,,,,,,,,,,,,,,,,,,,,
1406903458.671,,-2.500000e+001,2.979968e+002,2.979968e+002,1,0,8.161803e-001,1.408429e-001,1.408429e-001,1.092156e-001,1.136363e-001,5.765339e-002,2.602612e-002,3.044674e-002,3.069338e-006,3.069338e-006,,,,,,,,,,,,,,,,,,,,
1406903476.437,,-2.500000e+001,2.979968e+002,2.979885e+002,1,0,1.361633e+000,1.576281e-001,1.576281e-001,7.727206e-002,7.864483e-002,1.125451e-001,3.218905e-002,3.356182e-002,3.435131e-006,3.435131e-006,,,,,,,,,,,,,,,,,,,,
1406903476.437,,-2.500000e+001,2.979968e+002,2.979885e+002,1,0,3.987950e+000,5.584887e-002,5.584887e-002,-3.926444e-002,-2.313440e-002,1.109063e-001,1.579296e-002,3.192301e-002,1.217094e-006,1.217094e-006,,,,,,,,,,,,,,,,,,,,
1406903494.671,,-2.500000e+001,2.979968e+002,2.979968e+002,1,0,9.543387e-001,2.085940e-001,2.085940e-001,1.234690e-001,1.325904e-001,1.155371e-001,3.041206e-002,3.953340e-002,4.545812e-006,4.545812e-006,,,,,,,,,,,,,,,,,,,,
1406903612.906,,-2.000000e+001,2.979968e+002,2.979968e+002,1,0,1.187809e+000,1.448103e-001,1.448103e-001,1.005209e-001,9.772305e-002,5.139174e-002,7.102343e-003,4.304465e-003,3.155800e-006,3.155800e-006,,,,,,,,,,,,,,,,,,,,
1406903612.906,,-2.000000e+001,2.979968e+002,2.979968e+002,1,0,3.994907e+000,-1.663259e-002,-1.663259e-002,-3.686024e-002,-6.371987e-002,1.813039e-002,-2.097259e-003,-2.895689e-002,-3.624680e-007,-3.624680e-007,,,,,,,,,,,,,,,,,,,,
1406903630.156,,-2.000000e+001,2.979968e+002,2.979968e+002,1,0,1.098771e+000,1.893673e-001,1.893674e-001,1.289648e-001,1.161118e-001,6.686776e-002,6.465246e-003,-6.387800e-003,4.126815e-006,4.126815e-006,,,,,,,,,,,,,,,,,,,,
1406903648.390,,-2.000000e+001,2.979968e+002,2.979968e+002,1,0,1.018647e+000,1.806696e-001,1.806696e-001,1.026816e-001,9.993976e-002,8.320935e-002,5.221340e-003,2.479538e-003,3.937267e-006,3.937267e-006,,,,,,,,,,,,,,,,,,,,
1406903648.390,,-2.000000e+001,2.979968e+002,2.979968e+002,1,0,3.975087e+000,2.151555e-002,2.151555e-002,-3.682288e-002,-5.921426e-002,5.585675e-002,-2.481680e-003,-2.487306e-002,4.688806e-007,4.688806e-007,,,,,,,,,,,,,,,,,,,,
1406903764.640,,-1.500000e+001,2.980050e+002,2.979968e+002,1,0,1.249856e+000,1.156652e-001,1.156652e-001,1.297716e-001,1.042209e-001,-1.401148e-002,9.492808e-005,-2.545571e-002,2.520650e-006,2.520650e-006,,,,,,,,,,,,,,,,,,,,
1406903782.875,,-1.500000e+001,2.980050e+002,2.979968e+002,1,0,8.557141e-001,1.159703e-001,1.159703e-001,8.837588e-002,8.314304e-002,2.748408e-002,-1.103730e-004,-5.343219e-003,2.527301e-006,2.527301e-006,,,,,,,,,,,,,,,,,,,,
1406903782.875,,-1.500000e+001,2.980050e+002,2.979968e+002,1,0,3.930317e+000,-3.723258e-002,-3.723258e-002,-3.268241e-002,-7.005988e-002,-4.769880e-003,-2.197062e-004,-3.759718e-002,-8.113967e-007,-8.113967e-007,,,,,,,,,,,,,,,,,,,,
1406903800.609,,-1.500000e+001,2.979968e+002,2.979968e+002,1,0,1.408197e+000,1.396222e-001,1.396222e-001,1.054356e-001,8.372758e-002,3.399228e-002,-1.943104e-004,-2.190232e-002,3.042737e-006,3.042737e-006,,,,,,,,,,,,,,,,,,,,
1406903917.843,,-1.000000e+001,2.980050e+002,2.979968e+002,1,0,6.999019e-001,4.318369e-002,4.318369e-002,6.128844e-002,5.491368e-002,-2.738591e-002,-9.281162e-003,-1.565592e-002,9.410876e-007,9.410876e-007,,,,,,,,,,,,,,,,,,,,
1406903917.843,,-1.000000e+001,2.980050e+002,2.979968e+002,1,0,3.863262e+000,-8.941923e-002,-8.941923e-002,-3.705018e-002,-7.768924e-002,-6.383718e-002,-1.146813e-002,-5.210719e-002,-1.948683e-006,-1.948683e-006,,,,,,,,,,,,,,,,,,,,
1406903935.078,,-1.000000e+001,2.980050e+002,2.979968e+002,1,0,1.573525e+000,4.776147e-002,4.776147e-002,6.941362e-002,5.036208e-002,-1.498544e-003,2.015362e-002,1.102074e-003,1.040849e-006,1.040849e-006,,,,,,,,,,,,,,,,,,,,
1406903953.312,,-1.000000e+001,2.979968e+002,2.979968e+002,1,0,5.530308e-001,5.218665e-002,5.218665e-002,2.919369e-002,2.330305e-002,1.108659e-002,-1.190638e-002,-1.779702e-002,1.137286e-006,1.137286e-006,,,,,,,,,,,,,,,,,,,,
1406903953.312,,-1.000000e+001,2.979968e+002,2.979968e+002,1,0,3.777623e+000,-2.807703e-002,-2.807703e-002,-2.292582e-002,-5.696063e-002,-1.755527e-002,-1.240406e-002,-4.643887e-002,-6.118732e-007,-6.118732e-007,,,,,,,,,,,,,,,,,,,,
1406904069.593,,-5.000000e+000,2.979968e+002,2.980132e+002,1,0,1.745167e+000,2.166814e-002,2.166814e-002,6.002841e-002,1.081221e-001,4.892110e-002,8.728137e-002,1.353751e-001,4.722067e-007,4.722067e-007,,,,,,,,,,,,,,,,,,,,
1406904087.328,,-5.000000e+000,2.979968e+002,2.979968e+002,1,0,4.173472e-001,-3.051851e-003,-3.051851e-003,4.989120e-002,6.644811e-002,-1.525380e-002,3.768925e-002,5.424616e-002,-6.650799e-008,-6.650799e-008,,,,,,,,,,,,,,,,,,,,
1406904087.328,,-5.000000e+000,2.979968e+002,2.979968e+002,1,0,3.677111e+000,-2.945036e-002,-2.945036e-002,-4.770203e-002,4.004960e-002,-9.123921e-003,-2.737559e-002,6.037604e-002,-6.418020e-007,-6.418020e-007,,,,,,,,,,,,,,,,,,,,
1406904105.593,,-5.000000e+000,2.980050e+002,2.979968e+002,1,0,1.921757e+000,2.716147e-002,2.716147e-002,2.232931e-002,7.629894e-002,5.411661e-002,4.928445e-002,1.032541e-001,5.919211e-007,5.919211e-007,,,,,,,,,,,,,,,,,,,,
1406904223.328,,0.000000e+000,2.980050e+002,2.980050e+002,1,0,2.956539e-001,-1.306192e-001,-1.306192e-001,-5.992969e-003,1.230210e-002,-1.265092e-001,-1.882976e-003,1.641209e-002,-2.846543e-006,-2.846543e-006,,,,,,,,,,,,,,,,,,,,
1406904223.328,,0.000000e+000,2.980050e+002,2.980050e+002,1,0,3.565295e+000,-9.628590e-002,-9.628589e-002,-4.317673e-002,4.663543e-002,-9.295553e-002,-3.984636e-002,4.996580e-002,-2.098328e-006,-2.098328e-006,,,,,,,,,,,,,,,,,,,,
1406904241.593,,0.000000e+000,2.979968e+002,2.979968e+002,1,0,2.101469e+000,9.002960e-003,9.002960e-003,2.918887e-002,8.753488e-002,1.021857e-002,3.040448e-002,8.875049e-002,1.961986e-007,1.961986e-007,,,,,,,,,,,,,,,,,,,,
1406904259.828,,0.000000e+000,2.979968e+002,2.979968e+002,1,0,1.913314e-001,-1.580859e-001,-1.580859e-001,-4.780689e-002,-2.683914e-002,-1.328195e-001,-2.254054e-002,-1.572788e-003,-3.445115e-006,-3.445115e-006,,,,,,,,,,,,,,,,,,,,
1406904259.828,,0.000000e+000,2.979968e+002,2.979968e+002,1,0,3.444997e+000,-5.859554e-002,-5.859554e-002,-2.345099e-002,7.265121e-002,-8.324105e-002,-4.809650e-002,4.800570e-002,-1.276954e-006,-1.276954e-006,,,,,,,,,,,,,,,,,,,,
1406904376.578,,5.000000e+000,2.979968e+002,2.979968e+002,1,0,2.282534e+000,-6.439406e-002,-6.439406e-002,5.349897e-002,1.126201e-001,-1.086236e-001,9.269456e-003,6.839063e-002,-1.403318e-006,-1.403318e-006,,,,,,,,,,,,,,,,,,,,
1406904394.312,,5.000000e+000,2.979968e+002,2.979968e+002,1,0,1.076345e-001,-2.220222e-001,-2.220222e-001,-1.004414e-001,-7.457045e-002,-1.757750e-001,-5.419432e-002,-2.832332e-002,-4.838456e-006,-4.838456e-006,,,,,,,,,,,,,,,,,,,,
1406904394.312,,5.000000e+000,2.979968e+002,2.979968e+002,1,0,3.318072e+000,-5.829035e-002,-5.829035e-002,-2.228293e-002,8.916136e-002,-1.054573e-001,-6.944990e-002,4.199439e-002,-1.270303e-006,-1.270303e-006,,,,,,,,,,,,,,,,,,,,
1406904411.843,,5.000000e+000,2.979968e+002,2.980050e+002,1,0,2.462616e+000,-5.493332e-003,-5.493332e-003,5.563941e-002,1.204598e-001,-8.985519e-002,-2.872245e-002,3.609791e-002,-1.197144e-007,-1.197144e-007,,,,,,,,,,,,,,,,,,,,
1406904535.578,,1.000000e+001,2.980050e+002,2.980050e+002,1,0,4.774271e-002,-2.903836e-001,-2.903836e-001,-1.403867e-001,-1.135073e-001,-2.313925e-001,-8.139552e-002,-5.451615e-002,-6.328232e-006,-6.328232e-006,,,,,,,,,,,,,,,,,,,,
1406904535.578,,1.000000e+001,2.980050e+002,2.980050e+002,1,0,3.185523e+000,-7.995849e-002,-7.995850e-002,-1.251962e-002,9.691782e-002,-1.600818e-001,-9.264293e-002,1.679452e-002,-1.742508e-006,-1.742508e-006,,,,,,,,,,,,,,,,,,,,
1406904554.062,,1.000000e+001,2.980050e+002,2.979968e+002,1,0,2.640124e+000,-3.738517e-002,-3.738517e-002,6.808761e-002,1.397949e-001,-1.578487e-001,-5.237595e-002,1.933134e-002,-8.147225e-007,-8.147225e-007,,,,,,,,,,,,,,,,,,,,
1406904572.125,,1.000000e+001,2.980050e+002,2.980050e+002,1,0,1.384103e-002,-2.653584e-001,-2.653584e-001,-1.534806e-001,-1.234839e-001,-1.970375e-001,-8.515965e-002,-5.516298e-002,-5.782867e-006,-5.782867e-006,,,,,,,,,,,,,,,,,,,,
1406904572.125,,1.000000e+001,2.980050e+002,2.980050e+002,1,0,3.047344e+000,-2.441481e-002,-2.441481e-002,1.472608e-003,1.174597e-001,-1.213623e-001,-9.547485e-002,2.051229e-002,-5.320637e-007,-5.320637e-007,,,,,,,,,,,,,,,,,,,,
1406904683.906,,1.500000e+001,2.980050e+002,2.979968e+002,1,0,2.814167e+000,-7.446516e-002,-7.446516e-002,7.237170e-002,1.433972e-001,-2.226893e-001,-7.585247e-002,-4.826993e-003,-1.622793e-006,-1.622793e-006,,,,,,,,,,,,,,,,,,,,
1406904701.640,,1.500000e+001,2.979968e+002,2.979885e+002,1,0,6.924210e-003,-3.286843e-001,-3.286844e-001,-1.779833e-001,-1.449561e-001,-2.520261e-001,-1.013250e-001,-6.829779e-002,-7.162903e-006,-7.162903e-006,,,,,,,,,,,,,,,,,,,,
1406904701.640,,1.500000e+001,2.979968e+002,2.979885e+002,1,0,2.903036e+000,-4.287850e-002,-4.287850e-002,1.906176e-002,1.408498e-001,-1.513800e-001,-8.943974e-002,3.234826e-002,-9.344363e-007,-9.344363e-007,,,,,,,,,,,,,,,,,,,,
1406904719.375,,1.500000e+001,2.979885e+002,2.980050e+002,1,0,2.983181e+000,-6.576739e-002,-6.576739e-002,5.109093e-002,1.298669e-001,-2.150514e-001,-9.819303e-002,-1.941711e-002,-1.433246e-006,-1.433246e-006,,,,,,,,,,,,,,,,,,,,
1406904837.109,,2.000000e+001,2.979968e+002,2.980050e+002,1,0,2.665072e-002,-3.634754e-001,-3.634754e-001,-1.990760e-001,-1.647036e-001,-2.793361e-001,-1.149366e-001,-8.056428e-002,-7.921090e-006,-7.921090e-006,,,,,,,,,,,,,,,,,,,,
1406904837.109,,2.000000e+001,2.979968e+002,2.980050e+002,1,0,2.751911e+000,-3.067110e-002,-3.067110e-002,4.678651e-002,1.681007e-001,-1.293049e-001,-5.184726e-002,6.946695e-002,-6.684043e-007,-6.684043e-007,,,,,,,,,,,,,,,,,,,,
1406904855.843,,2.000000e+001,2.979968e+002,2.979968e+002,1,0,3.146014e+000,-1.086459e-001,-1.086459e-001,3.277509e-002,1.131110e-001,-2.556154e-001,-1.141944e-001,-3.385849e-002,-2.367681e-006,-2.367681e-006,,,,,,,,,,,,,,,,,,,,
1406904873.578,,2.000000e+001,2.980050e+002,2.980050e+002,1,0,7.147233e-002,-3.514206e-001,-3.514206e-001,-1.840348e-001,-1.458957e-001,-2.806463e-001,-1.132604e-001,-7.512128e-002,-7.658384e-006,-7.658384e-006,,,,,,,,,,,,,,,,,,,,
1406904873.578,,2.000000e+001,2.980050e+002,2.980050e+002,1,0,2.593588e+000,-1.892148e-002,-1.892148e-002,5.735423e-002,1.866035e-001,-8.498356e-002,-8.707852e-003,1.205414e-001,-4.123490e-007,-4.123490e-007,,,,,,,,,,,,,,,,,,,,
1406904991.828,,2.500000e+001,2.980050e+002,2.979968e+002,1,0,3.301952e+000,-1.982177e-001,-1.982177e-001,-4.527047e-004,8.081052e-002,-3.258241e-001,-1.280590e-001,-4.679582e-002,-4.319686e-006,-4.319686e-006,,,,,,,,,,,,,,,,,,,,
1406905010.843,,2.500000e+001,2.980050e+002,2.980050e+002,1,0,1.384120e-001,-3.964354e-001,-3.964354e-001,-1.915342e-001,-1.510859e-001,-3.308239e-001,-1.259227e-001,-8.547436e-002,-8.639371e-006,-8.639371e-006,,,,,,,,,,,,,,,,,,,,
1406905010.843,,2.500000e+001,2.980050e+002,2.980050e+002,1,0,2.428237e+000,-2.685629e-002,-2.685629e-002,8.650403e-002,2.184932e-001,-3.172122e-002,8.163910e-002,2.136283e-001,-5.852692e-007,-5.852692e-007,,,,,,,,,,,,,,,,,,,,
1406905028.875,,2.500000e+001,2.979968e+002,2.979968e+002,1,0,3.448713e+000,-1.887570e-001,-1.887570e-001,-4.755187e-002,4.131374e-002,-2.644207e-001,-1.232156e-001,-3.434996e-002,-4.113511e-006,-4.113511e-006,,,,,,,,,,,,,,,,,,,,
1406905140.359,,3.000000e+001,2.980050e+002,2.979968e+002,1,0,2.240678e-001,-3.962829e-001,-3.962829e-001,-1.806789e-001,-1.386139e-001,-3.530133e-001,-1.374094e-001,-9.534433e-002,-8.636042e-006,-8.636042e-006,,,,,,,,,,,,,,,,,,,,
1406905140.359,,3.000000e+001,2.980050e+002,2.979968e+002,1,0,2.256593e+000,-1.007111e-002,-1.007111e-002,1.150930e-001,2.475979e-001,6.086500e-002,1.860291e-001,3.185340e-001,-2.194759e-007,-2.194759e-007,,,,,,,,,,,,,,,,,,,,
1406905158.093,,3.000000e+001,2.979968e+002,2.979968e+002,1,0,3.584448e+000,-2.749718e-001,-2.749718e-001,-1.071688e-001,-1.550543e-002,-2.970800e-001,-1.292770e-001,-3.761360e-002,-5.992355e-006,-5.992355e-006,,,,,,,,,,,,,,,,,,,,
1406905176.078,,3.000000e+001,2.979968e+002,2.979968e+002,1,0,3.246834e-001,-3.703421e-001,-3.703421e-001,-1.413516e-001,-9.498161e-002,-3.552117e-001,-1.262212e-001,-7.985121e-002,-8.070725e-006,-8.070725e-006,,,,,,,,,,,,,,,,,,,,
1406905293.328,,3.500000e+001,2.979968e+002,2.979968e+002,1,0,2.080184e+000,-3.646962e-002,-3.646962e-002,2.934135e-001,2.934135e-001,-2.650755e-002,3.033755e-001,3.033755e-001,-7.947682e-007,-7.947682e-007,,,,,,,,,,,,,,,,,,,,
1406905293.328,,3.500000e+001,2.979968e+002,2.979968e+002,1,0,3.706105e+000,-4.049806e-001,-4.049806e-001,-1.651201e-001,-7.509753e-002,-3.743287e-001,-1.344682e-001,-4.444563e-002,-8.825585e-006,-8.825585e-006,,,,,,,,,,,,,,,,,,,,
1406905312.062,,3.500000e+001,2.979885e+002,2.979968e+002,1,0,4.364207e-001,-3.544725e-001,-3.544725e-001,-1.107296e-001,-6.227770e-002,-3.719023e-001,-1.281594e-001,-7.970753e-002,-7.724881e-006,-7.724881e-006,,,,,,,,,,,,,,,,,,,,
1406905329.562,,3.500000e+001,2.979968e+002,2.979968e+002,1,0,1.900312e+000,-2.288888e-003,-2.288888e-003,3.009866e-001,3.032314e-001,4.717751e-002,3.504530e-001,3.526978e-001,-4.988085e-008,-4.988085e-008,,,,,,,,,,,,,,,,,,,,
1406905329.562,,3.500000e+001,2.979968e+002,2.979968e+002,1,0,3.810406e+000,-4.094058e-001,-4.094058e-001,-2.026548e-001,-1.038855e-001,-3.260404e-001,-1.192893e-001,-2.052009e-002,-8.922021e-006,-8.922021e-006,,,,,,,,,,,,,,,,,,,,
1406905445.796,,4.000000e+001,2.980050e+002,2.979968e+002,1,0,5.566610e-001,-4.004028e-001,-4.004028e-001,-7.717742e-002,-2.671567e-002,-4.488197e-001,-1.255943e-001,-7.513255e-002,-8.725819e-006,-8.725819e-006,,,,,,,,,,,,,,,,,,,,
1406905463.781,,4.000000e+001,2.979968e+002,2.979968e+002,1,0,1.719442e+000,1.113926e-002,1.113926e-002,3.387722e-001,3.433337e-001,5.185495e-002,3.794879e-001,3.840494e-001,2.427533e-007,2.427533e-007,,,,,,,,,,,,,,,,,,,,
1406905463.781,,4.000000e+001,2.979968e+002,2.979968e+002,1,0,3.894028e+000,-4.931791e-001,-4.931791e-001,-2.636180e-001,-1.609847e-001,-3.570856e-001,-1.275245e-001,-2.489114e-002,-1.074766e-005,-1.074766e-005,,,,,,,,,,,,,,,,,,,,
1406905482.015,,4.000000e+001,2.979968e+002,2.979968e+002,1,0,6.834880e-001,-3.183081e-001,-3.183081e-001,-2.217874e-002,3.315982e-002,-3.800839e-001,-8.395460e-002,-2.861604e-002,-6.936760e-006,-6.936760e-006,,,,,,,,,,,,,,,,,,,,
1406905592.515,,4.500000e+001,2.979968e+002,2.979968e+002,1,0,1.539397e+000,-2.639851e-002,-2.639851e-002,3.583222e-001,3.651277e-001,-5.192760e-002,3.327931e-001,3.395986e-001,-5.752919e-007,-5.752919e-007,,,,,,,,,,,,,,,,,,,,
1406905592.515,,4.500000e+001,2.979968e+002,2.979968e+002,1,0,3.953981e+000,-5.948058e-001,-5.948058e-001,-3.076305e-001,-2.032796e-001,-4.225886e-001,-1.354134e-001,-3.106242e-002,-1.296236e-005,-1.296236e-005,,,,,,,,,,,,,,,,,,,,
1406905610.250,,4.500000e+001,2.979968e+002,2.979968e+002,1,0,8.160782e-001,-2.743614e-001,-2.743614e-001,3.192428e-002,9.034607e-002,-3.575779e-001,-5.129223e-002,7.129550e-003,-5.979045e-006,-5.979045e-006,,,,,,,,,,,,,,,,,,,,
1406905628.500,,4.500000e+001,2.979968e+002,2.979968e+002,1,0,1.361524e+000,-2.197333e-002,-2.197333e-002,3.259355e-001,3.356133e-001,-1.108639e-001,2.370450e-001,2.467228e-001,-4.788557e-007,-4.788557e-007,,,,,,,,,,,,,,,,,,,,
1406905628.500,,4.500000e+001,2.979968e+002,2.979968e+002,1,0,3.987881e+000,-5.642872e-001,-5.642872e-001,-3.204144e-001,-2.067006e-001,-3.736301e-001,-1.297573e-001,-1.604342e-002,-1.229728e-005,-1.229728e-005,,,,,,,,,,,,,,,,,,,,
1406905746.734,,5.000000e+001,2.979968e+002,2.980050e+002,1,0,9.543935e-001,-2.652059e-001,-2.652059e-001,1.037649e-001,1.660781e-001,-3.715402e-001,-2.569493e-003,5.974376e-002,-5.779520e-006,-5.779520e-006,,,,,,,,,,,,,,,,,,,,
1406905764.968,,5.000000e+001,2.979885e+002,2.980050e+002,1,0,1.187611e+000,-1.670888e-001,-1.670888e-001,2.712175e-001,2.829531e-001,-3.096558e-001,1.286505e-001,1.403861e-001,-3.641297e-006,-3.641297e-006,,,,,,,,,,,,,,,,,,,,
1406905764.968,,5.000000e+001,2.979885e+002,2.980050e+002,1,0,3.994832e+000,-6.860561e-001,-6.860561e-001,-3.486760e-001,-2.360142e-001,-4.855089e-001,-1.481288e-001,-3.546700e-002,-1.495093e-005,-1.495093e-005,,,,,,,,,,,,,,,,,,,,
1406905783.203,,5.000000e+001,2.980050e+002,2.979968e+002,1,0,1.098610e+000,-1.387066e-001,-1.387066e-001,1.831081e-001,2.506445e-001,-2.436618e-001,7.815292e-002,1.456894e-001,-3.022775e-006,-3.022775e-006,,,,,,,,,,,,,,,,,,,,
1406905906.203,,7.500000e+001,2.979968e+002,2.980050e+002,1,0,1.018723e+000,-3.595081e-001,-3.595080e-001,1.890801e-001,2.072750e-001,-5.600632e-001,-1.147506e-002,6.719768e-003,-7.834590e-006,-7.834590e-006,,,,,,,,,,,,,,,,,,,,
1406905906.203,,7.500000e+001,2.979968e+002,2.980050e+002,1,0,3.975098e+000,-8.845791e-001,-8.845790e-001,-4.663871e-001,-3.177960e-001,-6.528223e-001,-2.346304e-001,-8.603930e-002,-1.927721e-005,-1.927721e-005,,,,,,,,,,,,,,,,,,,,
1406905924.453,,7.500000e+001,2.979968e+002,2.980050e+002,1,0,1.249800e+000,-2.401807e-001,-2.401807e-001,2.880366e-001,3.732727e-001,-3.543580e-001,1.738592e-001,2.590954e-001,-5.234145e-006,-5.234145e-006,,,,,,,,,,,,,,,,,,,,
1406905942.187,,7.500000e+001,2.979968e+002,2.979968e+002,1,0,8.559139e-001,-4.611347e-001,-4.611347e-001,6.574880e-002,8.730626e-002,-6.523714e-001,-1.254879e-001,-1.039305e-001,-1.004929e-005,-1.004929e-005,,,,,,,,,,,,,,,,,,,,
1406905942.187,,7.500000e+001,2.979968e+002,2.979968e+002,1,0,3.930354e+000,-8.423108e-001,-8.423108e-001,-4.478518e-001,-2.938699e-001,-6.411939e-001,-2.467348e-001,-9.275293e-002,-1.835609e-005,-1.835609e-005,,,,,,,,,,,,,,,,,,,,
1406906066.421,,1.000000e+002,2.980050e+002,2.980050e+002,1,0,1.408014e+000,-2.095096e-001,-2.095096e-001,4.581268e-001,5.588362e-001,-2.903233e-001,3.773130e-001,4.780225e-001,-4.565733e-006,-4.565733e-006,,,,,,,,,,,,,,,,,,,,
1406906084.406,,1.000000e+002,2.979968e+002,2.979968e+002,1,0,7.000908e-001,-8.114872e-001,-8.114871e-001,-8.868449e-002,-6.059271e-002,-1.004758e+000,-2.819550e-001,-2.538632e-001,-1.768432e-005,-1.768432e-005,,,,,,,,,,,,,,,,,,,,
1406906084.406,,1.000000e+002,2.979968e+002,2.979968e+002,1,0,3.863352e+000,-1.084323e+000,-1.084323e+000,-5.125133e-001,-3.334283e-001,-9.112391e-001,-3.394298e-001,-1.603447e-001,-2.363008e-005,-2.363008e-005,,,,,,,,,,,,,,,,,,,,
1406906102.921,,1.000000e+002,2.979968e+002,2.979968e+002,1,0,1.573331e+000,-9.994812e-002,-9.994812e-002,5.466332e-001,6.491507e-001,-8.630329e-002,5.602780e-001,6.627955e-001,-2.178117e-006,-2.178117e-006,,,,,,,,,,,,,,,,,,,,
1406906102.921,,1.000000e+002,2.979968e+002,2.979968e+002,1,0,2.256622e+000,-1.113926e-002,-1.113926e-002,5.226728e-001,7.379595e-001,2.250056e-001,7.588176e-001,9.741043e-001,-2.427520e-007,-2.427520e-007,,,,,,,,,,,,,,,,,,,,